{"capturedAt":1776808415,"payload":{"market":"0x125149c5918fc5f8c6d34682f700a898a1a19ea4f4e2ae68ff4c5794ba657074","asset_id":"86520121088881862182423437128238697252500151785248183602134095101149900014256","bids":[{"price":"0.01","size":"12907.69"},{"price":"0.02","size":"1746.16"},{"price":"0.03","size":"1613.83"},{"price":"0.04","size":"938.3"},{"price":"0.05","size":"790.63"},{"price":"0.06","size":"395.8"},{"price":"0.07","size":"685.3"},{"price":"0.08","size":"656.9"},{"price":"0.09","size":"267.44"},{"price":"0.1","size":"812.8"},{"price":"0.11","size":"391.5"},{"price":"0.12","size":"308.5"},{"price":"0.13","size":"198.74"}],"asks":[{"price":"0.99","size":"12329.83"},{"price":"0.98","size":"1715.28"},{"price":"0.97","size":"1338.69"},{"price":"0.96","size":"583.84"},{"price":"0.95","size":"1006.34"},{"price":"0.94","size":"392.8"},{"price":"0.93","size":"304.69"},{"price":"0.92","size":"278.9"},{"price":"0.91","size":"225"},{"price":"0.9","size":"282"},{"price":"0.89","size":"217.79"},{"price":"0.88","size":"215.1"},{"price":"0.87","size":"202.8"},{"price":"0.86","size":"200.9"},{"price":"0.85","size":"209.2"},{"price":"0.84","size":"197.8"},{"price":"0.83","size":"202.39"},{"price":"0.82","size":"200.4"},{"price":"0.81","size":"194.4"},{"price":"0.8","size":"193.5"},{"price":"0.79","size":"215.31"},{"price":"0.78","size":"197"},{"price":"0.77","size":"229.34"},{"price":"0.76","size":"195.7"},{"price":"0.75","size":"190.2"},{"price":"0.74","size":"189.7"},{"price":"0.73","size":"194.3"},{"price":"0.72","size":"188.89"},{"price":"0.71","size":"188.5"},{"price":"0.7","size":"206.48"},{"price":"0.69","size":"394.45"},{"price":"0.68","size":"187.5"},{"price":"0.67","size":"193.55"},{"price":"0.66","size":"187"},{"price":"0.65","size":"602.68"},{"price":"0.64","size":"186.6"},{"price":"0.63","size":"191.96"},{"price":"0.62","size":"186.3"},{"price":"0.61","size":"491.36"},{"price":"0.6","size":"226"},{"price":"0.59","size":"203.32"},{"price":"0.58","size":"185.8"},{"price":"0.57","size":"190.8"},{"price":"0.56","size":"190.6"},{"price":"0.55","size":"230.58"},{"price":"0.54","size":"185.5"},{"price":"0.53","size":"245.86"},{"price":"0.52","size":"242.56"},{"price":"0.51","size":"222.4"},{"price":"0.5","size":"378.64"},{"price":"0.49","size":"205.25"},{"price":"0.48","size":"226.77"},{"price":"0.47","size":"136.71"},{"price":"0.46","size":"185.5"},{"price":"0.45","size":"207.66"},{"price":"0.44","size":"196.6"},{"price":"0.43","size":"180.7"},{"price":"0.42","size":"180.8"},{"price":"0.41","size":"180.9"},{"price":"0.4","size":"139"},{"price":"0.39","size":"185.46"},{"price":"0.38","size":"141.3"},{"price":"0.37","size":"131.4"},{"price":"0.36","size":"131.6"},{"price":"0.35","size":"136.8"},{"price":"0.34","size":"342"},{"price":"0.33","size":"232.3"},{"price":"0.32","size":"382.5"},{"price":"0.31","size":"182.8"},{"price":"0.3","size":"244.95"},{"price":"0.29","size":"405.5"},{"price":"0.28","size":"530.89"},{"price":"0.27","size":"217.3"},{"price":"0.26","size":"287.7"},{"price":"0.25","size":"382.29"},{"price":"0.24","size":"148.49"},{"price":"0.23","size":"221.3"},{"price":"0.22","size":"328.98"},{"price":"0.21","size":"219.7"},{"price":"0.2","size":"245.25"},{"price":"0.19","size":"304.9"},{"price":"0.18","size":"325.78"},{"price":"0.17","size":"347.49"},{"price":"0.16","size":"384.37"},{"price":"0.15","size":"437.28"},{"price":"0.14","size":"259.27"}],"hash":"9ac6b2ed50f984e3a1860eb849b3a209afe7b20d","timestamp":"1776808415667","event_type":"book"}}
{"capturedAt":1776808415,"payload":{"market":"0x125149c5918fc5f8c6d34682f700a898a1a19ea4f4e2ae68ff4c5794ba657074","price_changes":[{"asset_id":"86520121088881862182423437128238697252500151785248183602134095101149900014256","price":"0.13","size":"198.74","side":"BUY","hash":"9ac6b2ed50f984e3a1860eb849b3a209afe7b20d","best_bid":"0.13","best_ask":"0.14"},{"asset_id":"45936375922793925919605092352922707796689801895417366600539442410775071099958","price":"0.87","size":"198.74","side":"SELL","hash":"5d0e84aa6798e6ae6be6e5d15fd8ca3ad2f6b558","best_bid":"0.86","best_ask":"0.87"}],"timestamp":"1776808415667","event_type":"price_change"}}
{"capturedAt":1776808415,"payload":{"market":"0x125149c5918fc5f8c6d34682f700a898a1a19ea4f4e2ae68ff4c5794ba657074","price_changes":[{"asset_id":"45936375922793925919605092352922707796689801895417366600539442410775071099958","price":"0.86","size":"263.21","side":"BUY","hash":"793ab4ac8cf63261e7edb73a9a2c020cfee50e22","best_bid":"0.86","best_ask":"0.87"},{"asset_id":"86520121088881862182423437128238697252500151785248183602134095101149900014256","price":"0.14","size":"263.21","side":"SELL","hash":"848ebe5aed697480fbc9d54d285de47c5ed37848","best_bid":"0.13","best_ask":"0.14"}],"timestamp":"1776808415671","event_type":"price_change"}}
{"capturedAt":1776808415,"payload":{"market":"0x125149c5918fc5f8c6d34682f700a898a1a19ea4f4e2ae68ff4c5794ba657074","price_changes":[{"asset_id":"45936375922793925919605092352922707796689801895417366600539442410775071099958","price":"0.01","size":"12324.83","side":"BUY","hash":"e92b5fc5bd760e98c5256116a0591b4cb9c1f693","best_bid":"0.86","best_ask":"0.87"},{"asset_id":"86520121088881862182423437128238697252500151785248183602134095101149900014256","price":"0.99","size":"12324.83","side":"SELL","hash":"30dae50b45874f978d4134c83f87a35b910bb419","best_bid":"0.13","best_ask":"0.14"}],"timestamp":"1776808415668","event_type":"price_change"}}
{"capturedAt":1776808415,"payload":{"market":"0x125149c5918fc5f8c6d34682f700a898a1a19ea4f4e2ae68ff4c5794ba657074","price_changes":[{"asset_id":"45936375922793925919605092352922707796689801895417366600539442410775071099958","price":"0.86","size":"282.21","side":"BUY","hash":"234eb423d20af52a36cec04f6b04f3f85ee35e2c","best_bid":"0.86","best_ask":"0.87"},{"asset_id":"86520121088881862182423437128238697252500151785248183602134095101149900014256","price":"0.14","size":"282.21","side":"SELL","hash":"5803f6a2f2db7688499e2cb70be9dc5c60f9f73a","best_bid":"0.13","best_ask":"0.14"}],"timestamp":"1776808415672","event_type":"price_change"}}
{"capturedAt":1776808415,"payload":{"market":"0x125149c5918fc5f8c6d34682f700a898a1a19ea4f4e2ae68ff4c5794ba657074","price_changes":[{"asset_id":"45936375922793925919605092352922707796689801895417366600539442410775071099958","price":"0.86","size":"264.21","side":"BUY","hash":"e01ca15c70089d4857eee22e16239647715cffd4","best_bid":"0.86","best_ask":"0.87"},{"asset_id":"86520121088881862182423437128238697252500151785248183602134095101149900014256","price":"0.14","size":"264.21","side":"SELL","hash":"4eb060655c149a639bebdfa1d478d810b90c4cc6","best_bid":"0.13","best_ask":"0.14"}],"timestamp":"1776808415672","event_type":"price_change"}}
{"capturedAt":1776808415,"payload":{"market":"0x125149c5918fc5f8c6d34682f700a898a1a19ea4f4e2ae68ff4c5794ba657074","price_changes":[{"asset_id":"45936375922793925919605092352922707796689801895417366600539442410775071099958","price":"0.86","size":"283.21","side":"BUY","hash":"39476459fa25d59e1a6752b3237cc8fb1d1d5660","best_bid":"0.86","best_ask":"0.87"},{"asset_id":"86520121088881862182423437128238697252500151785248183602134095101149900014256","price":"0.14","size":"283.21","side":"SELL","hash":"3114160c55e9aa778d997c13d19e388e74231a99","best_bid":"0.13","best_ask":"0.14"}],"timestamp":"1776808415673","event_type":"price_change"}}
{"capturedAt":1776808415,"payload":{"market":"0x125149c5918fc5f8c6d34682f700a898a1a19ea4f4e2ae68ff4c5794ba657074","price_changes":[{"asset_id":"45936375922793925919605092352922707796689801895417366600539442410775071099958","price":"0.86","size":"302.21","side":"BUY","hash":"c726bec89546318f4d7eb7ef482d188bd60fab62","best_bid":"0.86","best_ask":"0.87"},{"asset_id":"86520121088881862182423437128238697252500151785248183602134095101149900014256","price":"0.14","size":"302.21","side":"SELL","hash":"e7a321ac69327d8eac73c2691425aed69cfb7fdd","best_bid":"0.13","best_ask":"0.14"}],"timestamp":"1776808415674","event_type":"price_change"}}
{"capturedAt":1776808415,"payload":{"market":"0x125149c5918fc5f8c6d34682f700a898a1a19ea4f4e2ae68ff4c5794ba657074","price_changes":[{"asset_id":"45936375922793925919605092352922707796689801895417366600539442410775071099958","price":"0.86","size":"244.21","side":"BUY","hash":"73093f0e9b927801149401e107394d6001681aa6","best_bid":"0.86","best_ask":"0.87"},{"asset_id":"86520121088881862182423437128238697252500151785248183602134095101149900014256","price":"0.14","size":"244.21","side":"SELL","hash":"36d6f976a6ae416bcf6f8c82bbf94961aad403d6","best_bid":"0.13","best_ask":"0.14"}],"timestamp":"1776808415670","event_type":"price_change"}}
{"capturedAt":1776808415,"payload":{"market":"0x125149c5918fc5f8c6d34682f700a898a1a19ea4f4e2ae68ff4c5794ba657074","price_changes":[{"asset_id":"45936375922793925919605092352922707796689801895417366600539442410775071099958","price":"0.86","size":"284.21","side":"BUY","hash":"40cab8c002ecd3bb9004e4c9c690133f7251db49","best_bid":"0.86","best_ask":"0.87"},{"asset_id":"86520121088881862182423437128238697252500151785248183602134095101149900014256","price":"0.14","size":"284.21","side":"SELL","hash":"78aae15de75cfd692f94c9821f29f64b1c3957b4","best_bid":"0.13","best_ask":"0.14"}],"timestamp":"1776808415675","event_type":"price_change"}}
{"capturedAt":1776808415,"payload":{"market":"0x125149c5918fc5f8c6d34682f700a898a1a19ea4f4e2ae68ff4c5794ba657074","price_changes":[{"asset_id":"86520121088881862182423437128238697252500151785248183602134095101149900014256","price":"0.07","size":"654.3","side":"BUY","hash":"01783986cc6c9ad879a7e2c292978577f8fcc7f3","best_bid":"0.13","best_ask":"0.14"},{"asset_id":"45936375922793925919605092352922707796689801895417366600539442410775071099958","price":"0.93","size":"654.3","side":"SELL","hash":"c3e0bcd4fbcdb95420ccce4ac9bebb30c04ed160","best_bid":"0.86","best_ask":"0.87"}],"timestamp":"1776808415677","event_type":"price_change"}}
{"capturedAt":1776808415,"payload":{"market":"0x125149c5918fc5f8c6d34682f700a898a1a19ea4f4e2ae68ff4c5794ba657074","price_changes":[{"asset_id":"86520121088881862182423437128238697252500151785248183602134095101149900014256","price":"0.06","size":"426.8","side":"BUY","hash":"0481a295d60da2b007085053652c04efb40ed888","best_bid":"0.13","best_ask":"0.14"},{"asset_id":"45936375922793925919605092352922707796689801895417366600539442410775071099958","price":"0.94","size":"426.8","side":"SELL","hash":"d5ccd2c6ec25e3d475916967e4ff547c6ed74475","best_bid":"0.86","best_ask":"0.87"}],"timestamp":"1776808415677","event_type":"price_change"}}
{"capturedAt":1776808415,"payload":{"market":"0x125149c5918fc5f8c6d34682f700a898a1a19ea4f4e2ae68ff4c5794ba657074","price_changes":[{"asset_id":"45936375922793925919605092352922707796689801895417366600539442410775071099958","price":"0.86","size":"313.21","side":"BUY","hash":"ea8a3cdada061c17e729a5caf9a7208a1060116c","best_bid":"0.86","best_ask":"0.87"},{"asset_id":"86520121088881862182423437128238697252500151785248183602134095101149900014256","price":"0.14","size":"313.21","side":"SELL","hash":"9ac823eaaf3cc492272d04a105fde5b0b0e7ad50","best_bid":"0.13","best_ask":"0.14"}],"timestamp":"1776808415681","event_type":"price_change"}}
{"capturedAt":1776808415,"payload":{"market":"0x125149c5918fc5f8c6d34682f700a898a1a19ea4f4e2ae68ff4c5794ba657074","price_changes":[{"asset_id":"45936375922793925919605092352922707796689801895417366600539442410775071099958","price":"0.86","size":"249.27","side":"BUY","hash":"faa5d00e03171bdcb4025f2a5047cab58c814940","best_bid":"0.86","best_ask":"0.87"},{"asset_id":"86520121088881862182423437128238697252500151785248183602134095101149900014256","price":"0.14","size":"249.27","side":"SELL","hash":"50c781801f0c4f613f0f15373696528a13e44ae0","best_bid":"0.13","best_ask":"0.14"}],"timestamp":"1776808415669","event_type":"price_change"}}
{"capturedAt":1776808415,"payload":{"market":"0x125149c5918fc5f8c6d34682f700a898a1a19ea4f4e2ae68ff4c5794ba657074","price_changes":[{"asset_id":"45936375922793925919605092352922707796689801895417366600539442410775071099958","price":"0.01","size":"12329.83","side":"BUY","hash":"7a3b891f8c1c85c92aa1a8b49653b087d9b78bf2","best_bid":"0.86","best_ask":"0.87"},{"asset_id":"86520121088881862182423437128238697252500151785248183602134095101149900014256","price":"0.99","size":"12329.83","side":"SELL","hash":"e69102d18833c8e74a8d561dda553ba9c5fdc586","best_bid":"0.13","best_ask":"0.14"}],"timestamp":"1776808415687","event_type":"price_change"}}
{"capturedAt":1776808415,"payload":{"market":"0x125149c5918fc5f8c6d34682f700a898a1a19ea4f4e2ae68ff4c5794ba657074","asset_id":"45936375922793925919605092352922707796689801895417366600539442410775071099958","bids":[{"price":"0.01","size":"12329.83"},{"price":"0.02","size":"1715.28"},{"price":"0.03","size":"1338.69"},{"price":"0.04","size":"583.84"},{"price":"0.05","size":"1006.34"},{"price":"0.06","size":"392.8"},{"price":"0.07","size":"304.69"},{"price":"0.08","size":"278.9"},{"price":"0.09","size":"225"},{"price":"0.1","size":"282"},{"price":"0.11","size":"217.79"},{"price":"0.12","size":"215.1"},{"price":"0.13","size":"202.8"},{"price":"0.14","size":"200.9"},{"price":"0.15","size":"209.2"},{"price":"0.16","size":"197.8"},{"price":"0.17","size":"202.39"},{"price":"0.18","size":"200.4"},{"price":"0.19","size":"194.4"},{"price":"0.2","size":"193.5"},{"price":"0.21","size":"215.31"},{"price":"0.22","size":"197"},{"price":"0.23","size":"229.34"},{"price":"0.24","size":"195.7"},{"price":"0.25","size":"190.2"},{"price":"0.26","size":"189.7"},{"price":"0.27","size":"194.3"},{"price":"0.28","size":"188.89"},{"price":"0.29","size":"188.5"},{"price":"0.3","size":"206.48"},{"price":"0.31","size":"394.45"},{"price":"0.32","size":"187.5"},{"price":"0.33","size":"193.55"},{"price":"0.34","size":"187"},{"price":"0.35","size":"602.68"},{"price":"0.36","size":"186.6"},{"price":"0.37","size":"191.96"},{"price":"0.38","size":"186.3"},{"price":"0.39","size":"491.36"},{"price":"0.4","size":"226"},{"price":"0.41","size":"203.32"},{"price":"0.42","size":"185.8"},{"price":"0.43","size":"190.8"},{"price":"0.44","size":"190.6"},{"price":"0.45","size":"230.58"},{"price":"0.46","size":"185.5"},{"price":"0.47","size":"245.86"},{"price":"0.48","size":"242.56"},{"price":"0.49","size":"222.4"},{"price":"0.5","size":"378.64"},{"price":"0.51","size":"205.25"},{"price":"0.52","size":"226.77"},{"price":"0.53","size":"136.71"},{"price":"0.54","size":"185.5"},{"price":"0.55","size":"207.66"},{"price":"0.56","size":"196.6"},{"price":"0.57","size":"180.7"},{"price":"0.58","size":"180.8"},{"price":"0.59","size":"180.9"},{"price":"0.6","size":"139"},{"price":"0.61","size":"185.46"},{"price":"0.62","size":"141.3"},{"price":"0.63","size":"131.4"},{"price":"0.64","size":"131.6"},{"price":"0.65","size":"136.8"},{"price":"0.66","size":"342"},{"price":"0.67","size":"232.3"},{"price":"0.68","size":"382.5"},{"price":"0.69","size":"182.8"},{"price":"0.7","size":"244.95"},{"price":"0.71","size":"405.5"},{"price":"0.72","size":"530.89"},{"price":"0.73","size":"217.3"},{"price":"0.74","size":"287.7"},{"price":"0.75","size":"382.29"},{"price":"0.76","size":"148.49"},{"price":"0.77","size":"221.3"},{"price":"0.78","size":"328.98"},{"price":"0.79","size":"219.7"},{"price":"0.8","size":"245.25"},{"price":"0.81","size":"304.9"},{"price":"0.82","size":"325.78"},{"price":"0.83","size":"347.49"},{"price":"0.84","size":"384.37"},{"price":"0.85","size":"437.28"},{"price":"0.86","size":"259.27"}],"asks":[{"price":"0.99","size":"12907.69"},{"price":"0.98","size":"1746.16"},{"price":"0.97","size":"1613.83"},{"price":"0.96","size":"938.3"},{"price":"0.95","size":"790.63"},{"price":"0.94","size":"395.8"},{"price":"0.93","size":"685.3"},{"price":"0.92","size":"656.9"},{"price":"0.91","size":"267.44"},{"price":"0.9","size":"812.8"},{"price":"0.89","size":"391.5"},{"price":"0.88","size":"308.5"},{"price":"0.87","size":"198.74"}],"hash":"5d0e84aa6798e6ae6be6e5d15fd8ca3ad2f6b558","timestamp":"1776808415667","event_type":"book"}}
{"capturedAt":1776808415,"payload":{"market":"0x125149c5918fc5f8c6d34682f700a898a1a19ea4f4e2ae68ff4c5794ba657074","price_changes":[{"asset_id":"45936375922793925919605092352922707796689801895417366600539442410775071099958","price":"0.86","size":"294.21","side":"BUY","hash":"37e85e042d30ac625cf8578ba6762dc98ef9e89c","best_bid":"0.86","best_ask":"0.87"},{"asset_id":"86520121088881862182423437128238697252500151785248183602134095101149900014256","price":"0.14","size":"294.21","side":"SELL","hash":"d37d82a4d2d30813cf7dbb4ab0a825d29a6cd2ef","best_bid":"0.13","best_ask":"0.14"}],"timestamp":"1776808415680","event_type":"price_change"}}
{"capturedAt":1776808415,"payload":{"market":"0x125149c5918fc5f8c6d34682f700a898a1a19ea4f4e2ae68ff4c5794ba657074","price_changes":[{"asset_id":"45936375922793925919605092352922707796689801895417366600539442410775071099958","price":"0.86","size":"301.21","side":"BUY","hash":"9c6cdcb110b4e5fb45b94c4ba45364f9a944c79f","best_bid":"0.86","best_ask":"0.87"},{"asset_id":"86520121088881862182423437128238697252500151785248183602134095101149900014256","price":"0.14","size":"301.21","side":"SELL","hash":"721cc455010ca2052bf9567ec9b8d9785fe5fc88","best_bid":"0.13","best_ask":"0.14"}],"timestamp":"1776808415693","event_type":"price_change"}}
{"capturedAt":1776808415,"payload":{"market":"0x125149c5918fc5f8c6d34682f700a898a1a19ea4f4e2ae68ff4c5794ba657074","price_changes":[{"asset_id":"45936375922793925919605092352922707796689801895417366600539442410775071099958","price":"0.86","size":"289.21","side":"BUY","hash":"55b6f176b7cc99164b041f690da121a13245cd91","best_bid":"0.86","best_ask":"0.87"},{"asset_id":"86520121088881862182423437128238697252500151785248183602134095101149900014256","price":"0.14","size":"289.21","side":"SELL","hash":"a85ad7b258a28a89d772f914991df6808c9eb787","best_bid":"0.13","best_ask":"0.14"}],"timestamp":"1776808415694","event_type":"price_change"}}
{"capturedAt":1776808415,"payload":{"market":"0x125149c5918fc5f8c6d34682f700a898a1a19ea4f4e2ae68ff4c5794ba657074","price_changes":[{"asset_id":"45936375922793925919605092352922707796689801895417366600539442410775071099958","price":"0.01","size":"12334.83","side":"BUY","hash":"221644d72e5c5aeced994a4aada2ab9737a3934f","best_bid":"0.86","best_ask":"0.87"},{"asset_id":"86520121088881862182423437128238697252500151785248183602134095101149900014256","price":"0.99","size":"12334.83","side":"SELL","hash":"0fe4ca0a295e8281fc390413ddea91907f179b67","best_bid":"0.13","best_ask":"0.14"}],"timestamp":"1776808415699","event_type":"price_change"}}
{"capturedAt":1776808415,"payload":{"market":"0x125149c5918fc5f8c6d34682f700a898a1a19ea4f4e2ae68ff4c5794ba657074","price_changes":[{"asset_id":"45936375922793925919605092352922707796689801895417366600539442410775071099958","price":"0.86","size":"309.21","side":"BUY","hash":"73c4ffc8c4b547412ae76677355970a1f666642e","best_bid":"0.86","best_ask":"0.87"},{"asset_id":"86520121088881862182423437128238697252500151785248183602134095101149900014256","price":"0.14","size":"309.21","side":"SELL","hash":"1956dd9e6ee630b7c7ce0953356d43dc5ce57229","best_bid":"0.13","best_ask":"0.14"}],"timestamp":"1776808415703","event_type":"price_change"}}
{"capturedAt":1776808415,"payload":{"market":"0x125149c5918fc5f8c6d34682f700a898a1a19ea4f4e2ae68ff4c5794ba657074","price_changes":[{"asset_id":"45936375922793925919605092352922707796689801895417366600539442410775071099958","price":"0.86","size":"331.21","side":"BUY","hash":"be8a9d207f53756b9dd64d203540d78e645d25e7","best_bid":"0.86","best_ask":"0.87"},{"asset_id":"86520121088881862182423437128238697252500151785248183602134095101149900014256","price":"0.14","size":"331.21","side":"SELL","hash":"87cd7abaa5a2b23e9807f28506a24c5e348be8f0","best_bid":"0.13","best_ask":"0.14"}],"timestamp":"1776808415704","event_type":"price_change"}}
{"capturedAt":1776808415,"payload":{"market":"0x125149c5918fc5f8c6d34682f700a898a1a19ea4f4e2ae68ff4c5794ba657074","price_changes":[{"asset_id":"45936375922793925919605092352922707796689801895417366600539442410775071099958","price":"0.86","size":"341.21","side":"BUY","hash":"022bab0099bcb89bd55529d86b34807ec66e6d65","best_bid":"0.86","best_ask":"0.87"},{"asset_id":"86520121088881862182423437128238697252500151785248183602134095101149900014256","price":"0.14","size":"341.21","side":"SELL","hash":"94af660d0da2c61bebb50a62d92416970cffb502","best_bid":"0.13","best_ask":"0.14"}],"timestamp":"1776808415705","event_type":"price_change"}}
{"capturedAt":1776808415,"payload":{"market":"0x125149c5918fc5f8c6d34682f700a898a1a19ea4f4e2ae68ff4c5794ba657074","price_changes":[{"asset_id":"45936375922793925919605092352922707796689801895417366600539442410775071099958","price":"0.86","size":"346.64","side":"BUY","hash":"db3fd7f92be65c78443812543fe8ca7bd71be962","best_bid":"0.86","best_ask":"0.87"},{"asset_id":"86520121088881862182423437128238697252500151785248183602134095101149900014256","price":"0.14","size":"346.64","side":"SELL","hash":"dd77f2d2c14a3644da14ec9b29c77f22edd93ece","best_bid":"0.13","best_ask":"0.14"}],"timestamp":"1776808415706","event_type":"price_change"}}
{"capturedAt":1776808415,"payload":{"market":"0x125149c5918fc5f8c6d34682f700a898a1a19ea4f4e2ae68ff4c5794ba657074","price_changes":[{"asset_id":"45936375922793925919605092352922707796689801895417366600539442410775071099958","price":"0.01","size":"12329.83","side":"BUY","hash":"4f06e783c28194f1886f0328eb65844d1691be97","best_bid":"0.86","best_ask":"0.87"},{"asset_id":"86520121088881862182423437128238697252500151785248183602134095101149900014256","price":"0.99","size":"12329.83","side":"SELL","hash":"59d63173e34ffcfb492d4bd094757b8ad80fbf7e","best_bid":"0.13","best_ask":"0.14"}],"timestamp":"1776808415707","event_type":"price_change"}}
{"capturedAt":1776808415,"payload":{"market":"0x125149c5918fc5f8c6d34682f700a898a1a19ea4f4e2ae68ff4c5794ba657074","price_changes":[{"asset_id":"45936375922793925919605092352922707796689801895417366600539442410775071099958","price":"0.86","size":"336.64","side":"BUY","hash":"6faa9e11b6e756055211a522565275f0ecce468a","best_bid":"0.86","best_ask":"0.87"},{"asset_id":"86520121088881862182423437128238697252500151785248183602134095101149900014256","price":"0.14","size":"336.64","side":"SELL","hash":"faa6fc79b9b21c5880bdd83e1a05caca6a4f34f0","best_bid":"0.13","best_ask":"0.14"}],"timestamp":"1776808415708","event_type":"price_change"}}
{"capturedAt":1776808415,"payload":{"market":"0x125149c5918fc5f8c6d34682f700a898a1a19ea4f4e2ae68ff4c5794ba657074","asset_id":"45936375922793925919605092352922707796689801895417366600539442410775071099958","price":"0.87","size":"4.551723","fee_rate_bps":"1000","side":"BUY","timestamp":"1776808415690","event_type":"last_trade_price","transaction_hash":"0xa350084d60b85aa2311a759add6364919e5fbb5b2e92e063ab8d6ca8ca3df2fe"}}
{"capturedAt":1776808415,"payload":{"market":"0x125149c5918fc5f8c6d34682f700a898a1a19ea4f4e2ae68ff4c5794ba657074","price_changes":[{"asset_id":"45936375922793925919605092352922707796689801895417366600539442410775071099958","price":"0.86","size":"348.64","side":"BUY","hash":"b1396e1885bec4917a4fa7f4a7bee42dffcb7074","best_bid":"0.86","best_ask":"0.87"},{"asset_id":"86520121088881862182423437128238697252500151785248183602134095101149900014256","price":"0.14","size":"348.64","side":"SELL","hash":"db1f7e8d76c652ba036c8ab3c92fc347397bf090","best_bid":"0.13","best_ask":"0.14"}],"timestamp":"1776808415726","event_type":"price_change"}}
{"capturedAt":1776808415,"payload":{"market":"0x125149c5918fc5f8c6d34682f700a898a1a19ea4f4e2ae68ff4c5794ba657074","asset_id":"45936375922793925919605092352922707796689801895417366600539442410775071099958","best_bid":"0.86","best_ask":"0.87","spread":"0.01","timestamp":"1776808415730","event_type":"best_bid_ask"}}
{"capturedAt":1776808415,"payload":{"market":"0x125149c5918fc5f8c6d34682f700a898a1a19ea4f4e2ae68ff4c5794ba657074","price_changes":[{"asset_id":"45936375922793925919605092352922707796689801895417366600539442410775071099958","price":"0.86","size":"348.27","side":"BUY","hash":"da75109c9e96713ad0886281e325130fcc501700","best_bid":"0.86","best_ask":"0.87"},{"asset_id":"86520121088881862182423437128238697252500151785248183602134095101149900014256","price":"0.14","size":"348.27","side":"SELL","hash":"08980b45829b63c65e3283ebf312ab12ef38805d","best_bid":"0.13","best_ask":"0.14"}],"timestamp":"1776808415729","event_type":"price_change"}}
{"capturedAt":1776808415,"payload":{"market":"0x125149c5918fc5f8c6d34682f700a898a1a19ea4f4e2ae68ff4c5794ba657074","asset_id":"86520121088881862182423437128238697252500151785248183602134095101149900014256","best_bid":"0.13","best_ask":"0.14","spread":"0.01","timestamp":"1776808415730","event_type":"best_bid_ask"}}
{"capturedAt":1776808415,"payload":{"market":"0x125149c5918fc5f8c6d34682f700a898a1a19ea4f4e2ae68ff4c5794ba657074","price_changes":[{"asset_id":"45936375922793925919605092352922707796689801895417366600539442410775071099958","price":"0.01","size":"12324.83","side":"BUY","hash":"cd8d4dfa1f989939ae4a8bb9b3aa5a35f86cba19","best_bid":"0.86","best_ask":"0.87"},{"asset_id":"86520121088881862182423437128238697252500151785248183602134095101149900014256","price":"0.99","size":"12324.83","side":"SELL","hash":"b4b6034f4dd5cdfa6671b8de4baf0c9b0f3b7afc","best_bid":"0.13","best_ask":"0.14"}],"timestamp":"1776808415730","event_type":"price_change"}}
{"capturedAt":1776808415,"payload":{"market":"0x125149c5918fc5f8c6d34682f700a898a1a19ea4f4e2ae68ff4c5794ba657074","price_changes":[{"asset_id":"45936375922793925919605092352922707796689801895417366600539442410775071099958","price":"0.86","size":"354.84","side":"BUY","hash":"ace4fe0792aec4316801330f017e2783db199925","best_bid":"0.86","best_ask":"0.87"},{"asset_id":"86520121088881862182423437128238697252500151785248183602134095101149900014256","price":"0.14","size":"354.84","side":"SELL","hash":"91f3906912f996a7eff69fed9b3fb54068fef4ab","best_bid":"0.13","best_ask":"0.14"}],"timestamp":"1776808415731","event_type":"price_change"}}
{"capturedAt":1776808415,"payload":{"market":"0x125149c5918fc5f8c6d34682f700a898a1a19ea4f4e2ae68ff4c5794ba657074","asset_id":"45936375922793925919605092352922707796689801895417366600539442410775071099958","bids":[{"price":"0.01","size":"12329.83"},{"price":"0.02","size":"1715.28"},{"price":"0.03","size":"1338.69"},{"price":"0.04","size":"583.84"},{"price":"0.05","size":"1006.34"},{"price":"0.06","size":"392.8"},{"price":"0.07","size":"304.69"},{"price":"0.08","size":"278.9"},{"price":"0.09","size":"225"},{"price":"0.1","size":"282"},{"price":"0.11","size":"217.79"},{"price":"0.12","size":"215.1"},{"price":"0.13","size":"202.8"},{"price":"0.14","size":"200.9"},{"price":"0.15","size":"209.2"},{"price":"0.16","size":"197.8"},{"price":"0.17","size":"202.39"},{"price":"0.18","size":"200.4"},{"price":"0.19","size":"194.4"},{"price":"0.2","size":"193.5"},{"price":"0.21","size":"215.31"},{"price":"0.22","size":"197"},{"price":"0.23","size":"229.34"},{"price":"0.24","size":"195.7"},{"price":"0.25","size":"190.2"},{"price":"0.26","size":"189.7"},{"price":"0.27","size":"194.3"},{"price":"0.28","size":"188.89"},{"price":"0.29","size":"188.5"},{"price":"0.3","size":"206.48"},{"price":"0.31","size":"394.45"},{"price":"0.32","size":"187.5"},{"price":"0.33","size":"193.55"},{"price":"0.34","size":"187"},{"price":"0.35","size":"602.68"},{"price":"0.36","size":"186.6"},{"price":"0.37","size":"191.96"},{"price":"0.38","size":"186.3"},{"price":"0.39","size":"491.36"},{"price":"0.4","size":"226"},{"price":"0.41","size":"203.32"},{"price":"0.42","size":"185.8"},{"price":"0.43","size":"190.8"},{"price":"0.44","size":"190.6"},{"price":"0.45","size":"230.58"},{"price":"0.46","size":"185.5"},{"price":"0.47","size":"245.86"},{"price":"0.48","size":"242.56"},{"price":"0.49","size":"222.4"},{"price":"0.5","size":"378.64"},{"price":"0.51","size":"205.25"},{"price":"0.52","size":"226.77"},{"price":"0.53","size":"136.71"},{"price":"0.54","size":"185.5"},{"price":"0.55","size":"207.66"},{"price":"0.56","size":"196.6"},{"price":"0.57","size":"180.7"},{"price":"0.58","size":"180.8"},{"price":"0.59","size":"180.9"},{"price":"0.6","size":"139"},{"price":"0.61","size":"185.46"},{"price":"0.62","size":"141.3"},{"price":"0.63","size":"131.4"},{"price":"0.64","size":"131.6"},{"price":"0.65","size":"136.8"},{"price":"0.66","size":"342"},{"price":"0.67","size":"232.3"},{"price":"0.68","size":"382.5"},{"price":"0.69","size":"182.8"},{"price":"0.7","size":"244.95"},{"price":"0.71","size":"405.5"},{"price":"0.72","size":"530.89"},{"price":"0.73","size":"217.3"},{"price":"0.74","size":"287.7"},{"price":"0.75","size":"382.29"},{"price":"0.76","size":"148.49"},{"price":"0.77","size":"221.3"},{"price":"0.78","size":"328.98"},{"price":"0.79","size":"219.7"},{"price":"0.8","size":"245.25"},{"price":"0.81","size":"304.9"},{"price":"0.82","size":"325.78"},{"price":"0.83","size":"347.49"},{"price":"0.84","size":"384.37"},{"price":"0.85","size":"437.28"},{"price":"0.86","size":"348.27"}],"asks":[{"price":"0.99","size":"12907.69"},{"price":"0.98","size":"1746.16"},{"price":"0.97","size":"1613.83"},{"price":"0.96","size":"938.3"},{"price":"0.95","size":"790.63"},{"price":"0.94","size":"426.8"},{"price":"0.93","size":"654.3"},{"price":"0.92","size":"656.9"},{"price":"0.91","size":"267.44"},{"price":"0.9","size":"812.8"},{"price":"0.89","size":"391.5"},{"price":"0.88","size":"308.5"},{"price":"0.87","size":"198.74"}],"hash":"da75109c9e96713ad0886281e325130fcc501700","timestamp":"1776808415729","event_type":"book"}}
{"capturedAt":1776808415,"payload":{"market":"0x125149c5918fc5f8c6d34682f700a898a1a19ea4f4e2ae68ff4c5794ba657074","price_changes":[{"asset_id":"45936375922793925919605092352922707796689801895417366600539442410775071099958","price":"0.86","size":"342.84","side":"BUY","hash":"42545c2f960e76626b3b969e4055fa80c8133dcf","best_bid":"0.86","best_ask":"0.87"},{"asset_id":"86520121088881862182423437128238697252500151785248183602134095101149900014256","price":"0.14","size":"342.84","side":"SELL","hash":"c38f9e362f62d4219166d4eee65dd692566ac499","best_bid":"0.13","best_ask":"0.14"}],"timestamp":"1776808415731","event_type":"price_change"}}
{"capturedAt":1776808415,"payload":{"market":"0x125149c5918fc5f8c6d34682f700a898a1a19ea4f4e2ae68ff4c5794ba657074","price_changes":[{"asset_id":"45936375922793925919605092352922707796689801895417366600539442410775071099958","price":"0.86","size":"312.84","side":"BUY","hash":"1725e2fc6855658ed9886708974b9124753d5db1","best_bid":"0.86","best_ask":"0.87"},{"asset_id":"86520121088881862182423437128238697252500151785248183602134095101149900014256","price":"0.14","size":"312.84","side":"SELL","hash":"eb58457515dc03bd9aca2e4d0f2bab798ec1f660","best_bid":"0.13","best_ask":"0.14"}],"timestamp":"1776808415733","event_type":"price_change"}}
{"capturedAt":1776808415,"payload":{"market":"0x125149c5918fc5f8c6d34682f700a898a1a19ea4f4e2ae68ff4c5794ba657074","price_changes":[{"asset_id":"45936375922793925919605092352922707796689801895417366600539442410775071099958","price":"0.86","size":"332.84","side":"BUY","hash":"64590066b3688dceebfa29feaadd9957adb397e2","best_bid":"0.86","best_ask":"0.87"},{"asset_id":"86520121088881862182423437128238697252500151785248183602134095101149900014256","price":"0.14","size":"332.84","side":"SELL","hash":"b8a1b9e25fe4338ac7dcbc12378cad27f67ecb73","best_bid":"0.13","best_ask":"0.14"}],"timestamp":"1776808415732","event_type":"price_change"}}
{"capturedAt":1776808415,"payload":{"market":"0x125149c5918fc5f8c6d34682f700a898a1a19ea4f4e2ae68ff4c5794ba657074","asset_id":"86520121088881862182423437128238697252500151785248183602134095101149900014256","bids":[{"price":"0.01","size":"12907.69"},{"price":"0.02","size":"1746.16"},{"price":"0.03","size":"1613.83"},{"price":"0.04","size":"938.3"},{"price":"0.05","size":"790.63"},{"price":"0.06","size":"426.8"},{"price":"0.07","size":"654.3"},{"price":"0.08","size":"656.9"},{"price":"0.09","size":"267.44"},{"price":"0.1","size":"812.8"},{"price":"0.11","size":"391.5"},{"price":"0.12","size":"308.5"},{"price":"0.13","size":"198.74"}],"asks":[{"price":"0.99","size":"12329.83"},{"price":"0.98","size":"1715.28"},{"price":"0.97","size":"1338.69"},{"price":"0.96","size":"583.84"},{"price":"0.95","size":"1006.34"},{"price":"0.94","size":"392.8"},{"price":"0.93","size":"304.69"},{"price":"0.92","size":"278.9"},{"price":"0.91","size":"225"},{"price":"0.9","size":"282"},{"price":"0.89","size":"217.79"},{"price":"0.88","size":"215.1"},{"price":"0.87","size":"202.8"},{"price":"0.86","size":"200.9"},{"price":"0.85","size":"209.2"},{"price":"0.84","size":"197.8"},{"price":"0.83","size":"202.39"},{"price":"0.82","size":"200.4"},{"price":"0.81","size":"194.4"},{"price":"0.8","size":"193.5"},{"price":"0.79","size":"215.31"},{"price":"0.78","size":"197"},{"price":"0.77","size":"229.34"},{"price":"0.76","size":"195.7"},{"price":"0.75","size":"190.2"},{"price":"0.74","size":"189.7"},{"price":"0.73","size":"194.3"},{"price":"0.72","size":"188.89"},{"price":"0.71","size":"188.5"},{"price":"0.7","size":"206.48"},{"price":"0.69","size":"394.45"},{"price":"0.68","size":"187.5"},{"price":"0.67","size":"193.55"},{"price":"0.66","size":"187"},{"price":"0.65","size":"602.68"},{"price":"0.64","size":"186.6"},{"price":"0.63","size":"191.96"},{"price":"0.62","size":"186.3"},{"price":"0.61","size":"491.36"},{"price":"0.6","size":"226"},{"price":"0.59","size":"203.32"},{"price":"0.58","size":"185.8"},{"price":"0.57","size":"190.8"},{"price":"0.56","size":"190.6"},{"price":"0.55","size":"230.58"},{"price":"0.54","size":"185.5"},{"price":"0.53","size":"245.86"},{"price":"0.52","size":"242.56"},{"price":"0.51","size":"222.4"},{"price":"0.5","size":"378.64"},{"price":"0.49","size":"205.25"},{"price":"0.48","size":"226.77"},{"price":"0.47","size":"136.71"},{"price":"0.46","size":"185.5"},{"price":"0.45","size":"207.66"},{"price":"0.44","size":"196.6"},{"price":"0.43","size":"180.7"},{"price":"0.42","size":"180.8"},{"price":"0.41","size":"180.9"},{"price":"0.4","size":"139"},{"price":"0.39","size":"185.46"},{"price":"0.38","size":"141.3"},{"price":"0.37","size":"131.4"},{"price":"0.36","size":"131.6"},{"price":"0.35","size":"136.8"},{"price":"0.34","size":"342"},{"price":"0.33","size":"232.3"},{"price":"0.32","size":"382.5"},{"price":"0.31","size":"182.8"},{"price":"0.3","size":"244.95"},{"price":"0.29","size":"405.5"},{"price":"0.28","size":"530.89"},{"price":"0.27","size":"217.3"},{"price":"0.26","size":"287.7"},{"price":"0.25","size":"382.29"},{"price":"0.24","size":"148.49"},{"price":"0.23","size":"221.3"},{"price":"0.22","size":"328.98"},{"price":"0.21","size":"219.7"},{"price":"0.2","size":"245.25"},{"price":"0.19","size":"304.9"},{"price":"0.18","size":"325.78"},{"price":"0.17","size":"347.49"},{"price":"0.16","size":"384.37"},{"price":"0.15","size":"437.28"},{"price":"0.14","size":"348.27"}],"hash":"08980b45829b63c65e3283ebf312ab12ef38805d","timestamp":"1776808415729","event_type":"book"}}
{"capturedAt":1776808415,"payload":{"market":"0x125149c5918fc5f8c6d34682f700a898a1a19ea4f4e2ae68ff4c5794ba657074","price_changes":[{"asset_id":"45936375922793925919605092352922707796689801895417366600539442410775071099958","price":"0.86","size":"302.84","side":"BUY","hash":"fe4c598e0f1f2516c3132a29182919db3e25a0b1","best_bid":"0.86","best_ask":"0.87"},{"asset_id":"86520121088881862182423437128238697252500151785248183602134095101149900014256","price":"0.14","size":"302.84","side":"SELL","hash":"c1e42e9f0802c44b0c36142c5cbd7e1b290251e2","best_bid":"0.13","best_ask":"0.14"}],"timestamp":"1776808415736","event_type":"price_change"}}
{"capturedAt":1776808415,"payload":{"market":"0x125149c5918fc5f8c6d34682f700a898a1a19ea4f4e2ae68ff4c5794ba657074","price_changes":[{"asset_id":"45936375922793925919605092352922707796689801895417366600539442410775071099958","price":"0.01","size":"12329.84","side":"BUY","hash":"d461205427a9fc2bfbfb16bd4d68280482524c01","best_bid":"0.86","best_ask":"0.87"},{"asset_id":"86520121088881862182423437128238697252500151785248183602134095101149900014256","price":"0.99","size":"12329.84","side":"SELL","hash":"a0dfef83f1353f9f3d214d9ff3068d6548ffcf4e","best_bid":"0.13","best_ask":"0.14"}],"timestamp":"1776808415737","event_type":"price_change"}}
{"capturedAt":1776808415,"payload":{"market":"0x125149c5918fc5f8c6d34682f700a898a1a19ea4f4e2ae68ff4c5794ba657074","price_changes":[{"asset_id":"45936375922793925919605092352922707796689801895417366600539442410775071099958","price":"0.01","size":"12334.84","side":"BUY","hash":"9ae16aa16201834b9e139e91177aaf33dc73c65b","best_bid":"0.86","best_ask":"0.87"},{"asset_id":"86520121088881862182423437128238697252500151785248183602134095101149900014256","price":"0.99","size":"12334.84","side":"SELL","hash":"300f2c56dcb67efb7a04cc31a940948ba5ed6919","best_bid":"0.13","best_ask":"0.14"}],"timestamp":"1776808415739","event_type":"price_change"}}
{"capturedAt":1776808415,"payload":{"market":"0x125149c5918fc5f8c6d34682f700a898a1a19ea4f4e2ae68ff4c5794ba657074","price_changes":[{"asset_id":"45936375922793925919605092352922707796689801895417366600539442410775071099958","price":"0.86","size":"283.84","side":"BUY","hash":"0d519723ca73c5fafb30e2cb700a551dae1b1e34","best_bid":"0.86","best_ask":"0.87"},{"asset_id":"86520121088881862182423437128238697252500151785248183602134095101149900014256","price":"0.14","size":"283.84","side":"SELL","hash":"07166c4ab7f4bfb975b58d81b2652504f3fec616","best_bid":"0.13","best_ask":"0.14"}],"timestamp":"1776808415741","event_type":"price_change"}}
{"capturedAt":1776808415,"payload":{"market":"0x125149c5918fc5f8c6d34682f700a898a1a19ea4f4e2ae68ff4c5794ba657074","price_changes":[{"asset_id":"45936375922793925919605092352922707796689801895417366600539442410775071099958","price":"0.86","size":"264.84","side":"BUY","hash":"3e55fda73f56a7c915162964b27f7de5cbb3fd47","best_bid":"0.86","best_ask":"0.87"},{"asset_id":"86520121088881862182423437128238697252500151785248183602134095101149900014256","price":"0.14","size":"264.84","side":"SELL","hash":"f5c2146dc2a64baf7da9f822a989e3a12ee09de3","best_bid":"0.13","best_ask":"0.14"}],"timestamp":"1776808415743","event_type":"price_change"}}
{"capturedAt":1776808415,"payload":{"market":"0x125149c5918fc5f8c6d34682f700a898a1a19ea4f4e2ae68ff4c5794ba657074","price_changes":[{"asset_id":"45936375922793925919605092352922707796689801895417366600539442410775071099958","price":"0.86","size":"245.84","side":"BUY","hash":"70fc0119b195457ce220506a55aa2f412c6feeb6","best_bid":"0.86","best_ask":"0.87"},{"asset_id":"86520121088881862182423437128238697252500151785248183602134095101149900014256","price":"0.14","size":"245.84","side":"SELL","hash":"809ac6598f17257c03ddba3dcdbb9fbe1ee12b37","best_bid":"0.13","best_ask":"0.14"}],"timestamp":"1776808415744","event_type":"price_change"}}
{"capturedAt":1776808415,"payload":{"market":"0x125149c5918fc5f8c6d34682f700a898a1a19ea4f4e2ae68ff4c5794ba657074","price_changes":[{"asset_id":"45936375922793925919605092352922707796689801895417366600539442410775071099958","price":"0.86","size":"226.84","side":"BUY","hash":"dbf3bac8415052ca3c83d1ce2d70194caae8a19a","best_bid":"0.86","best_ask":"0.87"},{"asset_id":"86520121088881862182423437128238697252500151785248183602134095101149900014256","price":"0.14","size":"226.84","side":"SELL","hash":"42c25afb57f171468da05647113834c55b9d2b05","best_bid":"0.13","best_ask":"0.14"}],"timestamp":"1776808415745","event_type":"price_change"}}
{"capturedAt":1776808415,"payload":{"market":"0x125149c5918fc5f8c6d34682f700a898a1a19ea4f4e2ae68ff4c5794ba657074","price_changes":[{"asset_id":"45936375922793925919605092352922707796689801895417366600539442410775071099958","price":"0.86","size":"232.2","side":"BUY","hash":"918596541c52654136fbd83a9e763ab24d64152c","best_bid":"0.86","best_ask":"0.87"},{"asset_id":"86520121088881862182423437128238697252500151785248183602134095101149900014256","price":"0.14","size":"232.2","side":"SELL","hash":"dc02211d8ec52d2618d47c6d021e5feb9c8ccae2","best_bid":"0.13","best_ask":"0.14"}],"timestamp":"1776808415750","event_type":"price_change"}}
{"capturedAt":1776808415,"payload":{"market":"0x125149c5918fc5f8c6d34682f700a898a1a19ea4f4e2ae68ff4c5794ba657074","asset_id":"45936375922793925919605092352922707796689801895417366600539442410775071099958","price":"0.86","size":"0.37","fee_rate_bps":"1000","side":"SELL","timestamp":"1776808415750","event_type":"last_trade_price","transaction_hash":"0xf8e83fcac3ab3f9f053ac096667a288e61e47167e2d3ef0ef6e2d6c3942d619b"}}
{"capturedAt":1776808415,"payload":{"market":"0x125149c5918fc5f8c6d34682f700a898a1a19ea4f4e2ae68ff4c5794ba657074","price_changes":[{"asset_id":"45936375922793925919605092352922707796689801895417366600539442410775071099958","price":"0.01","size":"12339.84","side":"BUY","hash":"26ec2ec4770b8d49b9150056135d2977b288b730","best_bid":"0.86","best_ask":"0.87"},{"asset_id":"86520121088881862182423437128238697252500151785248183602134095101149900014256","price":"0.99","size":"12339.84","side":"SELL","hash":"6a6676c20299b02c853e70fff577959ec9ff0eba","best_bid":"0.13","best_ask":"0.14"}],"timestamp":"1776808415753","event_type":"price_change"}}
{"capturedAt":1776808415,"payload":{"market":"0x125149c5918fc5f8c6d34682f700a898a1a19ea4f4e2ae68ff4c5794ba657074","price_changes":[{"asset_id":"45936375922793925919605092352922707796689801895417366600539442410775071099958","price":"0.86","size":"213.2","side":"BUY","hash":"f80a2fab44caedf92904acf53f8ae94a602afe0b","best_bid":"0.86","best_ask":"0.87"},{"asset_id":"86520121088881862182423437128238697252500151785248183602134095101149900014256","price":"0.14","size":"213.2","side":"SELL","hash":"92e0cf2cb5d919de13ad21a0d85761526d38f929","best_bid":"0.13","best_ask":"0.14"}],"timestamp":"1776808415753","event_type":"price_change"}}
{"capturedAt":1776808415,"payload":{"market":"0x125149c5918fc5f8c6d34682f700a898a1a19ea4f4e2ae68ff4c5794ba657074","price_changes":[{"asset_id":"45936375922793925919605092352922707796689801895417366600539442410775071099958","price":"0.86","size":"237.2","side":"BUY","hash":"73214237e0bf6dd9a58930ea4a68f1448d2d4dea","best_bid":"0.86","best_ask":"0.87"},{"asset_id":"86520121088881862182423437128238697252500151785248183602134095101149900014256","price":"0.14","size":"237.2","side":"SELL","hash":"a85c8d6a2acc310ea35fc9e5447743cf95e34d5d","best_bid":"0.13","best_ask":"0.14"}],"timestamp":"1776808415759","event_type":"price_change"}}
{"capturedAt":1776808415,"payload":{"market":"0x125149c5918fc5f8c6d34682f700a898a1a19ea4f4e2ae68ff4c5794ba657074","price_changes":[{"asset_id":"45936375922793925919605092352922707796689801895417366600539442410775071099958","price":"0.86","size":"247.2","side":"BUY","hash":"87e8bfa4beaf9b16e3407921898e859ac3b47830","best_bid":"0.86","best_ask":"0.87"},{"asset_id":"86520121088881862182423437128238697252500151785248183602134095101149900014256","price":"0.14","size":"247.2","side":"SELL","hash":"fa2ee419d26ba4c9d47f4398ed1cd9ff57eb5a74","best_bid":"0.13","best_ask":"0.14"}],"timestamp":"1776808415761","event_type":"price_change"}}
{"capturedAt":1776808415,"payload":{"market":"0x125149c5918fc5f8c6d34682f700a898a1a19ea4f4e2ae68ff4c5794ba657074","price_changes":[{"asset_id":"45936375922793925919605092352922707796689801895417366600539442410775071099958","price":"0.01","size":"12334.84","side":"BUY","hash":"d6b4aa91309257b2ddf3605ac8fd07dc132198a2","best_bid":"0.86","best_ask":"0.87"},{"asset_id":"86520121088881862182423437128238697252500151785248183602134095101149900014256","price":"0.99","size":"12334.84","side":"SELL","hash":"b28401eea7b219d8f6f27eb40ad09c1080a10706","best_bid":"0.13","best_ask":"0.14"}],"timestamp":"1776808415760","event_type":"price_change"}}
{"capturedAt":1776808415,"payload":{"market":"0x125149c5918fc5f8c6d34682f700a898a1a19ea4f4e2ae68ff4c5794ba657074","price_changes":[{"asset_id":"45936375922793925919605092352922707796689801895417366600539442410775071099958","price":"0.01","size":"12329.83","side":"BUY","hash":"1b367a3b4c141ef29f435472b7cb11df2c3472a8","best_bid":"0.86","best_ask":"0.87"},{"asset_id":"86520121088881862182423437128238697252500151785248183602134095101149900014256","price":"0.99","size":"12329.83","side":"SELL","hash":"3656a8642e4ff77d8c3b878db6fc0e95b3f1f4fe","best_bid":"0.13","best_ask":"0.14"}],"timestamp":"1776808415763","event_type":"price_change"}}
{"capturedAt":1776808415,"payload":{"market":"0x125149c5918fc5f8c6d34682f700a898a1a19ea4f4e2ae68ff4c5794ba657074","price_changes":[{"asset_id":"45936375922793925919605092352922707796689801895417366600539442410775071099958","price":"0.86","size":"271.2","side":"BUY","hash":"8256f2101484839068d26797241551fb1ab4b0a8","best_bid":"0.86","best_ask":"0.87"},{"asset_id":"86520121088881862182423437128238697252500151785248183602134095101149900014256","price":"0.14","size":"271.2","side":"SELL","hash":"981ec6e4dd8bca2226b53121291301223adcb29e","best_bid":"0.13","best_ask":"0.14"}],"timestamp":"1776808415764","event_type":"price_change"}}
{"capturedAt":1776808415,"payload":{"market":"0x125149c5918fc5f8c6d34682f700a898a1a19ea4f4e2ae68ff4c5794ba657074","price_changes":[{"asset_id":"45936375922793925919605092352922707796689801895417366600539442410775071099958","price":"0.86","size":"281.2","side":"BUY","hash":"9670825a13b06a5935e0972ff616e8a948ac06a0","best_bid":"0.86","best_ask":"0.87"},{"asset_id":"86520121088881862182423437128238697252500151785248183602134095101149900014256","price":"0.14","size":"281.2","side":"SELL","hash":"f426340e94fa78d3ef14d57f7885a53af659dc65","best_bid":"0.13","best_ask":"0.14"}],"timestamp":"1776808415765","event_type":"price_change"}}
{"capturedAt":1776808415,"payload":{"market":"0x125149c5918fc5f8c6d34682f700a898a1a19ea4f4e2ae68ff4c5794ba657074","price_changes":[{"asset_id":"45936375922793925919605092352922707796689801895417366600539442410775071099958","price":"0.01","size":"12334.84","side":"BUY","hash":"14d3adb4643bf82883e0c225b96ac80a39cb5269","best_bid":"0.86","best_ask":"0.87"},{"asset_id":"86520121088881862182423437128238697252500151785248183602134095101149900014256","price":"0.99","size":"12334.84","side":"SELL","hash":"7770046f4e6221b7cd8e2946c4f9a82a2d3a0888","best_bid":"0.13","best_ask":"0.14"}],"timestamp":"1776808415769","event_type":"price_change"}}
{"capturedAt":1776808415,"payload":{"market":"0x125149c5918fc5f8c6d34682f700a898a1a19ea4f4e2ae68ff4c5794ba657074","price_changes":[{"asset_id":"45936375922793925919605092352922707796689801895417366600539442410775071099958","price":"0.86","size":"304.2","side":"BUY","hash":"9197770d05cc128022adbbf8a9db072912400d77","best_bid":"0.86","best_ask":"0.87"},{"asset_id":"86520121088881862182423437128238697252500151785248183602134095101149900014256","price":"0.14","size":"304.2","side":"SELL","hash":"8a9f7235ace9ffabbdaa30663018e42b62154000","best_bid":"0.13","best_ask":"0.14"}],"timestamp":"1776808415771","event_type":"price_change"}}
{"capturedAt":1776808415,"payload":{"market":"0x125149c5918fc5f8c6d34682f700a898a1a19ea4f4e2ae68ff4c5794ba657074","price_changes":[{"asset_id":"45936375922793925919605092352922707796689801895417366600539442410775071099958","price":"0.86","size":"327.2","side":"BUY","hash":"b3bb50f7b835c6823523bf4c54d63bb0548ae333","best_bid":"0.86","best_ask":"0.87"},{"asset_id":"86520121088881862182423437128238697252500151785248183602134095101149900014256","price":"0.14","size":"327.2","side":"SELL","hash":"79361ad67fdc2f8f3b21e13dd6909e067b08e6aa","best_bid":"0.13","best_ask":"0.14"}],"timestamp":"1776808415773","event_type":"price_change"}}
{"capturedAt":1776808415,"payload":{"market":"0x125149c5918fc5f8c6d34682f700a898a1a19ea4f4e2ae68ff4c5794ba657074","price_changes":[{"asset_id":"45936375922793925919605092352922707796689801895417366600539442410775071099958","price":"0.86","size":"307.2","side":"BUY","hash":"e40670dd605afcbea6d949e236e6b269c6cae504","best_bid":"0.86","best_ask":"0.87"},{"asset_id":"86520121088881862182423437128238697252500151785248183602134095101149900014256","price":"0.14","size":"307.2","side":"SELL","hash":"4dea561a506aae88598a476880572e379d00c09a","best_bid":"0.13","best_ask":"0.14"}],"timestamp":"1776808415773","event_type":"price_change"}}
{"capturedAt":1776808415,"payload":{"market":"0x125149c5918fc5f8c6d34682f700a898a1a19ea4f4e2ae68ff4c5794ba657074","price_changes":[{"asset_id":"45936375922793925919605092352922707796689801895417366600539442410775071099958","price":"0.01","size":"12329.84","side":"BUY","hash":"166fd01df34dd76ee6ae6b0a0f419d257163cdd9","best_bid":"0.86","best_ask":"0.87"},{"asset_id":"86520121088881862182423437128238697252500151785248183602134095101149900014256","price":"0.99","size":"12329.84","side":"SELL","hash":"8b6247fc2d3742c4c6ee79d1c2f41f4b1f055109","best_bid":"0.13","best_ask":"0.14"}],"timestamp":"1776808415774","event_type":"price_change"}}
{"capturedAt":1776808415,"payload":{"market":"0x125149c5918fc5f8c6d34682f700a898a1a19ea4f4e2ae68ff4c5794ba657074","price_changes":[{"asset_id":"45936375922793925919605092352922707796689801895417366600539442410775071099958","price":"0.86","size":"330.2","side":"BUY","hash":"47c350f58a86c3448de6e657cecdb192d36653c6","best_bid":"0.86","best_ask":"0.87"},{"asset_id":"86520121088881862182423437128238697252500151785248183602134095101149900014256","price":"0.14","size":"330.2","side":"SELL","hash":"bb57cf4878b10a735fe170969cff339caa37f1f4","best_bid":"0.13","best_ask":"0.14"}],"timestamp":"1776808415775","event_type":"price_change"}}
{"capturedAt":1776808415,"payload":{"market":"0x125149c5918fc5f8c6d34682f700a898a1a19ea4f4e2ae68ff4c5794ba657074","price_changes":[{"asset_id":"45936375922793925919605092352922707796689801895417366600539442410775071099958","price":"0.86","size":"353.2","side":"BUY","hash":"2ce66c248950fcff7925a79ad1cbc5d3f9cae87b","best_bid":"0.86","best_ask":"0.87"},{"asset_id":"86520121088881862182423437128238697252500151785248183602134095101149900014256","price":"0.14","size":"353.2","side":"SELL","hash":"6444260febe4ddf8738fc2a8cac620072e721cda","best_bid":"0.13","best_ask":"0.14"}],"timestamp":"1776808415776","event_type":"price_change"}}
{"capturedAt":1776808415,"payload":{"market":"0x125149c5918fc5f8c6d34682f700a898a1a19ea4f4e2ae68ff4c5794ba657074","price_changes":[{"asset_id":"45936375922793925919605092352922707796689801895417366600539442410775071099958","price":"0.86","size":"331.2","side":"BUY","hash":"da47df3dddbc96f4c5d41dd9fc79ecfe2a6d51c8","best_bid":"0.86","best_ask":"0.87"},{"asset_id":"86520121088881862182423437128238697252500151785248183602134095101149900014256","price":"0.14","size":"331.2","side":"SELL","hash":"2868f267a283214687d9f302ab1142f455f4d40d","best_bid":"0.13","best_ask":"0.14"}],"timestamp":"1776808415778","event_type":"price_change"}}
{"capturedAt":1776808415,"payload":{"market":"0x125149c5918fc5f8c6d34682f700a898a1a19ea4f4e2ae68ff4c5794ba657074","price_changes":[{"asset_id":"45936375922793925919605092352922707796689801895417366600539442410775071099958","price":"0.86","size":"325.84","side":"BUY","hash":"8eb5e4b94f1a788362d8da026784c956f2ab1ea4","best_bid":"0.86","best_ask":"0.87"},{"asset_id":"86520121088881862182423437128238697252500151785248183602134095101149900014256","price":"0.14","size":"325.84","side":"SELL","hash":"13b34295950d7addb4bdb43e93bf546e11433415","best_bid":"0.13","best_ask":"0.14"}],"timestamp":"1776808415779","event_type":"price_change"}}
{"capturedAt":1776808415,"payload":{"market":"0x125149c5918fc5f8c6d34682f700a898a1a19ea4f4e2ae68ff4c5794ba657074","price_changes":[{"asset_id":"45936375922793925919605092352922707796689801895417366600539442410775071099958","price":"0.86","size":"315.84","side":"BUY","hash":"ee1c330ddb44b4271efea38487fed84068862556","best_bid":"0.86","best_ask":"0.87"},{"asset_id":"86520121088881862182423437128238697252500151785248183602134095101149900014256","price":"0.14","size":"315.84","side":"SELL","hash":"5c26092d4a5c6dff6a31f5e0fef2feae33f96af7","best_bid":"0.13","best_ask":"0.14"}],"timestamp":"1776808415781","event_type":"price_change"}}
{"capturedAt":1776808415,"payload":{"market":"0x125149c5918fc5f8c6d34682f700a898a1a19ea4f4e2ae68ff4c5794ba657074","price_changes":[{"asset_id":"45936375922793925919605092352922707796689801895417366600539442410775071099958","price":"0.86","size":"337.84","side":"BUY","hash":"046ce27e95d859489f1804ee31a8f4da9ee98fcb","best_bid":"0.86","best_ask":"0.87"},{"asset_id":"86520121088881862182423437128238697252500151785248183602134095101149900014256","price":"0.14","size":"337.84","side":"SELL","hash":"33cc042ca4e05dc956db9cb76e4f30489e0bda49","best_bid":"0.13","best_ask":"0.14"}],"timestamp":"1776808415782","event_type":"price_change"}}
{"capturedAt":1776808415,"payload":{"market":"0x125149c5918fc5f8c6d34682f700a898a1a19ea4f4e2ae68ff4c5794ba657074","price_changes":[{"asset_id":"45936375922793925919605092352922707796689801895417366600539442410775071099958","price":"0.01","size":"12334.84","side":"BUY","hash":"ff4f31b11a939fa13e406e0cc7aaa9a4ae1fe5d0","best_bid":"0.86","best_ask":"0.87"},{"asset_id":"86520121088881862182423437128238697252500151785248183602134095101149900014256","price":"0.99","size":"12334.84","side":"SELL","hash":"8376af3e076ac274589c29ffd7637b1dae347526","best_bid":"0.13","best_ask":"0.14"}],"timestamp":"1776808415788","event_type":"price_change"}}
{"capturedAt":1776808415,"payload":{"market":"0x125149c5918fc5f8c6d34682f700a898a1a19ea4f4e2ae68ff4c5794ba657074","price_changes":[{"asset_id":"45936375922793925919605092352922707796689801895417366600539442410775071099958","price":"0.86","size":"325.84","side":"BUY","hash":"06ffa5391793b75918876703af2b8d80a64e7172","best_bid":"0.86","best_ask":"0.87"},{"asset_id":"86520121088881862182423437128238697252500151785248183602134095101149900014256","price":"0.14","size":"325.84","side":"SELL","hash":"f82894bef8c5ea409a6f89aa30acc0110f9493db","best_bid":"0.13","best_ask":"0.14"}],"timestamp":"1776808415795","event_type":"price_change"}}
{"capturedAt":1776808415,"payload":{"market":"0x125149c5918fc5f8c6d34682f700a898a1a19ea4f4e2ae68ff4c5794ba657074","price_changes":[{"asset_id":"45936375922793925919605092352922707796689801895417366600539442410775071099958","price":"0.01","size":"12339.84","side":"BUY","hash":"13d7ef81ab0b10f2350999353bf7cb4eac840367","best_bid":"0.86","best_ask":"0.87"},{"asset_id":"86520121088881862182423437128238697252500151785248183602134095101149900014256","price":"0.99","size":"12339.84","side":"SELL","hash":"bb186fa9924d8fc55bddb6827ac380dccdf7fef2","best_bid":"0.13","best_ask":"0.14"}],"timestamp":"1776808415800","event_type":"price_change"}}
{"capturedAt":1776808415,"payload":{"market":"0x125149c5918fc5f8c6d34682f700a898a1a19ea4f4e2ae68ff4c5794ba657074","price_changes":[{"asset_id":"45936375922793925919605092352922707796689801895417366600539442410775071099958","price":"0.86","size":"313.84","side":"BUY","hash":"899f3595a0a06037a5db83307dec0011af683b1d","best_bid":"0.86","best_ask":"0.87"},{"asset_id":"86520121088881862182423437128238697252500151785248183602134095101149900014256","price":"0.14","size":"313.84","side":"SELL","hash":"ce531a5ee8301a80e26f8214c82c3a15830e2afe","best_bid":"0.13","best_ask":"0.14"}],"timestamp":"1776808415801","event_type":"price_change"}}
{"capturedAt":1776808415,"payload":{"market":"0x125149c5918fc5f8c6d34682f700a898a1a19ea4f4e2ae68ff4c5794ba657074","price_changes":[{"asset_id":"45936375922793925919605092352922707796689801895417366600539442410775071099958","price":"0.86","size":"337.84","side":"BUY","hash":"5bebec5e0bb3fb92488cc0b12da59222866f206c","best_bid":"0.86","best_ask":"0.87"},{"asset_id":"86520121088881862182423437128238697252500151785248183602134095101149900014256","price":"0.14","size":"337.84","side":"SELL","hash":"69fce9140aff1725006d84b13cd88e0f6e6d0c87","best_bid":"0.13","best_ask":"0.14"}],"timestamp":"1776808415803","event_type":"price_change"}}
{"capturedAt":1776808415,"payload":{"market":"0x125149c5918fc5f8c6d34682f700a898a1a19ea4f4e2ae68ff4c5794ba657074","price_changes":[{"asset_id":"45936375922793925919605092352922707796689801895417366600539442410775071099958","price":"0.86","size":"362.84","side":"BUY","hash":"52fea8a9fe8a4c3af25154bcb1ca9e4d1a500ef5","best_bid":"0.86","best_ask":"0.87"},{"asset_id":"86520121088881862182423437128238697252500151785248183602134095101149900014256","price":"0.14","size":"362.84","side":"SELL","hash":"5d5cd39dc894b174d596ef4eb70c9c0ea852ec69","best_bid":"0.13","best_ask":"0.14"}],"timestamp":"1776808415805","event_type":"price_change"}}
{"capturedAt":1776808415,"payload":{"market":"0x125149c5918fc5f8c6d34682f700a898a1a19ea4f4e2ae68ff4c5794ba657074","price_changes":[{"asset_id":"45936375922793925919605092352922707796689801895417366600539442410775071099958","price":"0.01","size":"12334.83","side":"BUY","hash":"e5a118c8bd1d0cf020ebc7b9efbce86141a033a8","best_bid":"0.86","best_ask":"0.87"},{"asset_id":"86520121088881862182423437128238697252500151785248183602134095101149900014256","price":"0.99","size":"12334.83","side":"SELL","hash":"f58ca9312f0d806143aada9b5ad3fae03ab9c3c3","best_bid":"0.13","best_ask":"0.14"}],"timestamp":"1776808415805","event_type":"price_change"}}
{"capturedAt":1776808415,"payload":{"market":"0x125149c5918fc5f8c6d34682f700a898a1a19ea4f4e2ae68ff4c5794ba657074","price_changes":[{"asset_id":"45936375922793925919605092352922707796689801895417366600539442410775071099958","price":"0.86","size":"368.19","side":"BUY","hash":"2ba6385634a89b9bb39895b0ba39fa7f31013935","best_bid":"0.86","best_ask":"0.87"},{"asset_id":"86520121088881862182423437128238697252500151785248183602134095101149900014256","price":"0.14","size":"368.19","side":"SELL","hash":"e200a9604d807af56896e401b67dfd6d3d95511f","best_bid":"0.13","best_ask":"0.14"}],"timestamp":"1776808415807","event_type":"price_change"}}
{"capturedAt":1776808415,"payload":{"market":"0x125149c5918fc5f8c6d34682f700a898a1a19ea4f4e2ae68ff4c5794ba657074","price_changes":[{"asset_id":"45936375922793925919605092352922707796689801895417366600539442410775071099958","price":"0.01","size":"12329.83","side":"BUY","hash":"1d9b2f69167d6dfe18f4976b0a104b6836e12c62","best_bid":"0.86","best_ask":"0.87"},{"asset_id":"86520121088881862182423437128238697252500151785248183602134095101149900014256","price":"0.99","size":"12329.83","side":"SELL","hash":"fe88086bcd6bd32667a1927be2d625c4af9582ee","best_bid":"0.13","best_ask":"0.14"}],"timestamp":"1776808415807","event_type":"price_change"}}
{"capturedAt":1776808415,"payload":{"market":"0x125149c5918fc5f8c6d34682f700a898a1a19ea4f4e2ae68ff4c5794ba657074","price_changes":[{"asset_id":"45936375922793925919605092352922707796689801895417366600539442410775071099958","price":"0.86","size":"378.19","side":"BUY","hash":"7d7d5bd8349417d3c5c6c82063da8ee801bf00d2","best_bid":"0.86","best_ask":"0.87"},{"asset_id":"86520121088881862182423437128238697252500151785248183602134095101149900014256","price":"0.14","size":"378.19","side":"SELL","hash":"23cf6cf45cbd32280d5295b6fdc3507086a13dfa","best_bid":"0.13","best_ask":"0.14"}],"timestamp":"1776808415808","event_type":"price_change"}}
{"capturedAt":1776808415,"payload":{"market":"0x125149c5918fc5f8c6d34682f700a898a1a19ea4f4e2ae68ff4c5794ba657074","price_changes":[{"asset_id":"45936375922793925919605092352922707796689801895417366600539442410775071099958","price":"0.85","size":"457.28","side":"BUY","hash":"12b3a70350a473353efc43238190ea8aced5456d","best_bid":"0.86","best_ask":"0.87"},{"asset_id":"86520121088881862182423437128238697252500151785248183602134095101149900014256","price":"0.15","size":"457.28","side":"SELL","hash":"5946d0f69d4d3cadb3953325fc96995189f5eee4","best_bid":"0.13","best_ask":"0.14"}],"timestamp":"1776808415809","event_type":"price_change"}}
{"capturedAt":1776808415,"payload":{"market":"0x125149c5918fc5f8c6d34682f700a898a1a19ea4f4e2ae68ff4c5794ba657074","price_changes":[{"asset_id":"45936375922793925919605092352922707796689801895417366600539442410775071099958","price":"0.01","size":"12324.83","side":"BUY","hash":"b991bb1c000668199499540abac0bc8ca55a619f","best_bid":"0.86","best_ask":"0.87"},{"asset_id":"86520121088881862182423437128238697252500151785248183602134095101149900014256","price":"0.99","size":"12324.83","side":"SELL","hash":"a361a405c024f6de4b704f271c96fce1e20def7f","best_bid":"0.13","best_ask":"0.14"}],"timestamp":"1776808415819","event_type":"price_change"}}
{"capturedAt":1776808415,"payload":{"market":"0x125149c5918fc5f8c6d34682f700a898a1a19ea4f4e2ae68ff4c5794ba657074","price_changes":[{"asset_id":"45936375922793925919605092352922707796689801895417366600539442410775071099958","price":"0.86","size":"368.19","side":"BUY","hash":"334131c537607cb64a7a2d81e241a7d14b4185e0","best_bid":"0.86","best_ask":"0.87"},{"asset_id":"86520121088881862182423437128238697252500151785248183602134095101149900014256","price":"0.14","size":"368.19","side":"SELL","hash":"233fd96ebb096b9899044c5a774b6fe8f70bb955","best_bid":"0.13","best_ask":"0.14"}],"timestamp":"1776808415824","event_type":"price_change"}}
{"capturedAt":1776808415,"payload":{"market":"0x125149c5918fc5f8c6d34682f700a898a1a19ea4f4e2ae68ff4c5794ba657074","price_changes":[{"asset_id":"45936375922793925919605092352922707796689801895417366600539442410775071099958","price":"0.86","size":"382.19","side":"BUY","hash":"52f747d9ab9443e2942e4587135605d480daf473","best_bid":"0.86","best_ask":"0.87"},{"asset_id":"86520121088881862182423437128238697252500151785248183602134095101149900014256","price":"0.14","size":"382.19","side":"SELL","hash":"21383d2e3e422814fc119ada508c6bb9297e6662","best_bid":"0.13","best_ask":"0.14"}],"timestamp":"1776808415825","event_type":"price_change"}}
{"capturedAt":1776808415,"payload":{"market":"0x125149c5918fc5f8c6d34682f700a898a1a19ea4f4e2ae68ff4c5794ba657074","price_changes":[{"asset_id":"45936375922793925919605092352922707796689801895417366600539442410775071099958","price":"0.86","size":"358.19","side":"BUY","hash":"359a10ccd18447d6daa6dc178204783ab6d63584","best_bid":"0.86","best_ask":"0.87"},{"asset_id":"86520121088881862182423437128238697252500151785248183602134095101149900014256","price":"0.14","size":"358.19","side":"SELL","hash":"a8f8b0377fc092d871e2c4ec92951341bd8a4175","best_bid":"0.13","best_ask":"0.14"}],"timestamp":"1776808415831","event_type":"price_change"}}
{"capturedAt":1776808415,"payload":{"market":"0x125149c5918fc5f8c6d34682f700a898a1a19ea4f4e2ae68ff4c5794ba657074","price_changes":[{"asset_id":"45936375922793925919605092352922707796689801895417366600539442410775071099958","price":"0.86","size":"324.19","side":"BUY","hash":"56942e16b3970bf47cf317ef682da30cb38a9620","best_bid":"0.86","best_ask":"0.87"},{"asset_id":"86520121088881862182423437128238697252500151785248183602134095101149900014256","price":"0.14","size":"324.19","side":"SELL","hash":"ea4985bd8b8c4cf680dbda3faf42014fb2ec3773","best_bid":"0.13","best_ask":"0.14"}],"timestamp":"1776808415834","event_type":"price_change"}}
{"capturedAt":1776808415,"payload":{"market":"0x125149c5918fc5f8c6d34682f700a898a1a19ea4f4e2ae68ff4c5794ba657074","price_changes":[{"asset_id":"45936375922793925919605092352922707796689801895417366600539442410775071099958","price":"0.86","size":"334.19","side":"BUY","hash":"77ba6faf9aa94fcb644977974b10813f1e057859","best_bid":"0.86","best_ask":"0.87"},{"asset_id":"86520121088881862182423437128238697252500151785248183602134095101149900014256","price":"0.14","size":"334.19","side":"SELL","hash":"846f2756a48c87c62593aa89962ac71b7505562b","best_bid":"0.13","best_ask":"0.14"}],"timestamp":"1776808415832","event_type":"price_change"}}
{"capturedAt":1776808415,"payload":{"market":"0x125149c5918fc5f8c6d34682f700a898a1a19ea4f4e2ae68ff4c5794ba657074","price_changes":[{"asset_id":"86520121088881862182423437128238697252500151785248183602134095101149900014256","price":"0.13","size":"149.74","side":"BUY","hash":"72ec23144ee46d340a014900502b49875cbfe024","best_bid":"0.13","best_ask":"0.14"},{"asset_id":"45936375922793925919605092352922707796689801895417366600539442410775071099958","price":"0.87","size":"149.74","side":"SELL","hash":"1f2616704cc77e1c84b7d366b10dcd38993c6f91","best_bid":"0.86","best_ask":"0.87"}],"timestamp":"1776808415835","event_type":"price_change"}}
{"capturedAt":1776808415,"payload":{"market":"0x125149c5918fc5f8c6d34682f700a898a1a19ea4f4e2ae68ff4c5794ba657074","price_changes":[{"asset_id":"86520121088881862182423437128238697252500151785248183602134095101149900014256","price":"0.12","size":"357.5","side":"BUY","hash":"3576ac17cc2ee244205f063e54a05f5ab6b346ee","best_bid":"0.13","best_ask":"0.14"},{"asset_id":"45936375922793925919605092352922707796689801895417366600539442410775071099958","price":"0.88","size":"357.5","side":"SELL","hash":"8d638a46efe9fb58b7b7c1a14591477fe5543812","best_bid":"0.86","best_ask":"0.87"}],"timestamp":"1776808415836","event_type":"price_change"}}
{"capturedAt":1776808415,"payload":{"market":"0x125149c5918fc5f8c6d34682f700a898a1a19ea4f4e2ae68ff4c5794ba657074","price_changes":[{"asset_id":"45936375922793925919605092352922707796689801895417366600539442410775071099958","price":"0.86","size":"338.19","side":"BUY","hash":"e581f65c3eb2cdbc2bcd24652b771fdc00f9ed09","best_bid":"0.86","best_ask":"0.87"},{"asset_id":"86520121088881862182423437128238697252500151785248183602134095101149900014256","price":"0.14","size":"338.19","side":"SELL","hash":"ee23c59dcccd2f082690cf536bbe8ca058b268a7","best_bid":"0.13","best_ask":"0.14"}],"timestamp":"1776808415838","event_type":"price_change"}}
{"capturedAt":1776808415,"payload":{"market":"0x125149c5918fc5f8c6d34682f700a898a1a19ea4f4e2ae68ff4c5794ba657074","price_changes":[{"asset_id":"45936375922793925919605092352922707796689801895417366600539442410775071099958","price":"0.01","size":"12329.83","side":"BUY","hash":"3023f953ff676fdfbbe3f3b4eb6a68c3e2164592","best_bid":"0.86","best_ask":"0.87"},{"asset_id":"86520121088881862182423437128238697252500151785248183602134095101149900014256","price":"0.99","size":"12329.83","side":"SELL","hash":"4c209b3a964d0a129388f0572b230ed06ba1f198","best_bid":"0.13","best_ask":"0.14"}],"timestamp":"1776808415839","event_type":"price_change"}}
{"capturedAt":1776808415,"payload":{"market":"0x125149c5918fc5f8c6d34682f700a898a1a19ea4f4e2ae68ff4c5794ba657074","price_changes":[{"asset_id":"45936375922793925919605092352922707796689801895417366600539442410775071099958","price":"0.86","size":"315.19","side":"BUY","hash":"d0abcb2ede473057ee76737a9610216bc68af97b","best_bid":"0.86","best_ask":"0.87"},{"asset_id":"86520121088881862182423437128238697252500151785248183602134095101149900014256","price":"0.14","size":"315.19","side":"SELL","hash":"c2da76d96a2c2ac9c6686a452194b32d5fefca21","best_bid":"0.13","best_ask":"0.14"}],"timestamp":"1776808415841","event_type":"price_change"}}
{"capturedAt":1776808415,"payload":{"market":"0x125149c5918fc5f8c6d34682f700a898a1a19ea4f4e2ae68ff4c5794ba657074","price_changes":[{"asset_id":"45936375922793925919605092352922707796689801895417366600539442410775071099958","price":"0.85","size":"427.28","side":"BUY","hash":"c559415abffb79ca03545ed66fb4fb7b24226355","best_bid":"0.86","best_ask":"0.87"},{"asset_id":"86520121088881862182423437128238697252500151785248183602134095101149900014256","price":"0.15","size":"427.28","side":"SELL","hash":"c6372f2369ed54148df77038005209bea76ea0a3","best_bid":"0.13","best_ask":"0.14"}],"timestamp":"1776808415842","event_type":"price_change"}}
{"capturedAt":1776808415,"payload":{"market":"0x125149c5918fc5f8c6d34682f700a898a1a19ea4f4e2ae68ff4c5794ba657074","price_changes":[{"asset_id":"45936375922793925919605092352922707796689801895417366600539442410775071099958","price":"0.86","size":"292.19","side":"BUY","hash":"eed7d37056405bc88a08e29f4a7e4a677c1a792e","best_bid":"0.86","best_ask":"0.87"},{"asset_id":"86520121088881862182423437128238697252500151785248183602134095101149900014256","price":"0.14","size":"292.19","side":"SELL","hash":"abd6513fb0a7b8e4d6b06164c242bb4b2b84a16e","best_bid":"0.13","best_ask":"0.14"}],"timestamp":"1776808415844","event_type":"price_change"}}
{"capturedAt":1776808415,"payload":{"market":"0x125149c5918fc5f8c6d34682f700a898a1a19ea4f4e2ae68ff4c5794ba657074","price_changes":[{"asset_id":"45936375922793925919605092352922707796689801895417366600539442410775071099958","price":"0.86","size":"269.19","side":"BUY","hash":"adacb352d85bb3f2a218ba86232e38385b66c452","best_bid":"0.86","best_ask":"0.87"},{"asset_id":"86520121088881862182423437128238697252500151785248183602134095101149900014256","price":"0.14","size":"269.19","side":"SELL","hash":"537062c2291cecee8e45bfbe10c552e8cd656c07","best_bid":"0.13","best_ask":"0.14"}],"timestamp":"1776808415844","event_type":"price_change"}}
{"capturedAt":1776808415,"payload":{"market":"0x125149c5918fc5f8c6d34682f700a898a1a19ea4f4e2ae68ff4c5794ba657074","price_changes":[{"asset_id":"45936375922793925919605092352922707796689801895417366600539442410775071099958","price":"0.86","size":"246.19","side":"BUY","hash":"cb85f49d0e2a3cc395bfebdb3867914525167070","best_bid":"0.86","best_ask":"0.87"},{"asset_id":"86520121088881862182423437128238697252500151785248183602134095101149900014256","price":"0.14","size":"246.19","side":"SELL","hash":"2443f52a763a62f1183e239afe086778fc672f5a","best_bid":"0.13","best_ask":"0.14"}],"timestamp":"1776808415848","event_type":"price_change"}}
{"capturedAt":1776808415,"payload":{"market":"0x125149c5918fc5f8c6d34682f700a898a1a19ea4f4e2ae68ff4c5794ba657074","price_changes":[{"asset_id":"45936375922793925919605092352922707796689801895417366600539442410775071099958","price":"0.01","size":"12334.83","side":"BUY","hash":"69bb8aa9d8cc33e001e071a5790cb10921b0791b","best_bid":"0.86","best_ask":"0.87"},{"asset_id":"86520121088881862182423437128238697252500151785248183602134095101149900014256","price":"0.99","size":"12334.83","side":"SELL","hash":"34badead822f1aaf7acad98d6413acf6f58e14be","best_bid":"0.13","best_ask":"0.14"}],"timestamp":"1776808415849","event_type":"price_change"}}
{"capturedAt":1776808415,"payload":{"market":"0x125149c5918fc5f8c6d34682f700a898a1a19ea4f4e2ae68ff4c5794ba657074","price_changes":[{"asset_id":"45936375922793925919605092352922707796689801895417366600539442410775071099958","price":"0.86","size":"256.19","side":"BUY","hash":"6a02cfce387b229cc8de46930dadf49578f6a429","best_bid":"0.86","best_ask":"0.87"},{"asset_id":"86520121088881862182423437128238697252500151785248183602134095101149900014256","price":"0.14","size":"256.19","side":"SELL","hash":"8f7dbfc23b0b8d0c3f5e53e478cbab7c65c0148d","best_bid":"0.13","best_ask":"0.14"}],"timestamp":"1776808415852","event_type":"price_change"}}
{"capturedAt":1776808415,"payload":{"market":"0x125149c5918fc5f8c6d34682f700a898a1a19ea4f4e2ae68ff4c5794ba657074","price_changes":[{"asset_id":"45936375922793925919605092352922707796689801895417366600539442410775071099958","price":"0.86","size":"234.19","side":"BUY","hash":"da796ad7827075b6653fa9aa6dd331db4e2b44f9","best_bid":"0.86","best_ask":"0.87"},{"asset_id":"86520121088881862182423437128238697252500151785248183602134095101149900014256","price":"0.14","size":"234.19","side":"SELL","hash":"e553966f7ed0da625c397b8a534a51775b4a595b","best_bid":"0.13","best_ask":"0.14"}],"timestamp":"1776808415854","event_type":"price_change"}}
{"capturedAt":1776808415,"payload":{"market":"0x125149c5918fc5f8c6d34682f700a898a1a19ea4f4e2ae68ff4c5794ba657074","price_changes":[{"asset_id":"45936375922793925919605092352922707796689801895417366600539442410775071099958","price":"0.86","size":"239.49","side":"BUY","hash":"0617b996c4e5bdb870ed589f64391c684daeb700","best_bid":"0.86","best_ask":"0.87"},{"asset_id":"86520121088881862182423437128238697252500151785248183602134095101149900014256","price":"0.14","size":"239.49","side":"SELL","hash":"b60f6b6c12dd6294bcc2745fdbd6a9a6ea181d39","best_bid":"0.13","best_ask":"0.14"}],"timestamp":"1776808415857","event_type":"price_change"}}
{"capturedAt":1776808415,"payload":{"market":"0x125149c5918fc5f8c6d34682f700a898a1a19ea4f4e2ae68ff4c5794ba657074","price_changes":[{"asset_id":"45936375922793925919605092352922707796689801895417366600539442410775071099958","price":"0.86","size":"234.14","side":"BUY","hash":"b098a5164333817ba9df595d2b4e109505f77ea4","best_bid":"0.86","best_ask":"0.87"},{"asset_id":"86520121088881862182423437128238697252500151785248183602134095101149900014256","price":"0.14","size":"234.14","side":"SELL","hash":"36496bd9bcbada9242b6f359f725ccf5c206feeb","best_bid":"0.13","best_ask":"0.14"}],"timestamp":"1776808415858","event_type":"price_change"}}
{"capturedAt":1776808415,"payload":{"market":"0x125149c5918fc5f8c6d34682f700a898a1a19ea4f4e2ae68ff4c5794ba657074","price_changes":[{"asset_id":"45936375922793925919605092352922707796689801895417366600539442410775071099958","price":"0.01","size":"12329.83","side":"BUY","hash":"674e8d6f7d20ef49f9ad1fda64410ed63bfa89aa","best_bid":"0.86","best_ask":"0.87"},{"asset_id":"86520121088881862182423437128238697252500151785248183602134095101149900014256","price":"0.99","size":"12329.83","side":"SELL","hash":"53aa0724e4318e9e823cd8c4a0faaa47e54d0d82","best_bid":"0.13","best_ask":"0.14"}],"timestamp":"1776808415858","event_type":"price_change"}}
{"capturedAt":1776808415,"payload":{"market":"0x125149c5918fc5f8c6d34682f700a898a1a19ea4f4e2ae68ff4c5794ba657074","price_changes":[{"asset_id":"45936375922793925919605092352922707796689801895417366600539442410775071099958","price":"0.86","size":"261.14","side":"BUY","hash":"c2a5d6a496ed20a2369529a81e6e5a2974e96a3e","best_bid":"0.86","best_ask":"0.87"},{"asset_id":"86520121088881862182423437128238697252500151785248183602134095101149900014256","price":"0.14","size":"261.14","side":"SELL","hash":"e71d321eca03d6cad87dcd9b6eaa256641ba7c81","best_bid":"0.13","best_ask":"0.14"}],"timestamp":"1776808415859","event_type":"price_change"}}
{"capturedAt":1776808415,"payload":{"market":"0x125149c5918fc5f8c6d34682f700a898a1a19ea4f4e2ae68ff4c5794ba657074","price_changes":[{"asset_id":"45936375922793925919605092352922707796689801895417366600539442410775071099958","price":"0.86","size":"271.14","side":"BUY","hash":"ec38ff103d1e5c7c44a05801976bab12970c9fba","best_bid":"0.86","best_ask":"0.87"},{"asset_id":"86520121088881862182423437128238697252500151785248183602134095101149900014256","price":"0.14","size":"271.14","side":"SELL","hash":"c8a89103fabea23726a0434f3d16f427feebc5ed","best_bid":"0.13","best_ask":"0.14"}],"timestamp":"1776808415860","event_type":"price_change"}}
{"capturedAt":1776808415,"payload":{"market":"0x125149c5918fc5f8c6d34682f700a898a1a19ea4f4e2ae68ff4c5794ba657074","price_changes":[{"asset_id":"45936375922793925919605092352922707796689801895417366600539442410775071099958","price":"0.86","size":"297.14","side":"BUY","hash":"3df1e7c3c8e2ff29999b6d37d59df82ad74e14c0","best_bid":"0.86","best_ask":"0.87"},{"asset_id":"86520121088881862182423437128238697252500151785248183602134095101149900014256","price":"0.14","size":"297.14","side":"SELL","hash":"a2f24058eda7158aa3dd49711f5193b661cfa263","best_bid":"0.13","best_ask":"0.14"}],"timestamp":"1776808415862","event_type":"price_change"}}
{"capturedAt":1776808415,"payload":{"market":"0x125149c5918fc5f8c6d34682f700a898a1a19ea4f4e2ae68ff4c5794ba657074","price_changes":[{"asset_id":"45936375922793925919605092352922707796689801895417366600539442410775071099958","price":"0.84","size":"414.37","side":"BUY","hash":"e1412af8441f9e37b43bad53a5b463c309fe0774","best_bid":"0.86","best_ask":"0.87"},{"asset_id":"86520121088881862182423437128238697252500151785248183602134095101149900014256","price":"0.16","size":"414.37","side":"SELL","hash":"eb654c7d76a9ef2f34e09febb46b5a76d034ecf4","best_bid":"0.13","best_ask":"0.14"}],"timestamp":"1776808415864","event_type":"price_change"}}
{"capturedAt":1776808415,"payload":{"market":"0x125149c5918fc5f8c6d34682f700a898a1a19ea4f4e2ae68ff4c5794ba657074","price_changes":[{"asset_id":"45936375922793925919605092352922707796689801895417366600539442410775071099958","price":"0.86","size":"323.14","side":"BUY","hash":"6e4536b5ab3da8de2b86450dbcceefea676bb3f7","best_bid":"0.86","best_ask":"0.87"},{"asset_id":"86520121088881862182423437128238697252500151785248183602134095101149900014256","price":"0.14","size":"323.14","side":"SELL","hash":"d9c5114f6918968a3ab20b846d85c11cc2892034","best_bid":"0.13","best_ask":"0.14"}],"timestamp":"1776808415863","event_type":"price_change"}}
{"capturedAt":1776808415,"payload":{"market":"0x125149c5918fc5f8c6d34682f700a898a1a19ea4f4e2ae68ff4c5794ba657074","price_changes":[{"asset_id":"45936375922793925919605092352922707796689801895417366600539442410775071099958","price":"0.01","size":"12324.83","side":"BUY","hash":"1a4ea75a70da5cf9c3aea1cc41fa29fc4f54c3be","best_bid":"0.86","best_ask":"0.87"},{"asset_id":"86520121088881862182423437128238697252500151785248183602134095101149900014256","price":"0.99","size":"12324.83","side":"SELL","hash":"dc73f4a180266404b4715d9b7b0ed3ec14381f97","best_bid":"0.13","best_ask":"0.14"}],"timestamp":"1776808415868","event_type":"price_change"}}
{"capturedAt":1776808415,"payload":{"market":"0x125149c5918fc5f8c6d34682f700a898a1a19ea4f4e2ae68ff4c5794ba657074","price_changes":[{"asset_id":"45936375922793925919605092352922707796689801895417366600539442410775071099958","price":"0.86","size":"346.14","side":"BUY","hash":"f9913cc34b063c20c7aec06e248596e72f7a2f46","best_bid":"0.86","best_ask":"0.87"},{"asset_id":"86520121088881862182423437128238697252500151785248183602134095101149900014256","price":"0.14","size":"346.14","side":"SELL","hash":"e94386c1422e8920df2129208ef5f89413665fb8","best_bid":"0.13","best_ask":"0.14"}],"timestamp":"1776808415870","event_type":"price_change"}}
{"capturedAt":1776808415,"payload":{"market":"0x125149c5918fc5f8c6d34682f700a898a1a19ea4f4e2ae68ff4c5794ba657074","price_changes":[{"asset_id":"45936375922793925919605092352922707796689801895417366600539442410775071099958","price":"0.86","size":"369.14","side":"BUY","hash":"19ee24046d6dac283ae5ed265645778e4e9ddbb6","best_bid":"0.86","best_ask":"0.87"},{"asset_id":"86520121088881862182423437128238697252500151785248183602134095101149900014256","price":"0.14","size":"369.14","side":"SELL","hash":"2187675cbbf000c6b3d73c1b43512ab62568e460","best_bid":"0.13","best_ask":"0.14"}],"timestamp":"1776808415872","event_type":"price_change"}}
{"capturedAt":1776808415,"payload":{"market":"0x125149c5918fc5f8c6d34682f700a898a1a19ea4f4e2ae68ff4c5794ba657074","price_changes":[{"asset_id":"45936375922793925919605092352922707796689801895417366600539442410775071099958","price":"0.86","size":"345.14","side":"BUY","hash":"e00a4e6c51007308a5a8cf262836aceaa4baa11a","best_bid":"0.86","best_ask":"0.87"},{"asset_id":"86520121088881862182423437128238697252500151785248183602134095101149900014256","price":"0.14","size":"345.14","side":"SELL","hash":"4bc56f849c95afa8ce7d80ad63b2b74404acd923","best_bid":"0.13","best_ask":"0.14"}],"timestamp":"1776808415874","event_type":"price_change"}}
{"capturedAt":1776808415,"payload":{"market":"0x125149c5918fc5f8c6d34682f700a898a1a19ea4f4e2ae68ff4c5794ba657074","price_changes":[{"asset_id":"45936375922793925919605092352922707796689801895417366600539442410775071099958","price":"0.86","size":"368.14","side":"BUY","hash":"443785c6bb0eb4180330950363e76328d6983698","best_bid":"0.86","best_ask":"0.87"},{"asset_id":"86520121088881862182423437128238697252500151785248183602134095101149900014256","price":"0.14","size":"368.14","side":"SELL","hash":"1bac3a93acf16bda8c30d989c38f4aaddd014740","best_bid":"0.13","best_ask":"0.14"}],"timestamp":"1776808415876","event_type":"price_change"}}
{"capturedAt":1776808415,"payload":{"market":"0x125149c5918fc5f8c6d34682f700a898a1a19ea4f4e2ae68ff4c5794ba657074","price_changes":[{"asset_id":"45936375922793925919605092352922707796689801895417366600539442410775071099958","price":"0.86","size":"343.14","side":"BUY","hash":"57ab2075b22650b8f56f5336feda663702aae37f","best_bid":"0.86","best_ask":"0.87"},{"asset_id":"86520121088881862182423437128238697252500151785248183602134095101149900014256","price":"0.14","size":"343.14","side":"SELL","hash":"0333e80c43e23c3f2933b817d95feb9ae8773204","best_bid":"0.13","best_ask":"0.14"}],"timestamp":"1776808415877","event_type":"price_change"}}
{"capturedAt":1776808415,"payload":{"market":"0x125149c5918fc5f8c6d34682f700a898a1a19ea4f4e2ae68ff4c5794ba657074","price_changes":[{"asset_id":"45936375922793925919605092352922707796689801895417366600539442410775071099958","price":"0.86","size":"333.14","side":"BUY","hash":"a1d8238670a921d6ac30d58a6b306044c57dfde2","best_bid":"0.86","best_ask":"0.87"},{"asset_id":"86520121088881862182423437128238697252500151785248183602134095101149900014256","price":"0.14","size":"333.14","side":"SELL","hash":"cc074b98d61900c1a92b14fa7a2fcfa75f3f7f72","best_bid":"0.13","best_ask":"0.14"}],"timestamp":"1776808415881","event_type":"price_change"}}
{"capturedAt":1776808415,"payload":{"market":"0x125149c5918fc5f8c6d34682f700a898a1a19ea4f4e2ae68ff4c5794ba657074","price_changes":[{"asset_id":"86520121088881862182423437128238697252500151785248183602134095101149900014256","price":"0.05","size":"590.63","side":"BUY","hash":"08747757c8f8fb6e14e60dcf222a40c6b884b7be","best_bid":"0.13","best_ask":"0.14"},{"asset_id":"45936375922793925919605092352922707796689801895417366600539442410775071099958","price":"0.95","size":"590.63","side":"SELL","hash":"c3b5822a2548f38049b4e1755513ac5b35306c56","best_bid":"0.86","best_ask":"0.87"}],"timestamp":"1776808415882","event_type":"price_change"}}
{"capturedAt":1776808415,"payload":{"market":"0x125149c5918fc5f8c6d34682f700a898a1a19ea4f4e2ae68ff4c5794ba657074","price_changes":[{"asset_id":"45936375922793925919605092352922707796689801895417366600539442410775071099958","price":"0.86","size":"356.14","side":"BUY","hash":"488364329ed1d94a130fc7ee18e1a56eee485828","best_bid":"0.86","best_ask":"0.87"},{"asset_id":"86520121088881862182423437128238697252500151785248183602134095101149900014256","price":"0.14","size":"356.14","side":"SELL","hash":"6fd93815462ba5d5afd216cfde42a4cf2993fd3b","best_bid":"0.13","best_ask":"0.14"}],"timestamp":"1776808415883","event_type":"price_change"}}
{"capturedAt":1776808415,"payload":{"market":"0x125149c5918fc5f8c6d34682f700a898a1a19ea4f4e2ae68ff4c5794ba657074","price_changes":[{"asset_id":"45936375922793925919605092352922707796689801895417366600539442410775071099958","price":"0.85","size":"457.28","side":"BUY","hash":"5b2b6fef6e9345c5e55e352acc972a69cd96fdb3","best_bid":"0.86","best_ask":"0.87"},{"asset_id":"86520121088881862182423437128238697252500151785248183602134095101149900014256","price":"0.15","size":"457.28","side":"SELL","hash":"48a1d4e43d6c4a77cc2b385819567f0398cc4261","best_bid":"0.13","best_ask":"0.14"}],"timestamp":"1776808415882","event_type":"price_change"}}
{"capturedAt":1776808415,"payload":{"market":"0x125149c5918fc5f8c6d34682f700a898a1a19ea4f4e2ae68ff4c5794ba657074","price_changes":[{"asset_id":"45936375922793925919605092352922707796689801895417366600539442410775071099958","price":"0.01","size":"12329.83","side":"BUY","hash":"01baabe60c8b3181fa9f30ce23c713ee94579ff1","best_bid":"0.86","best_ask":"0.87"},{"asset_id":"86520121088881862182423437128238697252500151785248183602134095101149900014256","price":"0.99","size":"12329.83","side":"SELL","hash":"b693046e23075a692b84cebbded94e26d8e9ecf8","best_bid":"0.13","best_ask":"0.14"}],"timestamp":"1776808415888","event_type":"price_change"}}
{"capturedAt":1776808415,"payload":{"market":"0x125149c5918fc5f8c6d34682f700a898a1a19ea4f4e2ae68ff4c5794ba657074","price_changes":[{"asset_id":"45936375922793925919605092352922707796689801895417366600539442410775071099958","price":"0.86","size":"342.14","side":"BUY","hash":"5d234732f0efab0dd2af2573c2603a5522178026","best_bid":"0.86","best_ask":"0.87"},{"asset_id":"86520121088881862182423437128238697252500151785248183602134095101149900014256","price":"0.14","size":"342.14","side":"SELL","hash":"e63d156bfe9511e52ab4f57eb8d60afca87c6662","best_bid":"0.13","best_ask":"0.14"}],"timestamp":"1776808415895","event_type":"price_change"}}
{"capturedAt":1776808415,"payload":{"market":"0x125149c5918fc5f8c6d34682f700a898a1a19ea4f4e2ae68ff4c5794ba657074","price_changes":[{"asset_id":"45936375922793925919605092352922707796689801895417366600539442410775071099958","price":"0.79","size":"189.7","side":"BUY","hash":"c0deed4f464b82b1969f42b0dfa26a00be2f7c6c","best_bid":"0.86","best_ask":"0.87"},{"asset_id":"86520121088881862182423437128238697252500151785248183602134095101149900014256","price":"0.21","size":"189.7","side":"SELL","hash":"832c27157c3d52d430bc9bc096a20c5a755eacd5","best_bid":"0.13","best_ask":"0.14"}],"timestamp":"1776808415896","event_type":"price_change"}}
{"capturedAt":1776808415,"payload":{"market":"0x125149c5918fc5f8c6d34682f700a898a1a19ea4f4e2ae68ff4c5794ba657074","price_changes":[{"asset_id":"45936375922793925919605092352922707796689801895417366600539442410775071099958","price":"0.84","size":"384.37","side":"BUY","hash":"64a46dbe84bf408a495604fb0df989f6167f6cbc","best_bid":"0.86","best_ask":"0.87"},{"asset_id":"86520121088881862182423437128238697252500151785248183602134095101149900014256","price":"0.16","size":"384.37","side":"SELL","hash":"64a8d4ef47d872e4546922b2dd494414618e786c","best_bid":"0.13","best_ask":"0.14"}],"timestamp":"1776808415901","event_type":"price_change"}}
{"capturedAt":1776808415,"payload":{"market":"0x125149c5918fc5f8c6d34682f700a898a1a19ea4f4e2ae68ff4c5794ba657074","price_changes":[{"asset_id":"45936375922793925919605092352922707796689801895417366600539442410775071099958","price":"0.01","size":"12334.83","side":"BUY","hash":"560ed9b28ca2346b6773b1949bfb28d3bcbe2c10","best_bid":"0.86","best_ask":"0.87"},{"asset_id":"86520121088881862182423437128238697252500151785248183602134095101149900014256","price":"0.99","size":"12334.83","side":"SELL","hash":"b7c7e72b6ab0a3b07edd2424b418e042e58459bf","best_bid":"0.13","best_ask":"0.14"}],"timestamp":"1776808415902","event_type":"price_change"}}
{"capturedAt":1776808415,"payload":{"market":"0x125149c5918fc5f8c6d34682f700a898a1a19ea4f4e2ae68ff4c5794ba657074","price_changes":[{"asset_id":"45936375922793925919605092352922707796689801895417366600539442410775071099958","price":"0.86","size":"407.14","side":"BUY","hash":"eb91b9e71fedcb292ec4f27c7db2b3aa397f3ba9","best_bid":"0.86","best_ask":"0.87"},{"asset_id":"86520121088881862182423437128238697252500151785248183602134095101149900014256","price":"0.14","size":"407.14","side":"SELL","hash":"d36a844fcde5c1126ca7f56ea5937b7f50d3871e","best_bid":"0.13","best_ask":"0.14"}],"timestamp":"1776808415907","event_type":"price_change"}}
{"capturedAt":1776808415,"payload":{"market":"0x125149c5918fc5f8c6d34682f700a898a1a19ea4f4e2ae68ff4c5794ba657074","price_changes":[{"asset_id":"45936375922793925919605092352922707796689801895417366600539442410775071099958","price":"0.86","size":"379.14","side":"BUY","hash":"c0cfad1d11c93cdc43aefe5b59998b294eab1c94","best_bid":"0.86","best_ask":"0.87"},{"asset_id":"86520121088881862182423437128238697252500151785248183602134095101149900014256","price":"0.14","size":"379.14","side":"SELL","hash":"6cd7f61983b3afc24d113547418945677dc9ebcc","best_bid":"0.13","best_ask":"0.14"}],"timestamp":"1776808415906","event_type":"price_change"}}
{"capturedAt":1776808415,"payload":{"market":"0x125149c5918fc5f8c6d34682f700a898a1a19ea4f4e2ae68ff4c5794ba657074","price_changes":[{"asset_id":"45936375922793925919605092352922707796689801895417366600539442410775071099958","price":"0.86","size":"369.14","side":"BUY","hash":"65a9a69557e5d50dd9a15c14f79bcda1ddcf3b42","best_bid":"0.86","best_ask":"0.87"},{"asset_id":"86520121088881862182423437128238697252500151785248183602134095101149900014256","price":"0.14","size":"369.14","side":"SELL","hash":"8d4628c2b0928959ff736fb3f4226078dfc19812","best_bid":"0.13","best_ask":"0.14"}],"timestamp":"1776808415905","event_type":"price_change"}}
{"capturedAt":1776808415,"payload":{"market":"0x125149c5918fc5f8c6d34682f700a898a1a19ea4f4e2ae68ff4c5794ba657074","price_changes":[{"asset_id":"45936375922793925919605092352922707796689801895417366600539442410775071099958","price":"0.01","size":"12329.83","side":"BUY","hash":"24657ad64af04bef6177f5e41cf38dea16c45e9b","best_bid":"0.86","best_ask":"0.87"},{"asset_id":"86520121088881862182423437128238697252500151785248183602134095101149900014256","price":"0.99","size":"12329.83","side":"SELL","hash":"9b578511034cbc2b74f102c47caa079d687f32d0","best_bid":"0.13","best_ask":"0.14"}],"timestamp":"1776808415908","event_type":"price_change"}}
{"capturedAt":1776808415,"payload":{"market":"0x125149c5918fc5f8c6d34682f700a898a1a19ea4f4e2ae68ff4c5794ba657074","price_changes":[{"asset_id":"45936375922793925919605092352922707796689801895417366600539442410775071099958","price":"0.86","size":"392.14","side":"BUY","hash":"cc6c751892347fa6ac90ad97987c667d8d3e33db","best_bid":"0.86","best_ask":"0.87"},{"asset_id":"86520121088881862182423437128238697252500151785248183602134095101149900014256","price":"0.14","size":"392.14","side":"SELL","hash":"e857f509e63d438baa690a5fd80e2864ded8bea8","best_bid":"0.13","best_ask":"0.14"}],"timestamp":"1776808415924","event_type":"price_change"}}
{"capturedAt":1776808415,"payload":{"market":"0x125149c5918fc5f8c6d34682f700a898a1a19ea4f4e2ae68ff4c5794ba657074","price_changes":[{"asset_id":"45936375922793925919605092352922707796689801895417366600539442410775071099958","price":"0.86","size":"397.14","side":"BUY","hash":"e0699c8ecd2b4ca49457d64a11c6bc19257b1a9d","best_bid":"0.86","best_ask":"0.87"},{"asset_id":"86520121088881862182423437128238697252500151785248183602134095101149900014256","price":"0.14","size":"397.14","side":"SELL","hash":"af637c2f3c7f6d1fe8b8fa90725085e38b282b59","best_bid":"0.13","best_ask":"0.14"}],"timestamp":"1776808415924","event_type":"price_change"}}
{"capturedAt":1776808415,"payload":{"market":"0x125149c5918fc5f8c6d34682f700a898a1a19ea4f4e2ae68ff4c5794ba657074","price_changes":[{"asset_id":"86520121088881862182423437128238697252500151785248183602134095101149900014256","price":"0.11","size":"386.5","side":"BUY","hash":"d7966428d298071b2c8c70aae6b8c109f2446ae0","best_bid":"0.13","best_ask":"0.14"},{"asset_id":"45936375922793925919605092352922707796689801895417366600539442410775071099958","price":"0.89","size":"386.5","side":"SELL","hash":"c09818f170e1a8c810029d5ddd7e8b925f3cacfb","best_bid":"0.86","best_ask":"0.87"}],"timestamp":"1776808415925","event_type":"price_change"}}
{"capturedAt":1776808415,"payload":{"market":"0x125149c5918fc5f8c6d34682f700a898a1a19ea4f4e2ae68ff4c5794ba657074","price_changes":[{"asset_id":"45936375922793925919605092352922707796689801895417366600539442410775071099958","price":"0.86","size":"405.14","side":"BUY","hash":"98e1a0c1d171f63b6580a5fe7913cfc08c935d22","best_bid":"0.86","best_ask":"0.87"},{"asset_id":"86520121088881862182423437128238697252500151785248183602134095101149900014256","price":"0.14","size":"405.14","side":"SELL","hash":"b436b0cdaa88521508c863f899b85d006bb09e46","best_bid":"0.13","best_ask":"0.14"}],"timestamp":"1776808415926","event_type":"price_change"}}
{"capturedAt":1776808415,"payload":{"market":"0x125149c5918fc5f8c6d34682f700a898a1a19ea4f4e2ae68ff4c5794ba657074","price_changes":[{"asset_id":"45936375922793925919605092352922707796689801895417366600539442410775071099958","price":"0.8","size":"275.25","side":"BUY","hash":"7ec845ebf82362fef662ea3a90e9587d347d390f","best_bid":"0.86","best_ask":"0.87"},{"asset_id":"86520121088881862182423437128238697252500151785248183602134095101149900014256","price":"0.2","size":"275.25","side":"SELL","hash":"1065c5cc66f486b3a436af80c086b5115977257b","best_bid":"0.13","best_ask":"0.14"}],"timestamp":"1776808415927","event_type":"price_change"}}
{"capturedAt":1776808415,"payload":{"market":"0x125149c5918fc5f8c6d34682f700a898a1a19ea4f4e2ae68ff4c5794ba657074","price_changes":[{"asset_id":"45936375922793925919605092352922707796689801895417366600539442410775071099958","price":"0.01","size":"12324.83","side":"BUY","hash":"fdfd7cabce720fef8860783ed661bcaf8676d3ee","best_bid":"0.86","best_ask":"0.87"},{"asset_id":"86520121088881862182423437128238697252500151785248183602134095101149900014256","price":"0.99","size":"12324.83","side":"SELL","hash":"510da176b2f06be4211adb51242c1522340a53f3","best_bid":"0.13","best_ask":"0.14"}],"timestamp":"1776808415927","event_type":"price_change"}}
{"capturedAt":1776808415,"payload":{"market":"0x125149c5918fc5f8c6d34682f700a898a1a19ea4f4e2ae68ff4c5794ba657074","price_changes":[{"asset_id":"86520121088881862182423437128238697252500151785248183602134095101149900014256","price":"0.13","size":"154.74","side":"BUY","hash":"9424d83fe40e7ae4d33105043393cca38eb157e9","best_bid":"0.13","best_ask":"0.14"},{"asset_id":"45936375922793925919605092352922707796689801895417366600539442410775071099958","price":"0.87","size":"154.74","side":"SELL","hash":"a901507292d7849efa7c22eb60d96987dbed6142","best_bid":"0.86","best_ask":"0.87"}],"timestamp":"1776808415928","event_type":"price_change"}}
{"capturedAt":1776808415,"payload":{"market":"0x125149c5918fc5f8c6d34682f700a898a1a19ea4f4e2ae68ff4c5794ba657074","price_changes":[{"asset_id":"45936375922793925919605092352922707796689801895417366600539442410775071099958","price":"0.86","size":"391.14","side":"BUY","hash":"6cd0f8bf4acdd55d7983992621a25be38553ea0b","best_bid":"0.86","best_ask":"0.87"},{"asset_id":"86520121088881862182423437128238697252500151785248183602134095101149900014256","price":"0.14","size":"391.14","side":"SELL","hash":"e5d6f22d34fedda823193bf0d5f20929b908f785","best_bid":"0.13","best_ask":"0.14"}],"timestamp":"1776808415929","event_type":"price_change"}}
{"capturedAt":1776808415,"payload":{"market":"0x125149c5918fc5f8c6d34682f700a898a1a19ea4f4e2ae68ff4c5794ba657074","price_changes":[{"asset_id":"45936375922793925919605092352922707796689801895417366600539442410775071099958","price":"0.86","size":"364.14","side":"BUY","hash":"eb18a6098682cd1be654fa9313775f2d201c3c48","best_bid":"0.86","best_ask":"0.87"},{"asset_id":"86520121088881862182423437128238697252500151785248183602134095101149900014256","price":"0.14","size":"364.14","side":"SELL","hash":"4695df90be3ec85440b302979722dc20e71e6939","best_bid":"0.13","best_ask":"0.14"}],"timestamp":"1776808415930","event_type":"price_change"}}
{"capturedAt":1776808415,"payload":{"market":"0x125149c5918fc5f8c6d34682f700a898a1a19ea4f4e2ae68ff4c5794ba657074","price_changes":[{"asset_id":"45936375922793925919605092352922707796689801895417366600539442410775071099958","price":"0.86","size":"328.14","side":"BUY","hash":"2c0ce29100c713c0a069a76e3f29e71509a4b015","best_bid":"0.86","best_ask":"0.87"},{"asset_id":"86520121088881862182423437128238697252500151785248183602134095101149900014256","price":"0.14","size":"328.14","side":"SELL","hash":"f389d94acbb60351fc91ed4b726bd0c89c8a9176","best_bid":"0.13","best_ask":"0.14"}],"timestamp":"1776808415932","event_type":"price_change"}}
{"capturedAt":1776808415,"payload":{"market":"0x125149c5918fc5f8c6d34682f700a898a1a19ea4f4e2ae68ff4c5794ba657074","price_changes":[{"asset_id":"45936375922793925919605092352922707796689801895417366600539442410775071099958","price":"0.86","size":"354.14","side":"BUY","hash":"ef963b7ef30f7b9968256b1da898e06c0b5d7589","best_bid":"0.86","best_ask":"0.87"},{"asset_id":"86520121088881862182423437128238697252500151785248183602134095101149900014256","price":"0.14","size":"354.14","side":"SELL","hash":"d350a700673b6a24e5b5cdda92f2017825b651f5","best_bid":"0.13","best_ask":"0.14"}],"timestamp":"1776808415931","event_type":"price_change"}}
{"capturedAt":1776808415,"payload":{"market":"0x125149c5918fc5f8c6d34682f700a898a1a19ea4f4e2ae68ff4c5794ba657074","price_changes":[{"asset_id":"45936375922793925919605092352922707796689801895417366600539442410775071099958","price":"0.86","size":"302.14","side":"BUY","hash":"7d3f8d6f9a620acc53ccbee39a0bd9dd8b81ecf8","best_bid":"0.86","best_ask":"0.87"},{"asset_id":"86520121088881862182423437128238697252500151785248183602134095101149900014256","price":"0.14","size":"302.14","side":"SELL","hash":"5f8783a94c9f21483e9d500a9ed218679f4fc295","best_bid":"0.13","best_ask":"0.14"}],"timestamp":"1776808415933","event_type":"price_change"}}
{"capturedAt":1776808416,"payload":{"market":"0x125149c5918fc5f8c6d34682f700a898a1a19ea4f4e2ae68ff4c5794ba657074","price_changes":[{"asset_id":"45936375922793925919605092352922707796689801895417366600539442410775071099958","price":"0.86","size":"238.15","side":"BUY","hash":"7fdad2e8819130b3e19f796b7b8d0147e7fbb8a7","best_bid":"0.86","best_ask":"0.87"},{"asset_id":"86520121088881862182423437128238697252500151785248183602134095101149900014256","price":"0.14","size":"238.15","side":"SELL","hash":"71dc941a24b07498f298a7fddb60d85014f37802","best_bid":"0.13","best_ask":"0.14"}],"timestamp":"1776808415945","event_type":"price_change"}}
{"capturedAt":1776808416,"payload":{"market":"0x125149c5918fc5f8c6d34682f700a898a1a19ea4f4e2ae68ff4c5794ba657074","price_changes":[{"asset_id":"45936375922793925919605092352922707796689801895417366600539442410775071099958","price":"0.86","size":"279.14","side":"BUY","hash":"19ead397f6fc714661cf508701f3eb34893d513d","best_bid":"0.86","best_ask":"0.87"},{"asset_id":"86520121088881862182423437128238697252500151785248183602134095101149900014256","price":"0.14","size":"279.14","side":"SELL","hash":"365631828dc603009ab486e374458c9d4ddd351a","best_bid":"0.13","best_ask":"0.14"}],"timestamp":"1776808415941","event_type":"price_change"}}
{"capturedAt":1776808416,"payload":{"market":"0x125149c5918fc5f8c6d34682f700a898a1a19ea4f4e2ae68ff4c5794ba657074","price_changes":[{"asset_id":"45936375922793925919605092352922707796689801895417366600539442410775071099958","price":"0.01","size":"12334.83","side":"BUY","hash":"bf56fb0afff81d7b476df894c1c09d90fd09e1b8","best_bid":"0.86","best_ask":"0.87"},{"asset_id":"86520121088881862182423437128238697252500151785248183602134095101149900014256","price":"0.99","size":"12334.83","side":"SELL","hash":"58d4e5b962f27d207d27947a37d01fd4aab02d51","best_bid":"0.13","best_ask":"0.14"}],"timestamp":"1776808415948","event_type":"price_change"}}
{"capturedAt":1776808416,"payload":{"market":"0x125149c5918fc5f8c6d34682f700a898a1a19ea4f4e2ae68ff4c5794ba657074","price_changes":[{"asset_id":"45936375922793925919605092352922707796689801895417366600539442410775071099958","price":"0.86","size":"243.45","side":"BUY","hash":"bf53613be9cf9ce3a953b698f09f52c9b579a69e","best_bid":"0.86","best_ask":"0.87"},{"asset_id":"86520121088881862182423437128238697252500151785248183602134095101149900014256","price":"0.14","size":"243.45","side":"SELL","hash":"e0c3d8925e7356648d759f06358a9801d89d00c8","best_bid":"0.13","best_ask":"0.14"}],"timestamp":"1776808415949","event_type":"price_change"}}
{"capturedAt":1776808416,"payload":{"market":"0x125149c5918fc5f8c6d34682f700a898a1a19ea4f4e2ae68ff4c5794ba657074","price_changes":[{"asset_id":"45936375922793925919605092352922707796689801895417366600539442410775071099958","price":"0.86","size":"277.45","side":"BUY","hash":"6bb4457053bcd485f6de2376caf0e013fc3df97b","best_bid":"0.86","best_ask":"0.87"},{"asset_id":"86520121088881862182423437128238697252500151785248183602134095101149900014256","price":"0.14","size":"277.45","side":"SELL","hash":"50312e8922aed5bfb883c3bc0e531752ffe22da5","best_bid":"0.13","best_ask":"0.14"}],"timestamp":"1776808415953","event_type":"price_change"}}
{"capturedAt":1776808416,"payload":{"market":"0x125149c5918fc5f8c6d34682f700a898a1a19ea4f4e2ae68ff4c5794ba657074","price_changes":[{"asset_id":"45936375922793925919605092352922707796689801895417366600539442410775071099958","price":"0.01","size":"12329.83","side":"BUY","hash":"e569baeb136f122900b1d09cea70f590653ac717","best_bid":"0.86","best_ask":"0.87"},{"asset_id":"86520121088881862182423437128238697252500151785248183602134095101149900014256","price":"0.99","size":"12329.83","side":"SELL","hash":"fb9b24c0664609acaec3f80a7a047f85cb862437","best_bid":"0.13","best_ask":"0.14"}],"timestamp":"1776808415956","event_type":"price_change"}}
{"capturedAt":1776808416,"payload":{"market":"0x125149c5918fc5f8c6d34682f700a898a1a19ea4f4e2ae68ff4c5794ba657074","price_changes":[{"asset_id":"45936375922793925919605092352922707796689801895417366600539442410775071099958","price":"0.86","size":"261.15","side":"BUY","hash":"57787ff7f03924e3c43cd20a74059750f38c214e","best_bid":"0.86","best_ask":"0.87"},{"asset_id":"86520121088881862182423437128238697252500151785248183602134095101149900014256","price":"0.14","size":"261.15","side":"SELL","hash":"eedd40a478fa3d20203832fed08bd8baa83d2153","best_bid":"0.13","best_ask":"0.14"}],"timestamp":"1776808415944","event_type":"price_change"}}
{"capturedAt":1776808416,"payload":{"market":"0x125149c5918fc5f8c6d34682f700a898a1a19ea4f4e2ae68ff4c5794ba657074","price_changes":[{"asset_id":"45936375922793925919605092352922707796689801895417366600539442410775071099958","price":"0.01","size":"12329.83","side":"BUY","hash":"c743eda5eb9375477e7427dc41a43447cf28f9c5","best_bid":"0.86","best_ask":"0.87"},{"asset_id":"86520121088881862182423437128238697252500151785248183602134095101149900014256","price":"0.99","size":"12329.83","side":"SELL","hash":"12504091e51784b04535dc8f563244d1d739d947","best_bid":"0.13","best_ask":"0.14"}],"timestamp":"1776808415938","event_type":"price_change"}}
{"capturedAt":1776808416,"payload":{"market":"0x125149c5918fc5f8c6d34682f700a898a1a19ea4f4e2ae68ff4c5794ba657074","price_changes":[{"asset_id":"45936375922793925919605092352922707796689801895417366600539442410775071099958","price":"0.86","size":"256.14","side":"BUY","hash":"7f593c094da1a6bf15f0f72cef25787895ddfa4d","best_bid":"0.86","best_ask":"0.87"},{"asset_id":"86520121088881862182423437128238697252500151785248183602134095101149900014256","price":"0.14","size":"256.14","side":"SELL","hash":"f4ad097de7334740adc12df47dc92f4d2f957963","best_bid":"0.13","best_ask":"0.14"}],"timestamp":"1776808415943","event_type":"price_change"}}
{"capturedAt":1776808416,"payload":{"market":"0x125149c5918fc5f8c6d34682f700a898a1a19ea4f4e2ae68ff4c5794ba657074","price_changes":[{"asset_id":"45936375922793925919605092352922707796689801895417366600539442410775071099958","price":"0.86","size":"271.45","side":"BUY","hash":"91e11b304f5b8cd87e230a550f7052f9fc5f96ad","best_bid":"0.86","best_ask":"0.87"},{"asset_id":"86520121088881862182423437128238697252500151785248183602134095101149900014256","price":"0.14","size":"271.45","side":"SELL","hash":"36b90e246cb9a7cc57bd1f3a9ae389aa60cbe73e","best_bid":"0.13","best_ask":"0.14"}],"timestamp":"1776808415959","event_type":"price_change"}}
{"capturedAt":1776808416,"payload":{"market":"0x125149c5918fc5f8c6d34682f700a898a1a19ea4f4e2ae68ff4c5794ba657074","price_changes":[{"asset_id":"45936375922793925919605092352922707796689801895417366600539442410775071099958","price":"0.86","size":"266.45","side":"BUY","hash":"61f050ac8edb6ad2b8ea04c07b00d2383a980009","best_bid":"0.86","best_ask":"0.87"},{"asset_id":"86520121088881862182423437128238697252500151785248183602134095101149900014256","price":"0.14","size":"266.45","side":"SELL","hash":"bc59338cd287ffef11599e39816d96878eb326ad","best_bid":"0.13","best_ask":"0.14"}],"timestamp":"1776808415958","event_type":"price_change"}}
{"capturedAt":1776808416,"payload":{"market":"0x125149c5918fc5f8c6d34682f700a898a1a19ea4f4e2ae68ff4c5794ba657074","price_changes":[{"asset_id":"45936375922793925919605092352922707796689801895417366600539442410775071099958","price":"0.86","size":"254.45","side":"BUY","hash":"536fe9e55b5317f15a2c7035b43b976da252d234","best_bid":"0.86","best_ask":"0.87"},{"asset_id":"86520121088881862182423437128238697252500151785248183602134095101149900014256","price":"0.14","size":"254.45","side":"SELL","hash":"01f3b1994278dfc307d51842c4ca4ad141f8482f","best_bid":"0.13","best_ask":"0.14"}],"timestamp":"1776808415957","event_type":"price_change"}}
{"capturedAt":1776808416,"payload":{"market":"0x125149c5918fc5f8c6d34682f700a898a1a19ea4f4e2ae68ff4c5794ba657074","price_changes":[{"asset_id":"45936375922793925919605092352922707796689801895417366600539442410775071099958","price":"0.86","size":"303.45","side":"BUY","hash":"9163db7629449845cb813a7ed2a7a374dab818d4","best_bid":"0.86","best_ask":"0.87"},{"asset_id":"86520121088881862182423437128238697252500151785248183602134095101149900014256","price":"0.14","size":"303.45","side":"SELL","hash":"1addbc470f0e6cbdd39faed1e1893d9fcca833a7","best_bid":"0.13","best_ask":"0.14"}],"timestamp":"1776808415961","event_type":"price_change"}}
{"capturedAt":1776808416,"payload":{"market":"0x125149c5918fc5f8c6d34682f700a898a1a19ea4f4e2ae68ff4c5794ba657074","price_changes":[{"asset_id":"45936375922793925919605092352922707796689801895417366600539442410775071099958","price":"0.86","size":"253.45","side":"BUY","hash":"bb2340a6bcda7db025d0471d736c236a1e6ae9cf","best_bid":"0.86","best_ask":"0.87"},{"asset_id":"86520121088881862182423437128238697252500151785248183602134095101149900014256","price":"0.14","size":"253.45","side":"SELL","hash":"7aba749aeb5a548c7805adbb85e8b570c22d087c","best_bid":"0.13","best_ask":"0.14"}],"timestamp":"1776808415952","event_type":"price_change"}}
{"capturedAt":1776808416,"payload":{"market":"0x125149c5918fc5f8c6d34682f700a898a1a19ea4f4e2ae68ff4c5794ba657074","price_changes":[{"asset_id":"45936375922793925919605092352922707796689801895417366600539442410775071099958","price":"0.86","size":"324.45","side":"BUY","hash":"f1182fca1d05d78e85626e37af96007dd38a58a9","best_bid":"0.86","best_ask":"0.87"},{"asset_id":"86520121088881862182423437128238697252500151785248183602134095101149900014256","price":"0.14","size":"324.45","side":"SELL","hash":"c365589c64025568a97ab71fd6dad8bdd4249443","best_bid":"0.13","best_ask":"0.14"}],"timestamp":"1776808415963","event_type":"price_change"}}
{"capturedAt":1776808416,"payload":{"market":"0x125149c5918fc5f8c6d34682f700a898a1a19ea4f4e2ae68ff4c5794ba657074","price_changes":[{"asset_id":"45936375922793925919605092352922707796689801895417366600539442410775071099958","price":"0.86","size":"293.45","side":"BUY","hash":"bff8352a4a20d78db6e6ecb5464aa7786700b3a7","best_bid":"0.86","best_ask":"0.87"},{"asset_id":"86520121088881862182423437128238697252500151785248183602134095101149900014256","price":"0.14","size":"293.45","side":"SELL","hash":"9be7e482b77b60da341825b79f8e62bde59d2abb","best_bid":"0.13","best_ask":"0.14"}],"timestamp":"1776808415960","event_type":"price_change"}}
{"capturedAt":1776808416,"payload":{"market":"0x125149c5918fc5f8c6d34682f700a898a1a19ea4f4e2ae68ff4c5794ba657074","price_changes":[{"asset_id":"86520121088881862182423437128238697252500151785248183602134095101149900014256","price":"0.13","size":"149.74","side":"BUY","hash":"63537d0475776f9c58ba9916b3362619749271da","best_bid":"0.13","best_ask":"0.14"},{"asset_id":"45936375922793925919605092352922707796689801895417366600539442410775071099958","price":"0.87","size":"149.74","side":"SELL","hash":"577d4130f321f026275d5a6ea1a01fd7a929ff9f","best_bid":"0.86","best_ask":"0.87"}],"timestamp":"1776808415960","event_type":"price_change"}}
{"capturedAt":1776808416,"payload":{"market":"0x125149c5918fc5f8c6d34682f700a898a1a19ea4f4e2ae68ff4c5794ba657074","price_changes":[{"asset_id":"86520121088881862182423437128238697252500151785248183602134095101149900014256","price":"0.11","size":"391.5","side":"BUY","hash":"3867d5eccf38988b9eaeca8b3137c7896a1fac43","best_bid":"0.13","best_ask":"0.14"},{"asset_id":"45936375922793925919605092352922707796689801895417366600539442410775071099958","price":"0.89","size":"391.5","side":"SELL","hash":"cd63df9f0746ed5b08b30aeb89f179a24d8f9ec9","best_bid":"0.86","best_ask":"0.87"}],"timestamp":"1776808415956","event_type":"price_change"}}
{"capturedAt":1776808416,"payload":{"market":"0x125149c5918fc5f8c6d34682f700a898a1a19ea4f4e2ae68ff4c5794ba657074","price_changes":[{"asset_id":"45936375922793925919605092352922707796689801895417366600539442410775071099958","price":"0.01","size":"12329.83","side":"BUY","hash":"d0fc9f918387c367a409a06ad887556deb154e0a","best_bid":"0.86","best_ask":"0.87"},{"asset_id":"86520121088881862182423437128238697252500151785248183602134095101149900014256","price":"0.99","size":"12329.83","side":"SELL","hash":"69ed05a14d37488f10bf08e23388183c007ef0b8","best_bid":"0.13","best_ask":"0.14"}],"timestamp":"1776808415968","event_type":"price_change"}}
{"capturedAt":1776808416,"payload":{"market":"0x125149c5918fc5f8c6d34682f700a898a1a19ea4f4e2ae68ff4c5794ba657074","price_changes":[{"asset_id":"45936375922793925919605092352922707796689801895417366600539442410775071099958","price":"0.86","size":"314.14","side":"BUY","hash":"58247354f970003ec20d5fc02233ad6d7e191487","best_bid":"0.86","best_ask":"0.87"},{"asset_id":"86520121088881862182423437128238697252500151785248183602134095101149900014256","price":"0.14","size":"314.14","side":"SELL","hash":"314dac9e9da76453801b439af58e5a8fbe48c00a","best_bid":"0.13","best_ask":"0.14"}],"timestamp":"1776808415970","event_type":"price_change"}}
{"capturedAt":1776808416,"payload":{"market":"0x125149c5918fc5f8c6d34682f700a898a1a19ea4f4e2ae68ff4c5794ba657074","price_changes":[{"asset_id":"45936375922793925919605092352922707796689801895417366600539442410775071099958","price":"0.86","size":"319.44","side":"BUY","hash":"ec06077640d725bcb0a135d9ed2c4615e0400d5e","best_bid":"0.86","best_ask":"0.87"},{"asset_id":"86520121088881862182423437128238697252500151785248183602134095101149900014256","price":"0.14","size":"319.44","side":"SELL","hash":"f28bfa4cba36dfbe3dffde849e937d3415fdb736","best_bid":"0.13","best_ask":"0.14"}],"timestamp":"1776808415967","event_type":"price_change"}}
{"capturedAt":1776808416,"payload":{"market":"0x125149c5918fc5f8c6d34682f700a898a1a19ea4f4e2ae68ff4c5794ba657074","price_changes":[{"asset_id":"45936375922793925919605092352922707796689801895417366600539442410775071099958","price":"0.01","size":"12334.83","side":"BUY","hash":"ce90f05a33d16b390fc1c3d2c33b1808af8e49d6","best_bid":"0.86","best_ask":"0.87"},{"asset_id":"86520121088881862182423437128238697252500151785248183602134095101149900014256","price":"0.99","size":"12334.83","side":"SELL","hash":"242fb60db4bcb0fdb91e0fa30b2aa32db1ac84c0","best_bid":"0.13","best_ask":"0.14"}],"timestamp":"1776808415963","event_type":"price_change"}}
{"capturedAt":1776808416,"payload":{"market":"0x125149c5918fc5f8c6d34682f700a898a1a19ea4f4e2ae68ff4c5794ba657074","price_changes":[{"asset_id":"45936375922793925919605092352922707796689801895417366600539442410775071099958","price":"0.86","size":"356.14","side":"BUY","hash":"16d2b6bfaae379c210d84fc34390b89ef90998e7","best_bid":"0.86","best_ask":"0.87"},{"asset_id":"86520121088881862182423437128238697252500151785248183602134095101149900014256","price":"0.14","size":"356.14","side":"SELL","hash":"4e6fe17300837172abc1b07790690b888ffd2690","best_bid":"0.13","best_ask":"0.14"}],"timestamp":"1776808415973","event_type":"price_change"}}
{"capturedAt":1776808416,"payload":{"market":"0x125149c5918fc5f8c6d34682f700a898a1a19ea4f4e2ae68ff4c5794ba657074","price_changes":[{"asset_id":"45936375922793925919605092352922707796689801895417366600539442410775071099958","price":"0.86","size":"350.14","side":"BUY","hash":"a0981151de035d363331f3488c1a43a0210ee9aa","best_bid":"0.86","best_ask":"0.87"},{"asset_id":"86520121088881862182423437128238697252500151785248183602134095101149900014256","price":"0.14","size":"350.14","side":"SELL","hash":"e5fac04c7fc17c2d15f0a2df04ca955d599ee8d6","best_bid":"0.13","best_ask":"0.14"}],"timestamp":"1776808415976","event_type":"price_change"}}
{"capturedAt":1776808416,"payload":{"market":"0x125149c5918fc5f8c6d34682f700a898a1a19ea4f4e2ae68ff4c5794ba657074","price_changes":[{"asset_id":"45936375922793925919605092352922707796689801895417366600539442410775071099958","price":"0.86","size":"329.14","side":"BUY","hash":"d117914b927984417d745c6b2a30e262e43fd4b8","best_bid":"0.86","best_ask":"0.87"},{"asset_id":"86520121088881862182423437128238697252500151785248183602134095101149900014256","price":"0.14","size":"329.14","side":"SELL","hash":"324bbe8b561bbc99dadbb9231ca0e2286171eea7","best_bid":"0.13","best_ask":"0.14"}],"timestamp":"1776808415974","event_type":"price_change"}}
{"capturedAt":1776808416,"payload":{"market":"0x125149c5918fc5f8c6d34682f700a898a1a19ea4f4e2ae68ff4c5794ba657074","price_changes":[{"asset_id":"45936375922793925919605092352922707796689801895417366600539442410775071099958","price":"0.86","size":"312.14","side":"BUY","hash":"3d16040cb5ba313eb47e4455b5e0353fd2a689c4","best_bid":"0.86","best_ask":"0.87"},{"asset_id":"86520121088881862182423437128238697252500151785248183602134095101149900014256","price":"0.14","size":"312.14","side":"SELL","hash":"cb12c6e9de2a269bedcd2988def5c7a41ad44dfd","best_bid":"0.13","best_ask":"0.14"}],"timestamp":"1776808415979","event_type":"price_change"}}
{"capturedAt":1776808416,"payload":{"market":"0x125149c5918fc5f8c6d34682f700a898a1a19ea4f4e2ae68ff4c5794ba657074","price_changes":[{"asset_id":"45936375922793925919605092352922707796689801895417366600539442410775071099958","price":"0.01","size":"12324.83","side":"BUY","hash":"ca15a0729bce743444b44cd417d7f1d3cb29ee13","best_bid":"0.86","best_ask":"0.87"},{"asset_id":"86520121088881862182423437128238697252500151785248183602134095101149900014256","price":"0.99","size":"12324.83","side":"SELL","hash":"5a037526fd76900a812ce560567df8fd6bc0ae41","best_bid":"0.13","best_ask":"0.14"}],"timestamp":"1776808415982","event_type":"price_change"}}
{"capturedAt":1776808416,"payload":{"market":"0x125149c5918fc5f8c6d34682f700a898a1a19ea4f4e2ae68ff4c5794ba657074","price_changes":[{"asset_id":"45936375922793925919605092352922707796689801895417366600539442410775071099958","price":"0.86","size":"340.14","side":"BUY","hash":"2ea322dd547573e2f3dd6f58c15e0c818d365ca4","best_bid":"0.86","best_ask":"0.87"},{"asset_id":"86520121088881862182423437128238697252500151785248183602134095101149900014256","price":"0.14","size":"340.14","side":"SELL","hash":"a03dfa29e061101681c3dddfc52f8d3530b86e1e","best_bid":"0.13","best_ask":"0.14"}],"timestamp":"1776808415978","event_type":"price_change"}}
{"capturedAt":1776808416,"payload":{"market":"0x125149c5918fc5f8c6d34682f700a898a1a19ea4f4e2ae68ff4c5794ba657074","price_changes":[{"asset_id":"45936375922793925919605092352922707796689801895417366600539442410775071099958","price":"0.86","size":"335.14","side":"BUY","hash":"48853fc20d8590f308a8d6567f985d11b21d99a3","best_bid":"0.86","best_ask":"0.87"},{"asset_id":"86520121088881862182423437128238697252500151785248183602134095101149900014256","price":"0.14","size":"335.14","side":"SELL","hash":"06628db5201ac771f5c762a5a6d3767a2486fd68","best_bid":"0.13","best_ask":"0.14"}],"timestamp":"1776808415971","event_type":"price_change"}}
{"capturedAt":1776808416,"payload":{"market":"0x125149c5918fc5f8c6d34682f700a898a1a19ea4f4e2ae68ff4c5794ba657074","price_changes":[{"asset_id":"45936375922793925919605092352922707796689801895417366600539442410775071099958","price":"0.01","size":"12329.83","side":"BUY","hash":"36aaa8aa0d5644671bed0c702966bdc8cb13d08a","best_bid":"0.86","best_ask":"0.87"},{"asset_id":"86520121088881862182423437128238697252500151785248183602134095101149900014256","price":"0.99","size":"12329.83","side":"SELL","hash":"9cc2a7aa30efa8b5d128738e13628d471274a143","best_bid":"0.13","best_ask":"0.14"}],"timestamp":"1776808415988","event_type":"price_change"}}
{"capturedAt":1776808416,"payload":{"market":"0x125149c5918fc5f8c6d34682f700a898a1a19ea4f4e2ae68ff4c5794ba657074","price_changes":[{"asset_id":"45936375922793925919605092352922707796689801895417366600539442410775071099958","price":"0.86","size":"330.27","side":"BUY","hash":"bc90fd0dcc9873029dde56b5c3630d6b40d0ff57","best_bid":"0.86","best_ask":"0.87"},{"asset_id":"86520121088881862182423437128238697252500151785248183602134095101149900014256","price":"0.14","size":"330.27","side":"SELL","hash":"186df27dcd8ed765dd6701ee69e8676a0efedf66","best_bid":"0.13","best_ask":"0.14"}],"timestamp":"1776808415996","event_type":"price_change"}}
{"capturedAt":1776808416,"payload":{"market":"0x125149c5918fc5f8c6d34682f700a898a1a19ea4f4e2ae68ff4c5794ba657074","price_changes":[{"asset_id":"45936375922793925919605092352922707796689801895417366600539442410775071099958","price":"0.86","size":"338.14","side":"BUY","hash":"9f9126171dc7f614a643941ef3379aadaee2f365","best_bid":"0.86","best_ask":"0.87"},{"asset_id":"86520121088881862182423437128238697252500151785248183602134095101149900014256","price":"0.14","size":"338.14","side":"SELL","hash":"0d4560cfac3b5cd28a04eb701857b1df8ff4da3a","best_bid":"0.13","best_ask":"0.14"}],"timestamp":"1776808415986","event_type":"price_change"}}
{"capturedAt":1776808416,"payload":{"market":"0x125149c5918fc5f8c6d34682f700a898a1a19ea4f4e2ae68ff4c5794ba657074","price_changes":[{"asset_id":"45936375922793925919605092352922707796689801895417366600539442410775071099958","price":"0.86","size":"325.14","side":"BUY","hash":"e656dc424c41208479388b637cefa7340f746b67","best_bid":"0.86","best_ask":"0.87"},{"asset_id":"86520121088881862182423437128238697252500151785248183602134095101149900014256","price":"0.14","size":"325.14","side":"SELL","hash":"3a15fe3706649ac1b8910c15eec5e11b8c2e78d8","best_bid":"0.13","best_ask":"0.14"}],"timestamp":"1776808415994","event_type":"price_change"}}
{"capturedAt":1776808416,"payload":{"market":"0x125149c5918fc5f8c6d34682f700a898a1a19ea4f4e2ae68ff4c5794ba657074","price_changes":[{"asset_id":"45936375922793925919605092352922707796689801895417366600539442410775071099958","price":"0.01","size":"12329.83","side":"BUY","hash":"4e70e0e63a2da66aea968d6c8727976b7dbe75e0","best_bid":"0.86","best_ask":"0.87"},{"asset_id":"86520121088881862182423437128238697252500151785248183602134095101149900014256","price":"0.99","size":"12329.83","side":"SELL","hash":"56d63976699ff78a1c62375f3cfd21e06a6cfeb8","best_bid":"0.13","best_ask":"0.14"}],"timestamp":"1776808416006","event_type":"price_change"}}
{"capturedAt":1776808416,"payload":{"market":"0x125149c5918fc5f8c6d34682f700a898a1a19ea4f4e2ae68ff4c5794ba657074","price_changes":[{"asset_id":"45936375922793925919605092352922707796689801895417366600539442410775071099958","price":"0.86","size":"365.27","side":"BUY","hash":"2ef526e03fa669f56f9ff9608eaacb22e68aaea4","best_bid":"0.86","best_ask":"0.87"},{"asset_id":"86520121088881862182423437128238697252500151785248183602134095101149900014256","price":"0.14","size":"365.27","side":"SELL","hash":"8d40387a894410b0362726250021233d6dbf57f3","best_bid":"0.13","best_ask":"0.14"}],"timestamp":"1776808416008","event_type":"price_change"}}
{"capturedAt":1776808416,"payload":{"market":"0x125149c5918fc5f8c6d34682f700a898a1a19ea4f4e2ae68ff4c5794ba657074","price_changes":[{"asset_id":"45936375922793925919605092352922707796689801895417366600539442410775071099958","price":"0.86","size":"381.27","side":"BUY","hash":"b649d2800c299a38cdd28fafd4dac68fbeaa5d33","best_bid":"0.86","best_ask":"0.87"},{"asset_id":"86520121088881862182423437128238697252500151785248183602134095101149900014256","price":"0.14","size":"381.27","side":"SELL","hash":"257eb3b1bf92f91a8a6f40d877876d4dda793c17","best_bid":"0.13","best_ask":"0.14"}],"timestamp":"1776808416011","event_type":"price_change"}}
{"capturedAt":1776808416,"payload":{"market":"0x125149c5918fc5f8c6d34682f700a898a1a19ea4f4e2ae68ff4c5794ba657074","price_changes":[{"asset_id":"45936375922793925919605092352922707796689801895417366600539442410775071099958","price":"0.86","size":"340.27","side":"BUY","hash":"0bef1d4f5a7bf0ba53b3e400aeb3122f5c38e13c","best_bid":"0.86","best_ask":"0.87"},{"asset_id":"86520121088881862182423437128238697252500151785248183602134095101149900014256","price":"0.14","size":"340.27","side":"SELL","hash":"7eb56fe7ae086a5f99e1a472657884d3dba20099","best_bid":"0.13","best_ask":"0.14"}],"timestamp":"1776808416007","event_type":"price_change"}}
{"capturedAt":1776808416,"payload":{"market":"0x125149c5918fc5f8c6d34682f700a898a1a19ea4f4e2ae68ff4c5794ba657074","price_changes":[{"asset_id":"45936375922793925919605092352922707796689801895417366600539442410775071099958","price":"0.8","size":"280.25","side":"BUY","hash":"c8722e5b8f710e26a14bc3f0b9447d6100af2f4c","best_bid":"0.86","best_ask":"0.87"},{"asset_id":"86520121088881862182423437128238697252500151785248183602134095101149900014256","price":"0.2","size":"280.25","side":"SELL","hash":"632a7b7fd9ddf09e58773883b62c76447cc4fad1","best_bid":"0.13","best_ask":"0.14"}],"timestamp":"1776808416012","event_type":"price_change"}}
{"capturedAt":1776808416,"payload":{"market":"0x125149c5918fc5f8c6d34682f700a898a1a19ea4f4e2ae68ff4c5794ba657074","price_changes":[{"asset_id":"45936375922793925919605092352922707796689801895417366600539442410775071099958","price":"0.86","size":"391.27","side":"BUY","hash":"46a9495ec508e3b7ab9a9ec1dd0e298d5aa506eb","best_bid":"0.86","best_ask":"0.87"},{"asset_id":"86520121088881862182423437128238697252500151785248183602134095101149900014256","price":"0.14","size":"391.27","side":"SELL","hash":"d7b3fbefe6c34e2beba66df9d1ee53a68df74a57","best_bid":"0.13","best_ask":"0.14"}],"timestamp":"1776808416009","event_type":"price_change"}}
{"capturedAt":1776808416,"payload":{"market":"0x125149c5918fc5f8c6d34682f700a898a1a19ea4f4e2ae68ff4c5794ba657074","price_changes":[{"asset_id":"45936375922793925919605092352922707796689801895417366600539442410775071099958","price":"0.86","size":"395.27","side":"BUY","hash":"28954d0131dac11d6afb44ff6edc54e9af271404","best_bid":"0.86","best_ask":"0.87"},{"asset_id":"86520121088881862182423437128238697252500151785248183602134095101149900014256","price":"0.14","size":"395.27","side":"SELL","hash":"ae38aa9eea3b8fc4b24fc12637f4366e5e62848c","best_bid":"0.13","best_ask":"0.14"}],"timestamp":"1776808416014","event_type":"price_change"}}
{"capturedAt":1776808416,"payload":{"market":"0x125149c5918fc5f8c6d34682f700a898a1a19ea4f4e2ae68ff4c5794ba657074","price_changes":[{"asset_id":"45936375922793925919605092352922707796689801895417366600539442410775071099958","price":"0.83","size":"354.46","side":"BUY","hash":"1998003ece8912d6ab0ad21993f338a938c3e04d","best_bid":"0.86","best_ask":"0.87"},{"asset_id":"86520121088881862182423437128238697252500151785248183602134095101149900014256","price":"0.17","size":"354.46","side":"SELL","hash":"bebf9321d1d1c52538279874cc6b89a363329995","best_bid":"0.13","best_ask":"0.14"}],"timestamp":"1776808416013","event_type":"price_change"}}
{"capturedAt":1776808416,"payload":{"market":"0x125149c5918fc5f8c6d34682f700a898a1a19ea4f4e2ae68ff4c5794ba657074","price_changes":[{"asset_id":"45936375922793925919605092352922707796689801895417366600539442410775071099958","price":"0.79","size":"184.7","side":"BUY","hash":"acf3b2e75301c3005b644f094d7d6ee3b8a4fc99","best_bid":"0.86","best_ask":"0.87"},{"asset_id":"86520121088881862182423437128238697252500151785248183602134095101149900014256","price":"0.21","size":"184.7","side":"SELL","hash":"0d4863e17dc769385d7bf8c45f5be08aa8fcd34e","best_bid":"0.13","best_ask":"0.14"}],"timestamp":"1776808416010","event_type":"price_change"}}
{"capturedAt":1776808416,"payload":{"market":"0x125149c5918fc5f8c6d34682f700a898a1a19ea4f4e2ae68ff4c5794ba657074","price_changes":[{"asset_id":"45936375922793925919605092352922707796689801895417366600539442410775071099958","price":"0.01","size":"12334.83","side":"BUY","hash":"f735097dd4bfac48517393be3b90ea7525eced2b","best_bid":"0.86","best_ask":"0.87"},{"asset_id":"86520121088881862182423437128238697252500151785248183602134095101149900014256","price":"0.99","size":"12334.83","side":"SELL","hash":"7bda571b35103b50df89830b54710b6d68de3757","best_bid":"0.13","best_ask":"0.14"}],"timestamp":"1776808415999","event_type":"price_change"}}
{"capturedAt":1776808416,"payload":{"market":"0x125149c5918fc5f8c6d34682f700a898a1a19ea4f4e2ae68ff4c5794ba657074","price_changes":[{"asset_id":"45936375922793925919605092352922707796689801895417366600539442410775071099958","price":"0.84","size":"378.63","side":"BUY","hash":"58cd2ce2208fff58c16d22bb098feca0589e985b","best_bid":"0.86","best_ask":"0.87"},{"asset_id":"86520121088881862182423437128238697252500151785248183602134095101149900014256","price":"0.16","size":"378.63","side":"SELL","hash":"2090e43470ad16a007f260a7ba0918411a1501c8","best_bid":"0.13","best_ask":"0.14"}],"timestamp":"1776808416012","event_type":"price_change"}}
{"capturedAt":1776808416,"payload":{"market":"0x125149c5918fc5f8c6d34682f700a898a1a19ea4f4e2ae68ff4c5794ba657074","price_changes":[{"asset_id":"45936375922793925919605092352922707796689801895417366600539442410775071099958","price":"0.86","size":"390.14","side":"BUY","hash":"3cb6c6534601dca499c5405ee802a872bc6deb38","best_bid":"0.86","best_ask":"0.87"},{"asset_id":"86520121088881862182423437128238697252500151785248183602134095101149900014256","price":"0.14","size":"390.14","side":"SELL","hash":"434aaca4cc61a9f4508b13ccac1caf5950a6cff8","best_bid":"0.13","best_ask":"0.14"}],"timestamp":"1776808416016","event_type":"price_change"}}
{"capturedAt":1776808416,"payload":{"market":"0x125149c5918fc5f8c6d34682f700a898a1a19ea4f4e2ae68ff4c5794ba657074","price_changes":[{"asset_id":"45936375922793925919605092352922707796689801895417366600539442410775071099958","price":"0.86","size":"366.14","side":"BUY","hash":"d8db1c50f61fda990328d107470f20c521ae1e3e","best_bid":"0.86","best_ask":"0.87"},{"asset_id":"86520121088881862182423437128238697252500151785248183602134095101149900014256","price":"0.14","size":"366.14","side":"SELL","hash":"1fbd78606651ed6696e215a6b156dddc4883da3a","best_bid":"0.13","best_ask":"0.14"}],"timestamp":"1776808416024","event_type":"price_change"}}
{"capturedAt":1776808416,"payload":{"market":"0x125149c5918fc5f8c6d34682f700a898a1a19ea4f4e2ae68ff4c5794ba657074","price_changes":[{"asset_id":"45936375922793925919605092352922707796689801895417366600539442410775071099958","price":"0.01","size":"12324.83","side":"BUY","hash":"0ad5c28a7da423c94ff729ddc27d7c666347e2d3","best_bid":"0.86","best_ask":"0.87"},{"asset_id":"86520121088881862182423437128238697252500151785248183602134095101149900014256","price":"0.99","size":"12324.83","side":"SELL","hash":"1756441c7b342098d46ee2a329df5651f9d8fbc1","best_bid":"0.13","best_ask":"0.14"}],"timestamp":"1776808416020","event_type":"price_change"}}
{"capturedAt":1776808416,"payload":{"market":"0x125149c5918fc5f8c6d34682f700a898a1a19ea4f4e2ae68ff4c5794ba657074","price_changes":[{"asset_id":"86520121088881862182423437128238697252500151785248183602134095101149900014256","price":"0.13","size":"154.74","side":"BUY","hash":"21a69124b950f69f2398e9ad5a47e4de05d33d30","best_bid":"0.13","best_ask":"0.14"},{"asset_id":"45936375922793925919605092352922707796689801895417366600539442410775071099958","price":"0.87","size":"154.74","side":"SELL","hash":"9de187996396c962a9d6baaa6f7683857ad8e6e7","best_bid":"0.86","best_ask":"0.87"}],"timestamp":"1776808416025","event_type":"price_change"}}
{"capturedAt":1776808416,"payload":{"market":"0x125149c5918fc5f8c6d34682f700a898a1a19ea4f4e2ae68ff4c5794ba657074","price_changes":[{"asset_id":"45936375922793925919605092352922707796689801895417366600539442410775071099958","price":"0.86","size":"354.14","side":"BUY","hash":"fe9774ad99717f1221d4e21c5f113948e3817bda","best_bid":"0.86","best_ask":"0.87"},{"asset_id":"86520121088881862182423437128238697252500151785248183602134095101149900014256","price":"0.14","size":"354.14","side":"SELL","hash":"e973bf178c4b0f2270dfc2f4174a309b6bd606b8","best_bid":"0.13","best_ask":"0.14"}],"timestamp":"1776808416027","event_type":"price_change"}}
{"capturedAt":1776808416,"payload":{"market":"0x125149c5918fc5f8c6d34682f700a898a1a19ea4f4e2ae68ff4c5794ba657074","price_changes":[{"asset_id":"45936375922793925919605092352922707796689801895417366600539442410775071099958","price":"0.86","size":"332.14","side":"BUY","hash":"b0ad99ef1489cd705c2353573bda5f6e6f2811d2","best_bid":"0.86","best_ask":"0.87"},{"asset_id":"86520121088881862182423437128238697252500151785248183602134095101149900014256","price":"0.14","size":"332.14","side":"SELL","hash":"c3d760eb2474ca10b7335d9298da0c10921eb83b","best_bid":"0.13","best_ask":"0.14"}],"timestamp":"1776808416029","event_type":"price_change"}}
{"capturedAt":1776808416,"payload":{"market":"0x125149c5918fc5f8c6d34682f700a898a1a19ea4f4e2ae68ff4c5794ba657074","price_changes":[{"asset_id":"45936375922793925919605092352922707796689801895417366600539442410775071099958","price":"0.82","size":"319.9","side":"BUY","hash":"a240b4044cb2c0708eba6b61f57cc63ef5a83e9e","best_bid":"0.86","best_ask":"0.87"},{"asset_id":"86520121088881862182423437128238697252500151785248183602134095101149900014256","price":"0.18","size":"319.9","side":"SELL","hash":"e48e9656ed56e2135dd4da8a7f85b9177e92e87c","best_bid":"0.13","best_ask":"0.14"}],"timestamp":"1776808416030","event_type":"price_change"}}
{"capturedAt":1776808416,"payload":{"market":"0x125149c5918fc5f8c6d34682f700a898a1a19ea4f4e2ae68ff4c5794ba657074","price_changes":[{"asset_id":"45936375922793925919605092352922707796689801895417366600539442410775071099958","price":"0.86","size":"322.14","side":"BUY","hash":"ffa5f5cf2ae8e4f18f1ecf34f23d2d39b050fb5a","best_bid":"0.86","best_ask":"0.87"},{"asset_id":"86520121088881862182423437128238697252500151785248183602134095101149900014256","price":"0.14","size":"322.14","side":"SELL","hash":"d059c8deb315d145c16ca40b26487477976ae46e","best_bid":"0.13","best_ask":"0.14"}],"timestamp":"1776808416033","event_type":"price_change"}}
{"capturedAt":1776808416,"payload":{"market":"0x125149c5918fc5f8c6d34682f700a898a1a19ea4f4e2ae68ff4c5794ba657074","price_changes":[{"asset_id":"45936375922793925919605092352922707796689801895417366600539442410775071099958","price":"0.83","size":"347.49","side":"BUY","hash":"2ff165b55be5f71817b53de9a0321c1d19e109ad","best_bid":"0.86","best_ask":"0.87"},{"asset_id":"86520121088881862182423437128238697252500151785248183602134095101149900014256","price":"0.17","size":"347.49","side":"SELL","hash":"eaa388ca38d2da78dab56829c4450c5005ad6418","best_bid":"0.13","best_ask":"0.14"}],"timestamp":"1776808416034","event_type":"price_change"}}
{"capturedAt":1776808416,"payload":{"market":"0x125149c5918fc5f8c6d34682f700a898a1a19ea4f4e2ae68ff4c5794ba657074","price_changes":[{"asset_id":"45936375922793925919605092352922707796689801895417366600539442410775071099958","price":"0.86","size":"301.14","side":"BUY","hash":"7c3b0ea1c194d2fc8957366d269d3e64159321d4","best_bid":"0.86","best_ask":"0.87"},{"asset_id":"86520121088881862182423437128238697252500151785248183602134095101149900014256","price":"0.14","size":"301.14","side":"SELL","hash":"232c0103268a55838b5df370d7c677b71768ba19","best_bid":"0.13","best_ask":"0.14"}],"timestamp":"1776808416034","event_type":"price_change"}}
{"capturedAt":1776808416,"payload":{"market":"0x125149c5918fc5f8c6d34682f700a898a1a19ea4f4e2ae68ff4c5794ba657074","price_changes":[{"asset_id":"45936375922793925919605092352922707796689801895417366600539442410775071099958","price":"0.01","size":"12329.83","side":"BUY","hash":"7455b3a0de5b624af2f6e51419de1d15dfa6076c","best_bid":"0.86","best_ask":"0.87"},{"asset_id":"86520121088881862182423437128238697252500151785248183602134095101149900014256","price":"0.99","size":"12329.83","side":"SELL","hash":"d124294eb9694782e1e1eb9bccaf3078be8ed766","best_bid":"0.13","best_ask":"0.14"}],"timestamp":"1776808416037","event_type":"price_change"}}
{"capturedAt":1776808416,"payload":{"market":"0x125149c5918fc5f8c6d34682f700a898a1a19ea4f4e2ae68ff4c5794ba657074","price_changes":[{"asset_id":"86520121088881862182423437128238697252500151785248183602134095101149900014256","price":"0.13","size":"149.74","side":"BUY","hash":"80adeb1323ea16888204b7c0efc7c11aa1d65cc5","best_bid":"0.13","best_ask":"0.14"},{"asset_id":"45936375922793925919605092352922707796689801895417366600539442410775071099958","price":"0.87","size":"149.74","side":"SELL","hash":"4a325317327b5ea067c7a8690ad5550c2c2ca2aa","best_bid":"0.86","best_ask":"0.87"}],"timestamp":"1776808416038","event_type":"price_change"}}
{"capturedAt":1776808416,"payload":{"market":"0x125149c5918fc5f8c6d34682f700a898a1a19ea4f4e2ae68ff4c5794ba657074","price_changes":[{"asset_id":"45936375922793925919605092352922707796689801895417366600539442410775071099958","price":"0.86","size":"311.14","side":"BUY","hash":"55fd762518b2f6f3280401eff1c919fe6fa24347","best_bid":"0.86","best_ask":"0.87"},{"asset_id":"86520121088881862182423437128238697252500151785248183602134095101149900014256","price":"0.14","size":"311.14","side":"SELL","hash":"1b3fef6f81f90610923f23323a3bbef2d9fb1992","best_bid":"0.13","best_ask":"0.14"}],"timestamp":"1776808416040","event_type":"price_change"}}
{"capturedAt":1776808416,"payload":{"market":"0x125149c5918fc5f8c6d34682f700a898a1a19ea4f4e2ae68ff4c5794ba657074","price_changes":[{"asset_id":"45936375922793925919605092352922707796689801895417366600539442410775071099958","price":"0.86","size":"290.14","side":"BUY","hash":"b01dbb98e03030702694a4b19f7517777b3f8af1","best_bid":"0.86","best_ask":"0.87"},{"asset_id":"86520121088881862182423437128238697252500151785248183602134095101149900014256","price":"0.14","size":"290.14","side":"SELL","hash":"076be9e2106ff04c63ca773198034344dbc7beca","best_bid":"0.13","best_ask":"0.14"}],"timestamp":"1776808416041","event_type":"price_change"}}
{"capturedAt":1776808416,"payload":{"market":"0x125149c5918fc5f8c6d34682f700a898a1a19ea4f4e2ae68ff4c5794ba657074","price_changes":[{"asset_id":"45936375922793925919605092352922707796689801895417366600539442410775071099958","price":"0.86","size":"295.56","side":"BUY","hash":"027bc1a56e1023aaeba777d199bad2d30571bf4c","best_bid":"0.86","best_ask":"0.87"},{"asset_id":"86520121088881862182423437128238697252500151785248183602134095101149900014256","price":"0.14","size":"295.56","side":"SELL","hash":"e39446b76353fffb9789bcda66c6fde2537f2b03","best_bid":"0.13","best_ask":"0.14"}],"timestamp":"1776808416042","event_type":"price_change"}}
{"capturedAt":1776808416,"payload":{"market":"0x125149c5918fc5f8c6d34682f700a898a1a19ea4f4e2ae68ff4c5794ba657074","price_changes":[{"asset_id":"45936375922793925919605092352922707796689801895417366600539442410775071099958","price":"0.86","size":"274.56","side":"BUY","hash":"4bffadfa7d1d612be0a585236810a0f3559915fd","best_bid":"0.86","best_ask":"0.87"},{"asset_id":"86520121088881862182423437128238697252500151785248183602134095101149900014256","price":"0.14","size":"274.56","side":"SELL","hash":"091c76c85a19b4e2ab0a4f73dba21a22c39b389c","best_bid":"0.13","best_ask":"0.14"}],"timestamp":"1776808416043","event_type":"price_change"}}
{"capturedAt":1776808416,"payload":{"market":"0x125149c5918fc5f8c6d34682f700a898a1a19ea4f4e2ae68ff4c5794ba657074","price_changes":[{"asset_id":"45936375922793925919605092352922707796689801895417366600539442410775071099958","price":"0.86","size":"301.56","side":"BUY","hash":"7ecacad06acf7570275424c74ce4ec4586a93522","best_bid":"0.86","best_ask":"0.87"},{"asset_id":"86520121088881862182423437128238697252500151785248183602134095101149900014256","price":"0.14","size":"301.56","side":"SELL","hash":"4c0464eacbe588606904f1c00d54c1720df76ebe","best_bid":"0.13","best_ask":"0.14"}],"timestamp":"1776808416043","event_type":"price_change"}}
{"capturedAt":1776808416,"payload":{"market":"0x125149c5918fc5f8c6d34682f700a898a1a19ea4f4e2ae68ff4c5794ba657074","price_changes":[{"asset_id":"45936375922793925919605092352922707796689801895417366600539442410775071099958","price":"0.86","size":"280.56","side":"BUY","hash":"542379bf088dc06cc5c06902fc9196eb9b361cbb","best_bid":"0.86","best_ask":"0.87"},{"asset_id":"86520121088881862182423437128238697252500151785248183602134095101149900014256","price":"0.14","size":"280.56","side":"SELL","hash":"e3c8d18e16b87ef930c3c881de20ff331c9a9486","best_bid":"0.13","best_ask":"0.14"}],"timestamp":"1776808416046","event_type":"price_change"}}
{"capturedAt":1776808416,"payload":{"market":"0x125149c5918fc5f8c6d34682f700a898a1a19ea4f4e2ae68ff4c5794ba657074","price_changes":[{"asset_id":"45936375922793925919605092352922707796689801895417366600539442410775071099958","price":"0.01","size":"12334.83","side":"BUY","hash":"f44a3fb32744d54d8ce455bf921b88f452fa4d39","best_bid":"0.86","best_ask":"0.87"},{"asset_id":"86520121088881862182423437128238697252500151785248183602134095101149900014256","price":"0.99","size":"12334.83","side":"SELL","hash":"1a711334bb9988615b7eac4bc0bc48c39780a1de","best_bid":"0.13","best_ask":"0.14"}],"timestamp":"1776808416049","event_type":"price_change"}}
{"capturedAt":1776808416,"payload":{"market":"0x125149c5918fc5f8c6d34682f700a898a1a19ea4f4e2ae68ff4c5794ba657074","price_changes":[{"asset_id":"45936375922793925919605092352922707796689801895417366600539442410775071099958","price":"0.01","size":"12329.83","side":"BUY","hash":"6352f3022637831520fdcf0c14de6a4ed68d004e","best_bid":"0.86","best_ask":"0.87"},{"asset_id":"86520121088881862182423437128238697252500151785248183602134095101149900014256","price":"0.99","size":"12329.83","side":"SELL","hash":"0c905b8e6597adfb3dbdef7dbf95c0b1c08e7742","best_bid":"0.13","best_ask":"0.14"}],"timestamp":"1776808416055","event_type":"price_change"}}
{"capturedAt":1776808416,"payload":{"market":"0x125149c5918fc5f8c6d34682f700a898a1a19ea4f4e2ae68ff4c5794ba657074","price_changes":[{"asset_id":"45936375922793925919605092352922707796689801895417366600539442410775071099958","price":"0.86","size":"293.56","side":"BUY","hash":"133b8d2537bd17036cf0149db1295c69a3de7186","best_bid":"0.86","best_ask":"0.87"},{"asset_id":"86520121088881862182423437128238697252500151785248183602134095101149900014256","price":"0.14","size":"293.56","side":"SELL","hash":"a736732b0a667fbbf04796bba4683f3b20d8fdac","best_bid":"0.13","best_ask":"0.14"}],"timestamp":"1776808416057","event_type":"price_change"}}
{"capturedAt":1776808416,"payload":{"market":"0x125149c5918fc5f8c6d34682f700a898a1a19ea4f4e2ae68ff4c5794ba657074","price_changes":[{"asset_id":"45936375922793925919605092352922707796689801895417366600539442410775071099958","price":"0.86","size":"267.56","side":"BUY","hash":"a178017b52644e228252f15e12d9af12326c53a1","best_bid":"0.86","best_ask":"0.87"},{"asset_id":"86520121088881862182423437128238697252500151785248183602134095101149900014256","price":"0.14","size":"267.56","side":"SELL","hash":"6a20938f5d72d25b71dbe2ec52e732971a0d92f8","best_bid":"0.13","best_ask":"0.14"}],"timestamp":"1776808416058","event_type":"price_change"}}
{"capturedAt":1776808416,"payload":{"market":"0x125149c5918fc5f8c6d34682f700a898a1a19ea4f4e2ae68ff4c5794ba657074","price_changes":[{"asset_id":"45936375922793925919605092352922707796689801895417366600539442410775071099958","price":"0.86","size":"272.56","side":"BUY","hash":"381e1e346b964249e3b58fe9220f4aa206cecf38","best_bid":"0.86","best_ask":"0.87"},{"asset_id":"86520121088881862182423437128238697252500151785248183602134095101149900014256","price":"0.14","size":"272.56","side":"SELL","hash":"4ebf0f7560a25133d5e2957f41df96537fe82ec5","best_bid":"0.13","best_ask":"0.14"}],"timestamp":"1776808416060","event_type":"price_change"}}
{"capturedAt":1776808416,"payload":{"market":"0x125149c5918fc5f8c6d34682f700a898a1a19ea4f4e2ae68ff4c5794ba657074","price_changes":[{"asset_id":"45936375922793925919605092352922707796689801895417366600539442410775071099958","price":"0.86","size":"277.56","side":"BUY","hash":"45e60ec849be003a09168da04607cbab552e5fd1","best_bid":"0.86","best_ask":"0.87"},{"asset_id":"86520121088881862182423437128238697252500151785248183602134095101149900014256","price":"0.14","size":"277.56","side":"SELL","hash":"a7d32786edf54c0e9a1a74f8dda0a73bffbfab07","best_bid":"0.13","best_ask":"0.14"}],"timestamp":"1776808416060","event_type":"price_change"}}
{"capturedAt":1776808416,"payload":{"market":"0x125149c5918fc5f8c6d34682f700a898a1a19ea4f4e2ae68ff4c5794ba657074","price_changes":[{"asset_id":"45936375922793925919605092352922707796689801895417366600539442410775071099958","price":"0.86","size":"295.56","side":"BUY","hash":"2227c0a45552feb2d5086c7ab9c89e1c900f6893","best_bid":"0.86","best_ask":"0.87"},{"asset_id":"86520121088881862182423437128238697252500151785248183602134095101149900014256","price":"0.14","size":"295.56","side":"SELL","hash":"af123885fe84e86058f96fa0042ebfaf691fba3c","best_bid":"0.13","best_ask":"0.14"}],"timestamp":"1776808416061","event_type":"price_change"}}
{"capturedAt":1776808416,"payload":{"market":"0x125149c5918fc5f8c6d34682f700a898a1a19ea4f4e2ae68ff4c5794ba657074","price_changes":[{"asset_id":"86520121088881862182423437128238697252500151785248183602134095101149900014256","price":"0.11","size":"386.5","side":"BUY","hash":"6211c9bafe30e428ad12200ef366f3d0bb618808","best_bid":"0.13","best_ask":"0.14"},{"asset_id":"45936375922793925919605092352922707796689801895417366600539442410775071099958","price":"0.89","size":"386.5","side":"SELL","hash":"69bfc4811c7b5fff86da0ef66bbb7e6929aef388","best_bid":"0.86","best_ask":"0.87"}],"timestamp":"1776808416062","event_type":"price_change"}}
{"capturedAt":1776808416,"payload":{"market":"0x125149c5918fc5f8c6d34682f700a898a1a19ea4f4e2ae68ff4c5794ba657074","price_changes":[{"asset_id":"45936375922793925919605092352922707796689801895417366600539442410775071099958","price":"0.86","size":"319.56","side":"BUY","hash":"1f1f140494f8c3bc84d919ad16a519549ec3f20a","best_bid":"0.86","best_ask":"0.87"},{"asset_id":"86520121088881862182423437128238697252500151785248183602134095101149900014256","price":"0.14","size":"319.56","side":"SELL","hash":"9c85abc63935d2d5153c3de702d430a7f65336d7","best_bid":"0.13","best_ask":"0.14"}],"timestamp":"1776808416063","event_type":"price_change"}}
{"capturedAt":1776808416,"payload":{"market":"0x125149c5918fc5f8c6d34682f700a898a1a19ea4f4e2ae68ff4c5794ba657074","price_changes":[{"asset_id":"45936375922793925919605092352922707796689801895417366600539442410775071099958","price":"0.86","size":"340.56","side":"BUY","hash":"c81670319ae03e42d9f4ee153da58f9b573a7aeb","best_bid":"0.86","best_ask":"0.87"},{"asset_id":"86520121088881862182423437128238697252500151785248183602134095101149900014256","price":"0.14","size":"340.56","side":"SELL","hash":"453ea12eb15d1317bb95fa88450c809e29e114f1","best_bid":"0.13","best_ask":"0.14"}],"timestamp":"1776808416064","event_type":"price_change"}}
{"capturedAt":1776808416,"payload":{"market":"0x125149c5918fc5f8c6d34682f700a898a1a19ea4f4e2ae68ff4c5794ba657074","price_changes":[{"asset_id":"45936375922793925919605092352922707796689801895417366600539442410775071099958","price":"0.86","size":"335.14","side":"BUY","hash":"2aa265895272d837a4ffdd157c8eb955ae08d6fa","best_bid":"0.86","best_ask":"0.87"},{"asset_id":"86520121088881862182423437128238697252500151785248183602134095101149900014256","price":"0.14","size":"335.14","side":"SELL","hash":"d88681be991be0f1900b762539d8b014f0ffe1af","best_bid":"0.13","best_ask":"0.14"}],"timestamp":"1776808416064","event_type":"price_change"}}
{"capturedAt":1776808416,"payload":{"market":"0x125149c5918fc5f8c6d34682f700a898a1a19ea4f4e2ae68ff4c5794ba657074","price_changes":[{"asset_id":"45936375922793925919605092352922707796689801895417366600539442410775071099958","price":"0.86","size":"358.14","side":"BUY","hash":"5c369b53aadc8ae86288d233ef4c652092c4b6c5","best_bid":"0.86","best_ask":"0.87"},{"asset_id":"86520121088881862182423437128238697252500151785248183602134095101149900014256","price":"0.14","size":"358.14","side":"SELL","hash":"5f32f391051265e86d6bc196edcf06b578b0d80f","best_bid":"0.13","best_ask":"0.14"}],"timestamp":"1776808416066","event_type":"price_change"}}
{"capturedAt":1776808416,"payload":{"market":"0x125149c5918fc5f8c6d34682f700a898a1a19ea4f4e2ae68ff4c5794ba657074","price_changes":[{"asset_id":"45936375922793925919605092352922707796689801895417366600539442410775071099958","price":"0.01","size":"12324.83","side":"BUY","hash":"f23a74c17dee0124106a95ebede84c5b0ad3996b","best_bid":"0.86","best_ask":"0.87"},{"asset_id":"86520121088881862182423437128238697252500151785248183602134095101149900014256","price":"0.99","size":"12324.83","side":"SELL","hash":"7a8d16d073b83d2ddc3fe7ae76a1cb5d180f1dad","best_bid":"0.13","best_ask":"0.14"}],"timestamp":"1776808416067","event_type":"price_change"}}
{"capturedAt":1776808416,"payload":{"market":"0x125149c5918fc5f8c6d34682f700a898a1a19ea4f4e2ae68ff4c5794ba657074","price_changes":[{"asset_id":"45936375922793925919605092352922707796689801895417366600539442410775071099958","price":"0.86","size":"379.14","side":"BUY","hash":"a6b6dd631920f7990e2bba4f6a5a6a1f861bbca6","best_bid":"0.86","best_ask":"0.87"},{"asset_id":"86520121088881862182423437128238697252500151785248183602134095101149900014256","price":"0.14","size":"379.14","side":"SELL","hash":"9fdf2008edb95c4a33d6d2546c72cadb3a51ea28","best_bid":"0.13","best_ask":"0.14"}],"timestamp":"1776808416074","event_type":"price_change"}}
{"capturedAt":1776808416,"payload":{"market":"0x125149c5918fc5f8c6d34682f700a898a1a19ea4f4e2ae68ff4c5794ba657074","price_changes":[{"asset_id":"45936375922793925919605092352922707796689801895417366600539442410775071099958","price":"0.86","size":"354.14","side":"BUY","hash":"59b9d3ee8302eb413cbe4a88d6746202c88275f5","best_bid":"0.86","best_ask":"0.87"},{"asset_id":"86520121088881862182423437128238697252500151785248183602134095101149900014256","price":"0.14","size":"354.14","side":"SELL","hash":"472f32f13d88cfa0e8149a18d2914aabbbcabdf1","best_bid":"0.13","best_ask":"0.14"}],"timestamp":"1776808416077","event_type":"price_change"}}
{"capturedAt":1776808416,"payload":{"market":"0x125149c5918fc5f8c6d34682f700a898a1a19ea4f4e2ae68ff4c5794ba657074","price_changes":[{"asset_id":"45936375922793925919605092352922707796689801895417366600539442410775071099958","price":"0.86","size":"344.14","side":"BUY","hash":"c9e06d29d2dd915a7208b80b728185457a5b3b1c","best_bid":"0.86","best_ask":"0.87"},{"asset_id":"86520121088881862182423437128238697252500151785248183602134095101149900014256","price":"0.14","size":"344.14","side":"SELL","hash":"1f16dfc4c2a221f63d3f5c9ff1992004c6b8efc2","best_bid":"0.13","best_ask":"0.14"}],"timestamp":"1776808416079","event_type":"price_change"}}
{"capturedAt":1776808416,"payload":{"market":"0x125149c5918fc5f8c6d34682f700a898a1a19ea4f4e2ae68ff4c5794ba657074","price_changes":[{"asset_id":"45936375922793925919605092352922707796689801895417366600539442410775071099958","price":"0.86","size":"323.26","side":"BUY","hash":"a90f9ac1074abd4d39396e6bcb39c92e797f59f8","best_bid":"0.86","best_ask":"0.87"},{"asset_id":"86520121088881862182423437128238697252500151785248183602134095101149900014256","price":"0.14","size":"323.26","side":"SELL","hash":"c034fb40ef2582a1e9540a0fc34a1f60f84c2bd5","best_bid":"0.13","best_ask":"0.14"}],"timestamp":"1776808416084","event_type":"price_change"}}
{"capturedAt":1776808416,"payload":{"market":"0x125149c5918fc5f8c6d34682f700a898a1a19ea4f4e2ae68ff4c5794ba657074","price_changes":[{"asset_id":"45936375922793925919605092352922707796689801895417366600539442410775071099958","price":"0.86","size":"349.26","side":"BUY","hash":"ca751fc8f7d1244cb9d13893469ef79eb5248895","best_bid":"0.86","best_ask":"0.87"},{"asset_id":"86520121088881862182423437128238697252500151785248183602134095101149900014256","price":"0.14","size":"349.26","side":"SELL","hash":"020d8ea8dcadae1ca54e5ea6c878d4abfacddced","best_bid":"0.13","best_ask":"0.14"}],"timestamp":"1776808416083","event_type":"price_change"}}
{"capturedAt":1776808416,"payload":{"market":"0x125149c5918fc5f8c6d34682f700a898a1a19ea4f4e2ae68ff4c5794ba657074","price_changes":[{"asset_id":"45936375922793925919605092352922707796689801895417366600539442410775071099958","price":"0.86","size":"328.79","side":"BUY","hash":"7a8ae783f1a61306a23755d76228320f9a8c72a2","best_bid":"0.86","best_ask":"0.87"},{"asset_id":"86520121088881862182423437128238697252500151785248183602134095101149900014256","price":"0.14","size":"328.79","side":"SELL","hash":"91d3e662e9baae9d8a65fa48c59c9fe3a1ac9651","best_bid":"0.13","best_ask":"0.14"}],"timestamp":"1776808416087","event_type":"price_change"}}
{"capturedAt":1776808416,"payload":{"market":"0x125149c5918fc5f8c6d34682f700a898a1a19ea4f4e2ae68ff4c5794ba657074","price_changes":[{"asset_id":"45936375922793925919605092352922707796689801895417366600539442410775071099958","price":"0.86","size":"353.79","side":"BUY","hash":"715162ce5dcad10b29a9efca5280dd8ebaa9e3bf","best_bid":"0.86","best_ask":"0.87"},{"asset_id":"86520121088881862182423437128238697252500151785248183602134095101149900014256","price":"0.14","size":"353.79","side":"SELL","hash":"cc01307671a7661c4f5b4a83b09bc214525c70e2","best_bid":"0.13","best_ask":"0.14"}],"timestamp":"1776808416088","event_type":"price_change"}}
{"capturedAt":1776808416,"payload":{"market":"0x125149c5918fc5f8c6d34682f700a898a1a19ea4f4e2ae68ff4c5794ba657074","price_changes":[{"asset_id":"45936375922793925919605092352922707796689801895417366600539442410775071099958","price":"0.01","size":"12329.83","side":"BUY","hash":"99ea2d6d1480be0aaf403e18e2bd20034c0c5b87","best_bid":"0.86","best_ask":"0.87"},{"asset_id":"86520121088881862182423437128238697252500151785248183602134095101149900014256","price":"0.99","size":"12329.83","side":"SELL","hash":"38c87c975a07fcec583cd8445cab4e29098511ca","best_bid":"0.13","best_ask":"0.14"}],"timestamp":"1776808416089","event_type":"price_change"}}
{"capturedAt":1776808416,"payload":{"market":"0x125149c5918fc5f8c6d34682f700a898a1a19ea4f4e2ae68ff4c5794ba657074","price_changes":[{"asset_id":"45936375922793925919605092352922707796689801895417366600539442410775071099958","price":"0.86","size":"339.79","side":"BUY","hash":"a916862de6198d5dd5bd4097d1f1734d7e9e69bc","best_bid":"0.86","best_ask":"0.87"},{"asset_id":"86520121088881862182423437128238697252500151785248183602134095101149900014256","price":"0.14","size":"339.79","side":"SELL","hash":"cdd47bc364c35d1b1a2a9c23d4789a10669ecff4","best_bid":"0.13","best_ask":"0.14"}],"timestamp":"1776808416090","event_type":"price_change"}}
{"capturedAt":1776808416,"payload":{"market":"0x125149c5918fc5f8c6d34682f700a898a1a19ea4f4e2ae68ff4c5794ba657074","price_changes":[{"asset_id":"45936375922793925919605092352922707796689801895417366600539442410775071099958","price":"0.86","size":"344.79","side":"BUY","hash":"08659c85a5e372f8b4796db4d84b2933dd48acd0","best_bid":"0.86","best_ask":"0.87"},{"asset_id":"86520121088881862182423437128238697252500151785248183602134095101149900014256","price":"0.14","size":"344.79","side":"SELL","hash":"7c70a70b586fc8677ac8c82b360abdf1b69ad321","best_bid":"0.13","best_ask":"0.14"}],"timestamp":"1776808416092","event_type":"price_change"}}
{"capturedAt":1776808416,"payload":{"market":"0x125149c5918fc5f8c6d34682f700a898a1a19ea4f4e2ae68ff4c5794ba657074","price_changes":[{"asset_id":"86520121088881862182423437128238697252500151785248183602134095101149900014256","price":"0.12","size":"352.5","side":"BUY","hash":"6cb056a98fe68af073d09e3abd8dbba92cebc2d6","best_bid":"0.13","best_ask":"0.14"},{"asset_id":"45936375922793925919605092352922707796689801895417366600539442410775071099958","price":"0.88","size":"352.5","side":"SELL","hash":"d9d572e2b31cf4b1d4dc9e543073298a7d997812","best_bid":"0.86","best_ask":"0.87"}],"timestamp":"1776808416092","event_type":"price_change"}}
{"capturedAt":1776808416,"payload":{"market":"0x125149c5918fc5f8c6d34682f700a898a1a19ea4f4e2ae68ff4c5794ba657074","price_changes":[{"asset_id":"86520121088881862182423437128238697252500151785248183602134095101149900014256","price":"0.11","size":"391.5","side":"BUY","hash":"ea21ac6ada7880ab748f712d1d228affc6120c48","best_bid":"0.13","best_ask":"0.14"},{"asset_id":"45936375922793925919605092352922707796689801895417366600539442410775071099958","price":"0.89","size":"391.5","side":"SELL","hash":"59847833d8cd58b287b99d0bee4dd9fad1d0f94f","best_bid":"0.86","best_ask":"0.87"}],"timestamp":"1776808416093","event_type":"price_change"}}
{"capturedAt":1776808416,"payload":{"market":"0x125149c5918fc5f8c6d34682f700a898a1a19ea4f4e2ae68ff4c5794ba657074","price_changes":[{"asset_id":"45936375922793925919605092352922707796689801895417366600539442410775071099958","price":"0.83","size":"354.46","side":"BUY","hash":"c0f039f6fe30750d4ddb8f24a49b329f6b669c84","best_bid":"0.86","best_ask":"0.87"},{"asset_id":"86520121088881862182423437128238697252500151785248183602134095101149900014256","price":"0.17","size":"354.46","side":"SELL","hash":"54e73d75eb1eaffd8ce95bcbd5a68d77494a3eca","best_bid":"0.13","best_ask":"0.14"}],"timestamp":"1776808416094","event_type":"price_change"}}
{"capturedAt":1776808416,"payload":{"market":"0x125149c5918fc5f8c6d34682f700a898a1a19ea4f4e2ae68ff4c5794ba657074","price_changes":[{"asset_id":"45936375922793925919605092352922707796689801895417366600539442410775071099958","price":"0.86","size":"334.79","side":"BUY","hash":"8781c2a49805cbd4ba0c14de451411fbdcaa61de","best_bid":"0.86","best_ask":"0.87"},{"asset_id":"86520121088881862182423437128238697252500151785248183602134095101149900014256","price":"0.14","size":"334.79","side":"SELL","hash":"979b3793650b91ef90ab7c140af2ceb9aa4190be","best_bid":"0.13","best_ask":"0.14"}],"timestamp":"1776808416097","event_type":"price_change"}}
{"capturedAt":1776808416,"payload":{"market":"0x125149c5918fc5f8c6d34682f700a898a1a19ea4f4e2ae68ff4c5794ba657074","price_changes":[{"asset_id":"45936375922793925919605092352922707796689801895417366600539442410775071099958","price":"0.01","size":"12334.83","side":"BUY","hash":"424adf6f30ffc99ad8d4ccd0f32c038df0496614","best_bid":"0.86","best_ask":"0.87"},{"asset_id":"86520121088881862182423437128238697252500151785248183602134095101149900014256","price":"0.99","size":"12334.83","side":"SELL","hash":"d876b635225d7f931ba20c9777ff74a5187f1522","best_bid":"0.13","best_ask":"0.14"}],"timestamp":"1776808416099","event_type":"price_change"}}
{"capturedAt":1776808416,"payload":{"market":"0x125149c5918fc5f8c6d34682f700a898a1a19ea4f4e2ae68ff4c5794ba657074","price_changes":[{"asset_id":"45936375922793925919605092352922707796689801895417366600539442410775071099958","price":"0.82","size":"325.78","side":"BUY","hash":"af595a1c2a08ade5bc4bbf16111ecae517ed59a1","best_bid":"0.86","best_ask":"0.87"},{"asset_id":"86520121088881862182423437128238697252500151785248183602134095101149900014256","price":"0.18","size":"325.78","side":"SELL","hash":"0cd56a03412f83b1ef5fd1b6b8890da07e7efa2c","best_bid":"0.13","best_ask":"0.14"}],"timestamp":"1776808416103","event_type":"price_change"}}
{"capturedAt":1776808416,"payload":{"market":"0x125149c5918fc5f8c6d34682f700a898a1a19ea4f4e2ae68ff4c5794ba657074","price_changes":[{"asset_id":"45936375922793925919605092352922707796689801895417366600539442410775071099958","price":"0.86","size":"359.79","side":"BUY","hash":"b4e696dfaa5a687ea8d69be47d9152ad156d46b1","best_bid":"0.86","best_ask":"0.87"},{"asset_id":"86520121088881862182423437128238697252500151785248183602134095101149900014256","price":"0.14","size":"359.79","side":"SELL","hash":"a4264c837454fec7840e588fca0b3456a3ca7b17","best_bid":"0.13","best_ask":"0.14"}],"timestamp":"1776808416105","event_type":"price_change"}}
{"capturedAt":1776808416,"payload":{"market":"0x125149c5918fc5f8c6d34682f700a898a1a19ea4f4e2ae68ff4c5794ba657074","price_changes":[{"asset_id":"45936375922793925919605092352922707796689801895417366600539442410775071099958","price":"0.86","size":"369.79","side":"BUY","hash":"af381f3979090b4bc8376020f10c169ce30da595","best_bid":"0.86","best_ask":"0.87"},{"asset_id":"86520121088881862182423437128238697252500151785248183602134095101149900014256","price":"0.14","size":"369.79","side":"SELL","hash":"0c3dafd6f230a30cafb1e39d3d9723a09c3c3fa4","best_bid":"0.13","best_ask":"0.14"}],"timestamp":"1776808416107","event_type":"price_change"}}
{"capturedAt":1776808416,"payload":{"market":"0x125149c5918fc5f8c6d34682f700a898a1a19ea4f4e2ae68ff4c5794ba657074","price_changes":[{"asset_id":"45936375922793925919605092352922707796689801895417366600539442410775071099958","price":"0.01","size":"12329.83","side":"BUY","hash":"aef7568aa68cf8e61daa80896aae4ac636edc53b","best_bid":"0.86","best_ask":"0.87"},{"asset_id":"86520121088881862182423437128238697252500151785248183602134095101149900014256","price":"0.99","size":"12329.83","side":"SELL","hash":"6591e65edb940afd25a6f37d162d171a75c68e88","best_bid":"0.13","best_ask":"0.14"}],"timestamp":"1776808416108","event_type":"price_change"}}
{"capturedAt":1776808416,"payload":{"market":"0x125149c5918fc5f8c6d34682f700a898a1a19ea4f4e2ae68ff4c5794ba657074","price_changes":[{"asset_id":"45936375922793925919605092352922707796689801895417366600539442410775071099958","price":"0.86","size":"364.67","side":"BUY","hash":"b820b31c04517af110b988870c2e599c2c4f83be","best_bid":"0.86","best_ask":"0.87"},{"asset_id":"86520121088881862182423437128238697252500151785248183602134095101149900014256","price":"0.14","size":"364.67","side":"SELL","hash":"855556af782a4abcfe27a8ea02176c9ace14aeb9","best_bid":"0.13","best_ask":"0.14"}],"timestamp":"1776808416109","event_type":"price_change"}}
{"capturedAt":1776808416,"payload":{"market":"0x125149c5918fc5f8c6d34682f700a898a1a19ea4f4e2ae68ff4c5794ba657074","price_changes":[{"asset_id":"45936375922793925919605092352922707796689801895417366600539442410775071099958","price":"0.86","size":"389.67","side":"BUY","hash":"0aa3a6da8e0542d401d858e17aca8bf569bb322c","best_bid":"0.86","best_ask":"0.87"},{"asset_id":"86520121088881862182423437128238697252500151785248183602134095101149900014256","price":"0.14","size":"389.67","side":"SELL","hash":"2e2fcdaa3e004991602ee13fa5d6cc572efb2821","best_bid":"0.13","best_ask":"0.14"}],"timestamp":"1776808416110","event_type":"price_change"}}
{"capturedAt":1776808416,"payload":{"market":"0x125149c5918fc5f8c6d34682f700a898a1a19ea4f4e2ae68ff4c5794ba657074","price_changes":[{"asset_id":"45936375922793925919605092352922707796689801895417366600539442410775071099958","price":"0.86","size":"384.14","side":"BUY","hash":"1c17ec6860653e1e28b1c12625fa4541e8fa5053","best_bid":"0.86","best_ask":"0.87"},{"asset_id":"86520121088881862182423437128238697252500151785248183602134095101149900014256","price":"0.14","size":"384.14","side":"SELL","hash":"49b80ee786d52b798b32769a1e953d88a0d54c72","best_bid":"0.13","best_ask":"0.14"}],"timestamp":"1776808416110","event_type":"price_change"}}
{"capturedAt":1776808416,"payload":{"market":"0x125149c5918fc5f8c6d34682f700a898a1a19ea4f4e2ae68ff4c5794ba657074","price_changes":[{"asset_id":"45936375922793925919605092352922707796689801895417366600539442410775071099958","price":"0.86","size":"344.14","side":"BUY","hash":"3347198277ed085bd0740f7593fcaae28495406d","best_bid":"0.86","best_ask":"0.87"},{"asset_id":"86520121088881862182423437128238697252500151785248183602134095101149900014256","price":"0.14","size":"344.14","side":"SELL","hash":"6b75a0af5799eae044ef06c28a867fcd90eee56a","best_bid":"0.13","best_ask":"0.14"}],"timestamp":"1776808416130","event_type":"price_change"}}
{"capturedAt":1776808416,"payload":{"market":"0x125149c5918fc5f8c6d34682f700a898a1a19ea4f4e2ae68ff4c5794ba657074","price_changes":[{"asset_id":"45936375922793925919605092352922707796689801895417366600539442410775071099958","price":"0.86","size":"357.14","side":"BUY","hash":"9583c2b20b4e399f58277cadbffbff66aae415fd","best_bid":"0.86","best_ask":"0.87"},{"asset_id":"86520121088881862182423437128238697252500151785248183602134095101149900014256","price":"0.14","size":"357.14","side":"SELL","hash":"62381ea1718d9cde938d5c3c0914192c585366e8","best_bid":"0.13","best_ask":"0.14"}],"timestamp":"1776808416132","event_type":"price_change"}}
{"capturedAt":1776808416,"payload":{"market":"0x125149c5918fc5f8c6d34682f700a898a1a19ea4f4e2ae68ff4c5794ba657074","price_changes":[{"asset_id":"45936375922793925919605092352922707796689801895417366600539442410775071099958","price":"0.01","size":"12324.83","side":"BUY","hash":"25fdfae1682234049a574ead646eb10ac6ab9fac","best_bid":"0.86","best_ask":"0.87"},{"asset_id":"86520121088881862182423437128238697252500151785248183602134095101149900014256","price":"0.99","size":"12324.83","side":"SELL","hash":"9d4e080b53ae9fa6fdf77e5566d82bfa15bcef49","best_bid":"0.13","best_ask":"0.14"}],"timestamp":"1776808416130","event_type":"price_change"}}
{"capturedAt":1776808416,"payload":{"market":"0x125149c5918fc5f8c6d34682f700a898a1a19ea4f4e2ae68ff4c5794ba657074","price_changes":[{"asset_id":"86520121088881862182423437128238697252500151785248183602134095101149900014256","price":"0.11","size":"396.5","side":"BUY","hash":"475d644eb27ad93760f72ef30d07a387531cede2","best_bid":"0.13","best_ask":"0.14"},{"asset_id":"45936375922793925919605092352922707796689801895417366600539442410775071099958","price":"0.89","size":"396.5","side":"SELL","hash":"0291925006689d8a5f13ae81d17e4acfc67bd4fd","best_bid":"0.86","best_ask":"0.87"}],"timestamp":"1776808416131","event_type":"price_change"}}
{"capturedAt":1776808416,"payload":{"market":"0x125149c5918fc5f8c6d34682f700a898a1a19ea4f4e2ae68ff4c5794ba657074","price_changes":[{"asset_id":"45936375922793925919605092352922707796689801895417366600539442410775071099958","price":"0.86","size":"367.14","side":"BUY","hash":"3584f3c42078582a90f80530990ffaf0f831ec5f","best_bid":"0.86","best_ask":"0.87"},{"asset_id":"86520121088881862182423437128238697252500151785248183602134095101149900014256","price":"0.14","size":"367.14","side":"SELL","hash":"c69b31d7c49970db20d9094ea2867a86425495dc","best_bid":"0.13","best_ask":"0.14"}],"timestamp":"1776808416133","event_type":"price_change"}}
{"capturedAt":1776808416,"payload":{"market":"0x125149c5918fc5f8c6d34682f700a898a1a19ea4f4e2ae68ff4c5794ba657074","price_changes":[{"asset_id":"86520121088881862182423437128238697252500151785248183602134095101149900014256","price":"0.09","size":"223.44","side":"BUY","hash":"3d5769b047801e4d71741ebbb23b91e2d15d99a9","best_bid":"0.13","best_ask":"0.14"},{"asset_id":"45936375922793925919605092352922707796689801895417366600539442410775071099958","price":"0.91","size":"223.44","side":"SELL","hash":"eb0498491c256a8bcb3450b670ebaa0980ad4824","best_bid":"0.86","best_ask":"0.87"}],"timestamp":"1776808416134","event_type":"price_change"}}
{"capturedAt":1776808416,"payload":{"market":"0x125149c5918fc5f8c6d34682f700a898a1a19ea4f4e2ae68ff4c5794ba657074","price_changes":[{"asset_id":"45936375922793925919605092352922707796689801895417366600539442410775071099958","price":"0.86","size":"343.14","side":"BUY","hash":"45d157986e1a25cdd8e7426b49e25fb7c4467b68","best_bid":"0.86","best_ask":"0.87"},{"asset_id":"86520121088881862182423437128238697252500151785248183602134095101149900014256","price":"0.14","size":"343.14","side":"SELL","hash":"eb3db7ab70c8cb39827625bf8774353f768f5457","best_bid":"0.13","best_ask":"0.14"}],"timestamp":"1776808416134","event_type":"price_change"}}
{"capturedAt":1776808416,"payload":{"market":"0x125149c5918fc5f8c6d34682f700a898a1a19ea4f4e2ae68ff4c5794ba657074","price_changes":[{"asset_id":"45936375922793925919605092352922707796689801895417366600539442410775071099958","price":"0.86","size":"320.14","side":"BUY","hash":"eae89a97680e2c3d514e9db508ba2989b4e9864f","best_bid":"0.86","best_ask":"0.87"},{"asset_id":"86520121088881862182423437128238697252500151785248183602134095101149900014256","price":"0.14","size":"320.14","side":"SELL","hash":"d199592a9ea87720979c337bc1d9aafe84a80a4a","best_bid":"0.13","best_ask":"0.14"}],"timestamp":"1776808416135","event_type":"price_change"}}
{"capturedAt":1776808416,"payload":{"market":"0x125149c5918fc5f8c6d34682f700a898a1a19ea4f4e2ae68ff4c5794ba657074","price_changes":[{"asset_id":"45936375922793925919605092352922707796689801895417366600539442410775071099958","price":"0.86","size":"289.14","side":"BUY","hash":"296f3b191a03f084cf48c0faac9f92c70e9fd54d","best_bid":"0.86","best_ask":"0.87"},{"asset_id":"86520121088881862182423437128238697252500151785248183602134095101149900014256","price":"0.14","size":"289.14","side":"SELL","hash":"b87522ddcd1819121336507a1073bd91d9f92155","best_bid":"0.13","best_ask":"0.14"}],"timestamp":"1776808416137","event_type":"price_change"}}
{"capturedAt":1776808416,"payload":{"market":"0x125149c5918fc5f8c6d34682f700a898a1a19ea4f4e2ae68ff4c5794ba657074","price_changes":[{"asset_id":"45936375922793925919605092352922707796689801895417366600539442410775071099958","price":"0.86","size":"294.19","side":"BUY","hash":"84d6c2648616299d414ea30ab29ed5261dec86e5","best_bid":"0.86","best_ask":"0.87"},{"asset_id":"86520121088881862182423437128238697252500151785248183602134095101149900014256","price":"0.14","size":"294.19","side":"SELL","hash":"86c5a9de85638e9be330115f68ca041b3579c8aa","best_bid":"0.13","best_ask":"0.14"}],"timestamp":"1776808416138","event_type":"price_change"}}
{"capturedAt":1776808416,"payload":{"market":"0x125149c5918fc5f8c6d34682f700a898a1a19ea4f4e2ae68ff4c5794ba657074","price_changes":[{"asset_id":"45936375922793925919605092352922707796689801895417366600539442410775071099958","price":"0.86","size":"371.14","side":"BUY","hash":"c2d87e5b6147590f6ce47663f79186c904e9c2e9","best_bid":"0.86","best_ask":"0.87"},{"asset_id":"86520121088881862182423437128238697252500151785248183602134095101149900014256","price":"0.14","size":"371.14","side":"SELL","hash":"ed570da627de308a903066d4ee52cad68f12779f","best_bid":"0.13","best_ask":"0.14"}],"timestamp":"1776808416129","event_type":"price_change"}}
{"capturedAt":1776808416,"payload":{"market":"0x125149c5918fc5f8c6d34682f700a898a1a19ea4f4e2ae68ff4c5794ba657074","price_changes":[{"asset_id":"45936375922793925919605092352922707796689801895417366600539442410775071099958","price":"0.86","size":"271.19","side":"BUY","hash":"2e33158449ac0a47d69abfd42a9a04dd9cd964ba","best_bid":"0.86","best_ask":"0.87"},{"asset_id":"86520121088881862182423437128238697252500151785248183602134095101149900014256","price":"0.14","size":"271.19","side":"SELL","hash":"5311c8deb65f6f8571471bbfbee9799ec960f483","best_bid":"0.13","best_ask":"0.14"}],"timestamp":"1776808416139","event_type":"price_change"}}
{"capturedAt":1776808416,"payload":{"market":"0x125149c5918fc5f8c6d34682f700a898a1a19ea4f4e2ae68ff4c5794ba657074","price_changes":[{"asset_id":"45936375922793925919605092352922707796689801895417366600539442410775071099958","price":"0.86","size":"299.14","side":"BUY","hash":"2a660375696ca0baa4f5862336da0fbd1a006ca2","best_bid":"0.86","best_ask":"0.87"},{"asset_id":"86520121088881862182423437128238697252500151785248183602134095101149900014256","price":"0.14","size":"299.14","side":"SELL","hash":"0b998ec8b5a4c4f9943066a56787732816abd45f","best_bid":"0.13","best_ask":"0.14"}],"timestamp":"1776808416136","event_type":"price_change"}}
{"capturedAt":1776808416,"payload":{"market":"0x125149c5918fc5f8c6d34682f700a898a1a19ea4f4e2ae68ff4c5794ba657074","price_changes":[{"asset_id":"45936375922793925919605092352922707796689801895417366600539442410775071099958","price":"0.01","size":"12329.83","side":"BUY","hash":"63511ed32f1d56d5b9f2111d768c7f7cc2a4f0dd","best_bid":"0.86","best_ask":"0.87"},{"asset_id":"86520121088881862182423437128238697252500151785248183602134095101149900014256","price":"0.99","size":"12329.83","side":"SELL","hash":"1fa5b0c4a3538ee11149f944af8677d4c7b55f79","best_bid":"0.13","best_ask":"0.14"}],"timestamp":"1776808416140","event_type":"price_change"}}
{"capturedAt":1776808416,"payload":{"market":"0x125149c5918fc5f8c6d34682f700a898a1a19ea4f4e2ae68ff4c5794ba657074","price_changes":[{"asset_id":"45936375922793925919605092352922707796689801895417366600539442410775071099958","price":"0.86","size":"276.9","side":"BUY","hash":"7ba2dbd31d7dbc44421afb57345db14d40a7ac23","best_bid":"0.86","best_ask":"0.87"},{"asset_id":"86520121088881862182423437128238697252500151785248183602134095101149900014256","price":"0.14","size":"276.9","side":"SELL","hash":"b1238afcbb519bd83f51869221747c30ed78f92e","best_bid":"0.13","best_ask":"0.14"}],"timestamp":"1776808416141","event_type":"price_change"}}
{"capturedAt":1776808416,"payload":{"market":"0x125149c5918fc5f8c6d34682f700a898a1a19ea4f4e2ae68ff4c5794ba657074","price_changes":[{"asset_id":"86520121088881862182423437128238697252500151785248183602134095101149900014256","price":"0.06","size":"435.8","side":"BUY","hash":"c2bbb52ee95e2786e046bcbba694f176efe7a87b","best_bid":"0.13","best_ask":"0.14"},{"asset_id":"45936375922793925919605092352922707796689801895417366600539442410775071099958","price":"0.94","size":"435.8","side":"SELL","hash":"e75039b7cf6c665e2c8b953bb1f7646463949241","best_bid":"0.86","best_ask":"0.87"}],"timestamp":"1776808416156","event_type":"price_change"}}
{"capturedAt":1776808416,"payload":{"market":"0x125149c5918fc5f8c6d34682f700a898a1a19ea4f4e2ae68ff4c5794ba657074","price_changes":[{"asset_id":"45936375922793925919605092352922707796689801895417366600539442410775071099958","price":"0.86","size":"255.9","side":"BUY","hash":"1834958c2a17f22b95e5be78cfdd70f1fdea1d23","best_bid":"0.86","best_ask":"0.87"},{"asset_id":"86520121088881862182423437128238697252500151785248183602134095101149900014256","price":"0.14","size":"255.9","side":"SELL","hash":"fee08741588b056a3c120515db4b512597543d80","best_bid":"0.13","best_ask":"0.14"}],"timestamp":"1776808416144","event_type":"price_change"}}
{"capturedAt":1776808416,"payload":{"market":"0x125149c5918fc5f8c6d34682f700a898a1a19ea4f4e2ae68ff4c5794ba657074","price_changes":[{"asset_id":"45936375922793925919605092352922707796689801895417366600539442410775071099958","price":"0.01","size":"12334.83","side":"BUY","hash":"63e7f0d07f4ddb98b8ab2987227278ee626cec31","best_bid":"0.86","best_ask":"0.87"},{"asset_id":"86520121088881862182423437128238697252500151785248183602134095101149900014256","price":"0.99","size":"12334.83","side":"SELL","hash":"bbbce6b2fdc046f6d2da4c7189040b0ad7b1f75e","best_bid":"0.13","best_ask":"0.14"}],"timestamp":"1776808416149","event_type":"price_change"}}
{"capturedAt":1776808416,"payload":{"market":"0x125149c5918fc5f8c6d34682f700a898a1a19ea4f4e2ae68ff4c5794ba657074","price_changes":[{"asset_id":"45936375922793925919605092352922707796689801895417366600539442410775071099958","price":"0.86","size":"301.9","side":"BUY","hash":"c314d5053847fb78296cde6227861983d16f9c83","best_bid":"0.86","best_ask":"0.87"},{"asset_id":"86520121088881862182423437128238697252500151785248183602134095101149900014256","price":"0.14","size":"301.9","side":"SELL","hash":"5841cd18eb1fc3620968de95a63691250e821ccb","best_bid":"0.13","best_ask":"0.14"}],"timestamp":"1776808416160","event_type":"price_change"}}
{"capturedAt":1776808416,"payload":{"market":"0x125149c5918fc5f8c6d34682f700a898a1a19ea4f4e2ae68ff4c5794ba657074","price_changes":[{"asset_id":"86520121088881862182423437128238697252500151785248183602134095101149900014256","price":"0.06","size":"427.8","side":"BUY","hash":"237053b2dffeda01f3d161020b0120d385066e31","best_bid":"0.13","best_ask":"0.14"},{"asset_id":"45936375922793925919605092352922707796689801895417366600539442410775071099958","price":"0.94","size":"427.8","side":"SELL","hash":"cb9e630b6c5de70e909747d932f2f2933ce59849","best_bid":"0.86","best_ask":"0.87"}],"timestamp":"1776808416156","event_type":"price_change"}}
{"capturedAt":1776808416,"payload":{"market":"0x125149c5918fc5f8c6d34682f700a898a1a19ea4f4e2ae68ff4c5794ba657074","price_changes":[{"asset_id":"45936375922793925919605092352922707796689801895417366600539442410775071099958","price":"0.86","size":"314.9","side":"BUY","hash":"057a52a05f0c8c7fa48a937413b6470c314247c9","best_bid":"0.86","best_ask":"0.87"},{"asset_id":"86520121088881862182423437128238697252500151785248183602134095101149900014256","price":"0.14","size":"314.9","side":"SELL","hash":"066c134a171715ce891ab085e50fbfd73d792668","best_bid":"0.13","best_ask":"0.14"}],"timestamp":"1776808416161","event_type":"price_change"}}
{"capturedAt":1776808416,"payload":{"market":"0x125149c5918fc5f8c6d34682f700a898a1a19ea4f4e2ae68ff4c5794ba657074","price_changes":[{"asset_id":"45936375922793925919605092352922707796689801895417366600539442410775071099958","price":"0.86","size":"280.9","side":"BUY","hash":"11318d879f20b6bedf0b76e9f444d546e52bef47","best_bid":"0.86","best_ask":"0.87"},{"asset_id":"86520121088881862182423437128238697252500151785248183602134095101149900014256","price":"0.14","size":"280.9","side":"SELL","hash":"79520b80bf85d98a7da80b6a70b1431f1c916815","best_bid":"0.13","best_ask":"0.14"}],"timestamp":"1776808416155","event_type":"price_change"}}
{"capturedAt":1776808416,"payload":{"market":"0x125149c5918fc5f8c6d34682f700a898a1a19ea4f4e2ae68ff4c5794ba657074","price_changes":[{"asset_id":"45936375922793925919605092352922707796689801895417366600539442410775071099958","price":"0.01","size":"12329.83","side":"BUY","hash":"3ab18e89a5b5a2cb25bd35b3a45c74715525e12c","best_bid":"0.86","best_ask":"0.87"},{"asset_id":"86520121088881862182423437128238697252500151785248183602134095101149900014256","price":"0.99","size":"12329.83","side":"SELL","hash":"54821d45797fffd123a34f19e08c370955f8b5ac","best_bid":"0.13","best_ask":"0.14"}],"timestamp":"1776808416159","event_type":"price_change"}}
{"capturedAt":1776808416,"payload":{"market":"0x125149c5918fc5f8c6d34682f700a898a1a19ea4f4e2ae68ff4c5794ba657074","price_changes":[{"asset_id":"45936375922793925919605092352922707796689801895417366600539442410775071099958","price":"0.86","size":"324.9","side":"BUY","hash":"070ea77b413f512c95d1c6a75ff6bef1b31112c1","best_bid":"0.86","best_ask":"0.87"},{"asset_id":"86520121088881862182423437128238697252500151785248183602134095101149900014256","price":"0.14","size":"324.9","side":"SELL","hash":"cdfaf8bee6407227f595d5ec1f3945c1391aad05","best_bid":"0.13","best_ask":"0.14"}],"timestamp":"1776808416162","event_type":"price_change"}}
{"capturedAt":1776808416,"payload":{"market":"0x125149c5918fc5f8c6d34682f700a898a1a19ea4f4e2ae68ff4c5794ba657074","price_changes":[{"asset_id":"45936375922793925919605092352922707796689801895417366600539442410775071099958","price":"0.86","size":"289.14","side":"BUY","hash":"644dde396efdd1fc7176bd4fa725c0a282bcdcbb","best_bid":"0.86","best_ask":"0.87"},{"asset_id":"86520121088881862182423437128238697252500151785248183602134095101149900014256","price":"0.14","size":"289.14","side":"SELL","hash":"b9b8db761fd39cea3eab30383d11531fc62f8349","best_bid":"0.13","best_ask":"0.14"}],"timestamp":"1776808416165","event_type":"price_change"}}
{"capturedAt":1776808416,"payload":{"market":"0x125149c5918fc5f8c6d34682f700a898a1a19ea4f4e2ae68ff4c5794ba657074","price_changes":[{"asset_id":"45936375922793925919605092352922707796689801895417366600539442410775071099958","price":"0.86","size":"311.14","side":"BUY","hash":"789f326edf6b10f387855df5380480cfbbf96481","best_bid":"0.86","best_ask":"0.87"},{"asset_id":"86520121088881862182423437128238697252500151785248183602134095101149900014256","price":"0.14","size":"311.14","side":"SELL","hash":"f7b50cf4e84b301b7c1514e09ea9b99603244e47","best_bid":"0.13","best_ask":"0.14"}],"timestamp":"1776808416166","event_type":"price_change"}}
{"capturedAt":1776808416,"payload":{"market":"0x125149c5918fc5f8c6d34682f700a898a1a19ea4f4e2ae68ff4c5794ba657074","price_changes":[{"asset_id":"45936375922793925919605092352922707796689801895417366600539442410775071099958","price":"0.86","size":"294.19","side":"BUY","hash":"1033068932eaab847b2970ff40f564ec1c995d90","best_bid":"0.86","best_ask":"0.87"},{"asset_id":"86520121088881862182423437128238697252500151785248183602134095101149900014256","price":"0.14","size":"294.19","side":"SELL","hash":"59e55e0e7e22f992ff78c68bdaf97abae09b76ae","best_bid":"0.13","best_ask":"0.14"}],"timestamp":"1776808416164","event_type":"price_change"}}
{"capturedAt":1776808416,"payload":{"market":"0x125149c5918fc5f8c6d34682f700a898a1a19ea4f4e2ae68ff4c5794ba657074","price_changes":[{"asset_id":"45936375922793925919605092352922707796689801895417366600539442410775071099958","price":"0.86","size":"333.14","side":"BUY","hash":"fada0b6b2cdbe63e340401583e371c750b2cd356","best_bid":"0.86","best_ask":"0.87"},{"asset_id":"86520121088881862182423437128238697252500151785248183602134095101149900014256","price":"0.14","size":"333.14","side":"SELL","hash":"2ae080b3767754b49a162c60c647f769113eb9d0","best_bid":"0.13","best_ask":"0.14"}],"timestamp":"1776808416166","event_type":"price_change"}}
{"capturedAt":1776808416,"payload":{"market":"0x125149c5918fc5f8c6d34682f700a898a1a19ea4f4e2ae68ff4c5794ba657074","price_changes":[{"asset_id":"45936375922793925919605092352922707796689801895417366600539442410775071099958","price":"0.86","size":"355.14","side":"BUY","hash":"0a0377a3ef085f3dbb06113fec6800cfc604201c","best_bid":"0.86","best_ask":"0.87"},{"asset_id":"86520121088881862182423437128238697252500151785248183602134095101149900014256","price":"0.14","size":"355.14","side":"SELL","hash":"d02ea7ea1f082e8408013f3c1b4e599c35e0dfeb","best_bid":"0.13","best_ask":"0.14"}],"timestamp":"1776808416167","event_type":"price_change"}}
{"capturedAt":1776808416,"payload":{"market":"0x125149c5918fc5f8c6d34682f700a898a1a19ea4f4e2ae68ff4c5794ba657074","price_changes":[{"asset_id":"45936375922793925919605092352922707796689801895417366600539442410775071099958","price":"0.86","size":"377.14","side":"BUY","hash":"b92d1b0d9076ac101f23d989c17d017edab10742","best_bid":"0.86","best_ask":"0.87"},{"asset_id":"86520121088881862182423437128238697252500151785248183602134095101149900014256","price":"0.14","size":"377.14","side":"SELL","hash":"cfbdab4a5d3a32f443b80093228a952680ea2fb9","best_bid":"0.13","best_ask":"0.14"}],"timestamp":"1776808416168","event_type":"price_change"}}
{"capturedAt":1776808416,"payload":{"market":"0x125149c5918fc5f8c6d34682f700a898a1a19ea4f4e2ae68ff4c5794ba657074","price_changes":[{"asset_id":"45936375922793925919605092352922707796689801895417366600539442410775071099958","price":"0.86","size":"299.9","side":"BUY","hash":"0c509582316f611ac3806cc7f3333fa0a058892a","best_bid":"0.86","best_ask":"0.87"},{"asset_id":"86520121088881862182423437128238697252500151785248183602134095101149900014256","price":"0.14","size":"299.9","side":"SELL","hash":"39122af2809e79bd13257bc99327abb52c460eeb","best_bid":"0.13","best_ask":"0.14"}],"timestamp":"1776808416163","event_type":"price_change"}}
{"capturedAt":1776808416,"payload":{"market":"0x125149c5918fc5f8c6d34682f700a898a1a19ea4f4e2ae68ff4c5794ba657074","price_changes":[{"asset_id":"45936375922793925919605092352922707796689801895417366600539442410775071099958","price":"0.01","size":"12324.83","side":"BUY","hash":"ac695a2c467811edd5ca045e61cd97aa2a8abcf4","best_bid":"0.86","best_ask":"0.87"},{"asset_id":"86520121088881862182423437128238697252500151785248183602134095101149900014256","price":"0.99","size":"12324.83","side":"SELL","hash":"ab2adf7d25709e0b6e2fdef96b173e1bfb4d4911","best_bid":"0.13","best_ask":"0.14"}],"timestamp":"1776808416169","event_type":"price_change"}}
{"capturedAt":1776808416,"payload":{"market":"0x125149c5918fc5f8c6d34682f700a898a1a19ea4f4e2ae68ff4c5794ba657074","price_changes":[{"asset_id":"45936375922793925919605092352922707796689801895417366600539442410775071099958","price":"0.86","size":"317.14","side":"BUY","hash":"bfe5616c0b34c47fac6bf1bf16dbb18a18d49e8a","best_bid":"0.86","best_ask":"0.87"},{"asset_id":"86520121088881862182423437128238697252500151785248183602134095101149900014256","price":"0.14","size":"317.14","side":"SELL","hash":"31be561f1063fd948f682194fe7b09efaf0cbd01","best_bid":"0.13","best_ask":"0.14"}],"timestamp":"1776808416181","event_type":"price_change"}}
{"capturedAt":1776808416,"payload":{"market":"0x125149c5918fc5f8c6d34682f700a898a1a19ea4f4e2ae68ff4c5794ba657074","price_changes":[{"asset_id":"45936375922793925919605092352922707796689801895417366600539442410775071099958","price":"0.74","size":"187.7","side":"BUY","hash":"ecdb5b89cd697366204e9c84a0a1a5884dea6c5e","best_bid":"0.86","best_ask":"0.87"},{"asset_id":"86520121088881862182423437128238697252500151785248183602134095101149900014256","price":"0.26","size":"187.7","side":"SELL","hash":"d22241ccc475dc4ad1b1a32f17ff765483d52f86","best_bid":"0.13","best_ask":"0.14"}],"timestamp":"1776808416175","event_type":"price_change"}}
{"capturedAt":1776808416,"payload":{"market":"0x125149c5918fc5f8c6d34682f700a898a1a19ea4f4e2ae68ff4c5794ba657074","price_changes":[{"asset_id":"45936375922793925919605092352922707796689801895417366600539442410775071099958","price":"0.86","size":"342.14","side":"BUY","hash":"b5d8a5b6b607847af4bb5ac206309bce2e12c080","best_bid":"0.86","best_ask":"0.87"},{"asset_id":"86520121088881862182423437128238697252500151785248183602134095101149900014256","price":"0.14","size":"342.14","side":"SELL","hash":"bc62ebd1ae8d8d28b362ebf0e225ee58b05c4ffb","best_bid":"0.13","best_ask":"0.14"}],"timestamp":"1776808416179","event_type":"price_change"}}
{"capturedAt":1776808416,"payload":{"market":"0x125149c5918fc5f8c6d34682f700a898a1a19ea4f4e2ae68ff4c5794ba657074","price_changes":[{"asset_id":"45936375922793925919605092352922707796689801895417366600539442410775071099958","price":"0.86","size":"322.52","side":"BUY","hash":"a2390d773dd93aa278afebb1bb8402b738ec44a5","best_bid":"0.86","best_ask":"0.87"},{"asset_id":"86520121088881862182423437128238697252500151785248183602134095101149900014256","price":"0.14","size":"322.52","side":"SELL","hash":"837051f2465a9856b31680933d04186c9f36eefc","best_bid":"0.13","best_ask":"0.14"}],"timestamp":"1776808416188","event_type":"price_change"}}
{"capturedAt":1776808416,"payload":{"market":"0x125149c5918fc5f8c6d34682f700a898a1a19ea4f4e2ae68ff4c5794ba657074","price_changes":[{"asset_id":"45936375922793925919605092352922707796689801895417366600539442410775071099958","price":"0.86","size":"352.14","side":"BUY","hash":"515da1adaa00942fe69fc636100bd8114abe553d","best_bid":"0.86","best_ask":"0.87"},{"asset_id":"86520121088881862182423437128238697252500151785248183602134095101149900014256","price":"0.14","size":"352.14","side":"SELL","hash":"35edc2a56b7435f430f91798a380a4cb9a096da7","best_bid":"0.13","best_ask":"0.14"}],"timestamp":"1776808416176","event_type":"price_change"}}
{"capturedAt":1776808416,"payload":{"market":"0x125149c5918fc5f8c6d34682f700a898a1a19ea4f4e2ae68ff4c5794ba657074","price_changes":[{"asset_id":"45936375922793925919605092352922707796689801895417366600539442410775071099958","price":"0.01","size":"12329.83","side":"BUY","hash":"df589d5651710e88630fac4f9117f71093262aa9","best_bid":"0.86","best_ask":"0.87"},{"asset_id":"86520121088881862182423437128238697252500151785248183602134095101149900014256","price":"0.99","size":"12329.83","side":"SELL","hash":"88e37c10dbd46e27574ec2cf1c3124a3cd7d2a27","best_bid":"0.13","best_ask":"0.14"}],"timestamp":"1776808416189","event_type":"price_change"}}
{"capturedAt":1776808416,"payload":{"market":"0x125149c5918fc5f8c6d34682f700a898a1a19ea4f4e2ae68ff4c5794ba657074","price_changes":[{"asset_id":"45936375922793925919605092352922707796689801895417366600539442410775071099958","price":"0.86","size":"350.52","side":"BUY","hash":"4c62c59b0219607e96886cbd9572dca285d2464c","best_bid":"0.86","best_ask":"0.87"},{"asset_id":"86520121088881862182423437128238697252500151785248183602134095101149900014256","price":"0.14","size":"350.52","side":"SELL","hash":"9a0010a42948adfb3b5e12a03a48fb72fa26a353","best_bid":"0.13","best_ask":"0.14"}],"timestamp":"1776808416190","event_type":"price_change"}}
{"capturedAt":1776808416,"payload":{"market":"0x125149c5918fc5f8c6d34682f700a898a1a19ea4f4e2ae68ff4c5794ba657074","price_changes":[{"asset_id":"45936375922793925919605092352922707796689801895417366600539442410775071099958","price":"0.86","size":"327.52","side":"BUY","hash":"b71d16515add92e6094774cfd62c5ddc47643eec","best_bid":"0.86","best_ask":"0.87"},{"asset_id":"86520121088881862182423437128238697252500151785248183602134095101149900014256","price":"0.14","size":"327.52","side":"SELL","hash":"8b4aef8261b8a84c886b7e436cc2b3951b007040","best_bid":"0.13","best_ask":"0.14"}],"timestamp":"1776808416203","event_type":"price_change"}}
{"capturedAt":1776808416,"payload":{"market":"0x125149c5918fc5f8c6d34682f700a898a1a19ea4f4e2ae68ff4c5794ba657074","price_changes":[{"asset_id":"45936375922793925919605092352922707796689801895417366600539442410775071099958","price":"0.86","size":"351.52","side":"BUY","hash":"50f74012c825fcc6cf93aa32e9de78ec987ccaa4","best_bid":"0.86","best_ask":"0.87"},{"asset_id":"86520121088881862182423437128238697252500151785248183602134095101149900014256","price":"0.14","size":"351.52","side":"SELL","hash":"c211c3b2344709bfcbb0a52fba777b2fd97ee8f1","best_bid":"0.13","best_ask":"0.14"}],"timestamp":"1776808416205","event_type":"price_change"}}
{"capturedAt":1776808416,"payload":{"market":"0x125149c5918fc5f8c6d34682f700a898a1a19ea4f4e2ae68ff4c5794ba657074","price_changes":[{"asset_id":"45936375922793925919605092352922707796689801895417366600539442410775071099958","price":"0.86","size":"340.52","side":"BUY","hash":"82ea573ec580d6390cce3f9a468ca67e0028d414","best_bid":"0.86","best_ask":"0.87"},{"asset_id":"86520121088881862182423437128238697252500151785248183602134095101149900014256","price":"0.14","size":"340.52","side":"SELL","hash":"5bebe84a014a578d72a94f2a3fad6e2df1d0aab7","best_bid":"0.13","best_ask":"0.14"}],"timestamp":"1776808416191","event_type":"price_change"}}
{"capturedAt":1776808416,"payload":{"market":"0x125149c5918fc5f8c6d34682f700a898a1a19ea4f4e2ae68ff4c5794ba657074","price_changes":[{"asset_id":"45936375922793925919605092352922707796689801895417366600539442410775071099958","price":"0.01","size":"12334.83","side":"BUY","hash":"d98ba3e5f998347e2806f2d23621449057fa81cb","best_bid":"0.86","best_ask":"0.87"},{"asset_id":"86520121088881862182423437128238697252500151785248183602134095101149900014256","price":"0.99","size":"12334.83","side":"SELL","hash":"1c41432598faa486122379c212be1648c3bfb354","best_bid":"0.13","best_ask":"0.14"}],"timestamp":"1776808416198","event_type":"price_change"}}
{"capturedAt":1776808416,"payload":{"market":"0x125149c5918fc5f8c6d34682f700a898a1a19ea4f4e2ae68ff4c5794ba657074","price_changes":[{"asset_id":"45936375922793925919605092352922707796689801895417366600539442410775071099958","price":"0.86","size":"361.52","side":"BUY","hash":"861f45dc0c3a6092bdca201086ea80a38b41c480","best_bid":"0.86","best_ask":"0.87"},{"asset_id":"86520121088881862182423437128238697252500151785248183602134095101149900014256","price":"0.14","size":"361.52","side":"SELL","hash":"caab6613e906916f378fdaaefc7db52c270bc40a","best_bid":"0.13","best_ask":"0.14"}],"timestamp":"1776808416207","event_type":"price_change"}}
{"capturedAt":1776808416,"payload":{"market":"0x125149c5918fc5f8c6d34682f700a898a1a19ea4f4e2ae68ff4c5794ba657074","price_changes":[{"asset_id":"86520121088881862182423437128238697252500151785248183602134095101149900014256","price":"0.05","size":"790.63","side":"BUY","hash":"15714dc6ac5b3edeaa514995a469d3c94421ca25","best_bid":"0.13","best_ask":"0.14"},{"asset_id":"45936375922793925919605092352922707796689801895417366600539442410775071099958","price":"0.95","size":"790.63","side":"SELL","hash":"cd950d4b2943e6203b6e5d6eec2b606c399c9e43","best_bid":"0.86","best_ask":"0.87"}],"timestamp":"1776808416208","event_type":"price_change"}}
{"capturedAt":1776808416,"payload":{"market":"0x125149c5918fc5f8c6d34682f700a898a1a19ea4f4e2ae68ff4c5794ba657074","price_changes":[{"asset_id":"45936375922793925919605092352922707796689801895417366600539442410775071099958","price":"0.75","size":"482.29","side":"BUY","hash":"1a23dd50b45a7986e923365eddc6c853807a4051","best_bid":"0.86","best_ask":"0.87"},{"asset_id":"86520121088881862182423437128238697252500151785248183602134095101149900014256","price":"0.25","size":"482.29","side":"SELL","hash":"4bea3b27d324b0f3e7904ac4eca53464af321a68","best_bid":"0.13","best_ask":"0.14"}],"timestamp":"1776808416200","event_type":"price_change"}}
{"capturedAt":1776808416,"payload":{"market":"0x125149c5918fc5f8c6d34682f700a898a1a19ea4f4e2ae68ff4c5794ba657074","price_changes":[{"asset_id":"45936375922793925919605092352922707796689801895417366600539442410775071099958","price":"0.86","size":"382.14","side":"BUY","hash":"15b0b1456c6eb328f0e59d378e8db4929ba58fb4","best_bid":"0.86","best_ask":"0.87"},{"asset_id":"86520121088881862182423437128238697252500151785248183602134095101149900014256","price":"0.14","size":"382.14","side":"SELL","hash":"ec824efe065969d7722b567adf1b4e43be081cde","best_bid":"0.13","best_ask":"0.14"}],"timestamp":"1776808416215","event_type":"price_change"}}
{"capturedAt":1776808416,"payload":{"market":"0x125149c5918fc5f8c6d34682f700a898a1a19ea4f4e2ae68ff4c5794ba657074","price_changes":[{"asset_id":"45936375922793925919605092352922707796689801895417366600539442410775071099958","price":"0.01","size":"12324.83","side":"BUY","hash":"26677db4ac5660a47d32f5315273f66970677f0d","best_bid":"0.86","best_ask":"0.87"},{"asset_id":"86520121088881862182423437128238697252500151785248183602134095101149900014256","price":"0.99","size":"12324.83","side":"SELL","hash":"1be94f0347349e6803d5d2100bdec374de5b0af4","best_bid":"0.13","best_ask":"0.14"}],"timestamp":"1776808416216","event_type":"price_change"}}
{"capturedAt":1776808416,"payload":{"market":"0x125149c5918fc5f8c6d34682f700a898a1a19ea4f4e2ae68ff4c5794ba657074","price_changes":[{"asset_id":"45936375922793925919605092352922707796689801895417366600539442410775071099958","price":"0.86","size":"356.14","side":"BUY","hash":"3b46ca9ac20353ccb9ee1a4c455a997ecea587e7","best_bid":"0.86","best_ask":"0.87"},{"asset_id":"86520121088881862182423437128238697252500151785248183602134095101149900014256","price":"0.14","size":"356.14","side":"SELL","hash":"7dca33aef42f99dc8d9f99ec94715ca09a4f78b1","best_bid":"0.13","best_ask":"0.14"}],"timestamp":"1776808416210","event_type":"price_change"}}
{"capturedAt":1776808416,"payload":{"market":"0x125149c5918fc5f8c6d34682f700a898a1a19ea4f4e2ae68ff4c5794ba657074","price_changes":[{"asset_id":"45936375922793925919605092352922707796689801895417366600539442410775071099958","price":"0.01","size":"12329.83","side":"BUY","hash":"a99e4be46e27e694c2df765b6692d7c83e516b6d","best_bid":"0.86","best_ask":"0.87"},{"asset_id":"86520121088881862182423437128238697252500151785248183602134095101149900014256","price":"0.99","size":"12329.83","side":"SELL","hash":"a1c2476f96651afed44a8e3700080c5f7dbf913b","best_bid":"0.13","best_ask":"0.14"}],"timestamp":"1776808416206","event_type":"price_change"}}
{"capturedAt":1776808416,"payload":{"market":"0x125149c5918fc5f8c6d34682f700a898a1a19ea4f4e2ae68ff4c5794ba657074","price_changes":[{"asset_id":"45936375922793925919605092352922707796689801895417366600539442410775071099958","price":"0.86","size":"392.14","side":"BUY","hash":"e985eb8f4b07d4d0077fa91a4772e19cd270e7ba","best_bid":"0.86","best_ask":"0.87"},{"asset_id":"86520121088881862182423437128238697252500151785248183602134095101149900014256","price":"0.14","size":"392.14","side":"SELL","hash":"998f7b6a73e584b0aa6165c5e3656c1aa98ee773","best_bid":"0.13","best_ask":"0.14"}],"timestamp":"1776808416218","event_type":"price_change"}}
{"capturedAt":1776808416,"payload":{"market":"0x125149c5918fc5f8c6d34682f700a898a1a19ea4f4e2ae68ff4c5794ba657074","price_changes":[{"asset_id":"45936375922793925919605092352922707796689801895417366600539442410775071099958","price":"0.86","size":"367.14","side":"BUY","hash":"013f722d6e1b4b3eebcd7f3193599b66cfb1cd89","best_bid":"0.86","best_ask":"0.87"},{"asset_id":"86520121088881862182423437128238697252500151785248183602134095101149900014256","price":"0.14","size":"367.14","side":"SELL","hash":"b0ba82bf7db2421d4c077ef5e45d3e792237b3b6","best_bid":"0.13","best_ask":"0.14"}],"timestamp":"1776808416223","event_type":"price_change"}}
{"capturedAt":1776808416,"payload":{"market":"0x125149c5918fc5f8c6d34682f700a898a1a19ea4f4e2ae68ff4c5794ba657074","price_changes":[{"asset_id":"45936375922793925919605092352922707796689801895417366600539442410775071099958","price":"0.86","size":"323.14","side":"BUY","hash":"29638e3d7ff88797de932695ffe8931f5f39e6f0","best_bid":"0.86","best_ask":"0.87"},{"asset_id":"86520121088881862182423437128238697252500151785248183602134095101149900014256","price":"0.14","size":"323.14","side":"SELL","hash":"9c508aeb23bd3259bf9b691799018cdb727852e9","best_bid":"0.13","best_ask":"0.14"}],"timestamp":"1776808416233","event_type":"price_change"}}
{"capturedAt":1776808416,"payload":{"market":"0x125149c5918fc5f8c6d34682f700a898a1a19ea4f4e2ae68ff4c5794ba657074","price_changes":[{"asset_id":"45936375922793925919605092352922707796689801895417366600539442410775071099958","price":"0.86","size":"354.14","side":"BUY","hash":"b1a60d27b07e354ae213f6e7ef01f57ab249e39f","best_bid":"0.86","best_ask":"0.87"},{"asset_id":"86520121088881862182423437128238697252500151785248183602134095101149900014256","price":"0.14","size":"354.14","side":"SELL","hash":"bd9ac2e8cf21745c500b8b42ba8a829e7ced476b","best_bid":"0.13","best_ask":"0.14"}],"timestamp":"1776808416231","event_type":"price_change"}}
{"capturedAt":1776808416,"payload":{"market":"0x125149c5918fc5f8c6d34682f700a898a1a19ea4f4e2ae68ff4c5794ba657074","price_changes":[{"asset_id":"45936375922793925919605092352922707796689801895417366600539442410775071099958","price":"0.86","size":"333.14","side":"BUY","hash":"703844704b7d5eccad23f8afa0b8a5000d9b48cd","best_bid":"0.86","best_ask":"0.87"},{"asset_id":"86520121088881862182423437128238697252500151785248183602134095101149900014256","price":"0.14","size":"333.14","side":"SELL","hash":"1fe88da0b062bcaddeb6e8749c775840f5377b33","best_bid":"0.13","best_ask":"0.14"}],"timestamp":"1776808416231","event_type":"price_change"}}
{"capturedAt":1776808416,"payload":{"market":"0x125149c5918fc5f8c6d34682f700a898a1a19ea4f4e2ae68ff4c5794ba657074","price_changes":[{"asset_id":"86520121088881862182423437128238697252500151785248183602134095101149900014256","price":"0.03","size":"1603.83","side":"BUY","hash":"fecd18f1b33f9cec1dc5a314579da7edf8fbcfd2","best_bid":"0.13","best_ask":"0.14"},{"asset_id":"45936375922793925919605092352922707796689801895417366600539442410775071099958","price":"0.97","size":"1603.83","side":"SELL","hash":"7f396a03fab0c4cce6dd64b7c8e576204e410c38","best_bid":"0.86","best_ask":"0.87"}],"timestamp":"1776808416229","event_type":"price_change"}}
{"capturedAt":1776808416,"payload":{"market":"0x125149c5918fc5f8c6d34682f700a898a1a19ea4f4e2ae68ff4c5794ba657074","price_changes":[{"asset_id":"45936375922793925919605092352922707796689801895417366600539442410775071099958","price":"0.86","size":"293.14","side":"BUY","hash":"51570ab55bf8aa14fff2d8916811892317821806","best_bid":"0.86","best_ask":"0.87"},{"asset_id":"86520121088881862182423437128238697252500151785248183602134095101149900014256","price":"0.14","size":"293.14","side":"SELL","hash":"0a2986644af95a0d1febe4ba17571ce075cbee59","best_bid":"0.13","best_ask":"0.14"}],"timestamp":"1776808416237","event_type":"price_change"}}
{"capturedAt":1776808416,"payload":{"market":"0x125149c5918fc5f8c6d34682f700a898a1a19ea4f4e2ae68ff4c5794ba657074","price_changes":[{"asset_id":"45936375922793925919605092352922707796689801895417366600539442410775071099958","price":"0.86","size":"315.14","side":"BUY","hash":"8c8b0c9870dbca2c42f183dfdb62f21956b501dc","best_bid":"0.86","best_ask":"0.87"},{"asset_id":"86520121088881862182423437128238697252500151785248183602134095101149900014256","price":"0.14","size":"315.14","side":"SELL","hash":"5fdc436fbbabb406d738a4d6ddb02b8f24c07618","best_bid":"0.13","best_ask":"0.14"}],"timestamp":"1776808416236","event_type":"price_change"}}
{"capturedAt":1776808416,"payload":{"market":"0x125149c5918fc5f8c6d34682f700a898a1a19ea4f4e2ae68ff4c5794ba657074","price_changes":[{"asset_id":"45936375922793925919605092352922707796689801895417366600539442410775071099958","price":"0.78","size":"318.98","side":"BUY","hash":"5e875c446fda48d883b6774377e3cf507ef333b9","best_bid":"0.86","best_ask":"0.87"},{"asset_id":"86520121088881862182423437128238697252500151785248183602134095101149900014256","price":"0.22","size":"318.98","side":"SELL","hash":"202d722bc579cc7fa14992b0849471ed28c0a200","best_bid":"0.13","best_ask":"0.14"}],"timestamp":"1776808416238","event_type":"price_change"}}
{"capturedAt":1776808416,"payload":{"market":"0x125149c5918fc5f8c6d34682f700a898a1a19ea4f4e2ae68ff4c5794ba657074","price_changes":[{"asset_id":"45936375922793925919605092352922707796689801895417366600539442410775071099958","price":"0.86","size":"271.14","side":"BUY","hash":"cb745ec400f0e325405c34a78812f828a7a736ce","best_bid":"0.86","best_ask":"0.87"},{"asset_id":"86520121088881862182423437128238697252500151785248183602134095101149900014256","price":"0.14","size":"271.14","side":"SELL","hash":"f84130fef9c0b49fbe4fff69191f109c9bd2508c","best_bid":"0.13","best_ask":"0.14"}],"timestamp":"1776808416239","event_type":"price_change"}}
{"capturedAt":1776808416,"payload":{"market":"0x125149c5918fc5f8c6d34682f700a898a1a19ea4f4e2ae68ff4c5794ba657074","price_changes":[{"asset_id":"45936375922793925919605092352922707796689801895417366600539442410775071099958","price":"0.01","size":"12334.84","side":"BUY","hash":"a06afa3d7b84409c3fbf23c6286ae9c84a7a121d","best_bid":"0.86","best_ask":"0.87"},{"asset_id":"86520121088881862182423437128238697252500151785248183602134095101149900014256","price":"0.99","size":"12334.84","side":"SELL","hash":"31dd17410e3e66809cfeb45c322db1b1d734235f","best_bid":"0.13","best_ask":"0.14"}],"timestamp":"1776808416241","event_type":"price_change"}}
{"capturedAt":1776808416,"payload":{"market":"0x125149c5918fc5f8c6d34682f700a898a1a19ea4f4e2ae68ff4c5794ba657074","price_changes":[{"asset_id":"45936375922793925919605092352922707796689801895417366600539442410775071099958","price":"0.86","size":"337.14","side":"BUY","hash":"771f56486a582bc75ecfad270766d41c8edabb71","best_bid":"0.86","best_ask":"0.87"},{"asset_id":"86520121088881862182423437128238697252500151785248183602134095101149900014256","price":"0.14","size":"337.14","side":"SELL","hash":"2273b3145791587d417dd25dceabdc29d8d11b77","best_bid":"0.13","best_ask":"0.14"}],"timestamp":"1776808416236","event_type":"price_change"}}
{"capturedAt":1776808416,"payload":{"market":"0x125149c5918fc5f8c6d34682f700a898a1a19ea4f4e2ae68ff4c5794ba657074","price_changes":[{"asset_id":"45936375922793925919605092352922707796689801895417366600539442410775071099958","price":"0.86","size":"249.14","side":"BUY","hash":"4c7b6bbf86e0e7aedc960f2d95db8f49bbc113e4","best_bid":"0.86","best_ask":"0.87"},{"asset_id":"86520121088881862182423437128238697252500151785248183602134095101149900014256","price":"0.14","size":"249.14","side":"SELL","hash":"e02fad1dad918291946c18dd66411d70f15667f0","best_bid":"0.13","best_ask":"0.14"}],"timestamp":"1776808416239","event_type":"price_change"}}
{"capturedAt":1776808416,"payload":{"market":"0x125149c5918fc5f8c6d34682f700a898a1a19ea4f4e2ae68ff4c5794ba657074","price_changes":[{"asset_id":"45936375922793925919605092352922707796689801895417366600539442410775071099958","price":"0.01","size":"12329.84","side":"BUY","hash":"4fceeed1e761dfe04b1e0f446cc5134b77eb60af","best_bid":"0.86","best_ask":"0.87"},{"asset_id":"86520121088881862182423437128238697252500151785248183602134095101149900014256","price":"0.99","size":"12329.84","side":"SELL","hash":"4f2f0f6658a3f36175b64291f6400c8b42bd9263","best_bid":"0.13","best_ask":"0.14"}],"timestamp":"1776808416240","event_type":"price_change"}}
{"capturedAt":1776808416,"payload":{"market":"0x125149c5918fc5f8c6d34682f700a898a1a19ea4f4e2ae68ff4c5794ba657074","price_changes":[{"asset_id":"45936375922793925919605092352922707796689801895417366600539442410775071099958","price":"0.86","size":"254.18","side":"BUY","hash":"7a3f4e209d5900790b83404fcaf33237ec0608a4","best_bid":"0.86","best_ask":"0.87"},{"asset_id":"86520121088881862182423437128238697252500151785248183602134095101149900014256","price":"0.14","size":"254.18","side":"SELL","hash":"c4b264af24a95d742297e5365f43a698ca225fc4","best_bid":"0.13","best_ask":"0.14"}],"timestamp":"1776808416246","event_type":"price_change"}}
{"capturedAt":1776808416,"payload":{"market":"0x125149c5918fc5f8c6d34682f700a898a1a19ea4f4e2ae68ff4c5794ba657074","price_changes":[{"asset_id":"45936375922793925919605092352922707796689801895417366600539442410775071099958","price":"0.01","size":"12339.84","side":"BUY","hash":"03a9261706fd5691d9c3decf7abe7b8c66412865","best_bid":"0.86","best_ask":"0.87"},{"asset_id":"86520121088881862182423437128238697252500151785248183602134095101149900014256","price":"0.99","size":"12339.84","side":"SELL","hash":"ab66d79f152d4511777fbc108d39d3c105aa3d92","best_bid":"0.13","best_ask":"0.14"}],"timestamp":"1776808416249","event_type":"price_change"}}
