{"capturedAt":1776808415,"payload":{"market":"0x125149c5918fc5f8c6d34682f700a898a1a19ea4f4e2ae68ff4c5794ba657074","asset_id":"86520121088881862182423437128238697252500151785248183602134095101149900014256","bids":[{"price":"0.01","size":"12907.69"},{"price":"0.02","size":"1746.16"},{"price":"0.03","size":"1413.83"},{"price":"0.04","size":"932.3"},{"price":"0.05","size":"796.63"},{"price":"0.06","size":"395.8"},{"price":"0.07","size":"682.3"},{"price":"0.08","size":"656.9"},{"price":"0.09","size":"267.44"},{"price":"0.1","size":"793.5"},{"price":"0.11","size":"356.5"},{"price":"0.12","size":"308.5"},{"price":"0.13","size":"223.2"}],"asks":[{"price":"0.99","size":"12329.83"},{"price":"0.98","size":"1715.28"},{"price":"0.97","size":"1338.69"},{"price":"0.96","size":"583.84"},{"price":"0.95","size":"906.34"},{"price":"0.94","size":"392.8"},{"price":"0.93","size":"304.69"},{"price":"0.92","size":"278.9"},{"price":"0.91","size":"225"},{"price":"0.9","size":"282"},{"price":"0.89","size":"217.79"},{"price":"0.88","size":"215.1"},{"price":"0.87","size":"202.8"},{"price":"0.86","size":"200.9"},{"price":"0.85","size":"209.2"},{"price":"0.84","size":"197.8"},{"price":"0.83","size":"202.39"},{"price":"0.82","size":"200.4"},{"price":"0.81","size":"194.4"},{"price":"0.8","size":"193.5"},{"price":"0.79","size":"215.31"},{"price":"0.78","size":"197"},{"price":"0.77","size":"229.34"},{"price":"0.76","size":"195.7"},{"price":"0.75","size":"190.2"},{"price":"0.74","size":"189.7"},{"price":"0.73","size":"194.3"},{"price":"0.72","size":"188.89"},{"price":"0.71","size":"188.5"},{"price":"0.7","size":"206.48"},{"price":"0.69","size":"394.45"},{"price":"0.68","size":"187.5"},{"price":"0.67","size":"193.55"},{"price":"0.66","size":"187"},{"price":"0.65","size":"602.68"},{"price":"0.64","size":"186.6"},{"price":"0.63","size":"191.96"},{"price":"0.62","size":"186.3"},{"price":"0.61","size":"491.36"},{"price":"0.6","size":"226"},{"price":"0.59","size":"203.32"},{"price":"0.58","size":"185.8"},{"price":"0.57","size":"190.8"},{"price":"0.56","size":"190.6"},{"price":"0.55","size":"230.58"},{"price":"0.54","size":"185.5"},{"price":"0.53","size":"245.86"},{"price":"0.52","size":"242.56"},{"price":"0.51","size":"222.4"},{"price":"0.5","size":"378.64"},{"price":"0.49","size":"205.25"},{"price":"0.48","size":"226.77"},{"price":"0.47","size":"136.71"},{"price":"0.46","size":"185.5"},{"price":"0.45","size":"213.66"},{"price":"0.44","size":"190.6"},{"price":"0.43","size":"180.7"},{"price":"0.42","size":"180.8"},{"price":"0.41","size":"180.9"},{"price":"0.4","size":"139"},{"price":"0.39","size":"185.46"},{"price":"0.38","size":"141.3"},{"price":"0.37","size":"131.4"},{"price":"0.36","size":"131.6"},{"price":"0.35","size":"136.8"},{"price":"0.34","size":"342"},{"price":"0.33","size":"232.3"},{"price":"0.32","size":"382.5"},{"price":"0.31","size":"182.8"},{"price":"0.3","size":"244.95"},{"price":"0.29","size":"405.5"},{"price":"0.28","size":"530.89"},{"price":"0.27","size":"217.3"},{"price":"0.26","size":"287.7"},{"price":"0.25","size":"387.29"},{"price":"0.24","size":"148.49"},{"price":"0.23","size":"221.3"},{"price":"0.22","size":"328.98"},{"price":"0.21","size":"219.7"},{"price":"0.2","size":"245.25"},{"price":"0.19","size":"304.9"},{"price":"0.18","size":"325.78"},{"price":"0.17","size":"327.8"},{"price":"0.16","size":"384.37"},{"price":"0.15","size":"452.28"},{"price":"0.14","size":"362.5"}],"hash":"62330640045949a2ffe7084bbc90003626fd457d","timestamp":"1776808415094","event_type":"book"}}
{"capturedAt":1776808415,"payload":{"market":"0x125149c5918fc5f8c6d34682f700a898a1a19ea4f4e2ae68ff4c5794ba657074","price_changes":[{"asset_id":"45936375922793925919605092352922707796689801895417366600539442410775071099958","price":"0.86","size":"385.23","side":"BUY","hash":"2c48b22878cab407f6bc210fafb41765071e71af","best_bid":"0.86","best_ask":"0.87"},{"asset_id":"86520121088881862182423437128238697252500151785248183602134095101149900014256","price":"0.14","size":"385.23","side":"SELL","hash":"133f6ebc25384f9e239627d6517fdb9e10a3772f","best_bid":"0.13","best_ask":"0.14"}],"timestamp":"1776808415105","event_type":"price_change"}}
{"capturedAt":1776808415,"payload":{"market":"0x125149c5918fc5f8c6d34682f700a898a1a19ea4f4e2ae68ff4c5794ba657074","price_changes":[{"asset_id":"45936375922793925919605092352922707796689801895417366600539442410775071099958","price":"0.86","size":"356.23","side":"BUY","hash":"53aa93a91dcab665fddfd4c81fbc09d06b71129d","best_bid":"0.86","best_ask":"0.87"},{"asset_id":"86520121088881862182423437128238697252500151785248183602134095101149900014256","price":"0.14","size":"356.23","side":"SELL","hash":"2a78324e02418c7c1cb5911533e1367cf4fe323b","best_bid":"0.13","best_ask":"0.14"}],"timestamp":"1776808415102","event_type":"price_change"}}
{"capturedAt":1776808415,"payload":{"market":"0x125149c5918fc5f8c6d34682f700a898a1a19ea4f4e2ae68ff4c5794ba657074","price_changes":[{"asset_id":"45936375922793925919605092352922707796689801895417366600539442410775071099958","price":"0.85","size":"457.28","side":"BUY","hash":"f84ab267867f1f6dce6458af25572951cc4ee105","best_bid":"0.86","best_ask":"0.87"},{"asset_id":"86520121088881862182423437128238697252500151785248183602134095101149900014256","price":"0.15","size":"457.28","side":"SELL","hash":"bfac6c939acedc0e934d3ad32299f5328eb2840b","best_bid":"0.13","best_ask":"0.14"}],"timestamp":"1776808415107","event_type":"price_change"}}
{"capturedAt":1776808415,"payload":{"market":"0x125149c5918fc5f8c6d34682f700a898a1a19ea4f4e2ae68ff4c5794ba657074","price_changes":[{"asset_id":"45936375922793925919605092352922707796689801895417366600539442410775071099958","price":"0.01","size":"12329.83","side":"BUY","hash":"bd60ea50ad2898c0a360524cb55d62f3b3215f39","best_bid":"0.86","best_ask":"0.87"},{"asset_id":"86520121088881862182423437128238697252500151785248183602134095101149900014256","price":"0.99","size":"12329.83","side":"SELL","hash":"3f961f49da03fc5cc25c20d412508324f275e436","best_bid":"0.13","best_ask":"0.14"}],"timestamp":"1776808415125","event_type":"price_change"}}
{"capturedAt":1776808415,"payload":{"market":"0x125149c5918fc5f8c6d34682f700a898a1a19ea4f4e2ae68ff4c5794ba657074","price_changes":[{"asset_id":"45936375922793925919605092352922707796689801895417366600539442410775071099958","price":"0.86","size":"314.23","side":"BUY","hash":"3dc600fa55b25049a510755d4613dd167a7a91f2","best_bid":"0.86","best_ask":"0.87"},{"asset_id":"86520121088881862182423437128238697252500151785248183602134095101149900014256","price":"0.14","size":"314.23","side":"SELL","hash":"fcc15bddf8bb02c4c27bab4d1fcffd146e7d55ee","best_bid":"0.13","best_ask":"0.14"}],"timestamp":"1776808415127","event_type":"price_change"}}
{"capturedAt":1776808415,"payload":{"market":"0x125149c5918fc5f8c6d34682f700a898a1a19ea4f4e2ae68ff4c5794ba657074","price_changes":[{"asset_id":"45936375922793925919605092352922707796689801895417366600539442410775071099958","price":"0.86","size":"373.23","side":"BUY","hash":"6d7768aef8ecae84564e256a9521652b95f6126f","best_bid":"0.86","best_ask":"0.87"},{"asset_id":"86520121088881862182423437128238697252500151785248183602134095101149900014256","price":"0.14","size":"373.23","side":"SELL","hash":"c1578818c028806169101a6d2c2226d62871836d","best_bid":"0.13","best_ask":"0.14"}],"timestamp":"1776808415106","event_type":"price_change"}}
{"capturedAt":1776808415,"payload":{"market":"0x125149c5918fc5f8c6d34682f700a898a1a19ea4f4e2ae68ff4c5794ba657074","price_changes":[{"asset_id":"45936375922793925919605092352922707796689801895417366600539442410775071099958","price":"0.86","size":"333.23","side":"BUY","hash":"5da560b9d042384fa271781889247186235cc60a","best_bid":"0.86","best_ask":"0.87"},{"asset_id":"86520121088881862182423437128238697252500151785248183602134095101149900014256","price":"0.14","size":"333.23","side":"SELL","hash":"3888d8e50faef6e6fe69884d211a57f15cfcd09c","best_bid":"0.13","best_ask":"0.14"}],"timestamp":"1776808415126","event_type":"price_change"}}
{"capturedAt":1776808415,"payload":{"market":"0x125149c5918fc5f8c6d34682f700a898a1a19ea4f4e2ae68ff4c5794ba657074","price_changes":[{"asset_id":"45936375922793925919605092352922707796689801895417366600539442410775071099958","price":"0.76","size":"148.49","side":"BUY","hash":"86415b395aa7d39ad9aae1f58cc3899140b8f868","best_bid":"0.86","best_ask":"0.87"},{"asset_id":"86520121088881862182423437128238697252500151785248183602134095101149900014256","price":"0.24","size":"148.49","side":"SELL","hash":"a839e33a60fcca834082a05c2b631cb46a2602ce","best_bid":"0.13","best_ask":"0.14"}],"timestamp":"1776808415128","event_type":"price_change"}}
{"capturedAt":1776808415,"payload":{"market":"0x125149c5918fc5f8c6d34682f700a898a1a19ea4f4e2ae68ff4c5794ba657074","asset_id":"86520121088881862182423437128238697252500151785248183602134095101149900014256","price":"0.14","size":"7.142856","fee_rate_bps":"1000","side":"BUY","timestamp":"1776808415116","event_type":"last_trade_price","transaction_hash":"0x2d9b80667cd3c9db175b6548762aa0b1b371b6e6f1590a3388c86668e1fb61fa"}}
{"capturedAt":1776808415,"payload":{"market":"0x125149c5918fc5f8c6d34682f700a898a1a19ea4f4e2ae68ff4c5794ba657074","price_changes":[{"asset_id":"45936375922793925919605092352922707796689801895417366600539442410775071099958","price":"0.86","size":"294.23","side":"BUY","hash":"618e176037b5ccd76b406f9e337f01031ecb4616","best_bid":"0.86","best_ask":"0.87"},{"asset_id":"86520121088881862182423437128238697252500151785248183602134095101149900014256","price":"0.14","size":"294.23","side":"SELL","hash":"e59ccabd3b9e500661ad9619b915ca4c8eccba17","best_bid":"0.13","best_ask":"0.14"}],"timestamp":"1776808415127","event_type":"price_change"}}
{"capturedAt":1776808415,"payload":{"market":"0x125149c5918fc5f8c6d34682f700a898a1a19ea4f4e2ae68ff4c5794ba657074","price_changes":[{"asset_id":"86520121088881862182423437128238697252500151785248183602134095101149900014256","price":"0.11","size":"386.5","side":"BUY","hash":"878b76bfdef01e2058974ec3c54445656a1881c2","best_bid":"0.13","best_ask":"0.14"},{"asset_id":"45936375922793925919605092352922707796689801895417366600539442410775071099958","price":"0.89","size":"386.5","side":"SELL","hash":"40f3edfc043d536ad9b1f2e03240e43adaee5131","best_bid":"0.86","best_ask":"0.87"}],"timestamp":"1776808415130","event_type":"price_change"}}
{"capturedAt":1776808415,"payload":{"market":"0x125149c5918fc5f8c6d34682f700a898a1a19ea4f4e2ae68ff4c5794ba657074","price_changes":[{"asset_id":"45936375922793925919605092352922707796689801895417366600539442410775071099958","price":"0.01","size":"12334.83","side":"BUY","hash":"a369f7ef9dbba6b1c88d9a0f00062ff675053a8c","best_bid":"0.86","best_ask":"0.87"},{"asset_id":"86520121088881862182423437128238697252500151785248183602134095101149900014256","price":"0.99","size":"12334.83","side":"SELL","hash":"4c1e97d2e949c955cc2cdfa2afcdb3c381a52f3c","best_bid":"0.13","best_ask":"0.14"}],"timestamp":"1776808415131","event_type":"price_change"}}
{"capturedAt":1776808415,"payload":{"market":"0x125149c5918fc5f8c6d34682f700a898a1a19ea4f4e2ae68ff4c5794ba657074","price_changes":[{"asset_id":"45936375922793925919605092352922707796689801895417366600539442410775071099958","price":"0.86","size":"353.23","side":"BUY","hash":"cd4f5441b37695c63f7d3f3cb0cff329b6d379dc","best_bid":"0.86","best_ask":"0.87"},{"asset_id":"86520121088881862182423437128238697252500151785248183602134095101149900014256","price":"0.14","size":"353.23","side":"SELL","hash":"47cb30c999ba77efa1d6a690150bcd87daed3220","best_bid":"0.13","best_ask":"0.14"}],"timestamp":"1776808415124","event_type":"price_change"}}
{"capturedAt":1776808415,"payload":{"market":"0x125149c5918fc5f8c6d34682f700a898a1a19ea4f4e2ae68ff4c5794ba657074","price_changes":[{"asset_id":"45936375922793925919605092352922707796689801895417366600539442410775071099958","price":"0.86","size":"267.23","side":"BUY","hash":"d40aef92b3113aa347c5d630a3b91f6d29eb40b2","best_bid":"0.86","best_ask":"0.87"},{"asset_id":"86520121088881862182423437128238697252500151785248183602134095101149900014256","price":"0.14","size":"267.23","side":"SELL","hash":"2da0e0bce24bccd50e63988b7e39da3c424a41e3","best_bid":"0.13","best_ask":"0.14"}],"timestamp":"1776808415132","event_type":"price_change"}}
{"capturedAt":1776808415,"payload":{"market":"0x125149c5918fc5f8c6d34682f700a898a1a19ea4f4e2ae68ff4c5794ba657074","price_changes":[{"asset_id":"45936375922793925919605092352922707796689801895417366600539442410775071099958","price":"0.75","size":"382.29","side":"BUY","hash":"86415b395aa7d39ad9aae1f58cc3899140b8f868","best_bid":"0.86","best_ask":"0.87"},{"asset_id":"86520121088881862182423437128238697252500151785248183602134095101149900014256","price":"0.25","size":"382.29","side":"SELL","hash":"a839e33a60fcca834082a05c2b631cb46a2602ce","best_bid":"0.13","best_ask":"0.14"}],"timestamp":"1776808415128","event_type":"price_change"}}
{"capturedAt":1776808415,"payload":{"market":"0x125149c5918fc5f8c6d34682f700a898a1a19ea4f4e2ae68ff4c5794ba657074","price_changes":[{"asset_id":"45936375922793925919605092352922707796689801895417366600539442410775071099958","price":"0.86","size":"270.23","side":"BUY","hash":"ca20781a4f13a345e9ecd787881430762f5c2949","best_bid":"0.86","best_ask":"0.87"},{"asset_id":"86520121088881862182423437128238697252500151785248183602134095101149900014256","price":"0.14","size":"270.23","side":"SELL","hash":"5cb60c1892103383a6d89953a5bc79a1345d4ac1","best_bid":"0.13","best_ask":"0.14"}],"timestamp":"1776808415133","event_type":"price_change"}}
{"capturedAt":1776808415,"payload":{"market":"0x125149c5918fc5f8c6d34682f700a898a1a19ea4f4e2ae68ff4c5794ba657074","price_changes":[{"asset_id":"45936375922793925919605092352922707796689801895417366600539442410775071099958","price":"0.86","size":"283.23","side":"BUY","hash":"7717663f607eec9c8df8442f90573417949ee310","best_bid":"0.86","best_ask":"0.87"},{"asset_id":"86520121088881862182423437128238697252500151785248183602134095101149900014256","price":"0.14","size":"283.23","side":"SELL","hash":"f77c005a3f5abd35f6693acc8aa712cd6ecc8200","best_bid":"0.13","best_ask":"0.14"}],"timestamp":"1776808415135","event_type":"price_change"}}
{"capturedAt":1776808415,"payload":{"market":"0x125149c5918fc5f8c6d34682f700a898a1a19ea4f4e2ae68ff4c5794ba657074","price_changes":[{"asset_id":"45936375922793925919605092352922707796689801895417366600539442410775071099958","price":"0.01","size":"12329.83","side":"BUY","hash":"9b69706b1800bb49fa5e7ff1e5a46fc4cba048ca","best_bid":"0.86","best_ask":"0.87"},{"asset_id":"86520121088881862182423437128238697252500151785248183602134095101149900014256","price":"0.99","size":"12329.83","side":"SELL","hash":"63218c5a22e5eb71bbf1065ebc4ed787fb1ad1ee","best_bid":"0.13","best_ask":"0.14"}],"timestamp":"1776808415145","event_type":"price_change"}}
{"capturedAt":1776808415,"payload":{"market":"0x125149c5918fc5f8c6d34682f700a898a1a19ea4f4e2ae68ff4c5794ba657074","price_changes":[{"asset_id":"45936375922793925919605092352922707796689801895417366600539442410775071099958","price":"0.86","size":"264.23","side":"BUY","hash":"abce945f590a35221f8a215f565928246d5cb2dc","best_bid":"0.86","best_ask":"0.87"},{"asset_id":"86520121088881862182423437128238697252500151785248183602134095101149900014256","price":"0.14","size":"264.23","side":"SELL","hash":"f8845deeb20a55e1b95983204cf6380a58005ec0","best_bid":"0.13","best_ask":"0.14"}],"timestamp":"1776808415147","event_type":"price_change"}}
{"capturedAt":1776808415,"payload":{"market":"0x125149c5918fc5f8c6d34682f700a898a1a19ea4f4e2ae68ff4c5794ba657074","price_changes":[{"asset_id":"45936375922793925919605092352922707796689801895417366600539442410775071099958","price":"0.86","size":"257.23","side":"BUY","hash":"ebc96b1a4a9add15254f3d61e5f129aef78ebc92","best_bid":"0.86","best_ask":"0.87"},{"asset_id":"86520121088881862182423437128238697252500151785248183602134095101149900014256","price":"0.14","size":"257.23","side":"SELL","hash":"3fb5679308973b115fc69dea83903fc4309fbfbf","best_bid":"0.13","best_ask":"0.14"}],"timestamp":"1776808415132","event_type":"price_change"}}
{"capturedAt":1776808415,"payload":{"market":"0x125149c5918fc5f8c6d34682f700a898a1a19ea4f4e2ae68ff4c5794ba657074","price_changes":[{"asset_id":"45936375922793925919605092352922707796689801895417366600539442410775071099958","price":"0.86","size":"284.23","side":"BUY","hash":"af60a1f8eccfa1f28e4b5aefab9c9aa1755b54ee","best_bid":"0.86","best_ask":"0.87"},{"asset_id":"86520121088881862182423437128238697252500151785248183602134095101149900014256","price":"0.14","size":"284.23","side":"SELL","hash":"81d760783c523b30232f3679accf5d6804e9796e","best_bid":"0.13","best_ask":"0.14"}],"timestamp":"1776808415129","event_type":"price_change"}}
{"capturedAt":1776808415,"payload":{"market":"0x125149c5918fc5f8c6d34682f700a898a1a19ea4f4e2ae68ff4c5794ba657074","price_changes":[{"asset_id":"45936375922793925919605092352922707796689801895417366600539442410775071099958","price":"0.86","size":"262.23","side":"BUY","hash":"f611c59e0aaa9fbadb11907fdb57177bc5ebe374","best_bid":"0.86","best_ask":"0.87"},{"asset_id":"86520121088881862182423437128238697252500151785248183602134095101149900014256","price":"0.14","size":"262.23","side":"SELL","hash":"e81d04f8606d78c67c049c066efc27dab73f88dc","best_bid":"0.13","best_ask":"0.14"}],"timestamp":"1776808415139","event_type":"price_change"}}
{"capturedAt":1776808415,"payload":{"market":"0x125149c5918fc5f8c6d34682f700a898a1a19ea4f4e2ae68ff4c5794ba657074","price_changes":[{"asset_id":"45936375922793925919605092352922707796689801895417366600539442410775071099958","price":"0.86","size":"258.5","side":"BUY","hash":"7f6de28885bc72eb875a6bde859bd8c1bb20a392","best_bid":"0.86","best_ask":"0.87"},{"asset_id":"86520121088881862182423437128238697252500151785248183602134095101149900014256","price":"0.14","size":"258.5","side":"SELL","hash":"10a715e8381d9059b02ae7eb409dd9ff7e9f4008","best_bid":"0.13","best_ask":"0.14"}],"timestamp":"1776808415148","event_type":"price_change"}}
{"capturedAt":1776808415,"payload":{"market":"0x125149c5918fc5f8c6d34682f700a898a1a19ea4f4e2ae68ff4c5794ba657074","price_changes":[{"asset_id":"45936375922793925919605092352922707796689801895417366600539442410775071099958","price":"0.86","size":"287.23","side":"BUY","hash":"11fc2d66e5b7f25291f4c163292e968cc34445d2","best_bid":"0.86","best_ask":"0.87"},{"asset_id":"86520121088881862182423437128238697252500151785248183602134095101149900014256","price":"0.14","size":"287.23","side":"SELL","hash":"cb5c1edf812a0d77f0e6decfc768c5f39236f355","best_bid":"0.13","best_ask":"0.14"}],"timestamp":"1776808415146","event_type":"price_change"}}
{"capturedAt":1776808415,"payload":{"market":"0x125149c5918fc5f8c6d34682f700a898a1a19ea4f4e2ae68ff4c5794ba657074","price_changes":[{"asset_id":"45936375922793925919605092352922707796689801895417366600539442410775071099958","price":"0.01","size":"12324.83","side":"BUY","hash":"d2c48e14a7c84ff9751fde69c2b317323e743e6c","best_bid":"0.86","best_ask":"0.87"},{"asset_id":"86520121088881862182423437128238697252500151785248183602134095101149900014256","price":"0.99","size":"12324.83","side":"SELL","hash":"7fb88c694ec9090caa5ccf45856fe6d9f5220cb3","best_bid":"0.13","best_ask":"0.14"}],"timestamp":"1776808415149","event_type":"price_change"}}
{"capturedAt":1776808415,"payload":{"market":"0x125149c5918fc5f8c6d34682f700a898a1a19ea4f4e2ae68ff4c5794ba657074","price_changes":[{"asset_id":"45936375922793925919605092352922707796689801895417366600539442410775071099958","price":"0.86","size":"368.23","side":"BUY","hash":"cd4e4035872bc4c7ab5b05dd31a7213cb5e73e22","best_bid":"0.86","best_ask":"0.87"},{"asset_id":"86520121088881862182423437128238697252500151785248183602134095101149900014256","price":"0.14","size":"368.23","side":"SELL","hash":"d131a11de5f1bfd0b25418a1222e250225b614bf","best_bid":"0.13","best_ask":"0.14"}],"timestamp":"1776808415100","event_type":"price_change"}}
{"capturedAt":1776808415,"payload":{"market":"0x125149c5918fc5f8c6d34682f700a898a1a19ea4f4e2ae68ff4c5794ba657074","price_changes":[{"asset_id":"45936375922793925919605092352922707796689801895417366600539442410775071099958","price":"0.86","size":"281.5","side":"BUY","hash":"d562379b63dee9c766b5eb99141b9cd6457baddf","best_bid":"0.86","best_ask":"0.87"},{"asset_id":"86520121088881862182423437128238697252500151785248183602134095101149900014256","price":"0.14","size":"281.5","side":"SELL","hash":"5a94fb6fa113db705b767f6c8fc6e9f3d2d8efc4","best_bid":"0.13","best_ask":"0.14"}],"timestamp":"1776808415150","event_type":"price_change"}}
{"capturedAt":1776808415,"payload":{"market":"0x125149c5918fc5f8c6d34682f700a898a1a19ea4f4e2ae68ff4c5794ba657074","price_changes":[{"asset_id":"45936375922793925919605092352922707796689801895417366600539442410775071099958","price":"0.86","size":"360.5","side":"BUY","hash":"20b6c048cac2c53a56bbb67806532854466b640c","best_bid":"0.86","best_ask":"0.87"},{"asset_id":"86520121088881862182423437128238697252500151785248183602134095101149900014256","price":"0.14","size":"360.5","side":"SELL","hash":"d8698fa1a955feb85494ddd9017b94dd06757963","best_bid":"0.13","best_ask":"0.14"}],"timestamp":"1776808415161","event_type":"price_change"}}
{"capturedAt":1776808415,"payload":{"market":"0x125149c5918fc5f8c6d34682f700a898a1a19ea4f4e2ae68ff4c5794ba657074","price_changes":[{"asset_id":"45936375922793925919605092352922707796689801895417366600539442410775071099958","price":"0.86","size":"338.5","side":"BUY","hash":"4ce319a1994490fc5789f45275e51614079f849c","best_bid":"0.86","best_ask":"0.87"},{"asset_id":"86520121088881862182423437128238697252500151785248183602134095101149900014256","price":"0.14","size":"338.5","side":"SELL","hash":"63437a969da8fffa9f756bbd8d104a047b746468","best_bid":"0.13","best_ask":"0.14"}],"timestamp":"1776808415160","event_type":"price_change"}}
{"capturedAt":1776808415,"payload":{"market":"0x125149c5918fc5f8c6d34682f700a898a1a19ea4f4e2ae68ff4c5794ba657074","price_changes":[{"asset_id":"45936375922793925919605092352922707796689801895417366600539442410775071099958","price":"0.86","size":"271.5","side":"BUY","hash":"2f0dd8adfc257e5f55d42a1f1586cee6e05500e7","best_bid":"0.86","best_ask":"0.87"},{"asset_id":"86520121088881862182423437128238697252500151785248183602134095101149900014256","price":"0.14","size":"271.5","side":"SELL","hash":"dd0a108643dcb784f0f87dfd93f7fb62bfa9b87f","best_bid":"0.13","best_ask":"0.14"}],"timestamp":"1776808415153","event_type":"price_change"}}
{"capturedAt":1776808415,"payload":{"market":"0x125149c5918fc5f8c6d34682f700a898a1a19ea4f4e2ae68ff4c5794ba657074","price_changes":[{"asset_id":"45936375922793925919605092352922707796689801895417366600539442410775071099958","price":"0.86","size":"338.5","side":"BUY","hash":"4ac5e3055415b406aecae57b1f87c0b27b992f11","best_bid":"0.86","best_ask":"0.87"},{"asset_id":"86520121088881862182423437128238697252500151785248183602134095101149900014256","price":"0.14","size":"338.5","side":"SELL","hash":"892462a9f8bc4a957afef173623a8b6632b2bc72","best_bid":"0.13","best_ask":"0.14"}],"timestamp":"1776808415166","event_type":"price_change"}}
{"capturedAt":1776808415,"payload":{"market":"0x125149c5918fc5f8c6d34682f700a898a1a19ea4f4e2ae68ff4c5794ba657074","price_changes":[{"asset_id":"45936375922793925919605092352922707796689801895417366600539442410775071099958","price":"0.86","size":"360.5","side":"BUY","hash":"36d9b19188efdd55b6d9262b99712aaf49a3cd67","best_bid":"0.86","best_ask":"0.87"},{"asset_id":"86520121088881862182423437128238697252500151785248183602134095101149900014256","price":"0.14","size":"360.5","side":"SELL","hash":"65fc8d36d2914a329080624a26dbebfe5558afa7","best_bid":"0.13","best_ask":"0.14"}],"timestamp":"1776808415169","event_type":"price_change"}}
{"capturedAt":1776808415,"payload":{"market":"0x125149c5918fc5f8c6d34682f700a898a1a19ea4f4e2ae68ff4c5794ba657074","price_changes":[{"asset_id":"45936375922793925919605092352922707796689801895417366600539442410775071099958","price":"0.86","size":"382.5","side":"BUY","hash":"caaf64326097af6153618ea8b5135aa60e8186b8","best_bid":"0.86","best_ask":"0.87"},{"asset_id":"86520121088881862182423437128238697252500151785248183602134095101149900014256","price":"0.14","size":"382.5","side":"SELL","hash":"952742e3649539e03208c15acdac5147390d0cae","best_bid":"0.13","best_ask":"0.14"}],"timestamp":"1776808415170","event_type":"price_change"}}
{"capturedAt":1776808415,"payload":{"market":"0x125149c5918fc5f8c6d34682f700a898a1a19ea4f4e2ae68ff4c5794ba657074","price_changes":[{"asset_id":"45936375922793925919605092352922707796689801895417366600539442410775071099958","price":"0.86","size":"387.5","side":"BUY","hash":"86158c7f09217a1383ccb1aa5f29de63c0619eff","best_bid":"0.86","best_ask":"0.87"},{"asset_id":"86520121088881862182423437128238697252500151785248183602134095101149900014256","price":"0.14","size":"387.5","side":"SELL","hash":"9c03a81f3432f222e5661defae54cae91e81b393","best_bid":"0.13","best_ask":"0.14"}],"timestamp":"1776808415172","event_type":"price_change"}}
{"capturedAt":1776808415,"payload":{"market":"0x125149c5918fc5f8c6d34682f700a898a1a19ea4f4e2ae68ff4c5794ba657074","price_changes":[{"asset_id":"45936375922793925919605092352922707796689801895417366600539442410775071099958","price":"0.86","size":"363.5","side":"BUY","hash":"a4aa6b26fed1661476a9a69c9061fd5925df7d3c","best_bid":"0.86","best_ask":"0.87"},{"asset_id":"86520121088881862182423437128238697252500151785248183602134095101149900014256","price":"0.14","size":"363.5","side":"SELL","hash":"c9269875784345b8f707570bcdb23959596145b7","best_bid":"0.13","best_ask":"0.14"}],"timestamp":"1776808415173","event_type":"price_change"}}
{"capturedAt":1776808415,"payload":{"market":"0x125149c5918fc5f8c6d34682f700a898a1a19ea4f4e2ae68ff4c5794ba657074","price_changes":[{"asset_id":"45936375922793925919605092352922707796689801895417366600539442410775071099958","price":"0.86","size":"306.5","side":"BUY","hash":"a2b5d32b6f026baafaeb0b6b932053fa29896c95","best_bid":"0.86","best_ask":"0.87"},{"asset_id":"86520121088881862182423437128238697252500151785248183602134095101149900014256","price":"0.14","size":"306.5","side":"SELL","hash":"7536b9cd50966fba85cc33858453048d6c8f9031","best_bid":"0.13","best_ask":"0.14"}],"timestamp":"1776808415157","event_type":"price_change"}}
{"capturedAt":1776808415,"payload":{"market":"0x125149c5918fc5f8c6d34682f700a898a1a19ea4f4e2ae68ff4c5794ba657074","price_changes":[{"asset_id":"45936375922793925919605092352922707796689801895417366600539442410775071099958","price":"0.86","size":"296.5","side":"BUY","hash":"eb1d11fc921825693a30aefcd28e4cedb016a87b","best_bid":"0.86","best_ask":"0.87"},{"asset_id":"86520121088881862182423437128238697252500151785248183602134095101149900014256","price":"0.14","size":"296.5","side":"SELL","hash":"d06c93c711901600d9b05407bedb476b758f2f43","best_bid":"0.13","best_ask":"0.14"}],"timestamp":"1776808415156","event_type":"price_change"}}
{"capturedAt":1776808415,"payload":{"market":"0x125149c5918fc5f8c6d34682f700a898a1a19ea4f4e2ae68ff4c5794ba657074","price_changes":[{"asset_id":"45936375922793925919605092352922707796689801895417366600539442410775071099958","price":"0.86","size":"328.5","side":"BUY","hash":"908220f7f5a7366451921f565a39573626578b2a","best_bid":"0.86","best_ask":"0.87"},{"asset_id":"86520121088881862182423437128238697252500151785248183602134095101149900014256","price":"0.14","size":"328.5","side":"SELL","hash":"6ad0f3cd0c491eb8c0dca8aa3d72a92839f07e86","best_bid":"0.13","best_ask":"0.14"}],"timestamp":"1776808415159","event_type":"price_change"}}
{"capturedAt":1776808415,"payload":{"market":"0x125149c5918fc5f8c6d34682f700a898a1a19ea4f4e2ae68ff4c5794ba657074","price_changes":[{"asset_id":"45936375922793925919605092352922707796689801895417366600539442410775071099958","price":"0.01","size":"12329.83","side":"BUY","hash":"079c076a8fb1d851a605f9d0eff3b0ca1e87c1f7","best_bid":"0.86","best_ask":"0.87"},{"asset_id":"86520121088881862182423437128238697252500151785248183602134095101149900014256","price":"0.99","size":"12329.83","side":"SELL","hash":"e8fd9fb19f154f408120af57e8f2f70878ee566a","best_bid":"0.13","best_ask":"0.14"}],"timestamp":"1776808415187","event_type":"price_change"}}
{"capturedAt":1776808415,"payload":{"market":"0x125149c5918fc5f8c6d34682f700a898a1a19ea4f4e2ae68ff4c5794ba657074","price_changes":[{"asset_id":"45936375922793925919605092352922707796689801895417366600539442410775071099958","price":"0.86","size":"358.5","side":"BUY","hash":"1ae8cdfc7e263424696e2f08d604414f74940e43","best_bid":"0.86","best_ask":"0.87"},{"asset_id":"86520121088881862182423437128238697252500151785248183602134095101149900014256","price":"0.14","size":"358.5","side":"SELL","hash":"5d14d474c12a89e071c05877fec32f8a08995011","best_bid":"0.13","best_ask":"0.14"}],"timestamp":"1776808415187","event_type":"price_change"}}
{"capturedAt":1776808415,"payload":{"market":"0x125149c5918fc5f8c6d34682f700a898a1a19ea4f4e2ae68ff4c5794ba657074","price_changes":[{"asset_id":"45936375922793925919605092352922707796689801895417366600539442410775071099958","price":"0.85","size":"452.28","side":"BUY","hash":"1ae8cdfc7e263424696e2f08d604414f74940e43","best_bid":"0.86","best_ask":"0.87"},{"asset_id":"86520121088881862182423437128238697252500151785248183602134095101149900014256","price":"0.15","size":"452.28","side":"SELL","hash":"5d14d474c12a89e071c05877fec32f8a08995011","best_bid":"0.13","best_ask":"0.14"}],"timestamp":"1776808415187","event_type":"price_change"}}
{"capturedAt":1776808415,"payload":{"market":"0x125149c5918fc5f8c6d34682f700a898a1a19ea4f4e2ae68ff4c5794ba657074","price_changes":[{"asset_id":"45936375922793925919605092352922707796689801895417366600539442410775071099958","price":"0.86","size":"363.5","side":"BUY","hash":"2ae611a9ca19d739352001b61b02a91a0cd8c9d6","best_bid":"0.86","best_ask":"0.87"},{"asset_id":"86520121088881862182423437128238697252500151785248183602134095101149900014256","price":"0.14","size":"363.5","side":"SELL","hash":"4a6198a2c27ee3bb95b6a1e987660866f5cefca0","best_bid":"0.13","best_ask":"0.14"}],"timestamp":"1776808415194","event_type":"price_change"}}
{"capturedAt":1776808415,"payload":{"market":"0x125149c5918fc5f8c6d34682f700a898a1a19ea4f4e2ae68ff4c5794ba657074","price_changes":[{"asset_id":"45936375922793925919605092352922707796689801895417366600539442410775071099958","price":"0.86","size":"353.5","side":"BUY","hash":"52d2c58f9ecdd2a6439174ab3633882fa2f59dba","best_bid":"0.86","best_ask":"0.87"},{"asset_id":"86520121088881862182423437128238697252500151785248183602134095101149900014256","price":"0.14","size":"353.5","side":"SELL","hash":"2ec03ae4e12611b9c406d858969d309ee3661e7d","best_bid":"0.13","best_ask":"0.14"}],"timestamp":"1776808415192","event_type":"price_change"}}
{"capturedAt":1776808415,"payload":{"market":"0x125149c5918fc5f8c6d34682f700a898a1a19ea4f4e2ae68ff4c5794ba657074","price_changes":[{"asset_id":"86520121088881862182423437128238697252500151785248183602134095101149900014256","price":"0.07","size":"685.3","side":"BUY","hash":"90f09f63cdb179c480069f9354c3a41a840d2870","best_bid":"0.13","best_ask":"0.14"},{"asset_id":"45936375922793925919605092352922707796689801895417366600539442410775071099958","price":"0.93","size":"685.3","side":"SELL","hash":"c6652de9a68b7afecec0768a023f350b8157fb6e","best_bid":"0.86","best_ask":"0.87"}],"timestamp":"1776808415196","event_type":"price_change"}}
{"capturedAt":1776808415,"payload":{"market":"0x125149c5918fc5f8c6d34682f700a898a1a19ea4f4e2ae68ff4c5794ba657074","price_changes":[{"asset_id":"86520121088881862182423437128238697252500151785248183602134095101149900014256","price":"0.07","size":"713.3","side":"BUY","hash":"43ef828f00c47b9dc224b158d415b96af1141c7c","best_bid":"0.13","best_ask":"0.14"},{"asset_id":"45936375922793925919605092352922707796689801895417366600539442410775071099958","price":"0.93","size":"713.3","side":"SELL","hash":"49b8722be6bf780b2a9bf33bb31797f8cc071232","best_bid":"0.86","best_ask":"0.87"}],"timestamp":"1776808415195","event_type":"price_change"}}
{"capturedAt":1776808415,"payload":{"market":"0x125149c5918fc5f8c6d34682f700a898a1a19ea4f4e2ae68ff4c5794ba657074","price_changes":[{"asset_id":"45936375922793925919605092352922707796689801895417366600539442410775071099958","price":"0.86","size":"387.5","side":"BUY","hash":"592de1e2b3a0aeece8da34d82b8527ed253bcbcd","best_bid":"0.86","best_ask":"0.87"},{"asset_id":"86520121088881862182423437128238697252500151785248183602134095101149900014256","price":"0.14","size":"387.5","side":"SELL","hash":"06dcdbab891463fdf33a55e95ef6a3f0580a92e6","best_bid":"0.13","best_ask":"0.14"}],"timestamp":"1776808415199","event_type":"price_change"}}
{"capturedAt":1776808415,"payload":{"market":"0x125149c5918fc5f8c6d34682f700a898a1a19ea4f4e2ae68ff4c5794ba657074","price_changes":[{"asset_id":"45936375922793925919605092352922707796689801895417366600539442410775071099958","price":"0.01","size":"12334.83","side":"BUY","hash":"6a33f628d34da73e0e08b860fee9f715229f93b7","best_bid":"0.86","best_ask":"0.87"},{"asset_id":"86520121088881862182423437128238697252500151785248183602134095101149900014256","price":"0.99","size":"12334.83","side":"SELL","hash":"f8e2cbbbbeb512e1cd95cfe16932d3a4a00ca17a","best_bid":"0.13","best_ask":"0.14"}],"timestamp":"1776808415200","event_type":"price_change"}}
{"capturedAt":1776808415,"payload":{"market":"0x125149c5918fc5f8c6d34682f700a898a1a19ea4f4e2ae68ff4c5794ba657074","price_changes":[{"asset_id":"45936375922793925919605092352922707796689801895417366600539442410775071099958","price":"0.86","size":"412.5","side":"BUY","hash":"51bb043392690d98b1ee1fdca32ab3fb35c939f7","best_bid":"0.86","best_ask":"0.87"},{"asset_id":"86520121088881862182423437128238697252500151785248183602134095101149900014256","price":"0.14","size":"412.5","side":"SELL","hash":"59cf473a2e9827312b90040af611ec84969cc3f1","best_bid":"0.13","best_ask":"0.14"}],"timestamp":"1776808415203","event_type":"price_change"}}
{"capturedAt":1776808415,"payload":{"market":"0x125149c5918fc5f8c6d34682f700a898a1a19ea4f4e2ae68ff4c5794ba657074","price_changes":[{"asset_id":"45936375922793925919605092352922707796689801895417366600539442410775071099958","price":"0.86","size":"399.5","side":"BUY","hash":"dacfd795eb5bd2ac6e8cc572ced3ad3f1942c898","best_bid":"0.86","best_ask":"0.87"},{"asset_id":"86520121088881862182423437128238697252500151785248183602134095101149900014256","price":"0.14","size":"399.5","side":"SELL","hash":"9be52dfb90f734808f868dd706707d2ecf5b405a","best_bid":"0.13","best_ask":"0.14"}],"timestamp":"1776808415203","event_type":"price_change"}}
{"capturedAt":1776808415,"payload":{"market":"0x125149c5918fc5f8c6d34682f700a898a1a19ea4f4e2ae68ff4c5794ba657074","price_changes":[{"asset_id":"45936375922793925919605092352922707796689801895417366600539442410775071099958","price":"0.86","size":"386.5","side":"BUY","hash":"708b7fde6546d3a3984ceb2f7dc6c7fbed86be13","best_bid":"0.86","best_ask":"0.87"},{"asset_id":"86520121088881862182423437128238697252500151785248183602134095101149900014256","price":"0.14","size":"386.5","side":"SELL","hash":"5d05d3d4551502f97d9a1ebde6a8103487f7f2af","best_bid":"0.13","best_ask":"0.14"}],"timestamp":"1776808415204","event_type":"price_change"}}
{"capturedAt":1776808415,"payload":{"market":"0x125149c5918fc5f8c6d34682f700a898a1a19ea4f4e2ae68ff4c5794ba657074","price_changes":[{"asset_id":"45936375922793925919605092352922707796689801895417366600539442410775071099958","price":"0.01","size":"12329.83","side":"BUY","hash":"abc89a46a579a9efc50f1287481d800b5107f48a","best_bid":"0.86","best_ask":"0.87"},{"asset_id":"86520121088881862182423437128238697252500151785248183602134095101149900014256","price":"0.99","size":"12329.83","side":"SELL","hash":"f9349d2124bf93b29527a0e32e9cedac953b0c47","best_bid":"0.13","best_ask":"0.14"}],"timestamp":"1776808415209","event_type":"price_change"}}
{"capturedAt":1776808415,"payload":{"market":"0x125149c5918fc5f8c6d34682f700a898a1a19ea4f4e2ae68ff4c5794ba657074","price_changes":[{"asset_id":"45936375922793925919605092352922707796689801895417366600539442410775071099958","price":"0.86","size":"361.6","side":"BUY","hash":"916fff5d93a611826c0d8495daa5e8e803902ce8","best_bid":"0.86","best_ask":"0.87"},{"asset_id":"86520121088881862182423437128238697252500151785248183602134095101149900014256","price":"0.14","size":"361.6","side":"SELL","hash":"ea7236607c4ac3f61b204626b291fd7ad31652c4","best_bid":"0.13","best_ask":"0.14"}],"timestamp":"1776808415219","event_type":"price_change"}}
{"capturedAt":1776808415,"payload":{"market":"0x125149c5918fc5f8c6d34682f700a898a1a19ea4f4e2ae68ff4c5794ba657074","price_changes":[{"asset_id":"45936375922793925919605092352922707796689801895417366600539442410775071099958","price":"0.86","size":"376.5","side":"BUY","hash":"bc7371ae45eeaf008822fd00cf2b14baa688c879","best_bid":"0.86","best_ask":"0.87"},{"asset_id":"86520121088881862182423437128238697252500151785248183602134095101149900014256","price":"0.14","size":"376.5","side":"SELL","hash":"d3adf6176295bd849bc2dc195234aa5617b4e0a0","best_bid":"0.13","best_ask":"0.14"}],"timestamp":"1776808415215","event_type":"price_change"}}
{"capturedAt":1776808415,"payload":{"market":"0x125149c5918fc5f8c6d34682f700a898a1a19ea4f4e2ae68ff4c5794ba657074","price_changes":[{"asset_id":"45936375922793925919605092352922707796689801895417366600539442410775071099958","price":"0.01","size":"12324.83","side":"BUY","hash":"aebdaa9b665580ba631bfda00e7e08286f91a601","best_bid":"0.86","best_ask":"0.87"},{"asset_id":"86520121088881862182423437128238697252500151785248183602134095101149900014256","price":"0.99","size":"12324.83","side":"SELL","hash":"fb6969afa01b2f60fead7bbce0eaa3d2a46cb211","best_bid":"0.13","best_ask":"0.14"}],"timestamp":"1776808415220","event_type":"price_change"}}
{"capturedAt":1776808415,"payload":{"market":"0x125149c5918fc5f8c6d34682f700a898a1a19ea4f4e2ae68ff4c5794ba657074","price_changes":[{"asset_id":"45936375922793925919605092352922707796689801895417366600539442410775071099958","price":"0.86","size":"356.6","side":"BUY","hash":"7f9f8cbd85f0d54e1cbd5266c9bd9ecf5e2d60a6","best_bid":"0.86","best_ask":"0.87"},{"asset_id":"86520121088881862182423437128238697252500151785248183602134095101149900014256","price":"0.14","size":"356.6","side":"SELL","hash":"269357fef6be372fc69a2ab331735d97b13dcd54","best_bid":"0.13","best_ask":"0.14"}],"timestamp":"1776808415217","event_type":"price_change"}}
{"capturedAt":1776808415,"payload":{"market":"0x125149c5918fc5f8c6d34682f700a898a1a19ea4f4e2ae68ff4c5794ba657074","price_changes":[{"asset_id":"45936375922793925919605092352922707796689801895417366600539442410775071099958","price":"0.86","size":"381.6","side":"BUY","hash":"205ce616b2d2e64ca0059a9b364feb41aff3ce79","best_bid":"0.86","best_ask":"0.87"},{"asset_id":"86520121088881862182423437128238697252500151785248183602134095101149900014256","price":"0.14","size":"381.6","side":"SELL","hash":"f86cb7fe5945ef6f6c4a3cc7101aefdd4ee51a37","best_bid":"0.13","best_ask":"0.14"}],"timestamp":"1776808415216","event_type":"price_change"}}
{"capturedAt":1776808415,"payload":{"market":"0x125149c5918fc5f8c6d34682f700a898a1a19ea4f4e2ae68ff4c5794ba657074","price_changes":[{"asset_id":"45936375922793925919605092352922707796689801895417366600539442410775071099958","price":"0.86","size":"338.6","side":"BUY","hash":"3f314fc2cfdaf9b89b551b6c8cfb6b153bd5d6f8","best_bid":"0.86","best_ask":"0.87"},{"asset_id":"86520121088881862182423437128238697252500151785248183602134095101149900014256","price":"0.14","size":"338.6","side":"SELL","hash":"dca4c0ac8051356f501e68e9827ee2d609869c36","best_bid":"0.13","best_ask":"0.14"}],"timestamp":"1776808415220","event_type":"price_change"}}
{"capturedAt":1776808415,"payload":{"market":"0x125149c5918fc5f8c6d34682f700a898a1a19ea4f4e2ae68ff4c5794ba657074","price_changes":[{"asset_id":"45936375922793925919605092352922707796689801895417366600539442410775071099958","price":"0.85","size":"457.28","side":"BUY","hash":"273b6d1071b0f2f314d649ea45c429405e0e9d14","best_bid":"0.86","best_ask":"0.87"},{"asset_id":"86520121088881862182423437128238697252500151785248183602134095101149900014256","price":"0.15","size":"457.28","side":"SELL","hash":"d2ef784523bb888885bdc8488a4aef176d16a94d","best_bid":"0.13","best_ask":"0.14"}],"timestamp":"1776808415218","event_type":"price_change"}}
{"capturedAt":1776808415,"payload":{"market":"0x125149c5918fc5f8c6d34682f700a898a1a19ea4f4e2ae68ff4c5794ba657074","price_changes":[{"asset_id":"45936375922793925919605092352922707796689801895417366600539442410775071099958","price":"0.86","size":"313.6","side":"BUY","hash":"3f8555094a0a1ede0c0c5c3091672f4f06dbdf96","best_bid":"0.86","best_ask":"0.87"},{"asset_id":"86520121088881862182423437128238697252500151785248183602134095101149900014256","price":"0.14","size":"313.6","side":"SELL","hash":"1a731b5d365056ae2150eac0bd44c217d31f7531","best_bid":"0.13","best_ask":"0.14"}],"timestamp":"1776808415225","event_type":"price_change"}}
{"capturedAt":1776808415,"payload":{"market":"0x125149c5918fc5f8c6d34682f700a898a1a19ea4f4e2ae68ff4c5794ba657074","price_changes":[{"asset_id":"45936375922793925919605092352922707796689801895417366600539442410775071099958","price":"0.86","size":"291.6","side":"BUY","hash":"867d249690e3d54dcd37dc1823479df20dd84332","best_bid":"0.86","best_ask":"0.87"},{"asset_id":"86520121088881862182423437128238697252500151785248183602134095101149900014256","price":"0.14","size":"291.6","side":"SELL","hash":"62bcac50139bf70a68004e084414058ead804c53","best_bid":"0.13","best_ask":"0.14"}],"timestamp":"1776808415228","event_type":"price_change"}}
{"capturedAt":1776808415,"payload":{"market":"0x125149c5918fc5f8c6d34682f700a898a1a19ea4f4e2ae68ff4c5794ba657074","price_changes":[{"asset_id":"45936375922793925919605092352922707796689801895417366600539442410775071099958","price":"0.86","size":"269.6","side":"BUY","hash":"47218aebb978f14fade153708f698b96b27b576e","best_bid":"0.86","best_ask":"0.87"},{"asset_id":"86520121088881862182423437128238697252500151785248183602134095101149900014256","price":"0.14","size":"269.6","side":"SELL","hash":"873fb834476554a1d39cb9cc3bac738a28c06ea2","best_bid":"0.13","best_ask":"0.14"}],"timestamp":"1776808415230","event_type":"price_change"}}
{"capturedAt":1776808415,"payload":{"market":"0x125149c5918fc5f8c6d34682f700a898a1a19ea4f4e2ae68ff4c5794ba657074","price_changes":[{"asset_id":"45936375922793925919605092352922707796689801895417366600539442410775071099958","price":"0.86","size":"259.6","side":"BUY","hash":"a3b7a090a08e73c3322b3e6b9b2464fa792af111","best_bid":"0.86","best_ask":"0.87"},{"asset_id":"86520121088881862182423437128238697252500151785248183602134095101149900014256","price":"0.14","size":"259.6","side":"SELL","hash":"614b34f822944065964605cdceadb3d4415d413e","best_bid":"0.13","best_ask":"0.14"}],"timestamp":"1776808415233","event_type":"price_change"}}
{"capturedAt":1776808415,"payload":{"market":"0x125149c5918fc5f8c6d34682f700a898a1a19ea4f4e2ae68ff4c5794ba657074","price_changes":[{"asset_id":"45936375922793925919605092352922707796689801895417366600539442410775071099958","price":"0.86","size":"271.6","side":"BUY","hash":"5bc6700cfcd21437011aebc711ff9c8746b1be05","best_bid":"0.86","best_ask":"0.87"},{"asset_id":"86520121088881862182423437128238697252500151785248183602134095101149900014256","price":"0.14","size":"271.6","side":"SELL","hash":"24f89af086ce0eefd0342fb42536aa385f160532","best_bid":"0.13","best_ask":"0.14"}],"timestamp":"1776808415234","event_type":"price_change"}}
{"capturedAt":1776808415,"payload":{"market":"0x125149c5918fc5f8c6d34682f700a898a1a19ea4f4e2ae68ff4c5794ba657074","price_changes":[{"asset_id":"45936375922793925919605092352922707796689801895417366600539442410775071099958","price":"0.86","size":"278.5","side":"BUY","hash":"68ff1f27bd0c965e07aae139026074683092d502","best_bid":"0.86","best_ask":"0.87"},{"asset_id":"86520121088881862182423437128238697252500151785248183602134095101149900014256","price":"0.14","size":"278.5","side":"SELL","hash":"18d12870c54b5f7a09a5d0960377c926f26a9027","best_bid":"0.13","best_ask":"0.14"}],"timestamp":"1776808415236","event_type":"price_change"}}
{"capturedAt":1776808415,"payload":{"market":"0x125149c5918fc5f8c6d34682f700a898a1a19ea4f4e2ae68ff4c5794ba657074","price_changes":[{"asset_id":"45936375922793925919605092352922707796689801895417366600539442410775071099958","price":"0.86","size":"266.5","side":"BUY","hash":"fa3df27af1b68114e955ce163070776a919e3259","best_bid":"0.86","best_ask":"0.87"},{"asset_id":"86520121088881862182423437128238697252500151785248183602134095101149900014256","price":"0.14","size":"266.5","side":"SELL","hash":"2c1198e5818cb776d3d0c15688385439ac75b7de","best_bid":"0.13","best_ask":"0.14"}],"timestamp":"1776808415235","event_type":"price_change"}}
{"capturedAt":1776808415,"payload":{"market":"0x125149c5918fc5f8c6d34682f700a898a1a19ea4f4e2ae68ff4c5794ba657074","price_changes":[{"asset_id":"45936375922793925919605092352922707796689801895417366600539442410775071099958","price":"0.01","size":"12329.84","side":"BUY","hash":"9dd3358910c3ed84813e8dc7fab512f8b0e46f15","best_bid":"0.86","best_ask":"0.87"},{"asset_id":"86520121088881862182423437128238697252500151785248183602134095101149900014256","price":"0.99","size":"12329.84","side":"SELL","hash":"b8897f08cfaa83729df2638ce8837da7f3758f28","best_bid":"0.13","best_ask":"0.14"}],"timestamp":"1776808415237","event_type":"price_change"}}
{"capturedAt":1776808415,"payload":{"market":"0x125149c5918fc5f8c6d34682f700a898a1a19ea4f4e2ae68ff4c5794ba657074","price_changes":[{"asset_id":"45936375922793925919605092352922707796689801895417366600539442410775071099958","price":"0.01","size":"12334.84","side":"BUY","hash":"fb06afe90ce46cf717119e027c9c28e694a361d2","best_bid":"0.86","best_ask":"0.87"},{"asset_id":"86520121088881862182423437128238697252500151785248183602134095101149900014256","price":"0.99","size":"12334.84","side":"SELL","hash":"5be4f053c36d5d2af057f6a7b44f83358fda2ef8","best_bid":"0.13","best_ask":"0.14"}],"timestamp":"1776808415238","event_type":"price_change"}}
{"capturedAt":1776808415,"payload":{"market":"0x125149c5918fc5f8c6d34682f700a898a1a19ea4f4e2ae68ff4c5794ba657074","price_changes":[{"asset_id":"45936375922793925919605092352922707796689801895417366600539442410775071099958","price":"0.86","size":"256.5","side":"BUY","hash":"cc88a6df10dfeed0dd661be19f23ef9eced90bb2","best_bid":"0.86","best_ask":"0.87"},{"asset_id":"86520121088881862182423437128238697252500151785248183602134095101149900014256","price":"0.14","size":"256.5","side":"SELL","hash":"fef0ed9d785540f8a5d898e3468d896b2e817def","best_bid":"0.13","best_ask":"0.14"}],"timestamp":"1776808415240","event_type":"price_change"}}
{"capturedAt":1776808415,"payload":{"market":"0x125149c5918fc5f8c6d34682f700a898a1a19ea4f4e2ae68ff4c5794ba657074","price_changes":[{"asset_id":"45936375922793925919605092352922707796689801895417366600539442410775071099958","price":"0.86","size":"234.5","side":"BUY","hash":"a20954bc69227e34e8c143264423c9e3090fcfe5","best_bid":"0.86","best_ask":"0.87"},{"asset_id":"86520121088881862182423437128238697252500151785248183602134095101149900014256","price":"0.14","size":"234.5","side":"SELL","hash":"f72ab677c091d6a7c1877ec01f921e576ba6f38b","best_bid":"0.13","best_ask":"0.14"}],"timestamp":"1776808415241","event_type":"price_change"}}
{"capturedAt":1776808415,"payload":{"market":"0x125149c5918fc5f8c6d34682f700a898a1a19ea4f4e2ae68ff4c5794ba657074","price_changes":[{"asset_id":"45936375922793925919605092352922707796689801895417366600539442410775071099958","price":"0.86","size":"244.5","side":"BUY","hash":"04a2c86cf250c94c45e95e22db975cb2fdef68f3","best_bid":"0.86","best_ask":"0.87"},{"asset_id":"86520121088881862182423437128238697252500151785248183602134095101149900014256","price":"0.14","size":"244.5","side":"SELL","hash":"c150ac2063d26b9ab1ae6922d6ec2cc56612a4da","best_bid":"0.13","best_ask":"0.14"}],"timestamp":"1776808415242","event_type":"price_change"}}
{"capturedAt":1776808415,"payload":{"market":"0x125149c5918fc5f8c6d34682f700a898a1a19ea4f4e2ae68ff4c5794ba657074","price_changes":[{"asset_id":"45936375922793925919605092352922707796689801895417366600539442410775071099958","price":"0.86","size":"264.5","side":"BUY","hash":"cbcc41f367d057b0b75d2a98824f0864a3a4ed03","best_bid":"0.86","best_ask":"0.87"},{"asset_id":"86520121088881862182423437128238697252500151785248183602134095101149900014256","price":"0.14","size":"264.5","side":"SELL","hash":"990e4bc174654ccd301f05ec9c8d4d5396b4b0c7","best_bid":"0.13","best_ask":"0.14"}],"timestamp":"1776808415246","event_type":"price_change"}}
{"capturedAt":1776808415,"payload":{"market":"0x125149c5918fc5f8c6d34682f700a898a1a19ea4f4e2ae68ff4c5794ba657074","price_changes":[{"asset_id":"45936375922793925919605092352922707796689801895417366600539442410775071099958","price":"0.01","size":"12339.84","side":"BUY","hash":"ee949b2fd6d33863fb54b0e80082598e5a3dc7d9","best_bid":"0.86","best_ask":"0.87"},{"asset_id":"86520121088881862182423437128238697252500151785248183602134095101149900014256","price":"0.99","size":"12339.84","side":"SELL","hash":"d0622b858ad21b32605bd0c8ed50634f1f69f13a","best_bid":"0.13","best_ask":"0.14"}],"timestamp":"1776808415249","event_type":"price_change"}}
{"capturedAt":1776808415,"payload":{"market":"0x125149c5918fc5f8c6d34682f700a898a1a19ea4f4e2ae68ff4c5794ba657074","price_changes":[{"asset_id":"45936375922793925919605092352922707796689801895417366600539442410775071099958","price":"0.86","size":"283.5","side":"BUY","hash":"bbf41c852653b972150f27fe9eae36d809b14bfa","best_bid":"0.86","best_ask":"0.87"},{"asset_id":"86520121088881862182423437128238697252500151785248183602134095101149900014256","price":"0.14","size":"283.5","side":"SELL","hash":"f8fdc161f88444bdff688a2ffc156cb196de6162","best_bid":"0.13","best_ask":"0.14"}],"timestamp":"1776808415250","event_type":"price_change"}}
{"capturedAt":1776808415,"payload":{"market":"0x125149c5918fc5f8c6d34682f700a898a1a19ea4f4e2ae68ff4c5794ba657074","price_changes":[{"asset_id":"45936375922793925919605092352922707796689801895417366600539442410775071099958","price":"0.86","size":"302.5","side":"BUY","hash":"5b8114a742635726321ee8fbf00156b6d0360603","best_bid":"0.86","best_ask":"0.87"},{"asset_id":"86520121088881862182423437128238697252500151785248183602134095101149900014256","price":"0.14","size":"302.5","side":"SELL","hash":"92737d4326fa5684144ddf4470b47384685c3ef6","best_bid":"0.13","best_ask":"0.14"}],"timestamp":"1776808415251","event_type":"price_change"}}
{"capturedAt":1776808415,"payload":{"market":"0x125149c5918fc5f8c6d34682f700a898a1a19ea4f4e2ae68ff4c5794ba657074","price_changes":[{"asset_id":"45936375922793925919605092352922707796689801895417366600539442410775071099958","price":"0.01","size":"12334.84","side":"BUY","hash":"7049fb03359d72e18949f8d3885ea4a1de332628","best_bid":"0.86","best_ask":"0.87"},{"asset_id":"86520121088881862182423437128238697252500151785248183602134095101149900014256","price":"0.99","size":"12334.84","side":"SELL","hash":"7ac12dac2d1c406f5f79263db36c248d9c2066c3","best_bid":"0.13","best_ask":"0.14"}],"timestamp":"1776808415257","event_type":"price_change"}}
{"capturedAt":1776808415,"payload":{"market":"0x125149c5918fc5f8c6d34682f700a898a1a19ea4f4e2ae68ff4c5794ba657074","price_changes":[{"asset_id":"45936375922793925919605092352922707796689801895417366600539442410775071099958","price":"0.86","size":"320.5","side":"BUY","hash":"0339271d8d43591004255f147762712c8dfce44b","best_bid":"0.86","best_ask":"0.87"},{"asset_id":"86520121088881862182423437128238697252500151785248183602134095101149900014256","price":"0.14","size":"320.5","side":"SELL","hash":"963ba0dd06c46317fb6c777a3ff322ade4a3ce9c","best_bid":"0.13","best_ask":"0.14"}],"timestamp":"1776808415258","event_type":"price_change"}}
{"capturedAt":1776808415,"payload":{"market":"0x125149c5918fc5f8c6d34682f700a898a1a19ea4f4e2ae68ff4c5794ba657074","price_changes":[{"asset_id":"45936375922793925919605092352922707796689801895417366600539442410775071099958","price":"0.86","size":"330.5","side":"BUY","hash":"ccbe90182438c244a09a7f38534ae45b5a9185a3","best_bid":"0.86","best_ask":"0.87"},{"asset_id":"86520121088881862182423437128238697252500151785248183602134095101149900014256","price":"0.14","size":"330.5","side":"SELL","hash":"d56765e73f959e5215a347632fd912dcb27c2ff7","best_bid":"0.13","best_ask":"0.14"}],"timestamp":"1776808415259","event_type":"price_change"}}
{"capturedAt":1776808415,"payload":{"market":"0x125149c5918fc5f8c6d34682f700a898a1a19ea4f4e2ae68ff4c5794ba657074","price_changes":[{"asset_id":"45936375922793925919605092352922707796689801895417366600539442410775071099958","price":"0.86","size":"348.5","side":"BUY","hash":"21566bcdb884b47e6472df0baf7af376e9ac2c82","best_bid":"0.86","best_ask":"0.87"},{"asset_id":"86520121088881862182423437128238697252500151785248183602134095101149900014256","price":"0.14","size":"348.5","side":"SELL","hash":"27bbcaa036abe81c04f1dda8760241c8654b02f1","best_bid":"0.13","best_ask":"0.14"}],"timestamp":"1776808415260","event_type":"price_change"}}
{"capturedAt":1776808415,"payload":{"market":"0x125149c5918fc5f8c6d34682f700a898a1a19ea4f4e2ae68ff4c5794ba657074","price_changes":[{"asset_id":"45936375922793925919605092352922707796689801895417366600539442410775071099958","price":"0.01","size":"12329.83","side":"BUY","hash":"6e35b97a397fd1bc8a945024750fc813ec014142","best_bid":"0.86","best_ask":"0.87"},{"asset_id":"86520121088881862182423437128238697252500151785248183602134095101149900014256","price":"0.99","size":"12329.83","side":"SELL","hash":"9e21b00c3e72ff88bd899dd5ce1386e24f815fe8","best_bid":"0.13","best_ask":"0.14"}],"timestamp":"1776808415263","event_type":"price_change"}}
{"capturedAt":1776808415,"payload":{"market":"0x125149c5918fc5f8c6d34682f700a898a1a19ea4f4e2ae68ff4c5794ba657074","price_changes":[{"asset_id":"45936375922793925919605092352922707796689801895417366600539442410775071099958","price":"0.86","size":"338.5","side":"BUY","hash":"131b3002bc386a525ebd28bf38ff96e332668beb","best_bid":"0.86","best_ask":"0.87"},{"asset_id":"86520121088881862182423437128238697252500151785248183602134095101149900014256","price":"0.14","size":"338.5","side":"SELL","hash":"fce8841947fae788a90258588936f339671e4756","best_bid":"0.13","best_ask":"0.14"}],"timestamp":"1776808415265","event_type":"price_change"}}
{"capturedAt":1776808415,"payload":{"market":"0x125149c5918fc5f8c6d34682f700a898a1a19ea4f4e2ae68ff4c5794ba657074","price_changes":[{"asset_id":"45936375922793925919605092352922707796689801895417366600539442410775071099958","price":"0.55","size":"207.66","side":"BUY","hash":"730c97c04c2a961241fe4f9c3c986adbab453c30","best_bid":"0.86","best_ask":"0.87"},{"asset_id":"86520121088881862182423437128238697252500151785248183602134095101149900014256","price":"0.45","size":"207.66","side":"SELL","hash":"cf74713205e0e4b006b8be20a5da002c09e9e1e8","best_bid":"0.13","best_ask":"0.14"}],"timestamp":"1776808415267","event_type":"price_change"}}
{"capturedAt":1776808415,"payload":{"market":"0x125149c5918fc5f8c6d34682f700a898a1a19ea4f4e2ae68ff4c5794ba657074","price_changes":[{"asset_id":"86520121088881862182423437128238697252500151785248183602134095101149900014256","price":"0.05","size":"790.63","side":"BUY","hash":"7d538750276de11f9a3ae1b60eea6e68411a1626","best_bid":"0.13","best_ask":"0.14"},{"asset_id":"45936375922793925919605092352922707796689801895417366600539442410775071099958","price":"0.95","size":"790.63","side":"SELL","hash":"e39e10f6d9c7dea5f91c58a70650a3f0eecff7ff","best_bid":"0.86","best_ask":"0.87"}],"timestamp":"1776808415268","event_type":"price_change"}}
{"capturedAt":1776808415,"payload":{"market":"0x125149c5918fc5f8c6d34682f700a898a1a19ea4f4e2ae68ff4c5794ba657074","price_changes":[{"asset_id":"45936375922793925919605092352922707796689801895417366600539442410775071099958","price":"0.01","size":"12324.83","side":"BUY","hash":"4c3ab6774978ef9057968b07e1c02c60ffe488e4","best_bid":"0.86","best_ask":"0.87"},{"asset_id":"86520121088881862182423437128238697252500151785248183602134095101149900014256","price":"0.99","size":"12324.83","side":"SELL","hash":"fa72f5292acbf00b99606b2b16ef9269a0638627","best_bid":"0.13","best_ask":"0.14"}],"timestamp":"1776808415269","event_type":"price_change"}}
{"capturedAt":1776808415,"payload":{"market":"0x125149c5918fc5f8c6d34682f700a898a1a19ea4f4e2ae68ff4c5794ba657074","price_changes":[{"asset_id":"45936375922793925919605092352922707796689801895417366600539442410775071099958","price":"0.86","size":"356.5","side":"BUY","hash":"8e2dac07d016ec71576fda9f35c66308baf6a14a","best_bid":"0.86","best_ask":"0.87"},{"asset_id":"86520121088881862182423437128238697252500151785248183602134095101149900014256","price":"0.14","size":"356.5","side":"SELL","hash":"79afd255db824d68bc46a803f22387492337c071","best_bid":"0.13","best_ask":"0.14"}],"timestamp":"1776808415270","event_type":"price_change"}}
{"capturedAt":1776808415,"payload":{"market":"0x125149c5918fc5f8c6d34682f700a898a1a19ea4f4e2ae68ff4c5794ba657074","price_changes":[{"asset_id":"45936375922793925919605092352922707796689801895417366600539442410775071099958","price":"0.86","size":"374.5","side":"BUY","hash":"2951c6a45263e2fa79801a518f7f94991e05d92f","best_bid":"0.86","best_ask":"0.87"},{"asset_id":"86520121088881862182423437128238697252500151785248183602134095101149900014256","price":"0.14","size":"374.5","side":"SELL","hash":"5aada0b52fa501f0032f62edb93fd203d206c4b0","best_bid":"0.13","best_ask":"0.14"}],"timestamp":"1776808415271","event_type":"price_change"}}
{"capturedAt":1776808415,"payload":{"market":"0x125149c5918fc5f8c6d34682f700a898a1a19ea4f4e2ae68ff4c5794ba657074","price_changes":[{"asset_id":"45936375922793925919605092352922707796689801895417366600539442410775071099958","price":"0.86","size":"350.5","side":"BUY","hash":"fe0483fb86a8ac53ef45befea300e8ac4677ba1e","best_bid":"0.86","best_ask":"0.87"},{"asset_id":"86520121088881862182423437128238697252500151785248183602134095101149900014256","price":"0.14","size":"350.5","side":"SELL","hash":"280f3572cf137c77a55e51ee437c493616b60f3b","best_bid":"0.13","best_ask":"0.14"}],"timestamp":"1776808415272","event_type":"price_change"}}
{"capturedAt":1776808415,"payload":{"market":"0x125149c5918fc5f8c6d34682f700a898a1a19ea4f4e2ae68ff4c5794ba657074","price_changes":[{"asset_id":"45936375922793925919605092352922707796689801895417366600539442410775071099958","price":"0.86","size":"325.5","side":"BUY","hash":"7834aff13e249b4b314a06f5162de47b2f7c15c1","best_bid":"0.86","best_ask":"0.87"},{"asset_id":"86520121088881862182423437128238697252500151785248183602134095101149900014256","price":"0.14","size":"325.5","side":"SELL","hash":"0296520a4066a54140a9744f098f9ab925b134cf","best_bid":"0.13","best_ask":"0.14"}],"timestamp":"1776808415274","event_type":"price_change"}}
{"capturedAt":1776808415,"payload":{"market":"0x125149c5918fc5f8c6d34682f700a898a1a19ea4f4e2ae68ff4c5794ba657074","price_changes":[{"asset_id":"45936375922793925919605092352922707796689801895417366600539442410775071099958","price":"0.01","size":"12329.84","side":"BUY","hash":"9e90376e26f5426b4dd4da41757c6b863870dec8","best_bid":"0.86","best_ask":"0.87"},{"asset_id":"86520121088881862182423437128238697252500151785248183602134095101149900014256","price":"0.99","size":"12329.84","side":"SELL","hash":"bf3deee472ea5d2c0ae50c2c95580671909af231","best_bid":"0.13","best_ask":"0.14"}],"timestamp":"1776808415275","event_type":"price_change"}}
{"capturedAt":1776808415,"payload":{"market":"0x125149c5918fc5f8c6d34682f700a898a1a19ea4f4e2ae68ff4c5794ba657074","price_changes":[{"asset_id":"45936375922793925919605092352922707796689801895417366600539442410775071099958","price":"0.01","size":"12334.84","side":"BUY","hash":"0b7827e267c6f77189c45a3423b7832d904aa1f8","best_bid":"0.86","best_ask":"0.87"},{"asset_id":"86520121088881862182423437128238697252500151785248183602134095101149900014256","price":"0.99","size":"12334.84","side":"SELL","hash":"84a6c8cbe953628d3b3d415d598553a522acaa64","best_bid":"0.13","best_ask":"0.14"}],"timestamp":"1776808415291","event_type":"price_change"}}
{"capturedAt":1776808415,"payload":{"market":"0x125149c5918fc5f8c6d34682f700a898a1a19ea4f4e2ae68ff4c5794ba657074","price_changes":[{"asset_id":"45936375922793925919605092352922707796689801895417366600539442410775071099958","price":"0.86","size":"335.5","side":"BUY","hash":"2b2935a7e6d26815f7aabf81e09347636d83af68","best_bid":"0.86","best_ask":"0.87"},{"asset_id":"86520121088881862182423437128238697252500151785248183602134095101149900014256","price":"0.14","size":"335.5","side":"SELL","hash":"de454e376493e92b637c87cce6185aadec6ecb9e","best_bid":"0.13","best_ask":"0.14"}],"timestamp":"1776808415293","event_type":"price_change"}}
{"capturedAt":1776808415,"payload":{"market":"0x125149c5918fc5f8c6d34682f700a898a1a19ea4f4e2ae68ff4c5794ba657074","price_changes":[{"asset_id":"45936375922793925919605092352922707796689801895417366600539442410775071099958","price":"0.83","size":"353.3","side":"BUY","hash":"1ada67f041b14e723169a71aaa8aecefa2044556","best_bid":"0.86","best_ask":"0.87"},{"asset_id":"86520121088881862182423437128238697252500151785248183602134095101149900014256","price":"0.17","size":"353.3","side":"SELL","hash":"dd6d97066d819dd0750da195221fa9ed17ee2749","best_bid":"0.13","best_ask":"0.14"}],"timestamp":"1776808415294","event_type":"price_change"}}
{"capturedAt":1776808415,"payload":{"market":"0x125149c5918fc5f8c6d34682f700a898a1a19ea4f4e2ae68ff4c5794ba657074","price_changes":[{"asset_id":"45936375922793925919605092352922707796689801895417366600539442410775071099958","price":"0.86","size":"325.5","side":"BUY","hash":"7af1e7436d440e4b28ee180937b92ff9b463279a","best_bid":"0.86","best_ask":"0.87"},{"asset_id":"86520121088881862182423437128238697252500151785248183602134095101149900014256","price":"0.14","size":"325.5","side":"SELL","hash":"723ee704f4c90bfdac232f9f8d0f38d5311eb38d","best_bid":"0.13","best_ask":"0.14"}],"timestamp":"1776808415300","event_type":"price_change"}}
{"capturedAt":1776808415,"payload":{"market":"0x125149c5918fc5f8c6d34682f700a898a1a19ea4f4e2ae68ff4c5794ba657074","price_changes":[{"asset_id":"45936375922793925919605092352922707796689801895417366600539442410775071099958","price":"0.86","size":"345.5","side":"BUY","hash":"15d28da97c9011d1ee81652be54088930e76366c","best_bid":"0.86","best_ask":"0.87"},{"asset_id":"86520121088881862182423437128238697252500151785248183602134095101149900014256","price":"0.14","size":"345.5","side":"SELL","hash":"028e4562e50a7e39c5ab1d7c45c178e7937c74ab","best_bid":"0.13","best_ask":"0.14"}],"timestamp":"1776808415302","event_type":"price_change"}}
{"capturedAt":1776808415,"payload":{"market":"0x125149c5918fc5f8c6d34682f700a898a1a19ea4f4e2ae68ff4c5794ba657074","price_changes":[{"asset_id":"45936375922793925919605092352922707796689801895417366600539442410775071099958","price":"0.01","size":"12339.84","side":"BUY","hash":"bf766e80415123fd0a8807bf37ffeab25b31059b","best_bid":"0.86","best_ask":"0.87"},{"asset_id":"86520121088881862182423437128238697252500151785248183602134095101149900014256","price":"0.99","size":"12339.84","side":"SELL","hash":"871656386f814745a27b96844739671e62e64fed","best_bid":"0.13","best_ask":"0.14"}],"timestamp":"1776808415301","event_type":"price_change"}}
{"capturedAt":1776808415,"payload":{"market":"0x125149c5918fc5f8c6d34682f700a898a1a19ea4f4e2ae68ff4c5794ba657074","price_changes":[{"asset_id":"45936375922793925919605092352922707796689801895417366600539442410775071099958","price":"0.86","size":"365.5","side":"BUY","hash":"34b148820cf96d40724b2e50d712d1846f1a234f","best_bid":"0.86","best_ask":"0.87"},{"asset_id":"86520121088881862182423437128238697252500151785248183602134095101149900014256","price":"0.14","size":"365.5","side":"SELL","hash":"c300e70fe26201202a99f0a376782b1c86be6bd0","best_bid":"0.13","best_ask":"0.14"}],"timestamp":"1776808415303","event_type":"price_change"}}
{"capturedAt":1776808415,"payload":{"market":"0x125149c5918fc5f8c6d34682f700a898a1a19ea4f4e2ae68ff4c5794ba657074","price_changes":[{"asset_id":"45936375922793925919605092352922707796689801895417366600539442410775071099958","price":"0.86","size":"353.5","side":"BUY","hash":"e33c424d43e862cd13b4580535a2e02a6fa4ee55","best_bid":"0.86","best_ask":"0.87"},{"asset_id":"86520121088881862182423437128238697252500151785248183602134095101149900014256","price":"0.14","size":"353.5","side":"SELL","hash":"b55137eea51a03fa56258fe334b2ee753cd88e40","best_bid":"0.13","best_ask":"0.14"}],"timestamp":"1776808415304","event_type":"price_change"}}
{"capturedAt":1776808415,"payload":{"market":"0x125149c5918fc5f8c6d34682f700a898a1a19ea4f4e2ae68ff4c5794ba657074","price_changes":[{"asset_id":"45936375922793925919605092352922707796689801895417366600539442410775071099958","price":"0.01","size":"12334.83","side":"BUY","hash":"c53cee98f2c6f0e6d4316a0b0c8b192fc57254ce","best_bid":"0.86","best_ask":"0.87"},{"asset_id":"86520121088881862182423437128238697252500151785248183602134095101149900014256","price":"0.99","size":"12334.83","side":"SELL","hash":"5d92a1ebffcced9d3918914c5e2dd57d4d041b54","best_bid":"0.13","best_ask":"0.14"}],"timestamp":"1776808415306","event_type":"price_change"}}
{"capturedAt":1776808415,"payload":{"market":"0x125149c5918fc5f8c6d34682f700a898a1a19ea4f4e2ae68ff4c5794ba657074","price_changes":[{"asset_id":"45936375922793925919605092352922707796689801895417366600539442410775071099958","price":"0.86","size":"341.5","side":"BUY","hash":"6dfcb09052fe0e262ebe114a94aca7d924c14ec6","best_bid":"0.86","best_ask":"0.87"},{"asset_id":"86520121088881862182423437128238697252500151785248183602134095101149900014256","price":"0.14","size":"341.5","side":"SELL","hash":"de9c43b17444c545a96a4e3b127263ee1918b4cf","best_bid":"0.13","best_ask":"0.14"}],"timestamp":"1776808415307","event_type":"price_change"}}
{"capturedAt":1776808415,"payload":{"market":"0x125149c5918fc5f8c6d34682f700a898a1a19ea4f4e2ae68ff4c5794ba657074","price_changes":[{"asset_id":"45936375922793925919605092352922707796689801895417366600539442410775071099958","price":"0.01","size":"12329.83","side":"BUY","hash":"42cec648680e65066e43bda20c55dd3b64314d64","best_bid":"0.86","best_ask":"0.87"},{"asset_id":"86520121088881862182423437128238697252500151785248183602134095101149900014256","price":"0.99","size":"12329.83","side":"SELL","hash":"582c2bb2c06d4acc781e6a8d0e1e0c5ae551e6a5","best_bid":"0.13","best_ask":"0.14"}],"timestamp":"1776808415327","event_type":"price_change"}}
{"capturedAt":1776808415,"payload":{"market":"0x125149c5918fc5f8c6d34682f700a898a1a19ea4f4e2ae68ff4c5794ba657074","price_changes":[{"asset_id":"86520121088881862182423437128238697252500151785248183602134095101149900014256","price":"0.13","size":"228.2","side":"BUY","hash":"b5be1e6aec8701b7cff3010144e79d6b6aae9cba","best_bid":"0.13","best_ask":"0.14"},{"asset_id":"45936375922793925919605092352922707796689801895417366600539442410775071099958","price":"0.87","size":"228.2","side":"SELL","hash":"9addd977ea9b70e62aa8264dfb762b1c69fcac08","best_bid":"0.86","best_ask":"0.87"}],"timestamp":"1776808415326","event_type":"price_change"}}
{"capturedAt":1776808415,"payload":{"market":"0x125149c5918fc5f8c6d34682f700a898a1a19ea4f4e2ae68ff4c5794ba657074","price_changes":[{"asset_id":"45936375922793925919605092352922707796689801895417366600539442410775071099958","price":"0.86","size":"321.5","side":"BUY","hash":"aa70ff152c645a74292959c13f46cf6dc03a19e3","best_bid":"0.86","best_ask":"0.87"},{"asset_id":"86520121088881862182423437128238697252500151785248183602134095101149900014256","price":"0.14","size":"321.5","side":"SELL","hash":"78369ffb4727f4ea1c0975a712352aa904e3ca3c","best_bid":"0.13","best_ask":"0.14"}],"timestamp":"1776808415328","event_type":"price_change"}}
{"capturedAt":1776808415,"payload":{"market":"0x125149c5918fc5f8c6d34682f700a898a1a19ea4f4e2ae68ff4c5794ba657074","price_changes":[{"asset_id":"45936375922793925919605092352922707796689801895417366600539442410775071099958","price":"0.86","size":"283.5","side":"BUY","hash":"2984e4cc3903d90f3cd7aa65a0aac563aee60da5","best_bid":"0.86","best_ask":"0.87"},{"asset_id":"86520121088881862182423437128238697252500151785248183602134095101149900014256","price":"0.14","size":"283.5","side":"SELL","hash":"296c2ec5a942e5530499edfa718842143f06eb61","best_bid":"0.13","best_ask":"0.14"}],"timestamp":"1776808415329","event_type":"price_change"}}
{"capturedAt":1776808415,"payload":{"market":"0x125149c5918fc5f8c6d34682f700a898a1a19ea4f4e2ae68ff4c5794ba657074","price_changes":[{"asset_id":"45936375922793925919605092352922707796689801895417366600539442410775071099958","price":"0.86","size":"302.5","side":"BUY","hash":"728cdf7554c78fa0f080cfc33b4623735ac255cd","best_bid":"0.86","best_ask":"0.87"},{"asset_id":"86520121088881862182423437128238697252500151785248183602134095101149900014256","price":"0.14","size":"302.5","side":"SELL","hash":"67942c1dc6e7527a73b8bde0a41bf7bd0cb5ef62","best_bid":"0.13","best_ask":"0.14"}],"timestamp":"1776808415329","event_type":"price_change"}}
{"capturedAt":1776808415,"payload":{"market":"0x125149c5918fc5f8c6d34682f700a898a1a19ea4f4e2ae68ff4c5794ba657074","price_changes":[{"asset_id":"45936375922793925919605092352922707796689801895417366600539442410775071099958","price":"0.01","size":"12324.83","side":"BUY","hash":"0e3b1ba6154045652d79fbe565f7dbeb2f209dac","best_bid":"0.86","best_ask":"0.87"},{"asset_id":"86520121088881862182423437128238697252500151785248183602134095101149900014256","price":"0.99","size":"12324.83","side":"SELL","hash":"41e6c0863b1becdb43148a7b18194cc7dd85244e","best_bid":"0.13","best_ask":"0.14"}],"timestamp":"1776808415330","event_type":"price_change"}}
{"capturedAt":1776808415,"payload":{"market":"0x125149c5918fc5f8c6d34682f700a898a1a19ea4f4e2ae68ff4c5794ba657074","price_changes":[{"asset_id":"45936375922793925919605092352922707796689801895417366600539442410775071099958","price":"0.86","size":"299.2","side":"BUY","hash":"116617d0b1e8a113715a70f6f356fa025f5efecd","best_bid":"0.86","best_ask":"0.87"},{"asset_id":"86520121088881862182423437128238697252500151785248183602134095101149900014256","price":"0.14","size":"299.2","side":"SELL","hash":"97d978ba9e9740091ec68df0312f54e5f167ffbb","best_bid":"0.13","best_ask":"0.14"}],"timestamp":"1776808415332","event_type":"price_change"}}
{"capturedAt":1776808415,"payload":{"market":"0x125149c5918fc5f8c6d34682f700a898a1a19ea4f4e2ae68ff4c5794ba657074","price_changes":[{"asset_id":"45936375922793925919605092352922707796689801895417366600539442410775071099958","price":"0.86","size":"289.2","side":"BUY","hash":"da10cb6167f020e5e4b2cca49ae8b83b82f69a73","best_bid":"0.86","best_ask":"0.87"},{"asset_id":"86520121088881862182423437128238697252500151785248183602134095101149900014256","price":"0.14","size":"289.2","side":"SELL","hash":"2bcff8e0dd7fce625da938e3b9bd620e83f583b7","best_bid":"0.13","best_ask":"0.14"}],"timestamp":"1776808415331","event_type":"price_change"}}
{"capturedAt":1776808415,"payload":{"market":"0x125149c5918fc5f8c6d34682f700a898a1a19ea4f4e2ae68ff4c5794ba657074","price_changes":[{"asset_id":"45936375922793925919605092352922707796689801895417366600539442410775071099958","price":"0.86","size":"281.2","side":"BUY","hash":"751e0a3d553824462ab83d98b50257687b3e4253","best_bid":"0.86","best_ask":"0.87"},{"asset_id":"86520121088881862182423437128238697252500151785248183602134095101149900014256","price":"0.14","size":"281.2","side":"SELL","hash":"67d435a8c4cffecbb60418b9ef25881356fa7151","best_bid":"0.13","best_ask":"0.14"}],"timestamp":"1776808415333","event_type":"price_change"}}
{"capturedAt":1776808415,"payload":{"market":"0x125149c5918fc5f8c6d34682f700a898a1a19ea4f4e2ae68ff4c5794ba657074","price_changes":[{"asset_id":"45936375922793925919605092352922707796689801895417366600539442410775071099958","price":"0.86","size":"271.2","side":"BUY","hash":"ae44403deb5b3e728d668d29c23f056354e55a6a","best_bid":"0.86","best_ask":"0.87"},{"asset_id":"86520121088881862182423437128238697252500151785248183602134095101149900014256","price":"0.14","size":"271.2","side":"SELL","hash":"ef45424cf459f8666215f88dd506303d9f548785","best_bid":"0.13","best_ask":"0.14"}],"timestamp":"1776808415334","event_type":"price_change"}}
{"capturedAt":1776808415,"payload":{"market":"0x125149c5918fc5f8c6d34682f700a898a1a19ea4f4e2ae68ff4c5794ba657074","price_changes":[{"asset_id":"45936375922793925919605092352922707796689801895417366600539442410775071099958","price":"0.86","size":"283.2","side":"BUY","hash":"1676b2a309a7b764ef3d280bd855e282a914c43e","best_bid":"0.86","best_ask":"0.87"},{"asset_id":"86520121088881862182423437128238697252500151785248183602134095101149900014256","price":"0.14","size":"283.2","side":"SELL","hash":"e2f50c082d701d3e7e5c62625cc89bff45ddc52c","best_bid":"0.13","best_ask":"0.14"}],"timestamp":"1776808415334","event_type":"price_change"}}
{"capturedAt":1776808415,"payload":{"market":"0x125149c5918fc5f8c6d34682f700a898a1a19ea4f4e2ae68ff4c5794ba657074","price_changes":[{"asset_id":"45936375922793925919605092352922707796689801895417366600539442410775071099958","price":"0.86","size":"295.2","side":"BUY","hash":"44e7e59e31b2b5f89857c4746a899cbe4e9f9904","best_bid":"0.86","best_ask":"0.87"},{"asset_id":"86520121088881862182423437128238697252500151785248183602134095101149900014256","price":"0.14","size":"295.2","side":"SELL","hash":"81dc50d46017759a79ee98702a1d23698ce44b27","best_bid":"0.13","best_ask":"0.14"}],"timestamp":"1776808415336","event_type":"price_change"}}
{"capturedAt":1776808415,"payload":{"market":"0x125149c5918fc5f8c6d34682f700a898a1a19ea4f4e2ae68ff4c5794ba657074","price_changes":[{"asset_id":"45936375922793925919605092352922707796689801895417366600539442410775071099958","price":"0.86","size":"277.2","side":"BUY","hash":"868a9af983d6a2fb34fdb0170b7b2f3de674ee0a","best_bid":"0.86","best_ask":"0.87"},{"asset_id":"86520121088881862182423437128238697252500151785248183602134095101149900014256","price":"0.14","size":"277.2","side":"SELL","hash":"653b2ea961315c1424262230537081bc04d3813c","best_bid":"0.13","best_ask":"0.14"}],"timestamp":"1776808415338","event_type":"price_change"}}
{"capturedAt":1776808415,"payload":{"market":"0x125149c5918fc5f8c6d34682f700a898a1a19ea4f4e2ae68ff4c5794ba657074","price_changes":[{"asset_id":"45936375922793925919605092352922707796689801895417366600539442410775071099958","price":"0.86","size":"259.2","side":"BUY","hash":"53c38bb899b0d0aae64f7493ea1b593c611affd8","best_bid":"0.86","best_ask":"0.87"},{"asset_id":"86520121088881862182423437128238697252500151785248183602134095101149900014256","price":"0.14","size":"259.2","side":"SELL","hash":"38f74a23a6df72c6f74b706e9aa85fb054686eae","best_bid":"0.13","best_ask":"0.14"}],"timestamp":"1776808415340","event_type":"price_change"}}
{"capturedAt":1776808415,"payload":{"market":"0x125149c5918fc5f8c6d34682f700a898a1a19ea4f4e2ae68ff4c5794ba657074","price_changes":[{"asset_id":"45936375922793925919605092352922707796689801895417366600539442410775071099958","price":"0.86","size":"241.2","side":"BUY","hash":"1104f98421e5d7b1b7d2f510f64d7a724986df0b","best_bid":"0.86","best_ask":"0.87"},{"asset_id":"86520121088881862182423437128238697252500151785248183602134095101149900014256","price":"0.14","size":"241.2","side":"SELL","hash":"8af81983e922629b899ec88451aeeed67618df8d","best_bid":"0.13","best_ask":"0.14"}],"timestamp":"1776808415341","event_type":"price_change"}}
{"capturedAt":1776808415,"payload":{"market":"0x125149c5918fc5f8c6d34682f700a898a1a19ea4f4e2ae68ff4c5794ba657074","price_changes":[{"asset_id":"86520121088881862182423437128238697252500151785248183602134095101149900014256","price":"0.04","size":"938.3","side":"BUY","hash":"9c7d8fad9e14b36ad5e30998a3d2ee32bf522b0e","best_bid":"0.13","best_ask":"0.14"},{"asset_id":"45936375922793925919605092352922707796689801895417366600539442410775071099958","price":"0.96","size":"938.3","side":"SELL","hash":"604fdd87176936d9f0181a4bf13bcae74b8b5dca","best_bid":"0.86","best_ask":"0.87"}],"timestamp":"1776808415346","event_type":"price_change"}}
{"capturedAt":1776808415,"payload":{"market":"0x125149c5918fc5f8c6d34682f700a898a1a19ea4f4e2ae68ff4c5794ba657074","price_changes":[{"asset_id":"86520121088881862182423437128238697252500151785248183602134095101149900014256","price":"0.13","size":"223.2","side":"BUY","hash":"66cbb94664fca3d8fcc3319efc18bad350bd1400","best_bid":"0.13","best_ask":"0.14"},{"asset_id":"45936375922793925919605092352922707796689801895417366600539442410775071099958","price":"0.87","size":"223.2","side":"SELL","hash":"17d6d2c6f99a51ac4ef66b9ded8f7d6708ec59e8","best_bid":"0.86","best_ask":"0.87"}],"timestamp":"1776808415346","event_type":"price_change"}}
{"capturedAt":1776808415,"payload":{"market":"0x125149c5918fc5f8c6d34682f700a898a1a19ea4f4e2ae68ff4c5794ba657074","price_changes":[{"asset_id":"45936375922793925919605092352922707796689801895417366600539442410775071099958","price":"0.56","size":"196.6","side":"BUY","hash":"82648c1b26ba341d1f6bcde01cde1a120892f377","best_bid":"0.86","best_ask":"0.87"},{"asset_id":"86520121088881862182423437128238697252500151785248183602134095101149900014256","price":"0.44","size":"196.6","side":"SELL","hash":"754d4eff9a760e6c3252a96bbecad3c48429cb25","best_bid":"0.13","best_ask":"0.14"}],"timestamp":"1776808415347","event_type":"price_change"}}
{"capturedAt":1776808415,"payload":{"market":"0x125149c5918fc5f8c6d34682f700a898a1a19ea4f4e2ae68ff4c5794ba657074","price_changes":[{"asset_id":"45936375922793925919605092352922707796689801895417366600539442410775071099958","price":"0.85","size":"452.28","side":"BUY","hash":"e103d6d3cfe5367fce53e79664b6b2bba9883b17","best_bid":"0.86","best_ask":"0.87"},{"asset_id":"86520121088881862182423437128238697252500151785248183602134095101149900014256","price":"0.15","size":"452.28","side":"SELL","hash":"093d6cb6beb1f45c328ebbb210ba81a5c3a101b0","best_bid":"0.13","best_ask":"0.14"}],"timestamp":"1776808415347","event_type":"price_change"}}
{"capturedAt":1776808415,"payload":{"market":"0x125149c5918fc5f8c6d34682f700a898a1a19ea4f4e2ae68ff4c5794ba657074","asset_id":"86520121088881862182423437128238697252500151785248183602134095101149900014256","best_bid":"0.13","best_ask":"0.14","spread":"0.01","timestamp":"1776808415353","event_type":"best_bid_ask"}}
{"capturedAt":1776808415,"payload":{"market":"0x125149c5918fc5f8c6d34682f700a898a1a19ea4f4e2ae68ff4c5794ba657074","price_changes":[{"asset_id":"45936375922793925919605092352922707796689801895417366600539442410775071099958","price":"0.86","size":"221.91","side":"BUY","hash":"db7301c5fd981d57387707f67f1bc7f58877089e","best_bid":"0.86","best_ask":"0.87"},{"asset_id":"86520121088881862182423437128238697252500151785248183602134095101149900014256","price":"0.14","size":"221.91","side":"SELL","hash":"aae92c8df918ca7d9f396ff28d66303ef9023815","best_bid":"0.13","best_ask":"0.14"}],"timestamp":"1776808415352","event_type":"price_change"}}
{"capturedAt":1776808415,"payload":{"market":"0x125149c5918fc5f8c6d34682f700a898a1a19ea4f4e2ae68ff4c5794ba657074","asset_id":"45936375922793925919605092352922707796689801895417366600539442410775071099958","best_bid":"0.86","best_ask":"0.87","spread":"0.01","timestamp":"1776808415353","event_type":"best_bid_ask"}}
{"capturedAt":1776808415,"payload":{"market":"0x125149c5918fc5f8c6d34682f700a898a1a19ea4f4e2ae68ff4c5794ba657074","asset_id":"86520121088881862182423437128238697252500151785248183602134095101149900014256","bids":[{"price":"0.01","size":"12907.69"},{"price":"0.02","size":"1746.16"},{"price":"0.03","size":"1413.83"},{"price":"0.04","size":"938.3"},{"price":"0.05","size":"790.63"},{"price":"0.06","size":"395.8"},{"price":"0.07","size":"685.3"},{"price":"0.08","size":"656.9"},{"price":"0.09","size":"267.44"},{"price":"0.1","size":"793.5"},{"price":"0.11","size":"386.5"},{"price":"0.12","size":"308.5"},{"price":"0.13","size":"223.2"}],"asks":[{"price":"0.99","size":"12324.83"},{"price":"0.98","size":"1715.28"},{"price":"0.97","size":"1338.69"},{"price":"0.96","size":"583.84"},{"price":"0.95","size":"1006.34"},{"price":"0.94","size":"392.8"},{"price":"0.93","size":"304.69"},{"price":"0.92","size":"278.9"},{"price":"0.91","size":"225"},{"price":"0.9","size":"282"},{"price":"0.89","size":"217.79"},{"price":"0.88","size":"215.1"},{"price":"0.87","size":"202.8"},{"price":"0.86","size":"200.9"},{"price":"0.85","size":"209.2"},{"price":"0.84","size":"197.8"},{"price":"0.83","size":"202.39"},{"price":"0.82","size":"200.4"},{"price":"0.81","size":"194.4"},{"price":"0.8","size":"193.5"},{"price":"0.79","size":"215.31"},{"price":"0.78","size":"197"},{"price":"0.77","size":"229.34"},{"price":"0.76","size":"195.7"},{"price":"0.75","size":"190.2"},{"price":"0.74","size":"189.7"},{"price":"0.73","size":"194.3"},{"price":"0.72","size":"188.89"},{"price":"0.71","size":"188.5"},{"price":"0.7","size":"206.48"},{"price":"0.69","size":"394.45"},{"price":"0.68","size":"187.5"},{"price":"0.67","size":"193.55"},{"price":"0.66","size":"187"},{"price":"0.65","size":"602.68"},{"price":"0.64","size":"186.6"},{"price":"0.63","size":"191.96"},{"price":"0.62","size":"186.3"},{"price":"0.61","size":"491.36"},{"price":"0.6","size":"226"},{"price":"0.59","size":"203.32"},{"price":"0.58","size":"185.8"},{"price":"0.57","size":"190.8"},{"price":"0.56","size":"190.6"},{"price":"0.55","size":"230.58"},{"price":"0.54","size":"185.5"},{"price":"0.53","size":"245.86"},{"price":"0.52","size":"242.56"},{"price":"0.51","size":"222.4"},{"price":"0.5","size":"378.64"},{"price":"0.49","size":"205.25"},{"price":"0.48","size":"226.77"},{"price":"0.47","size":"136.71"},{"price":"0.46","size":"185.5"},{"price":"0.45","size":"207.66"},{"price":"0.44","size":"196.6"},{"price":"0.43","size":"180.7"},{"price":"0.42","size":"180.8"},{"price":"0.41","size":"180.9"},{"price":"0.4","size":"139"},{"price":"0.39","size":"185.46"},{"price":"0.38","size":"141.3"},{"price":"0.37","size":"131.4"},{"price":"0.36","size":"131.6"},{"price":"0.35","size":"136.8"},{"price":"0.34","size":"342"},{"price":"0.33","size":"232.3"},{"price":"0.32","size":"382.5"},{"price":"0.31","size":"182.8"},{"price":"0.3","size":"244.95"},{"price":"0.29","size":"405.5"},{"price":"0.28","size":"530.89"},{"price":"0.27","size":"217.3"},{"price":"0.26","size":"287.7"},{"price":"0.25","size":"382.29"},{"price":"0.24","size":"148.49"},{"price":"0.23","size":"221.3"},{"price":"0.22","size":"328.98"},{"price":"0.21","size":"219.7"},{"price":"0.2","size":"245.25"},{"price":"0.19","size":"304.9"},{"price":"0.18","size":"325.78"},{"price":"0.17","size":"353.3"},{"price":"0.16","size":"384.37"},{"price":"0.15","size":"452.28"},{"price":"0.14","size":"221.91"}],"hash":"aae92c8df918ca7d9f396ff28d66303ef9023815","timestamp":"1776808415352","event_type":"book"}}
{"capturedAt":1776808415,"payload":{"market":"0x125149c5918fc5f8c6d34682f700a898a1a19ea4f4e2ae68ff4c5794ba657074","price_changes":[{"asset_id":"45936375922793925919605092352922707796689801895417366600539442410775071099958","price":"0.86","size":"216.21","side":"BUY","hash":"1d1f6fc32818aea4fe3fe36506ad02f9c3eb7569","best_bid":"0.86","best_ask":"0.87"},{"asset_id":"86520121088881862182423437128238697252500151785248183602134095101149900014256","price":"0.14","size":"216.21","side":"SELL","hash":"eb1715e5f772d74ddb059f478b2af8fa245594f9","best_bid":"0.13","best_ask":"0.14"}],"timestamp":"1776808415353","event_type":"price_change"}}
{"capturedAt":1776808415,"payload":{"market":"0x125149c5918fc5f8c6d34682f700a898a1a19ea4f4e2ae68ff4c5794ba657074","asset_id":"45936375922793925919605092352922707796689801895417366600539442410775071099958","bids":[{"price":"0.01","size":"12324.83"},{"price":"0.02","size":"1715.28"},{"price":"0.03","size":"1338.69"},{"price":"0.04","size":"583.84"},{"price":"0.05","size":"1006.34"},{"price":"0.06","size":"392.8"},{"price":"0.07","size":"304.69"},{"price":"0.08","size":"278.9"},{"price":"0.09","size":"225"},{"price":"0.1","size":"282"},{"price":"0.11","size":"217.79"},{"price":"0.12","size":"215.1"},{"price":"0.13","size":"202.8"},{"price":"0.14","size":"200.9"},{"price":"0.15","size":"209.2"},{"price":"0.16","size":"197.8"},{"price":"0.17","size":"202.39"},{"price":"0.18","size":"200.4"},{"price":"0.19","size":"194.4"},{"price":"0.2","size":"193.5"},{"price":"0.21","size":"215.31"},{"price":"0.22","size":"197"},{"price":"0.23","size":"229.34"},{"price":"0.24","size":"195.7"},{"price":"0.25","size":"190.2"},{"price":"0.26","size":"189.7"},{"price":"0.27","size":"194.3"},{"price":"0.28","size":"188.89"},{"price":"0.29","size":"188.5"},{"price":"0.3","size":"206.48"},{"price":"0.31","size":"394.45"},{"price":"0.32","size":"187.5"},{"price":"0.33","size":"193.55"},{"price":"0.34","size":"187"},{"price":"0.35","size":"602.68"},{"price":"0.36","size":"186.6"},{"price":"0.37","size":"191.96"},{"price":"0.38","size":"186.3"},{"price":"0.39","size":"491.36"},{"price":"0.4","size":"226"},{"price":"0.41","size":"203.32"},{"price":"0.42","size":"185.8"},{"price":"0.43","size":"190.8"},{"price":"0.44","size":"190.6"},{"price":"0.45","size":"230.58"},{"price":"0.46","size":"185.5"},{"price":"0.47","size":"245.86"},{"price":"0.48","size":"242.56"},{"price":"0.49","size":"222.4"},{"price":"0.5","size":"378.64"},{"price":"0.51","size":"205.25"},{"price":"0.52","size":"226.77"},{"price":"0.53","size":"136.71"},{"price":"0.54","size":"185.5"},{"price":"0.55","size":"207.66"},{"price":"0.56","size":"196.6"},{"price":"0.57","size":"180.7"},{"price":"0.58","size":"180.8"},{"price":"0.59","size":"180.9"},{"price":"0.6","size":"139"},{"price":"0.61","size":"185.46"},{"price":"0.62","size":"141.3"},{"price":"0.63","size":"131.4"},{"price":"0.64","size":"131.6"},{"price":"0.65","size":"136.8"},{"price":"0.66","size":"342"},{"price":"0.67","size":"232.3"},{"price":"0.68","size":"382.5"},{"price":"0.69","size":"182.8"},{"price":"0.7","size":"244.95"},{"price":"0.71","size":"405.5"},{"price":"0.72","size":"530.89"},{"price":"0.73","size":"217.3"},{"price":"0.74","size":"287.7"},{"price":"0.75","size":"382.29"},{"price":"0.76","size":"148.49"},{"price":"0.77","size":"221.3"},{"price":"0.78","size":"328.98"},{"price":"0.79","size":"219.7"},{"price":"0.8","size":"245.25"},{"price":"0.81","size":"304.9"},{"price":"0.82","size":"325.78"},{"price":"0.83","size":"353.3"},{"price":"0.84","size":"384.37"},{"price":"0.85","size":"452.28"},{"price":"0.86","size":"221.91"}],"asks":[{"price":"0.99","size":"12907.69"},{"price":"0.98","size":"1746.16"},{"price":"0.97","size":"1413.83"},{"price":"0.96","size":"938.3"},{"price":"0.95","size":"790.63"},{"price":"0.94","size":"395.8"},{"price":"0.93","size":"685.3"},{"price":"0.92","size":"656.9"},{"price":"0.91","size":"267.44"},{"price":"0.9","size":"793.5"},{"price":"0.89","size":"386.5"},{"price":"0.88","size":"308.5"},{"price":"0.87","size":"223.2"}],"hash":"db7301c5fd981d57387707f67f1bc7f58877089e","timestamp":"1776808415352","event_type":"book"}}
{"capturedAt":1776808415,"payload":{"market":"0x125149c5918fc5f8c6d34682f700a898a1a19ea4f4e2ae68ff4c5794ba657074","price_changes":[{"asset_id":"45936375922793925919605092352922707796689801895417366600539442410775071099958","price":"0.86","size":"235.21","side":"BUY","hash":"ae7669a0338b95604dee07729ab19aed9b120222","best_bid":"0.86","best_ask":"0.87"},{"asset_id":"86520121088881862182423437128238697252500151785248183602134095101149900014256","price":"0.14","size":"235.21","side":"SELL","hash":"abfe958063080498094444dcf294bfcf1c57258d","best_bid":"0.13","best_ask":"0.14"}],"timestamp":"1776808415357","event_type":"price_change"}}
{"capturedAt":1776808415,"payload":{"market":"0x125149c5918fc5f8c6d34682f700a898a1a19ea4f4e2ae68ff4c5794ba657074","price_changes":[{"asset_id":"45936375922793925919605092352922707796689801895417366600539442410775071099958","price":"0.86","size":"245.21","side":"BUY","hash":"82e121314e368e3d5231883c16df39cfbcc7bde6","best_bid":"0.86","best_ask":"0.87"},{"asset_id":"86520121088881862182423437128238697252500151785248183602134095101149900014256","price":"0.14","size":"245.21","side":"SELL","hash":"052ad406ef865316b11da98f9e6d8a8eb9b7a48d","best_bid":"0.13","best_ask":"0.14"}],"timestamp":"1776808415358","event_type":"price_change"}}
{"capturedAt":1776808415,"payload":{"market":"0x125149c5918fc5f8c6d34682f700a898a1a19ea4f4e2ae68ff4c5794ba657074","price_changes":[{"asset_id":"45936375922793925919605092352922707796689801895417366600539442410775071099958","price":"0.01","size":"12329.83","side":"BUY","hash":"9705ca637158be2c2f76ec06286cc0a10871f086","best_bid":"0.86","best_ask":"0.87"},{"asset_id":"86520121088881862182423437128238697252500151785248183602134095101149900014256","price":"0.99","size":"12329.83","side":"SELL","hash":"af1a477bed57b70c5df67f151bc704db04dd9010","best_bid":"0.13","best_ask":"0.14"}],"timestamp":"1776808415362","event_type":"price_change"}}
{"capturedAt":1776808415,"payload":{"market":"0x125149c5918fc5f8c6d34682f700a898a1a19ea4f4e2ae68ff4c5794ba657074","price_changes":[{"asset_id":"45936375922793925919605092352922707796689801895417366600539442410775071099958","price":"0.86","size":"264.21","side":"BUY","hash":"9e2d1a03533eb9a82a34428f71769a159fb31423","best_bid":"0.86","best_ask":"0.87"},{"asset_id":"86520121088881862182423437128238697252500151785248183602134095101149900014256","price":"0.14","size":"264.21","side":"SELL","hash":"3c11baf8a4f106d8cb1302dec5aab2790bd237ea","best_bid":"0.13","best_ask":"0.14"}],"timestamp":"1776808415361","event_type":"price_change"}}
{"capturedAt":1776808415,"payload":{"market":"0x125149c5918fc5f8c6d34682f700a898a1a19ea4f4e2ae68ff4c5794ba657074","price_changes":[{"asset_id":"45936375922793925919605092352922707796689801895417366600539442410775071099958","price":"0.01","size":"12334.83","side":"BUY","hash":"f174c5ff3c3c1382bf827703c499217f4d1ac173","best_bid":"0.86","best_ask":"0.87"},{"asset_id":"86520121088881862182423437128238697252500151785248183602134095101149900014256","price":"0.99","size":"12334.83","side":"SELL","hash":"a8606d28e31bc7eed0beb7e8ed7bd9636aedd36f","best_bid":"0.13","best_ask":"0.14"}],"timestamp":"1776808415365","event_type":"price_change"}}
{"capturedAt":1776808415,"payload":{"market":"0x125149c5918fc5f8c6d34682f700a898a1a19ea4f4e2ae68ff4c5794ba657074","price_changes":[{"asset_id":"45936375922793925919605092352922707796689801895417366600539442410775071099958","price":"0.86","size":"254.21","side":"BUY","hash":"0ad9d4a3c25756b4ff72a3c2f1c61a5051574ff0","best_bid":"0.86","best_ask":"0.87"},{"asset_id":"86520121088881862182423437128238697252500151785248183602134095101149900014256","price":"0.14","size":"254.21","side":"SELL","hash":"c173e0294bfc6ba73a86f29978472f5110fbc7b7","best_bid":"0.13","best_ask":"0.14"}],"timestamp":"1776808415365","event_type":"price_change"}}
{"capturedAt":1776808415,"payload":{"market":"0x125149c5918fc5f8c6d34682f700a898a1a19ea4f4e2ae68ff4c5794ba657074","price_changes":[{"asset_id":"45936375922793925919605092352922707796689801895417366600539442410775071099958","price":"0.86","size":"259.46","side":"BUY","hash":"330bd71280c223ed963283c094bc254893fb2e13","best_bid":"0.86","best_ask":"0.87"},{"asset_id":"86520121088881862182423437128238697252500151785248183602134095101149900014256","price":"0.14","size":"259.46","side":"SELL","hash":"79b52612a060fda3c3a8eded3a50ad168816496f","best_bid":"0.13","best_ask":"0.14"}],"timestamp":"1776808415369","event_type":"price_change"}}
{"capturedAt":1776808415,"payload":{"market":"0x125149c5918fc5f8c6d34682f700a898a1a19ea4f4e2ae68ff4c5794ba657074","price_changes":[{"asset_id":"45936375922793925919605092352922707796689801895417366600539442410775071099958","price":"0.86","size":"277.46","side":"BUY","hash":"e01f3fe2fe39d0fc48e289e877e7fafe1a087bf0","best_bid":"0.86","best_ask":"0.87"},{"asset_id":"86520121088881862182423437128238697252500151785248183602134095101149900014256","price":"0.14","size":"277.46","side":"SELL","hash":"cc9e039efc8c4fc48febd6778200112a98da2ce9","best_bid":"0.13","best_ask":"0.14"}],"timestamp":"1776808415373","event_type":"price_change"}}
{"capturedAt":1776808415,"payload":{"market":"0x125149c5918fc5f8c6d34682f700a898a1a19ea4f4e2ae68ff4c5794ba657074","price_changes":[{"asset_id":"45936375922793925919605092352922707796689801895417366600539442410775071099958","price":"0.86","size":"257.46","side":"BUY","hash":"95b4001a77b6d625e18c151e8c4de774503bc81e","best_bid":"0.86","best_ask":"0.87"},{"asset_id":"86520121088881862182423437128238697252500151785248183602134095101149900014256","price":"0.14","size":"257.46","side":"SELL","hash":"d03b13a691fdbdf26fc0621fe4c9199fdd15b408","best_bid":"0.13","best_ask":"0.14"}],"timestamp":"1776808415374","event_type":"price_change"}}
{"capturedAt":1776808415,"payload":{"market":"0x125149c5918fc5f8c6d34682f700a898a1a19ea4f4e2ae68ff4c5794ba657074","price_changes":[{"asset_id":"45936375922793925919605092352922707796689801895417366600539442410775071099958","price":"0.84","size":"389.37","side":"BUY","hash":"f624a0ed3960749820cb6f1a3cd058df301c90aa","best_bid":"0.86","best_ask":"0.87"},{"asset_id":"86520121088881862182423437128238697252500151785248183602134095101149900014256","price":"0.16","size":"389.37","side":"SELL","hash":"f9a78f020a60d9dbd18ee652037c15871f2f4e95","best_bid":"0.13","best_ask":"0.14"}],"timestamp":"1776808415372","event_type":"price_change"}}
{"capturedAt":1776808415,"payload":{"market":"0x125149c5918fc5f8c6d34682f700a898a1a19ea4f4e2ae68ff4c5794ba657074","asset_id":"86520121088881862182423437128238697252500151785248183602134095101149900014256","price":"0.14","size":"19.285713","fee_rate_bps":"1000","side":"BUY","timestamp":"1776808415373","event_type":"last_trade_price","transaction_hash":"0x5afa74f0ad2a6dbc51507a7d27f1a5c35b6788c668e5731317fd3827ea0fdff2"}}
{"capturedAt":1776808415,"payload":{"market":"0x125149c5918fc5f8c6d34682f700a898a1a19ea4f4e2ae68ff4c5794ba657074","price_changes":[{"asset_id":"45936375922793925919605092352922707796689801895417366600539442410775071099958","price":"0.86","size":"275.46","side":"BUY","hash":"3c950ad35ea502145e812a8fa6edf50cde235d48","best_bid":"0.86","best_ask":"0.87"},{"asset_id":"86520121088881862182423437128238697252500151785248183602134095101149900014256","price":"0.14","size":"275.46","side":"SELL","hash":"d5bf861e50ce8eb03bf1221e87a71e8771b9ce93","best_bid":"0.13","best_ask":"0.14"}],"timestamp":"1776808415375","event_type":"price_change"}}
{"capturedAt":1776808415,"payload":{"market":"0x125149c5918fc5f8c6d34682f700a898a1a19ea4f4e2ae68ff4c5794ba657074","price_changes":[{"asset_id":"45936375922793925919605092352922707796689801895417366600539442410775071099958","price":"0.86","size":"292.46","side":"BUY","hash":"0923bf1107ee1145b654891284f5a9b95364ace4","best_bid":"0.86","best_ask":"0.87"},{"asset_id":"86520121088881862182423437128238697252500151785248183602134095101149900014256","price":"0.14","size":"292.46","side":"SELL","hash":"52b5a20d09c0f9dc13039ee85b19801d5d9d0f9c","best_bid":"0.13","best_ask":"0.14"}],"timestamp":"1776808415377","event_type":"price_change"}}
{"capturedAt":1776808415,"payload":{"market":"0x125149c5918fc5f8c6d34682f700a898a1a19ea4f4e2ae68ff4c5794ba657074","price_changes":[{"asset_id":"45936375922793925919605092352922707796689801895417366600539442410775071099958","price":"0.01","size":"12339.83","side":"BUY","hash":"0b9fce7ae4e562e5003ee2fc5ea6035b46c140ec","best_bid":"0.86","best_ask":"0.87"},{"asset_id":"86520121088881862182423437128238697252500151785248183602134095101149900014256","price":"0.99","size":"12339.83","side":"SELL","hash":"fd4061002e8190f9c64ba1e7e40be096c73414a1","best_bid":"0.13","best_ask":"0.14"}],"timestamp":"1776808415378","event_type":"price_change"}}
{"capturedAt":1776808415,"payload":{"market":"0x125149c5918fc5f8c6d34682f700a898a1a19ea4f4e2ae68ff4c5794ba657074","price_changes":[{"asset_id":"45936375922793925919605092352922707796689801895417366600539442410775071099958","price":"0.86","size":"272.46","side":"BUY","hash":"3fbf0c9ad3243db6e54abc3c2f6805e876c9a426","best_bid":"0.86","best_ask":"0.87"},{"asset_id":"86520121088881862182423437128238697252500151785248183602134095101149900014256","price":"0.14","size":"272.46","side":"SELL","hash":"94d053a7f260bd1840e4579bedf1e335f5105098","best_bid":"0.13","best_ask":"0.14"}],"timestamp":"1776808415378","event_type":"price_change"}}
{"capturedAt":1776808415,"payload":{"market":"0x125149c5918fc5f8c6d34682f700a898a1a19ea4f4e2ae68ff4c5794ba657074","price_changes":[{"asset_id":"45936375922793925919605092352922707796689801895417366600539442410775071099958","price":"0.86","size":"290.46","side":"BUY","hash":"c5ba79595d950f6237ea1804894d54328734b48a","best_bid":"0.86","best_ask":"0.87"},{"asset_id":"86520121088881862182423437128238697252500151785248183602134095101149900014256","price":"0.14","size":"290.46","side":"SELL","hash":"3d9e4ad4a8225f1f17881c36e19907323900f6c9","best_bid":"0.13","best_ask":"0.14"}],"timestamp":"1776808415379","event_type":"price_change"}}
{"capturedAt":1776808415,"payload":{"market":"0x125149c5918fc5f8c6d34682f700a898a1a19ea4f4e2ae68ff4c5794ba657074","price_changes":[{"asset_id":"45936375922793925919605092352922707796689801895417366600539442410775071099958","price":"0.86","size":"310.46","side":"BUY","hash":"2b5cceded4649e54fddffcf4a0ae71a982a43afb","best_bid":"0.86","best_ask":"0.87"},{"asset_id":"86520121088881862182423437128238697252500151785248183602134095101149900014256","price":"0.14","size":"310.46","side":"SELL","hash":"b3570dbc46d2ccffb3c5d2d7b1ad81f0fa5746b3","best_bid":"0.13","best_ask":"0.14"}],"timestamp":"1776808415380","event_type":"price_change"}}
{"capturedAt":1776808415,"payload":{"market":"0x125149c5918fc5f8c6d34682f700a898a1a19ea4f4e2ae68ff4c5794ba657074","price_changes":[{"asset_id":"45936375922793925919605092352922707796689801895417366600539442410775071099958","price":"0.01","size":"12334.83","side":"BUY","hash":"80863b5a711136fb14d1f2f5dce0001de4a7463b","best_bid":"0.86","best_ask":"0.87"},{"asset_id":"86520121088881862182423437128238697252500151785248183602134095101149900014256","price":"0.99","size":"12334.83","side":"SELL","hash":"793dfc5fec5bdb7ec011fe18e2ceedafa907492a","best_bid":"0.13","best_ask":"0.14"}],"timestamp":"1776808415381","event_type":"price_change"}}
{"capturedAt":1776808415,"payload":{"market":"0x125149c5918fc5f8c6d34682f700a898a1a19ea4f4e2ae68ff4c5794ba657074","price_changes":[{"asset_id":"45936375922793925919605092352922707796689801895417366600539442410775071099958","price":"0.01","size":"12329.83","side":"BUY","hash":"b82d3f582e75f5cdf11cf34ae239598e20d8c996","best_bid":"0.86","best_ask":"0.87"},{"asset_id":"86520121088881862182423437128238697252500151785248183602134095101149900014256","price":"0.99","size":"12329.83","side":"SELL","hash":"dfc5af1e9cacd67566bc4797d006f60ebf28ee23","best_bid":"0.13","best_ask":"0.14"}],"timestamp":"1776808415383","event_type":"price_change"}}
{"capturedAt":1776808415,"payload":{"market":"0x125149c5918fc5f8c6d34682f700a898a1a19ea4f4e2ae68ff4c5794ba657074","price_changes":[{"asset_id":"45936375922793925919605092352922707796689801895417366600539442410775071099958","price":"0.86","size":"300.46","side":"BUY","hash":"0689729637fa9a90bbecc02c7c2fe17847a29d0a","best_bid":"0.86","best_ask":"0.87"},{"asset_id":"86520121088881862182423437128238697252500151785248183602134095101149900014256","price":"0.14","size":"300.46","side":"SELL","hash":"58c3a461fa4d259f4631c7a2b8cefc4fb87a919d","best_bid":"0.13","best_ask":"0.14"}],"timestamp":"1776808415390","event_type":"price_change"}}
{"capturedAt":1776808415,"payload":{"market":"0x125149c5918fc5f8c6d34682f700a898a1a19ea4f4e2ae68ff4c5794ba657074","price_changes":[{"asset_id":"45936375922793925919605092352922707796689801895417366600539442410775071099958","price":"0.86","size":"310.46","side":"BUY","hash":"adeef4ad61ca317d061ce0bb0167169525624cc8","best_bid":"0.86","best_ask":"0.87"},{"asset_id":"86520121088881862182423437128238697252500151785248183602134095101149900014256","price":"0.14","size":"310.46","side":"SELL","hash":"8f44bea1f5bc24954ae73c108a5c0db9daf5eec9","best_bid":"0.13","best_ask":"0.14"}],"timestamp":"1776808415393","event_type":"price_change"}}
{"capturedAt":1776808415,"payload":{"market":"0x125149c5918fc5f8c6d34682f700a898a1a19ea4f4e2ae68ff4c5794ba657074","price_changes":[{"asset_id":"45936375922793925919605092352922707796689801895417366600539442410775071099958","price":"0.01","size":"12324.83","side":"BUY","hash":"7d673423f408447bae7fe9c261dc16b4b3b7c5e3","best_bid":"0.86","best_ask":"0.87"},{"asset_id":"86520121088881862182423437128238697252500151785248183602134095101149900014256","price":"0.99","size":"12324.83","side":"SELL","hash":"f7ef7895b24bb0d8eda29b3c82e3b30c53049a01","best_bid":"0.13","best_ask":"0.14"}],"timestamp":"1776808415398","event_type":"price_change"}}
{"capturedAt":1776808415,"payload":{"market":"0x125149c5918fc5f8c6d34682f700a898a1a19ea4f4e2ae68ff4c5794ba657074","asset_id":"86520121088881862182423437128238697252500151785248183602134095101149900014256","best_bid":"0.13","best_ask":"0.14","spread":"0.01","timestamp":"1776808415409","event_type":"best_bid_ask"}}
{"capturedAt":1776808415,"payload":{"market":"0x125149c5918fc5f8c6d34682f700a898a1a19ea4f4e2ae68ff4c5794ba657074","price_changes":[{"asset_id":"45936375922793925919605092352922707796689801895417366600539442410775071099958","price":"0.86","size":"335.46","side":"BUY","hash":"8a0b9f9c8a34a946e709a11c52a177600c3aab98","best_bid":"0.86","best_ask":"0.87"},{"asset_id":"86520121088881862182423437128238697252500151785248183602134095101149900014256","price":"0.14","size":"335.46","side":"SELL","hash":"0ff54bd53f89a03e51e4c88c77d4fef1237fdac5","best_bid":"0.13","best_ask":"0.14"}],"timestamp":"1776808415404","event_type":"price_change"}}
{"capturedAt":1776808415,"payload":{"market":"0x125149c5918fc5f8c6d34682f700a898a1a19ea4f4e2ae68ff4c5794ba657074","asset_id":"45936375922793925919605092352922707796689801895417366600539442410775071099958","best_bid":"0.86","best_ask":"0.87","spread":"0.01","timestamp":"1776808415409","event_type":"best_bid_ask"}}
{"capturedAt":1776808415,"payload":{"market":"0x125149c5918fc5f8c6d34682f700a898a1a19ea4f4e2ae68ff4c5794ba657074","price_changes":[{"asset_id":"45936375922793925919605092352922707796689801895417366600539442410775071099958","price":"0.86","size":"328.46","side":"BUY","hash":"a04fa2e6ab3b73c8c17e29b2193bc292619877ba","best_bid":"0.86","best_ask":"0.87"},{"asset_id":"86520121088881862182423437128238697252500151785248183602134095101149900014256","price":"0.14","size":"328.46","side":"SELL","hash":"c8f905e06b04bb1512158771587e599bc4ccb355","best_bid":"0.13","best_ask":"0.14"}],"timestamp":"1776808415402","event_type":"price_change"}}
{"capturedAt":1776808415,"payload":{"market":"0x125149c5918fc5f8c6d34682f700a898a1a19ea4f4e2ae68ff4c5794ba657074","price_changes":[{"asset_id":"45936375922793925919605092352922707796689801895417366600539442410775071099958","price":"0.86","size":"347.46","side":"BUY","hash":"4404727f7a91578ece9d6560c69fb75c9a586c46","best_bid":"0.86","best_ask":"0.87"},{"asset_id":"86520121088881862182423437128238697252500151785248183602134095101149900014256","price":"0.14","size":"347.46","side":"SELL","hash":"54482c4873d7e34510cd74c049fd80a6d8d720b3","best_bid":"0.13","best_ask":"0.14"}],"timestamp":"1776808415403","event_type":"price_change"}}
{"capturedAt":1776808415,"payload":{"market":"0x125149c5918fc5f8c6d34682f700a898a1a19ea4f4e2ae68ff4c5794ba657074","price_changes":[{"asset_id":"86520121088881862182423437128238697252500151785248183602134095101149900014256","price":"0.13","size":"210.55","side":"BUY","hash":"73716d8ab71dad5bb09cc8a01f7e15c7252a7a85","best_bid":"0.13","best_ask":"0.14"},{"asset_id":"45936375922793925919605092352922707796689801895417366600539442410775071099958","price":"0.87","size":"210.55","side":"SELL","hash":"c683760af5d0911868ba5321a02e21ebe6503a1b","best_bid":"0.86","best_ask":"0.87"}],"timestamp":"1776808415408","event_type":"price_change"}}
{"capturedAt":1776808415,"payload":{"market":"0x125149c5918fc5f8c6d34682f700a898a1a19ea4f4e2ae68ff4c5794ba657074","price_changes":[{"asset_id":"86520121088881862182423437128238697252500151785248183602134095101149900014256","price":"0.03","size":"1613.83","side":"BUY","hash":"eb7e3790dee88e4d0c1cda74a024a27ad34b3086","best_bid":"0.13","best_ask":"0.14"},{"asset_id":"45936375922793925919605092352922707796689801895417366600539442410775071099958","price":"0.97","size":"1613.83","side":"SELL","hash":"bf3e84347099929d4a2d8ad02b2297e45f90327b","best_bid":"0.86","best_ask":"0.87"}],"timestamp":"1776808415418","event_type":"price_change"}}
{"capturedAt":1776808415,"payload":{"market":"0x125149c5918fc5f8c6d34682f700a898a1a19ea4f4e2ae68ff4c5794ba657074","price_changes":[{"asset_id":"45936375922793925919605092352922707796689801895417366600539442410775071099958","price":"0.01","size":"12329.83","side":"BUY","hash":"353adc6b0b0db8b8d26b7c740640fca6f09a07fe","best_bid":"0.86","best_ask":"0.87"},{"asset_id":"86520121088881862182423437128238697252500151785248183602134095101149900014256","price":"0.99","size":"12329.83","side":"SELL","hash":"413dd330dcf4824877105c45f368fd197141b3dc","best_bid":"0.13","best_ask":"0.14"}],"timestamp":"1776808415413","event_type":"price_change"}}
{"capturedAt":1776808415,"payload":{"market":"0x125149c5918fc5f8c6d34682f700a898a1a19ea4f4e2ae68ff4c5794ba657074","price_changes":[{"asset_id":"45936375922793925919605092352922707796689801895417366600539442410775071099958","price":"0.86","size":"344.46","side":"BUY","hash":"63062649e9a8b5a9bc393fdacac365896d13797b","best_bid":"0.86","best_ask":"0.87"},{"asset_id":"86520121088881862182423437128238697252500151785248183602134095101149900014256","price":"0.14","size":"344.46","side":"SELL","hash":"4d27cdd031f72ad1759f654c71523879a8adf616","best_bid":"0.13","best_ask":"0.14"}],"timestamp":"1776808415423","event_type":"price_change"}}
{"capturedAt":1776808415,"payload":{"market":"0x125149c5918fc5f8c6d34682f700a898a1a19ea4f4e2ae68ff4c5794ba657074","price_changes":[{"asset_id":"45936375922793925919605092352922707796689801895417366600539442410775071099958","price":"0.01","size":"12334.83","side":"BUY","hash":"7a33c329c89ed46e0ff139a20e947f0c756bb00d","best_bid":"0.86","best_ask":"0.87"},{"asset_id":"86520121088881862182423437128238697252500151785248183602134095101149900014256","price":"0.99","size":"12334.83","side":"SELL","hash":"0e2a2164272b4c164c27863d5f941b05b6b11c54","best_bid":"0.13","best_ask":"0.14"}],"timestamp":"1776808415424","event_type":"price_change"}}
{"capturedAt":1776808415,"payload":{"market":"0x125149c5918fc5f8c6d34682f700a898a1a19ea4f4e2ae68ff4c5794ba657074","asset_id":"45936375922793925919605092352922707796689801895417366600539442410775071099958","bids":[{"price":"0.01","size":"12324.83"},{"price":"0.02","size":"1715.28"},{"price":"0.03","size":"1338.69"},{"price":"0.04","size":"583.84"},{"price":"0.05","size":"1006.34"},{"price":"0.06","size":"392.8"},{"price":"0.07","size":"304.69"},{"price":"0.08","size":"278.9"},{"price":"0.09","size":"225"},{"price":"0.1","size":"282"},{"price":"0.11","size":"217.79"},{"price":"0.12","size":"215.1"},{"price":"0.13","size":"202.8"},{"price":"0.14","size":"200.9"},{"price":"0.15","size":"209.2"},{"price":"0.16","size":"197.8"},{"price":"0.17","size":"202.39"},{"price":"0.18","size":"200.4"},{"price":"0.19","size":"194.4"},{"price":"0.2","size":"193.5"},{"price":"0.21","size":"215.31"},{"price":"0.22","size":"197"},{"price":"0.23","size":"229.34"},{"price":"0.24","size":"195.7"},{"price":"0.25","size":"190.2"},{"price":"0.26","size":"189.7"},{"price":"0.27","size":"194.3"},{"price":"0.28","size":"188.89"},{"price":"0.29","size":"188.5"},{"price":"0.3","size":"206.48"},{"price":"0.31","size":"394.45"},{"price":"0.32","size":"187.5"},{"price":"0.33","size":"193.55"},{"price":"0.34","size":"187"},{"price":"0.35","size":"602.68"},{"price":"0.36","size":"186.6"},{"price":"0.37","size":"191.96"},{"price":"0.38","size":"186.3"},{"price":"0.39","size":"491.36"},{"price":"0.4","size":"226"},{"price":"0.41","size":"203.32"},{"price":"0.42","size":"185.8"},{"price":"0.43","size":"190.8"},{"price":"0.44","size":"190.6"},{"price":"0.45","size":"230.58"},{"price":"0.46","size":"185.5"},{"price":"0.47","size":"245.86"},{"price":"0.48","size":"242.56"},{"price":"0.49","size":"222.4"},{"price":"0.5","size":"378.64"},{"price":"0.51","size":"205.25"},{"price":"0.52","size":"226.77"},{"price":"0.53","size":"136.71"},{"price":"0.54","size":"185.5"},{"price":"0.55","size":"207.66"},{"price":"0.56","size":"196.6"},{"price":"0.57","size":"180.7"},{"price":"0.58","size":"180.8"},{"price":"0.59","size":"180.9"},{"price":"0.6","size":"139"},{"price":"0.61","size":"185.46"},{"price":"0.62","size":"141.3"},{"price":"0.63","size":"131.4"},{"price":"0.64","size":"131.6"},{"price":"0.65","size":"136.8"},{"price":"0.66","size":"342"},{"price":"0.67","size":"232.3"},{"price":"0.68","size":"382.5"},{"price":"0.69","size":"182.8"},{"price":"0.7","size":"244.95"},{"price":"0.71","size":"405.5"},{"price":"0.72","size":"530.89"},{"price":"0.73","size":"217.3"},{"price":"0.74","size":"287.7"},{"price":"0.75","size":"382.29"},{"price":"0.76","size":"148.49"},{"price":"0.77","size":"221.3"},{"price":"0.78","size":"328.98"},{"price":"0.79","size":"219.7"},{"price":"0.8","size":"245.25"},{"price":"0.81","size":"304.9"},{"price":"0.82","size":"325.78"},{"price":"0.83","size":"353.3"},{"price":"0.84","size":"389.37"},{"price":"0.85","size":"452.28"},{"price":"0.86","size":"335.46"}],"asks":[{"price":"0.99","size":"12907.69"},{"price":"0.98","size":"1746.16"},{"price":"0.97","size":"1413.83"},{"price":"0.96","size":"938.3"},{"price":"0.95","size":"790.63"},{"price":"0.94","size":"395.8"},{"price":"0.93","size":"685.3"},{"price":"0.92","size":"656.9"},{"price":"0.91","size":"267.44"},{"price":"0.9","size":"793.5"},{"price":"0.89","size":"386.5"},{"price":"0.88","size":"308.5"},{"price":"0.87","size":"210.55"}],"hash":"c683760af5d0911868ba5321a02e21ebe6503a1b","timestamp":"1776808415408","event_type":"book"}}
{"capturedAt":1776808415,"payload":{"market":"0x125149c5918fc5f8c6d34682f700a898a1a19ea4f4e2ae68ff4c5794ba657074","price_changes":[{"asset_id":"45936375922793925919605092352922707796689801895417366600539442410775071099958","price":"0.86","size":"325.46","side":"BUY","hash":"8832d255d72fe071306bc005f7b24a4abdde6e28","best_bid":"0.86","best_ask":"0.87"},{"asset_id":"86520121088881862182423437128238697252500151785248183602134095101149900014256","price":"0.14","size":"325.46","side":"SELL","hash":"7d28691a9d6fc90684f2502da08a4bce58a02944","best_bid":"0.13","best_ask":"0.14"}],"timestamp":"1776808415427","event_type":"price_change"}}
{"capturedAt":1776808415,"payload":{"market":"0x125149c5918fc5f8c6d34682f700a898a1a19ea4f4e2ae68ff4c5794ba657074","asset_id":"45936375922793925919605092352922707796689801895417366600539442410775071099958","price":"0.87","size":"12.643676","fee_rate_bps":"1000","side":"BUY","timestamp":"1776808415427","event_type":"last_trade_price","transaction_hash":"0xc4f34cd0cb4e23c8a2cb8d8e3dfd127a94ccecffb52511529b17fe2ed9b291e4"}}
{"capturedAt":1776808415,"payload":{"market":"0x125149c5918fc5f8c6d34682f700a898a1a19ea4f4e2ae68ff4c5794ba657074","price_changes":[{"asset_id":"45936375922793925919605092352922707796689801895417366600539442410775071099958","price":"0.86","size":"315.46","side":"BUY","hash":"b3b58e021f37ae2d05c224a0a7cd3d7af2ef58ce","best_bid":"0.86","best_ask":"0.87"},{"asset_id":"86520121088881862182423437128238697252500151785248183602134095101149900014256","price":"0.14","size":"315.46","side":"SELL","hash":"7ea51b4ffcb9d5350d0eabbd2a3b4b5b9049d3e6","best_bid":"0.13","best_ask":"0.14"}],"timestamp":"1776808415429","event_type":"price_change"}}
{"capturedAt":1776808415,"payload":{"market":"0x125149c5918fc5f8c6d34682f700a898a1a19ea4f4e2ae68ff4c5794ba657074","price_changes":[{"asset_id":"45936375922793925919605092352922707796689801895417366600539442410775071099958","price":"0.86","size":"323.46","side":"BUY","hash":"a82c4f59fa92bc6de5959670dd332cf75d9ddfd5","best_bid":"0.86","best_ask":"0.87"},{"asset_id":"86520121088881862182423437128238697252500151785248183602134095101149900014256","price":"0.14","size":"323.46","side":"SELL","hash":"9bfac154b342f1075ee6fd682eb2c44bbff7108f","best_bid":"0.13","best_ask":"0.14"}],"timestamp":"1776808415415","event_type":"price_change"}}
{"capturedAt":1776808415,"payload":{"market":"0x125149c5918fc5f8c6d34682f700a898a1a19ea4f4e2ae68ff4c5794ba657074","price_changes":[{"asset_id":"45936375922793925919605092352922707796689801895417366600539442410775071099958","price":"0.86","size":"296.46","side":"BUY","hash":"d8460cc0aecadf77ebba8a3fe9e1d870dfc73706","best_bid":"0.86","best_ask":"0.87"},{"asset_id":"86520121088881862182423437128238697252500151785248183602134095101149900014256","price":"0.14","size":"296.46","side":"SELL","hash":"7ea26faf2d9760329844f1595db52fc15cc9f32b","best_bid":"0.13","best_ask":"0.14"}],"timestamp":"1776808415431","event_type":"price_change"}}
{"capturedAt":1776808415,"payload":{"market":"0x125149c5918fc5f8c6d34682f700a898a1a19ea4f4e2ae68ff4c5794ba657074","price_changes":[{"asset_id":"45936375922793925919605092352922707796689801895417366600539442410775071099958","price":"0.01","size":"12329.83","side":"BUY","hash":"6e1c564d877581d31b85256316d2cfe76539bc5b","best_bid":"0.86","best_ask":"0.87"},{"asset_id":"86520121088881862182423437128238697252500151785248183602134095101149900014256","price":"0.99","size":"12329.83","side":"SELL","hash":"497c5ca586d208055e62540f0bb9ffa7dc8e2ee8","best_bid":"0.13","best_ask":"0.14"}],"timestamp":"1776808415432","event_type":"price_change"}}
{"capturedAt":1776808415,"payload":{"market":"0x125149c5918fc5f8c6d34682f700a898a1a19ea4f4e2ae68ff4c5794ba657074","price_changes":[{"asset_id":"45936375922793925919605092352922707796689801895417366600539442410775071099958","price":"0.86","size":"307.46","side":"BUY","hash":"548caf1795a3e1f539235b2ce9d4cb505a827e73","best_bid":"0.86","best_ask":"0.87"},{"asset_id":"86520121088881862182423437128238697252500151785248183602134095101149900014256","price":"0.14","size":"307.46","side":"SELL","hash":"8daf1dceba4bd6156cfe2fcbe00d60c46922c11e","best_bid":"0.13","best_ask":"0.14"}],"timestamp":"1776808415434","event_type":"price_change"}}
{"capturedAt":1776808415,"payload":{"market":"0x125149c5918fc5f8c6d34682f700a898a1a19ea4f4e2ae68ff4c5794ba657074","price_changes":[{"asset_id":"86520121088881862182423437128238697252500151785248183602134095101149900014256","price":"0.1","size":"812.8","side":"BUY","hash":"5782725e651163fa83540469a68f6f75a211cc67","best_bid":"0.13","best_ask":"0.14"},{"asset_id":"45936375922793925919605092352922707796689801895417366600539442410775071099958","price":"0.9","size":"812.8","side":"SELL","hash":"b265c4f72a1ce5e7a5a9f406f745afdf0f167dfb","best_bid":"0.86","best_ask":"0.87"}],"timestamp":"1776808415422","event_type":"price_change"}}
{"capturedAt":1776808415,"payload":{"market":"0x125149c5918fc5f8c6d34682f700a898a1a19ea4f4e2ae68ff4c5794ba657074","price_changes":[{"asset_id":"45936375922793925919605092352922707796689801895417366600539442410775071099958","price":"0.01","size":"12324.83","side":"BUY","hash":"6d5e05d8880c7ed60523c34581e7aeff758add9c","best_bid":"0.86","best_ask":"0.87"},{"asset_id":"86520121088881862182423437128238697252500151785248183602134095101149900014256","price":"0.99","size":"12324.83","side":"SELL","hash":"273f6a0eacfc01a4ed3164fdf3860604ea617982","best_bid":"0.13","best_ask":"0.14"}],"timestamp":"1776808415443","event_type":"price_change"}}
{"capturedAt":1776808415,"payload":{"market":"0x125149c5918fc5f8c6d34682f700a898a1a19ea4f4e2ae68ff4c5794ba657074","price_changes":[{"asset_id":"45936375922793925919605092352922707796689801895417366600539442410775071099958","price":"0.86","size":"333.46","side":"BUY","hash":"8c649f6e6c8a4a2fb14d4f34c60ddd3f6b98aa62","best_bid":"0.86","best_ask":"0.87"},{"asset_id":"86520121088881862182423437128238697252500151785248183602134095101149900014256","price":"0.14","size":"333.46","side":"SELL","hash":"94c180b2f98f75d8eaf691238a49c397dca0a971","best_bid":"0.13","best_ask":"0.14"}],"timestamp":"1776808415419","event_type":"price_change"}}
{"capturedAt":1776808415,"payload":{"market":"0x125149c5918fc5f8c6d34682f700a898a1a19ea4f4e2ae68ff4c5794ba657074","asset_id":"86520121088881862182423437128238697252500151785248183602134095101149900014256","bids":[{"price":"0.01","size":"12907.69"},{"price":"0.02","size":"1746.16"},{"price":"0.03","size":"1413.83"},{"price":"0.04","size":"938.3"},{"price":"0.05","size":"790.63"},{"price":"0.06","size":"395.8"},{"price":"0.07","size":"685.3"},{"price":"0.08","size":"656.9"},{"price":"0.09","size":"267.44"},{"price":"0.1","size":"793.5"},{"price":"0.11","size":"386.5"},{"price":"0.12","size":"308.5"},{"price":"0.13","size":"210.55"}],"asks":[{"price":"0.99","size":"12324.83"},{"price":"0.98","size":"1715.28"},{"price":"0.97","size":"1338.69"},{"price":"0.96","size":"583.84"},{"price":"0.95","size":"1006.34"},{"price":"0.94","size":"392.8"},{"price":"0.93","size":"304.69"},{"price":"0.92","size":"278.9"},{"price":"0.91","size":"225"},{"price":"0.9","size":"282"},{"price":"0.89","size":"217.79"},{"price":"0.88","size":"215.1"},{"price":"0.87","size":"202.8"},{"price":"0.86","size":"200.9"},{"price":"0.85","size":"209.2"},{"price":"0.84","size":"197.8"},{"price":"0.83","size":"202.39"},{"price":"0.82","size":"200.4"},{"price":"0.81","size":"194.4"},{"price":"0.8","size":"193.5"},{"price":"0.79","size":"215.31"},{"price":"0.78","size":"197"},{"price":"0.77","size":"229.34"},{"price":"0.76","size":"195.7"},{"price":"0.75","size":"190.2"},{"price":"0.74","size":"189.7"},{"price":"0.73","size":"194.3"},{"price":"0.72","size":"188.89"},{"price":"0.71","size":"188.5"},{"price":"0.7","size":"206.48"},{"price":"0.69","size":"394.45"},{"price":"0.68","size":"187.5"},{"price":"0.67","size":"193.55"},{"price":"0.66","size":"187"},{"price":"0.65","size":"602.68"},{"price":"0.64","size":"186.6"},{"price":"0.63","size":"191.96"},{"price":"0.62","size":"186.3"},{"price":"0.61","size":"491.36"},{"price":"0.6","size":"226"},{"price":"0.59","size":"203.32"},{"price":"0.58","size":"185.8"},{"price":"0.57","size":"190.8"},{"price":"0.56","size":"190.6"},{"price":"0.55","size":"230.58"},{"price":"0.54","size":"185.5"},{"price":"0.53","size":"245.86"},{"price":"0.52","size":"242.56"},{"price":"0.51","size":"222.4"},{"price":"0.5","size":"378.64"},{"price":"0.49","size":"205.25"},{"price":"0.48","size":"226.77"},{"price":"0.47","size":"136.71"},{"price":"0.46","size":"185.5"},{"price":"0.45","size":"207.66"},{"price":"0.44","size":"196.6"},{"price":"0.43","size":"180.7"},{"price":"0.42","size":"180.8"},{"price":"0.41","size":"180.9"},{"price":"0.4","size":"139"},{"price":"0.39","size":"185.46"},{"price":"0.38","size":"141.3"},{"price":"0.37","size":"131.4"},{"price":"0.36","size":"131.6"},{"price":"0.35","size":"136.8"},{"price":"0.34","size":"342"},{"price":"0.33","size":"232.3"},{"price":"0.32","size":"382.5"},{"price":"0.31","size":"182.8"},{"price":"0.3","size":"244.95"},{"price":"0.29","size":"405.5"},{"price":"0.28","size":"530.89"},{"price":"0.27","size":"217.3"},{"price":"0.26","size":"287.7"},{"price":"0.25","size":"382.29"},{"price":"0.24","size":"148.49"},{"price":"0.23","size":"221.3"},{"price":"0.22","size":"328.98"},{"price":"0.21","size":"219.7"},{"price":"0.2","size":"245.25"},{"price":"0.19","size":"304.9"},{"price":"0.18","size":"325.78"},{"price":"0.17","size":"353.3"},{"price":"0.16","size":"389.37"},{"price":"0.15","size":"452.28"},{"price":"0.14","size":"335.46"}],"hash":"73716d8ab71dad5bb09cc8a01f7e15c7252a7a85","timestamp":"1776808415408","event_type":"book"}}
{"capturedAt":1776808415,"payload":{"market":"0x125149c5918fc5f8c6d34682f700a898a1a19ea4f4e2ae68ff4c5794ba657074","price_changes":[{"asset_id":"45936375922793925919605092352922707796689801895417366600539442410775071099958","price":"0.84","size":"384.37","side":"BUY","hash":"920c4d6cbdaa39e58d2b37847a4895c018021b36","best_bid":"0.86","best_ask":"0.87"},{"asset_id":"86520121088881862182423437128238697252500151785248183602134095101149900014256","price":"0.16","size":"384.37","side":"SELL","hash":"5e0850fcbbbe13ef2d5f1a448961862ab34298cf","best_bid":"0.13","best_ask":"0.14"}],"timestamp":"1776808415437","event_type":"price_change"}}
{"capturedAt":1776808415,"payload":{"market":"0x125149c5918fc5f8c6d34682f700a898a1a19ea4f4e2ae68ff4c5794ba657074","price_changes":[{"asset_id":"45936375922793925919605092352922707796689801895417366600539442410775071099958","price":"0.86","size":"289.46","side":"BUY","hash":"64f916653c737b7d166f42a7231685814d049b3b","best_bid":"0.86","best_ask":"0.87"},{"asset_id":"86520121088881862182423437128238697252500151785248183602134095101149900014256","price":"0.14","size":"289.46","side":"SELL","hash":"d95241fb92be1f0301fa368893b2a9dd3173f04c","best_bid":"0.13","best_ask":"0.14"}],"timestamp":"1776808415444","event_type":"price_change"}}
{"capturedAt":1776808415,"payload":{"market":"0x125149c5918fc5f8c6d34682f700a898a1a19ea4f4e2ae68ff4c5794ba657074","price_changes":[{"asset_id":"45936375922793925919605092352922707796689801895417366600539442410775071099958","price":"0.86","size":"284.21","side":"BUY","hash":"f040e987c673a405a7a624d16b4fe82af969671d","best_bid":"0.86","best_ask":"0.87"},{"asset_id":"86520121088881862182423437128238697252500151785248183602134095101149900014256","price":"0.14","size":"284.21","side":"SELL","hash":"a1beaf3a750229b2871938ce67c5dd678ca1caed","best_bid":"0.13","best_ask":"0.14"}],"timestamp":"1776808415445","event_type":"price_change"}}
{"capturedAt":1776808415,"payload":{"market":"0x125149c5918fc5f8c6d34682f700a898a1a19ea4f4e2ae68ff4c5794ba657074","price_changes":[{"asset_id":"45936375922793925919605092352922707796689801895417366600539442410775071099958","price":"0.86","size":"289.26","side":"BUY","hash":"0336d597f83b016383ad675bf4e8aa54adcc5d1b","best_bid":"0.86","best_ask":"0.87"},{"asset_id":"86520121088881862182423437128238697252500151785248183602134095101149900014256","price":"0.14","size":"289.26","side":"SELL","hash":"6ea893d46ba216a9507c957e4b140702935ace46","best_bid":"0.13","best_ask":"0.14"}],"timestamp":"1776808415446","event_type":"price_change"}}
{"capturedAt":1776808415,"payload":{"market":"0x125149c5918fc5f8c6d34682f700a898a1a19ea4f4e2ae68ff4c5794ba657074","price_changes":[{"asset_id":"45936375922793925919605092352922707796689801895417366600539442410775071099958","price":"0.86","size":"254.26","side":"BUY","hash":"2ea6405a45a28394e02b097ce5d0bbb67236db98","best_bid":"0.86","best_ask":"0.87"},{"asset_id":"86520121088881862182423437128238697252500151785248183602134095101149900014256","price":"0.14","size":"254.26","side":"SELL","hash":"2aed6064feb4543a74d253f493a5f160a7e8833f","best_bid":"0.13","best_ask":"0.14"}],"timestamp":"1776808415453","event_type":"price_change"}}
{"capturedAt":1776808415,"payload":{"market":"0x125149c5918fc5f8c6d34682f700a898a1a19ea4f4e2ae68ff4c5794ba657074","price_changes":[{"asset_id":"45936375922793925919605092352922707796689801895417366600539442410775071099958","price":"0.86","size":"271.26","side":"BUY","hash":"7a2103e366fea83bd9e195d830766f0500a4042a","best_bid":"0.86","best_ask":"0.87"},{"asset_id":"86520121088881862182423437128238697252500151785248183602134095101149900014256","price":"0.14","size":"271.26","side":"SELL","hash":"47eaa25facaa7946b1998f98f0c26063291007df","best_bid":"0.13","best_ask":"0.14"}],"timestamp":"1776808415451","event_type":"price_change"}}
{"capturedAt":1776808415,"payload":{"market":"0x125149c5918fc5f8c6d34682f700a898a1a19ea4f4e2ae68ff4c5794ba657074","price_changes":[{"asset_id":"45936375922793925919605092352922707796689801895417366600539442410775071099958","price":"0.86","size":"247.26","side":"BUY","hash":"e91a291bd586b62bcc1b1648c55310daf72aff9f","best_bid":"0.86","best_ask":"0.87"},{"asset_id":"86520121088881862182423437128238697252500151785248183602134095101149900014256","price":"0.14","size":"247.26","side":"SELL","hash":"ff858de03e907b460b90f40bd4d1a49f3a50b8cb","best_bid":"0.13","best_ask":"0.14"}],"timestamp":"1776808415459","event_type":"price_change"}}
{"capturedAt":1776808415,"payload":{"market":"0x125149c5918fc5f8c6d34682f700a898a1a19ea4f4e2ae68ff4c5794ba657074","price_changes":[{"asset_id":"45936375922793925919605092352922707796689801895417366600539442410775071099958","price":"0.86","size":"269.26","side":"BUY","hash":"31795e7b4d4d0bada3d6568f969d660e60d4f1a5","best_bid":"0.86","best_ask":"0.87"},{"asset_id":"86520121088881862182423437128238697252500151785248183602134095101149900014256","price":"0.14","size":"269.26","side":"SELL","hash":"79e56c4143111685e9d1b8a85fda3a910a6a45f6","best_bid":"0.13","best_ask":"0.14"}],"timestamp":"1776808415462","event_type":"price_change"}}
{"capturedAt":1776808415,"payload":{"market":"0x125149c5918fc5f8c6d34682f700a898a1a19ea4f4e2ae68ff4c5794ba657074","price_changes":[{"asset_id":"45936375922793925919605092352922707796689801895417366600539442410775071099958","price":"0.86","size":"216.26","side":"BUY","hash":"414131651fa964500d3077c55b9040e1571ad585","best_bid":"0.86","best_ask":"0.87"},{"asset_id":"86520121088881862182423437128238697252500151785248183602134095101149900014256","price":"0.14","size":"216.26","side":"SELL","hash":"1be1e40bad8b57ec73c4c25cfe282e1665352d20","best_bid":"0.13","best_ask":"0.14"}],"timestamp":"1776808415456","event_type":"price_change"}}
{"capturedAt":1776808415,"payload":{"market":"0x125149c5918fc5f8c6d34682f700a898a1a19ea4f4e2ae68ff4c5794ba657074","price_changes":[{"asset_id":"45936375922793925919605092352922707796689801895417366600539442410775071099958","price":"0.85","size":"457.28","side":"BUY","hash":"5571775f5125fa0ae4d90b37a5be68a433a2141d","best_bid":"0.86","best_ask":"0.87"},{"asset_id":"86520121088881862182423437128238697252500151785248183602134095101149900014256","price":"0.15","size":"457.28","side":"SELL","hash":"cf2dd487810cad4c9e798afa8b48b76b2608fc9b","best_bid":"0.13","best_ask":"0.14"}],"timestamp":"1776808415460","event_type":"price_change"}}
{"capturedAt":1776808415,"payload":{"market":"0x125149c5918fc5f8c6d34682f700a898a1a19ea4f4e2ae68ff4c5794ba657074","price_changes":[{"asset_id":"45936375922793925919605092352922707796689801895417366600539442410775071099958","price":"0.86","size":"236.26","side":"BUY","hash":"c1b31497bd97c2db5e553f88b05b12677b59222f","best_bid":"0.86","best_ask":"0.87"},{"asset_id":"86520121088881862182423437128238697252500151785248183602134095101149900014256","price":"0.14","size":"236.26","side":"SELL","hash":"e8b35819dd6c2fe8260e4b9da6e437c4be271c84","best_bid":"0.13","best_ask":"0.14"}],"timestamp":"1776808415454","event_type":"price_change"}}
{"capturedAt":1776808415,"payload":{"market":"0x125149c5918fc5f8c6d34682f700a898a1a19ea4f4e2ae68ff4c5794ba657074","price_changes":[{"asset_id":"45936375922793925919605092352922707796689801895417366600539442410775071099958","price":"0.86","size":"237.26","side":"BUY","hash":"6e3fca1ecb32c943ab5307618dd72af48b6a8b18","best_bid":"0.86","best_ask":"0.87"},{"asset_id":"86520121088881862182423437128238697252500151785248183602134095101149900014256","price":"0.14","size":"237.26","side":"SELL","hash":"1756db4e6257ebbb11b8579c3ca226a56467ef02","best_bid":"0.13","best_ask":"0.14"}],"timestamp":"1776808415457","event_type":"price_change"}}
{"capturedAt":1776808415,"payload":{"market":"0x125149c5918fc5f8c6d34682f700a898a1a19ea4f4e2ae68ff4c5794ba657074","price_changes":[{"asset_id":"45936375922793925919605092352922707796689801895417366600539442410775071099958","price":"0.86","size":"259.26","side":"BUY","hash":"72b671482a0beee4d4863214cc1a5400b17a3378","best_bid":"0.86","best_ask":"0.87"},{"asset_id":"86520121088881862182423437128238697252500151785248183602134095101149900014256","price":"0.14","size":"259.26","side":"SELL","hash":"e25a3b600b992737aa7ddc8f839c6a1b53bf0a4c","best_bid":"0.13","best_ask":"0.14"}],"timestamp":"1776808415464","event_type":"price_change"}}
{"capturedAt":1776808415,"payload":{"market":"0x125149c5918fc5f8c6d34682f700a898a1a19ea4f4e2ae68ff4c5794ba657074","price_changes":[{"asset_id":"45936375922793925919605092352922707796689801895417366600539442410775071099958","price":"0.86","size":"280.26","side":"BUY","hash":"7344f3d91fc537a927008a25fbaea006c22b6f2f","best_bid":"0.86","best_ask":"0.87"},{"asset_id":"86520121088881862182423437128238697252500151785248183602134095101149900014256","price":"0.14","size":"280.26","side":"SELL","hash":"3a8de32faf85906abf1366307c8c48d01af8cbf9","best_bid":"0.13","best_ask":"0.14"}],"timestamp":"1776808415471","event_type":"price_change"}}
{"capturedAt":1776808415,"payload":{"market":"0x125149c5918fc5f8c6d34682f700a898a1a19ea4f4e2ae68ff4c5794ba657074","price_changes":[{"asset_id":"45936375922793925919605092352922707796689801895417366600539442410775071099958","price":"0.01","size":"12329.83","side":"BUY","hash":"d82c195b22024182cc3c90da8b9d3b1f83879f26","best_bid":"0.86","best_ask":"0.87"},{"asset_id":"86520121088881862182423437128238697252500151785248183602134095101149900014256","price":"0.99","size":"12329.83","side":"SELL","hash":"9d31e37ea1356aa6caf32c45844d8b97ebebda7f","best_bid":"0.13","best_ask":"0.14"}],"timestamp":"1776808415463","event_type":"price_change"}}
{"capturedAt":1776808415,"payload":{"market":"0x125149c5918fc5f8c6d34682f700a898a1a19ea4f4e2ae68ff4c5794ba657074","price_changes":[{"asset_id":"45936375922793925919605092352922707796689801895417366600539442410775071099958","price":"0.86","size":"271.26","side":"BUY","hash":"5801e085921e25d008c0e2e584793dc8d6461a00","best_bid":"0.86","best_ask":"0.87"},{"asset_id":"86520121088881862182423437128238697252500151785248183602134095101149900014256","price":"0.14","size":"271.26","side":"SELL","hash":"93277112dc159946e76ff84bdbfe97b79832ffdb","best_bid":"0.13","best_ask":"0.14"}],"timestamp":"1776808415482","event_type":"price_change"}}
{"capturedAt":1776808415,"payload":{"market":"0x125149c5918fc5f8c6d34682f700a898a1a19ea4f4e2ae68ff4c5794ba657074","price_changes":[{"asset_id":"45936375922793925919605092352922707796689801895417366600539442410775071099958","price":"0.86","size":"252.26","side":"BUY","hash":"2723901654b8856b4e8fb5f7aec6964eb866f09d","best_bid":"0.86","best_ask":"0.87"},{"asset_id":"86520121088881862182423437128238697252500151785248183602134095101149900014256","price":"0.14","size":"252.26","side":"SELL","hash":"9c3a0e9327a14e7ebb837121e87301a69e66f612","best_bid":"0.13","best_ask":"0.14"}],"timestamp":"1776808415480","event_type":"price_change"}}
{"capturedAt":1776808415,"payload":{"market":"0x125149c5918fc5f8c6d34682f700a898a1a19ea4f4e2ae68ff4c5794ba657074","price_changes":[{"asset_id":"45936375922793925919605092352922707796689801895417366600539442410775071099958","price":"0.01","size":"12329.83","side":"BUY","hash":"5e47e8ac784c5bbd89b6091c41d6b6e5d9027d75","best_bid":"0.86","best_ask":"0.87"},{"asset_id":"86520121088881862182423437128238697252500151785248183602134095101149900014256","price":"0.99","size":"12329.83","side":"SELL","hash":"df24f6ad9b06e41b55b2108eee5c97ba6ed722fd","best_bid":"0.13","best_ask":"0.14"}],"timestamp":"1776808415483","event_type":"price_change"}}
{"capturedAt":1776808415,"payload":{"market":"0x125149c5918fc5f8c6d34682f700a898a1a19ea4f4e2ae68ff4c5794ba657074","price_changes":[{"asset_id":"45936375922793925919605092352922707796689801895417366600539442410775071099958","price":"0.86","size":"233.26","side":"BUY","hash":"4b2f2e6ee6d867ccd561e7b27594373be055ca04","best_bid":"0.86","best_ask":"0.87"},{"asset_id":"86520121088881862182423437128238697252500151785248183602134095101149900014256","price":"0.14","size":"233.26","side":"SELL","hash":"b93433e58cdb13f8286e046762fd322787c2f64e","best_bid":"0.13","best_ask":"0.14"}],"timestamp":"1776808415477","event_type":"price_change"}}
{"capturedAt":1776808415,"payload":{"market":"0x125149c5918fc5f8c6d34682f700a898a1a19ea4f4e2ae68ff4c5794ba657074","price_changes":[{"asset_id":"45936375922793925919605092352922707796689801895417366600539442410775071099958","price":"0.86","size":"243.26","side":"BUY","hash":"5852e77c14d575824b307fb416070857046c2ae1","best_bid":"0.86","best_ask":"0.87"},{"asset_id":"86520121088881862182423437128238697252500151785248183602134095101149900014256","price":"0.14","size":"243.26","side":"SELL","hash":"9baaa2293743164adfa16db6e042e6bb53ab8ff4","best_bid":"0.13","best_ask":"0.14"}],"timestamp":"1776808415476","event_type":"price_change"}}
{"capturedAt":1776808415,"payload":{"market":"0x125149c5918fc5f8c6d34682f700a898a1a19ea4f4e2ae68ff4c5794ba657074","price_changes":[{"asset_id":"45936375922793925919605092352922707796689801895417366600539442410775071099958","price":"0.86","size":"290.26","side":"BUY","hash":"9faa2ae8cb96ce9f69b582fd124f0fa5a71c2fb6","best_bid":"0.86","best_ask":"0.87"},{"asset_id":"86520121088881862182423437128238697252500151785248183602134095101149900014256","price":"0.14","size":"290.26","side":"SELL","hash":"3e06b53adc362ff145a3e72b31713faaf8cdeaf7","best_bid":"0.13","best_ask":"0.14"}],"timestamp":"1776808415484","event_type":"price_change"}}
{"capturedAt":1776808415,"payload":{"market":"0x125149c5918fc5f8c6d34682f700a898a1a19ea4f4e2ae68ff4c5794ba657074","price_changes":[{"asset_id":"45936375922793925919605092352922707796689801895417366600539442410775071099958","price":"0.86","size":"310.26","side":"BUY","hash":"59b9b03fa85e0ca9a15a170febcdabdbbd9ac212","best_bid":"0.86","best_ask":"0.87"},{"asset_id":"86520121088881862182423437128238697252500151785248183602134095101149900014256","price":"0.14","size":"310.26","side":"SELL","hash":"9f0ff78d3ee62d8c5e135c0d4ddf82fe27ec35dc","best_bid":"0.13","best_ask":"0.14"}],"timestamp":"1776808415485","event_type":"price_change"}}
{"capturedAt":1776808415,"payload":{"market":"0x125149c5918fc5f8c6d34682f700a898a1a19ea4f4e2ae68ff4c5794ba657074","price_changes":[{"asset_id":"45936375922793925919605092352922707796689801895417366600539442410775071099958","price":"0.85","size":"437.28","side":"BUY","hash":"104f39bbde5f98f36d15a338740bd8cb6325484f","best_bid":"0.86","best_ask":"0.87"},{"asset_id":"86520121088881862182423437128238697252500151785248183602134095101149900014256","price":"0.15","size":"437.28","side":"SELL","hash":"bb3eea2021cb124c9e54cc54281c79a75e61119c","best_bid":"0.13","best_ask":"0.14"}],"timestamp":"1776808415489","event_type":"price_change"}}
{"capturedAt":1776808415,"payload":{"market":"0x125149c5918fc5f8c6d34682f700a898a1a19ea4f4e2ae68ff4c5794ba657074","price_changes":[{"asset_id":"45936375922793925919605092352922707796689801895417366600539442410775071099958","price":"0.01","size":"12334.83","side":"BUY","hash":"787b9c183d20bd38b761332e669f75c5793b557d","best_bid":"0.86","best_ask":"0.87"},{"asset_id":"86520121088881862182423437128238697252500151785248183602134095101149900014256","price":"0.99","size":"12334.83","side":"SELL","hash":"24c3c21d87cf757ee790af702d79ef4e9900783e","best_bid":"0.13","best_ask":"0.14"}],"timestamp":"1776808415475","event_type":"price_change"}}
{"capturedAt":1776808415,"payload":{"market":"0x125149c5918fc5f8c6d34682f700a898a1a19ea4f4e2ae68ff4c5794ba657074","price_changes":[{"asset_id":"45936375922793925919605092352922707796689801895417366600539442410775071099958","price":"0.86","size":"262.26","side":"BUY","hash":"10b787371b6af19292b9bc40294d5ffb0411a4fd","best_bid":"0.86","best_ask":"0.87"},{"asset_id":"86520121088881862182423437128238697252500151785248183602134095101149900014256","price":"0.14","size":"262.26","side":"SELL","hash":"98ff9ce5dd4480da7f24a862e0d007d5b125056b","best_bid":"0.13","best_ask":"0.14"}],"timestamp":"1776808415474","event_type":"price_change"}}
{"capturedAt":1776808415,"payload":{"market":"0x125149c5918fc5f8c6d34682f700a898a1a19ea4f4e2ae68ff4c5794ba657074","price_changes":[{"asset_id":"45936375922793925919605092352922707796689801895417366600539442410775071099958","price":"0.01","size":"12324.83","side":"BUY","hash":"153c6260445dbb8ef2ef24908c4211d0a6c6a0b9","best_bid":"0.86","best_ask":"0.87"},{"asset_id":"86520121088881862182423437128238697252500151785248183602134095101149900014256","price":"0.99","size":"12324.83","side":"SELL","hash":"223cb87d33cd0c5d2cdb011f32e7b2d311ff742d","best_bid":"0.13","best_ask":"0.14"}],"timestamp":"1776808415494","event_type":"price_change"}}
{"capturedAt":1776808415,"payload":{"market":"0x125149c5918fc5f8c6d34682f700a898a1a19ea4f4e2ae68ff4c5794ba657074","price_changes":[{"asset_id":"45936375922793925919605092352922707796689801895417366600539442410775071099958","price":"0.86","size":"309.26","side":"BUY","hash":"796092093bb94ea5db4c57ec257c218cae9fdbcc","best_bid":"0.86","best_ask":"0.87"},{"asset_id":"86520121088881862182423437128238697252500151785248183602134095101149900014256","price":"0.14","size":"309.26","side":"SELL","hash":"4f3baa9a99581fb954530fcb5373a5a807ddfa9c","best_bid":"0.13","best_ask":"0.14"}],"timestamp":"1776808415495","event_type":"price_change"}}
{"capturedAt":1776808415,"payload":{"market":"0x125149c5918fc5f8c6d34682f700a898a1a19ea4f4e2ae68ff4c5794ba657074","price_changes":[{"asset_id":"45936375922793925919605092352922707796689801895417366600539442410775071099958","price":"0.86","size":"304.21","side":"BUY","hash":"7558438a8f1c7dbc9377f7c3d2e35ec32f5c89aa","best_bid":"0.86","best_ask":"0.87"},{"asset_id":"86520121088881862182423437128238697252500151785248183602134095101149900014256","price":"0.14","size":"304.21","side":"SELL","hash":"54b13596c38361bd2ba26e9c2b72ecdb65efc696","best_bid":"0.13","best_ask":"0.14"}],"timestamp":"1776808415496","event_type":"price_change"}}
{"capturedAt":1776808415,"payload":{"market":"0x125149c5918fc5f8c6d34682f700a898a1a19ea4f4e2ae68ff4c5794ba657074","price_changes":[{"asset_id":"45936375922793925919605092352922707796689801895417366600539442410775071099958","price":"0.86","size":"299.26","side":"BUY","hash":"653ac0550792bf28d67347715a7b920381466eef","best_bid":"0.86","best_ask":"0.87"},{"asset_id":"86520121088881862182423437128238697252500151785248183602134095101149900014256","price":"0.14","size":"299.26","side":"SELL","hash":"4f198a5e7601a3f32c6fd4cd24fdc9f0ef481a0b","best_bid":"0.13","best_ask":"0.14"}],"timestamp":"1776808415493","event_type":"price_change"}}
{"capturedAt":1776808415,"payload":{"market":"0x125149c5918fc5f8c6d34682f700a898a1a19ea4f4e2ae68ff4c5794ba657074","price_changes":[{"asset_id":"45936375922793925919605092352922707796689801895417366600539442410775071099958","price":"0.86","size":"324.21","side":"BUY","hash":"25964c56b4125d91c2581c5f4a49fcb80cac91d0","best_bid":"0.86","best_ask":"0.87"},{"asset_id":"86520121088881862182423437128238697252500151785248183602134095101149900014256","price":"0.14","size":"324.21","side":"SELL","hash":"ac1057fce46c509fa10d9d9cf3a92be8fe512a25","best_bid":"0.13","best_ask":"0.14"}],"timestamp":"1776808415501","event_type":"price_change"}}
{"capturedAt":1776808415,"payload":{"market":"0x125149c5918fc5f8c6d34682f700a898a1a19ea4f4e2ae68ff4c5794ba657074","price_changes":[{"asset_id":"45936375922793925919605092352922707796689801895417366600539442410775071099958","price":"0.86","size":"323.21","side":"BUY","hash":"e360e093aaaea92652f3863c23a396eaf221d0a8","best_bid":"0.86","best_ask":"0.87"},{"asset_id":"86520121088881862182423437128238697252500151785248183602134095101149900014256","price":"0.14","size":"323.21","side":"SELL","hash":"a67be03d78ac7acde2aead6122b9a01afd1ef565","best_bid":"0.13","best_ask":"0.14"}],"timestamp":"1776808415506","event_type":"price_change"}}
{"capturedAt":1776808415,"payload":{"market":"0x125149c5918fc5f8c6d34682f700a898a1a19ea4f4e2ae68ff4c5794ba657074","price_changes":[{"asset_id":"45936375922793925919605092352922707796689801895417366600539442410775071099958","price":"0.86","size":"313.21","side":"BUY","hash":"ba97ff44d6e43d108d9c5a434fbfb3f8958f4fd5","best_bid":"0.86","best_ask":"0.87"},{"asset_id":"86520121088881862182423437128238697252500151785248183602134095101149900014256","price":"0.14","size":"313.21","side":"SELL","hash":"559bd65309ff97ef20b6b10d502ae2a14de51b88","best_bid":"0.13","best_ask":"0.14"}],"timestamp":"1776808415505","event_type":"price_change"}}
{"capturedAt":1776808415,"payload":{"market":"0x125149c5918fc5f8c6d34682f700a898a1a19ea4f4e2ae68ff4c5794ba657074","price_changes":[{"asset_id":"45936375922793925919605092352922707796689801895417366600539442410775071099958","price":"0.86","size":"344.21","side":"BUY","hash":"6eff3f3fcdaed5028087bb6f9266d987332a9cfe","best_bid":"0.86","best_ask":"0.87"},{"asset_id":"86520121088881862182423437128238697252500151785248183602134095101149900014256","price":"0.14","size":"344.21","side":"SELL","hash":"2c04306f48435a1dc085b652dde5c6d40d136d26","best_bid":"0.13","best_ask":"0.14"}],"timestamp":"1776808415507","event_type":"price_change"}}
{"capturedAt":1776808415,"payload":{"market":"0x125149c5918fc5f8c6d34682f700a898a1a19ea4f4e2ae68ff4c5794ba657074","price_changes":[{"asset_id":"45936375922793925919605092352922707796689801895417366600539442410775071099958","price":"0.86","size":"349.74","side":"BUY","hash":"285b95c63e8e222180d2e4d079a854c7652b5ed2","best_bid":"0.86","best_ask":"0.87"},{"asset_id":"86520121088881862182423437128238697252500151785248183602134095101149900014256","price":"0.14","size":"349.74","side":"SELL","hash":"30bb123c4fcf7c5b548ee05b5af956477959f48b","best_bid":"0.13","best_ask":"0.14"}],"timestamp":"1776808415527","event_type":"price_change"}}
{"capturedAt":1776808415,"payload":{"market":"0x125149c5918fc5f8c6d34682f700a898a1a19ea4f4e2ae68ff4c5794ba657074","price_changes":[{"asset_id":"45936375922793925919605092352922707796689801895417366600539442410775071099958","price":"0.86","size":"361.74","side":"BUY","hash":"d355fcc63e37c1357dd0770d8a284b5f813172a4","best_bid":"0.86","best_ask":"0.87"},{"asset_id":"86520121088881862182423437128238697252500151785248183602134095101149900014256","price":"0.14","size":"361.74","side":"SELL","hash":"ed7b86a3ab78321550de2c37d9143140e5146894","best_bid":"0.13","best_ask":"0.14"}],"timestamp":"1776808415529","event_type":"price_change"}}
{"capturedAt":1776808415,"payload":{"market":"0x125149c5918fc5f8c6d34682f700a898a1a19ea4f4e2ae68ff4c5794ba657074","price_changes":[{"asset_id":"45936375922793925919605092352922707796689801895417366600539442410775071099958","price":"0.01","size":"12329.83","side":"BUY","hash":"11d0352e6c45b199635a97f27ecbe9a5edf3317e","best_bid":"0.86","best_ask":"0.87"},{"asset_id":"86520121088881862182423437128238697252500151785248183602134095101149900014256","price":"0.99","size":"12329.83","side":"SELL","hash":"06a9e5cc8d846fcd3c1bc3b9a8150c8aca991c9c","best_bid":"0.13","best_ask":"0.14"}],"timestamp":"1776808415528","event_type":"price_change"}}
{"capturedAt":1776808415,"payload":{"market":"0x125149c5918fc5f8c6d34682f700a898a1a19ea4f4e2ae68ff4c5794ba657074","price_changes":[{"asset_id":"45936375922793925919605092352922707796689801895417366600539442410775071099958","price":"0.86","size":"340.74","side":"BUY","hash":"17dc6d244fe098133d74394a5c0adfb15612430a","best_bid":"0.86","best_ask":"0.87"},{"asset_id":"86520121088881862182423437128238697252500151785248183602134095101149900014256","price":"0.14","size":"340.74","side":"SELL","hash":"8304a9ad73ac1bf88890583b1a589a51a1ca85ca","best_bid":"0.13","best_ask":"0.14"}],"timestamp":"1776808415529","event_type":"price_change"}}
{"capturedAt":1776808415,"payload":{"market":"0x125149c5918fc5f8c6d34682f700a898a1a19ea4f4e2ae68ff4c5794ba657074","price_changes":[{"asset_id":"45936375922793925919605092352922707796689801895417366600539442410775071099958","price":"0.01","size":"12334.83","side":"BUY","hash":"7ff19a2a3e32d924a225ca32f4abb15bbbb72e4c","best_bid":"0.86","best_ask":"0.87"},{"asset_id":"86520121088881862182423437128238697252500151785248183602134095101149900014256","price":"0.99","size":"12334.83","side":"SELL","hash":"872217d275b68829198980420dc7c469de011303","best_bid":"0.13","best_ask":"0.14"}],"timestamp":"1776808415530","event_type":"price_change"}}
{"capturedAt":1776808415,"payload":{"market":"0x125149c5918fc5f8c6d34682f700a898a1a19ea4f4e2ae68ff4c5794ba657074","price_changes":[{"asset_id":"45936375922793925919605092352922707796689801895417366600539442410775071099958","price":"0.86","size":"353.74","side":"BUY","hash":"0e4ae1743599492c4e7425355e852a10d7624e02","best_bid":"0.86","best_ask":"0.87"},{"asset_id":"86520121088881862182423437128238697252500151785248183602134095101149900014256","price":"0.14","size":"353.74","side":"SELL","hash":"1a07f9136a7b191b1bdb64ec6607b5033a36de7d","best_bid":"0.13","best_ask":"0.14"}],"timestamp":"1776808415531","event_type":"price_change"}}
{"capturedAt":1776808415,"payload":{"market":"0x125149c5918fc5f8c6d34682f700a898a1a19ea4f4e2ae68ff4c5794ba657074","price_changes":[{"asset_id":"45936375922793925919605092352922707796689801895417366600539442410775071099958","price":"0.86","size":"343.74","side":"BUY","hash":"d40b7798a4d40031b5243a10ea0b813b4498c0f8","best_bid":"0.86","best_ask":"0.87"},{"asset_id":"86520121088881862182423437128238697252500151785248183602134095101149900014256","price":"0.14","size":"343.74","side":"SELL","hash":"fce7db0c6a809434b9f65b7650ce98536944b20c","best_bid":"0.13","best_ask":"0.14"}],"timestamp":"1776808415532","event_type":"price_change"}}
{"capturedAt":1776808415,"payload":{"market":"0x125149c5918fc5f8c6d34682f700a898a1a19ea4f4e2ae68ff4c5794ba657074","price_changes":[{"asset_id":"45936375922793925919605092352922707796689801895417366600539442410775071099958","price":"0.86","size":"321.74","side":"BUY","hash":"bc3ce3197234e587cfcb8c7bae5cb445521ac9e0","best_bid":"0.86","best_ask":"0.87"},{"asset_id":"86520121088881862182423437128238697252500151785248183602134095101149900014256","price":"0.14","size":"321.74","side":"SELL","hash":"36881c2edfcd05ecdfb7f6eb5f2fc00a69644c5a","best_bid":"0.13","best_ask":"0.14"}],"timestamp":"1776808415533","event_type":"price_change"}}
{"capturedAt":1776808415,"payload":{"market":"0x125149c5918fc5f8c6d34682f700a898a1a19ea4f4e2ae68ff4c5794ba657074","price_changes":[{"asset_id":"45936375922793925919605092352922707796689801895417366600539442410775071099958","price":"0.82","size":"319.9","side":"BUY","hash":"5aa929dc616a8f4ed2384511407730b430f1da19","best_bid":"0.86","best_ask":"0.87"},{"asset_id":"86520121088881862182423437128238697252500151785248183602134095101149900014256","price":"0.18","size":"319.9","side":"SELL","hash":"0689fada5b4d2474bc8c73ed1b5bb7fb0f7df548","best_bid":"0.13","best_ask":"0.14"}],"timestamp":"1776808415535","event_type":"price_change"}}
{"capturedAt":1776808415,"payload":{"market":"0x125149c5918fc5f8c6d34682f700a898a1a19ea4f4e2ae68ff4c5794ba657074","price_changes":[{"asset_id":"45936375922793925919605092352922707796689801895417366600539442410775071099958","price":"0.86","size":"300.74","side":"BUY","hash":"36f1a3e40fa1876c26480a60591113450a7b546d","best_bid":"0.86","best_ask":"0.87"},{"asset_id":"86520121088881862182423437128238697252500151785248183602134095101149900014256","price":"0.14","size":"300.74","side":"SELL","hash":"65be2015f366cde4cd922d6a1b382b73b971223f","best_bid":"0.13","best_ask":"0.14"}],"timestamp":"1776808415542","event_type":"price_change"}}
{"capturedAt":1776808415,"payload":{"market":"0x125149c5918fc5f8c6d34682f700a898a1a19ea4f4e2ae68ff4c5794ba657074","price_changes":[{"asset_id":"45936375922793925919605092352922707796689801895417366600539442410775071099958","price":"0.01","size":"12329.83","side":"BUY","hash":"05c633d5985552aba70e3e756c9042ec7843b679","best_bid":"0.86","best_ask":"0.87"},{"asset_id":"86520121088881862182423437128238697252500151785248183602134095101149900014256","price":"0.99","size":"12329.83","side":"SELL","hash":"0ac2df4a7735629a3ee395a4c0fd0e686c84a642","best_bid":"0.13","best_ask":"0.14"}],"timestamp":"1776808415547","event_type":"price_change"}}
{"capturedAt":1776808415,"payload":{"market":"0x125149c5918fc5f8c6d34682f700a898a1a19ea4f4e2ae68ff4c5794ba657074","price_changes":[{"asset_id":"45936375922793925919605092352922707796689801895417366600539442410775071099958","price":"0.01","size":"12324.83","side":"BUY","hash":"8e0f998f3c065422aaaac8a445c2e6bd131734a3","best_bid":"0.86","best_ask":"0.87"},{"asset_id":"86520121088881862182423437128238697252500151785248183602134095101149900014256","price":"0.99","size":"12324.83","side":"SELL","hash":"e57b72a9f1f37a686df842305f82ba88182c099b","best_bid":"0.13","best_ask":"0.14"}],"timestamp":"1776808415548","event_type":"price_change"}}
{"capturedAt":1776808415,"payload":{"market":"0x125149c5918fc5f8c6d34682f700a898a1a19ea4f4e2ae68ff4c5794ba657074","price_changes":[{"asset_id":"45936375922793925919605092352922707796689801895417366600539442410775071099958","price":"0.86","size":"262.74","side":"BUY","hash":"0c4c109b29295e12ff8bcdd815773711f7d6cc69","best_bid":"0.86","best_ask":"0.87"},{"asset_id":"86520121088881862182423437128238697252500151785248183602134095101149900014256","price":"0.14","size":"262.74","side":"SELL","hash":"74b1ea1c22c5b0758fe31311a91e33baa7ddbbf9","best_bid":"0.13","best_ask":"0.14"}],"timestamp":"1776808415551","event_type":"price_change"}}
{"capturedAt":1776808415,"payload":{"market":"0x125149c5918fc5f8c6d34682f700a898a1a19ea4f4e2ae68ff4c5794ba657074","price_changes":[{"asset_id":"45936375922793925919605092352922707796689801895417366600539442410775071099958","price":"0.86","size":"281.74","side":"BUY","hash":"f1267b45a7749fb0297211f49c645cf0778dfaa3","best_bid":"0.86","best_ask":"0.87"},{"asset_id":"86520121088881862182423437128238697252500151785248183602134095101149900014256","price":"0.14","size":"281.74","side":"SELL","hash":"29d4ab2e69ed8b6b662c99d23db4905c447a8a07","best_bid":"0.13","best_ask":"0.14"}],"timestamp":"1776808415550","event_type":"price_change"}}
{"capturedAt":1776808415,"payload":{"market":"0x125149c5918fc5f8c6d34682f700a898a1a19ea4f4e2ae68ff4c5794ba657074","price_changes":[{"asset_id":"45936375922793925919605092352922707796689801895417366600539442410775071099958","price":"0.86","size":"242.74","side":"BUY","hash":"263da37d11ea80a3354e56d7e8405bd70d7f5d36","best_bid":"0.86","best_ask":"0.87"},{"asset_id":"86520121088881862182423437128238697252500151785248183602134095101149900014256","price":"0.14","size":"242.74","side":"SELL","hash":"ee9dbfd9c158ab5cc5b8fdcd0bcb5f203ef7cb13","best_bid":"0.13","best_ask":"0.14"}],"timestamp":"1776808415554","event_type":"price_change"}}
{"capturedAt":1776808415,"payload":{"market":"0x125149c5918fc5f8c6d34682f700a898a1a19ea4f4e2ae68ff4c5794ba657074","price_changes":[{"asset_id":"45936375922793925919605092352922707796689801895417366600539442410775071099958","price":"0.86","size":"223.74","side":"BUY","hash":"2549e00b03cb875861cef39a7c32fb0e2372ee51","best_bid":"0.86","best_ask":"0.87"},{"asset_id":"86520121088881862182423437128238697252500151785248183602134095101149900014256","price":"0.14","size":"223.74","side":"SELL","hash":"54a624abbf5101b6fa15eb0240a4f2d479449af1","best_bid":"0.13","best_ask":"0.14"}],"timestamp":"1776808415555","event_type":"price_change"}}
{"capturedAt":1776808415,"payload":{"market":"0x125149c5918fc5f8c6d34682f700a898a1a19ea4f4e2ae68ff4c5794ba657074","price_changes":[{"asset_id":"45936375922793925919605092352922707796689801895417366600539442410775071099958","price":"0.86","size":"233.74","side":"BUY","hash":"af26412658bd4a36a2c261a7d53e09acb4890f29","best_bid":"0.86","best_ask":"0.87"},{"asset_id":"86520121088881862182423437128238697252500151785248183602134095101149900014256","price":"0.14","size":"233.74","side":"SELL","hash":"7cc56e9c198361af61ea9ac3b0d50b689eda62b6","best_bid":"0.13","best_ask":"0.14"}],"timestamp":"1776808415558","event_type":"price_change"}}
{"capturedAt":1776808415,"payload":{"market":"0x125149c5918fc5f8c6d34682f700a898a1a19ea4f4e2ae68ff4c5794ba657074","price_changes":[{"asset_id":"45936375922793925919605092352922707796689801895417366600539442410775071099958","price":"0.86","size":"253.74","side":"BUY","hash":"1612306730cef1c1037d5106881ee94d65445c1f","best_bid":"0.86","best_ask":"0.87"},{"asset_id":"86520121088881862182423437128238697252500151785248183602134095101149900014256","price":"0.14","size":"253.74","side":"SELL","hash":"a9f99b07793fbee22eb35c2158f5b7bdf57a181e","best_bid":"0.13","best_ask":"0.14"}],"timestamp":"1776808415559","event_type":"price_change"}}
{"capturedAt":1776808415,"payload":{"market":"0x125149c5918fc5f8c6d34682f700a898a1a19ea4f4e2ae68ff4c5794ba657074","price_changes":[{"asset_id":"45936375922793925919605092352922707796689801895417366600539442410775071099958","price":"0.86","size":"274.74","side":"BUY","hash":"d64e37e555d50eaa21134f6cfcdcf7a3343949d9","best_bid":"0.86","best_ask":"0.87"},{"asset_id":"86520121088881862182423437128238697252500151785248183602134095101149900014256","price":"0.14","size":"274.74","side":"SELL","hash":"ff9fdb5a4b58ebe69992edd3725935a9f1d96c71","best_bid":"0.13","best_ask":"0.14"}],"timestamp":"1776808415563","event_type":"price_change"}}
{"capturedAt":1776808415,"payload":{"market":"0x125149c5918fc5f8c6d34682f700a898a1a19ea4f4e2ae68ff4c5794ba657074","price_changes":[{"asset_id":"86520121088881862182423437128238697252500151785248183602134095101149900014256","price":"0.11","size":"391.5","side":"BUY","hash":"a64bcdb0730cd27e85858993e4920b5ec3beded4","best_bid":"0.13","best_ask":"0.14"},{"asset_id":"45936375922793925919605092352922707796689801895417366600539442410775071099958","price":"0.89","size":"391.5","side":"SELL","hash":"c603de10acf6356ad3c592b28268eb4d97549403","best_bid":"0.86","best_ask":"0.87"}],"timestamp":"1776808415564","event_type":"price_change"}}
{"capturedAt":1776808415,"payload":{"market":"0x125149c5918fc5f8c6d34682f700a898a1a19ea4f4e2ae68ff4c5794ba657074","price_changes":[{"asset_id":"45936375922793925919605092352922707796689801895417366600539442410775071099958","price":"0.86","size":"264.74","side":"BUY","hash":"05b0647e26cb839b044117604058675850ebd174","best_bid":"0.86","best_ask":"0.87"},{"asset_id":"86520121088881862182423437128238697252500151785248183602134095101149900014256","price":"0.14","size":"264.74","side":"SELL","hash":"ca3a72f4c06519af7ca6cf67f3ff25a6d9cafd15","best_bid":"0.13","best_ask":"0.14"}],"timestamp":"1776808415565","event_type":"price_change"}}
{"capturedAt":1776808415,"payload":{"market":"0x125149c5918fc5f8c6d34682f700a898a1a19ea4f4e2ae68ff4c5794ba657074","price_changes":[{"asset_id":"45936375922793925919605092352922707796689801895417366600539442410775071099958","price":"0.86","size":"259.21","side":"BUY","hash":"cd6efb05d9674457dbf69c87ad1c7f782d15010c","best_bid":"0.86","best_ask":"0.87"},{"asset_id":"86520121088881862182423437128238697252500151785248183602134095101149900014256","price":"0.14","size":"259.21","side":"SELL","hash":"1b3171138ab1b1123235791c41ef1a190ddd9644","best_bid":"0.13","best_ask":"0.14"}],"timestamp":"1776808415566","event_type":"price_change"}}
{"capturedAt":1776808415,"payload":{"market":"0x125149c5918fc5f8c6d34682f700a898a1a19ea4f4e2ae68ff4c5794ba657074","price_changes":[{"asset_id":"45936375922793925919605092352922707796689801895417366600539442410775071099958","price":"0.86","size":"264.44","side":"BUY","hash":"60f27b285a700b413b8fa59c400c6122730de9b8","best_bid":"0.86","best_ask":"0.87"},{"asset_id":"86520121088881862182423437128238697252500151785248183602134095101149900014256","price":"0.14","size":"264.44","side":"SELL","hash":"4a3fea45877402c6574b4581eaec1b74983cb446","best_bid":"0.13","best_ask":"0.14"}],"timestamp":"1776808415567","event_type":"price_change"}}
{"capturedAt":1776808415,"payload":{"market":"0x125149c5918fc5f8c6d34682f700a898a1a19ea4f4e2ae68ff4c5794ba657074","price_changes":[{"asset_id":"45936375922793925919605092352922707796689801895417366600539442410775071099958","price":"0.86","size":"254.44","side":"BUY","hash":"efdffb657565165c46b55144e534a3ce801007ea","best_bid":"0.86","best_ask":"0.87"},{"asset_id":"86520121088881862182423437128238697252500151785248183602134095101149900014256","price":"0.14","size":"254.44","side":"SELL","hash":"a27f75a12908dde24335f0c04cc29a12e6186250","best_bid":"0.13","best_ask":"0.14"}],"timestamp":"1776808415570","event_type":"price_change"}}
{"capturedAt":1776808415,"payload":{"market":"0x125149c5918fc5f8c6d34682f700a898a1a19ea4f4e2ae68ff4c5794ba657074","price_changes":[{"asset_id":"45936375922793925919605092352922707796689801895417366600539442410775071099958","price":"0.86","size":"274.44","side":"BUY","hash":"10ddefcbc6a34659b936d1e68b20960482f3c165","best_bid":"0.86","best_ask":"0.87"},{"asset_id":"86520121088881862182423437128238697252500151785248183602134095101149900014256","price":"0.14","size":"274.44","side":"SELL","hash":"b83aee32c8f81e9ec563c33a0b54f1175e99fbea","best_bid":"0.13","best_ask":"0.14"}],"timestamp":"1776808415571","event_type":"price_change"}}
{"capturedAt":1776808415,"payload":{"market":"0x125149c5918fc5f8c6d34682f700a898a1a19ea4f4e2ae68ff4c5794ba657074","price_changes":[{"asset_id":"45936375922793925919605092352922707796689801895417366600539442410775071099958","price":"0.86","size":"293.44","side":"BUY","hash":"a40c89b04fa2e457811de079ede771925cae5222","best_bid":"0.86","best_ask":"0.87"},{"asset_id":"86520121088881862182423437128238697252500151785248183602134095101149900014256","price":"0.14","size":"293.44","side":"SELL","hash":"a4442b4018386f95ec74394c2fc7a14ddc3c658f","best_bid":"0.13","best_ask":"0.14"}],"timestamp":"1776808415572","event_type":"price_change"}}
{"capturedAt":1776808415,"payload":{"market":"0x125149c5918fc5f8c6d34682f700a898a1a19ea4f4e2ae68ff4c5794ba657074","price_changes":[{"asset_id":"45936375922793925919605092352922707796689801895417366600539442410775071099958","price":"0.86","size":"273.44","side":"BUY","hash":"532db7f4cfb203a871133ca7812b84004937f86e","best_bid":"0.86","best_ask":"0.87"},{"asset_id":"86520121088881862182423437128238697252500151785248183602134095101149900014256","price":"0.14","size":"273.44","side":"SELL","hash":"23c382f38119b6f0b63dd09811196aca6b83239f","best_bid":"0.13","best_ask":"0.14"}],"timestamp":"1776808415573","event_type":"price_change"}}
{"capturedAt":1776808415,"payload":{"market":"0x125149c5918fc5f8c6d34682f700a898a1a19ea4f4e2ae68ff4c5794ba657074","price_changes":[{"asset_id":"45936375922793925919605092352922707796689801895417366600539442410775071099958","price":"0.86","size":"252.44","side":"BUY","hash":"87d12b87e9b9e346dc9cd2dacef5d56695a88bc4","best_bid":"0.86","best_ask":"0.87"},{"asset_id":"86520121088881862182423437128238697252500151785248183602134095101149900014256","price":"0.14","size":"252.44","side":"SELL","hash":"6868101a94e5be8522dd2797aea172c42bc209c7","best_bid":"0.13","best_ask":"0.14"}],"timestamp":"1776808415579","event_type":"price_change"}}
{"capturedAt":1776808415,"payload":{"market":"0x125149c5918fc5f8c6d34682f700a898a1a19ea4f4e2ae68ff4c5794ba657074","price_changes":[{"asset_id":"45936375922793925919605092352922707796689801895417366600539442410775071099958","price":"0.86","size":"270.44","side":"BUY","hash":"f8b4f3d55b33b39079178c597031c8f3c5022e2d","best_bid":"0.86","best_ask":"0.87"},{"asset_id":"86520121088881862182423437128238697252500151785248183602134095101149900014256","price":"0.14","size":"270.44","side":"SELL","hash":"96401c5cfc82e17a642674c69e0a565d854d1240","best_bid":"0.13","best_ask":"0.14"}],"timestamp":"1776808415580","event_type":"price_change"}}
{"capturedAt":1776808415,"payload":{"market":"0x125149c5918fc5f8c6d34682f700a898a1a19ea4f4e2ae68ff4c5794ba657074","price_changes":[{"asset_id":"45936375922793925919605092352922707796689801895417366600539442410775071099958","price":"0.86","size":"288.44","side":"BUY","hash":"57cd783e08058b5285901932104ce3a01787b05a","best_bid":"0.86","best_ask":"0.87"},{"asset_id":"86520121088881862182423437128238697252500151785248183602134095101149900014256","price":"0.14","size":"288.44","side":"SELL","hash":"3d6dbb77d6284b43b7ec633bcaa73507a0b918bf","best_bid":"0.13","best_ask":"0.14"}],"timestamp":"1776808415581","event_type":"price_change"}}
{"capturedAt":1776808415,"payload":{"market":"0x125149c5918fc5f8c6d34682f700a898a1a19ea4f4e2ae68ff4c5794ba657074","price_changes":[{"asset_id":"45936375922793925919605092352922707796689801895417366600539442410775071099958","price":"0.86","size":"306.44","side":"BUY","hash":"986fd3965324c146a217ee2c3c1b6a57655c72bb","best_bid":"0.86","best_ask":"0.87"},{"asset_id":"86520121088881862182423437128238697252500151785248183602134095101149900014256","price":"0.14","size":"306.44","side":"SELL","hash":"c759ca15323a77a52d9d71ef674ae80857fa8d2c","best_bid":"0.13","best_ask":"0.14"}],"timestamp":"1776808415584","event_type":"price_change"}}
{"capturedAt":1776808415,"payload":{"market":"0x125149c5918fc5f8c6d34682f700a898a1a19ea4f4e2ae68ff4c5794ba657074","price_changes":[{"asset_id":"45936375922793925919605092352922707796689801895417366600539442410775071099958","price":"0.86","size":"301.21","side":"BUY","hash":"624440871ba61bdab9b39a0fe94b844467d680ad","best_bid":"0.86","best_ask":"0.87"},{"asset_id":"86520121088881862182423437128238697252500151785248183602134095101149900014256","price":"0.14","size":"301.21","side":"SELL","hash":"4368f01a9b94d791d26815a141301ac1b2f5a3dd","best_bid":"0.13","best_ask":"0.14"}],"timestamp":"1776808415585","event_type":"price_change"}}
{"capturedAt":1776808415,"payload":{"market":"0x125149c5918fc5f8c6d34682f700a898a1a19ea4f4e2ae68ff4c5794ba657074","price_changes":[{"asset_id":"45936375922793925919605092352922707796689801895417366600539442410775071099958","price":"0.01","size":"12329.83","side":"BUY","hash":"aef1fce29bcaa695ba45c5d663ad17bffa828372","best_bid":"0.86","best_ask":"0.87"},{"asset_id":"86520121088881862182423437128238697252500151785248183602134095101149900014256","price":"0.99","size":"12329.83","side":"SELL","hash":"b1f486e949673d328a5bb3fe42e00a856fac528f","best_bid":"0.13","best_ask":"0.14"}],"timestamp":"1776808415588","event_type":"price_change"}}
{"capturedAt":1776808415,"payload":{"market":"0x125149c5918fc5f8c6d34682f700a898a1a19ea4f4e2ae68ff4c5794ba657074","price_changes":[{"asset_id":"45936375922793925919605092352922707796689801895417366600539442410775071099958","price":"0.83","size":"347.49","side":"BUY","hash":"ebb88ad81bd1f3c683f7781a857c1c3f3fd3bd3a","best_bid":"0.86","best_ask":"0.87"},{"asset_id":"86520121088881862182423437128238697252500151785248183602134095101149900014256","price":"0.17","size":"347.49","side":"SELL","hash":"fe3b5d205b57ecfb967b2d8c8dd39652d42701b3","best_bid":"0.13","best_ask":"0.14"}],"timestamp":"1776808415589","event_type":"price_change"}}
{"capturedAt":1776808415,"payload":{"market":"0x125149c5918fc5f8c6d34682f700a898a1a19ea4f4e2ae68ff4c5794ba657074","price_changes":[{"asset_id":"45936375922793925919605092352922707796689801895417366600539442410775071099958","price":"0.86","size":"311.21","side":"BUY","hash":"9ee86c70d71d6d20dc7058884a4e5259ae369be8","best_bid":"0.86","best_ask":"0.87"},{"asset_id":"86520121088881862182423437128238697252500151785248183602134095101149900014256","price":"0.14","size":"311.21","side":"SELL","hash":"8b6e0392895645be2d1add7166a0d7920ce4ab8a","best_bid":"0.13","best_ask":"0.14"}],"timestamp":"1776808415593","event_type":"price_change"}}
{"capturedAt":1776808415,"payload":{"market":"0x125149c5918fc5f8c6d34682f700a898a1a19ea4f4e2ae68ff4c5794ba657074","price_changes":[{"asset_id":"45936375922793925919605092352922707796689801895417366600539442410775071099958","price":"0.86","size":"321.21","side":"BUY","hash":"681c8cb1cd35dcfb476ca625a548613b53608527","best_bid":"0.86","best_ask":"0.87"},{"asset_id":"86520121088881862182423437128238697252500151785248183602134095101149900014256","price":"0.14","size":"321.21","side":"SELL","hash":"177e78d19dae8b13e947dc9daa66e1c30b5bbc17","best_bid":"0.13","best_ask":"0.14"}],"timestamp":"1776808415594","event_type":"price_change"}}
{"capturedAt":1776808415,"payload":{"market":"0x125149c5918fc5f8c6d34682f700a898a1a19ea4f4e2ae68ff4c5794ba657074","price_changes":[{"asset_id":"45936375922793925919605092352922707796689801895417366600539442410775071099958","price":"0.86","size":"309.21","side":"BUY","hash":"470f283e4c2ab86cdd3847e76a3e8e4f74b0eea6","best_bid":"0.86","best_ask":"0.87"},{"asset_id":"86520121088881862182423437128238697252500151785248183602134095101149900014256","price":"0.14","size":"309.21","side":"SELL","hash":"adb670f45b69478ddc001b2010d4974d5de30335","best_bid":"0.13","best_ask":"0.14"}],"timestamp":"1776808415599","event_type":"price_change"}}
{"capturedAt":1776808415,"payload":{"market":"0x125149c5918fc5f8c6d34682f700a898a1a19ea4f4e2ae68ff4c5794ba657074","price_changes":[{"asset_id":"45936375922793925919605092352922707796689801895417366600539442410775071099958","price":"0.86","size":"296.21","side":"BUY","hash":"99660e70542e95825b0cc4d8c991d8b338780a4f","best_bid":"0.86","best_ask":"0.87"},{"asset_id":"86520121088881862182423437128238697252500151785248183602134095101149900014256","price":"0.14","size":"296.21","side":"SELL","hash":"40e5c7d7da2855c123305cca023d6a13f286af44","best_bid":"0.13","best_ask":"0.14"}],"timestamp":"1776808415600","event_type":"price_change"}}
{"capturedAt":1776808415,"payload":{"market":"0x125149c5918fc5f8c6d34682f700a898a1a19ea4f4e2ae68ff4c5794ba657074","price_changes":[{"asset_id":"45936375922793925919605092352922707796689801895417366600539442410775071099958","price":"0.01","size":"12334.83","side":"BUY","hash":"41e9d83c1b00af7738562217fc32997f54be4e1f","best_bid":"0.86","best_ask":"0.87"},{"asset_id":"86520121088881862182423437128238697252500151785248183602134095101149900014256","price":"0.99","size":"12334.83","side":"SELL","hash":"79e44896a0f2f421257ad9c6ab0e15fe6e83d7a2","best_bid":"0.13","best_ask":"0.14"}],"timestamp":"1776808415602","event_type":"price_change"}}
{"capturedAt":1776808415,"payload":{"market":"0x125149c5918fc5f8c6d34682f700a898a1a19ea4f4e2ae68ff4c5794ba657074","price_changes":[{"asset_id":"45936375922793925919605092352922707796689801895417366600539442410775071099958","price":"0.86","size":"332.21","side":"BUY","hash":"1f1ea58a423befff05bc065f016893cbff984967","best_bid":"0.86","best_ask":"0.87"},{"asset_id":"86520121088881862182423437128238697252500151785248183602134095101149900014256","price":"0.14","size":"332.21","side":"SELL","hash":"a065dcaf2a4c7d80cbe4eec10170485567d03bc8","best_bid":"0.13","best_ask":"0.14"}],"timestamp":"1776808415602","event_type":"price_change"}}
{"capturedAt":1776808415,"payload":{"market":"0x125149c5918fc5f8c6d34682f700a898a1a19ea4f4e2ae68ff4c5794ba657074","price_changes":[{"asset_id":"45936375922793925919605092352922707796689801895417366600539442410775071099958","price":"0.86","size":"314.21","side":"BUY","hash":"40167b3a8a93e8ba0f67820eb588b47c33a1a931","best_bid":"0.86","best_ask":"0.87"},{"asset_id":"86520121088881862182423437128238697252500151785248183602134095101149900014256","price":"0.14","size":"314.21","side":"SELL","hash":"c413e3e6a5485c2bdb44d1885779199ed78f93e7","best_bid":"0.13","best_ask":"0.14"}],"timestamp":"1776808415601","event_type":"price_change"}}
{"capturedAt":1776808415,"payload":{"market":"0x125149c5918fc5f8c6d34682f700a898a1a19ea4f4e2ae68ff4c5794ba657074","price_changes":[{"asset_id":"86520121088881862182423437128238697252500151785248183602134095101149900014256","price":"0.13","size":"203.3","side":"BUY","hash":"fc92b1478bb80c4cf4b41bf530c2fab477f596bd","best_bid":"0.13","best_ask":"0.14"},{"asset_id":"45936375922793925919605092352922707796689801895417366600539442410775071099958","price":"0.87","size":"203.3","side":"SELL","hash":"bf76ffd7b8d6e77768112f03dbd7dc0a9201c3a4","best_bid":"0.86","best_ask":"0.87"}],"timestamp":"1776808415606","event_type":"price_change"}}
{"capturedAt":1776808415,"payload":{"market":"0x125149c5918fc5f8c6d34682f700a898a1a19ea4f4e2ae68ff4c5794ba657074","asset_id":"45936375922793925919605092352922707796689801895417366600539442410775071099958","bids":[{"price":"0.01","size":"12334.83"},{"price":"0.02","size":"1715.28"},{"price":"0.03","size":"1338.69"},{"price":"0.04","size":"583.84"},{"price":"0.05","size":"1006.34"},{"price":"0.06","size":"392.8"},{"price":"0.07","size":"304.69"},{"price":"0.08","size":"278.9"},{"price":"0.09","size":"225"},{"price":"0.1","size":"282"},{"price":"0.11","size":"217.79"},{"price":"0.12","size":"215.1"},{"price":"0.13","size":"202.8"},{"price":"0.14","size":"200.9"},{"price":"0.15","size":"209.2"},{"price":"0.16","size":"197.8"},{"price":"0.17","size":"202.39"},{"price":"0.18","size":"200.4"},{"price":"0.19","size":"194.4"},{"price":"0.2","size":"193.5"},{"price":"0.21","size":"215.31"},{"price":"0.22","size":"197"},{"price":"0.23","size":"229.34"},{"price":"0.24","size":"195.7"},{"price":"0.25","size":"190.2"},{"price":"0.26","size":"189.7"},{"price":"0.27","size":"194.3"},{"price":"0.28","size":"188.89"},{"price":"0.29","size":"188.5"},{"price":"0.3","size":"206.48"},{"price":"0.31","size":"394.45"},{"price":"0.32","size":"187.5"},{"price":"0.33","size":"193.55"},{"price":"0.34","size":"187"},{"price":"0.35","size":"602.68"},{"price":"0.36","size":"186.6"},{"price":"0.37","size":"191.96"},{"price":"0.38","size":"186.3"},{"price":"0.39","size":"491.36"},{"price":"0.4","size":"226"},{"price":"0.41","size":"203.32"},{"price":"0.42","size":"185.8"},{"price":"0.43","size":"190.8"},{"price":"0.44","size":"190.6"},{"price":"0.45","size":"230.58"},{"price":"0.46","size":"185.5"},{"price":"0.47","size":"245.86"},{"price":"0.48","size":"242.56"},{"price":"0.49","size":"222.4"},{"price":"0.5","size":"378.64"},{"price":"0.51","size":"205.25"},{"price":"0.52","size":"226.77"},{"price":"0.53","size":"136.71"},{"price":"0.54","size":"185.5"},{"price":"0.55","size":"207.66"},{"price":"0.56","size":"196.6"},{"price":"0.57","size":"180.7"},{"price":"0.58","size":"180.8"},{"price":"0.59","size":"180.9"},{"price":"0.6","size":"139"},{"price":"0.61","size":"185.46"},{"price":"0.62","size":"141.3"},{"price":"0.63","size":"131.4"},{"price":"0.64","size":"131.6"},{"price":"0.65","size":"136.8"},{"price":"0.66","size":"342"},{"price":"0.67","size":"232.3"},{"price":"0.68","size":"382.5"},{"price":"0.69","size":"182.8"},{"price":"0.7","size":"244.95"},{"price":"0.71","size":"405.5"},{"price":"0.72","size":"530.89"},{"price":"0.73","size":"217.3"},{"price":"0.74","size":"287.7"},{"price":"0.75","size":"382.29"},{"price":"0.76","size":"148.49"},{"price":"0.77","size":"221.3"},{"price":"0.78","size":"328.98"},{"price":"0.79","size":"219.7"},{"price":"0.8","size":"245.25"},{"price":"0.81","size":"304.9"},{"price":"0.82","size":"319.9"},{"price":"0.83","size":"347.49"},{"price":"0.84","size":"384.37"},{"price":"0.85","size":"437.28"},{"price":"0.86","size":"332.21"}],"asks":[{"price":"0.99","size":"12907.69"},{"price":"0.98","size":"1746.16"},{"price":"0.97","size":"1613.83"},{"price":"0.96","size":"938.3"},{"price":"0.95","size":"790.63"},{"price":"0.94","size":"395.8"},{"price":"0.93","size":"685.3"},{"price":"0.92","size":"656.9"},{"price":"0.91","size":"267.44"},{"price":"0.9","size":"812.8"},{"price":"0.89","size":"391.5"},{"price":"0.88","size":"308.5"},{"price":"0.87","size":"203.3"}],"hash":"bf76ffd7b8d6e77768112f03dbd7dc0a9201c3a4","timestamp":"1776808415606","event_type":"book"}}
{"capturedAt":1776808415,"payload":{"market":"0x125149c5918fc5f8c6d34682f700a898a1a19ea4f4e2ae68ff4c5794ba657074","price_changes":[{"asset_id":"45936375922793925919605092352922707796689801895417366600539442410775071099958","price":"0.01","size":"12329.83","side":"BUY","hash":"2bb2c7a4bc513ecc93ac6aabfcd92c24697d3d66","best_bid":"0.86","best_ask":"0.87"},{"asset_id":"86520121088881862182423437128238697252500151785248183602134095101149900014256","price":"0.99","size":"12329.83","side":"SELL","hash":"8ef0170429201419f6daabcbdde62d3efab3e385","best_bid":"0.13","best_ask":"0.14"}],"timestamp":"1776808415607","event_type":"price_change"}}
{"capturedAt":1776808415,"payload":{"market":"0x125149c5918fc5f8c6d34682f700a898a1a19ea4f4e2ae68ff4c5794ba657074","asset_id":"86520121088881862182423437128238697252500151785248183602134095101149900014256","best_bid":"0.13","best_ask":"0.14","spread":"0.01","timestamp":"1776808415607","event_type":"best_bid_ask"}}
{"capturedAt":1776808415,"payload":{"market":"0x125149c5918fc5f8c6d34682f700a898a1a19ea4f4e2ae68ff4c5794ba657074","asset_id":"86520121088881862182423437128238697252500151785248183602134095101149900014256","bids":[{"price":"0.01","size":"12907.69"},{"price":"0.02","size":"1746.16"},{"price":"0.03","size":"1613.83"},{"price":"0.04","size":"938.3"},{"price":"0.05","size":"790.63"},{"price":"0.06","size":"395.8"},{"price":"0.07","size":"685.3"},{"price":"0.08","size":"656.9"},{"price":"0.09","size":"267.44"},{"price":"0.1","size":"812.8"},{"price":"0.11","size":"391.5"},{"price":"0.12","size":"308.5"},{"price":"0.13","size":"203.3"}],"asks":[{"price":"0.99","size":"12334.83"},{"price":"0.98","size":"1715.28"},{"price":"0.97","size":"1338.69"},{"price":"0.96","size":"583.84"},{"price":"0.95","size":"1006.34"},{"price":"0.94","size":"392.8"},{"price":"0.93","size":"304.69"},{"price":"0.92","size":"278.9"},{"price":"0.91","size":"225"},{"price":"0.9","size":"282"},{"price":"0.89","size":"217.79"},{"price":"0.88","size":"215.1"},{"price":"0.87","size":"202.8"},{"price":"0.86","size":"200.9"},{"price":"0.85","size":"209.2"},{"price":"0.84","size":"197.8"},{"price":"0.83","size":"202.39"},{"price":"0.82","size":"200.4"},{"price":"0.81","size":"194.4"},{"price":"0.8","size":"193.5"},{"price":"0.79","size":"215.31"},{"price":"0.78","size":"197"},{"price":"0.77","size":"229.34"},{"price":"0.76","size":"195.7"},{"price":"0.75","size":"190.2"},{"price":"0.74","size":"189.7"},{"price":"0.73","size":"194.3"},{"price":"0.72","size":"188.89"},{"price":"0.71","size":"188.5"},{"price":"0.7","size":"206.48"},{"price":"0.69","size":"394.45"},{"price":"0.68","size":"187.5"},{"price":"0.67","size":"193.55"},{"price":"0.66","size":"187"},{"price":"0.65","size":"602.68"},{"price":"0.64","size":"186.6"},{"price":"0.63","size":"191.96"},{"price":"0.62","size":"186.3"},{"price":"0.61","size":"491.36"},{"price":"0.6","size":"226"},{"price":"0.59","size":"203.32"},{"price":"0.58","size":"185.8"},{"price":"0.57","size":"190.8"},{"price":"0.56","size":"190.6"},{"price":"0.55","size":"230.58"},{"price":"0.54","size":"185.5"},{"price":"0.53","size":"245.86"},{"price":"0.52","size":"242.56"},{"price":"0.51","size":"222.4"},{"price":"0.5","size":"378.64"},{"price":"0.49","size":"205.25"},{"price":"0.48","size":"226.77"},{"price":"0.47","size":"136.71"},{"price":"0.46","size":"185.5"},{"price":"0.45","size":"207.66"},{"price":"0.44","size":"196.6"},{"price":"0.43","size":"180.7"},{"price":"0.42","size":"180.8"},{"price":"0.41","size":"180.9"},{"price":"0.4","size":"139"},{"price":"0.39","size":"185.46"},{"price":"0.38","size":"141.3"},{"price":"0.37","size":"131.4"},{"price":"0.36","size":"131.6"},{"price":"0.35","size":"136.8"},{"price":"0.34","size":"342"},{"price":"0.33","size":"232.3"},{"price":"0.32","size":"382.5"},{"price":"0.31","size":"182.8"},{"price":"0.3","size":"244.95"},{"price":"0.29","size":"405.5"},{"price":"0.28","size":"530.89"},{"price":"0.27","size":"217.3"},{"price":"0.26","size":"287.7"},{"price":"0.25","size":"382.29"},{"price":"0.24","size":"148.49"},{"price":"0.23","size":"221.3"},{"price":"0.22","size":"328.98"},{"price":"0.21","size":"219.7"},{"price":"0.2","size":"245.25"},{"price":"0.19","size":"304.9"},{"price":"0.18","size":"319.9"},{"price":"0.17","size":"347.49"},{"price":"0.16","size":"384.37"},{"price":"0.15","size":"437.28"},{"price":"0.14","size":"332.21"}],"hash":"fc92b1478bb80c4cf4b41bf530c2fab477f596bd","timestamp":"1776808415606","event_type":"book"}}
{"capturedAt":1776808415,"payload":{"market":"0x125149c5918fc5f8c6d34682f700a898a1a19ea4f4e2ae68ff4c5794ba657074","asset_id":"45936375922793925919605092352922707796689801895417366600539442410775071099958","best_bid":"0.86","best_ask":"0.87","spread":"0.01","timestamp":"1776808415607","event_type":"best_bid_ask"}}
{"capturedAt":1776808415,"payload":{"market":"0x125149c5918fc5f8c6d34682f700a898a1a19ea4f4e2ae68ff4c5794ba657074","price_changes":[{"asset_id":"45936375922793925919605092352922707796689801895417366600539442410775071099958","price":"0.01","size":"12324.83","side":"BUY","hash":"d8f91facbd2ee4f0a913c3196f616795509a078c","best_bid":"0.86","best_ask":"0.87"},{"asset_id":"86520121088881862182423437128238697252500151785248183602134095101149900014256","price":"0.99","size":"12324.83","side":"SELL","hash":"73dd1f12c55106046656fe669be48f2c3ae7d127","best_bid":"0.13","best_ask":"0.14"}],"timestamp":"1776808415619","event_type":"price_change"}}
{"capturedAt":1776808415,"payload":{"market":"0x125149c5918fc5f8c6d34682f700a898a1a19ea4f4e2ae68ff4c5794ba657074","price_changes":[{"asset_id":"45936375922793925919605092352922707796689801895417366600539442410775071099958","price":"0.86","size":"337.27","side":"BUY","hash":"9b3ebba618d411f17c5a9ff3367b3336a8a0f211","best_bid":"0.86","best_ask":"0.87"},{"asset_id":"86520121088881862182423437128238697252500151785248183602134095101149900014256","price":"0.14","size":"337.27","side":"SELL","hash":"83551777e6cd24086f66349df06a36f77e14671a","best_bid":"0.13","best_ask":"0.14"}],"timestamp":"1776808415621","event_type":"price_change"}}
{"capturedAt":1776808415,"payload":{"market":"0x125149c5918fc5f8c6d34682f700a898a1a19ea4f4e2ae68ff4c5794ba657074","price_changes":[{"asset_id":"45936375922793925919605092352922707796689801895417366600539442410775071099958","price":"0.86","size":"361.27","side":"BUY","hash":"3d2ce05aba6a79ed1f6d746a3aa6d9f32b9024e0","best_bid":"0.86","best_ask":"0.87"},{"asset_id":"86520121088881862182423437128238697252500151785248183602134095101149900014256","price":"0.14","size":"361.27","side":"SELL","hash":"03466a68a540029573a640ba9e92793fa01d163d","best_bid":"0.13","best_ask":"0.14"}],"timestamp":"1776808415624","event_type":"price_change"}}
{"capturedAt":1776808415,"payload":{"market":"0x125149c5918fc5f8c6d34682f700a898a1a19ea4f4e2ae68ff4c5794ba657074","price_changes":[{"asset_id":"45936375922793925919605092352922707796689801895417366600539442410775071099958","price":"0.86","size":"351.27","side":"BUY","hash":"c2953cf0441066588442e91602f0742684643eeb","best_bid":"0.86","best_ask":"0.87"},{"asset_id":"86520121088881862182423437128238697252500151785248183602134095101149900014256","price":"0.14","size":"351.27","side":"SELL","hash":"c3bf8898104379187c23b91a3de0beddb0739298","best_bid":"0.13","best_ask":"0.14"}],"timestamp":"1776808415629","event_type":"price_change"}}
{"capturedAt":1776808415,"payload":{"market":"0x125149c5918fc5f8c6d34682f700a898a1a19ea4f4e2ae68ff4c5794ba657074","price_changes":[{"asset_id":"45936375922793925919605092352922707796689801895417366600539442410775071099958","price":"0.86","size":"349.27","side":"BUY","hash":"eeeff5ae84bfa8ecb75069c06c10287af91ba4dd","best_bid":"0.86","best_ask":"0.87"},{"asset_id":"86520121088881862182423437128238697252500151785248183602134095101149900014256","price":"0.14","size":"349.27","side":"SELL","hash":"d0c731b3cc6b45aba82808495edd0326cc12bbcd","best_bid":"0.13","best_ask":"0.14"}],"timestamp":"1776808415623","event_type":"price_change"}}
{"capturedAt":1776808415,"payload":{"market":"0x125149c5918fc5f8c6d34682f700a898a1a19ea4f4e2ae68ff4c5794ba657074","price_changes":[{"asset_id":"45936375922793925919605092352922707796689801895417366600539442410775071099958","price":"0.86","size":"331.27","side":"BUY","hash":"8a8799635e4897a52a4b2ea72d38e570736ffb9a","best_bid":"0.86","best_ask":"0.87"},{"asset_id":"86520121088881862182423437128238697252500151785248183602134095101149900014256","price":"0.14","size":"331.27","side":"SELL","hash":"486cc24017a10a142daea16714ea5c77fc965129","best_bid":"0.13","best_ask":"0.14"}],"timestamp":"1776808415631","event_type":"price_change"}}
{"capturedAt":1776808415,"payload":{"market":"0x125149c5918fc5f8c6d34682f700a898a1a19ea4f4e2ae68ff4c5794ba657074","price_changes":[{"asset_id":"45936375922793925919605092352922707796689801895417366600539442410775071099958","price":"0.82","size":"325.78","side":"BUY","hash":"056ac7bf2865c915a1bae7a11e26a22a433c2eda","best_bid":"0.86","best_ask":"0.87"},{"asset_id":"86520121088881862182423437128238697252500151785248183602134095101149900014256","price":"0.18","size":"325.78","side":"SELL","hash":"0b4cac0384275e2c46b62b5f10c92c1297240717","best_bid":"0.13","best_ask":"0.14"}],"timestamp":"1776808415631","event_type":"price_change"}}
{"capturedAt":1776808415,"payload":{"market":"0x125149c5918fc5f8c6d34682f700a898a1a19ea4f4e2ae68ff4c5794ba657074","asset_id":"45936375922793925919605092352922707796689801895417366600539442410775071099958","price":"0.87","size":"7.241376","fee_rate_bps":"1000","side":"BUY","timestamp":"1776808415628","event_type":"last_trade_price","transaction_hash":"0x04ebbd56df79bf310635d81293dd6e00782f6cedf48536eab864ab5013085d89"}}
{"capturedAt":1776808415,"payload":{"market":"0x125149c5918fc5f8c6d34682f700a898a1a19ea4f4e2ae68ff4c5794ba657074","price_changes":[{"asset_id":"45936375922793925919605092352922707796689801895417366600539442410775071099958","price":"0.86","size":"310.27","side":"BUY","hash":"c68cf354d0c79513bfab480bd32218c1040cc5a7","best_bid":"0.86","best_ask":"0.87"},{"asset_id":"86520121088881862182423437128238697252500151785248183602134095101149900014256","price":"0.14","size":"310.27","side":"SELL","hash":"3e7f3c6ac26cb9d6c5520138f7f216a734d57719","best_bid":"0.13","best_ask":"0.14"}],"timestamp":"1776808415633","event_type":"price_change"}}
{"capturedAt":1776808415,"payload":{"market":"0x125149c5918fc5f8c6d34682f700a898a1a19ea4f4e2ae68ff4c5794ba657074","price_changes":[{"asset_id":"45936375922793925919605092352922707796689801895417366600539442410775071099958","price":"0.86","size":"271.27","side":"BUY","hash":"37fd9fa3e6057a872bb4e46366c789357881010c","best_bid":"0.86","best_ask":"0.87"},{"asset_id":"86520121088881862182423437128238697252500151785248183602134095101149900014256","price":"0.14","size":"271.27","side":"SELL","hash":"43c4ee48a69a619017bef61f24479d03a4c8bce1","best_bid":"0.13","best_ask":"0.14"}],"timestamp":"1776808415642","event_type":"price_change"}}
{"capturedAt":1776808415,"payload":{"market":"0x125149c5918fc5f8c6d34682f700a898a1a19ea4f4e2ae68ff4c5794ba657074","price_changes":[{"asset_id":"45936375922793925919605092352922707796689801895417366600539442410775071099958","price":"0.01","size":"12334.83","side":"BUY","hash":"f4f20923bedcf98fdb1af9b2ed6818bfca32594b","best_bid":"0.86","best_ask":"0.87"},{"asset_id":"86520121088881862182423437128238697252500151785248183602134095101149900014256","price":"0.99","size":"12334.83","side":"SELL","hash":"3e7a87fa552f5c0a513b271b66793a71c74f0a7b","best_bid":"0.13","best_ask":"0.14"}],"timestamp":"1776808415648","event_type":"price_change"}}
{"capturedAt":1776808415,"payload":{"market":"0x125149c5918fc5f8c6d34682f700a898a1a19ea4f4e2ae68ff4c5794ba657074","price_changes":[{"asset_id":"45936375922793925919605092352922707796689801895417366600539442410775071099958","price":"0.01","size":"12329.83","side":"BUY","hash":"ab9b69e728f739d55e3b7503743145965e368b7b","best_bid":"0.86","best_ask":"0.87"},{"asset_id":"86520121088881862182423437128238697252500151785248183602134095101149900014256","price":"0.99","size":"12329.83","side":"SELL","hash":"fb4c93346df8d1b5de212b73d73db176dca617b8","best_bid":"0.13","best_ask":"0.14"}],"timestamp":"1776808415637","event_type":"price_change"}}
{"capturedAt":1776808415,"payload":{"market":"0x125149c5918fc5f8c6d34682f700a898a1a19ea4f4e2ae68ff4c5794ba657074","price_changes":[{"asset_id":"45936375922793925919605092352922707796689801895417366600539442410775071099958","price":"0.86","size":"253.27","side":"BUY","hash":"531e4518feca20085b91bc6a6ed740c5cbed2ed2","best_bid":"0.86","best_ask":"0.87"},{"asset_id":"86520121088881862182423437128238697252500151785248183602134095101149900014256","price":"0.14","size":"253.27","side":"SELL","hash":"5bdfacc437f8ff1ac32179e1afc44d402d2c7535","best_bid":"0.13","best_ask":"0.14"}],"timestamp":"1776808415650","event_type":"price_change"}}
{"capturedAt":1776808415,"payload":{"market":"0x125149c5918fc5f8c6d34682f700a898a1a19ea4f4e2ae68ff4c5794ba657074","price_changes":[{"asset_id":"45936375922793925919605092352922707796689801895417366600539442410775071099958","price":"0.86","size":"291.27","side":"BUY","hash":"e87dfe56b9ac829f16accd54741c3a357c6b7338","best_bid":"0.86","best_ask":"0.87"},{"asset_id":"86520121088881862182423437128238697252500151785248183602134095101149900014256","price":"0.14","size":"291.27","side":"SELL","hash":"c45a95bdd77feab783c59e239d1dc2fe87d8a61d","best_bid":"0.13","best_ask":"0.14"}],"timestamp":"1776808415641","event_type":"price_change"}}
{"capturedAt":1776808415,"payload":{"market":"0x125149c5918fc5f8c6d34682f700a898a1a19ea4f4e2ae68ff4c5794ba657074","price_changes":[{"asset_id":"45936375922793925919605092352922707796689801895417366600539442410775071099958","price":"0.86","size":"235.27","side":"BUY","hash":"83c1e4603cff2b4d438f05cd950a524654828707","best_bid":"0.86","best_ask":"0.87"},{"asset_id":"86520121088881862182423437128238697252500151785248183602134095101149900014256","price":"0.14","size":"235.27","side":"SELL","hash":"a0189e62a1b33aea526289f2aca6254fae807fb2","best_bid":"0.13","best_ask":"0.14"}],"timestamp":"1776808415651","event_type":"price_change"}}
{"capturedAt":1776808415,"payload":{"market":"0x125149c5918fc5f8c6d34682f700a898a1a19ea4f4e2ae68ff4c5794ba657074","price_changes":[{"asset_id":"45936375922793925919605092352922707796689801895417366600539442410775071099958","price":"0.86","size":"225.27","side":"BUY","hash":"63475cffb1777c2e5313026c6a112adf606f4a15","best_bid":"0.86","best_ask":"0.87"},{"asset_id":"86520121088881862182423437128238697252500151785248183602134095101149900014256","price":"0.14","size":"225.27","side":"SELL","hash":"691e67ce07136addb29bac11b36e2afe3d7bee71","best_bid":"0.13","best_ask":"0.14"}],"timestamp":"1776808415652","event_type":"price_change"}}
{"capturedAt":1776808415,"payload":{"market":"0x125149c5918fc5f8c6d34682f700a898a1a19ea4f4e2ae68ff4c5794ba657074","price_changes":[{"asset_id":"45936375922793925919605092352922707796689801895417366600539442410775071099958","price":"0.86","size":"229.27","side":"BUY","hash":"72d69030b7eee1a70dd34bd86da284495d3e3dc2","best_bid":"0.86","best_ask":"0.87"},{"asset_id":"86520121088881862182423437128238697252500151785248183602134095101149900014256","price":"0.14","size":"229.27","side":"SELL","hash":"061bf4f8a41d128d1834179b1f0eaa7582fe8064","best_bid":"0.13","best_ask":"0.14"}],"timestamp":"1776808415658","event_type":"price_change"}}
{"capturedAt":1776808415,"payload":{"market":"0x125149c5918fc5f8c6d34682f700a898a1a19ea4f4e2ae68ff4c5794ba657074","price_changes":[{"asset_id":"45936375922793925919605092352922707796689801895417366600539442410775071099958","price":"0.86","size":"239.27","side":"BUY","hash":"533fb2b0c1f66409f4a6d2818f3b3caece93769e","best_bid":"0.86","best_ask":"0.87"},{"asset_id":"86520121088881862182423437128238697252500151785248183602134095101149900014256","price":"0.14","size":"239.27","side":"SELL","hash":"ad154a43fd7f2164ab6733ea3133b2ea0d5f5c64","best_bid":"0.13","best_ask":"0.14"}],"timestamp":"1776808415662","event_type":"price_change"}}
{"capturedAt":1776808415,"payload":{"market":"0x125149c5918fc5f8c6d34682f700a898a1a19ea4f4e2ae68ff4c5794ba657074","price_changes":[{"asset_id":"45936375922793925919605092352922707796689801895417366600539442410775071099958","price":"0.01","size":"12329.83","side":"BUY","hash":"0a3006822a4802dcdb8b214dc7c13b98339c6fb0","best_bid":"0.86","best_ask":"0.87"},{"asset_id":"86520121088881862182423437128238697252500151785248183602134095101149900014256","price":"0.99","size":"12329.83","side":"SELL","hash":"da3c6fbdce8f5f2687d93b015850663d4a188f88","best_bid":"0.13","best_ask":"0.14"}],"timestamp":"1776808415656","event_type":"price_change"}}
{"capturedAt":1776808415,"payload":{"market":"0x125149c5918fc5f8c6d34682f700a898a1a19ea4f4e2ae68ff4c5794ba657074","price_changes":[{"asset_id":"45936375922793925919605092352922707796689801895417366600539442410775071099958","price":"0.86","size":"259.27","side":"BUY","hash":"8d4d4304fef2fe33808da0fdd0aadd655c799b4b","best_bid":"0.86","best_ask":"0.87"},{"asset_id":"86520121088881862182423437128238697252500151785248183602134095101149900014256","price":"0.14","size":"259.27","side":"SELL","hash":"0ca2b53ce66a98404086e8c0235947c1bdded3a5","best_bid":"0.13","best_ask":"0.14"}],"timestamp":"1776808415663","event_type":"price_change"}}
{"capturedAt":1776808415,"payload":{"market":"0x125149c5918fc5f8c6d34682f700a898a1a19ea4f4e2ae68ff4c5794ba657074","asset_id":"86520121088881862182423437128238697252500151785248183602134095101149900014256","best_bid":"0.13","best_ask":"0.14","spread":"0.01","timestamp":"1776808415668","event_type":"best_bid_ask"}}
{"capturedAt":1776808415,"payload":{"market":"0x125149c5918fc5f8c6d34682f700a898a1a19ea4f4e2ae68ff4c5794ba657074","price_changes":[{"asset_id":"45936375922793925919605092352922707796689801895417366600539442410775071099958","price":"0.86","size":"207.27","side":"BUY","hash":"26086f6b58d9f6200c1e1c6eff89b27dd74f7b62","best_bid":"0.86","best_ask":"0.87"},{"asset_id":"86520121088881862182423437128238697252500151785248183602134095101149900014256","price":"0.14","size":"207.27","side":"SELL","hash":"631be476e63de5804b51cd6d68f08f89fde64e06","best_bid":"0.13","best_ask":"0.14"}],"timestamp":"1776808415654","event_type":"price_change"}}
{"capturedAt":1776808415,"payload":{"market":"0x125149c5918fc5f8c6d34682f700a898a1a19ea4f4e2ae68ff4c5794ba657074","asset_id":"45936375922793925919605092352922707796689801895417366600539442410775071099958","best_bid":"0.86","best_ask":"0.87","spread":"0.01","timestamp":"1776808415668","event_type":"best_bid_ask"}}
{"capturedAt":1776808415,"payload":{"market":"0x125149c5918fc5f8c6d34682f700a898a1a19ea4f4e2ae68ff4c5794ba657074","price_changes":[{"asset_id":"45936375922793925919605092352922707796689801895417366600539442410775071099958","price":"0.87","size":"198.74","side":"SELL","hash":"5d0e84aa6798e6ae6be6e5d15fd8ca3ad2f6b558","best_bid":"0.86","best_ask":"0.87"},{"asset_id":"86520121088881862182423437128238697252500151785248183602134095101149900014256","price":"0.13","size":"198.74","side":"BUY","hash":"9ac6b2ed50f984e3a1860eb849b3a209afe7b20d","best_bid":"0.13","best_ask":"0.14"}],"timestamp":"1776808415667","event_type":"price_change"}}
