{"capturedAt":1776808414,"payload":{"market":"0x125149c5918fc5f8c6d34682f700a898a1a19ea4f4e2ae68ff4c5794ba657074","price_changes":[{"asset_id":"45936375922793925919605092352922707796689801895417366600539442410775071099958","price":"0.86","size":"362.17","side":"BUY","hash":"425af2848c4f6462b5d2954448419abc0abac9ac","best_bid":"0.86","best_ask":"0.87"},{"asset_id":"86520121088881862182423437128238697252500151785248183602134095101149900014256","price":"0.14","size":"362.17","side":"SELL","hash":"a1e787af723e1ed926a99bf9c1676cf18167c829","best_bid":"0.13","best_ask":"0.14"}],"timestamp":"1776808414710","event_type":"price_change"}}
{"capturedAt":1776808414,"payload":{"market":"0x125149c5918fc5f8c6d34682f700a898a1a19ea4f4e2ae68ff4c5794ba657074","price_changes":[{"asset_id":"45936375922793925919605092352922707796689801895417366600539442410775071099958","price":"0.01","size":"12329.83","side":"BUY","hash":"c4849e310777ed6f292b51a4e5ca5a63e185650f","best_bid":"0.86","best_ask":"0.87"},{"asset_id":"86520121088881862182423437128238697252500151785248183602134095101149900014256","price":"0.99","size":"12329.83","side":"SELL","hash":"e2c3a991c11c4d513f285d0f3d58952b00687d5e","best_bid":"0.13","best_ask":"0.14"}],"timestamp":"1776808414713","event_type":"price_change"}}
{"capturedAt":1776808414,"payload":{"market":"0x125149c5918fc5f8c6d34682f700a898a1a19ea4f4e2ae68ff4c5794ba657074","price_changes":[{"asset_id":"45936375922793925919605092352922707796689801895417366600539442410775071099958","price":"0.01","size":"12334.83","side":"BUY","hash":"1e3876a0fbf9402afd9001ead127fad8ead4399f","best_bid":"0.86","best_ask":"0.87"},{"asset_id":"86520121088881862182423437128238697252500151785248183602134095101149900014256","price":"0.99","size":"12334.83","side":"SELL","hash":"70bdff6f08ee154bc2686f5007002f58a5b14741","best_bid":"0.13","best_ask":"0.14"}],"timestamp":"1776808414725","event_type":"price_change"}}
{"capturedAt":1776808414,"payload":{"market":"0x125149c5918fc5f8c6d34682f700a898a1a19ea4f4e2ae68ff4c5794ba657074","asset_id":"86520121088881862182423437128238697252500151785248183602134095101149900014256","timestamp":"1776808414710","hash":"a1e787af723e1ed926a99bf9c1676cf18167c829","bids":[{"price":"0.01","size":"12902.69"},{"price":"0.02","size":"1746.16"},{"price":"0.03","size":"1413.83"},{"price":"0.04","size":"932.3"},{"price":"0.05","size":"796.63"},{"price":"0.06","size":"395.8"},{"price":"0.07","size":"682.3"},{"price":"0.08","size":"661.9"},{"price":"0.09","size":"267.44"},{"price":"0.1","size":"793.5"},{"price":"0.11","size":"339"},{"price":"0.12","size":"301"},{"price":"0.13","size":"258.35"}],"asks":[{"price":"0.99","size":"12324.83"},{"price":"0.98","size":"1715.28"},{"price":"0.97","size":"1338.69"},{"price":"0.96","size":"583.84"},{"price":"0.95","size":"1006.34"},{"price":"0.94","size":"392.8"},{"price":"0.93","size":"304.69"},{"price":"0.92","size":"278.9"},{"price":"0.91","size":"225"},{"price":"0.9","size":"282"},{"price":"0.89","size":"217.79"},{"price":"0.88","size":"215.1"},{"price":"0.87","size":"202.8"},{"price":"0.86","size":"200.9"},{"price":"0.85","size":"209.2"},{"price":"0.84","size":"197.8"},{"price":"0.83","size":"202.39"},{"price":"0.82","size":"200.4"},{"price":"0.81","size":"194.4"},{"price":"0.8","size":"193.5"},{"price":"0.79","size":"215.31"},{"price":"0.78","size":"197"},{"price":"0.77","size":"229.34"},{"price":"0.76","size":"195.7"},{"price":"0.75","size":"190.2"},{"price":"0.74","size":"189.7"},{"price":"0.73","size":"194.3"},{"price":"0.72","size":"188.89"},{"price":"0.71","size":"188.5"},{"price":"0.7","size":"206.48"},{"price":"0.69","size":"394.45"},{"price":"0.68","size":"187.5"},{"price":"0.67","size":"193.55"},{"price":"0.66","size":"187"},{"price":"0.65","size":"602.68"},{"price":"0.64","size":"186.6"},{"price":"0.63","size":"191.96"},{"price":"0.62","size":"186.3"},{"price":"0.61","size":"491.36"},{"price":"0.6","size":"226"},{"price":"0.59","size":"203.32"},{"price":"0.58","size":"185.8"},{"price":"0.57","size":"190.8"},{"price":"0.56","size":"190.6"},{"price":"0.55","size":"230.58"},{"price":"0.54","size":"224.63"},{"price":"0.53","size":"207.56"},{"price":"0.52","size":"242.56"},{"price":"0.51","size":"227.4"},{"price":"0.5","size":"378.64"},{"price":"0.49","size":"205.25"},{"price":"0.48","size":"226.77"},{"price":"0.47","size":"136.71"},{"price":"0.46","size":"185.5"},{"price":"0.45","size":"213.66"},{"price":"0.44","size":"190.6"},{"price":"0.43","size":"180.7"},{"price":"0.42","size":"180.8"},{"price":"0.41","size":"130.9"},{"price":"0.4","size":"139"},{"price":"0.39","size":"185.46"},{"price":"0.38","size":"141.3"},{"price":"0.37","size":"131.4"},{"price":"0.36","size":"131.6"},{"price":"0.35","size":"136.8"},{"price":"0.34","size":"342"},{"price":"0.33","size":"232.3"},{"price":"0.32","size":"382.5"},{"price":"0.31","size":"182.8"},{"price":"0.3","size":"244.95"},{"price":"0.29","size":"405.5"},{"price":"0.28","size":"530.89"},{"price":"0.27","size":"217.3"},{"price":"0.26","size":"287.7"},{"price":"0.25","size":"382.29"},{"price":"0.24","size":"148.49"},{"price":"0.23","size":"221.3"},{"price":"0.22","size":"323.98"},{"price":"0.21","size":"219.7"},{"price":"0.2","size":"245.25"},{"price":"0.19","size":"304.9"},{"price":"0.18","size":"325.78"},{"price":"0.17","size":"353.3"},{"price":"0.16","size":"384.37"},{"price":"0.15","size":"419.78"},{"price":"0.14","size":"362.17"}],"tick_size":"0.01","event_type":"book","last_trade_price":"0.130"}}
{"capturedAt":1776808414,"payload":{"market":"0x125149c5918fc5f8c6d34682f700a898a1a19ea4f4e2ae68ff4c5794ba657074","price_changes":[{"asset_id":"45936375922793925919605092352922707796689801895417366600539442410775071099958","price":"0.86","size":"347.17","side":"BUY","hash":"51888a43806d5e28dcb499a4da6543b88ce93a8a","best_bid":"0.86","best_ask":"0.87"},{"asset_id":"86520121088881862182423437128238697252500151785248183602134095101149900014256","price":"0.14","size":"347.17","side":"SELL","hash":"4a1ff3a025b6e0d63574c8296df3e227d65ed498","best_bid":"0.13","best_ask":"0.14"}],"timestamp":"1776808414723","event_type":"price_change"}}
{"capturedAt":1776808414,"payload":{"market":"0x125149c5918fc5f8c6d34682f700a898a1a19ea4f4e2ae68ff4c5794ba657074","price_changes":[{"asset_id":"45936375922793925919605092352922707796689801895417366600539442410775071099958","price":"0.86","size":"372.17","side":"BUY","hash":"c5a84b65424b0241de870f3599d5f7840ec613b8","best_bid":"0.86","best_ask":"0.87"},{"asset_id":"86520121088881862182423437128238697252500151785248183602134095101149900014256","price":"0.14","size":"372.17","side":"SELL","hash":"08c92b8d56dfe895b50fcc01a1eeb3d52747f4f2","best_bid":"0.13","best_ask":"0.14"}],"timestamp":"1776808414717","event_type":"price_change"}}
{"capturedAt":1776808414,"payload":{"market":"0xdab1ff110d9d2439c5bd75c4f503ae7300457a35b124ce0c7260ec86dcc688c8","asset_id":"13917627517502768201235213826866970628416806758650647861097354638225151676696","timestamp":"1776808411018","hash":"f8f6fb29637b209cea4e518ba2820d86ec91db04","bids":[{"price":"0.01","size":"15345.95"},{"price":"0.02","size":"16995.76"},{"price":"0.03","size":"37760.75"},{"price":"0.04","size":"10176"},{"price":"0.05","size":"7289"},{"price":"0.06","size":"4896"},{"price":"0.07","size":"3307"},{"price":"0.08","size":"2613"},{"price":"0.09","size":"3629.9"},{"price":"0.1","size":"8581"},{"price":"0.11","size":"1606"},{"price":"0.12","size":"71.67"},{"price":"0.13","size":"1278"},{"price":"0.14","size":"130"},{"price":"0.15","size":"5993.01"},{"price":"0.16","size":"705.64"},{"price":"0.17","size":"1009"},{"price":"0.18","size":"123.56"},{"price":"0.19","size":"85.07"},{"price":"0.2","size":"561.25"},{"price":"0.21","size":"1965.62"},{"price":"0.22","size":"587.39"},{"price":"0.23","size":"118"},{"price":"0.24","size":"974.15"},{"price":"0.25","size":"1322"},{"price":"0.26","size":"1034.74"},{"price":"0.27","size":"1343"},{"price":"0.28","size":"703.68"},{"price":"0.29","size":"511.5"},{"price":"0.3","size":"1330.69"},{"price":"0.31","size":"1631.88"},{"price":"0.32","size":"692.12"},{"price":"0.33","size":"1179.7"},{"price":"0.34","size":"626.29"},{"price":"0.35","size":"1326.88"},{"price":"0.36","size":"499.44"},{"price":"0.37","size":"568.31"},{"price":"0.38","size":"297"},{"price":"0.39","size":"199.26"},{"price":"0.4","size":"280.25"},{"price":"0.41","size":"280.12"},{"price":"0.42","size":"474.86"},{"price":"0.43","size":"318.1"},{"price":"0.44","size":"472.25"},{"price":"0.45","size":"538.08"},{"price":"0.46","size":"1593.57"},{"price":"0.47","size":"1227.29"},{"price":"0.48","size":"495.33"},{"price":"0.49","size":"217"},{"price":"0.5","size":"1451.51"}],"asks":[{"price":"0.99","size":"15338.75"},{"price":"0.98","size":"16995.79"},{"price":"0.97","size":"37932.42"},{"price":"0.96","size":"10157"},{"price":"0.95","size":"7294"},{"price":"0.94","size":"4896"},{"price":"0.93","size":"3307"},{"price":"0.92","size":"2613"},{"price":"0.91","size":"3674.34"},{"price":"0.9","size":"8581"},{"price":"0.89","size":"1606"},{"price":"0.88","size":"113.34"},{"price":"0.87","size":"1278"},{"price":"0.86","size":"130"},{"price":"0.85","size":"6000.51"},{"price":"0.84","size":"768.14"},{"price":"0.83","size":"1016.5"},{"price":"0.82","size":"123.56"},{"price":"0.81","size":"35.07"},{"price":"0.8","size":"561.25"},{"price":"0.79","size":"1965.62"},{"price":"0.78","size":"564.66"},{"price":"0.77","size":"118"},{"price":"0.76","size":"974.15"},{"price":"0.75","size":"1502"},{"price":"0.74","size":"1295.5"},{"price":"0.73","size":"1523"},{"price":"0.72","size":"892.53"},{"price":"0.71","size":"691.5"},{"price":"0.7","size":"1494.01"},{"price":"0.69","size":"1883.66"},{"price":"0.68","size":"872.12"},{"price":"0.67","size":"1359.7"},{"price":"0.66","size":"626.29"},{"price":"0.65","size":"1326.88"},{"price":"0.64","size":"499.44"},{"price":"0.63","size":"527.77"},{"price":"0.62","size":"297"},{"price":"0.61","size":"199.26"},{"price":"0.6","size":"242.75"},{"price":"0.59","size":"400.12"},{"price":"0.58","size":"594.86"},{"price":"0.57","size":"323.1"},{"price":"0.56","size":"526.87"},{"price":"0.55","size":"650.08"},{"price":"0.54","size":"1460.97"},{"price":"0.53","size":"1054.38"},{"price":"0.52","size":"264"},{"price":"0.51","size":"202.44"}],"tick_size":"0.01","event_type":"book","last_trade_price":"0.490"}}
{"capturedAt":1776808414,"payload":{"market":"0x125149c5918fc5f8c6d34682f700a898a1a19ea4f4e2ae68ff4c5794ba657074","price_changes":[{"asset_id":"45936375922793925919605092352922707796689801895417366600539442410775071099958","price":"0.86","size":"322.17","side":"BUY","hash":"184cbf186b8e2e8e6314dfaa41b5afadea224535","best_bid":"0.86","best_ask":"0.87"},{"asset_id":"86520121088881862182423437128238697252500151785248183602134095101149900014256","price":"0.14","size":"322.17","side":"SELL","hash":"859598cbef33d6f390d29cd015ccd38b307413d0","best_bid":"0.13","best_ask":"0.14"}],"timestamp":"1776808414726","event_type":"price_change"}}
{"capturedAt":1776808414,"payload":{"market":"0x125149c5918fc5f8c6d34682f700a898a1a19ea4f4e2ae68ff4c5794ba657074","asset_id":"45936375922793925919605092352922707796689801895417366600539442410775071099958","timestamp":"1776808414710","hash":"425af2848c4f6462b5d2954448419abc0abac9ac","bids":[{"price":"0.01","size":"12324.83"},{"price":"0.02","size":"1715.28"},{"price":"0.03","size":"1338.69"},{"price":"0.04","size":"583.84"},{"price":"0.05","size":"1006.34"},{"price":"0.06","size":"392.8"},{"price":"0.07","size":"304.69"},{"price":"0.08","size":"278.9"},{"price":"0.09","size":"225"},{"price":"0.1","size":"282"},{"price":"0.11","size":"217.79"},{"price":"0.12","size":"215.1"},{"price":"0.13","size":"202.8"},{"price":"0.14","size":"200.9"},{"price":"0.15","size":"209.2"},{"price":"0.16","size":"197.8"},{"price":"0.17","size":"202.39"},{"price":"0.18","size":"200.4"},{"price":"0.19","size":"194.4"},{"price":"0.2","size":"193.5"},{"price":"0.21","size":"215.31"},{"price":"0.22","size":"197"},{"price":"0.23","size":"229.34"},{"price":"0.24","size":"195.7"},{"price":"0.25","size":"190.2"},{"price":"0.26","size":"189.7"},{"price":"0.27","size":"194.3"},{"price":"0.28","size":"188.89"},{"price":"0.29","size":"188.5"},{"price":"0.3","size":"206.48"},{"price":"0.31","size":"394.45"},{"price":"0.32","size":"187.5"},{"price":"0.33","size":"193.55"},{"price":"0.34","size":"187"},{"price":"0.35","size":"602.68"},{"price":"0.36","size":"186.6"},{"price":"0.37","size":"191.96"},{"price":"0.38","size":"186.3"},{"price":"0.39","size":"491.36"},{"price":"0.4","size":"226"},{"price":"0.41","size":"203.32"},{"price":"0.42","size":"185.8"},{"price":"0.43","size":"190.8"},{"price":"0.44","size":"190.6"},{"price":"0.45","size":"230.58"},{"price":"0.46","size":"224.63"},{"price":"0.47","size":"207.56"},{"price":"0.48","size":"242.56"},{"price":"0.49","size":"227.4"},{"price":"0.5","size":"378.64"},{"price":"0.51","size":"205.25"},{"price":"0.52","size":"226.77"},{"price":"0.53","size":"136.71"},{"price":"0.54","size":"185.5"},{"price":"0.55","size":"213.66"},{"price":"0.56","size":"190.6"},{"price":"0.57","size":"180.7"},{"price":"0.58","size":"180.8"},{"price":"0.59","size":"130.9"},{"price":"0.6","size":"139"},{"price":"0.61","size":"185.46"},{"price":"0.62","size":"141.3"},{"price":"0.63","size":"131.4"},{"price":"0.64","size":"131.6"},{"price":"0.65","size":"136.8"},{"price":"0.66","size":"342"},{"price":"0.67","size":"232.3"},{"price":"0.68","size":"382.5"},{"price":"0.69","size":"182.8"},{"price":"0.7","size":"244.95"},{"price":"0.71","size":"405.5"},{"price":"0.72","size":"530.89"},{"price":"0.73","size":"217.3"},{"price":"0.74","size":"287.7"},{"price":"0.75","size":"382.29"},{"price":"0.76","size":"148.49"},{"price":"0.77","size":"221.3"},{"price":"0.78","size":"323.98"},{"price":"0.79","size":"219.7"},{"price":"0.8","size":"245.25"},{"price":"0.81","size":"304.9"},{"price":"0.82","size":"325.78"},{"price":"0.83","size":"353.3"},{"price":"0.84","size":"384.37"},{"price":"0.85","size":"419.78"},{"price":"0.86","size":"362.17"}],"asks":[{"price":"0.99","size":"12902.69"},{"price":"0.98","size":"1746.16"},{"price":"0.97","size":"1413.83"},{"price":"0.96","size":"932.3"},{"price":"0.95","size":"796.63"},{"price":"0.94","size":"395.8"},{"price":"0.93","size":"682.3"},{"price":"0.92","size":"661.9"},{"price":"0.91","size":"267.44"},{"price":"0.9","size":"793.5"},{"price":"0.89","size":"339"},{"price":"0.88","size":"301"},{"price":"0.87","size":"258.35"}],"tick_size":"0.01","event_type":"book","last_trade_price":"0.130"}}
{"capturedAt":1776808414,"payload":{"market":"0x125149c5918fc5f8c6d34682f700a898a1a19ea4f4e2ae68ff4c5794ba657074","price_changes":[{"asset_id":"45936375922793925919605092352922707796689801895417366600539442410775071099958","price":"0.86","size":"292.17","side":"BUY","hash":"26d6cb5d1ae53cdf9e575cafc563940959669320","best_bid":"0.86","best_ask":"0.87"},{"asset_id":"86520121088881862182423437128238697252500151785248183602134095101149900014256","price":"0.14","size":"292.17","side":"SELL","hash":"85f25141e9b76f8ff51870bf724854ae35db0eb4","best_bid":"0.13","best_ask":"0.14"}],"timestamp":"1776808414728","event_type":"price_change"}}
{"capturedAt":1776808414,"payload":{"market":"0x125149c5918fc5f8c6d34682f700a898a1a19ea4f4e2ae68ff4c5794ba657074","price_changes":[{"asset_id":"45936375922793925919605092352922707796689801895417366600539442410775071099958","price":"0.86","size":"312.17","side":"BUY","hash":"e1d9fcf677a2190c7027d607ba41da982f0c83a0","best_bid":"0.86","best_ask":"0.87"},{"asset_id":"86520121088881862182423437128238697252500151785248183602134095101149900014256","price":"0.14","size":"312.17","side":"SELL","hash":"e754d87dd79f9bbde6524ec3db57c7a3efd26837","best_bid":"0.13","best_ask":"0.14"}],"timestamp":"1776808414727","event_type":"price_change"}}
{"capturedAt":1776808414,"payload":{"market":"0x125149c5918fc5f8c6d34682f700a898a1a19ea4f4e2ae68ff4c5794ba657074","price_changes":[{"asset_id":"45936375922793925919605092352922707796689801895417366600539442410775071099958","price":"0.01","size":"12329.83","side":"BUY","hash":"61bb9fbc9db93e4a95e67491b9915b3cf4d4e658","best_bid":"0.86","best_ask":"0.87"},{"asset_id":"86520121088881862182423437128238697252500151785248183602134095101149900014256","price":"0.99","size":"12329.83","side":"SELL","hash":"6d84d1a5ee83bad99a0816cc4e9c6e01c973fbec","best_bid":"0.13","best_ask":"0.14"}],"timestamp":"1776808414732","event_type":"price_change"}}
{"capturedAt":1776808414,"payload":{"market":"0x125149c5918fc5f8c6d34682f700a898a1a19ea4f4e2ae68ff4c5794ba657074","asset_id":"45936375922793925919605092352922707796689801895417366600539442410775071099958","price":"0.87","size":"13.7931","fee_rate_bps":"1000","side":"BUY","timestamp":"1776808414725","event_type":"last_trade_price","transaction_hash":"0x6893bfa548783f987119f14d65d8cf044586c04ca1f128e289d2e3e5674a1ef2"}}
{"capturedAt":1776808414,"payload":{"market":"0x125149c5918fc5f8c6d34682f700a898a1a19ea4f4e2ae68ff4c5794ba657074","price_changes":[{"asset_id":"45936375922793925919605092352922707796689801895417366600539442410775071099958","price":"0.86","size":"272.17","side":"BUY","hash":"a9965e10ada5f590f4b6461c6c5296ce4003385c","best_bid":"0.86","best_ask":"0.87"},{"asset_id":"86520121088881862182423437128238697252500151785248183602134095101149900014256","price":"0.14","size":"272.17","side":"SELL","hash":"af9198f253800fe23e714a7c9dd19d1f0572249f","best_bid":"0.13","best_ask":"0.14"}],"timestamp":"1776808414731","event_type":"price_change"}}
{"capturedAt":1776808414,"payload":{"market":"0x125149c5918fc5f8c6d34682f700a898a1a19ea4f4e2ae68ff4c5794ba657074","price_changes":[{"asset_id":"45936375922793925919605092352922707796689801895417366600539442410775071099958","price":"0.86","size":"248.17","side":"BUY","hash":"cc9db7102b4ccbee9efbdb859d822c9811ea8bd3","best_bid":"0.86","best_ask":"0.87"},{"asset_id":"86520121088881862182423437128238697252500151785248183602134095101149900014256","price":"0.14","size":"248.17","side":"SELL","hash":"d739bb4856997f356807b81bf6ff0ffb9253031f","best_bid":"0.13","best_ask":"0.14"}],"timestamp":"1776808414737","event_type":"price_change"}}
{"capturedAt":1776808414,"payload":{"market":"0x125149c5918fc5f8c6d34682f700a898a1a19ea4f4e2ae68ff4c5794ba657074","price_changes":[{"asset_id":"45936375922793925919605092352922707796689801895417366600539442410775071099958","price":"0.86","size":"274.17","side":"BUY","hash":"55f7494f9bb802ac6ffd99ebab1eb73ae43a0fa0","best_bid":"0.86","best_ask":"0.87"},{"asset_id":"86520121088881862182423437128238697252500151785248183602134095101149900014256","price":"0.14","size":"274.17","side":"SELL","hash":"18b967a1d22c61e4aead8d47e30709be691923fb","best_bid":"0.13","best_ask":"0.14"}],"timestamp":"1776808414737","event_type":"price_change"}}
{"capturedAt":1776808414,"payload":{"market":"0x125149c5918fc5f8c6d34682f700a898a1a19ea4f4e2ae68ff4c5794ba657074","price_changes":[{"asset_id":"45936375922793925919605092352922707796689801895417366600539442410775071099958","price":"0.01","size":"12334.84","side":"BUY","hash":"ae6d2296467441f879b9e480342601e5f5050d72","best_bid":"0.86","best_ask":"0.87"},{"asset_id":"86520121088881862182423437128238697252500151785248183602134095101149900014256","price":"0.99","size":"12334.84","side":"SELL","hash":"b8f60f952cfae51b8d838e02acbd86c671eea181","best_bid":"0.13","best_ask":"0.14"}],"timestamp":"1776808414736","event_type":"price_change"}}
{"capturedAt":1776808414,"payload":{"market":"0x125149c5918fc5f8c6d34682f700a898a1a19ea4f4e2ae68ff4c5794ba657074","price_changes":[{"asset_id":"45936375922793925919605092352922707796689801895417366600539442410775071099958","price":"0.86","size":"264.17","side":"BUY","hash":"bcd4def3ac97d8085cffccbcdfe0b1e2a262f6a5","best_bid":"0.86","best_ask":"0.87"},{"asset_id":"86520121088881862182423437128238697252500151785248183602134095101149900014256","price":"0.14","size":"264.17","side":"SELL","hash":"7efdb600fb08575f8c5630149086df92e2eccf49","best_bid":"0.13","best_ask":"0.14"}],"timestamp":"1776808414738","event_type":"price_change"}}
{"capturedAt":1776808414,"payload":{"market":"0x125149c5918fc5f8c6d34682f700a898a1a19ea4f4e2ae68ff4c5794ba657074","price_changes":[{"asset_id":"45936375922793925919605092352922707796689801895417366600539442410775071099958","price":"0.86","size":"254.17","side":"BUY","hash":"6f4f4f4010829d6c7208a778cccf27b565f1b815","best_bid":"0.86","best_ask":"0.87"},{"asset_id":"86520121088881862182423437128238697252500151785248183602134095101149900014256","price":"0.14","size":"254.17","side":"SELL","hash":"b6a1678d3085dbc4a5537907d9f8c2d89d476d61","best_bid":"0.13","best_ask":"0.14"}],"timestamp":"1776808414740","event_type":"price_change"}}
{"capturedAt":1776808414,"payload":{"market":"0x125149c5918fc5f8c6d34682f700a898a1a19ea4f4e2ae68ff4c5794ba657074","price_changes":[{"asset_id":"45936375922793925919605092352922707796689801895417366600539442410775071099958","price":"0.86","size":"278.17","side":"BUY","hash":"6557d15e76b5d4e607f73489c22a5d4bb6488b38","best_bid":"0.86","best_ask":"0.87"},{"asset_id":"86520121088881862182423437128238697252500151785248183602134095101149900014256","price":"0.14","size":"278.17","side":"SELL","hash":"abf8656c3c161fbe6a078a41f3974992f2b84b21","best_bid":"0.13","best_ask":"0.14"}],"timestamp":"1776808414739","event_type":"price_change"}}
{"capturedAt":1776808414,"payload":{"market":"0x125149c5918fc5f8c6d34682f700a898a1a19ea4f4e2ae68ff4c5794ba657074","price_changes":[{"asset_id":"45936375922793925919605092352922707796689801895417366600539442410775071099958","price":"0.01","size":"12329.84","side":"BUY","hash":"5bf30a90ac849ec6f30107911f2c6294276b349b","best_bid":"0.86","best_ask":"0.87"},{"asset_id":"86520121088881862182423437128238697252500151785248183602134095101149900014256","price":"0.99","size":"12329.84","side":"SELL","hash":"814e9fe4448f1aa246c6ffaa6ecd4d0cc046cdd5","best_bid":"0.13","best_ask":"0.14"}],"timestamp":"1776808414744","event_type":"price_change"}}
{"capturedAt":1776808414,"payload":{"market":"0x125149c5918fc5f8c6d34682f700a898a1a19ea4f4e2ae68ff4c5794ba657074","price_changes":[{"asset_id":"45936375922793925919605092352922707796689801895417366600539442410775071099958","price":"0.86","size":"268.17","side":"BUY","hash":"53f94aaf6399b6425201b1848c14aa25c63df953","best_bid":"0.86","best_ask":"0.87"},{"asset_id":"86520121088881862182423437128238697252500151785248183602134095101149900014256","price":"0.14","size":"268.17","side":"SELL","hash":"0bd9b10b343bcedfedd3d3c1f3a7aee5816c311e","best_bid":"0.13","best_ask":"0.14"}],"timestamp":"1776808414741","event_type":"price_change"}}
{"capturedAt":1776808414,"payload":{"market":"0x125149c5918fc5f8c6d34682f700a898a1a19ea4f4e2ae68ff4c5794ba657074","price_changes":[{"asset_id":"45936375922793925919605092352922707796689801895417366600539442410775071099958","price":"0.86","size":"274.17","side":"BUY","hash":"645a121b60b269e83f0847279662fdb71382ffe6","best_bid":"0.86","best_ask":"0.87"},{"asset_id":"86520121088881862182423437128238697252500151785248183602134095101149900014256","price":"0.14","size":"274.17","side":"SELL","hash":"fec042094be6dfde3fa745d809dcea24ec922986","best_bid":"0.13","best_ask":"0.14"}],"timestamp":"1776808414745","event_type":"price_change"}}
{"capturedAt":1776808414,"payload":{"market":"0x125149c5918fc5f8c6d34682f700a898a1a19ea4f4e2ae68ff4c5794ba657074","price_changes":[{"asset_id":"45936375922793925919605092352922707796689801895417366600539442410775071099958","price":"0.86","size":"248.17","side":"BUY","hash":"efbe07ff2daa84936df0e1edb8f22d1c43d5d55e","best_bid":"0.86","best_ask":"0.87"},{"asset_id":"86520121088881862182423437128238697252500151785248183602134095101149900014256","price":"0.14","size":"248.17","side":"SELL","hash":"cb4d045305bfab6db84acd1482d00674f3b79dac","best_bid":"0.13","best_ask":"0.14"}],"timestamp":"1776808414743","event_type":"price_change"}}
{"capturedAt":1776808414,"payload":{"market":"0x125149c5918fc5f8c6d34682f700a898a1a19ea4f4e2ae68ff4c5794ba657074","price_changes":[{"asset_id":"45936375922793925919605092352922707796689801895417366600539442410775071099958","price":"0.86","size":"299.17","side":"BUY","hash":"6130b3b16648a46f05490cc041459e141a848f1e","best_bid":"0.86","best_ask":"0.87"},{"asset_id":"86520121088881862182423437128238697252500151785248183602134095101149900014256","price":"0.14","size":"299.17","side":"SELL","hash":"7cf6521ba63119bb909283e5b0f7af07e34232f4","best_bid":"0.13","best_ask":"0.14"}],"timestamp":"1776808414748","event_type":"price_change"}}
{"capturedAt":1776808414,"payload":{"market":"0x125149c5918fc5f8c6d34682f700a898a1a19ea4f4e2ae68ff4c5794ba657074","price_changes":[{"asset_id":"45936375922793925919605092352922707796689801895417366600539442410775071099958","price":"0.86","size":"294.02","side":"BUY","hash":"dab3e78d65f0111bd3c9cf8fe9ca1f022287715b","best_bid":"0.86","best_ask":"0.87"},{"asset_id":"86520121088881862182423437128238697252500151785248183602134095101149900014256","price":"0.14","size":"294.02","side":"SELL","hash":"52a6c490c2a1fad57ec103782612082eea4bf2c7","best_bid":"0.13","best_ask":"0.14"}],"timestamp":"1776808414755","event_type":"price_change"}}
{"capturedAt":1776808414,"payload":{"market":"0x125149c5918fc5f8c6d34682f700a898a1a19ea4f4e2ae68ff4c5794ba657074","price_changes":[{"asset_id":"45936375922793925919605092352922707796689801895417366600539442410775071099958","price":"0.86","size":"328.02","side":"BUY","hash":"6dfb95dc944082a50d12dfd3704679e95c598102","best_bid":"0.86","best_ask":"0.87"},{"asset_id":"86520121088881862182423437128238697252500151785248183602134095101149900014256","price":"0.14","size":"328.02","side":"SELL","hash":"383ad070b6f9e4a5512a78f707daa91f5b467f57","best_bid":"0.13","best_ask":"0.14"}],"timestamp":"1776808414759","event_type":"price_change"}}
{"capturedAt":1776808414,"payload":{"market":"0x125149c5918fc5f8c6d34682f700a898a1a19ea4f4e2ae68ff4c5794ba657074","price_changes":[{"asset_id":"45936375922793925919605092352922707796689801895417366600539442410775071099958","price":"0.86","size":"348.02","side":"BUY","hash":"69a161dce27a30e58f8b536e1321ddd970144170","best_bid":"0.86","best_ask":"0.87"},{"asset_id":"86520121088881862182423437128238697252500151785248183602134095101149900014256","price":"0.14","size":"348.02","side":"SELL","hash":"23d6597ab2f16096576afb0921dad4f00ce3064c","best_bid":"0.13","best_ask":"0.14"}],"timestamp":"1776808414760","event_type":"price_change"}}
{"capturedAt":1776808414,"payload":{"market":"0x125149c5918fc5f8c6d34682f700a898a1a19ea4f4e2ae68ff4c5794ba657074","price_changes":[{"asset_id":"45936375922793925919605092352922707796689801895417366600539442410775071099958","price":"0.86","size":"318.02","side":"BUY","hash":"617974da8fc0245774aa823c983f00454c7410b5","best_bid":"0.86","best_ask":"0.87"},{"asset_id":"86520121088881862182423437128238697252500151785248183602134095101149900014256","price":"0.14","size":"318.02","side":"SELL","hash":"f26f534ba8b5744f2c8200fc4691187bc5772089","best_bid":"0.13","best_ask":"0.14"}],"timestamp":"1776808414758","event_type":"price_change"}}
{"capturedAt":1776808414,"payload":{"market":"0x125149c5918fc5f8c6d34682f700a898a1a19ea4f4e2ae68ff4c5794ba657074","price_changes":[{"asset_id":"45936375922793925919605092352922707796689801895417366600539442410775071099958","price":"0.86","size":"328.02","side":"BUY","hash":"143a1d4b114b686c6b56d55dea50124f42f2bbbc","best_bid":"0.86","best_ask":"0.87"},{"asset_id":"86520121088881862182423437128238697252500151785248183602134095101149900014256","price":"0.14","size":"328.02","side":"SELL","hash":"30ca15c02639581716610a1da83b84d13603e4cc","best_bid":"0.13","best_ask":"0.14"}],"timestamp":"1776808414761","event_type":"price_change"}}
{"capturedAt":1776808414,"payload":{"market":"0x125149c5918fc5f8c6d34682f700a898a1a19ea4f4e2ae68ff4c5794ba657074","price_changes":[{"asset_id":"45936375922793925919605092352922707796689801895417366600539442410775071099958","price":"0.01","size":"12324.83","side":"BUY","hash":"17bd04e320f5fd7f0375753199138fb0f9b87162","best_bid":"0.86","best_ask":"0.87"},{"asset_id":"86520121088881862182423437128238697252500151785248183602134095101149900014256","price":"0.99","size":"12324.83","side":"SELL","hash":"ea5e5428c63c681c3ab8057dc293a1c3966f7ca4","best_bid":"0.13","best_ask":"0.14"}],"timestamp":"1776808414762","event_type":"price_change"}}
{"capturedAt":1776808414,"payload":{"market":"0x125149c5918fc5f8c6d34682f700a898a1a19ea4f4e2ae68ff4c5794ba657074","price_changes":[{"asset_id":"45936375922793925919605092352922707796689801895417366600539442410775071099958","price":"0.86","size":"352.02","side":"BUY","hash":"1233e307b7029f0729d74843d6a4a68f822c0c66","best_bid":"0.86","best_ask":"0.87"},{"asset_id":"86520121088881862182423437128238697252500151785248183602134095101149900014256","price":"0.14","size":"352.02","side":"SELL","hash":"fbfc71fea802c6ffd36a6b449f0db536622fba9f","best_bid":"0.13","best_ask":"0.14"}],"timestamp":"1776808414765","event_type":"price_change"}}
{"capturedAt":1776808414,"payload":{"market":"0x125149c5918fc5f8c6d34682f700a898a1a19ea4f4e2ae68ff4c5794ba657074","price_changes":[{"asset_id":"45936375922793925919605092352922707796689801895417366600539442410775071099958","price":"0.01","size":"12329.83","side":"BUY","hash":"2c032ba46e67bf764cd15d26b876101e3d3624e5","best_bid":"0.86","best_ask":"0.87"},{"asset_id":"86520121088881862182423437128238697252500151785248183602134095101149900014256","price":"0.99","size":"12329.83","side":"SELL","hash":"f11239d06334066f50c7175afd016f564e98fac4","best_bid":"0.13","best_ask":"0.14"}],"timestamp":"1776808414764","event_type":"price_change"}}
{"capturedAt":1776808414,"payload":{"market":"0x125149c5918fc5f8c6d34682f700a898a1a19ea4f4e2ae68ff4c5794ba657074","price_changes":[{"asset_id":"45936375922793925919605092352922707796689801895417366600539442410775071099958","price":"0.86","size":"357.04","side":"BUY","hash":"ba08c72489b6b1c6844e988215d289d58356e973","best_bid":"0.86","best_ask":"0.87"},{"asset_id":"86520121088881862182423437128238697252500151785248183602134095101149900014256","price":"0.14","size":"357.04","side":"SELL","hash":"10aecc3355a5f08b188bb71666a647fab8bb0cb9","best_bid":"0.13","best_ask":"0.14"}],"timestamp":"1776808414767","event_type":"price_change"}}
{"capturedAt":1776808414,"payload":{"market":"0x125149c5918fc5f8c6d34682f700a898a1a19ea4f4e2ae68ff4c5794ba657074","price_changes":[{"asset_id":"45936375922793925919605092352922707796689801895417366600539442410775071099958","price":"0.86","size":"381.04","side":"BUY","hash":"1ff7bd00f3121993da352f483b3b393cc9953ff9","best_bid":"0.86","best_ask":"0.87"},{"asset_id":"86520121088881862182423437128238697252500151785248183602134095101149900014256","price":"0.14","size":"381.04","side":"SELL","hash":"0362117eba0473075c23ec55a3325f3f722aa546","best_bid":"0.13","best_ask":"0.14"}],"timestamp":"1776808414768","event_type":"price_change"}}
{"capturedAt":1776808414,"payload":{"market":"0x125149c5918fc5f8c6d34682f700a898a1a19ea4f4e2ae68ff4c5794ba657074","price_changes":[{"asset_id":"45936375922793925919605092352922707796689801895417366600539442410775071099958","price":"0.86","size":"391.04","side":"BUY","hash":"6dd867fc9f7d4d6de9a01a366d12aeb326ecbc30","best_bid":"0.86","best_ask":"0.87"},{"asset_id":"86520121088881862182423437128238697252500151785248183602134095101149900014256","price":"0.14","size":"391.04","side":"SELL","hash":"8d98bad2f20dab9ff54b07909761b265e79817c5","best_bid":"0.13","best_ask":"0.14"}],"timestamp":"1776808414770","event_type":"price_change"}}
{"capturedAt":1776808414,"payload":{"market":"0x125149c5918fc5f8c6d34682f700a898a1a19ea4f4e2ae68ff4c5794ba657074","price_changes":[{"asset_id":"45936375922793925919605092352922707796689801895417366600539442410775071099958","price":"0.86","size":"416.04","side":"BUY","hash":"6791593053106b8b6f16f903a000ee8b23c50941","best_bid":"0.86","best_ask":"0.87"},{"asset_id":"86520121088881862182423437128238697252500151785248183602134095101149900014256","price":"0.14","size":"416.04","side":"SELL","hash":"6ec2fe916f19914fbee8c64e80e06c3ed2429861","best_bid":"0.13","best_ask":"0.14"}],"timestamp":"1776808414772","event_type":"price_change"}}
{"capturedAt":1776808414,"payload":{"market":"0x125149c5918fc5f8c6d34682f700a898a1a19ea4f4e2ae68ff4c5794ba657074","price_changes":[{"asset_id":"45936375922793925919605092352922707796689801895417366600539442410775071099958","price":"0.01","size":"12334.84","side":"BUY","hash":"dce85661f43ccc1414e3a9f987795774e85963c6","best_bid":"0.86","best_ask":"0.87"},{"asset_id":"86520121088881862182423437128238697252500151785248183602134095101149900014256","price":"0.99","size":"12334.84","side":"SELL","hash":"f95b21fafaaad027197b56797d70b53c6cda663e","best_bid":"0.13","best_ask":"0.14"}],"timestamp":"1776808414769","event_type":"price_change"}}
{"capturedAt":1776808414,"payload":{"market":"0xdab1ff110d9d2439c5bd75c4f503ae7300457a35b124ce0c7260ec86dcc688c8","asset_id":"79951446619687279678993570456142474051779067785614208685555261501997794502271","timestamp":"1776808411018","hash":"d8d1047a431db485165d2445003fba18727826d5","bids":[{"price":"0.01","size":"15338.75"},{"price":"0.02","size":"16995.79"},{"price":"0.03","size":"37932.42"},{"price":"0.04","size":"10157"},{"price":"0.05","size":"7294"},{"price":"0.06","size":"4896"},{"price":"0.07","size":"3307"},{"price":"0.08","size":"2613"},{"price":"0.09","size":"3674.34"},{"price":"0.1","size":"8581"},{"price":"0.11","size":"1606"},{"price":"0.12","size":"113.34"},{"price":"0.13","size":"1278"},{"price":"0.14","size":"130"},{"price":"0.15","size":"6000.51"},{"price":"0.16","size":"768.14"},{"price":"0.17","size":"1016.5"},{"price":"0.18","size":"123.56"},{"price":"0.19","size":"35.07"},{"price":"0.2","size":"561.25"},{"price":"0.21","size":"1965.62"},{"price":"0.22","size":"564.66"},{"price":"0.23","size":"118"},{"price":"0.24","size":"974.15"},{"price":"0.25","size":"1502"},{"price":"0.26","size":"1295.5"},{"price":"0.27","size":"1523"},{"price":"0.28","size":"892.53"},{"price":"0.29","size":"691.5"},{"price":"0.3","size":"1494.01"},{"price":"0.31","size":"1883.66"},{"price":"0.32","size":"872.12"},{"price":"0.33","size":"1359.7"},{"price":"0.34","size":"626.29"},{"price":"0.35","size":"1326.88"},{"price":"0.36","size":"499.44"},{"price":"0.37","size":"527.77"},{"price":"0.38","size":"297"},{"price":"0.39","size":"199.26"},{"price":"0.4","size":"242.75"},{"price":"0.41","size":"400.12"},{"price":"0.42","size":"594.86"},{"price":"0.43","size":"323.1"},{"price":"0.44","size":"526.87"},{"price":"0.45","size":"650.08"},{"price":"0.46","size":"1460.97"},{"price":"0.47","size":"1054.38"},{"price":"0.48","size":"264"},{"price":"0.49","size":"202.44"}],"asks":[{"price":"0.99","size":"15345.95"},{"price":"0.98","size":"16995.76"},{"price":"0.97","size":"37760.75"},{"price":"0.96","size":"10176"},{"price":"0.95","size":"7289"},{"price":"0.94","size":"4896"},{"price":"0.93","size":"3307"},{"price":"0.92","size":"2613"},{"price":"0.91","size":"3629.9"},{"price":"0.9","size":"8581"},{"price":"0.89","size":"1606"},{"price":"0.88","size":"71.67"},{"price":"0.87","size":"1278"},{"price":"0.86","size":"130"},{"price":"0.85","size":"5993.01"},{"price":"0.84","size":"705.64"},{"price":"0.83","size":"1009"},{"price":"0.82","size":"123.56"},{"price":"0.81","size":"85.07"},{"price":"0.8","size":"561.25"},{"price":"0.79","size":"1965.62"},{"price":"0.78","size":"587.39"},{"price":"0.77","size":"118"},{"price":"0.76","size":"974.15"},{"price":"0.75","size":"1322"},{"price":"0.74","size":"1034.74"},{"price":"0.73","size":"1343"},{"price":"0.72","size":"703.68"},{"price":"0.71","size":"511.5"},{"price":"0.7","size":"1330.69"},{"price":"0.69","size":"1631.88"},{"price":"0.68","size":"692.12"},{"price":"0.67","size":"1179.7"},{"price":"0.66","size":"626.29"},{"price":"0.65","size":"1326.88"},{"price":"0.64","size":"499.44"},{"price":"0.63","size":"568.31"},{"price":"0.62","size":"297"},{"price":"0.61","size":"199.26"},{"price":"0.6","size":"280.25"},{"price":"0.59","size":"280.12"},{"price":"0.58","size":"474.86"},{"price":"0.57","size":"318.1"},{"price":"0.56","size":"472.25"},{"price":"0.55","size":"538.08"},{"price":"0.54","size":"1593.57"},{"price":"0.53","size":"1227.29"},{"price":"0.52","size":"495.33"},{"price":"0.51","size":"217"},{"price":"0.5","size":"1451.51"}],"tick_size":"0.01","event_type":"book","last_trade_price":"0.490"}}
{"capturedAt":1776808414,"payload":{"market":"0x125149c5918fc5f8c6d34682f700a898a1a19ea4f4e2ae68ff4c5794ba657074","price_changes":[{"asset_id":"45936375922793925919605092352922707796689801895417366600539442410775071099958","price":"0.01","size":"12339.84","side":"BUY","hash":"e9e1681b7ebfdd2ef38a5113341f263543c37312","best_bid":"0.86","best_ask":"0.87"},{"asset_id":"86520121088881862182423437128238697252500151785248183602134095101149900014256","price":"0.99","size":"12339.84","side":"SELL","hash":"8eb02fb2ea8b75224fa02c1087263fb66c76317d","best_bid":"0.13","best_ask":"0.14"}],"timestamp":"1776808414774","event_type":"price_change"}}
{"capturedAt":1776808414,"payload":{"market":"0x125149c5918fc5f8c6d34682f700a898a1a19ea4f4e2ae68ff4c5794ba657074","price_changes":[{"asset_id":"45936375922793925919605092352922707796689801895417366600539442410775071099958","price":"0.86","size":"406.04","side":"BUY","hash":"11706bfaab1683130e7d39065af0af8ddb8c3795","best_bid":"0.86","best_ask":"0.87"},{"asset_id":"86520121088881862182423437128238697252500151785248183602134095101149900014256","price":"0.14","size":"406.04","side":"SELL","hash":"c750d67f13b5e06a6002bc13391c1aff6bf600c2","best_bid":"0.13","best_ask":"0.14"}],"timestamp":"1776808414775","event_type":"price_change"}}
{"capturedAt":1776808414,"payload":{"market":"0x125149c5918fc5f8c6d34682f700a898a1a19ea4f4e2ae68ff4c5794ba657074","price_changes":[{"asset_id":"45936375922793925919605092352922707796689801895417366600539442410775071099958","price":"0.01","size":"12334.84","side":"BUY","hash":"fdfd8a51de9c8815b5994a2d04e3211601bf07c4","best_bid":"0.86","best_ask":"0.87"},{"asset_id":"86520121088881862182423437128238697252500151785248183602134095101149900014256","price":"0.99","size":"12334.84","side":"SELL","hash":"381dd36e1f798b79e7bed81bf25b53e08d4a2e7a","best_bid":"0.13","best_ask":"0.14"}],"timestamp":"1776808414783","event_type":"price_change"}}
{"capturedAt":1776808414,"payload":{"market":"0x125149c5918fc5f8c6d34682f700a898a1a19ea4f4e2ae68ff4c5794ba657074","price_changes":[{"asset_id":"45936375922793925919605092352922707796689801895417366600539442410775071099958","price":"0.86","size":"433.04","side":"BUY","hash":"2c80bc69e76c71cc8b1453aa2a3a6210cd2a5863","best_bid":"0.86","best_ask":"0.87"},{"asset_id":"86520121088881862182423437128238697252500151785248183602134095101149900014256","price":"0.14","size":"433.04","side":"SELL","hash":"519ba333b84c82978da674d2eb8cb668af93d389","best_bid":"0.13","best_ask":"0.14"}],"timestamp":"1776808414787","event_type":"price_change"}}
{"capturedAt":1776808414,"payload":{"market":"0x125149c5918fc5f8c6d34682f700a898a1a19ea4f4e2ae68ff4c5794ba657074","price_changes":[{"asset_id":"45936375922793925919605092352922707796689801895417366600539442410775071099958","price":"0.86","size":"429.04","side":"BUY","hash":"e896417f75d9ca4134b426dc33b8a350ac098c8d","best_bid":"0.86","best_ask":"0.87"},{"asset_id":"86520121088881862182423437128238697252500151785248183602134095101149900014256","price":"0.14","size":"429.04","side":"SELL","hash":"70c9cb4be2598ba5cc635af5c8348c9e2db4165c","best_bid":"0.13","best_ask":"0.14"}],"timestamp":"1776808414808","event_type":"price_change"}}
{"capturedAt":1776808414,"payload":{"market":"0x125149c5918fc5f8c6d34682f700a898a1a19ea4f4e2ae68ff4c5794ba657074","price_changes":[{"asset_id":"45936375922793925919605092352922707796689801895417366600539442410775071099958","price":"0.01","size":"12324.83","side":"BUY","hash":"0ddc43c3f7d85b4b47293d8666f9c45aadb10387","best_bid":"0.86","best_ask":"0.87"},{"asset_id":"86520121088881862182423437128238697252500151785248183602134095101149900014256","price":"0.99","size":"12324.83","side":"SELL","hash":"6eac3d4587b5055ec45624f13e184df5f014574b","best_bid":"0.13","best_ask":"0.14"}],"timestamp":"1776808414795","event_type":"price_change"}}
{"capturedAt":1776808414,"payload":{"market":"0x125149c5918fc5f8c6d34682f700a898a1a19ea4f4e2ae68ff4c5794ba657074","price_changes":[{"asset_id":"45936375922793925919605092352922707796689801895417366600539442410775071099958","price":"0.01","size":"12329.83","side":"BUY","hash":"f7c2841370ab712533d07f11f3c8dbb9bf582ae4","best_bid":"0.86","best_ask":"0.87"},{"asset_id":"86520121088881862182423437128238697252500151785248183602134095101149900014256","price":"0.99","size":"12329.83","side":"SELL","hash":"bd9804a4c7a6f7dfc004ed8135af633dc9d12c7b","best_bid":"0.13","best_ask":"0.14"}],"timestamp":"1776808414814","event_type":"price_change"}}
{"capturedAt":1776808414,"payload":{"market":"0x125149c5918fc5f8c6d34682f700a898a1a19ea4f4e2ae68ff4c5794ba657074","price_changes":[{"asset_id":"45936375922793925919605092352922707796689801895417366600539442410775071099958","price":"0.86","size":"389.04","side":"BUY","hash":"a7288e937f5ce9d76483e7633d7899e85542a1fe","best_bid":"0.86","best_ask":"0.87"},{"asset_id":"86520121088881862182423437128238697252500151785248183602134095101149900014256","price":"0.14","size":"389.04","side":"SELL","hash":"a2074533c2e51b778f50288bd690bc09cd88fb0c","best_bid":"0.13","best_ask":"0.14"}],"timestamp":"1776808414813","event_type":"price_change"}}
{"capturedAt":1776808414,"payload":{"market":"0x125149c5918fc5f8c6d34682f700a898a1a19ea4f4e2ae68ff4c5794ba657074","price_changes":[{"asset_id":"45936375922793925919605092352922707796689801895417366600539442410775071099958","price":"0.01","size":"12334.83","side":"BUY","hash":"95da2bae26d13a0c555502acb5e2913c1ccb997a","best_bid":"0.86","best_ask":"0.87"},{"asset_id":"86520121088881862182423437128238697252500151785248183602134095101149900014256","price":"0.99","size":"12334.83","side":"SELL","hash":"7e7d09bf6697a1ffaad2d4e36ca144e8997d45dc","best_bid":"0.13","best_ask":"0.14"}],"timestamp":"1776808414828","event_type":"price_change"}}
{"capturedAt":1776808414,"payload":{"market":"0x125149c5918fc5f8c6d34682f700a898a1a19ea4f4e2ae68ff4c5794ba657074","price_changes":[{"asset_id":"45936375922793925919605092352922707796689801895417366600539442410775071099958","price":"0.86","size":"338.04","side":"BUY","hash":"2e3ea5e086e5a780617e9ba251e277f36339312d","best_bid":"0.86","best_ask":"0.87"},{"asset_id":"86520121088881862182423437128238697252500151785248183602134095101149900014256","price":"0.14","size":"338.04","side":"SELL","hash":"3a89ccfee43428b5d08d8b7d2e8053bcd90eaeef","best_bid":"0.13","best_ask":"0.14"}],"timestamp":"1776808414818","event_type":"price_change"}}
{"capturedAt":1776808414,"payload":{"market":"0x125149c5918fc5f8c6d34682f700a898a1a19ea4f4e2ae68ff4c5794ba657074","price_changes":[{"asset_id":"45936375922793925919605092352922707796689801895417366600539442410775071099958","price":"0.86","size":"353.04","side":"BUY","hash":"3606c2c940cab97e0485f8076db7e304ffd51611","best_bid":"0.86","best_ask":"0.87"},{"asset_id":"86520121088881862182423437128238697252500151785248183602134095101149900014256","price":"0.14","size":"353.04","side":"SELL","hash":"a38d688f80bf9a4cc8b7cdaf004ba844443c1b4e","best_bid":"0.13","best_ask":"0.14"}],"timestamp":"1776808414829","event_type":"price_change"}}
{"capturedAt":1776808414,"payload":{"market":"0x125149c5918fc5f8c6d34682f700a898a1a19ea4f4e2ae68ff4c5794ba657074","price_changes":[{"asset_id":"45936375922793925919605092352922707796689801895417366600539442410775071099958","price":"0.86","size":"363.04","side":"BUY","hash":"873a37bd107f65ff3096e14058f2a5ce241806f1","best_bid":"0.86","best_ask":"0.87"},{"asset_id":"86520121088881862182423437128238697252500151785248183602134095101149900014256","price":"0.14","size":"363.04","side":"SELL","hash":"88a40e2e5c110d01ca27aaf0ceaa2dbc9c3ef21b","best_bid":"0.13","best_ask":"0.14"}],"timestamp":"1776808414815","event_type":"price_change"}}
{"capturedAt":1776808414,"payload":{"market":"0x125149c5918fc5f8c6d34682f700a898a1a19ea4f4e2ae68ff4c5794ba657074","price_changes":[{"asset_id":"45936375922793925919605092352922707796689801895417366600539442410775071099958","price":"0.86","size":"344.04","side":"BUY","hash":"8fcde36f012d6b8eae6ff20fefb28ff3cf8fa65a","best_bid":"0.86","best_ask":"0.87"},{"asset_id":"86520121088881862182423437128238697252500151785248183602134095101149900014256","price":"0.14","size":"344.04","side":"SELL","hash":"3e12321d6591b3e12ce9b1d2ad4e13cfeca8f31e","best_bid":"0.13","best_ask":"0.14"}],"timestamp":"1776808414831","event_type":"price_change"}}
{"capturedAt":1776808414,"payload":{"market":"0x125149c5918fc5f8c6d34682f700a898a1a19ea4f4e2ae68ff4c5794ba657074","price_changes":[{"asset_id":"45936375922793925919605092352922707796689801895417366600539442410775071099958","price":"0.86","size":"329.04","side":"BUY","hash":"bed60056953f26615daa3892d63abc5c06475aaa","best_bid":"0.86","best_ask":"0.87"},{"asset_id":"86520121088881862182423437128238697252500151785248183602134095101149900014256","price":"0.14","size":"329.04","side":"SELL","hash":"fe3962c65d51ee5accb4d6845a9eb0055380dd4b","best_bid":"0.13","best_ask":"0.14"}],"timestamp":"1776808414830","event_type":"price_change"}}
{"capturedAt":1776808414,"payload":{"market":"0x125149c5918fc5f8c6d34682f700a898a1a19ea4f4e2ae68ff4c5794ba657074","price_changes":[{"asset_id":"45936375922793925919605092352922707796689801895417366600539442410775071099958","price":"0.86","size":"334.04","side":"BUY","hash":"34976969fbd8aea0d8f1177e3e6dc0b7571f8c65","best_bid":"0.86","best_ask":"0.87"},{"asset_id":"86520121088881862182423437128238697252500151785248183602134095101149900014256","price":"0.14","size":"334.04","side":"SELL","hash":"80bd2ef1ccb1ff347523bbf9d379c09f7518fa20","best_bid":"0.13","best_ask":"0.14"}],"timestamp":"1776808414832","event_type":"price_change"}}
{"capturedAt":1776808414,"payload":{"market":"0x125149c5918fc5f8c6d34682f700a898a1a19ea4f4e2ae68ff4c5794ba657074","price_changes":[{"asset_id":"45936375922793925919605092352922707796689801895417366600539442410775071099958","price":"0.86","size":"314.04","side":"BUY","hash":"ccf1a8f4ea5e53079078890d2a7401ef169ad90f","best_bid":"0.86","best_ask":"0.87"},{"asset_id":"86520121088881862182423437128238697252500151785248183602134095101149900014256","price":"0.14","size":"314.04","side":"SELL","hash":"ad65cb736d401c8d8dce73f6f73b266e4aa4a611","best_bid":"0.13","best_ask":"0.14"}],"timestamp":"1776808414833","event_type":"price_change"}}
{"capturedAt":1776808414,"payload":{"market":"0x125149c5918fc5f8c6d34682f700a898a1a19ea4f4e2ae68ff4c5794ba657074","price_changes":[{"asset_id":"45936375922793925919605092352922707796689801895417366600539442410775071099958","price":"0.86","size":"309.02","side":"BUY","hash":"e15f1999ff09417506eaf09e4fc6421cc719abbe","best_bid":"0.86","best_ask":"0.87"},{"asset_id":"86520121088881862182423437128238697252500151785248183602134095101149900014256","price":"0.14","size":"309.02","side":"SELL","hash":"a2af428789640263c472fd4f8e7aa1cf12ce535a","best_bid":"0.13","best_ask":"0.14"}],"timestamp":"1776808414834","event_type":"price_change"}}
{"capturedAt":1776808414,"payload":{"market":"0x125149c5918fc5f8c6d34682f700a898a1a19ea4f4e2ae68ff4c5794ba657074","price_changes":[{"asset_id":"45936375922793925919605092352922707796689801895417366600539442410775071099958","price":"0.86","size":"285.02","side":"BUY","hash":"63d5f7a486791e9300e1b438bcb531cf913c1e2d","best_bid":"0.86","best_ask":"0.87"},{"asset_id":"86520121088881862182423437128238697252500151785248183602134095101149900014256","price":"0.14","size":"285.02","side":"SELL","hash":"0613c4945b741b8cfda4761cfb95942468f7f201","best_bid":"0.13","best_ask":"0.14"}],"timestamp":"1776808414835","event_type":"price_change"}}
{"capturedAt":1776808414,"payload":{"market":"0x125149c5918fc5f8c6d34682f700a898a1a19ea4f4e2ae68ff4c5794ba657074","price_changes":[{"asset_id":"45936375922793925919605092352922707796689801895417366600539442410775071099958","price":"0.86","size":"443.04","side":"BUY","hash":"44a3d3bdac073f09665e22603ce28c11e3e12cdb","best_bid":"0.86","best_ask":"0.87"},{"asset_id":"86520121088881862182423437128238697252500151785248183602134095101149900014256","price":"0.14","size":"443.04","side":"SELL","hash":"efde23241f19b9a203d4e606b4afcfe5b119e3bb","best_bid":"0.13","best_ask":"0.14"}],"timestamp":"1776808414804","event_type":"price_change"}}
{"capturedAt":1776808414,"payload":{"market":"0x125149c5918fc5f8c6d34682f700a898a1a19ea4f4e2ae68ff4c5794ba657074","price_changes":[{"asset_id":"45936375922793925919605092352922707796689801895417366600539442410775071099958","price":"0.01","size":"12329.83","side":"BUY","hash":"220cce82affb3e7465d1c2bf35b9996fe7f6570f","best_bid":"0.86","best_ask":"0.87"},{"asset_id":"86520121088881862182423437128238697252500151785248183602134095101149900014256","price":"0.99","size":"12329.83","side":"SELL","hash":"e77d69ff2b210ced80a9ba81ec92423ae2798bbe","best_bid":"0.13","best_ask":"0.14"}],"timestamp":"1776808414833","event_type":"price_change"}}
{"capturedAt":1776808414,"payload":{"market":"0x125149c5918fc5f8c6d34682f700a898a1a19ea4f4e2ae68ff4c5794ba657074","price_changes":[{"asset_id":"45936375922793925919605092352922707796689801895417366600539442410775071099958","price":"0.01","size":"12329.84","side":"BUY","hash":"610253ce7cb3bff707854087a56ce391354ee710","best_bid":"0.86","best_ask":"0.87"},{"asset_id":"86520121088881862182423437128238697252500151785248183602134095101149900014256","price":"0.99","size":"12329.84","side":"SELL","hash":"dc63a7175594c502b18360cf0b9ba17a82505fe7","best_bid":"0.13","best_ask":"0.14"}],"timestamp":"1776808414793","event_type":"price_change"}}
{"capturedAt":1776808414,"payload":{"market":"0x125149c5918fc5f8c6d34682f700a898a1a19ea4f4e2ae68ff4c5794ba657074","price_changes":[{"asset_id":"45936375922793925919605092352922707796689801895417366600539442410775071099958","price":"0.86","size":"415.04","side":"BUY","hash":"87f99aaf583f07b3ea231296c80ba32e052f69bb","best_bid":"0.86","best_ask":"0.87"},{"asset_id":"86520121088881862182423437128238697252500151785248183602134095101149900014256","price":"0.14","size":"415.04","side":"SELL","hash":"92091522bd611423613abd11bf517762b102d203","best_bid":"0.13","best_ask":"0.14"}],"timestamp":"1776808414809","event_type":"price_change"}}
{"capturedAt":1776808414,"payload":{"market":"0x125149c5918fc5f8c6d34682f700a898a1a19ea4f4e2ae68ff4c5794ba657074","price_changes":[{"asset_id":"45936375922793925919605092352922707796689801895417366600539442410775071099958","price":"0.86","size":"261.02","side":"BUY","hash":"19abbfb3a691a4be6cb760fd020956fd1f4e7fd3","best_bid":"0.86","best_ask":"0.87"},{"asset_id":"86520121088881862182423437128238697252500151785248183602134095101149900014256","price":"0.14","size":"261.02","side":"SELL","hash":"3fac308257fe872ede7fd384e2cafe22eb6e028b","best_bid":"0.13","best_ask":"0.14"}],"timestamp":"1776808414837","event_type":"price_change"}}
{"capturedAt":1776808414,"payload":{"market":"0x125149c5918fc5f8c6d34682f700a898a1a19ea4f4e2ae68ff4c5794ba657074","price_changes":[{"asset_id":"45936375922793925919605092352922707796689801895417366600539442410775071099958","price":"0.86","size":"251.02","side":"BUY","hash":"63e0810a0c81dc28927a0f104ef1195eba801666","best_bid":"0.86","best_ask":"0.87"},{"asset_id":"86520121088881862182423437128238697252500151785248183602134095101149900014256","price":"0.14","size":"251.02","side":"SELL","hash":"f7dcf736d8b31779dda03fbf1b0ea5997cf9ff9b","best_bid":"0.13","best_ask":"0.14"}],"timestamp":"1776808414840","event_type":"price_change"}}
{"capturedAt":1776808414,"payload":{"market":"0x125149c5918fc5f8c6d34682f700a898a1a19ea4f4e2ae68ff4c5794ba657074","price_changes":[{"asset_id":"45936375922793925919605092352922707796689801895417366600539442410775071099958","price":"0.86","size":"301.02","side":"BUY","hash":"33620a689dc1e8262f48fb3861e0a9c1ff47db6f","best_bid":"0.86","best_ask":"0.87"},{"asset_id":"86520121088881862182423437128238697252500151785248183602134095101149900014256","price":"0.14","size":"301.02","side":"SELL","hash":"fce130df5fd396a29258cce7c17ae5becfc8dda6","best_bid":"0.13","best_ask":"0.14"}],"timestamp":"1776808414842","event_type":"price_change"}}
{"capturedAt":1776808414,"payload":{"market":"0x125149c5918fc5f8c6d34682f700a898a1a19ea4f4e2ae68ff4c5794ba657074","price_changes":[{"asset_id":"45936375922793925919605092352922707796689801895417366600539442410775071099958","price":"0.86","size":"276.02","side":"BUY","hash":"4ec572bd9b520a82ea840a996ebceb096087609b","best_bid":"0.86","best_ask":"0.87"},{"asset_id":"86520121088881862182423437128238697252500151785248183602134095101149900014256","price":"0.14","size":"276.02","side":"SELL","hash":"cc990102f39e14ed7f0c40a049ed375603bc71a0","best_bid":"0.13","best_ask":"0.14"}],"timestamp":"1776808414841","event_type":"price_change"}}
{"capturedAt":1776808414,"payload":{"market":"0x125149c5918fc5f8c6d34682f700a898a1a19ea4f4e2ae68ff4c5794ba657074","price_changes":[{"asset_id":"45936375922793925919605092352922707796689801895417366600539442410775071099958","price":"0.86","size":"276.02","side":"BUY","hash":"d741f5a6609ee0f01bfa18905e76d2b75e43dcba","best_bid":"0.86","best_ask":"0.87"},{"asset_id":"86520121088881862182423437128238697252500151785248183602134095101149900014256","price":"0.14","size":"276.02","side":"SELL","hash":"41d94d4f94d040d56e09b504a23b64bc3edd90eb","best_bid":"0.13","best_ask":"0.14"}],"timestamp":"1776808414845","event_type":"price_change"}}
{"capturedAt":1776808414,"payload":{"market":"0x125149c5918fc5f8c6d34682f700a898a1a19ea4f4e2ae68ff4c5794ba657074","price_changes":[{"asset_id":"45936375922793925919605092352922707796689801895417366600539442410775071099958","price":"0.01","size":"12324.83","side":"BUY","hash":"145f4c3555e942c6dc3266f13c22533889aaa45b","best_bid":"0.86","best_ask":"0.87"},{"asset_id":"86520121088881862182423437128238697252500151785248183602134095101149900014256","price":"0.99","size":"12324.83","side":"SELL","hash":"06722c15e51372c3ec2f5707abc06e7a1769114a","best_bid":"0.13","best_ask":"0.14"}],"timestamp":"1776808414846","event_type":"price_change"}}
{"capturedAt":1776808414,"payload":{"market":"0x125149c5918fc5f8c6d34682f700a898a1a19ea4f4e2ae68ff4c5794ba657074","price_changes":[{"asset_id":"45936375922793925919605092352922707796689801895417366600539442410775071099958","price":"0.86","size":"299.02","side":"BUY","hash":"1dc7c487deb7d60312a2c79a111fd01834ff848b","best_bid":"0.86","best_ask":"0.87"},{"asset_id":"86520121088881862182423437128238697252500151785248183602134095101149900014256","price":"0.14","size":"299.02","side":"SELL","hash":"74b7ac428202adf0f593da4060033a582187d516","best_bid":"0.13","best_ask":"0.14"}],"timestamp":"1776808414849","event_type":"price_change"}}
{"capturedAt":1776808414,"payload":{"market":"0x125149c5918fc5f8c6d34682f700a898a1a19ea4f4e2ae68ff4c5794ba657074","price_changes":[{"asset_id":"45936375922793925919605092352922707796689801895417366600539442410775071099958","price":"0.59","size":"180.9","side":"BUY","hash":"a2f53247161f2d7c56ab9a7208e7d5f983007a8d","best_bid":"0.86","best_ask":"0.87"},{"asset_id":"86520121088881862182423437128238697252500151785248183602134095101149900014256","price":"0.41","size":"180.9","side":"SELL","hash":"0de16dd82b83b7527c516888409cd140ad4d8f03","best_bid":"0.13","best_ask":"0.14"}],"timestamp":"1776808414851","event_type":"price_change"}}
{"capturedAt":1776808414,"payload":{"market":"0x125149c5918fc5f8c6d34682f700a898a1a19ea4f4e2ae68ff4c5794ba657074","price_changes":[{"asset_id":"45936375922793925919605092352922707796689801895417366600539442410775071099958","price":"0.86","size":"320.02","side":"BUY","hash":"0afff9eca15decf9b327254837ccb4efed5c244d","best_bid":"0.86","best_ask":"0.87"},{"asset_id":"86520121088881862182423437128238697252500151785248183602134095101149900014256","price":"0.14","size":"320.02","side":"SELL","hash":"1d5188cf03cdf2843908b00469cb87940b1f6920","best_bid":"0.13","best_ask":"0.14"}],"timestamp":"1776808414856","event_type":"price_change"}}
{"capturedAt":1776808414,"payload":{"market":"0x125149c5918fc5f8c6d34682f700a898a1a19ea4f4e2ae68ff4c5794ba657074","price_changes":[{"asset_id":"45936375922793925919605092352922707796689801895417366600539442410775071099958","price":"0.86","size":"293.02","side":"BUY","hash":"4bfde11f907069be234ad30b9166f0d4ac190272","best_bid":"0.86","best_ask":"0.87"},{"asset_id":"86520121088881862182423437128238697252500151785248183602134095101149900014256","price":"0.14","size":"293.02","side":"SELL","hash":"d41af45a51f744d5bc0ab977cf0c76e25ebf44b3","best_bid":"0.13","best_ask":"0.14"}],"timestamp":"1776808414857","event_type":"price_change"}}
{"capturedAt":1776808414,"payload":{"market":"0x125149c5918fc5f8c6d34682f700a898a1a19ea4f4e2ae68ff4c5794ba657074","price_changes":[{"asset_id":"45936375922793925919605092352922707796689801895417366600539442410775071099958","price":"0.86","size":"325.02","side":"BUY","hash":"ada8867a2bd90e1e7c8f4bca2cfd861d3ff20177","best_bid":"0.86","best_ask":"0.87"},{"asset_id":"86520121088881862182423437128238697252500151785248183602134095101149900014256","price":"0.14","size":"325.02","side":"SELL","hash":"b345c382c2fed5df0d6b3fe5852423b8bb1ef5bc","best_bid":"0.13","best_ask":"0.14"}],"timestamp":"1776808414859","event_type":"price_change"}}
{"capturedAt":1776808414,"payload":{"market":"0x125149c5918fc5f8c6d34682f700a898a1a19ea4f4e2ae68ff4c5794ba657074","price_changes":[{"asset_id":"45936375922793925919605092352922707796689801895417366600539442410775071099958","price":"0.86","size":"315.02","side":"BUY","hash":"0a47629ff57ebb3c928a20f8cbb7f3abfef7a72d","best_bid":"0.86","best_ask":"0.87"},{"asset_id":"86520121088881862182423437128238697252500151785248183602134095101149900014256","price":"0.14","size":"315.02","side":"SELL","hash":"a2805545235412c80f59b14e30964386d6dd342f","best_bid":"0.13","best_ask":"0.14"}],"timestamp":"1776808414858","event_type":"price_change"}}
{"capturedAt":1776808414,"payload":{"market":"0x125149c5918fc5f8c6d34682f700a898a1a19ea4f4e2ae68ff4c5794ba657074","price_changes":[{"asset_id":"45936375922793925919605092352922707796689801895417366600539442410775071099958","price":"0.86","size":"315.02","side":"BUY","hash":"91152ca96d3db27f8881272885a71d5681b58905","best_bid":"0.86","best_ask":"0.87"},{"asset_id":"86520121088881862182423437128238697252500151785248183602134095101149900014256","price":"0.14","size":"315.02","side":"SELL","hash":"bd64184636e11348814c56d919a0ce152caf440e","best_bid":"0.13","best_ask":"0.14"}],"timestamp":"1776808414862","event_type":"price_change"}}
{"capturedAt":1776808414,"payload":{"market":"0x125149c5918fc5f8c6d34682f700a898a1a19ea4f4e2ae68ff4c5794ba657074","price_changes":[{"asset_id":"45936375922793925919605092352922707796689801895417366600539442410775071099958","price":"0.86","size":"336.02","side":"BUY","hash":"540b8dbbc97f3f1c2b7f3e5fdde737ca5f6f9f28","best_bid":"0.86","best_ask":"0.87"},{"asset_id":"86520121088881862182423437128238697252500151785248183602134095101149900014256","price":"0.14","size":"336.02","side":"SELL","hash":"b7fd37a61b21a3619d2d818fb3d6c13489db560c","best_bid":"0.13","best_ask":"0.14"}],"timestamp":"1776808414863","event_type":"price_change"}}
{"capturedAt":1776808414,"payload":{"market":"0x125149c5918fc5f8c6d34682f700a898a1a19ea4f4e2ae68ff4c5794ba657074","price_changes":[{"asset_id":"45936375922793925919605092352922707796689801895417366600539442410775071099958","price":"0.01","size":"12329.83","side":"BUY","hash":"df56aa3c593f985f869ae2302f099306696ebc33","best_bid":"0.86","best_ask":"0.87"},{"asset_id":"86520121088881862182423437128238697252500151785248183602134095101149900014256","price":"0.99","size":"12329.83","side":"SELL","hash":"0fa9157b68250fe44ec644ec542f5342eae69e16","best_bid":"0.13","best_ask":"0.14"}],"timestamp":"1776808414863","event_type":"price_change"}}
{"capturedAt":1776808414,"payload":{"market":"0x125149c5918fc5f8c6d34682f700a898a1a19ea4f4e2ae68ff4c5794ba657074","price_changes":[{"asset_id":"45936375922793925919605092352922707796689801895417366600539442410775071099958","price":"0.86","size":"357.02","side":"BUY","hash":"8269794eecb600c0dfe3adf784f605d08ef9df78","best_bid":"0.86","best_ask":"0.87"},{"asset_id":"86520121088881862182423437128238697252500151785248183602134095101149900014256","price":"0.14","size":"357.02","side":"SELL","hash":"7865f2f12de0b5858e9dc05335b97e92859a51b1","best_bid":"0.13","best_ask":"0.14"}],"timestamp":"1776808414868","event_type":"price_change"}}
{"capturedAt":1776808414,"payload":{"market":"0x125149c5918fc5f8c6d34682f700a898a1a19ea4f4e2ae68ff4c5794ba657074","price_changes":[{"asset_id":"45936375922793925919605092352922707796689801895417366600539442410775071099958","price":"0.86","size":"367.02","side":"BUY","hash":"7e4e6f5c9aad2409d9c54449c67fd98add6a91cc","best_bid":"0.86","best_ask":"0.87"},{"asset_id":"86520121088881862182423437128238697252500151785248183602134095101149900014256","price":"0.14","size":"367.02","side":"SELL","hash":"d62b1061f6256c30956f13fb7a9e97662058b371","best_bid":"0.13","best_ask":"0.14"}],"timestamp":"1776808414869","event_type":"price_change"}}
{"capturedAt":1776808414,"payload":{"market":"0x125149c5918fc5f8c6d34682f700a898a1a19ea4f4e2ae68ff4c5794ba657074","price_changes":[{"asset_id":"45936375922793925919605092352922707796689801895417366600539442410775071099958","price":"0.86","size":"388.02","side":"BUY","hash":"382dc41231c27c5e81892e7a8acd12383e45ff02","best_bid":"0.86","best_ask":"0.87"},{"asset_id":"86520121088881862182423437128238697252500151785248183602134095101149900014256","price":"0.14","size":"388.02","side":"SELL","hash":"9df0f416895322ce4f845f2bcc912f84a8be90ac","best_bid":"0.13","best_ask":"0.14"}],"timestamp":"1776808414873","event_type":"price_change"}}
{"capturedAt":1776808414,"payload":{"market":"0x125149c5918fc5f8c6d34682f700a898a1a19ea4f4e2ae68ff4c5794ba657074","price_changes":[{"asset_id":"45936375922793925919605092352922707796689801895417366600539442410775071099958","price":"0.01","size":"12334.83","side":"BUY","hash":"967a93b42b431f68b95d8db33e285fbe95cdd3db","best_bid":"0.86","best_ask":"0.87"},{"asset_id":"86520121088881862182423437128238697252500151785248183602134095101149900014256","price":"0.99","size":"12334.83","side":"SELL","hash":"59fef5923f5589bf4afbcda6c249ab39925dc04c","best_bid":"0.13","best_ask":"0.14"}],"timestamp":"1776808414876","event_type":"price_change"}}
{"capturedAt":1776808414,"payload":{"market":"0x125149c5918fc5f8c6d34682f700a898a1a19ea4f4e2ae68ff4c5794ba657074","price_changes":[{"asset_id":"86520121088881862182423437128238697252500151785248183602134095101149900014256","price":"0.13","size":"257.2","side":"BUY","hash":"6013894d47496207366d4af8c264bbf7842915ef","best_bid":"0.13","best_ask":"0.14"},{"asset_id":"45936375922793925919605092352922707796689801895417366600539442410775071099958","price":"0.87","size":"257.2","side":"SELL","hash":"ff010305a6fbde85baf499e6d606cc2f387352ac","best_bid":"0.86","best_ask":"0.87"}],"timestamp":"1776808414886","event_type":"price_change"}}
{"capturedAt":1776808414,"payload":{"market":"0x125149c5918fc5f8c6d34682f700a898a1a19ea4f4e2ae68ff4c5794ba657074","asset_id":"45936375922793925919605092352922707796689801895417366600539442410775071099958","bids":[{"price":"0.01","size":"12329.83"},{"price":"0.02","size":"1715.28"},{"price":"0.03","size":"1338.69"},{"price":"0.04","size":"583.84"},{"price":"0.05","size":"1006.34"},{"price":"0.06","size":"392.8"},{"price":"0.07","size":"304.69"},{"price":"0.08","size":"278.9"},{"price":"0.09","size":"225"},{"price":"0.1","size":"282"},{"price":"0.11","size":"217.79"},{"price":"0.12","size":"215.1"},{"price":"0.13","size":"202.8"},{"price":"0.14","size":"200.9"},{"price":"0.15","size":"209.2"},{"price":"0.16","size":"197.8"},{"price":"0.17","size":"202.39"},{"price":"0.18","size":"200.4"},{"price":"0.19","size":"194.4"},{"price":"0.2","size":"193.5"},{"price":"0.21","size":"215.31"},{"price":"0.22","size":"197"},{"price":"0.23","size":"229.34"},{"price":"0.24","size":"195.7"},{"price":"0.25","size":"190.2"},{"price":"0.26","size":"189.7"},{"price":"0.27","size":"194.3"},{"price":"0.28","size":"188.89"},{"price":"0.29","size":"188.5"},{"price":"0.3","size":"206.48"},{"price":"0.31","size":"394.45"},{"price":"0.32","size":"187.5"},{"price":"0.33","size":"193.55"},{"price":"0.34","size":"187"},{"price":"0.35","size":"602.68"},{"price":"0.36","size":"186.6"},{"price":"0.37","size":"191.96"},{"price":"0.38","size":"186.3"},{"price":"0.39","size":"491.36"},{"price":"0.4","size":"226"},{"price":"0.41","size":"203.32"},{"price":"0.42","size":"185.8"},{"price":"0.43","size":"190.8"},{"price":"0.44","size":"190.6"},{"price":"0.45","size":"230.58"},{"price":"0.46","size":"224.63"},{"price":"0.47","size":"207.56"},{"price":"0.48","size":"242.56"},{"price":"0.49","size":"227.4"},{"price":"0.5","size":"378.64"},{"price":"0.51","size":"205.25"},{"price":"0.52","size":"226.77"},{"price":"0.53","size":"136.71"},{"price":"0.54","size":"185.5"},{"price":"0.55","size":"213.66"},{"price":"0.56","size":"190.6"},{"price":"0.57","size":"180.7"},{"price":"0.58","size":"180.8"},{"price":"0.59","size":"180.9"},{"price":"0.6","size":"139"},{"price":"0.61","size":"185.46"},{"price":"0.62","size":"141.3"},{"price":"0.63","size":"131.4"},{"price":"0.64","size":"131.6"},{"price":"0.65","size":"136.8"},{"price":"0.66","size":"342"},{"price":"0.67","size":"232.3"},{"price":"0.68","size":"382.5"},{"price":"0.69","size":"182.8"},{"price":"0.7","size":"244.95"},{"price":"0.71","size":"405.5"},{"price":"0.72","size":"530.89"},{"price":"0.73","size":"217.3"},{"price":"0.74","size":"287.7"},{"price":"0.75","size":"382.29"},{"price":"0.76","size":"148.49"},{"price":"0.77","size":"221.3"},{"price":"0.78","size":"323.98"},{"price":"0.79","size":"219.7"},{"price":"0.8","size":"245.25"},{"price":"0.81","size":"304.9"},{"price":"0.82","size":"325.78"},{"price":"0.83","size":"353.3"},{"price":"0.84","size":"384.37"},{"price":"0.85","size":"419.78"},{"price":"0.86","size":"388.02"}],"asks":[{"price":"0.99","size":"12902.69"},{"price":"0.98","size":"1746.16"},{"price":"0.97","size":"1413.83"},{"price":"0.96","size":"932.3"},{"price":"0.95","size":"796.63"},{"price":"0.94","size":"395.8"},{"price":"0.93","size":"682.3"},{"price":"0.92","size":"661.9"},{"price":"0.91","size":"267.44"},{"price":"0.9","size":"793.5"},{"price":"0.89","size":"339"},{"price":"0.88","size":"301"},{"price":"0.87","size":"257.2"}],"hash":"ff010305a6fbde85baf499e6d606cc2f387352ac","timestamp":"1776808414886","event_type":"book"}}
{"capturedAt":1776808414,"payload":{"market":"0x125149c5918fc5f8c6d34682f700a898a1a19ea4f4e2ae68ff4c5794ba657074","price_changes":[{"asset_id":"45936375922793925919605092352922707796689801895417366600539442410775071099958","price":"0.47","size":"220.33","side":"BUY","hash":"e95be88beb688926eba914ab0ff6fe902113fab6","best_bid":"0.86","best_ask":"0.87"},{"asset_id":"86520121088881862182423437128238697252500151785248183602134095101149900014256","price":"0.53","size":"220.33","side":"SELL","hash":"e9bc63d622973830b37d7e8ded361ce39e5fdecd","best_bid":"0.13","best_ask":"0.14"}],"timestamp":"1776808414888","event_type":"price_change"}}
{"capturedAt":1776808414,"payload":{"market":"0x125149c5918fc5f8c6d34682f700a898a1a19ea4f4e2ae68ff4c5794ba657074","price_changes":[{"asset_id":"45936375922793925919605092352922707796689801895417366600539442410775071099958","price":"0.01","size":"12329.83","side":"BUY","hash":"68e1ad54c2d56365825bee6b6ec27e16e209d6ea","best_bid":"0.86","best_ask":"0.87"},{"asset_id":"86520121088881862182423437128238697252500151785248183602134095101149900014256","price":"0.99","size":"12329.83","side":"SELL","hash":"edc6d5d84c42a6c83e882a8a028f0beb831026e9","best_bid":"0.13","best_ask":"0.14"}],"timestamp":"1776808414882","event_type":"price_change"}}
{"capturedAt":1776808414,"payload":{"market":"0x125149c5918fc5f8c6d34682f700a898a1a19ea4f4e2ae68ff4c5794ba657074","price_changes":[{"asset_id":"45936375922793925919605092352922707796689801895417366600539442410775071099958","price":"0.86","size":"409.02","side":"BUY","hash":"859547a2ae5d1cb405eafc7e6d2454c3fa8754e6","best_bid":"0.86","best_ask":"0.87"},{"asset_id":"86520121088881862182423437128238697252500151785248183602134095101149900014256","price":"0.14","size":"409.02","side":"SELL","hash":"cbaabe7b6fe14733c5c980456b380055d1c7360e","best_bid":"0.13","best_ask":"0.14"}],"timestamp":"1776808414887","event_type":"price_change"}}
{"capturedAt":1776808414,"payload":{"market":"0x125149c5918fc5f8c6d34682f700a898a1a19ea4f4e2ae68ff4c5794ba657074","asset_id":"45936375922793925919605092352922707796689801895417366600539442410775071099958","best_bid":"0.86","best_ask":"0.87","spread":"0.01","timestamp":"1776808414887","event_type":"best_bid_ask"}}
{"capturedAt":1776808414,"payload":{"market":"0x125149c5918fc5f8c6d34682f700a898a1a19ea4f4e2ae68ff4c5794ba657074","asset_id":"86520121088881862182423437128238697252500151785248183602134095101149900014256","bids":[{"price":"0.01","size":"12902.69"},{"price":"0.02","size":"1746.16"},{"price":"0.03","size":"1413.83"},{"price":"0.04","size":"932.3"},{"price":"0.05","size":"796.63"},{"price":"0.06","size":"395.8"},{"price":"0.07","size":"682.3"},{"price":"0.08","size":"661.9"},{"price":"0.09","size":"267.44"},{"price":"0.1","size":"793.5"},{"price":"0.11","size":"339"},{"price":"0.12","size":"301"},{"price":"0.13","size":"257.2"}],"asks":[{"price":"0.99","size":"12329.83"},{"price":"0.98","size":"1715.28"},{"price":"0.97","size":"1338.69"},{"price":"0.96","size":"583.84"},{"price":"0.95","size":"1006.34"},{"price":"0.94","size":"392.8"},{"price":"0.93","size":"304.69"},{"price":"0.92","size":"278.9"},{"price":"0.91","size":"225"},{"price":"0.9","size":"282"},{"price":"0.89","size":"217.79"},{"price":"0.88","size":"215.1"},{"price":"0.87","size":"202.8"},{"price":"0.86","size":"200.9"},{"price":"0.85","size":"209.2"},{"price":"0.84","size":"197.8"},{"price":"0.83","size":"202.39"},{"price":"0.82","size":"200.4"},{"price":"0.81","size":"194.4"},{"price":"0.8","size":"193.5"},{"price":"0.79","size":"215.31"},{"price":"0.78","size":"197"},{"price":"0.77","size":"229.34"},{"price":"0.76","size":"195.7"},{"price":"0.75","size":"190.2"},{"price":"0.74","size":"189.7"},{"price":"0.73","size":"194.3"},{"price":"0.72","size":"188.89"},{"price":"0.71","size":"188.5"},{"price":"0.7","size":"206.48"},{"price":"0.69","size":"394.45"},{"price":"0.68","size":"187.5"},{"price":"0.67","size":"193.55"},{"price":"0.66","size":"187"},{"price":"0.65","size":"602.68"},{"price":"0.64","size":"186.6"},{"price":"0.63","size":"191.96"},{"price":"0.62","size":"186.3"},{"price":"0.61","size":"491.36"},{"price":"0.6","size":"226"},{"price":"0.59","size":"203.32"},{"price":"0.58","size":"185.8"},{"price":"0.57","size":"190.8"},{"price":"0.56","size":"190.6"},{"price":"0.55","size":"230.58"},{"price":"0.54","size":"224.63"},{"price":"0.53","size":"207.56"},{"price":"0.52","size":"242.56"},{"price":"0.51","size":"227.4"},{"price":"0.5","size":"378.64"},{"price":"0.49","size":"205.25"},{"price":"0.48","size":"226.77"},{"price":"0.47","size":"136.71"},{"price":"0.46","size":"185.5"},{"price":"0.45","size":"213.66"},{"price":"0.44","size":"190.6"},{"price":"0.43","size":"180.7"},{"price":"0.42","size":"180.8"},{"price":"0.41","size":"180.9"},{"price":"0.4","size":"139"},{"price":"0.39","size":"185.46"},{"price":"0.38","size":"141.3"},{"price":"0.37","size":"131.4"},{"price":"0.36","size":"131.6"},{"price":"0.35","size":"136.8"},{"price":"0.34","size":"342"},{"price":"0.33","size":"232.3"},{"price":"0.32","size":"382.5"},{"price":"0.31","size":"182.8"},{"price":"0.3","size":"244.95"},{"price":"0.29","size":"405.5"},{"price":"0.28","size":"530.89"},{"price":"0.27","size":"217.3"},{"price":"0.26","size":"287.7"},{"price":"0.25","size":"382.29"},{"price":"0.24","size":"148.49"},{"price":"0.23","size":"221.3"},{"price":"0.22","size":"323.98"},{"price":"0.21","size":"219.7"},{"price":"0.2","size":"245.25"},{"price":"0.19","size":"304.9"},{"price":"0.18","size":"325.78"},{"price":"0.17","size":"353.3"},{"price":"0.16","size":"384.37"},{"price":"0.15","size":"419.78"},{"price":"0.14","size":"388.02"}],"hash":"6013894d47496207366d4af8c264bbf7842915ef","timestamp":"1776808414886","event_type":"book"}}
{"capturedAt":1776808414,"payload":{"market":"0x125149c5918fc5f8c6d34682f700a898a1a19ea4f4e2ae68ff4c5794ba657074","price_changes":[{"asset_id":"45936375922793925919605092352922707796689801895417366600539442410775071099958","price":"0.86","size":"414.13","side":"BUY","hash":"61d367796d4bad0d3feb463fb8f4285f3844ae03","best_bid":"0.86","best_ask":"0.87"},{"asset_id":"86520121088881862182423437128238697252500151785248183602134095101149900014256","price":"0.14","size":"414.13","side":"SELL","hash":"1812429551ca0853b4443873c7b435aac7a16e88","best_bid":"0.13","best_ask":"0.14"}],"timestamp":"1776808414889","event_type":"price_change"}}
{"capturedAt":1776808414,"payload":{"market":"0x125149c5918fc5f8c6d34682f700a898a1a19ea4f4e2ae68ff4c5794ba657074","price_changes":[{"asset_id":"45936375922793925919605092352922707796689801895417366600539442410775071099958","price":"0.86","size":"424.13","side":"BUY","hash":"f0c78756cc7d5bef51cc39e6ef466a5950ac0199","best_bid":"0.86","best_ask":"0.87"},{"asset_id":"86520121088881862182423437128238697252500151785248183602134095101149900014256","price":"0.14","size":"424.13","side":"SELL","hash":"5acc994d475a073ef63e9359c379c3896a739435","best_bid":"0.13","best_ask":"0.14"}],"timestamp":"1776808414891","event_type":"price_change"}}
{"capturedAt":1776808414,"payload":{"market":"0x125149c5918fc5f8c6d34682f700a898a1a19ea4f4e2ae68ff4c5794ba657074","asset_id":"86520121088881862182423437128238697252500151785248183602134095101149900014256","best_bid":"0.13","best_ask":"0.14","spread":"0.01","timestamp":"1776808414887","event_type":"best_bid_ask"}}
{"capturedAt":1776808414,"payload":{"market":"0x125149c5918fc5f8c6d34682f700a898a1a19ea4f4e2ae68ff4c5794ba657074","price_changes":[{"asset_id":"45936375922793925919605092352922707796689801895417366600539442410775071099958","price":"0.01","size":"12324.83","side":"BUY","hash":"e58f8900f4f35fe9b710ed8939f3ab8a49994b37","best_bid":"0.86","best_ask":"0.87"},{"asset_id":"86520121088881862182423437128238697252500151785248183602134095101149900014256","price":"0.99","size":"12324.83","side":"SELL","hash":"7b7cc0507128f9af293afc9de758518cb6b10e7e","best_bid":"0.13","best_ask":"0.14"}],"timestamp":"1776808414909","event_type":"price_change"}}
{"capturedAt":1776808414,"payload":{"market":"0x125149c5918fc5f8c6d34682f700a898a1a19ea4f4e2ae68ff4c5794ba657074","price_changes":[{"asset_id":"45936375922793925919605092352922707796689801895417366600539442410775071099958","price":"0.47","size":"245.86","side":"BUY","hash":"40aee111ed57b1417472548406430325f7c01d3f","best_bid":"0.86","best_ask":"0.87"},{"asset_id":"86520121088881862182423437128238697252500151785248183602134095101149900014256","price":"0.53","size":"245.86","side":"SELL","hash":"e78619703d1930da4f6d0ed23055d2a2dbfd69a8","best_bid":"0.13","best_ask":"0.14"}],"timestamp":"1776808414908","event_type":"price_change"}}
{"capturedAt":1776808414,"payload":{"market":"0x125149c5918fc5f8c6d34682f700a898a1a19ea4f4e2ae68ff4c5794ba657074","price_changes":[{"asset_id":"45936375922793925919605092352922707796689801895417366600539442410775071099958","price":"0.01","size":"12329.83","side":"BUY","hash":"5b20feb313bd9e6e0a274274318d0dcbb9488672","best_bid":"0.86","best_ask":"0.87"},{"asset_id":"86520121088881862182423437128238697252500151785248183602134095101149900014256","price":"0.99","size":"12329.83","side":"SELL","hash":"9d88c5558e30aeddd0711d4cf5130636bd1e000d","best_bid":"0.13","best_ask":"0.14"}],"timestamp":"1776808414913","event_type":"price_change"}}
{"capturedAt":1776808414,"payload":{"market":"0x125149c5918fc5f8c6d34682f700a898a1a19ea4f4e2ae68ff4c5794ba657074","price_changes":[{"asset_id":"45936375922793925919605092352922707796689801895417366600539442410775071099958","price":"0.86","size":"394.13","side":"BUY","hash":"653571833937741523bb29a0e68a0ec00a0923f2","best_bid":"0.86","best_ask":"0.87"},{"asset_id":"86520121088881862182423437128238697252500151785248183602134095101149900014256","price":"0.14","size":"394.13","side":"SELL","hash":"04c2bbd64665ada0410acfd4386dbc63265e16ab","best_bid":"0.13","best_ask":"0.14"}],"timestamp":"1776808414910","event_type":"price_change"}}
{"capturedAt":1776808414,"payload":{"market":"0x125149c5918fc5f8c6d34682f700a898a1a19ea4f4e2ae68ff4c5794ba657074","price_changes":[{"asset_id":"45936375922793925919605092352922707796689801895417366600539442410775071099958","price":"0.86","size":"344.13","side":"BUY","hash":"a52c38f69a5ecf4125ca650ec1cee41f9e78fdaf","best_bid":"0.86","best_ask":"0.87"},{"asset_id":"86520121088881862182423437128238697252500151785248183602134095101149900014256","price":"0.14","size":"344.13","side":"SELL","hash":"27299cef2c3bf485b7246e943a2c90639ce8c6b7","best_bid":"0.13","best_ask":"0.14"}],"timestamp":"1776808414912","event_type":"price_change"}}
{"capturedAt":1776808414,"payload":{"market":"0x125149c5918fc5f8c6d34682f700a898a1a19ea4f4e2ae68ff4c5794ba657074","price_changes":[{"asset_id":"45936375922793925919605092352922707796689801895417366600539442410775071099958","price":"0.92","size":"656.9","side":"SELL","hash":"b49e608293e9560d7a6ee9bc149630a42f470f6d","best_bid":"0.86","best_ask":"0.87"},{"asset_id":"86520121088881862182423437128238697252500151785248183602134095101149900014256","price":"0.08","size":"656.9","side":"BUY","hash":"c21a0f4e1a6487a5a31aca4992647198c42fedba","best_bid":"0.13","best_ask":"0.14"}],"timestamp":"1776808414919","event_type":"price_change"}}
{"capturedAt":1776808414,"payload":{"market":"0x125149c5918fc5f8c6d34682f700a898a1a19ea4f4e2ae68ff4c5794ba657074","price_changes":[{"asset_id":"45936375922793925919605092352922707796689801895417366600539442410775071099958","price":"0.86","size":"321.13","side":"BUY","hash":"f8146f061c999e87cb427e20a21c3ad40203be36","best_bid":"0.86","best_ask":"0.87"},{"asset_id":"86520121088881862182423437128238697252500151785248183602134095101149900014256","price":"0.14","size":"321.13","side":"SELL","hash":"66c96c8232252256fc22a6d6d7e22d17414e6706","best_bid":"0.13","best_ask":"0.14"}],"timestamp":"1776808414920","event_type":"price_change"}}
{"capturedAt":1776808414,"payload":{"market":"0x125149c5918fc5f8c6d34682f700a898a1a19ea4f4e2ae68ff4c5794ba657074","price_changes":[{"asset_id":"45936375922793925919605092352922707796689801895417366600539442410775071099958","price":"0.79","size":"214.7","side":"BUY","hash":"e31cdba47dc3b44e57de4bad6903cc306aec6440","best_bid":"0.86","best_ask":"0.87"},{"asset_id":"86520121088881862182423437128238697252500151785248183602134095101149900014256","price":"0.21","size":"214.7","side":"SELL","hash":"ddac93811b72a5ce0a0f68029fac2cce8c25cb63","best_bid":"0.13","best_ask":"0.14"}],"timestamp":"1776808414928","event_type":"price_change"}}
{"capturedAt":1776808414,"payload":{"market":"0x125149c5918fc5f8c6d34682f700a898a1a19ea4f4e2ae68ff4c5794ba657074","asset_id":"45936375922793925919605092352922707796689801895417366600539442410775071099958","best_bid":"0.86","best_ask":"0.87","spread":"0.01","timestamp":"1776808414932","event_type":"best_bid_ask"}}
{"capturedAt":1776808414,"payload":{"market":"0x125149c5918fc5f8c6d34682f700a898a1a19ea4f4e2ae68ff4c5794ba657074","price_changes":[{"asset_id":"45936375922793925919605092352922707796689801895417366600539442410775071099958","price":"0.86","size":"409.13","side":"BUY","hash":"94064516e3b12645dfd0f5d2d5605f97f0026200","best_bid":"0.86","best_ask":"0.87"},{"asset_id":"86520121088881862182423437128238697252500151785248183602134095101149900014256","price":"0.14","size":"409.13","side":"SELL","hash":"7f83238407df3e57be3cfab58d82b27470cd4a7f","best_bid":"0.13","best_ask":"0.14"}],"timestamp":"1776808414910","event_type":"price_change"}}
{"capturedAt":1776808414,"payload":{"market":"0x125149c5918fc5f8c6d34682f700a898a1a19ea4f4e2ae68ff4c5794ba657074","price_changes":[{"asset_id":"45936375922793925919605092352922707796689801895417366600539442410775071099958","price":"0.86","size":"320.76","side":"BUY","hash":"59bc4aa5bbda53247f0e71c098cc507a7364e15c","best_bid":"0.86","best_ask":"0.87"},{"asset_id":"86520121088881862182423437128238697252500151785248183602134095101149900014256","price":"0.14","size":"320.76","side":"SELL","hash":"fa30697381b87c2bde885dc004a1b207bc2f9720","best_bid":"0.13","best_ask":"0.14"}],"timestamp":"1776808414931","event_type":"price_change"}}
{"capturedAt":1776808414,"payload":{"market":"0x125149c5918fc5f8c6d34682f700a898a1a19ea4f4e2ae68ff4c5794ba657074","price_changes":[{"asset_id":"45936375922793925919605092352922707796689801895417366600539442410775071099958","price":"0.01","size":"12334.83","side":"BUY","hash":"7ba143f84568867e788a8e4b6493140926176583","best_bid":"0.86","best_ask":"0.87"},{"asset_id":"86520121088881862182423437128238697252500151785248183602134095101149900014256","price":"0.99","size":"12334.83","side":"SELL","hash":"9b82a9423061ecd1b5b020acef38dd1c0fdf07db","best_bid":"0.13","best_ask":"0.14"}],"timestamp":"1776808414924","event_type":"price_change"}}
{"capturedAt":1776808414,"payload":{"market":"0x125149c5918fc5f8c6d34682f700a898a1a19ea4f4e2ae68ff4c5794ba657074","price_changes":[{"asset_id":"45936375922793925919605092352922707796689801895417366600539442410775071099958","price":"0.86","size":"369.13","side":"BUY","hash":"43fc3c774d6d484adcdde8eaefa540fb295761bd","best_bid":"0.86","best_ask":"0.87"},{"asset_id":"86520121088881862182423437128238697252500151785248183602134095101149900014256","price":"0.14","size":"369.13","side":"SELL","hash":"63db0d5981961ee27d6e7f0bab608e5d98454492","best_bid":"0.13","best_ask":"0.14"}],"timestamp":"1776808414911","event_type":"price_change"}}
{"capturedAt":1776808414,"payload":{"market":"0x125149c5918fc5f8c6d34682f700a898a1a19ea4f4e2ae68ff4c5794ba657074","asset_id":"45936375922793925919605092352922707796689801895417366600539442410775071099958","price":"0.87","size":"1.149423","fee_rate_bps":"1000","side":"BUY","timestamp":"1776808414905","event_type":"last_trade_price","transaction_hash":"0x7ee37fa7068810220caa593267cc65623f5c369d9bb766005c1ad76a94b643ce"}}
{"capturedAt":1776808414,"payload":{"market":"0x125149c5918fc5f8c6d34682f700a898a1a19ea4f4e2ae68ff4c5794ba657074","asset_id":"45936375922793925919605092352922707796689801895417366600539442410775071099958","bids":[{"price":"0.01","size":"12334.83"},{"price":"0.02","size":"1715.28"},{"price":"0.03","size":"1338.69"},{"price":"0.04","size":"583.84"},{"price":"0.05","size":"1006.34"},{"price":"0.06","size":"392.8"},{"price":"0.07","size":"304.69"},{"price":"0.08","size":"278.9"},{"price":"0.09","size":"225"},{"price":"0.1","size":"282"},{"price":"0.11","size":"217.79"},{"price":"0.12","size":"215.1"},{"price":"0.13","size":"202.8"},{"price":"0.14","size":"200.9"},{"price":"0.15","size":"209.2"},{"price":"0.16","size":"197.8"},{"price":"0.17","size":"202.39"},{"price":"0.18","size":"200.4"},{"price":"0.19","size":"194.4"},{"price":"0.2","size":"193.5"},{"price":"0.21","size":"215.31"},{"price":"0.22","size":"197"},{"price":"0.23","size":"229.34"},{"price":"0.24","size":"195.7"},{"price":"0.25","size":"190.2"},{"price":"0.26","size":"189.7"},{"price":"0.27","size":"194.3"},{"price":"0.28","size":"188.89"},{"price":"0.29","size":"188.5"},{"price":"0.3","size":"206.48"},{"price":"0.31","size":"394.45"},{"price":"0.32","size":"187.5"},{"price":"0.33","size":"193.55"},{"price":"0.34","size":"187"},{"price":"0.35","size":"602.68"},{"price":"0.36","size":"186.6"},{"price":"0.37","size":"191.96"},{"price":"0.38","size":"186.3"},{"price":"0.39","size":"491.36"},{"price":"0.4","size":"226"},{"price":"0.41","size":"203.32"},{"price":"0.42","size":"185.8"},{"price":"0.43","size":"190.8"},{"price":"0.44","size":"190.6"},{"price":"0.45","size":"230.58"},{"price":"0.46","size":"224.63"},{"price":"0.47","size":"245.86"},{"price":"0.48","size":"242.56"},{"price":"0.49","size":"227.4"},{"price":"0.5","size":"378.64"},{"price":"0.51","size":"205.25"},{"price":"0.52","size":"226.77"},{"price":"0.53","size":"136.71"},{"price":"0.54","size":"185.5"},{"price":"0.55","size":"213.66"},{"price":"0.56","size":"190.6"},{"price":"0.57","size":"180.7"},{"price":"0.58","size":"180.8"},{"price":"0.59","size":"180.9"},{"price":"0.6","size":"139"},{"price":"0.61","size":"185.46"},{"price":"0.62","size":"141.3"},{"price":"0.63","size":"131.4"},{"price":"0.64","size":"131.6"},{"price":"0.65","size":"136.8"},{"price":"0.66","size":"342"},{"price":"0.67","size":"232.3"},{"price":"0.68","size":"382.5"},{"price":"0.69","size":"182.8"},{"price":"0.7","size":"244.95"},{"price":"0.71","size":"405.5"},{"price":"0.72","size":"530.89"},{"price":"0.73","size":"217.3"},{"price":"0.74","size":"287.7"},{"price":"0.75","size":"382.29"},{"price":"0.76","size":"148.49"},{"price":"0.77","size":"221.3"},{"price":"0.78","size":"323.98"},{"price":"0.79","size":"214.7"},{"price":"0.8","size":"245.25"},{"price":"0.81","size":"304.9"},{"price":"0.82","size":"325.78"},{"price":"0.83","size":"353.3"},{"price":"0.84","size":"384.37"},{"price":"0.85","size":"419.78"},{"price":"0.86","size":"320.76"}],"asks":[{"price":"0.99","size":"12902.69"},{"price":"0.98","size":"1746.16"},{"price":"0.97","size":"1413.83"},{"price":"0.96","size":"932.3"},{"price":"0.95","size":"796.63"},{"price":"0.94","size":"395.8"},{"price":"0.93","size":"682.3"},{"price":"0.92","size":"656.9"},{"price":"0.91","size":"267.44"},{"price":"0.9","size":"793.5"},{"price":"0.89","size":"339"},{"price":"0.88","size":"301"},{"price":"0.87","size":"257.2"}],"hash":"59bc4aa5bbda53247f0e71c098cc507a7364e15c","timestamp":"1776808414931","event_type":"book"}}
{"capturedAt":1776808414,"payload":{"market":"0x125149c5918fc5f8c6d34682f700a898a1a19ea4f4e2ae68ff4c5794ba657074","asset_id":"86520121088881862182423437128238697252500151785248183602134095101149900014256","best_bid":"0.13","best_ask":"0.14","spread":"0.01","timestamp":"1776808414932","event_type":"best_bid_ask"}}
{"capturedAt":1776808414,"payload":{"market":"0x125149c5918fc5f8c6d34682f700a898a1a19ea4f4e2ae68ff4c5794ba657074","price_changes":[{"asset_id":"45936375922793925919605092352922707796689801895417366600539442410775071099958","price":"0.86","size":"309.76","side":"BUY","hash":"f267c787da4a322e1530cc62b0408e94d9fe2550","best_bid":"0.86","best_ask":"0.87"},{"asset_id":"86520121088881862182423437128238697252500151785248183602134095101149900014256","price":"0.14","size":"309.76","side":"SELL","hash":"e82c9158b95a2f8a6c6a1c418dcefd0472217f67","best_bid":"0.13","best_ask":"0.14"}],"timestamp":"1776808414933","event_type":"price_change"}}
{"capturedAt":1776808414,"payload":{"market":"0x125149c5918fc5f8c6d34682f700a898a1a19ea4f4e2ae68ff4c5794ba657074","asset_id":"86520121088881862182423437128238697252500151785248183602134095101149900014256","bids":[{"price":"0.01","size":"12902.69"},{"price":"0.02","size":"1746.16"},{"price":"0.03","size":"1413.83"},{"price":"0.04","size":"932.3"},{"price":"0.05","size":"796.63"},{"price":"0.06","size":"395.8"},{"price":"0.07","size":"682.3"},{"price":"0.08","size":"656.9"},{"price":"0.09","size":"267.44"},{"price":"0.1","size":"793.5"},{"price":"0.11","size":"339"},{"price":"0.12","size":"301"},{"price":"0.13","size":"257.2"}],"asks":[{"price":"0.99","size":"12334.83"},{"price":"0.98","size":"1715.28"},{"price":"0.97","size":"1338.69"},{"price":"0.96","size":"583.84"},{"price":"0.95","size":"1006.34"},{"price":"0.94","size":"392.8"},{"price":"0.93","size":"304.69"},{"price":"0.92","size":"278.9"},{"price":"0.91","size":"225"},{"price":"0.9","size":"282"},{"price":"0.89","size":"217.79"},{"price":"0.88","size":"215.1"},{"price":"0.87","size":"202.8"},{"price":"0.86","size":"200.9"},{"price":"0.85","size":"209.2"},{"price":"0.84","size":"197.8"},{"price":"0.83","size":"202.39"},{"price":"0.82","size":"200.4"},{"price":"0.81","size":"194.4"},{"price":"0.8","size":"193.5"},{"price":"0.79","size":"215.31"},{"price":"0.78","size":"197"},{"price":"0.77","size":"229.34"},{"price":"0.76","size":"195.7"},{"price":"0.75","size":"190.2"},{"price":"0.74","size":"189.7"},{"price":"0.73","size":"194.3"},{"price":"0.72","size":"188.89"},{"price":"0.71","size":"188.5"},{"price":"0.7","size":"206.48"},{"price":"0.69","size":"394.45"},{"price":"0.68","size":"187.5"},{"price":"0.67","size":"193.55"},{"price":"0.66","size":"187"},{"price":"0.65","size":"602.68"},{"price":"0.64","size":"186.6"},{"price":"0.63","size":"191.96"},{"price":"0.62","size":"186.3"},{"price":"0.61","size":"491.36"},{"price":"0.6","size":"226"},{"price":"0.59","size":"203.32"},{"price":"0.58","size":"185.8"},{"price":"0.57","size":"190.8"},{"price":"0.56","size":"190.6"},{"price":"0.55","size":"230.58"},{"price":"0.54","size":"224.63"},{"price":"0.53","size":"245.86"},{"price":"0.52","size":"242.56"},{"price":"0.51","size":"227.4"},{"price":"0.5","size":"378.64"},{"price":"0.49","size":"205.25"},{"price":"0.48","size":"226.77"},{"price":"0.47","size":"136.71"},{"price":"0.46","size":"185.5"},{"price":"0.45","size":"213.66"},{"price":"0.44","size":"190.6"},{"price":"0.43","size":"180.7"},{"price":"0.42","size":"180.8"},{"price":"0.41","size":"180.9"},{"price":"0.4","size":"139"},{"price":"0.39","size":"185.46"},{"price":"0.38","size":"141.3"},{"price":"0.37","size":"131.4"},{"price":"0.36","size":"131.6"},{"price":"0.35","size":"136.8"},{"price":"0.34","size":"342"},{"price":"0.33","size":"232.3"},{"price":"0.32","size":"382.5"},{"price":"0.31","size":"182.8"},{"price":"0.3","size":"244.95"},{"price":"0.29","size":"405.5"},{"price":"0.28","size":"530.89"},{"price":"0.27","size":"217.3"},{"price":"0.26","size":"287.7"},{"price":"0.25","size":"382.29"},{"price":"0.24","size":"148.49"},{"price":"0.23","size":"221.3"},{"price":"0.22","size":"323.98"},{"price":"0.21","size":"214.7"},{"price":"0.2","size":"245.25"},{"price":"0.19","size":"304.9"},{"price":"0.18","size":"325.78"},{"price":"0.17","size":"353.3"},{"price":"0.16","size":"384.37"},{"price":"0.15","size":"419.78"},{"price":"0.14","size":"320.76"}],"hash":"fa30697381b87c2bde885dc004a1b207bc2f9720","timestamp":"1776808414931","event_type":"book"}}
{"capturedAt":1776808414,"payload":{"market":"0x125149c5918fc5f8c6d34682f700a898a1a19ea4f4e2ae68ff4c5794ba657074","price_changes":[{"asset_id":"45936375922793925919605092352922707796689801895417366600539442410775071099958","price":"0.86","size":"288.76","side":"BUY","hash":"4e5371a1ab06a315bcba8459213240b0431b0ae6","best_bid":"0.86","best_ask":"0.87"},{"asset_id":"86520121088881862182423437128238697252500151785248183602134095101149900014256","price":"0.14","size":"288.76","side":"SELL","hash":"165248457948e89e6e107fdb098b74ba94ba15b9","best_bid":"0.13","best_ask":"0.14"}],"timestamp":"1776808414934","event_type":"price_change"}}
{"capturedAt":1776808414,"payload":{"market":"0x125149c5918fc5f8c6d34682f700a898a1a19ea4f4e2ae68ff4c5794ba657074","price_changes":[{"asset_id":"45936375922793925919605092352922707796689801895417366600539442410775071099958","price":"0.86","size":"331.76","side":"BUY","hash":"c5e75b5ce5d6337bbfedc7dca4c49867e9c2131e","best_bid":"0.86","best_ask":"0.87"},{"asset_id":"86520121088881862182423437128238697252500151785248183602134095101149900014256","price":"0.14","size":"331.76","side":"SELL","hash":"edca2198917ece164b3784e96e2c11d214b43ee3","best_bid":"0.13","best_ask":"0.14"}],"timestamp":"1776808414932","event_type":"price_change"}}
{"capturedAt":1776808414,"payload":{"market":"0x125149c5918fc5f8c6d34682f700a898a1a19ea4f4e2ae68ff4c5794ba657074","price_changes":[{"asset_id":"45936375922793925919605092352922707796689801895417366600539442410775071099958","price":"0.86","size":"278.76","side":"BUY","hash":"2f77b68dcd21933bd5760dc7a25a05587287efe2","best_bid":"0.86","best_ask":"0.87"},{"asset_id":"86520121088881862182423437128238697252500151785248183602134095101149900014256","price":"0.14","size":"278.76","side":"SELL","hash":"60ac3aaedfe2e0daee1304244dc73aedab8deb4f","best_bid":"0.13","best_ask":"0.14"}],"timestamp":"1776808414935","event_type":"price_change"}}
{"capturedAt":1776808414,"payload":{"market":"0x125149c5918fc5f8c6d34682f700a898a1a19ea4f4e2ae68ff4c5794ba657074","price_changes":[{"asset_id":"45936375922793925919605092352922707796689801895417366600539442410775071099958","price":"0.01","size":"12329.83","side":"BUY","hash":"a41f5878585fb1864a476e641270c718fbcd1853","best_bid":"0.86","best_ask":"0.87"},{"asset_id":"86520121088881862182423437128238697252500151785248183602134095101149900014256","price":"0.99","size":"12329.83","side":"SELL","hash":"56731b73ae44e182dbbcd7bde120b340facfd2d9","best_bid":"0.13","best_ask":"0.14"}],"timestamp":"1776808414934","event_type":"price_change"}}
{"capturedAt":1776808414,"payload":{"market":"0x125149c5918fc5f8c6d34682f700a898a1a19ea4f4e2ae68ff4c5794ba657074","price_changes":[{"asset_id":"45936375922793925919605092352922707796689801895417366600539442410775071099958","price":"0.86","size":"289.76","side":"BUY","hash":"94708e3f0331bf5c57873bbceca9a96f96bdeb60","best_bid":"0.86","best_ask":"0.87"},{"asset_id":"86520121088881862182423437128238697252500151785248183602134095101149900014256","price":"0.14","size":"289.76","side":"SELL","hash":"b89f1df32fcbbb1442b13c37125a03364fa5068e","best_bid":"0.13","best_ask":"0.14"}],"timestamp":"1776808414936","event_type":"price_change"}}
{"capturedAt":1776808414,"payload":{"market":"0x125149c5918fc5f8c6d34682f700a898a1a19ea4f4e2ae68ff4c5794ba657074","price_changes":[{"asset_id":"45936375922793925919605092352922707796689801895417366600539442410775071099958","price":"0.86","size":"247.76","side":"BUY","hash":"3b4d127765809616862737c7ca489561627facbe","best_bid":"0.86","best_ask":"0.87"},{"asset_id":"86520121088881862182423437128238697252500151785248183602134095101149900014256","price":"0.14","size":"247.76","side":"SELL","hash":"35a19e894d95d72d15f38ac61a692b2ddbc4af3f","best_bid":"0.13","best_ask":"0.14"}],"timestamp":"1776808414938","event_type":"price_change"}}
{"capturedAt":1776808414,"payload":{"market":"0x125149c5918fc5f8c6d34682f700a898a1a19ea4f4e2ae68ff4c5794ba657074","price_changes":[{"asset_id":"45936375922793925919605092352922707796689801895417366600539442410775071099958","price":"0.86","size":"242.65","side":"BUY","hash":"4af6b0f859b98641f8519ca0cacc591c5de04bf6","best_bid":"0.86","best_ask":"0.87"},{"asset_id":"86520121088881862182423437128238697252500151785248183602134095101149900014256","price":"0.14","size":"242.65","side":"SELL","hash":"180d8fc409c7c91675fbe71c2077bc6621b3a737","best_bid":"0.13","best_ask":"0.14"}],"timestamp":"1776808414939","event_type":"price_change"}}
{"capturedAt":1776808414,"payload":{"market":"0x125149c5918fc5f8c6d34682f700a898a1a19ea4f4e2ae68ff4c5794ba657074","price_changes":[{"asset_id":"45936375922793925919605092352922707796689801895417366600539442410775071099958","price":"0.86","size":"247.73","side":"BUY","hash":"0fa159b6faec0a11823fb5f0c86d06f8bddc5337","best_bid":"0.86","best_ask":"0.87"},{"asset_id":"86520121088881862182423437128238697252500151785248183602134095101149900014256","price":"0.14","size":"247.73","side":"SELL","hash":"8a0a37eb92bb6e712112fbf8ae96084cbefcb3e5","best_bid":"0.13","best_ask":"0.14"}],"timestamp":"1776808414941","event_type":"price_change"}}
{"capturedAt":1776808414,"payload":{"market":"0x125149c5918fc5f8c6d34682f700a898a1a19ea4f4e2ae68ff4c5794ba657074","price_changes":[{"asset_id":"45936375922793925919605092352922707796689801895417366600539442410775071099958","price":"0.86","size":"268.76","side":"BUY","hash":"61565cc245e0df62c3ca566d37f4b3ad16e16805","best_bid":"0.86","best_ask":"0.87"},{"asset_id":"86520121088881862182423437128238697252500151785248183602134095101149900014256","price":"0.14","size":"268.76","side":"SELL","hash":"6fd3d9e24c646e644eb406bae15a76d95fc62705","best_bid":"0.13","best_ask":"0.14"}],"timestamp":"1776808414937","event_type":"price_change"}}
{"capturedAt":1776808414,"payload":{"market":"0x125149c5918fc5f8c6d34682f700a898a1a19ea4f4e2ae68ff4c5794ba657074","price_changes":[{"asset_id":"45936375922793925919605092352922707796689801895417366600539442410775071099958","price":"0.86","size":"254.73","side":"BUY","hash":"f5f26899a6a653b11f5a0e5ce12bfd8865ba5eba","best_bid":"0.86","best_ask":"0.87"},{"asset_id":"86520121088881862182423437128238697252500151785248183602134095101149900014256","price":"0.14","size":"254.73","side":"SELL","hash":"bd2546cee0d545d2a74ee10a2ccd85bae4bf1a6d","best_bid":"0.13","best_ask":"0.14"}],"timestamp":"1776808414949","event_type":"price_change"}}
{"capturedAt":1776808414,"payload":{"market":"0x125149c5918fc5f8c6d34682f700a898a1a19ea4f4e2ae68ff4c5794ba657074","price_changes":[{"asset_id":"45936375922793925919605092352922707796689801895417366600539442410775071099958","price":"0.86","size":"285.73","side":"BUY","hash":"097d8f773c2a38a95cae14887fb8a1ef6818cae8","best_bid":"0.86","best_ask":"0.87"},{"asset_id":"86520121088881862182423437128238697252500151785248183602134095101149900014256","price":"0.14","size":"285.73","side":"SELL","hash":"2157a36b84f1b37c001ef2ac1d6ca86e25966f83","best_bid":"0.13","best_ask":"0.14"}],"timestamp":"1776808414942","event_type":"price_change"}}
{"capturedAt":1776808414,"payload":{"market":"0x125149c5918fc5f8c6d34682f700a898a1a19ea4f4e2ae68ff4c5794ba657074","price_changes":[{"asset_id":"45936375922793925919605092352922707796689801895417366600539442410775071099958","price":"0.86","size":"264.73","side":"BUY","hash":"8bcbe527a28f19046d79dfb5e5aecbf26fe601a9","best_bid":"0.86","best_ask":"0.87"},{"asset_id":"86520121088881862182423437128238697252500151785248183602134095101149900014256","price":"0.14","size":"264.73","side":"SELL","hash":"ecc3bbaf849ee815245b36a03311fdb78a28d477","best_bid":"0.13","best_ask":"0.14"}],"timestamp":"1776808414945","event_type":"price_change"}}
{"capturedAt":1776808414,"payload":{"market":"0x125149c5918fc5f8c6d34682f700a898a1a19ea4f4e2ae68ff4c5794ba657074","price_changes":[{"asset_id":"45936375922793925919605092352922707796689801895417366600539442410775071099958","price":"0.86","size":"266.73","side":"BUY","hash":"a5866025651ad3a3340884184a56280a9e450b72","best_bid":"0.86","best_ask":"0.87"},{"asset_id":"86520121088881862182423437128238697252500151785248183602134095101149900014256","price":"0.14","size":"266.73","side":"SELL","hash":"775786d8e457fe30ff293de5d6897482fdcf71c3","best_bid":"0.13","best_ask":"0.14"}],"timestamp":"1776808414942","event_type":"price_change"}}
{"capturedAt":1776808414,"payload":{"market":"0x125149c5918fc5f8c6d34682f700a898a1a19ea4f4e2ae68ff4c5794ba657074","price_changes":[{"asset_id":"45936375922793925919605092352922707796689801895417366600539442410775071099958","price":"0.86","size":"264.73","side":"BUY","hash":"ba2572d06e9172076979ab4e72b4bc924b09ce14","best_bid":"0.86","best_ask":"0.87"},{"asset_id":"86520121088881862182423437128238697252500151785248183602134095101149900014256","price":"0.14","size":"264.73","side":"SELL","hash":"dbcca1255a9d83a58b9b301d699d59142b7aad77","best_bid":"0.13","best_ask":"0.14"}],"timestamp":"1776808414950","event_type":"price_change"}}
{"capturedAt":1776808414,"payload":{"market":"0x125149c5918fc5f8c6d34682f700a898a1a19ea4f4e2ae68ff4c5794ba657074","price_changes":[{"asset_id":"45936375922793925919605092352922707796689801895417366600539442410775071099958","price":"0.86","size":"284.73","side":"BUY","hash":"1cf15463923547122dfff82e60a9c0fad238dd30","best_bid":"0.86","best_ask":"0.87"},{"asset_id":"86520121088881862182423437128238697252500151785248183602134095101149900014256","price":"0.14","size":"284.73","side":"SELL","hash":"ecfd5bfdd199cc6e3401a076a1fa9922b50b9b4d","best_bid":"0.13","best_ask":"0.14"}],"timestamp":"1776808414957","event_type":"price_change"}}
{"capturedAt":1776808414,"payload":{"market":"0x125149c5918fc5f8c6d34682f700a898a1a19ea4f4e2ae68ff4c5794ba657074","price_changes":[{"asset_id":"45936375922793925919605092352922707796689801895417366600539442410775071099958","price":"0.86","size":"244.73","side":"BUY","hash":"f1bc92f1c244ba905a594b465657c376690e9e6e","best_bid":"0.86","best_ask":"0.87"},{"asset_id":"86520121088881862182423437128238697252500151785248183602134095101149900014256","price":"0.14","size":"244.73","side":"SELL","hash":"876f31651ad243e3842ef39e9369a78700942b6e","best_bid":"0.13","best_ask":"0.14"}],"timestamp":"1776808414949","event_type":"price_change"}}
{"capturedAt":1776808414,"payload":{"market":"0x125149c5918fc5f8c6d34682f700a898a1a19ea4f4e2ae68ff4c5794ba657074","price_changes":[{"asset_id":"45936375922793925919605092352922707796689801895417366600539442410775071099958","price":"0.01","size":"12324.83","side":"BUY","hash":"12aa85c048e57d1d2a078de884f1b933f2974ab7","best_bid":"0.86","best_ask":"0.87"},{"asset_id":"86520121088881862182423437128238697252500151785248183602134095101149900014256","price":"0.99","size":"12324.83","side":"SELL","hash":"9f897619b4a2105122fbb21f33a1b58af5d3dc4f","best_bid":"0.13","best_ask":"0.14"}],"timestamp":"1776808414943","event_type":"price_change"}}
{"capturedAt":1776808414,"payload":{"market":"0x125149c5918fc5f8c6d34682f700a898a1a19ea4f4e2ae68ff4c5794ba657074","price_changes":[{"asset_id":"45936375922793925919605092352922707796689801895417366600539442410775071099958","price":"0.86","size":"263.73","side":"BUY","hash":"ad7a63dc73c21ffea89fb4443cd9a5944c8874f1","best_bid":"0.86","best_ask":"0.87"},{"asset_id":"86520121088881862182423437128238697252500151785248183602134095101149900014256","price":"0.14","size":"263.73","side":"SELL","hash":"1e0cdc600d4f58e327609961f90d584b38994134","best_bid":"0.13","best_ask":"0.14"}],"timestamp":"1776808414958","event_type":"price_change"}}
{"capturedAt":1776808414,"payload":{"market":"0x125149c5918fc5f8c6d34682f700a898a1a19ea4f4e2ae68ff4c5794ba657074","price_changes":[{"asset_id":"45936375922793925919605092352922707796689801895417366600539442410775071099958","price":"0.86","size":"288.65","side":"BUY","hash":"36ff39b3096945912f2579680d17b8fe96aca4b9","best_bid":"0.86","best_ask":"0.87"},{"asset_id":"86520121088881862182423437128238697252500151785248183602134095101149900014256","price":"0.14","size":"288.65","side":"SELL","hash":"09b42efd621d01c20a3c8f31df9de59fc606b188","best_bid":"0.13","best_ask":"0.14"}],"timestamp":"1776808414960","event_type":"price_change"}}
{"capturedAt":1776808414,"payload":{"market":"0x125149c5918fc5f8c6d34682f700a898a1a19ea4f4e2ae68ff4c5794ba657074","price_changes":[{"asset_id":"45936375922793925919605092352922707796689801895417366600539442410775071099958","price":"0.79","size":"219.7","side":"BUY","hash":"15da4b1173d1b38f5169ed43154c06ca0ed99b95","best_bid":"0.86","best_ask":"0.87"},{"asset_id":"86520121088881862182423437128238697252500151785248183602134095101149900014256","price":"0.21","size":"219.7","side":"SELL","hash":"174a07d72168a340eadd8cc41abb8803cc75ee35","best_bid":"0.13","best_ask":"0.14"}],"timestamp":"1776808414951","event_type":"price_change"}}
{"capturedAt":1776808414,"payload":{"market":"0x125149c5918fc5f8c6d34682f700a898a1a19ea4f4e2ae68ff4c5794ba657074","asset_id":"45936375922793925919605092352922707796689801895417366600539442410775071099958","price":"0.86","size":"0.37","fee_rate_bps":"1000","side":"SELL","timestamp":"1776808414952","event_type":"last_trade_price","transaction_hash":"0x4da60e249b17196a28d63d8c0ab331b7b42c2a29b189edba04589d28dcbb8410"}}
{"capturedAt":1776808414,"payload":{"market":"0x125149c5918fc5f8c6d34682f700a898a1a19ea4f4e2ae68ff4c5794ba657074","price_changes":[{"asset_id":"45936375922793925919605092352922707796689801895417366600539442410775071099958","price":"0.86","size":"283.73","side":"BUY","hash":"604bd1ea732e64423ce22888f27c11beb91ba05e","best_bid":"0.86","best_ask":"0.87"},{"asset_id":"86520121088881862182423437128238697252500151785248183602134095101149900014256","price":"0.14","size":"283.73","side":"SELL","hash":"8312a8726ac377a4bfbe11b99c9e856e14b5fb54","best_bid":"0.13","best_ask":"0.14"}],"timestamp":"1776808414959","event_type":"price_change"}}
{"capturedAt":1776808414,"payload":{"market":"0x125149c5918fc5f8c6d34682f700a898a1a19ea4f4e2ae68ff4c5794ba657074","price_changes":[{"asset_id":"45936375922793925919605092352922707796689801895417366600539442410775071099958","price":"0.86","size":"293.73","side":"BUY","hash":"b11359ef3f777ccfffc19762d00ff1e5093bdd94","best_bid":"0.86","best_ask":"0.87"},{"asset_id":"86520121088881862182423437128238697252500151785248183602134095101149900014256","price":"0.14","size":"293.73","side":"SELL","hash":"a478f0e9c7ecafb166fbdc31dff44daf7185d34b","best_bid":"0.13","best_ask":"0.14"}],"timestamp":"1776808414960","event_type":"price_change"}}
{"capturedAt":1776808414,"payload":{"market":"0x125149c5918fc5f8c6d34682f700a898a1a19ea4f4e2ae68ff4c5794ba657074","price_changes":[{"asset_id":"45936375922793925919605092352922707796689801895417366600539442410775071099958","price":"0.01","size":"12329.83","side":"BUY","hash":"46bdde65163583e7648c6415d2460c7294f1d017","best_bid":"0.86","best_ask":"0.87"},{"asset_id":"86520121088881862182423437128238697252500151785248183602134095101149900014256","price":"0.99","size":"12329.83","side":"SELL","hash":"a79ddcf63d6e6de3ca5dd80188ec704111d66743","best_bid":"0.13","best_ask":"0.14"}],"timestamp":"1776808414963","event_type":"price_change"}}
{"capturedAt":1776808414,"payload":{"market":"0x125149c5918fc5f8c6d34682f700a898a1a19ea4f4e2ae68ff4c5794ba657074","price_changes":[{"asset_id":"45936375922793925919605092352922707796689801895417366600539442410775071099958","price":"0.01","size":"12334.83","side":"BUY","hash":"614c730942a0e139aecd97eade98497eeeaa5b17","best_bid":"0.86","best_ask":"0.87"},{"asset_id":"86520121088881862182423437128238697252500151785248183602134095101149900014256","price":"0.99","size":"12334.83","side":"SELL","hash":"b5fc356363f4c534a08c5f54140242b28dfee78c","best_bid":"0.13","best_ask":"0.14"}],"timestamp":"1776808414964","event_type":"price_change"}}
{"capturedAt":1776808414,"payload":{"market":"0x125149c5918fc5f8c6d34682f700a898a1a19ea4f4e2ae68ff4c5794ba657074","price_changes":[{"asset_id":"45936375922793925919605092352922707796689801895417366600539442410775071099958","price":"0.78","size":"328.98","side":"BUY","hash":"3aa53549d7460e6bdd7763e2f147bf956a3a8bc0","best_bid":"0.86","best_ask":"0.87"},{"asset_id":"86520121088881862182423437128238697252500151785248183602134095101149900014256","price":"0.22","size":"328.98","side":"SELL","hash":"511a87b6d007688040939b9e45c21d3e2291cdba","best_bid":"0.13","best_ask":"0.14"}],"timestamp":"1776808414973","event_type":"price_change"}}
{"capturedAt":1776808414,"payload":{"market":"0x125149c5918fc5f8c6d34682f700a898a1a19ea4f4e2ae68ff4c5794ba657074","price_changes":[{"asset_id":"45936375922793925919605092352922707796689801895417366600539442410775071099958","price":"0.86","size":"304.65","side":"BUY","hash":"e5d9ce981a6e8f9d9e94670ab37fe30df0704a4e","best_bid":"0.86","best_ask":"0.87"},{"asset_id":"86520121088881862182423437128238697252500151785248183602134095101149900014256","price":"0.14","size":"304.65","side":"SELL","hash":"aa04af12ef9f3f4252c9ff98614eab3dd2c57f65","best_bid":"0.13","best_ask":"0.14"}],"timestamp":"1776808414962","event_type":"price_change"}}
{"capturedAt":1776808414,"payload":{"market":"0x125149c5918fc5f8c6d34682f700a898a1a19ea4f4e2ae68ff4c5794ba657074","price_changes":[{"asset_id":"45936375922793925919605092352922707796689801895417366600539442410775071099958","price":"0.86","size":"325.65","side":"BUY","hash":"21b9458a2a82090ee00abfd1a91d60efdfd1fe9f","best_bid":"0.86","best_ask":"0.87"},{"asset_id":"86520121088881862182423437128238697252500151785248183602134095101149900014256","price":"0.14","size":"325.65","side":"SELL","hash":"0cf74ffe7f145969628d5732913a342d97146471","best_bid":"0.13","best_ask":"0.14"}],"timestamp":"1776808414968","event_type":"price_change"}}
{"capturedAt":1776808414,"payload":{"market":"0x125149c5918fc5f8c6d34682f700a898a1a19ea4f4e2ae68ff4c5794ba657074","price_changes":[{"asset_id":"45936375922793925919605092352922707796689801895417366600539442410775071099958","price":"0.01","size":"12339.83","side":"BUY","hash":"9283773828c54398dc7159e65d8b2d0e08323345","best_bid":"0.86","best_ask":"0.87"},{"asset_id":"86520121088881862182423437128238697252500151785248183602134095101149900014256","price":"0.99","size":"12339.83","side":"SELL","hash":"38d251cde46558c0a8c42ab57b381cd7f132b761","best_bid":"0.13","best_ask":"0.14"}],"timestamp":"1776808414975","event_type":"price_change"}}
{"capturedAt":1776808414,"payload":{"market":"0x125149c5918fc5f8c6d34682f700a898a1a19ea4f4e2ae68ff4c5794ba657074","price_changes":[{"asset_id":"45936375922793925919605092352922707796689801895417366600539442410775071099958","price":"0.86","size":"335.65","side":"BUY","hash":"66b148e09462cb22e773cadb16ee75e89a1c0991","best_bid":"0.86","best_ask":"0.87"},{"asset_id":"86520121088881862182423437128238697252500151785248183602134095101149900014256","price":"0.14","size":"335.65","side":"SELL","hash":"542308ef82a3c0fa78248437e5ae6d4302207925","best_bid":"0.13","best_ask":"0.14"}],"timestamp":"1776808414976","event_type":"price_change"}}
{"capturedAt":1776808414,"payload":{"market":"0x125149c5918fc5f8c6d34682f700a898a1a19ea4f4e2ae68ff4c5794ba657074","price_changes":[{"asset_id":"45936375922793925919605092352922707796689801895417366600539442410775071099958","price":"0.86","size":"340.7","side":"BUY","hash":"5a4ccf82bcf90ebc968afcd01da6c25e9d7c79c4","best_bid":"0.86","best_ask":"0.87"},{"asset_id":"86520121088881862182423437128238697252500151785248183602134095101149900014256","price":"0.14","size":"340.7","side":"SELL","hash":"ffb6f759befd83ee4daf4b7da1556ba102ae0e45","best_bid":"0.13","best_ask":"0.14"}],"timestamp":"1776808414979","event_type":"price_change"}}
{"capturedAt":1776808414,"payload":{"market":"0x125149c5918fc5f8c6d34682f700a898a1a19ea4f4e2ae68ff4c5794ba657074","price_changes":[{"asset_id":"86520121088881862182423437128238697252500151785248183602134095101149900014256","price":"0.11","size":"356.5","side":"BUY","hash":"3ae4e51b18eb8e3a68365aa7feb8cd60d4a004cd","best_bid":"0.13","best_ask":"0.14"},{"asset_id":"45936375922793925919605092352922707796689801895417366600539442410775071099958","price":"0.89","size":"356.5","side":"SELL","hash":"944d3f452d8e1dd351cffaf79bc23919bbbeef29","best_bid":"0.86","best_ask":"0.87"}],"timestamp":"1776808414978","event_type":"price_change"}}
{"capturedAt":1776808414,"payload":{"market":"0x125149c5918fc5f8c6d34682f700a898a1a19ea4f4e2ae68ff4c5794ba657074","price_changes":[{"asset_id":"45936375922793925919605092352922707796689801895417366600539442410775071099958","price":"0.01","size":"12334.83","side":"BUY","hash":"ff1020a815edf56884846f08086f480c6ae70001","best_bid":"0.86","best_ask":"0.87"},{"asset_id":"86520121088881862182423437128238697252500151785248183602134095101149900014256","price":"0.99","size":"12334.83","side":"SELL","hash":"a6f7f40ff69bb4a805677397e3a6eb5563f57533","best_bid":"0.13","best_ask":"0.14"}],"timestamp":"1776808414981","event_type":"price_change"}}
{"capturedAt":1776808414,"payload":{"market":"0x125149c5918fc5f8c6d34682f700a898a1a19ea4f4e2ae68ff4c5794ba657074","price_changes":[{"asset_id":"45936375922793925919605092352922707796689801895417366600539442410775071099958","price":"0.01","size":"12329.83","side":"BUY","hash":"e1c4fa0a1a9e9f8393bb4579d8a47cca6f35b18c","best_bid":"0.86","best_ask":"0.87"},{"asset_id":"86520121088881862182423437128238697252500151785248183602134095101149900014256","price":"0.99","size":"12329.83","side":"SELL","hash":"10747d69d02516ff7b1cb88e95705a7755766ea4","best_bid":"0.13","best_ask":"0.14"}],"timestamp":"1776808414983","event_type":"price_change"}}
{"capturedAt":1776808414,"payload":{"market":"0x125149c5918fc5f8c6d34682f700a898a1a19ea4f4e2ae68ff4c5794ba657074","price_changes":[{"asset_id":"45936375922793925919605092352922707796689801895417366600539442410775071099958","price":"0.86","size":"350.7","side":"BUY","hash":"9ad2261aa49d6fe5d71b637a8d3d2669e917d103","best_bid":"0.86","best_ask":"0.87"},{"asset_id":"86520121088881862182423437128238697252500151785248183602134095101149900014256","price":"0.14","size":"350.7","side":"SELL","hash":"324206315ffffb25b04dfccdcb6b3a942fb15253","best_bid":"0.13","best_ask":"0.14"}],"timestamp":"1776808414981","event_type":"price_change"}}
{"capturedAt":1776808414,"payload":{"market":"0x125149c5918fc5f8c6d34682f700a898a1a19ea4f4e2ae68ff4c5794ba657074","price_changes":[{"asset_id":"45936375922793925919605092352922707796689801895417366600539442410775071099958","price":"0.86","size":"368.7","side":"BUY","hash":"5cb9a787d496edc1a1cb8675a4f9bf01cbdec5d3","best_bid":"0.86","best_ask":"0.87"},{"asset_id":"86520121088881862182423437128238697252500151785248183602134095101149900014256","price":"0.14","size":"368.7","side":"SELL","hash":"b793b9247f8903f78d64066417c71d00a6c15c89","best_bid":"0.13","best_ask":"0.14"}],"timestamp":"1776808414986","event_type":"price_change"}}
{"capturedAt":1776808414,"payload":{"market":"0x125149c5918fc5f8c6d34682f700a898a1a19ea4f4e2ae68ff4c5794ba657074","price_changes":[{"asset_id":"45936375922793925919605092352922707796689801895417366600539442410775071099958","price":"0.86","size":"388.7","side":"BUY","hash":"f87bd3d6c4e500ec6d2ae7640a6dc2a2a532f51b","best_bid":"0.86","best_ask":"0.87"},{"asset_id":"86520121088881862182423437128238697252500151785248183602134095101149900014256","price":"0.14","size":"388.7","side":"SELL","hash":"27caa0d503ab5189874075a1eba3b7d147f68938","best_bid":"0.13","best_ask":"0.14"}],"timestamp":"1776808414989","event_type":"price_change"}}
{"capturedAt":1776808415,"payload":{"market":"0x125149c5918fc5f8c6d34682f700a898a1a19ea4f4e2ae68ff4c5794ba657074","price_changes":[{"asset_id":"45936375922793925919605092352922707796689801895417366600539442410775071099958","price":"0.01","size":"12324.83","side":"BUY","hash":"6d105dc5c3b744a6c6e12f5ffc5c7e2f604a53c4","best_bid":"0.86","best_ask":"0.87"},{"asset_id":"86520121088881862182423437128238697252500151785248183602134095101149900014256","price":"0.99","size":"12324.83","side":"SELL","hash":"081629a91b7b9895f1fb28fe3285cd6058520189","best_bid":"0.13","best_ask":"0.14"}],"timestamp":"1776808414993","event_type":"price_change"}}
{"capturedAt":1776808415,"payload":{"market":"0x125149c5918fc5f8c6d34682f700a898a1a19ea4f4e2ae68ff4c5794ba657074","price_changes":[{"asset_id":"45936375922793925919605092352922707796689801895417366600539442410775071099958","price":"0.49","size":"222.4","side":"BUY","hash":"dc34271264399664ce83623fb21711983c8801e5","best_bid":"0.86","best_ask":"0.87"},{"asset_id":"86520121088881862182423437128238697252500151785248183602134095101149900014256","price":"0.51","size":"222.4","side":"SELL","hash":"de7cf2f2f56721be73cac34ab54fad3a50437f0b","best_bid":"0.13","best_ask":"0.14"}],"timestamp":"1776808415000","event_type":"price_change"}}
{"capturedAt":1776808415,"payload":{"market":"0x125149c5918fc5f8c6d34682f700a898a1a19ea4f4e2ae68ff4c5794ba657074","price_changes":[{"asset_id":"45936375922793925919605092352922707796689801895417366600539442410775071099958","price":"0.46","size":"185.5","side":"BUY","hash":"ff95bfbd95e50dae6683f528ec96979c3fd8f77e","best_bid":"0.86","best_ask":"0.87"},{"asset_id":"86520121088881862182423437128238697252500151785248183602134095101149900014256","price":"0.54","size":"185.5","side":"SELL","hash":"56dd9725ce5134a4b2e376a0820fbd3de58dde4d","best_bid":"0.13","best_ask":"0.14"}],"timestamp":"1776808415002","event_type":"price_change"}}
{"capturedAt":1776808415,"payload":{"market":"0xdab1ff110d9d2439c5bd75c4f503ae7300457a35b124ce0c7260ec86dcc688c8","price_changes":[{"asset_id":"13917627517502768201235213826866970628416806758650647861097354638225151676696","price":"0.31","size":"1561.88","side":"BUY","hash":"d55f46eadec7980bc79f0af3ae279b61d8b56a09","best_bid":"0.5","best_ask":"0.51"},{"asset_id":"79951446619687279678993570456142474051779067785614208685555261501997794502271","price":"0.69","size":"1561.88","side":"SELL","hash":"fd7bfa76de57b319fbe7a2a9ac63c7939cf61cb9","best_bid":"0.49","best_ask":"0.5"}],"timestamp":"1776808415002","event_type":"price_change"}}
{"capturedAt":1776808415,"payload":{"market":"0x125149c5918fc5f8c6d34682f700a898a1a19ea4f4e2ae68ff4c5794ba657074","price_changes":[{"asset_id":"45936375922793925919605092352922707796689801895417366600539442410775071099958","price":"0.46","size":"185.5","side":"BUY","hash":"ff95bfbd95e50dae6683f528ec96979c3fd8f77e","best_bid":"0.86","best_ask":"0.87"},{"asset_id":"86520121088881862182423437128238697252500151785248183602134095101149900014256","price":"0.54","size":"185.5","side":"SELL","hash":"56dd9725ce5134a4b2e376a0820fbd3de58dde4d","best_bid":"0.13","best_ask":"0.14"}],"timestamp":"1776808415002","event_type":"price_change"}}
{"capturedAt":1776808415,"payload":{"market":"0xdab1ff110d9d2439c5bd75c4f503ae7300457a35b124ce0c7260ec86dcc688c8","price_changes":[{"asset_id":"79951446619687279678993570456142474051779067785614208685555261501997794502271","price":"0.31","size":"1813.66","side":"BUY","hash":"b7d2db40d3f9d94891eebfac64ae0967f6746fc4","best_bid":"0.49","best_ask":"0.5"},{"asset_id":"13917627517502768201235213826866970628416806758650647861097354638225151676696","price":"0.69","size":"1813.66","side":"SELL","hash":"cdc5989b76bdd1afe38570f18e9609ac6a53e87c","best_bid":"0.5","best_ask":"0.51"}],"timestamp":"1776808415001","event_type":"price_change"}}
{"capturedAt":1776808415,"payload":{"market":"0x125149c5918fc5f8c6d34682f700a898a1a19ea4f4e2ae68ff4c5794ba657074","price_changes":[{"asset_id":"45936375922793925919605092352922707796689801895417366600539442410775071099958","price":"0.86","size":"377.7","side":"BUY","hash":"b95311adc62305f4f01ae765eaace44791d76e06","best_bid":"0.86","best_ask":"0.87"},{"asset_id":"86520121088881862182423437128238697252500151785248183602134095101149900014256","price":"0.14","size":"377.7","side":"SELL","hash":"016ff4ef157817dc0a1250c8180589037a55e97e","best_bid":"0.13","best_ask":"0.14"}],"timestamp":"1776808415004","event_type":"price_change"}}
{"capturedAt":1776808415,"payload":{"market":"0x125149c5918fc5f8c6d34682f700a898a1a19ea4f4e2ae68ff4c5794ba657074","price_changes":[{"asset_id":"45936375922793925919605092352922707796689801895417366600539442410775071099958","price":"0.86","size":"366.7","side":"BUY","hash":"3026b90f724f9216eead252d870a841fe9a28d09","best_bid":"0.86","best_ask":"0.87"},{"asset_id":"86520121088881862182423437128238697252500151785248183602134095101149900014256","price":"0.14","size":"366.7","side":"SELL","hash":"8bfcc69558ec8df808c2d927cbb03fa0c81cd8fc","best_bid":"0.13","best_ask":"0.14"}],"timestamp":"1776808415008","event_type":"price_change"}}
{"capturedAt":1776808415,"payload":{"market":"0x125149c5918fc5f8c6d34682f700a898a1a19ea4f4e2ae68ff4c5794ba657074","price_changes":[{"asset_id":"45936375922793925919605092352922707796689801895417366600539442410775071099958","price":"0.86","size":"347.7","side":"BUY","hash":"11fdad56f59aa7ad742821a5c8e172a458f62782","best_bid":"0.86","best_ask":"0.87"},{"asset_id":"86520121088881862182423437128238697252500151785248183602134095101149900014256","price":"0.14","size":"347.7","side":"SELL","hash":"162382e155904ffa642e4e74e58346abbf7b4bc7","best_bid":"0.13","best_ask":"0.14"}],"timestamp":"1776808415012","event_type":"price_change"}}
{"capturedAt":1776808415,"payload":{"market":"0x125149c5918fc5f8c6d34682f700a898a1a19ea4f4e2ae68ff4c5794ba657074","price_changes":[{"asset_id":"45936375922793925919605092352922707796689801895417366600539442410775071099958","price":"0.86","size":"328.7","side":"BUY","hash":"d3c03b8f1f6c1d43c45060a328e5be5e0fc9dfc9","best_bid":"0.86","best_ask":"0.87"},{"asset_id":"86520121088881862182423437128238697252500151785248183602134095101149900014256","price":"0.14","size":"328.7","side":"SELL","hash":"38eb26684d5291fa8ef519471575e6c6714551a4","best_bid":"0.13","best_ask":"0.14"}],"timestamp":"1776808415013","event_type":"price_change"}}
{"capturedAt":1776808415,"payload":{"market":"0x125149c5918fc5f8c6d34682f700a898a1a19ea4f4e2ae68ff4c5794ba657074","price_changes":[{"asset_id":"45936375922793925919605092352922707796689801895417366600539442410775071099958","price":"0.01","size":"12329.83","side":"BUY","hash":"dc2fce35cf39d1838bc0947f0bb52676fb6585f9","best_bid":"0.86","best_ask":"0.87"},{"asset_id":"86520121088881862182423437128238697252500151785248183602134095101149900014256","price":"0.99","size":"12329.83","side":"SELL","hash":"2fa9a33011ab986ebf6941023ba99e9d5f95765d","best_bid":"0.13","best_ask":"0.14"}],"timestamp":"1776808415014","event_type":"price_change"}}
{"capturedAt":1776808415,"payload":{"market":"0x125149c5918fc5f8c6d34682f700a898a1a19ea4f4e2ae68ff4c5794ba657074","price_changes":[{"asset_id":"45936375922793925919605092352922707796689801895417366600539442410775071099958","price":"0.86","size":"308.7","side":"BUY","hash":"d6c5544fab310610a363d0a67cd8f7f7570b83aa","best_bid":"0.86","best_ask":"0.87"},{"asset_id":"86520121088881862182423437128238697252500151785248183602134095101149900014256","price":"0.14","size":"308.7","side":"SELL","hash":"f35cc44240dea96e3990de5d72f01b758a337206","best_bid":"0.13","best_ask":"0.14"}],"timestamp":"1776808415021","event_type":"price_change"}}
{"capturedAt":1776808415,"payload":{"market":"0x125149c5918fc5f8c6d34682f700a898a1a19ea4f4e2ae68ff4c5794ba657074","price_changes":[{"asset_id":"45936375922793925919605092352922707796689801895417366600539442410775071099958","price":"0.01","size":"12334.83","side":"BUY","hash":"dcc0fbbaae497b81bd9a5743d3acce6437dc7d92","best_bid":"0.86","best_ask":"0.87"},{"asset_id":"86520121088881862182423437128238697252500151785248183602134095101149900014256","price":"0.99","size":"12334.83","side":"SELL","hash":"2e1170717e9bb55bac69c0fe03bf275bdaa7f2e0","best_bid":"0.13","best_ask":"0.14"}],"timestamp":"1776808415024","event_type":"price_change"}}
{"capturedAt":1776808415,"payload":{"market":"0x125149c5918fc5f8c6d34682f700a898a1a19ea4f4e2ae68ff4c5794ba657074","price_changes":[{"asset_id":"45936375922793925919605092352922707796689801895417366600539442410775071099958","price":"0.86","size":"288.7","side":"BUY","hash":"75783f90ccb0506af15799c9baa2ed4092d430bf","best_bid":"0.86","best_ask":"0.87"},{"asset_id":"86520121088881862182423437128238697252500151785248183602134095101149900014256","price":"0.14","size":"288.7","side":"SELL","hash":"2546bae47d04b2af750d1c30f9341b62e3091a93","best_bid":"0.13","best_ask":"0.14"}],"timestamp":"1776808415027","event_type":"price_change"}}
{"capturedAt":1776808415,"payload":{"market":"0x125149c5918fc5f8c6d34682f700a898a1a19ea4f4e2ae68ff4c5794ba657074","price_changes":[{"asset_id":"45936375922793925919605092352922707796689801895417366600539442410775071099958","price":"0.86","size":"272.7","side":"BUY","hash":"a0364d5169b84c510d914b9f53f18b3191cdb2f6","best_bid":"0.86","best_ask":"0.87"},{"asset_id":"86520121088881862182423437128238697252500151785248183602134095101149900014256","price":"0.14","size":"272.7","side":"SELL","hash":"9228c6aaf7882746e6b104a7506141d0f11f0879","best_bid":"0.13","best_ask":"0.14"}],"timestamp":"1776808415031","event_type":"price_change"}}
{"capturedAt":1776808415,"payload":{"market":"0x125149c5918fc5f8c6d34682f700a898a1a19ea4f4e2ae68ff4c5794ba657074","price_changes":[{"asset_id":"45936375922793925919605092352922707796689801895417366600539442410775071099958","price":"0.01","size":"12329.83","side":"BUY","hash":"94c06fa91472fd05c74a9b24a8ddbf33305c41db","best_bid":"0.86","best_ask":"0.87"},{"asset_id":"86520121088881862182423437128238697252500151785248183602134095101149900014256","price":"0.99","size":"12329.83","side":"SELL","hash":"f50b3f4ac0d5303fea1fbc98fb1cf31fd31a9d27","best_bid":"0.13","best_ask":"0.14"}],"timestamp":"1776808415032","event_type":"price_change"}}
{"capturedAt":1776808415,"payload":{"market":"0x125149c5918fc5f8c6d34682f700a898a1a19ea4f4e2ae68ff4c5794ba657074","price_changes":[{"asset_id":"45936375922793925919605092352922707796689801895417366600539442410775071099958","price":"0.86","size":"284.7","side":"BUY","hash":"6f858652fddcb428d8855776167e214d8305df11","best_bid":"0.86","best_ask":"0.87"},{"asset_id":"86520121088881862182423437128238697252500151785248183602134095101149900014256","price":"0.14","size":"284.7","side":"SELL","hash":"b6ff6f3f8026c8e75a013a7489779f374ccb8642","best_bid":"0.13","best_ask":"0.14"}],"timestamp":"1776808415033","event_type":"price_change"}}
{"capturedAt":1776808415,"payload":{"market":"0x125149c5918fc5f8c6d34682f700a898a1a19ea4f4e2ae68ff4c5794ba657074","price_changes":[{"asset_id":"45936375922793925919605092352922707796689801895417366600539442410775071099958","price":"0.86","size":"274.7","side":"BUY","hash":"7d3ee739b99c0d25d96769f52b52a9d59ef14a91","best_bid":"0.86","best_ask":"0.87"},{"asset_id":"86520121088881862182423437128238697252500151785248183602134095101149900014256","price":"0.14","size":"274.7","side":"SELL","hash":"aa1427dcf7be6ccae54b0b0e45fe1949a7770614","best_bid":"0.13","best_ask":"0.14"}],"timestamp":"1776808415034","event_type":"price_change"}}
{"capturedAt":1776808415,"payload":{"market":"0x125149c5918fc5f8c6d34682f700a898a1a19ea4f4e2ae68ff4c5794ba657074","price_changes":[{"asset_id":"45936375922793925919605092352922707796689801895417366600539442410775071099958","price":"0.86","size":"286.7","side":"BUY","hash":"aa5df6a30bd8e6a17ff4a33b9c018a731c0a85bc","best_bid":"0.86","best_ask":"0.87"},{"asset_id":"86520121088881862182423437128238697252500151785248183602134095101149900014256","price":"0.14","size":"286.7","side":"SELL","hash":"66216c0603f9a0b78aaf8b3233945390e08213b3","best_bid":"0.13","best_ask":"0.14"}],"timestamp":"1776808415035","event_type":"price_change"}}
{"capturedAt":1776808415,"payload":{"market":"0x125149c5918fc5f8c6d34682f700a898a1a19ea4f4e2ae68ff4c5794ba657074","price_changes":[{"asset_id":"45936375922793925919605092352922707796689801895417366600539442410775071099958","price":"0.86","size":"255.7","side":"BUY","hash":"5b58aa7a824dec6e2d9d66b510959161d154fef5","best_bid":"0.86","best_ask":"0.87"},{"asset_id":"86520121088881862182423437128238697252500151785248183602134095101149900014256","price":"0.14","size":"255.7","side":"SELL","hash":"82922d2012c1ab128ebfdea02eeec92bf4b21298","best_bid":"0.13","best_ask":"0.14"}],"timestamp":"1776808415038","event_type":"price_change"}}
{"capturedAt":1776808415,"payload":{"market":"0x125149c5918fc5f8c6d34682f700a898a1a19ea4f4e2ae68ff4c5794ba657074","price_changes":[{"asset_id":"86520121088881862182423437128238697252500151785248183602134095101149900014256","price":"0.12","size":"338.5","side":"BUY","hash":"d909729e263d175b05460b5516779f3e1208745c","best_bid":"0.13","best_ask":"0.14"},{"asset_id":"45936375922793925919605092352922707796689801895417366600539442410775071099958","price":"0.88","size":"338.5","side":"SELL","hash":"16c8c13835fb6d42f98cc65610133377a99e64b8","best_bid":"0.86","best_ask":"0.87"}],"timestamp":"1776808415037","event_type":"price_change"}}
{"capturedAt":1776808415,"payload":{"market":"0x125149c5918fc5f8c6d34682f700a898a1a19ea4f4e2ae68ff4c5794ba657074","price_changes":[{"asset_id":"45936375922793925919605092352922707796689801895417366600539442410775071099958","price":"0.86","size":"276.7","side":"BUY","hash":"4d01635518230a28e62db1794a896bcae015bdd3","best_bid":"0.86","best_ask":"0.87"},{"asset_id":"86520121088881862182423437128238697252500151785248183602134095101149900014256","price":"0.14","size":"276.7","side":"SELL","hash":"2b5de6b8b523cfdfd800a2f5cbf63198569902da","best_bid":"0.13","best_ask":"0.14"}],"timestamp":"1776808415036","event_type":"price_change"}}
{"capturedAt":1776808415,"payload":{"market":"0x125149c5918fc5f8c6d34682f700a898a1a19ea4f4e2ae68ff4c5794ba657074","price_changes":[{"asset_id":"45936375922793925919605092352922707796689801895417366600539442410775071099958","price":"0.85","size":"457.28","side":"BUY","hash":"e9b4fc284f80022433f99ce3b2b2805f791ba04d","best_bid":"0.86","best_ask":"0.87"},{"asset_id":"86520121088881862182423437128238697252500151785248183602134095101149900014256","price":"0.15","size":"457.28","side":"SELL","hash":"28458f36dd0b4bce5f2e0c0df9e153dbc3cd7f10","best_bid":"0.13","best_ask":"0.14"}],"timestamp":"1776808415039","event_type":"price_change"}}
{"capturedAt":1776808415,"payload":{"market":"0x125149c5918fc5f8c6d34682f700a898a1a19ea4f4e2ae68ff4c5794ba657074","price_changes":[{"asset_id":"45936375922793925919605092352922707796689801895417366600539442410775071099958","price":"0.86","size":"250.65","side":"BUY","hash":"68ef24762a330b951d6867dfb1d626003ebb7adb","best_bid":"0.86","best_ask":"0.87"},{"asset_id":"86520121088881862182423437128238697252500151785248183602134095101149900014256","price":"0.14","size":"250.65","side":"SELL","hash":"b908e4aeb24f93b3ad69cfd0f2920deca21805a2","best_bid":"0.13","best_ask":"0.14"}],"timestamp":"1776808415040","event_type":"price_change"}}
{"capturedAt":1776808415,"payload":{"market":"0x125149c5918fc5f8c6d34682f700a898a1a19ea4f4e2ae68ff4c5794ba657074","asset_id":"86520121088881862182423437128238697252500151785248183602134095101149900014256","best_bid":"0.13","best_ask":"0.14","spread":"0.01","timestamp":"1776808415044","event_type":"best_bid_ask"}}
{"capturedAt":1776808415,"payload":{"market":"0x125149c5918fc5f8c6d34682f700a898a1a19ea4f4e2ae68ff4c5794ba657074","asset_id":"45936375922793925919605092352922707796689801895417366600539442410775071099958","best_bid":"0.86","best_ask":"0.87","spread":"0.01","timestamp":"1776808415044","event_type":"best_bid_ask"}}
{"capturedAt":1776808415,"payload":{"market":"0x125149c5918fc5f8c6d34682f700a898a1a19ea4f4e2ae68ff4c5794ba657074","price_changes":[{"asset_id":"45936375922793925919605092352922707796689801895417366600539442410775071099958","price":"0.01","size":"12324.83","side":"BUY","hash":"5e7fbd9d77831d9d7978384e549552944c1d4afc","best_bid":"0.86","best_ask":"0.87"},{"asset_id":"86520121088881862182423437128238697252500151785248183602134095101149900014256","price":"0.99","size":"12324.83","side":"SELL","hash":"4ce517b9d023ce626ff4c86b6ab6c820c3016b69","best_bid":"0.13","best_ask":"0.14"}],"timestamp":"1776808415045","event_type":"price_change"}}
{"capturedAt":1776808415,"payload":{"market":"0x125149c5918fc5f8c6d34682f700a898a1a19ea4f4e2ae68ff4c5794ba657074","price_changes":[{"asset_id":"86520121088881862182423437128238697252500151785248183602134095101149900014256","price":"0.13","size":"223.2","side":"BUY","hash":"7404152a3a3a6945ca6849786999a0ae26312909","best_bid":"0.13","best_ask":"0.14"},{"asset_id":"45936375922793925919605092352922707796689801895417366600539442410775071099958","price":"0.87","size":"223.2","side":"SELL","hash":"316ef7e01f63a972c8dcace52c55fcb82c42fb78","best_bid":"0.86","best_ask":"0.87"}],"timestamp":"1776808415043","event_type":"price_change"}}
{"capturedAt":1776808415,"payload":{"market":"0x125149c5918fc5f8c6d34682f700a898a1a19ea4f4e2ae68ff4c5794ba657074","price_changes":[{"asset_id":"45936375922793925919605092352922707796689801895417366600539442410775071099958","price":"0.86","size":"270.65","side":"BUY","hash":"217cd7fb17a676a20f6578b1b00ecf62cc3ca6f5","best_bid":"0.86","best_ask":"0.87"},{"asset_id":"86520121088881862182423437128238697252500151785248183602134095101149900014256","price":"0.14","size":"270.65","side":"SELL","hash":"09f6888da8dfeac40e371c56282994f2275f1721","best_bid":"0.13","best_ask":"0.14"}],"timestamp":"1776808415044","event_type":"price_change"}}
{"capturedAt":1776808415,"payload":{"market":"0x125149c5918fc5f8c6d34682f700a898a1a19ea4f4e2ae68ff4c5794ba657074","asset_id":"45936375922793925919605092352922707796689801895417366600539442410775071099958","bids":[{"price":"0.01","size":"12329.83"},{"price":"0.02","size":"1715.28"},{"price":"0.03","size":"1338.69"},{"price":"0.04","size":"583.84"},{"price":"0.05","size":"1006.34"},{"price":"0.06","size":"392.8"},{"price":"0.07","size":"304.69"},{"price":"0.08","size":"278.9"},{"price":"0.09","size":"225"},{"price":"0.1","size":"282"},{"price":"0.11","size":"217.79"},{"price":"0.12","size":"215.1"},{"price":"0.13","size":"202.8"},{"price":"0.14","size":"200.9"},{"price":"0.15","size":"209.2"},{"price":"0.16","size":"197.8"},{"price":"0.17","size":"202.39"},{"price":"0.18","size":"200.4"},{"price":"0.19","size":"194.4"},{"price":"0.2","size":"193.5"},{"price":"0.21","size":"215.31"},{"price":"0.22","size":"197"},{"price":"0.23","size":"229.34"},{"price":"0.24","size":"195.7"},{"price":"0.25","size":"190.2"},{"price":"0.26","size":"189.7"},{"price":"0.27","size":"194.3"},{"price":"0.28","size":"188.89"},{"price":"0.29","size":"188.5"},{"price":"0.3","size":"206.48"},{"price":"0.31","size":"394.45"},{"price":"0.32","size":"187.5"},{"price":"0.33","size":"193.55"},{"price":"0.34","size":"187"},{"price":"0.35","size":"602.68"},{"price":"0.36","size":"186.6"},{"price":"0.37","size":"191.96"},{"price":"0.38","size":"186.3"},{"price":"0.39","size":"491.36"},{"price":"0.4","size":"226"},{"price":"0.41","size":"203.32"},{"price":"0.42","size":"185.8"},{"price":"0.43","size":"190.8"},{"price":"0.44","size":"190.6"},{"price":"0.45","size":"230.58"},{"price":"0.46","size":"185.5"},{"price":"0.47","size":"245.86"},{"price":"0.48","size":"242.56"},{"price":"0.49","size":"222.4"},{"price":"0.5","size":"378.64"},{"price":"0.51","size":"205.25"},{"price":"0.52","size":"226.77"},{"price":"0.53","size":"136.71"},{"price":"0.54","size":"185.5"},{"price":"0.55","size":"213.66"},{"price":"0.56","size":"190.6"},{"price":"0.57","size":"180.7"},{"price":"0.58","size":"180.8"},{"price":"0.59","size":"180.9"},{"price":"0.6","size":"139"},{"price":"0.61","size":"185.46"},{"price":"0.62","size":"141.3"},{"price":"0.63","size":"131.4"},{"price":"0.64","size":"131.6"},{"price":"0.65","size":"136.8"},{"price":"0.66","size":"342"},{"price":"0.67","size":"232.3"},{"price":"0.68","size":"382.5"},{"price":"0.69","size":"182.8"},{"price":"0.7","size":"244.95"},{"price":"0.71","size":"405.5"},{"price":"0.72","size":"530.89"},{"price":"0.73","size":"217.3"},{"price":"0.74","size":"287.7"},{"price":"0.75","size":"382.29"},{"price":"0.76","size":"148.49"},{"price":"0.77","size":"221.3"},{"price":"0.78","size":"328.98"},{"price":"0.79","size":"219.7"},{"price":"0.8","size":"245.25"},{"price":"0.81","size":"304.9"},{"price":"0.82","size":"325.78"},{"price":"0.83","size":"353.3"},{"price":"0.84","size":"384.37"},{"price":"0.85","size":"457.28"},{"price":"0.86","size":"250.65"}],"asks":[{"price":"0.99","size":"12902.69"},{"price":"0.98","size":"1746.16"},{"price":"0.97","size":"1413.83"},{"price":"0.96","size":"932.3"},{"price":"0.95","size":"796.63"},{"price":"0.94","size":"395.8"},{"price":"0.93","size":"682.3"},{"price":"0.92","size":"656.9"},{"price":"0.91","size":"267.44"},{"price":"0.9","size":"793.5"},{"price":"0.89","size":"356.5"},{"price":"0.88","size":"338.5"},{"price":"0.87","size":"223.2"}],"hash":"316ef7e01f63a972c8dcace52c55fcb82c42fb78","timestamp":"1776808415043","event_type":"book"}}
{"capturedAt":1776808415,"payload":{"market":"0x125149c5918fc5f8c6d34682f700a898a1a19ea4f4e2ae68ff4c5794ba657074","price_changes":[{"asset_id":"45936375922793925919605092352922707796689801895417366600539442410775071099958","price":"0.86","size":"275.66","side":"BUY","hash":"9f0d4e2438d51ed55fc6eba85de594cb14070f99","best_bid":"0.86","best_ask":"0.87"},{"asset_id":"86520121088881862182423437128238697252500151785248183602134095101149900014256","price":"0.14","size":"275.66","side":"SELL","hash":"d50d3ccf9e9055c5831934bd91c1987536b1f67a","best_bid":"0.13","best_ask":"0.14"}],"timestamp":"1776808415046","event_type":"price_change"}}
{"capturedAt":1776808415,"payload":{"market":"0x125149c5918fc5f8c6d34682f700a898a1a19ea4f4e2ae68ff4c5794ba657074","asset_id":"86520121088881862182423437128238697252500151785248183602134095101149900014256","bids":[{"price":"0.01","size":"12902.69"},{"price":"0.02","size":"1746.16"},{"price":"0.03","size":"1413.83"},{"price":"0.04","size":"932.3"},{"price":"0.05","size":"796.63"},{"price":"0.06","size":"395.8"},{"price":"0.07","size":"682.3"},{"price":"0.08","size":"656.9"},{"price":"0.09","size":"267.44"},{"price":"0.1","size":"793.5"},{"price":"0.11","size":"356.5"},{"price":"0.12","size":"338.5"},{"price":"0.13","size":"223.2"}],"asks":[{"price":"0.99","size":"12329.83"},{"price":"0.98","size":"1715.28"},{"price":"0.97","size":"1338.69"},{"price":"0.96","size":"583.84"},{"price":"0.95","size":"1006.34"},{"price":"0.94","size":"392.8"},{"price":"0.93","size":"304.69"},{"price":"0.92","size":"278.9"},{"price":"0.91","size":"225"},{"price":"0.9","size":"282"},{"price":"0.89","size":"217.79"},{"price":"0.88","size":"215.1"},{"price":"0.87","size":"202.8"},{"price":"0.86","size":"200.9"},{"price":"0.85","size":"209.2"},{"price":"0.84","size":"197.8"},{"price":"0.83","size":"202.39"},{"price":"0.82","size":"200.4"},{"price":"0.81","size":"194.4"},{"price":"0.8","size":"193.5"},{"price":"0.79","size":"215.31"},{"price":"0.78","size":"197"},{"price":"0.77","size":"229.34"},{"price":"0.76","size":"195.7"},{"price":"0.75","size":"190.2"},{"price":"0.74","size":"189.7"},{"price":"0.73","size":"194.3"},{"price":"0.72","size":"188.89"},{"price":"0.71","size":"188.5"},{"price":"0.7","size":"206.48"},{"price":"0.69","size":"394.45"},{"price":"0.68","size":"187.5"},{"price":"0.67","size":"193.55"},{"price":"0.66","size":"187"},{"price":"0.65","size":"602.68"},{"price":"0.64","size":"186.6"},{"price":"0.63","size":"191.96"},{"price":"0.62","size":"186.3"},{"price":"0.61","size":"491.36"},{"price":"0.6","size":"226"},{"price":"0.59","size":"203.32"},{"price":"0.58","size":"185.8"},{"price":"0.57","size":"190.8"},{"price":"0.56","size":"190.6"},{"price":"0.55","size":"230.58"},{"price":"0.54","size":"185.5"},{"price":"0.53","size":"245.86"},{"price":"0.52","size":"242.56"},{"price":"0.51","size":"222.4"},{"price":"0.5","size":"378.64"},{"price":"0.49","size":"205.25"},{"price":"0.48","size":"226.77"},{"price":"0.47","size":"136.71"},{"price":"0.46","size":"185.5"},{"price":"0.45","size":"213.66"},{"price":"0.44","size":"190.6"},{"price":"0.43","size":"180.7"},{"price":"0.42","size":"180.8"},{"price":"0.41","size":"180.9"},{"price":"0.4","size":"139"},{"price":"0.39","size":"185.46"},{"price":"0.38","size":"141.3"},{"price":"0.37","size":"131.4"},{"price":"0.36","size":"131.6"},{"price":"0.35","size":"136.8"},{"price":"0.34","size":"342"},{"price":"0.33","size":"232.3"},{"price":"0.32","size":"382.5"},{"price":"0.31","size":"182.8"},{"price":"0.3","size":"244.95"},{"price":"0.29","size":"405.5"},{"price":"0.28","size":"530.89"},{"price":"0.27","size":"217.3"},{"price":"0.26","size":"287.7"},{"price":"0.25","size":"382.29"},{"price":"0.24","size":"148.49"},{"price":"0.23","size":"221.3"},{"price":"0.22","size":"328.98"},{"price":"0.21","size":"219.7"},{"price":"0.2","size":"245.25"},{"price":"0.19","size":"304.9"},{"price":"0.18","size":"325.78"},{"price":"0.17","size":"353.3"},{"price":"0.16","size":"384.37"},{"price":"0.15","size":"457.28"},{"price":"0.14","size":"250.65"}],"hash":"7404152a3a3a6945ca6849786999a0ae26312909","timestamp":"1776808415043","event_type":"book"}}
{"capturedAt":1776808415,"payload":{"market":"0x125149c5918fc5f8c6d34682f700a898a1a19ea4f4e2ae68ff4c5794ba657074","price_changes":[{"asset_id":"45936375922793925919605092352922707796689801895417366600539442410775071099958","price":"0.86","size":"295.66","side":"BUY","hash":"f408b632b8fab5cb2ef79ba8a92a770b289dcf3b","best_bid":"0.86","best_ask":"0.87"},{"asset_id":"86520121088881862182423437128238697252500151785248183602134095101149900014256","price":"0.14","size":"295.66","side":"SELL","hash":"35c13d9e086c92e5e63bcd4d977a8d810b366de1","best_bid":"0.13","best_ask":"0.14"}],"timestamp":"1776808415047","event_type":"price_change"}}
{"capturedAt":1776808415,"payload":{"market":"0x125149c5918fc5f8c6d34682f700a898a1a19ea4f4e2ae68ff4c5794ba657074","price_changes":[{"asset_id":"45936375922793925919605092352922707796689801895417366600539442410775071099958","price":"0.86","size":"314.66","side":"BUY","hash":"32f512a687122093b093a910c44b8b8eb699d213","best_bid":"0.86","best_ask":"0.87"},{"asset_id":"86520121088881862182423437128238697252500151785248183602134095101149900014256","price":"0.14","size":"314.66","side":"SELL","hash":"0b9baf6ffef6e34713cffa7fa8d192ccbe6fbc9c","best_bid":"0.13","best_ask":"0.14"}],"timestamp":"1776808415049","event_type":"price_change"}}
{"capturedAt":1776808415,"payload":{"market":"0x125149c5918fc5f8c6d34682f700a898a1a19ea4f4e2ae68ff4c5794ba657074","price_changes":[{"asset_id":"45936375922793925919605092352922707796689801895417366600539442410775071099958","price":"0.86","size":"314.66","side":"BUY","hash":"f453ca62a9f0de3684d3b0d545ac7803e24b30dd","best_bid":"0.86","best_ask":"0.87"},{"asset_id":"86520121088881862182423437128238697252500151785248183602134095101149900014256","price":"0.14","size":"314.66","side":"SELL","hash":"67b0d558db4e4f7fc3c8f13c605e261d927990ab","best_bid":"0.13","best_ask":"0.14"}],"timestamp":"1776808415052","event_type":"price_change"}}
{"capturedAt":1776808415,"payload":{"market":"0x125149c5918fc5f8c6d34682f700a898a1a19ea4f4e2ae68ff4c5794ba657074","price_changes":[{"asset_id":"45936375922793925919605092352922707796689801895417366600539442410775071099958","price":"0.86","size":"294.66","side":"BUY","hash":"660bb7c1623f3963945ce30c5852d85eca796427","best_bid":"0.86","best_ask":"0.87"},{"asset_id":"86520121088881862182423437128238697252500151785248183602134095101149900014256","price":"0.14","size":"294.66","side":"SELL","hash":"944f275c6523ffc35de5495b1ec3287ee9e592a0","best_bid":"0.13","best_ask":"0.14"}],"timestamp":"1776808415051","event_type":"price_change"}}
{"capturedAt":1776808415,"payload":{"market":"0x125149c5918fc5f8c6d34682f700a898a1a19ea4f4e2ae68ff4c5794ba657074","price_changes":[{"asset_id":"86520121088881862182423437128238697252500151785248183602134095101149900014256","price":"0.01","size":"12907.69","side":"BUY","hash":"47af5e18094463648225ed89f1e0209fe5f05d5f","best_bid":"0.13","best_ask":"0.14"},{"asset_id":"45936375922793925919605092352922707796689801895417366600539442410775071099958","price":"0.99","size":"12907.69","side":"SELL","hash":"35a7d4beb9de0127d45d7030e56f6d8d5995655b","best_bid":"0.86","best_ask":"0.87"}],"timestamp":"1776808415053","event_type":"price_change"}}
{"capturedAt":1776808415,"payload":{"market":"0x125149c5918fc5f8c6d34682f700a898a1a19ea4f4e2ae68ff4c5794ba657074","price_changes":[{"asset_id":"45936375922793925919605092352922707796689801895417366600539442410775071099958","price":"0.86","size":"304.66","side":"BUY","hash":"eb0a110b81781fe1371b0d185e88aabda293840b","best_bid":"0.86","best_ask":"0.87"},{"asset_id":"86520121088881862182423437128238697252500151785248183602134095101149900014256","price":"0.14","size":"304.66","side":"SELL","hash":"188b2a814afdbb3a7b682a04b37e46ab44c80416","best_bid":"0.13","best_ask":"0.14"}],"timestamp":"1776808415053","event_type":"price_change"}}
{"capturedAt":1776808415,"payload":{"market":"0x125149c5918fc5f8c6d34682f700a898a1a19ea4f4e2ae68ff4c5794ba657074","price_changes":[{"asset_id":"45936375922793925919605092352922707796689801895417366600539442410775071099958","price":"0.86","size":"286.66","side":"BUY","hash":"8d38a9709013286f51e53adaac671335507ee82c","best_bid":"0.86","best_ask":"0.87"},{"asset_id":"86520121088881862182423437128238697252500151785248183602134095101149900014256","price":"0.14","size":"286.66","side":"SELL","hash":"66f48e20c0bd00bfe33ce9a4b3f2303dbc1f927c","best_bid":"0.13","best_ask":"0.14"}],"timestamp":"1776808415057","event_type":"price_change"}}
{"capturedAt":1776808415,"payload":{"market":"0x125149c5918fc5f8c6d34682f700a898a1a19ea4f4e2ae68ff4c5794ba657074","price_changes":[{"asset_id":"45936375922793925919605092352922707796689801895417366600539442410775071099958","price":"0.86","size":"281.66","side":"BUY","hash":"7e363e8e66004d026d896f6ff78e6edb1dc6ab03","best_bid":"0.86","best_ask":"0.87"},{"asset_id":"86520121088881862182423437128238697252500151785248183602134095101149900014256","price":"0.14","size":"281.66","side":"SELL","hash":"3b6d835b122a4192a084cb002e8107a13df9220c","best_bid":"0.13","best_ask":"0.14"}],"timestamp":"1776808415058","event_type":"price_change"}}
{"capturedAt":1776808415,"payload":{"market":"0x125149c5918fc5f8c6d34682f700a898a1a19ea4f4e2ae68ff4c5794ba657074","price_changes":[{"asset_id":"45936375922793925919605092352922707796689801895417366600539442410775071099958","price":"0.86","size":"291.66","side":"BUY","hash":"77e3bde4f881a6b185e11ce27acb7cea08d6d314","best_bid":"0.86","best_ask":"0.87"},{"asset_id":"86520121088881862182423437128238697252500151785248183602134095101149900014256","price":"0.14","size":"291.66","side":"SELL","hash":"ed61fb6dcb98d08e2eb1554a71c9b9f83361f01e","best_bid":"0.13","best_ask":"0.14"}],"timestamp":"1776808415059","event_type":"price_change"}}
{"capturedAt":1776808415,"payload":{"market":"0x125149c5918fc5f8c6d34682f700a898a1a19ea4f4e2ae68ff4c5794ba657074","price_changes":[{"asset_id":"45936375922793925919605092352922707796689801895417366600539442410775071099958","price":"0.85","size":"452.28","side":"BUY","hash":"7e363e8e66004d026d896f6ff78e6edb1dc6ab03","best_bid":"0.86","best_ask":"0.87"},{"asset_id":"86520121088881862182423437128238697252500151785248183602134095101149900014256","price":"0.15","size":"452.28","side":"SELL","hash":"3b6d835b122a4192a084cb002e8107a13df9220c","best_bid":"0.13","best_ask":"0.14"}],"timestamp":"1776808415058","event_type":"price_change"}}
{"capturedAt":1776808415,"payload":{"market":"0x125149c5918fc5f8c6d34682f700a898a1a19ea4f4e2ae68ff4c5794ba657074","price_changes":[{"asset_id":"45936375922793925919605092352922707796689801895417366600539442410775071099958","price":"0.86","size":"308.66","side":"BUY","hash":"0549f4995f983cbfc2992e2c20720a17b93e821f","best_bid":"0.86","best_ask":"0.87"},{"asset_id":"86520121088881862182423437128238697252500151785248183602134095101149900014256","price":"0.14","size":"308.66","side":"SELL","hash":"295a2f9fb65c003ddd34131c07976a4cfc865df6","best_bid":"0.13","best_ask":"0.14"}],"timestamp":"1776808415060","event_type":"price_change"}}
{"capturedAt":1776808415,"payload":{"market":"0x125149c5918fc5f8c6d34682f700a898a1a19ea4f4e2ae68ff4c5794ba657074","price_changes":[{"asset_id":"45936375922793925919605092352922707796689801895417366600539442410775071099958","price":"0.01","size":"12329.83","side":"BUY","hash":"ab0461db40a45e7f3d8667e2270554e908a7b702","best_bid":"0.86","best_ask":"0.87"},{"asset_id":"86520121088881862182423437128238697252500151785248183602134095101149900014256","price":"0.99","size":"12329.83","side":"SELL","hash":"3761b6e12cb6fbb810dd5e40b54150ecf2fd09f2","best_bid":"0.13","best_ask":"0.14"}],"timestamp":"1776808415063","event_type":"price_change"}}
{"capturedAt":1776808415,"payload":{"market":"0x125149c5918fc5f8c6d34682f700a898a1a19ea4f4e2ae68ff4c5794ba657074","asset_id":"45936375922793925919605092352922707796689801895417366600539442410775071099958","price":"0.87","size":"34","fee_rate_bps":"1000","side":"BUY","timestamp":"1776808415061","event_type":"last_trade_price","transaction_hash":"0x01ba6050e9c325ca1cfaf5358e70a77e6b6e9784c7f1b8c86be7270d95f27407"}}
{"capturedAt":1776808415,"payload":{"market":"0x125149c5918fc5f8c6d34682f700a898a1a19ea4f4e2ae68ff4c5794ba657074","price_changes":[{"asset_id":"45936375922793925919605092352922707796689801895417366600539442410775071099958","price":"0.86","size":"288.66","side":"BUY","hash":"695fbd0448251c10fd63e9e9c6fbdc6e1a2dc15a","best_bid":"0.86","best_ask":"0.87"},{"asset_id":"86520121088881862182423437128238697252500151785248183602134095101149900014256","price":"0.14","size":"288.66","side":"SELL","hash":"9542e5b424650cc5aebd90779b637e4195eee3e2","best_bid":"0.13","best_ask":"0.14"}],"timestamp":"1776808415061","event_type":"price_change"}}
{"capturedAt":1776808415,"payload":{"market":"0x125149c5918fc5f8c6d34682f700a898a1a19ea4f4e2ae68ff4c5794ba657074","price_changes":[{"asset_id":"45936375922793925919605092352922707796689801895417366600539442410775071099958","price":"0.86","size":"298.66","side":"BUY","hash":"d40185c0e24ec4e0fe971a105e011c6e246f5b57","best_bid":"0.86","best_ask":"0.87"},{"asset_id":"86520121088881862182423437128238697252500151785248183602134095101149900014256","price":"0.14","size":"298.66","side":"SELL","hash":"18eb53d01d5bd2f817da06d8a2a58c5ec671e9fd","best_bid":"0.13","best_ask":"0.14"}],"timestamp":"1776808415065","event_type":"price_change"}}
{"capturedAt":1776808415,"payload":{"market":"0x125149c5918fc5f8c6d34682f700a898a1a19ea4f4e2ae68ff4c5794ba657074","price_changes":[{"asset_id":"45936375922793925919605092352922707796689801895417366600539442410775071099958","price":"0.86","size":"293.65","side":"BUY","hash":"ae479dd67b27e45f86d1038f32d3f559aa3567ae","best_bid":"0.86","best_ask":"0.87"},{"asset_id":"86520121088881862182423437128238697252500151785248183602134095101149900014256","price":"0.14","size":"293.65","side":"SELL","hash":"9376cbf688187fae1f970856d6137bb4a4bd7ff0","best_bid":"0.13","best_ask":"0.14"}],"timestamp":"1776808415066","event_type":"price_change"}}
{"capturedAt":1776808415,"payload":{"market":"0x125149c5918fc5f8c6d34682f700a898a1a19ea4f4e2ae68ff4c5794ba657074","price_changes":[{"asset_id":"45936375922793925919605092352922707796689801895417366600539442410775071099958","price":"0.86","size":"314.65","side":"BUY","hash":"714d23d8fcf5e39dd94164f0624e62480516630f","best_bid":"0.86","best_ask":"0.87"},{"asset_id":"86520121088881862182423437128238697252500151785248183602134095101149900014256","price":"0.14","size":"314.65","side":"SELL","hash":"2a2d357545a9d00d9bafe45d497eafdb511086ff","best_bid":"0.13","best_ask":"0.14"}],"timestamp":"1776808415068","event_type":"price_change"}}
{"capturedAt":1776808415,"payload":{"market":"0x125149c5918fc5f8c6d34682f700a898a1a19ea4f4e2ae68ff4c5794ba657074","price_changes":[{"asset_id":"45936375922793925919605092352922707796689801895417366600539442410775071099958","price":"0.01","size":"12334.83","side":"BUY","hash":"299306cfa2d17b4902c91c4a9e1063efc23edf33","best_bid":"0.86","best_ask":"0.87"},{"asset_id":"86520121088881862182423437128238697252500151785248183602134095101149900014256","price":"0.99","size":"12334.83","side":"SELL","hash":"2a6c5a013a379aa52887bbe87f242d82e25bc1d5","best_bid":"0.13","best_ask":"0.14"}],"timestamp":"1776808415074","event_type":"price_change"}}
{"capturedAt":1776808415,"payload":{"market":"0x125149c5918fc5f8c6d34682f700a898a1a19ea4f4e2ae68ff4c5794ba657074","price_changes":[{"asset_id":"86520121088881862182423437128238697252500151785248183602134095101149900014256","price":"0.95","size":"906.34","side":"SELL","hash":"de91b8b56dbe547a5ded3f10bacb830161398e46","best_bid":"0.13","best_ask":"0.14"},{"asset_id":"45936375922793925919605092352922707796689801895417366600539442410775071099958","price":"0.05","size":"906.34","side":"BUY","hash":"609d4b438526951676af1135ea7758fb559eebf7","best_bid":"0.86","best_ask":"0.87"}],"timestamp":"1776808415078","event_type":"price_change"}}
{"capturedAt":1776808415,"payload":{"market":"0x125149c5918fc5f8c6d34682f700a898a1a19ea4f4e2ae68ff4c5794ba657074","price_changes":[{"asset_id":"45936375922793925919605092352922707796689801895417366600539442410775071099958","price":"0.86","size":"337.65","side":"BUY","hash":"dc3ed6d18611b960224bf40e918b29e771236e67","best_bid":"0.86","best_ask":"0.87"},{"asset_id":"86520121088881862182423437128238697252500151785248183602134095101149900014256","price":"0.14","size":"337.65","side":"SELL","hash":"cb338e125986213d07cca1fc2d3e21f911152321","best_bid":"0.13","best_ask":"0.14"}],"timestamp":"1776808415080","event_type":"price_change"}}
{"capturedAt":1776808415,"payload":{"market":"0x125149c5918fc5f8c6d34682f700a898a1a19ea4f4e2ae68ff4c5794ba657074","price_changes":[{"asset_id":"45936375922793925919605092352922707796689801895417366600539442410775071099958","price":"0.83","size":"327.8","side":"BUY","hash":"c84e003826134760d957f70111a9bb9ac2257961","best_bid":"0.86","best_ask":"0.87"},{"asset_id":"86520121088881862182423437128238697252500151785248183602134095101149900014256","price":"0.17","size":"327.8","side":"SELL","hash":"a3f15641c04169db6c8d1bb3dd54c9379854326d","best_bid":"0.13","best_ask":"0.14"}],"timestamp":"1776808415081","event_type":"price_change"}}
{"capturedAt":1776808415,"payload":{"market":"0x125149c5918fc5f8c6d34682f700a898a1a19ea4f4e2ae68ff4c5794ba657074","price_changes":[{"asset_id":"45936375922793925919605092352922707796689801895417366600539442410775071099958","price":"0.86","size":"347.65","side":"BUY","hash":"11361be55e8dcc8b60a523729c03b7061a7199dd","best_bid":"0.86","best_ask":"0.87"},{"asset_id":"86520121088881862182423437128238697252500151785248183602134095101149900014256","price":"0.14","size":"347.65","side":"SELL","hash":"fe732f16dc4d0cd6fa15531bcda454e156fbae17","best_bid":"0.13","best_ask":"0.14"}],"timestamp":"1776808415082","event_type":"price_change"}}
{"capturedAt":1776808415,"payload":{"market":"0x125149c5918fc5f8c6d34682f700a898a1a19ea4f4e2ae68ff4c5794ba657074","price_changes":[{"asset_id":"45936375922793925919605092352922707796689801895417366600539442410775071099958","price":"0.01","size":"12329.83","side":"BUY","hash":"5f46d795a23ff15cc3c2e598841a9b847f596fa6","best_bid":"0.86","best_ask":"0.87"},{"asset_id":"86520121088881862182423437128238697252500151785248183602134095101149900014256","price":"0.99","size":"12329.83","side":"SELL","hash":"7fd8e86adf2801fb09be4ced5415f718c4163bea","best_bid":"0.13","best_ask":"0.14"}],"timestamp":"1776808415083","event_type":"price_change"}}
{"capturedAt":1776808415,"payload":{"market":"0x125149c5918fc5f8c6d34682f700a898a1a19ea4f4e2ae68ff4c5794ba657074","price_changes":[{"asset_id":"45936375922793925919605092352922707796689801895417366600539442410775071099958","price":"0.86","size":"369.65","side":"BUY","hash":"e05d6db3d333ac71bcd3b247820e2c9afbffb9a5","best_bid":"0.86","best_ask":"0.87"},{"asset_id":"86520121088881862182423437128238697252500151785248183602134095101149900014256","price":"0.14","size":"369.65","side":"SELL","hash":"82e2f550b7d5505bb43b21fc77baa0af8cf4ffbe","best_bid":"0.13","best_ask":"0.14"}],"timestamp":"1776808415089","event_type":"price_change"}}
{"capturedAt":1776808415,"payload":{"market":"0x125149c5918fc5f8c6d34682f700a898a1a19ea4f4e2ae68ff4c5794ba657074","asset_id":"86520121088881862182423437128238697252500151785248183602134095101149900014256","best_bid":"0.13","best_ask":"0.14","spread":"0.01","timestamp":"1776808415095","event_type":"best_bid_ask"}}
{"capturedAt":1776808415,"payload":{"market":"0x125149c5918fc5f8c6d34682f700a898a1a19ea4f4e2ae68ff4c5794ba657074","asset_id":"45936375922793925919605092352922707796689801895417366600539442410775071099958","bids":[{"price":"0.01","size":"12329.83"},{"price":"0.02","size":"1715.28"},{"price":"0.03","size":"1338.69"},{"price":"0.04","size":"583.84"},{"price":"0.05","size":"906.34"},{"price":"0.06","size":"392.8"},{"price":"0.07","size":"304.69"},{"price":"0.08","size":"278.9"},{"price":"0.09","size":"225"},{"price":"0.1","size":"282"},{"price":"0.11","size":"217.79"},{"price":"0.12","size":"215.1"},{"price":"0.13","size":"202.8"},{"price":"0.14","size":"200.9"},{"price":"0.15","size":"209.2"},{"price":"0.16","size":"197.8"},{"price":"0.17","size":"202.39"},{"price":"0.18","size":"200.4"},{"price":"0.19","size":"194.4"},{"price":"0.2","size":"193.5"},{"price":"0.21","size":"215.31"},{"price":"0.22","size":"197"},{"price":"0.23","size":"229.34"},{"price":"0.24","size":"195.7"},{"price":"0.25","size":"190.2"},{"price":"0.26","size":"189.7"},{"price":"0.27","size":"194.3"},{"price":"0.28","size":"188.89"},{"price":"0.29","size":"188.5"},{"price":"0.3","size":"206.48"},{"price":"0.31","size":"394.45"},{"price":"0.32","size":"187.5"},{"price":"0.33","size":"193.55"},{"price":"0.34","size":"187"},{"price":"0.35","size":"602.68"},{"price":"0.36","size":"186.6"},{"price":"0.37","size":"191.96"},{"price":"0.38","size":"186.3"},{"price":"0.39","size":"491.36"},{"price":"0.4","size":"226"},{"price":"0.41","size":"203.32"},{"price":"0.42","size":"185.8"},{"price":"0.43","size":"190.8"},{"price":"0.44","size":"190.6"},{"price":"0.45","size":"230.58"},{"price":"0.46","size":"185.5"},{"price":"0.47","size":"245.86"},{"price":"0.48","size":"242.56"},{"price":"0.49","size":"222.4"},{"price":"0.5","size":"378.64"},{"price":"0.51","size":"205.25"},{"price":"0.52","size":"226.77"},{"price":"0.53","size":"136.71"},{"price":"0.54","size":"185.5"},{"price":"0.55","size":"213.66"},{"price":"0.56","size":"190.6"},{"price":"0.57","size":"180.7"},{"price":"0.58","size":"180.8"},{"price":"0.59","size":"180.9"},{"price":"0.6","size":"139"},{"price":"0.61","size":"185.46"},{"price":"0.62","size":"141.3"},{"price":"0.63","size":"131.4"},{"price":"0.64","size":"131.6"},{"price":"0.65","size":"136.8"},{"price":"0.66","size":"342"},{"price":"0.67","size":"232.3"},{"price":"0.68","size":"382.5"},{"price":"0.69","size":"182.8"},{"price":"0.7","size":"244.95"},{"price":"0.71","size":"405.5"},{"price":"0.72","size":"530.89"},{"price":"0.73","size":"217.3"},{"price":"0.74","size":"287.7"},{"price":"0.75","size":"387.29"},{"price":"0.76","size":"148.49"},{"price":"0.77","size":"221.3"},{"price":"0.78","size":"328.98"},{"price":"0.79","size":"219.7"},{"price":"0.8","size":"245.25"},{"price":"0.81","size":"304.9"},{"price":"0.82","size":"325.78"},{"price":"0.83","size":"327.8"},{"price":"0.84","size":"384.37"},{"price":"0.85","size":"452.28"},{"price":"0.86","size":"362.5"}],"asks":[{"price":"0.99","size":"12907.69"},{"price":"0.98","size":"1746.16"},{"price":"0.97","size":"1413.83"},{"price":"0.96","size":"932.3"},{"price":"0.95","size":"796.63"},{"price":"0.94","size":"395.8"},{"price":"0.93","size":"682.3"},{"price":"0.92","size":"656.9"},{"price":"0.91","size":"267.44"},{"price":"0.9","size":"793.5"},{"price":"0.89","size":"356.5"},{"price":"0.88","size":"308.5"},{"price":"0.87","size":"223.2"}],"hash":"7718937c47b10dbeded9e5b6ce73328fca0c18d4","timestamp":"1776808415094","event_type":"book"}}
{"capturedAt":1776808415,"payload":{"market":"0x125149c5918fc5f8c6d34682f700a898a1a19ea4f4e2ae68ff4c5794ba657074","price_changes":[{"asset_id":"45936375922793925919605092352922707796689801895417366600539442410775071099958","price":"0.86","size":"362.5","side":"BUY","hash":"7718937c47b10dbeded9e5b6ce73328fca0c18d4","best_bid":"0.86","best_ask":"0.87"},{"asset_id":"86520121088881862182423437128238697252500151785248183602134095101149900014256","price":"0.14","size":"362.5","side":"SELL","hash":"62330640045949a2ffe7084bbc90003626fd457d","best_bid":"0.13","best_ask":"0.14"}],"timestamp":"1776808415094","event_type":"price_change"}}
{"capturedAt":1776808415,"payload":{"market":"0x125149c5918fc5f8c6d34682f700a898a1a19ea4f4e2ae68ff4c5794ba657074","price_changes":[{"asset_id":"45936375922793925919605092352922707796689801895417366600539442410775071099958","price":"0.76","size":"153.49","side":"BUY","hash":"c88ad7271d9795c9a796dff65ccb2e0e8b5cd331","best_bid":"0.86","best_ask":"0.87"},{"asset_id":"86520121088881862182423437128238697252500151785248183602134095101149900014256","price":"0.24","size":"153.49","side":"SELL","hash":"ea5a6f7d95275a36b477d5b87960ecf714ad7ae5","best_bid":"0.13","best_ask":"0.14"}],"timestamp":"1776808415095","event_type":"price_change"}}
{"capturedAt":1776808415,"payload":{"market":"0x125149c5918fc5f8c6d34682f700a898a1a19ea4f4e2ae68ff4c5794ba657074","asset_id":"45936375922793925919605092352922707796689801895417366600539442410775071099958","best_bid":"0.86","best_ask":"0.87","spread":"0.01","timestamp":"1776808415095","event_type":"best_bid_ask"}}
{"capturedAt":1776808415,"payload":{"market":"0x125149c5918fc5f8c6d34682f700a898a1a19ea4f4e2ae68ff4c5794ba657074","price_changes":[{"asset_id":"86520121088881862182423437128238697252500151785248183602134095101149900014256","price":"0.95","size":"1006.34","side":"SELL","hash":"83b1bd28b17750d82f4e75c972c979fe213ede8d","best_bid":"0.13","best_ask":"0.14"},{"asset_id":"45936375922793925919605092352922707796689801895417366600539442410775071099958","price":"0.05","size":"1006.34","side":"BUY","hash":"53e57dd188c4fd8eab6b368d11d523a23e622dc6","best_bid":"0.86","best_ask":"0.87"}],"timestamp":"1776808415100","event_type":"price_change"}}
{"capturedAt":1776808415,"payload":{"market":"0x125149c5918fc5f8c6d34682f700a898a1a19ea4f4e2ae68ff4c5794ba657074","price_changes":[{"asset_id":"45936375922793925919605092352922707796689801895417366600539442410775071099958","price":"0.01","size":"12324.83","side":"BUY","hash":"2788587c47e4440ae553b044e417247d3feb9c8b","best_bid":"0.86","best_ask":"0.87"},{"asset_id":"86520121088881862182423437128238697252500151785248183602134095101149900014256","price":"0.99","size":"12324.83","side":"SELL","hash":"609fe7fe60bbac43aa34c377d615ee35f6629970","best_bid":"0.13","best_ask":"0.14"}],"timestamp":"1776808415095","event_type":"price_change"}}
{"capturedAt":1776808415,"payload":{"market":"0x125149c5918fc5f8c6d34682f700a898a1a19ea4f4e2ae68ff4c5794ba657074","price_changes":[{"asset_id":"86520121088881862182423437128238697252500151785248183602134095101149900014256","price":"0.12","size":"308.5","side":"BUY","hash":"bb628a23fea4dac1c0f05e3a57cfff16a7d9e3da","best_bid":"0.13","best_ask":"0.14"},{"asset_id":"45936375922793925919605092352922707796689801895417366600539442410775071099958","price":"0.88","size":"308.5","side":"SELL","hash":"62a510f6034a0afc073e0b85f12f66a1bf595b71","best_bid":"0.86","best_ask":"0.87"}],"timestamp":"1776808415083","event_type":"price_change"}}
{"capturedAt":1776808415,"payload":{"market":"0x125149c5918fc5f8c6d34682f700a898a1a19ea4f4e2ae68ff4c5794ba657074","price_changes":[{"asset_id":"45936375922793925919605092352922707796689801895417366600539442410775071099958","price":"0.75","size":"387.29","side":"BUY","hash":"d9f56f26eb256c8fd251b31767eab3d6d99408f3","best_bid":"0.86","best_ask":"0.87"},{"asset_id":"86520121088881862182423437128238697252500151785248183602134095101149900014256","price":"0.25","size":"387.29","side":"SELL","hash":"856cb2eff44b1940f4a8314e6f3e00756905e692","best_bid":"0.13","best_ask":"0.14"}],"timestamp":"1776808415091","event_type":"price_change"}}
{"capturedAt":1776808415,"payload":{"market":"0x125149c5918fc5f8c6d34682f700a898a1a19ea4f4e2ae68ff4c5794ba657074","price_changes":[{"asset_id":"45936375922793925919605092352922707796689801895417366600539442410775071099958","price":"0.86","size":"380.23","side":"BUY","hash":"a4011d82151d6af637f3cb3d1dc7ff8ed0072063","best_bid":"0.86","best_ask":"0.87"},{"asset_id":"86520121088881862182423437128238697252500151785248183602134095101149900014256","price":"0.14","size":"380.23","side":"SELL","hash":"ec6b1a73be86a68d2ae3bfc96900b131cf7a57c3","best_bid":"0.13","best_ask":"0.14"}],"timestamp":"1776808415103","event_type":"price_change"}}
