{"capturedAt":1776808417,"payload":{"market":"0x125149c5918fc5f8c6d34682f700a898a1a19ea4f4e2ae68ff4c5794ba657074","price_changes":[{"asset_id":"45936375922793925919605092352922707796689801895417366600539442410775071099958","price":"0.83","size":"312.49","side":"BUY","hash":"5c6d893baa0ce30418ad8281dfff8d0f53ff6cb5","best_bid":"0.86","best_ask":"0.87"},{"asset_id":"86520121088881862182423437128238697252500151785248183602134095101149900014256","price":"0.17","size":"312.49","side":"SELL","hash":"a4649647e5446956c1bd6e17169787a0ee13534d","best_bid":"0.13","best_ask":"0.14"}],"timestamp":"1776808417499","event_type":"price_change"}}
{"capturedAt":1776808417,"payload":{"market":"0x125149c5918fc5f8c6d34682f700a898a1a19ea4f4e2ae68ff4c5794ba657074","price_changes":[{"asset_id":"86520121088881862182423437128238697252500151785248183602134095101149900014256","price":"0.13","size":"218.74","side":"BUY","hash":"fbd364a20ffad35e6d8e0476f5890f42d2776663","best_bid":"0.13","best_ask":"0.14"},{"asset_id":"45936375922793925919605092352922707796689801895417366600539442410775071099958","price":"0.87","size":"218.74","side":"SELL","hash":"3be34b8826dd7a172f01ec2fd776f60b365b1556","best_bid":"0.86","best_ask":"0.87"}],"timestamp":"1776808417501","event_type":"price_change"}}
{"capturedAt":1776808417,"payload":{"market":"0x125149c5918fc5f8c6d34682f700a898a1a19ea4f4e2ae68ff4c5794ba657074","price_changes":[{"asset_id":"45936375922793925919605092352922707796689801895417366600539442410775071099958","price":"0.75","size":"275.29","side":"BUY","hash":"5d956e29efec14d7e7d9120775610dda90fc553f","best_bid":"0.86","best_ask":"0.87"},{"asset_id":"86520121088881862182423437128238697252500151785248183602134095101149900014256","price":"0.25","size":"275.29","side":"SELL","hash":"3d68fb4cc2a0b103efe4cdfd373dc69bef1e62cf","best_bid":"0.13","best_ask":"0.14"}],"timestamp":"1776808417501","event_type":"price_change"}}
{"capturedAt":1776808417,"payload":{"market":"0x125149c5918fc5f8c6d34682f700a898a1a19ea4f4e2ae68ff4c5794ba657074","price_changes":[{"asset_id":"45936375922793925919605092352922707796689801895417366600539442410775071099958","price":"0.66","size":"142","side":"BUY","hash":"5d956e29efec14d7e7d9120775610dda90fc553f","best_bid":"0.86","best_ask":"0.87"},{"asset_id":"86520121088881862182423437128238697252500151785248183602134095101149900014256","price":"0.34","size":"142","side":"SELL","hash":"3d68fb4cc2a0b103efe4cdfd373dc69bef1e62cf","best_bid":"0.13","best_ask":"0.14"}],"timestamp":"1776808417501","event_type":"price_change"}}
{"capturedAt":1776808417,"payload":{"market":"0x125149c5918fc5f8c6d34682f700a898a1a19ea4f4e2ae68ff4c5794ba657074","price_changes":[{"asset_id":"86520121088881862182423437128238697252500151785248183602134095101149900014256","price":"0.13","size":"223.74","side":"BUY","hash":"08976fc1e6edd7387c80ae26e8739326e5cf6aa7","best_bid":"0.13","best_ask":"0.14"},{"asset_id":"45936375922793925919605092352922707796689801895417366600539442410775071099958","price":"0.87","size":"223.74","side":"SELL","hash":"350670f097e8cb58dbdf5eced5765df8d1183dca","best_bid":"0.86","best_ask":"0.87"}],"timestamp":"1776808417504","event_type":"price_change"}}
{"capturedAt":1776808417,"payload":{"market":"0x125149c5918fc5f8c6d34682f700a898a1a19ea4f4e2ae68ff4c5794ba657074","price_changes":[{"asset_id":"45936375922793925919605092352922707796689801895417366600539442410775071099958","price":"0.01","size":"12324.83","side":"BUY","hash":"f508dd697eda7854a147f1907d74852c90b91075","best_bid":"0.86","best_ask":"0.87"},{"asset_id":"86520121088881862182423437128238697252500151785248183602134095101149900014256","price":"0.99","size":"12324.83","side":"SELL","hash":"917f9184734d89ed8a23b49c37b8fa781d62450c","best_bid":"0.13","best_ask":"0.14"}],"timestamp":"1776808417502","event_type":"price_change"}}
{"capturedAt":1776808417,"payload":{"market":"0x125149c5918fc5f8c6d34682f700a898a1a19ea4f4e2ae68ff4c5794ba657074","price_changes":[{"asset_id":"45936375922793925919605092352922707796689801895417366600539442410775071099958","price":"0.82","size":"305.9","side":"BUY","hash":"b1a3da8f01c7a2253e2748ee452180ce68984a1c","best_bid":"0.86","best_ask":"0.87"},{"asset_id":"86520121088881862182423437128238697252500151785248183602134095101149900014256","price":"0.18","size":"305.9","side":"SELL","hash":"8f61091c1c239b2f9f7373f29aed441f5a01ec64","best_bid":"0.13","best_ask":"0.14"}],"timestamp":"1776808417504","event_type":"price_change"}}
{"capturedAt":1776808417,"payload":{"market":"0x125149c5918fc5f8c6d34682f700a898a1a19ea4f4e2ae68ff4c5794ba657074","price_changes":[{"asset_id":"45936375922793925919605092352922707796689801895417366600539442410775071099958","price":"0.97","size":"1713.83","side":"SELL","hash":"b1a3da8f01c7a2253e2748ee452180ce68984a1c","best_bid":"0.86","best_ask":"0.87"},{"asset_id":"86520121088881862182423437128238697252500151785248183602134095101149900014256","price":"0.03","size":"1713.83","side":"BUY","hash":"8f61091c1c239b2f9f7373f29aed441f5a01ec64","best_bid":"0.13","best_ask":"0.14"}],"timestamp":"1776808417504","event_type":"price_change"}}
{"capturedAt":1776808417,"payload":{"market":"0x125149c5918fc5f8c6d34682f700a898a1a19ea4f4e2ae68ff4c5794ba657074","price_changes":[{"asset_id":"45936375922793925919605092352922707796689801895417366600539442410775071099958","price":"0.86","size":"214.59","side":"BUY","hash":"1c0aabd21491c149c229b324094662c52cfebe4f","best_bid":"0.86","best_ask":"0.87"},{"asset_id":"86520121088881862182423437128238697252500151785248183602134095101149900014256","price":"0.14","size":"214.59","side":"SELL","hash":"e1f8fa22784030e2679ad8982b66c018ff83534b","best_bid":"0.13","best_ask":"0.14"}],"timestamp":"1776808417506","event_type":"price_change"}}
{"capturedAt":1776808417,"payload":{"market":"0x125149c5918fc5f8c6d34682f700a898a1a19ea4f4e2ae68ff4c5794ba657074","price_changes":[{"asset_id":"86520121088881862182423437128238697252500151785248183602134095101149900014256","price":"0.13","size":"228.74","side":"BUY","hash":"862743555afe674bb84a77cab5f83b8f3c85b407","best_bid":"0.13","best_ask":"0.14"},{"asset_id":"45936375922793925919605092352922707796689801895417366600539442410775071099958","price":"0.87","size":"228.74","side":"SELL","hash":"ecd75905f6a50207bd2129a8b67cdf5b63264ea9","best_bid":"0.86","best_ask":"0.87"}],"timestamp":"1776808417507","event_type":"price_change"}}
{"capturedAt":1776808417,"payload":{"market":"0x125149c5918fc5f8c6d34682f700a898a1a19ea4f4e2ae68ff4c5794ba657074","price_changes":[{"asset_id":"45936375922793925919605092352922707796689801895417366600539442410775071099958","price":"0.86","size":"214.59","side":"BUY","hash":"c106dc151da8f74731b19931186b4f92f49dcae8","best_bid":"0.86","best_ask":"0.87"},{"asset_id":"86520121088881862182423437128238697252500151785248183602134095101149900014256","price":"0.14","size":"214.59","side":"SELL","hash":"0f31958a1fe65eaed8579d6e5b538a3205839c0b","best_bid":"0.13","best_ask":"0.14"}],"timestamp":"1776808417510","event_type":"price_change"}}
{"capturedAt":1776808417,"payload":{"market":"0x125149c5918fc5f8c6d34682f700a898a1a19ea4f4e2ae68ff4c5794ba657074","price_changes":[{"asset_id":"45936375922793925919605092352922707796689801895417366600539442410775071099958","price":"0.86","size":"204.59","side":"BUY","hash":"ecbf95517812825e5db8eb477deaf22d5f2b0c87","best_bid":"0.86","best_ask":"0.87"},{"asset_id":"86520121088881862182423437128238697252500151785248183602134095101149900014256","price":"0.14","size":"204.59","side":"SELL","hash":"57bfc01564246f5a467e09ae66f48b9c68469b53","best_bid":"0.13","best_ask":"0.14"}],"timestamp":"1776808417511","event_type":"price_change"}}
{"capturedAt":1776808417,"payload":{"market":"0x125149c5918fc5f8c6d34682f700a898a1a19ea4f4e2ae68ff4c5794ba657074","price_changes":[{"asset_id":"45936375922793925919605092352922707796689801895417366600539442410775071099958","price":"0.86","size":"209.59","side":"BUY","hash":"75e9dd36512d70dd05e8dd3b7b6b2d629e243c29","best_bid":"0.86","best_ask":"0.87"},{"asset_id":"86520121088881862182423437128238697252500151785248183602134095101149900014256","price":"0.14","size":"209.59","side":"SELL","hash":"5b32c3d4eddb2d11c8325824a30ea6a7ac4b8226","best_bid":"0.13","best_ask":"0.14"}],"timestamp":"1776808417509","event_type":"price_change"}}
{"capturedAt":1776808417,"payload":{"market":"0x125149c5918fc5f8c6d34682f700a898a1a19ea4f4e2ae68ff4c5794ba657074","price_changes":[{"asset_id":"45936375922793925919605092352922707796689801895417366600539442410775071099958","price":"0.84","size":"394.37","side":"BUY","hash":"56657036f3aa00195132b8e0975fff39f1ed45e0","best_bid":"0.86","best_ask":"0.87"},{"asset_id":"86520121088881862182423437128238697252500151785248183602134095101149900014256","price":"0.16","size":"394.37","side":"SELL","hash":"8d40d8432cf7e8e066ef078f358257973ece6322","best_bid":"0.13","best_ask":"0.14"}],"timestamp":"1776808417513","event_type":"price_change"}}
{"capturedAt":1776808417,"payload":{"market":"0x125149c5918fc5f8c6d34682f700a898a1a19ea4f4e2ae68ff4c5794ba657074","price_changes":[{"asset_id":"45936375922793925919605092352922707796689801895417366600539442410775071099958","price":"0.86","size":"204.59","side":"BUY","hash":"f9a79cbf958770065360239df6b0a352696c84bf","best_bid":"0.86","best_ask":"0.87"},{"asset_id":"86520121088881862182423437128238697252500151785248183602134095101149900014256","price":"0.14","size":"204.59","side":"SELL","hash":"73f1ebdb04543e8d291853c2bef83644162a930a","best_bid":"0.13","best_ask":"0.14"}],"timestamp":"1776808417508","event_type":"price_change"}}
{"capturedAt":1776808417,"payload":{"market":"0x125149c5918fc5f8c6d34682f700a898a1a19ea4f4e2ae68ff4c5794ba657074","price_changes":[{"asset_id":"45936375922793925919605092352922707796689801895417366600539442410775071099958","price":"0.86","size":"199.59","side":"BUY","hash":"b67aa20ae78ffd2c798582c28be9ddfa065a18a0","best_bid":"0.86","best_ask":"0.87"},{"asset_id":"86520121088881862182423437128238697252500151785248183602134095101149900014256","price":"0.14","size":"199.59","side":"SELL","hash":"af14c570f31e0cd2d6bb3396b6954a0de33fc43d","best_bid":"0.13","best_ask":"0.14"}],"timestamp":"1776808417535","event_type":"price_change"}}
{"capturedAt":1776808417,"payload":{"market":"0x125149c5918fc5f8c6d34682f700a898a1a19ea4f4e2ae68ff4c5794ba657074","price_changes":[{"asset_id":"86520121088881862182423437128238697252500151785248183602134095101149900014256","price":"0.13","size":"233.74","side":"BUY","hash":"836b808c7289a6bd7198fcc1f4a4a22b15f6be41","best_bid":"0.13","best_ask":"0.14"},{"asset_id":"45936375922793925919605092352922707796689801895417366600539442410775071099958","price":"0.87","size":"233.74","side":"SELL","hash":"ba4e7ffaef2c1dcbda88ac70f80b883b30d838a2","best_bid":"0.86","best_ask":"0.87"}],"timestamp":"1776808417536","event_type":"price_change"}}
{"capturedAt":1776808417,"payload":{"market":"0x125149c5918fc5f8c6d34682f700a898a1a19ea4f4e2ae68ff4c5794ba657074","price_changes":[{"asset_id":"86520121088881862182423437128238697252500151785248183602134095101149900014256","price":"0.13","size":"238.74","side":"BUY","hash":"ce8de50d02d794dc5b4369ab0a7d98dc37435561","best_bid":"0.13","best_ask":"0.14"},{"asset_id":"45936375922793925919605092352922707796689801895417366600539442410775071099958","price":"0.87","size":"238.74","side":"SELL","hash":"f10ef6c7a8f0a7d5c33a4b9b9bc304f9db4358d3","best_bid":"0.86","best_ask":"0.87"}],"timestamp":"1776808417537","event_type":"price_change"}}
{"capturedAt":1776808417,"payload":{"market":"0x125149c5918fc5f8c6d34682f700a898a1a19ea4f4e2ae68ff4c5794ba657074","price_changes":[{"asset_id":"45936375922793925919605092352922707796689801895417366600539442410775071099958","price":"0.86","size":"207.59","side":"BUY","hash":"38161df3079d5b3ebd2a2495a978f6cb7bf8dd56","best_bid":"0.86","best_ask":"0.87"},{"asset_id":"86520121088881862182423437128238697252500151785248183602134095101149900014256","price":"0.14","size":"207.59","side":"SELL","hash":"157f76cdddc02e4646e8a33fe4774daef0f80687","best_bid":"0.13","best_ask":"0.14"}],"timestamp":"1776808417538","event_type":"price_change"}}
{"capturedAt":1776808417,"payload":{"market":"0x125149c5918fc5f8c6d34682f700a898a1a19ea4f4e2ae68ff4c5794ba657074","price_changes":[{"asset_id":"45936375922793925919605092352922707796689801895417366600539442410775071099958","price":"0.01","size":"12329.83","side":"BUY","hash":"541dea53e0a94c05ea39e4987d2f2a88ba2df0ce","best_bid":"0.86","best_ask":"0.87"},{"asset_id":"86520121088881862182423437128238697252500151785248183602134095101149900014256","price":"0.99","size":"12329.83","side":"SELL","hash":"0c28ffcfed21d54642127f3eacc4bafce4f8f03b","best_bid":"0.13","best_ask":"0.14"}],"timestamp":"1776808417539","event_type":"price_change"}}
{"capturedAt":1776808417,"payload":{"market":"0x125149c5918fc5f8c6d34682f700a898a1a19ea4f4e2ae68ff4c5794ba657074","price_changes":[{"asset_id":"45936375922793925919605092352922707796689801895417366600539442410775071099958","price":"0.91","size":"238.44","side":"SELL","hash":"f2349993b1957beb41fbe3689de5313d40be3140","best_bid":"0.86","best_ask":"0.87"},{"asset_id":"86520121088881862182423437128238697252500151785248183602134095101149900014256","price":"0.09","size":"238.44","side":"BUY","hash":"4f2c5a15348c7b8c40116c10f2e225794eb8c980","best_bid":"0.13","best_ask":"0.14"}],"timestamp":"1776808417540","event_type":"price_change"}}
{"capturedAt":1776808417,"payload":{"market":"0x125149c5918fc5f8c6d34682f700a898a1a19ea4f4e2ae68ff4c5794ba657074","price_changes":[{"asset_id":"86520121088881862182423437128238697252500151785248183602134095101149900014256","price":"0.09","size":"223.44","side":"BUY","hash":"23f8efca25996e67717f0bd9fd459e82ee609f13","best_bid":"0.13","best_ask":"0.14"},{"asset_id":"45936375922793925919605092352922707796689801895417366600539442410775071099958","price":"0.91","size":"223.44","side":"SELL","hash":"9f86b38ac01c7f96d7bd6cf5c85393ee439543b4","best_bid":"0.86","best_ask":"0.87"}],"timestamp":"1776808417507","event_type":"price_change"}}
{"capturedAt":1776808417,"payload":{"market":"0x125149c5918fc5f8c6d34682f700a898a1a19ea4f4e2ae68ff4c5794ba657074","price_changes":[{"asset_id":"45936375922793925919605092352922707796689801895417366600539442410775071099958","price":"0.86","size":"197.59","side":"BUY","hash":"6b2c483cb425f8ffa49748c22b0cbb5d632bdb24","best_bid":"0.86","best_ask":"0.87"},{"asset_id":"86520121088881862182423437128238697252500151785248183602134095101149900014256","price":"0.14","size":"197.59","side":"SELL","hash":"1694c7bd3ccbc26a21642bea87e8f48720dad283","best_bid":"0.13","best_ask":"0.14"}],"timestamp":"1776808417542","event_type":"price_change"}}
{"capturedAt":1776808417,"payload":{"market":"0x125149c5918fc5f8c6d34682f700a898a1a19ea4f4e2ae68ff4c5794ba657074","price_changes":[{"asset_id":"45936375922793925919605092352922707796689801895417366600539442410775071099958","price":"0.82","size":"311.78","side":"BUY","hash":"44e1351d3cb25fee85be1875ced11512c37954f6","best_bid":"0.86","best_ask":"0.87"},{"asset_id":"86520121088881862182423437128238697252500151785248183602134095101149900014256","price":"0.18","size":"311.78","side":"SELL","hash":"27f8fe6f08d1bf3adc7f848e324fba7767442d26","best_bid":"0.13","best_ask":"0.14"}],"timestamp":"1776808417545","event_type":"price_change"}}
{"capturedAt":1776808417,"payload":{"market":"0x125149c5918fc5f8c6d34682f700a898a1a19ea4f4e2ae68ff4c5794ba657074","price_changes":[{"asset_id":"45936375922793925919605092352922707796689801895417366600539442410775071099958","price":"0.76","size":"148.49","side":"BUY","hash":"30aaf9a75f03a2c18107c1183a3356b8d8994f3d","best_bid":"0.86","best_ask":"0.87"},{"asset_id":"86520121088881862182423437128238697252500151785248183602134095101149900014256","price":"0.24","size":"148.49","side":"SELL","hash":"8212ccda567befa6e978077d38d34f0b7510b5e2","best_bid":"0.13","best_ask":"0.14"}],"timestamp":"1776808417541","event_type":"price_change"}}
{"capturedAt":1776808417,"payload":{"market":"0x125149c5918fc5f8c6d34682f700a898a1a19ea4f4e2ae68ff4c5794ba657074","price_changes":[{"asset_id":"45936375922793925919605092352922707796689801895417366600539442410775071099958","price":"0.73","size":"237.3","side":"BUY","hash":"c4706fa33221a774bbff9477158590a7aef34598","best_bid":"0.86","best_ask":"0.87"},{"asset_id":"86520121088881862182423437128238697252500151785248183602134095101149900014256","price":"0.27","size":"237.3","side":"SELL","hash":"4b2e059d0e8408d3aa46b2555896627dc639c8e9","best_bid":"0.13","best_ask":"0.14"}],"timestamp":"1776808417543","event_type":"price_change"}}
{"capturedAt":1776808417,"payload":{"market":"0x125149c5918fc5f8c6d34682f700a898a1a19ea4f4e2ae68ff4c5794ba657074","price_changes":[{"asset_id":"86520121088881862182423437128238697252500151785248183602134095101149900014256","price":"0.09","size":"217","side":"BUY","hash":"7518f49b509bea8f20167c400ff9720547f4554a","best_bid":"0.13","best_ask":"0.14"},{"asset_id":"45936375922793925919605092352922707796689801895417366600539442410775071099958","price":"0.91","size":"217","side":"SELL","hash":"6413fdebff288b7c609e07a90256e7699849ce58","best_bid":"0.86","best_ask":"0.87"}],"timestamp":"1776808417547","event_type":"price_change"}}
{"capturedAt":1776808417,"payload":{"market":"0x125149c5918fc5f8c6d34682f700a898a1a19ea4f4e2ae68ff4c5794ba657074","price_changes":[{"asset_id":"86520121088881862182423437128238697252500151785248183602134095101149900014256","price":"0.13","size":"243.74","side":"BUY","hash":"c13a2fe1563f9712be44916c40f2b7176b33dbcb","best_bid":"0.13","best_ask":"0.14"},{"asset_id":"45936375922793925919605092352922707796689801895417366600539442410775071099958","price":"0.87","size":"243.74","side":"SELL","hash":"87ad5a9e961140d14ecfbf02030ab94cb60c4e0f","best_bid":"0.86","best_ask":"0.87"}],"timestamp":"1776808417550","event_type":"price_change"}}
{"capturedAt":1776808417,"payload":{"market":"0x125149c5918fc5f8c6d34682f700a898a1a19ea4f4e2ae68ff4c5794ba657074","price_changes":[{"asset_id":"45936375922793925919605092352922707796689801895417366600539442410775071099958","price":"0.82","size":"341.78","side":"BUY","hash":"821dc76cf4ae133a0379d0424f2ad651442fdf54","best_bid":"0.86","best_ask":"0.87"},{"asset_id":"86520121088881862182423437128238697252500151785248183602134095101149900014256","price":"0.18","size":"341.78","side":"SELL","hash":"8253d8554873fabdaae481fd40d5881d4fb70aa7","best_bid":"0.13","best_ask":"0.14"}],"timestamp":"1776808417546","event_type":"price_change"}}
{"capturedAt":1776808417,"payload":{"market":"0x125149c5918fc5f8c6d34682f700a898a1a19ea4f4e2ae68ff4c5794ba657074","price_changes":[{"asset_id":"45936375922793925919605092352922707796689801895417366600539442410775071099958","price":"0.86","size":"209.59","side":"BUY","hash":"5e9f81664974acd9cab127e952cb1f9b569dfc4b","best_bid":"0.86","best_ask":"0.87"},{"asset_id":"86520121088881862182423437128238697252500151785248183602134095101149900014256","price":"0.14","size":"209.59","side":"SELL","hash":"b4efcee2371e3ff5a0c318b41f9189e39148e1d0","best_bid":"0.13","best_ask":"0.14"}],"timestamp":"1776808417534","event_type":"price_change"}}
{"capturedAt":1776808417,"payload":{"market":"0x125149c5918fc5f8c6d34682f700a898a1a19ea4f4e2ae68ff4c5794ba657074","price_changes":[{"asset_id":"45936375922793925919605092352922707796689801895417366600539442410775071099958","price":"0.86","size":"190.59","side":"BUY","hash":"6d9bc4cea3430e5f2b89ccad63f4a92fb71d290e","best_bid":"0.86","best_ask":"0.87"},{"asset_id":"86520121088881862182423437128238697252500151785248183602134095101149900014256","price":"0.14","size":"190.59","side":"SELL","hash":"4c703029c3b301aaf43b5d89d1e6c6ddc0062979","best_bid":"0.13","best_ask":"0.14"}],"timestamp":"1776808417547","event_type":"price_change"}}
{"capturedAt":1776808417,"payload":{"market":"0x125149c5918fc5f8c6d34682f700a898a1a19ea4f4e2ae68ff4c5794ba657074","price_changes":[{"asset_id":"45936375922793925919605092352922707796689801895417366600539442410775071099958","price":"0.01","size":"12334.83","side":"BUY","hash":"03a92a88a996bc2891d959360ca4c7e771cc6468","best_bid":"0.86","best_ask":"0.87"},{"asset_id":"86520121088881862182423437128238697252500151785248183602134095101149900014256","price":"0.99","size":"12334.83","side":"SELL","hash":"023c30de20c27ed7fec4e7ce501048a8881892db","best_bid":"0.13","best_ask":"0.14"}],"timestamp":"1776808417553","event_type":"price_change"}}
{"capturedAt":1776808417,"payload":{"market":"0x125149c5918fc5f8c6d34682f700a898a1a19ea4f4e2ae68ff4c5794ba657074","price_changes":[{"asset_id":"45936375922793925919605092352922707796689801895417366600539442410775071099958","price":"0.86","size":"195.59","side":"BUY","hash":"9183a3ad94c73a82216115507ef30574af3e7b84","best_bid":"0.86","best_ask":"0.87"},{"asset_id":"86520121088881862182423437128238697252500151785248183602134095101149900014256","price":"0.14","size":"195.59","side":"SELL","hash":"6680d5a7d12fdd51316e371c0412a1cfc8f67ccb","best_bid":"0.13","best_ask":"0.14"}],"timestamp":"1776808417551","event_type":"price_change"}}
{"capturedAt":1776808417,"payload":{"market":"0x125149c5918fc5f8c6d34682f700a898a1a19ea4f4e2ae68ff4c5794ba657074","price_changes":[{"asset_id":"45936375922793925919605092352922707796689801895417366600539442410775071099958","price":"0.97","size":"1743.83","side":"SELL","hash":"9d91e0bebd03035bcbab7dd746b424da2f811f26","best_bid":"0.86","best_ask":"0.87"},{"asset_id":"86520121088881862182423437128238697252500151785248183602134095101149900014256","price":"0.03","size":"1743.83","side":"BUY","hash":"5cd5b2498d797267eef0c0784a2c2f6cabd3dd78","best_bid":"0.13","best_ask":"0.14"}],"timestamp":"1776808417555","event_type":"price_change"}}
{"capturedAt":1776808417,"payload":{"market":"0x125149c5918fc5f8c6d34682f700a898a1a19ea4f4e2ae68ff4c5794ba657074","price_changes":[{"asset_id":"86520121088881862182423437128238697252500151785248183602134095101149900014256","price":"0.13","size":"253.74","side":"BUY","hash":"ffa4015b1cb0d9cbe32f091fb248052474ab27a6","best_bid":"0.13","best_ask":"0.14"},{"asset_id":"45936375922793925919605092352922707796689801895417366600539442410775071099958","price":"0.87","size":"253.74","side":"SELL","hash":"ea24fe8b8aac6f1d9e7b3d46645fbff519555980","best_bid":"0.86","best_ask":"0.87"}],"timestamp":"1776808417550","event_type":"price_change"}}
{"capturedAt":1776808417,"payload":{"market":"0x125149c5918fc5f8c6d34682f700a898a1a19ea4f4e2ae68ff4c5794ba657074","price_changes":[{"asset_id":"86520121088881862182423437128238697252500151785248183602134095101149900014256","price":"0.1","size":"612.8","side":"BUY","hash":"7a72bc4296f544c9bf47564324b5c168d3c818e4","best_bid":"0.13","best_ask":"0.14"},{"asset_id":"45936375922793925919605092352922707796689801895417366600539442410775071099958","price":"0.9","size":"612.8","side":"SELL","hash":"dbe025b7758d8324ed980557df80dcda115eab5c","best_bid":"0.86","best_ask":"0.87"}],"timestamp":"1776808417555","event_type":"price_change"}}
{"capturedAt":1776808417,"payload":{"market":"0x125149c5918fc5f8c6d34682f700a898a1a19ea4f4e2ae68ff4c5794ba657074","price_changes":[{"asset_id":"86520121088881862182423437128238697252500151785248183602134095101149900014256","price":"0.13","size":"263.74","side":"BUY","hash":"ef1301fa73c14bd616e213d218718b972e92fe81","best_bid":"0.13","best_ask":"0.14"},{"asset_id":"45936375922793925919605092352922707796689801895417366600539442410775071099958","price":"0.87","size":"263.74","side":"SELL","hash":"964ca6fa65bbc3751411baf391d7315a7e3a1925","best_bid":"0.86","best_ask":"0.87"}],"timestamp":"1776808417558","event_type":"price_change"}}
{"capturedAt":1776808417,"payload":{"market":"0x125149c5918fc5f8c6d34682f700a898a1a19ea4f4e2ae68ff4c5794ba657074","price_changes":[{"asset_id":"45936375922793925919605092352922707796689801895417366600539442410775071099958","price":"0.86","size":"200.59","side":"BUY","hash":"6b14459adbd01740cb6ad153aedce4e07742a13e","best_bid":"0.86","best_ask":"0.87"},{"asset_id":"86520121088881862182423437128238697252500151785248183602134095101149900014256","price":"0.14","size":"200.59","side":"SELL","hash":"e60183bc0a9fae81f1828cf1b6b25f95257d06ad","best_bid":"0.13","best_ask":"0.14"}],"timestamp":"1776808417557","event_type":"price_change"}}
{"capturedAt":1776808417,"payload":{"market":"0x125149c5918fc5f8c6d34682f700a898a1a19ea4f4e2ae68ff4c5794ba657074","price_changes":[{"asset_id":"45936375922793925919605092352922707796689801895417366600539442410775071099958","price":"0.82","size":"371.78","side":"BUY","hash":"9e8bdfdbd6afc096387724b2a85d642fb23d9195","best_bid":"0.86","best_ask":"0.87"},{"asset_id":"86520121088881862182423437128238697252500151785248183602134095101149900014256","price":"0.18","size":"371.78","side":"SELL","hash":"562c6940b3fd6ed0e093223cda105db6f01347eb","best_bid":"0.13","best_ask":"0.14"}],"timestamp":"1776808417552","event_type":"price_change"}}
{"capturedAt":1776808417,"payload":{"market":"0x125149c5918fc5f8c6d34682f700a898a1a19ea4f4e2ae68ff4c5794ba657074","price_changes":[{"asset_id":"45936375922793925919605092352922707796689801895417366600539442410775071099958","price":"0.86","size":"100.59","side":"BUY","hash":"278df4bfe8db4904e428e752aee721167cad3fd2","best_bid":"0.86","best_ask":"0.87"},{"asset_id":"86520121088881862182423437128238697252500151785248183602134095101149900014256","price":"0.14","size":"100.59","side":"SELL","hash":"d156e15301348cc104ed5d086a4d479f8d1c2c7c","best_bid":"0.13","best_ask":"0.14"}],"timestamp":"1776808417560","event_type":"price_change"}}
{"capturedAt":1776808417,"payload":{"market":"0x125149c5918fc5f8c6d34682f700a898a1a19ea4f4e2ae68ff4c5794ba657074","price_changes":[{"asset_id":"45936375922793925919605092352922707796689801895417366600539442410775071099958","price":"0.01","size":"12329.83","side":"BUY","hash":"afe52a476751a9181abae31dad356691f38f61b9","best_bid":"0.86","best_ask":"0.87"},{"asset_id":"86520121088881862182423437128238697252500151785248183602134095101149900014256","price":"0.99","size":"12329.83","side":"SELL","hash":"a710f5c28a09099b499572f19d41266784039af4","best_bid":"0.13","best_ask":"0.14"}],"timestamp":"1776808417563","event_type":"price_change"}}
{"capturedAt":1776808417,"payload":{"market":"0x125149c5918fc5f8c6d34682f700a898a1a19ea4f4e2ae68ff4c5794ba657074","price_changes":[{"asset_id":"45936375922793925919605092352922707796689801895417366600539442410775071099958","price":"0.86","size":"105.59","side":"BUY","hash":"f913fe79145aeec03a07453047120b7c849db40e","best_bid":"0.86","best_ask":"0.87"},{"asset_id":"86520121088881862182423437128238697252500151785248183602134095101149900014256","price":"0.14","size":"105.59","side":"SELL","hash":"e3d5ced93a233681ce1e90e0275af1e2aa1f459c","best_bid":"0.13","best_ask":"0.14"}],"timestamp":"1776808417561","event_type":"price_change"}}
{"capturedAt":1776808417,"payload":{"market":"0x125149c5918fc5f8c6d34682f700a898a1a19ea4f4e2ae68ff4c5794ba657074","price_changes":[{"asset_id":"45936375922793925919605092352922707796689801895417366600539442410775071099958","price":"0.86","size":"110.59","side":"BUY","hash":"3cee7a4b580895e28ffa1d2112d09ad08fa3cef3","best_bid":"0.86","best_ask":"0.87"},{"asset_id":"86520121088881862182423437128238697252500151785248183602134095101149900014256","price":"0.14","size":"110.59","side":"SELL","hash":"3a6f4516b0b87d735523bbc316e93acba8448092","best_bid":"0.13","best_ask":"0.14"}],"timestamp":"1776808417562","event_type":"price_change"}}
{"capturedAt":1776808417,"payload":{"market":"0x125149c5918fc5f8c6d34682f700a898a1a19ea4f4e2ae68ff4c5794ba657074","price_changes":[{"asset_id":"45936375922793925919605092352922707796689801895417366600539442410775071099958","price":"0.86","size":"108.59","side":"BUY","hash":"b09c39a5352b7fa43eff2a31426dc9a359e0eebc","best_bid":"0.86","best_ask":"0.87"},{"asset_id":"86520121088881862182423437128238697252500151785248183602134095101149900014256","price":"0.14","size":"108.59","side":"SELL","hash":"b6f4dfe1b725036932f18f36af79074330fe3b17","best_bid":"0.13","best_ask":"0.14"}],"timestamp":"1776808417565","event_type":"price_change"}}
{"capturedAt":1776808417,"payload":{"market":"0x125149c5918fc5f8c6d34682f700a898a1a19ea4f4e2ae68ff4c5794ba657074","price_changes":[{"asset_id":"45936375922793925919605092352922707796689801895417366600539442410775071099958","price":"0.86","size":"115.59","side":"BUY","hash":"6f349ca9d78b11c0b2d76efb6487321783086be6","best_bid":"0.86","best_ask":"0.87"},{"asset_id":"86520121088881862182423437128238697252500151785248183602134095101149900014256","price":"0.14","size":"115.59","side":"SELL","hash":"03190e60aa2308a155fb8aaf750977af4cde0feb","best_bid":"0.13","best_ask":"0.14"}],"timestamp":"1776808417564","event_type":"price_change"}}
{"capturedAt":1776808417,"payload":{"market":"0x125149c5918fc5f8c6d34682f700a898a1a19ea4f4e2ae68ff4c5794ba657074","price_changes":[{"asset_id":"45936375922793925919605092352922707796689801895417366600539442410775071099958","price":"0.48","size":"242.56","side":"BUY","hash":"d42851447521eaf52aba8f9a78fa614edfc08252","best_bid":"0.86","best_ask":"0.87"},{"asset_id":"86520121088881862182423437128238697252500151785248183602134095101149900014256","price":"0.52","size":"242.56","side":"SELL","hash":"82a2eec2f41961789974610c4ebb160b66d14c0b","best_bid":"0.13","best_ask":"0.14"}],"timestamp":"1776808417559","event_type":"price_change"}}
{"capturedAt":1776808417,"payload":{"market":"0x125149c5918fc5f8c6d34682f700a898a1a19ea4f4e2ae68ff4c5794ba657074","price_changes":[{"asset_id":"86520121088881862182423437128238697252500151785248183602134095101149900014256","price":"0.13","size":"258.74","side":"BUY","hash":"40a7f703243a0e5b5a4bf5c6fadfbb8a8c98dda7","best_bid":"0.13","best_ask":"0.14"},{"asset_id":"45936375922793925919605092352922707796689801895417366600539442410775071099958","price":"0.87","size":"258.74","side":"SELL","hash":"8dbd7675af77045ae8ad088e87a365e70b5aba31","best_bid":"0.86","best_ask":"0.87"}],"timestamp":"1776808417556","event_type":"price_change"}}
{"capturedAt":1776808417,"payload":{"market":"0x125149c5918fc5f8c6d34682f700a898a1a19ea4f4e2ae68ff4c5794ba657074","price_changes":[{"asset_id":"86520121088881862182423437128238697252500151785248183602134095101149900014256","price":"0.13","size":"268.74","side":"BUY","hash":"ae2d2a99a16e98a9af482704d34c8bb5e6c11a90","best_bid":"0.13","best_ask":"0.14"},{"asset_id":"45936375922793925919605092352922707796689801895417366600539442410775071099958","price":"0.87","size":"268.74","side":"SELL","hash":"bc62edb3a8835d9c271a50a76d777b23d3dba64d","best_bid":"0.86","best_ask":"0.87"}],"timestamp":"1776808417566","event_type":"price_change"}}
{"capturedAt":1776808417,"payload":{"market":"0x125149c5918fc5f8c6d34682f700a898a1a19ea4f4e2ae68ff4c5794ba657074","price_changes":[{"asset_id":"86520121088881862182423437128238697252500151785248183602134095101149900014256","price":"0.13","size":"278.74","side":"BUY","hash":"3b310a64f55050a34f689720c1d4f1b9a21c80bb","best_bid":"0.13","best_ask":"0.14"},{"asset_id":"45936375922793925919605092352922707796689801895417366600539442410775071099958","price":"0.87","size":"278.74","side":"SELL","hash":"b2c11116001ba27c40633b1c0e2ae3128caecebb","best_bid":"0.86","best_ask":"0.87"}],"timestamp":"1776808417571","event_type":"price_change"}}
{"capturedAt":1776808417,"payload":{"market":"0x125149c5918fc5f8c6d34682f700a898a1a19ea4f4e2ae68ff4c5794ba657074","price_changes":[{"asset_id":"45936375922793925919605092352922707796689801895417366600539442410775071099958","price":"0.76","size":"348.49","side":"BUY","hash":"2e19f96529e0dae08a11d4bf26bb5ac222b2e85f","best_bid":"0.86","best_ask":"0.87"},{"asset_id":"86520121088881862182423437128238697252500151785248183602134095101149900014256","price":"0.24","size":"348.49","side":"SELL","hash":"1f5e04ca81504ccb1cea3da873a8727c4dc1c0f1","best_bid":"0.13","best_ask":"0.14"}],"timestamp":"1776808417574","event_type":"price_change"}}
{"capturedAt":1776808417,"payload":{"market":"0x125149c5918fc5f8c6d34682f700a898a1a19ea4f4e2ae68ff4c5794ba657074","price_changes":[{"asset_id":"86520121088881862182423437128238697252500151785248183602134095101149900014256","price":"0.09","size":"417","side":"BUY","hash":"37631d637cb02d9acf33248531039a99d6caf329","best_bid":"0.13","best_ask":"0.14"},{"asset_id":"45936375922793925919605092352922707796689801895417366600539442410775071099958","price":"0.91","size":"417","side":"SELL","hash":"52403569cad80d3e428aac82245fad7c1c2f18bc","best_bid":"0.86","best_ask":"0.87"}],"timestamp":"1776808417573","event_type":"price_change"}}
{"capturedAt":1776808417,"payload":{"market":"0x125149c5918fc5f8c6d34682f700a898a1a19ea4f4e2ae68ff4c5794ba657074","price_changes":[{"asset_id":"45936375922793925919605092352922707796689801895417366600539442410775071099958","price":"0.86","size":"113.59","side":"BUY","hash":"b773a9751200f38e64dc020110b9de38461c4190","best_bid":"0.86","best_ask":"0.87"},{"asset_id":"86520121088881862182423437128238697252500151785248183602134095101149900014256","price":"0.14","size":"113.59","side":"SELL","hash":"585fdea31b7cb9be69f4997a60d647c1cb4d058c","best_bid":"0.13","best_ask":"0.14"}],"timestamp":"1776808417567","event_type":"price_change"}}
{"capturedAt":1776808417,"payload":{"market":"0x125149c5918fc5f8c6d34682f700a898a1a19ea4f4e2ae68ff4c5794ba657074","price_changes":[{"asset_id":"86520121088881862182423437128238697252500151785248183602134095101149900014256","price":"0.06","size":"647.8","side":"BUY","hash":"05377e901fd27902b143a54e4ab9e4ad35ce5428","best_bid":"0.13","best_ask":"0.14"},{"asset_id":"45936375922793925919605092352922707796689801895417366600539442410775071099958","price":"0.94","size":"647.8","side":"SELL","hash":"ef8e95fd1533be470b45cb5a2c13794b28188450","best_bid":"0.86","best_ask":"0.87"}],"timestamp":"1776808417577","event_type":"price_change"}}
{"capturedAt":1776808417,"payload":{"market":"0x125149c5918fc5f8c6d34682f700a898a1a19ea4f4e2ae68ff4c5794ba657074","price_changes":[{"asset_id":"45936375922793925919605092352922707796689801895417366600539442410775071099958","price":"0.82","size":"365.9","side":"BUY","hash":"f261ee28600c7913ac6f3b6ce0f37e1877186034","best_bid":"0.86","best_ask":"0.87"},{"asset_id":"86520121088881862182423437128238697252500151785248183602134095101149900014256","price":"0.18","size":"365.9","side":"SELL","hash":"4536a5ee717e4cf8d1c7413a9085f9fbfa0bf85f","best_bid":"0.13","best_ask":"0.14"}],"timestamp":"1776808417579","event_type":"price_change"}}
{"capturedAt":1776808417,"payload":{"market":"0x125149c5918fc5f8c6d34682f700a898a1a19ea4f4e2ae68ff4c5794ba657074","price_changes":[{"asset_id":"45936375922793925919605092352922707796689801895417366600539442410775071099958","price":"0.83","size":"318.3","side":"BUY","hash":"2f56ca1d5404fa6194f4c0b97163492519725bda","best_bid":"0.86","best_ask":"0.87"},{"asset_id":"86520121088881862182423437128238697252500151785248183602134095101149900014256","price":"0.17","size":"318.3","side":"SELL","hash":"3b9c763078841351d5511a1b3ac497e338a849ec","best_bid":"0.13","best_ask":"0.14"}],"timestamp":"1776808417578","event_type":"price_change"}}
{"capturedAt":1776808417,"payload":{"market":"0x125149c5918fc5f8c6d34682f700a898a1a19ea4f4e2ae68ff4c5794ba657074","price_changes":[{"asset_id":"86520121088881862182423437128238697252500151785248183602134095101149900014256","price":"0.1","size":"593.5","side":"BUY","hash":"0020ea5103338b3c9399120c7320a576e67b7da8","best_bid":"0.13","best_ask":"0.14"},{"asset_id":"45936375922793925919605092352922707796689801895417366600539442410775071099958","price":"0.9","size":"593.5","side":"SELL","hash":"b42dba835039e4f3bada314fe1655c15ec1db55c","best_bid":"0.86","best_ask":"0.87"}],"timestamp":"1776808417580","event_type":"price_change"}}
{"capturedAt":1776808417,"payload":{"market":"0x125149c5918fc5f8c6d34682f700a898a1a19ea4f4e2ae68ff4c5794ba657074","price_changes":[{"asset_id":"45936375922793925919605092352922707796689801895417366600539442410775071099958","price":"0.01","size":"12324.83","side":"BUY","hash":"4f2237cbe82b20170e3a6b0e590b3a85d27bb9dd","best_bid":"0.86","best_ask":"0.87"},{"asset_id":"86520121088881862182423437128238697252500151785248183602134095101149900014256","price":"0.99","size":"12324.83","side":"SELL","hash":"a4d9493149158d5faf94d328a77ad97281bacf6e","best_bid":"0.13","best_ask":"0.14"}],"timestamp":"1776808417576","event_type":"price_change"}}
{"capturedAt":1776808417,"payload":{"market":"0x125149c5918fc5f8c6d34682f700a898a1a19ea4f4e2ae68ff4c5794ba657074","price_changes":[{"asset_id":"86520121088881862182423437128238697252500151785248183602134095101149900014256","price":"0.13","size":"263.74","side":"BUY","hash":"fc931d2498ac3b505b78d32da86ecd592eee46e1","best_bid":"0.13","best_ask":"0.14"},{"asset_id":"45936375922793925919605092352922707796689801895417366600539442410775071099958","price":"0.87","size":"263.74","side":"SELL","hash":"59f1d3cffa16d4444e51d46ef116c8f01f4e5811","best_bid":"0.86","best_ask":"0.87"}],"timestamp":"1776808417581","event_type":"price_change"}}
{"capturedAt":1776808417,"payload":{"market":"0x125149c5918fc5f8c6d34682f700a898a1a19ea4f4e2ae68ff4c5794ba657074","price_changes":[{"asset_id":"86520121088881862182423437128238697252500151785248183602134095101149900014256","price":"0.13","size":"268.74","side":"BUY","hash":"2159ea622203eaf1547abea699460b0edec71697","best_bid":"0.13","best_ask":"0.14"},{"asset_id":"45936375922793925919605092352922707796689801895417366600539442410775071099958","price":"0.87","size":"268.74","side":"SELL","hash":"c07dbdc4214235527769ab3b28992ddf6bf89e24","best_bid":"0.86","best_ask":"0.87"}],"timestamp":"1776808417572","event_type":"price_change"}}
{"capturedAt":1776808417,"payload":{"market":"0x125149c5918fc5f8c6d34682f700a898a1a19ea4f4e2ae68ff4c5794ba657074","price_changes":[{"asset_id":"86520121088881862182423437128238697252500151785248183602134095101149900014256","price":"0.13","size":"268.74","side":"BUY","hash":"4efa6a0b331532bcb03fed06642203caa067771d","best_bid":"0.13","best_ask":"0.14"},{"asset_id":"45936375922793925919605092352922707796689801895417366600539442410775071099958","price":"0.87","size":"268.74","side":"SELL","hash":"4a1c54efb2b2596e9e0ee33deb4e0c807029d55b","best_bid":"0.86","best_ask":"0.87"}],"timestamp":"1776808417582","event_type":"price_change"}}
{"capturedAt":1776808417,"payload":{"market":"0x125149c5918fc5f8c6d34682f700a898a1a19ea4f4e2ae68ff4c5794ba657074","price_changes":[{"asset_id":"45936375922793925919605092352922707796689801895417366600539442410775071099958","price":"0.67","size":"432.3","side":"BUY","hash":"6f42f76f0e2a386a5a01a90521126fe0e301211c","best_bid":"0.86","best_ask":"0.87"},{"asset_id":"86520121088881862182423437128238697252500151785248183602134095101149900014256","price":"0.33","size":"432.3","side":"SELL","hash":"9f6159fcf15d5d5650f7aef223cf8ef422934642","best_bid":"0.13","best_ask":"0.14"}],"timestamp":"1776808417582","event_type":"price_change"}}
{"capturedAt":1776808417,"payload":{"market":"0x125149c5918fc5f8c6d34682f700a898a1a19ea4f4e2ae68ff4c5794ba657074","price_changes":[{"asset_id":"45936375922793925919605092352922707796689801895417366600539442410775071099958","price":"0.86","size":"108.59","side":"BUY","hash":"6f9bfecfbbc4bbcab28b98be7fd03f97e4b3756d","best_bid":"0.86","best_ask":"0.87"},{"asset_id":"86520121088881862182423437128238697252500151785248183602134095101149900014256","price":"0.14","size":"108.59","side":"SELL","hash":"a3813c136e0779d0f8cb432f08ed24c4e7ba6cfe","best_bid":"0.13","best_ask":"0.14"}],"timestamp":"1776808417580","event_type":"price_change"}}
{"capturedAt":1776808417,"payload":{"market":"0x125149c5918fc5f8c6d34682f700a898a1a19ea4f4e2ae68ff4c5794ba657074","price_changes":[{"asset_id":"86520121088881862182423437128238697252500151785248183602134095101149900014256","price":"0.13","size":"263.74","side":"BUY","hash":"6c14902cd9da46fce957653100a2ec558c2c8544","best_bid":"0.13","best_ask":"0.14"},{"asset_id":"45936375922793925919605092352922707796689801895417366600539442410775071099958","price":"0.87","size":"263.74","side":"SELL","hash":"ed30bb36866b051a82cdc8e039403a3941d1282c","best_bid":"0.86","best_ask":"0.87"}],"timestamp":"1776808417585","event_type":"price_change"}}
{"capturedAt":1776808417,"payload":{"market":"0x125149c5918fc5f8c6d34682f700a898a1a19ea4f4e2ae68ff4c5794ba657074","price_changes":[{"asset_id":"45936375922793925919605092352922707796689801895417366600539442410775071099958","price":"0.86","size":"103.59","side":"BUY","hash":"d462724980458ed1332742277629dfa969a93ea4","best_bid":"0.86","best_ask":"0.87"},{"asset_id":"86520121088881862182423437128238697252500151785248183602134095101149900014256","price":"0.14","size":"103.59","side":"SELL","hash":"45a7a141bdf06a95de83f4f9b56a9ed335ecc8a4","best_bid":"0.13","best_ask":"0.14"}],"timestamp":"1776808417585","event_type":"price_change"}}
{"capturedAt":1776808417,"payload":{"market":"0x125149c5918fc5f8c6d34682f700a898a1a19ea4f4e2ae68ff4c5794ba657074","price_changes":[{"asset_id":"45936375922793925919605092352922707796689801895417366600539442410775071099958","price":"0.86","size":"108.59","side":"BUY","hash":"39b4201d778ec35a88d138374f67d4baaf06a9f1","best_bid":"0.86","best_ask":"0.87"},{"asset_id":"86520121088881862182423437128238697252500151785248183602134095101149900014256","price":"0.14","size":"108.59","side":"SELL","hash":"615d790bdd32a1beb07ba8c420ffa408b5e47bf7","best_bid":"0.13","best_ask":"0.14"}],"timestamp":"1776808417586","event_type":"price_change"}}
{"capturedAt":1776808417,"payload":{"market":"0x125149c5918fc5f8c6d34682f700a898a1a19ea4f4e2ae68ff4c5794ba657074","price_changes":[{"asset_id":"45936375922793925919605092352922707796689801895417366600539442410775071099958","price":"0.01","size":"12329.83","side":"BUY","hash":"a0c43e43f2c508cacf78968036c7cc153b1df899","best_bid":"0.86","best_ask":"0.87"},{"asset_id":"86520121088881862182423437128238697252500151785248183602134095101149900014256","price":"0.99","size":"12329.83","side":"SELL","hash":"733698567e7f3f0466ce81087f92026fa87db705","best_bid":"0.13","best_ask":"0.14"}],"timestamp":"1776808417588","event_type":"price_change"}}
{"capturedAt":1776808417,"payload":{"market":"0x125149c5918fc5f8c6d34682f700a898a1a19ea4f4e2ae68ff4c5794ba657074","price_changes":[{"asset_id":"45936375922793925919605092352922707796689801895417366600539442410775071099958","price":"0.78","size":"293.98","side":"BUY","hash":"348894208628db72cf0b37e14433f271ce210389","best_bid":"0.86","best_ask":"0.87"},{"asset_id":"86520121088881862182423437128238697252500151785248183602134095101149900014256","price":"0.22","size":"293.98","side":"SELL","hash":"d0acf70c7fd0b4b1aa0c14f500a42fa20d7584cc","best_bid":"0.13","best_ask":"0.14"}],"timestamp":"1776808417583","event_type":"price_change"}}
{"capturedAt":1776808417,"payload":{"market":"0x125149c5918fc5f8c6d34682f700a898a1a19ea4f4e2ae68ff4c5794ba657074","price_changes":[{"asset_id":"45936375922793925919605092352922707796689801895417366600539442410775071099958","price":"0.86","size":"102.98","side":"BUY","hash":"dbbf8bed1c6fb9099a963842cbe743154ab86785","best_bid":"0.86","best_ask":"0.87"},{"asset_id":"86520121088881862182423437128238697252500151785248183602134095101149900014256","price":"0.14","size":"102.98","side":"SELL","hash":"c305e69c1a97026c18a9eba8c714d1b05cdc28c3","best_bid":"0.13","best_ask":"0.14"}],"timestamp":"1776808417590","event_type":"price_change"}}
{"capturedAt":1776808417,"payload":{"market":"0x125149c5918fc5f8c6d34682f700a898a1a19ea4f4e2ae68ff4c5794ba657074","price_changes":[{"asset_id":"45936375922793925919605092352922707796689801895417366600539442410775071099958","price":"0.01","size":"12334.83","side":"BUY","hash":"5ede38a43abb5f23f28bee09f01f9411022b9aad","best_bid":"0.86","best_ask":"0.87"},{"asset_id":"86520121088881862182423437128238697252500151785248183602134095101149900014256","price":"0.99","size":"12334.83","side":"SELL","hash":"38dc77a9299c883ae9a530c1f1fc7286fcf93334","best_bid":"0.13","best_ask":"0.14"}],"timestamp":"1776808417599","event_type":"price_change"}}
{"capturedAt":1776808417,"payload":{"market":"0x125149c5918fc5f8c6d34682f700a898a1a19ea4f4e2ae68ff4c5794ba657074","price_changes":[{"asset_id":"86520121088881862182423437128238697252500151785248183602134095101149900014256","price":"0.13","size":"268.74","side":"BUY","hash":"362847e0329f5ce7546e029ccf5fcd52e1c3f325","best_bid":"0.13","best_ask":"0.14"},{"asset_id":"45936375922793925919605092352922707796689801895417366600539442410775071099958","price":"0.87","size":"268.74","side":"SELL","hash":"05538f9cce9bafc7fd2396bd9f2702d365dbcb4d","best_bid":"0.86","best_ask":"0.87"}],"timestamp":"1776808417603","event_type":"price_change"}}
{"capturedAt":1776808417,"payload":{"market":"0x125149c5918fc5f8c6d34682f700a898a1a19ea4f4e2ae68ff4c5794ba657074","price_changes":[{"asset_id":"86520121088881862182423437128238697252500151785248183602134095101149900014256","price":"0.12","size":"327.5","side":"BUY","hash":"d92b67df9bbdb5e9452c8ba024364990d6aa7036","best_bid":"0.13","best_ask":"0.14"},{"asset_id":"45936375922793925919605092352922707796689801895417366600539442410775071099958","price":"0.88","size":"327.5","side":"SELL","hash":"1bf13ece70ea1f4e469c39cc9bc63209e195c9f3","best_bid":"0.86","best_ask":"0.87"}],"timestamp":"1776808417605","event_type":"price_change"}}
{"capturedAt":1776808417,"payload":{"market":"0x125149c5918fc5f8c6d34682f700a898a1a19ea4f4e2ae68ff4c5794ba657074","price_changes":[{"asset_id":"86520121088881862182423437128238697252500151785248183602134095101149900014256","price":"0.13","size":"278.74","side":"BUY","hash":"66262b89e00d167d4f030e13f305c8d26b17bd37","best_bid":"0.13","best_ask":"0.14"},{"asset_id":"45936375922793925919605092352922707796689801895417366600539442410775071099958","price":"0.87","size":"278.74","side":"SELL","hash":"4c54a6f1becf4c27d768cdbf86b9889586a9be60","best_bid":"0.86","best_ask":"0.87"}],"timestamp":"1776808417606","event_type":"price_change"}}
{"capturedAt":1776808417,"payload":{"market":"0x125149c5918fc5f8c6d34682f700a898a1a19ea4f4e2ae68ff4c5794ba657074","price_changes":[{"asset_id":"86520121088881862182423437128238697252500151785248183602134095101149900014256","price":"0.13","size":"273.74","side":"BUY","hash":"2c7203ff48c3debd90a5939b61fc0786319d2608","best_bid":"0.13","best_ask":"0.14"},{"asset_id":"45936375922793925919605092352922707796689801895417366600539442410775071099958","price":"0.87","size":"273.74","side":"SELL","hash":"7955a843fa121b7110705667fa203c7ecd392dd4","best_bid":"0.86","best_ask":"0.87"}],"timestamp":"1776808417606","event_type":"price_change"}}
{"capturedAt":1776808417,"payload":{"market":"0x125149c5918fc5f8c6d34682f700a898a1a19ea4f4e2ae68ff4c5794ba657074","price_changes":[{"asset_id":"45936375922793925919605092352922707796689801895417366600539442410775071099958","price":"0.86","size":"97.98","side":"BUY","hash":"a8db9f5c73b264aeb6f25a58b832b688a8d5bb1f","best_bid":"0.86","best_ask":"0.87"},{"asset_id":"86520121088881862182423437128238697252500151785248183602134095101149900014256","price":"0.14","size":"97.98","side":"SELL","hash":"b17ed56be888f4a72b88a4bc8b8ec7682a1e0e38","best_bid":"0.13","best_ask":"0.14"}],"timestamp":"1776808417607","event_type":"price_change"}}
{"capturedAt":1776808417,"payload":{"market":"0x125149c5918fc5f8c6d34682f700a898a1a19ea4f4e2ae68ff4c5794ba657074","price_changes":[{"asset_id":"45936375922793925919605092352922707796689801895417366600539442410775071099958","price":"0.01","size":"12329.83","side":"BUY","hash":"73cb9e3ef720f92cf05545fa29bea274011e445f","best_bid":"0.86","best_ask":"0.87"},{"asset_id":"86520121088881862182423437128238697252500151785248183602134095101149900014256","price":"0.99","size":"12329.83","side":"SELL","hash":"dcac1c11a827d8b236497a06e48bfc29446c0314","best_bid":"0.13","best_ask":"0.14"}],"timestamp":"1776808417609","event_type":"price_change"}}
