{"capturedAt":1776808416,"payload":{"market":"0x125149c5918fc5f8c6d34682f700a898a1a19ea4f4e2ae68ff4c5794ba657074","price_changes":[{"asset_id":"45936375922793925919605092352922707796689801895417366600539442410775071099958","price":"0.86","size":"279.18","side":"BUY","hash":"bdd32528359ac6b79c7251c41a0d69190821b569","best_bid":"0.86","best_ask":"0.87"},{"asset_id":"86520121088881862182423437128238697252500151785248183602134095101149900014256","price":"0.14","size":"279.18","side":"SELL","hash":"871eeaa248d8dbe62a6872ba201410aa40b172f4","best_bid":"0.13","best_ask":"0.14"}],"timestamp":"1776808416247","event_type":"price_change"}}
{"capturedAt":1776808416,"payload":{"market":"0x125149c5918fc5f8c6d34682f700a898a1a19ea4f4e2ae68ff4c5794ba657074","price_changes":[{"asset_id":"45936375922793925919605092352922707796689801895417366600539442410775071099958","price":"0.86","size":"293.18","side":"BUY","hash":"1ad1ee07d3ac6885c77e8b1ea9ebb6e5fb1124b4","best_bid":"0.86","best_ask":"0.87"},{"asset_id":"86520121088881862182423437128238697252500151785248183602134095101149900014256","price":"0.14","size":"293.18","side":"SELL","hash":"6dda687379aa0a499fa04207696fe56ecc67277e","best_bid":"0.13","best_ask":"0.14"}],"timestamp":"1776808416258","event_type":"price_change"}}
{"capturedAt":1776808416,"payload":{"market":"0x125149c5918fc5f8c6d34682f700a898a1a19ea4f4e2ae68ff4c5794ba657074","price_changes":[{"asset_id":"45936375922793925919605092352922707796689801895417366600539442410775071099958","price":"0.86","size":"299.18","side":"BUY","hash":"82494eb68454364211db3c2f9f90733d78e22176","best_bid":"0.86","best_ask":"0.87"},{"asset_id":"86520121088881862182423437128238697252500151785248183602134095101149900014256","price":"0.14","size":"299.18","side":"SELL","hash":"90e533ac652435d7f731a8af2b7ad63246fe860a","best_bid":"0.13","best_ask":"0.14"}],"timestamp":"1776808416263","event_type":"price_change"}}
{"capturedAt":1776808416,"payload":{"market":"0x125149c5918fc5f8c6d34682f700a898a1a19ea4f4e2ae68ff4c5794ba657074","price_changes":[{"asset_id":"45936375922793925919605092352922707796689801895417366600539442410775071099958","price":"0.86","size":"327.18","side":"BUY","hash":"148fbe7ea8d4108779c8d5c4ae0f8577d0938038","best_bid":"0.86","best_ask":"0.87"},{"asset_id":"86520121088881862182423437128238697252500151785248183602134095101149900014256","price":"0.14","size":"327.18","side":"SELL","hash":"f358f7bc99b811b5aac0651cd848ba09e4571577","best_bid":"0.13","best_ask":"0.14"}],"timestamp":"1776808416262","event_type":"price_change"}}
{"capturedAt":1776808416,"payload":{"market":"0x125149c5918fc5f8c6d34682f700a898a1a19ea4f4e2ae68ff4c5794ba657074","price_changes":[{"asset_id":"45936375922793925919605092352922707796689801895417366600539442410775071099958","price":"0.01","size":"12329.83","side":"BUY","hash":"37d3bf0eabe34bbdc54d0f2b8ca41507b2be2f6f","best_bid":"0.86","best_ask":"0.87"},{"asset_id":"86520121088881862182423437128238697252500151785248183602134095101149900014256","price":"0.99","size":"12329.83","side":"SELL","hash":"b5f59652b5b87a37eae45d74b8e6457f73993ad7","best_bid":"0.13","best_ask":"0.14"}],"timestamp":"1776808416265","event_type":"price_change"}}
{"capturedAt":1776808416,"payload":{"market":"0x125149c5918fc5f8c6d34682f700a898a1a19ea4f4e2ae68ff4c5794ba657074","price_changes":[{"asset_id":"45936375922793925919605092352922707796689801895417366600539442410775071099958","price":"0.86","size":"317.18","side":"BUY","hash":"22bf275b096880a016f97db3ae7f451cbc174e63","best_bid":"0.86","best_ask":"0.87"},{"asset_id":"86520121088881862182423437128238697252500151785248183602134095101149900014256","price":"0.14","size":"317.18","side":"SELL","hash":"fb5eb7f08d2358e03c019a80ac557c79724ec792","best_bid":"0.13","best_ask":"0.14"}],"timestamp":"1776808416261","event_type":"price_change"}}
{"capturedAt":1776808416,"payload":{"market":"0x125149c5918fc5f8c6d34682f700a898a1a19ea4f4e2ae68ff4c5794ba657074","price_changes":[{"asset_id":"45936375922793925919605092352922707796689801895417366600539442410775071099958","price":"0.86","size":"347.18","side":"BUY","hash":"c15e96887203c9c9e3bcb4d827e750e99a618e03","best_bid":"0.86","best_ask":"0.87"},{"asset_id":"86520121088881862182423437128238697252500151785248183602134095101149900014256","price":"0.14","size":"347.18","side":"SELL","hash":"3d7d972bfcb84e6bfe265709507b156e5d4b518b","best_bid":"0.13","best_ask":"0.14"}],"timestamp":"1776808416266","event_type":"price_change"}}
{"capturedAt":1776808416,"payload":{"market":"0x125149c5918fc5f8c6d34682f700a898a1a19ea4f4e2ae68ff4c5794ba657074","price_changes":[{"asset_id":"45936375922793925919605092352922707796689801895417366600539442410775071099958","price":"0.01","size":"12334.84","side":"BUY","hash":"3596273f8c81d0372394da9c1008b69110f60d33","best_bid":"0.86","best_ask":"0.87"},{"asset_id":"86520121088881862182423437128238697252500151785248183602134095101149900014256","price":"0.99","size":"12334.84","side":"SELL","hash":"1836410455df4bb6f06d64af0b861f8d0cecd9e1","best_bid":"0.13","best_ask":"0.14"}],"timestamp":"1776808416259","event_type":"price_change"}}
{"capturedAt":1776808416,"payload":{"market":"0x125149c5918fc5f8c6d34682f700a898a1a19ea4f4e2ae68ff4c5794ba657074","price_changes":[{"asset_id":"45936375922793925919605092352922707796689801895417366600539442410775071099958","price":"0.86","size":"323.18","side":"BUY","hash":"2ac5a745645291a8f443e224d3834c71181b9e4d","best_bid":"0.86","best_ask":"0.87"},{"asset_id":"86520121088881862182423437128238697252500151785248183602134095101149900014256","price":"0.14","size":"323.18","side":"SELL","hash":"d904cb73283b35c5d080a87449cd5835ad448fe2","best_bid":"0.13","best_ask":"0.14"}],"timestamp":"1776808416264","event_type":"price_change"}}
{"capturedAt":1776808416,"payload":{"market":"0x125149c5918fc5f8c6d34682f700a898a1a19ea4f4e2ae68ff4c5794ba657074","price_changes":[{"asset_id":"45936375922793925919605092352922707796689801895417366600539442410775071099958","price":"0.01","size":"12324.83","side":"BUY","hash":"19ab6082d23dff53a4ec7551300bb640eec6d11e","best_bid":"0.86","best_ask":"0.87"},{"asset_id":"86520121088881862182423437128238697252500151785248183602134095101149900014256","price":"0.99","size":"12324.83","side":"SELL","hash":"1529432b5869397c4beb7c7b0f65ff8782023ed5","best_bid":"0.13","best_ask":"0.14"}],"timestamp":"1776808416268","event_type":"price_change"}}
{"capturedAt":1776808416,"payload":{"market":"0x125149c5918fc5f8c6d34682f700a898a1a19ea4f4e2ae68ff4c5794ba657074","price_changes":[{"asset_id":"45936375922793925919605092352922707796689801895417366600539442410775071099958","price":"0.86","size":"371.18","side":"BUY","hash":"4f6b2ff8897310b3534be22e80790f61d340e25f","best_bid":"0.86","best_ask":"0.87"},{"asset_id":"86520121088881862182423437128238697252500151785248183602134095101149900014256","price":"0.14","size":"371.18","side":"SELL","hash":"0155a167fad621fc726e32b739a5b228bbbe7297","best_bid":"0.13","best_ask":"0.14"}],"timestamp":"1776808416267","event_type":"price_change"}}
{"capturedAt":1776808416,"payload":{"market":"0x125149c5918fc5f8c6d34682f700a898a1a19ea4f4e2ae68ff4c5794ba657074","price_changes":[{"asset_id":"45936375922793925919605092352922707796689801895417366600539442410775071099958","price":"0.86","size":"366.14","side":"BUY","hash":"cf032fb82840590fc24a6e9d77995707a0ff1086","best_bid":"0.86","best_ask":"0.87"},{"asset_id":"86520121088881862182423437128238697252500151785248183602134095101149900014256","price":"0.14","size":"366.14","side":"SELL","hash":"6c5920aacfa3313c87ab4cd89ab7ffb7fa324b28","best_bid":"0.13","best_ask":"0.14"}],"timestamp":"1776808416269","event_type":"price_change"}}
{"capturedAt":1776808416,"payload":{"market":"0x125149c5918fc5f8c6d34682f700a898a1a19ea4f4e2ae68ff4c5794ba657074","price_changes":[{"asset_id":"45936375922793925919605092352922707796689801895417366600539442410775071099958","price":"0.86","size":"390.14","side":"BUY","hash":"fecc676bcf6737167aff8c03f60bb5139e2ad8eb","best_bid":"0.86","best_ask":"0.87"},{"asset_id":"86520121088881862182423437128238697252500151785248183602134095101149900014256","price":"0.14","size":"390.14","side":"SELL","hash":"b614343a394d2a506a609507e59d51a19a0c808d","best_bid":"0.13","best_ask":"0.14"}],"timestamp":"1776808416270","event_type":"price_change"}}
{"capturedAt":1776808416,"payload":{"market":"0x125149c5918fc5f8c6d34682f700a898a1a19ea4f4e2ae68ff4c5794ba657074","price_changes":[{"asset_id":"45936375922793925919605092352922707796689801895417366600539442410775071099958","price":"0.75","size":"475.29","side":"BUY","hash":"f14aae918ce9221c7f24cf7c26d786e96fb5ef42","best_bid":"0.86","best_ask":"0.87"},{"asset_id":"86520121088881862182423437128238697252500151785248183602134095101149900014256","price":"0.25","size":"475.29","side":"SELL","hash":"469b34a9682961fbafb12224083c8491c4213b44","best_bid":"0.13","best_ask":"0.14"}],"timestamp":"1776808416271","event_type":"price_change"}}
{"capturedAt":1776808416,"payload":{"market":"0x125149c5918fc5f8c6d34682f700a898a1a19ea4f4e2ae68ff4c5794ba657074","price_changes":[{"asset_id":"45936375922793925919605092352922707796689801895417366600539442410775071099958","price":"0.01","size":"12329.84","side":"BUY","hash":"5182aea3b9bba9adbd7d06ef5bf632a8553dc1e6","best_bid":"0.86","best_ask":"0.87"},{"asset_id":"86520121088881862182423437128238697252500151785248183602134095101149900014256","price":"0.99","size":"12329.84","side":"SELL","hash":"12dde934e4b1c0b4106c2a3c1c7228b0bdb4cafe","best_bid":"0.13","best_ask":"0.14"}],"timestamp":"1776808416272","event_type":"price_change"}}
{"capturedAt":1776808416,"payload":{"market":"0x125149c5918fc5f8c6d34682f700a898a1a19ea4f4e2ae68ff4c5794ba657074","price_changes":[{"asset_id":"45936375922793925919605092352922707796689801895417366600539442410775071099958","price":"0.86","size":"366.14","side":"BUY","hash":"5d7c90a7b73bbedbeb659a35e5c80aae211c9c70","best_bid":"0.86","best_ask":"0.87"},{"asset_id":"86520121088881862182423437128238697252500151785248183602134095101149900014256","price":"0.14","size":"366.14","side":"SELL","hash":"b7ba1b468afe0a688b9eea588c26dab4725994ad","best_bid":"0.13","best_ask":"0.14"}],"timestamp":"1776808416274","event_type":"price_change"}}
{"capturedAt":1776808416,"payload":{"market":"0x125149c5918fc5f8c6d34682f700a898a1a19ea4f4e2ae68ff4c5794ba657074","price_changes":[{"asset_id":"45936375922793925919605092352922707796689801895417366600539442410775071099958","price":"0.83","size":"349.46","side":"BUY","hash":"6755c93d46cc409400f24d4425961b120c21d569","best_bid":"0.86","best_ask":"0.87"},{"asset_id":"86520121088881862182423437128238697252500151785248183602134095101149900014256","price":"0.17","size":"349.46","side":"SELL","hash":"266b047f179ec3f7e028341f810c97d282aa1c71","best_bid":"0.13","best_ask":"0.14"}],"timestamp":"1776808416275","event_type":"price_change"}}
{"capturedAt":1776808416,"payload":{"market":"0x125149c5918fc5f8c6d34682f700a898a1a19ea4f4e2ae68ff4c5794ba657074","price_changes":[{"asset_id":"45936375922793925919605092352922707796689801895417366600539442410775071099958","price":"0.86","size":"356.14","side":"BUY","hash":"a92089c9bfd932c856ddec972a99a1b2f4144e73","best_bid":"0.86","best_ask":"0.87"},{"asset_id":"86520121088881862182423437128238697252500151785248183602134095101149900014256","price":"0.14","size":"356.14","side":"SELL","hash":"e0981b97fdd8843270481e009ed162e7c0946e2e","best_bid":"0.13","best_ask":"0.14"}],"timestamp":"1776808416276","event_type":"price_change"}}
{"capturedAt":1776808416,"payload":{"market":"0x125149c5918fc5f8c6d34682f700a898a1a19ea4f4e2ae68ff4c5794ba657074","price_changes":[{"asset_id":"45936375922793925919605092352922707796689801895417366600539442410775071099958","price":"0.86","size":"346.14","side":"BUY","hash":"d1b568c1a23bdeecdeafafe7a211e406394a2fbe","best_bid":"0.86","best_ask":"0.87"},{"asset_id":"86520121088881862182423437128238697252500151785248183602134095101149900014256","price":"0.14","size":"346.14","side":"SELL","hash":"15560e416e583807b8027df7ff2fd9dc061cfdfc","best_bid":"0.13","best_ask":"0.14"}],"timestamp":"1776808416279","event_type":"price_change"}}
{"capturedAt":1776808416,"payload":{"market":"0x125149c5918fc5f8c6d34682f700a898a1a19ea4f4e2ae68ff4c5794ba657074","price_changes":[{"asset_id":"45936375922793925919605092352922707796689801895417366600539442410775071099958","price":"0.86","size":"320.14","side":"BUY","hash":"3e2851884b9df39330b09934e9732e5aed3f6ce8","best_bid":"0.86","best_ask":"0.87"},{"asset_id":"86520121088881862182423437128238697252500151785248183602134095101149900014256","price":"0.14","size":"320.14","side":"SELL","hash":"3d2091cc789dc5d30de08c1a4d857204994a2dde","best_bid":"0.13","best_ask":"0.14"}],"timestamp":"1776808416286","event_type":"price_change"}}
{"capturedAt":1776808416,"payload":{"market":"0x125149c5918fc5f8c6d34682f700a898a1a19ea4f4e2ae68ff4c5794ba657074","price_changes":[{"asset_id":"45936375922793925919605092352922707796689801895417366600539442410775071099958","price":"0.01","size":"12334.84","side":"BUY","hash":"bd34fa214d533ee9945ab01d26bfddca6ac0e510","best_bid":"0.86","best_ask":"0.87"},{"asset_id":"86520121088881862182423437128238697252500151785248183602134095101149900014256","price":"0.99","size":"12334.84","side":"SELL","hash":"98e867a863eb1d965060d6b05e06082f94b24f65","best_bid":"0.13","best_ask":"0.14"}],"timestamp":"1776808416288","event_type":"price_change"}}
{"capturedAt":1776808416,"payload":{"market":"0x125149c5918fc5f8c6d34682f700a898a1a19ea4f4e2ae68ff4c5794ba657074","price_changes":[{"asset_id":"45936375922793925919605092352922707796689801895417366600539442410775071099958","price":"0.86","size":"346.14","side":"BUY","hash":"45c97fc46b3affaefa22afdf1821bb98b60b01af","best_bid":"0.86","best_ask":"0.87"},{"asset_id":"86520121088881862182423437128238697252500151785248183602134095101149900014256","price":"0.14","size":"346.14","side":"SELL","hash":"7b7848f9fd8932fb3d511efccb715ddd725e010e","best_bid":"0.13","best_ask":"0.14"}],"timestamp":"1776808416291","event_type":"price_change"}}
{"capturedAt":1776808416,"payload":{"market":"0x125149c5918fc5f8c6d34682f700a898a1a19ea4f4e2ae68ff4c5794ba657074","price_changes":[{"asset_id":"45936375922793925919605092352922707796689801895417366600539442410775071099958","price":"0.77","size":"229.3","side":"BUY","hash":"7767ee1d2a715b5c4af5852667d98714cd55cbf2","best_bid":"0.86","best_ask":"0.87"},{"asset_id":"86520121088881862182423437128238697252500151785248183602134095101149900014256","price":"0.23","size":"229.3","side":"SELL","hash":"4a342bed201dd1708505c9a32a009ec124f7dea1","best_bid":"0.13","best_ask":"0.14"}],"timestamp":"1776808416295","event_type":"price_change"}}
{"capturedAt":1776808416,"payload":{"market":"0x125149c5918fc5f8c6d34682f700a898a1a19ea4f4e2ae68ff4c5794ba657074","price_changes":[{"asset_id":"45936375922793925919605092352922707796689801895417366600539442410775071099958","price":"0.01","size":"12339.84","side":"BUY","hash":"e44d33b5c5863b0f20f15952294d0a101553abfa","best_bid":"0.86","best_ask":"0.87"},{"asset_id":"86520121088881862182423437128238697252500151785248183602134095101149900014256","price":"0.99","size":"12339.84","side":"SELL","hash":"fee5c88f129591a239fd044cdd4bd8db4235127f","best_bid":"0.13","best_ask":"0.14"}],"timestamp":"1776808416298","event_type":"price_change"}}
{"capturedAt":1776808416,"payload":{"market":"0x125149c5918fc5f8c6d34682f700a898a1a19ea4f4e2ae68ff4c5794ba657074","price_changes":[{"asset_id":"45936375922793925919605092352922707796689801895417366600539442410775071099958","price":"0.01","size":"12334.83","side":"BUY","hash":"f6295dfd68bf1b30a36ae3675987998407f8ae82","best_bid":"0.86","best_ask":"0.87"},{"asset_id":"86520121088881862182423437128238697252500151785248183602134095101149900014256","price":"0.99","size":"12334.83","side":"SELL","hash":"e360943f3100f87593af69a09e03e371ceea16a6","best_bid":"0.13","best_ask":"0.14"}],"timestamp":"1776808416302","event_type":"price_change"}}
{"capturedAt":1776808416,"payload":{"market":"0x125149c5918fc5f8c6d34682f700a898a1a19ea4f4e2ae68ff4c5794ba657074","price_changes":[{"asset_id":"45936375922793925919605092352922707796689801895417366600539442410775071099958","price":"0.86","size":"375.14","side":"BUY","hash":"aba7521912d13e9a7c96772301fba56eeebef886","best_bid":"0.86","best_ask":"0.87"},{"asset_id":"86520121088881862182423437128238697252500151785248183602134095101149900014256","price":"0.14","size":"375.14","side":"SELL","hash":"4273551c7e2451323d56dbf03ed28a1548c7033e","best_bid":"0.13","best_ask":"0.14"}],"timestamp":"1776808416304","event_type":"price_change"}}
{"capturedAt":1776808416,"payload":{"market":"0x125149c5918fc5f8c6d34682f700a898a1a19ea4f4e2ae68ff4c5794ba657074","price_changes":[{"asset_id":"45936375922793925919605092352922707796689801895417366600539442410775071099958","price":"0.01","size":"12329.83","side":"BUY","hash":"3a7a26968e38065c289f7dc138b830f967a702d2","best_bid":"0.86","best_ask":"0.87"},{"asset_id":"86520121088881862182423437128238697252500151785248183602134095101149900014256","price":"0.99","size":"12329.83","side":"SELL","hash":"4a624cf0d81779df197060a1c7aa19d2bb1bdf49","best_bid":"0.13","best_ask":"0.14"}],"timestamp":"1776808416305","event_type":"price_change"}}
{"capturedAt":1776808416,"payload":{"market":"0x125149c5918fc5f8c6d34682f700a898a1a19ea4f4e2ae68ff4c5794ba657074","price_changes":[{"asset_id":"45936375922793925919605092352922707796689801895417366600539442410775071099958","price":"0.86","size":"385.14","side":"BUY","hash":"4a58dd669ab02a803cca99185a8dbe0ff6dc391d","best_bid":"0.86","best_ask":"0.87"},{"asset_id":"86520121088881862182423437128238697252500151785248183602134095101149900014256","price":"0.14","size":"385.14","side":"SELL","hash":"ad4b77ec69245076f32582d48bb99805045ad643","best_bid":"0.13","best_ask":"0.14"}],"timestamp":"1776808416385","event_type":"price_change"}}
{"capturedAt":1776808416,"payload":{"market":"0x125149c5918fc5f8c6d34682f700a898a1a19ea4f4e2ae68ff4c5794ba657074","price_changes":[{"asset_id":"45936375922793925919605092352922707796689801895417366600539442410775071099958","price":"0.86","size":"395.14","side":"BUY","hash":"3b8b3958b8b5a5179c8a0ee493e1f31d4ec59b1c","best_bid":"0.86","best_ask":"0.87"},{"asset_id":"86520121088881862182423437128238697252500151785248183602134095101149900014256","price":"0.14","size":"395.14","side":"SELL","hash":"ec36c2bc47913a0bfef10261820f31ffeff0deef","best_bid":"0.13","best_ask":"0.14"}],"timestamp":"1776808416387","event_type":"price_change"}}
{"capturedAt":1776808416,"payload":{"market":"0x125149c5918fc5f8c6d34682f700a898a1a19ea4f4e2ae68ff4c5794ba657074","price_changes":[{"asset_id":"45936375922793925919605092352922707796689801895417366600539442410775071099958","price":"0.86","size":"423.14","side":"BUY","hash":"46ff1e6b3c653df0e0c576d87c9a5c9637b0d9da","best_bid":"0.86","best_ask":"0.87"},{"asset_id":"86520121088881862182423437128238697252500151785248183602134095101149900014256","price":"0.14","size":"423.14","side":"SELL","hash":"fa61680263057d06f9593a6607e939825e1acf0e","best_bid":"0.13","best_ask":"0.14"}],"timestamp":"1776808416388","event_type":"price_change"}}
{"capturedAt":1776808416,"payload":{"market":"0x125149c5918fc5f8c6d34682f700a898a1a19ea4f4e2ae68ff4c5794ba657074","price_changes":[{"asset_id":"45936375922793925919605092352922707796689801895417366600539442410775071099958","price":"0.86","size":"409.14","side":"BUY","hash":"fe4393ad9e019d3a234eb3079c0036ad10170bd3","best_bid":"0.86","best_ask":"0.87"},{"asset_id":"86520121088881862182423437128238697252500151785248183602134095101149900014256","price":"0.14","size":"409.14","side":"SELL","hash":"4460fca0ff641d739ba55abaa38544a7d3189f7d","best_bid":"0.13","best_ask":"0.14"}],"timestamp":"1776808416390","event_type":"price_change"}}
{"capturedAt":1776808416,"payload":{"market":"0x125149c5918fc5f8c6d34682f700a898a1a19ea4f4e2ae68ff4c5794ba657074","price_changes":[{"asset_id":"45936375922793925919605092352922707796689801895417366600539442410775071099958","price":"0.01","size":"12324.83","side":"BUY","hash":"c60cd7f04a93b211993bd4ee18dec3dd1c731c0b","best_bid":"0.86","best_ask":"0.87"},{"asset_id":"86520121088881862182423437128238697252500151785248183602134095101149900014256","price":"0.99","size":"12324.83","side":"SELL","hash":"ceba9d21487c98ba153863426cae530773b5d7eb","best_bid":"0.13","best_ask":"0.14"}],"timestamp":"1776808416392","event_type":"price_change"}}
{"capturedAt":1776808416,"payload":{"market":"0x125149c5918fc5f8c6d34682f700a898a1a19ea4f4e2ae68ff4c5794ba657074","price_changes":[{"asset_id":"45936375922793925919605092352922707796689801895417366600539442410775071099958","price":"0.86","size":"360.14","side":"BUY","hash":"cd5f4763fca31f7eb0159a09d50fc1f84718f1cc","best_bid":"0.86","best_ask":"0.87"},{"asset_id":"86520121088881862182423437128238697252500151785248183602134095101149900014256","price":"0.14","size":"360.14","side":"SELL","hash":"2dc223411be43fd9d5ca774cabcbd7257fecea48","best_bid":"0.13","best_ask":"0.14"}],"timestamp":"1776808416394","event_type":"price_change"}}
{"capturedAt":1776808416,"payload":{"market":"0x125149c5918fc5f8c6d34682f700a898a1a19ea4f4e2ae68ff4c5794ba657074","price_changes":[{"asset_id":"45936375922793925919605092352922707796689801895417366600539442410775071099958","price":"0.86","size":"384.14","side":"BUY","hash":"a3446978b9d5b3314586e96a705dec66ccc6dae1","best_bid":"0.86","best_ask":"0.87"},{"asset_id":"86520121088881862182423437128238697252500151785248183602134095101149900014256","price":"0.14","size":"384.14","side":"SELL","hash":"d9fb4ca061336a78b827f4f28537080abb49084f","best_bid":"0.13","best_ask":"0.14"}],"timestamp":"1776808416393","event_type":"price_change"}}
{"capturedAt":1776808416,"payload":{"market":"0x125149c5918fc5f8c6d34682f700a898a1a19ea4f4e2ae68ff4c5794ba657074","price_changes":[{"asset_id":"45936375922793925919605092352922707796689801895417366600539442410775071099958","price":"0.86","size":"350.14","side":"BUY","hash":"6cb41d67282202f12462b96fb3dd662c82cd7009","best_bid":"0.86","best_ask":"0.87"},{"asset_id":"86520121088881862182423437128238697252500151785248183602134095101149900014256","price":"0.14","size":"350.14","side":"SELL","hash":"a569b2040b1d28fc74d0da6853b2d739b3776340","best_bid":"0.13","best_ask":"0.14"}],"timestamp":"1776808416396","event_type":"price_change"}}
{"capturedAt":1776808416,"payload":{"market":"0x125149c5918fc5f8c6d34682f700a898a1a19ea4f4e2ae68ff4c5794ba657074","price_changes":[{"asset_id":"45936375922793925919605092352922707796689801895417366600539442410775071099958","price":"0.86","size":"326.14","side":"BUY","hash":"d916687e4cd785feff28b70678d3cb23def22317","best_bid":"0.86","best_ask":"0.87"},{"asset_id":"86520121088881862182423437128238697252500151785248183602134095101149900014256","price":"0.14","size":"326.14","side":"SELL","hash":"de8309145a5c284c017472901cb2c4e65f10ce5a","best_bid":"0.13","best_ask":"0.14"}],"timestamp":"1776808416397","event_type":"price_change"}}
{"capturedAt":1776808416,"payload":{"market":"0x125149c5918fc5f8c6d34682f700a898a1a19ea4f4e2ae68ff4c5794ba657074","price_changes":[{"asset_id":"45936375922793925919605092352922707796689801895417366600539442410775071099958","price":"0.86","size":"302.14","side":"BUY","hash":"d46a6860dfe9fc3e2cca48200e76ea9bc0763994","best_bid":"0.86","best_ask":"0.87"},{"asset_id":"86520121088881862182423437128238697252500151785248183602134095101149900014256","price":"0.14","size":"302.14","side":"SELL","hash":"ca4e043c0d0896746c5233a5c613d4a267228bc9","best_bid":"0.13","best_ask":"0.14"}],"timestamp":"1776808416399","event_type":"price_change"}}
{"capturedAt":1776808416,"payload":{"market":"0x125149c5918fc5f8c6d34682f700a898a1a19ea4f4e2ae68ff4c5794ba657074","price_changes":[{"asset_id":"45936375922793925919605092352922707796689801895417366600539442410775071099958","price":"0.86","size":"264.14","side":"BUY","hash":"d820498631e13e530cab35b55b5d1b0549648276","best_bid":"0.86","best_ask":"0.87"},{"asset_id":"86520121088881862182423437128238697252500151785248183602134095101149900014256","price":"0.14","size":"264.14","side":"SELL","hash":"bb64d5ecbb851516cc0e4f5cab5711639eb661ed","best_bid":"0.13","best_ask":"0.14"}],"timestamp":"1776808416401","event_type":"price_change"}}
{"capturedAt":1776808416,"payload":{"market":"0x125149c5918fc5f8c6d34682f700a898a1a19ea4f4e2ae68ff4c5794ba657074","price_changes":[{"asset_id":"45936375922793925919605092352922707796689801895417366600539442410775071099958","price":"0.86","size":"240.14","side":"BUY","hash":"2e31c454077c6c14422d84d26d4e4805f2a51873","best_bid":"0.86","best_ask":"0.87"},{"asset_id":"86520121088881862182423437128238697252500151785248183602134095101149900014256","price":"0.14","size":"240.14","side":"SELL","hash":"683b43e0339890cc0e71e0221e1dc3f7460ad2e8","best_bid":"0.13","best_ask":"0.14"}],"timestamp":"1776808416402","event_type":"price_change"}}
{"capturedAt":1776808416,"payload":{"market":"0x125149c5918fc5f8c6d34682f700a898a1a19ea4f4e2ae68ff4c5794ba657074","price_changes":[{"asset_id":"45936375922793925919605092352922707796689801895417366600539442410775071099958","price":"0.86","size":"278.14","side":"BUY","hash":"12ebd298d2c1427b011fe81e68f95d6c09bc85d0","best_bid":"0.86","best_ask":"0.87"},{"asset_id":"86520121088881862182423437128238697252500151785248183602134095101149900014256","price":"0.14","size":"278.14","side":"SELL","hash":"be02f0587c9630ec6199cd6da9acdf1cfccb3562","best_bid":"0.13","best_ask":"0.14"}],"timestamp":"1776808416400","event_type":"price_change"}}
{"capturedAt":1776808416,"payload":{"market":"0x125149c5918fc5f8c6d34682f700a898a1a19ea4f4e2ae68ff4c5794ba657074","price_changes":[{"asset_id":"45936375922793925919605092352922707796689801895417366600539442410775071099958","price":"0.01","size":"12329.83","side":"BUY","hash":"7c91322684a1dba39e3c0b51fe94ee00279a783d","best_bid":"0.86","best_ask":"0.87"},{"asset_id":"86520121088881862182423437128238697252500151785248183602134095101149900014256","price":"0.99","size":"12329.83","side":"SELL","hash":"afe8ba21ac6eda79efe148ecf81e1229bbb00a8b","best_bid":"0.13","best_ask":"0.14"}],"timestamp":"1776808416404","event_type":"price_change"}}
{"capturedAt":1776808416,"payload":{"market":"0x125149c5918fc5f8c6d34682f700a898a1a19ea4f4e2ae68ff4c5794ba657074","price_changes":[{"asset_id":"45936375922793925919605092352922707796689801895417366600539442410775071099958","price":"0.86","size":"245.42","side":"BUY","hash":"699b0187fedfb920aac52fb168a47db1cf3aa137","best_bid":"0.86","best_ask":"0.87"},{"asset_id":"86520121088881862182423437128238697252500151785248183602134095101149900014256","price":"0.14","size":"245.42","side":"SELL","hash":"c20b00d91bb7ea3481b418c8c3a2bf8a7b977630","best_bid":"0.13","best_ask":"0.14"}],"timestamp":"1776808416405","event_type":"price_change"}}
{"capturedAt":1776808416,"payload":{"market":"0x125149c5918fc5f8c6d34682f700a898a1a19ea4f4e2ae68ff4c5794ba657074","price_changes":[{"asset_id":"45936375922793925919605092352922707796689801895417366600539442410775071099958","price":"0.01","size":"12334.83","side":"BUY","hash":"85eededed6a89b2a5a7ee8fcc25dbc1b162d01d1","best_bid":"0.86","best_ask":"0.87"},{"asset_id":"86520121088881862182423437128238697252500151785248183602134095101149900014256","price":"0.99","size":"12334.83","side":"SELL","hash":"2ef6161796923c708b39600ca8af41b6419c9baf","best_bid":"0.13","best_ask":"0.14"}],"timestamp":"1776808416407","event_type":"price_change"}}
{"capturedAt":1776808416,"payload":{"market":"0x125149c5918fc5f8c6d34682f700a898a1a19ea4f4e2ae68ff4c5794ba657074","price_changes":[{"asset_id":"45936375922793925919605092352922707796689801895417366600539442410775071099958","price":"0.86","size":"219.42","side":"BUY","hash":"01c1a63cddf46bef8a92298c74b41a4a6b7b79f4","best_bid":"0.86","best_ask":"0.87"},{"asset_id":"86520121088881862182423437128238697252500151785248183602134095101149900014256","price":"0.14","size":"219.42","side":"SELL","hash":"27a0c9698f853e27d27fa4107b36e62df89fb3d7","best_bid":"0.13","best_ask":"0.14"}],"timestamp":"1776808416408","event_type":"price_change"}}
{"capturedAt":1776808416,"payload":{"market":"0x125149c5918fc5f8c6d34682f700a898a1a19ea4f4e2ae68ff4c5794ba657074","price_changes":[{"asset_id":"45936375922793925919605092352922707796689801895417366600539442410775071099958","price":"0.86","size":"190.42","side":"BUY","hash":"3f5a6f70e638097675a1bd3d8e73a3b1e27426cb","best_bid":"0.86","best_ask":"0.87"},{"asset_id":"86520121088881862182423437128238697252500151785248183602134095101149900014256","price":"0.14","size":"190.42","side":"SELL","hash":"e445a55d2799dad02a3436d57e517d59a7e0d512","best_bid":"0.13","best_ask":"0.14"}],"timestamp":"1776808416409","event_type":"price_change"}}
{"capturedAt":1776808416,"payload":{"market":"0x125149c5918fc5f8c6d34682f700a898a1a19ea4f4e2ae68ff4c5794ba657074","price_changes":[{"asset_id":"45936375922793925919605092352922707796689801895417366600539442410775071099958","price":"0.01","size":"12339.83","side":"BUY","hash":"7e5f31d418670a2aa93ef8c344ff4f4c1940cdb0","best_bid":"0.86","best_ask":"0.87"},{"asset_id":"86520121088881862182423437128238697252500151785248183602134095101149900014256","price":"0.99","size":"12339.83","side":"SELL","hash":"35ab0c812636764af7ab296ef8a9e4e0f4d16abe","best_bid":"0.13","best_ask":"0.14"}],"timestamp":"1776808416411","event_type":"price_change"}}
{"capturedAt":1776808416,"payload":{"market":"0x125149c5918fc5f8c6d34682f700a898a1a19ea4f4e2ae68ff4c5794ba657074","price_changes":[{"asset_id":"86520121088881862182423437128238697252500151785248183602134095101149900014256","price":"0.13","size":"154.74","side":"BUY","hash":"1d4b051ae7f23cef7bf753181d812216b6b72401","best_bid":"0.13","best_ask":"0.14"},{"asset_id":"45936375922793925919605092352922707796689801895417366600539442410775071099958","price":"0.87","size":"154.74","side":"SELL","hash":"c15c6460beb81aca68cc87ec79356f1d516c4385","best_bid":"0.86","best_ask":"0.87"}],"timestamp":"1776808416412","event_type":"price_change"}}
{"capturedAt":1776808416,"payload":{"market":"0x125149c5918fc5f8c6d34682f700a898a1a19ea4f4e2ae68ff4c5794ba657074","price_changes":[{"asset_id":"45936375922793925919605092352922707796689801895417366600539442410775071099958","price":"0.86","size":"152.42","side":"BUY","hash":"18bf22e54a08433ae26dfa15065e9983b7b636a5","best_bid":"0.86","best_ask":"0.87"},{"asset_id":"86520121088881862182423437128238697252500151785248183602134095101149900014256","price":"0.14","size":"152.42","side":"SELL","hash":"2e275048f0379ce446632a68fb76aeddf75f1bf5","best_bid":"0.13","best_ask":"0.14"}],"timestamp":"1776808416415","event_type":"price_change"}}
{"capturedAt":1776808416,"payload":{"market":"0x125149c5918fc5f8c6d34682f700a898a1a19ea4f4e2ae68ff4c5794ba657074","price_changes":[{"asset_id":"45936375922793925919605092352922707796689801895417366600539442410775071099958","price":"0.86","size":"162.42","side":"BUY","hash":"b7f954479b3e1f8a6af37cdb5e0010079605a6c8","best_bid":"0.86","best_ask":"0.87"},{"asset_id":"86520121088881862182423437128238697252500151785248183602134095101149900014256","price":"0.14","size":"162.42","side":"SELL","hash":"f57b3a12c74bdf154b1735533070e3139c9fb7e9","best_bid":"0.13","best_ask":"0.14"}],"timestamp":"1776808416413","event_type":"price_change"}}
{"capturedAt":1776808416,"payload":{"market":"0x125149c5918fc5f8c6d34682f700a898a1a19ea4f4e2ae68ff4c5794ba657074","price_changes":[{"asset_id":"45936375922793925919605092352922707796689801895417366600539442410775071099958","price":"0.86","size":"179.42","side":"BUY","hash":"27da94403988fdf527596c83d02a101b285d3b7a","best_bid":"0.86","best_ask":"0.87"},{"asset_id":"86520121088881862182423437128238697252500151785248183602134095101149900014256","price":"0.14","size":"179.42","side":"SELL","hash":"e48ba477a6e5963f419c999aa0fff435cc7930cf","best_bid":"0.13","best_ask":"0.14"}],"timestamp":"1776808416416","event_type":"price_change"}}
{"capturedAt":1776808416,"payload":{"market":"0x125149c5918fc5f8c6d34682f700a898a1a19ea4f4e2ae68ff4c5794ba657074","price_changes":[{"asset_id":"45936375922793925919605092352922707796689801895417366600539442410775071099958","price":"0.86","size":"194.42","side":"BUY","hash":"22506031e5442aa83731c23e76a77b350cf31496","best_bid":"0.86","best_ask":"0.87"},{"asset_id":"86520121088881862182423437128238697252500151785248183602134095101149900014256","price":"0.14","size":"194.42","side":"SELL","hash":"051ba17a9be4644d3cd2bc3900c9055f57759b80","best_bid":"0.13","best_ask":"0.14"}],"timestamp":"1776808416417","event_type":"price_change"}}
{"capturedAt":1776808416,"payload":{"market":"0x125149c5918fc5f8c6d34682f700a898a1a19ea4f4e2ae68ff4c5794ba657074","price_changes":[{"asset_id":"45936375922793925919605092352922707796689801895417366600539442410775071099958","price":"0.86","size":"204.42","side":"BUY","hash":"76d0718c52dc866aaf7b5af95f836201ed9b00af","best_bid":"0.86","best_ask":"0.87"},{"asset_id":"86520121088881862182423437128238697252500151785248183602134095101149900014256","price":"0.14","size":"204.42","side":"SELL","hash":"a4edb41404cf5654614179f5e2f0ffdc4b882362","best_bid":"0.13","best_ask":"0.14"}],"timestamp":"1776808416419","event_type":"price_change"}}
{"capturedAt":1776808416,"payload":{"market":"0x125149c5918fc5f8c6d34682f700a898a1a19ea4f4e2ae68ff4c5794ba657074","price_changes":[{"asset_id":"45936375922793925919605092352922707796689801895417366600539442410775071099958","price":"0.01","size":"12334.83","side":"BUY","hash":"63a65cca5eae9051f4f9c3d0611def7ead9f4d2b","best_bid":"0.86","best_ask":"0.87"},{"asset_id":"86520121088881862182423437128238697252500151785248183602134095101149900014256","price":"0.99","size":"12334.83","side":"SELL","hash":"b7159459b22d841c2f8b40302959ef66a61f2c6f","best_bid":"0.13","best_ask":"0.14"}],"timestamp":"1776808416423","event_type":"price_change"}}
{"capturedAt":1776808416,"payload":{"market":"0x125149c5918fc5f8c6d34682f700a898a1a19ea4f4e2ae68ff4c5794ba657074","price_changes":[{"asset_id":"45936375922793925919605092352922707796689801895417366600539442410775071099958","price":"0.86","size":"228.42","side":"BUY","hash":"3b4a344ccc817e7339386b1c40846d9beea9099b","best_bid":"0.86","best_ask":"0.87"},{"asset_id":"86520121088881862182423437128238697252500151785248183602134095101149900014256","price":"0.14","size":"228.42","side":"SELL","hash":"15eb9fc3cdc0f6ad8a7b4feb982d1dd6204d27d0","best_bid":"0.13","best_ask":"0.14"}],"timestamp":"1776808416425","event_type":"price_change"}}
{"capturedAt":1776808416,"payload":{"market":"0x125149c5918fc5f8c6d34682f700a898a1a19ea4f4e2ae68ff4c5794ba657074","price_changes":[{"asset_id":"45936375922793925919605092352922707796689801895417366600539442410775071099958","price":"0.86","size":"241.42","side":"BUY","hash":"92aa1950edf1209179e6d028e97245cba4297887","best_bid":"0.86","best_ask":"0.87"},{"asset_id":"86520121088881862182423437128238697252500151785248183602134095101149900014256","price":"0.14","size":"241.42","side":"SELL","hash":"947b0f5b94f12d035a8e192a484d5fbed23e651c","best_bid":"0.13","best_ask":"0.14"}],"timestamp":"1776808416426","event_type":"price_change"}}
{"capturedAt":1776808416,"payload":{"market":"0x125149c5918fc5f8c6d34682f700a898a1a19ea4f4e2ae68ff4c5794ba657074","price_changes":[{"asset_id":"45936375922793925919605092352922707796689801895417366600539442410775071099958","price":"0.86","size":"265.42","side":"BUY","hash":"b0a03f3e289ad21e51d1198b54f89f4466b8f40d","best_bid":"0.86","best_ask":"0.87"},{"asset_id":"86520121088881862182423437128238697252500151785248183602134095101149900014256","price":"0.14","size":"265.42","side":"SELL","hash":"d21a93ba37e3a7f65002a0e0831c8a347626e390","best_bid":"0.13","best_ask":"0.14"}],"timestamp":"1776808416428","event_type":"price_change"}}
{"capturedAt":1776808416,"payload":{"market":"0x125149c5918fc5f8c6d34682f700a898a1a19ea4f4e2ae68ff4c5794ba657074","price_changes":[{"asset_id":"45936375922793925919605092352922707796689801895417366600539442410775071099958","price":"0.01","size":"12329.83","side":"BUY","hash":"714a4a2b1cccec5ee25acb6e52dee40442ad4442","best_bid":"0.86","best_ask":"0.87"},{"asset_id":"86520121088881862182423437128238697252500151785248183602134095101149900014256","price":"0.99","size":"12329.83","side":"SELL","hash":"9d20a5f39c75391c3a41664f42d9390f9fe4ce4c","best_bid":"0.13","best_ask":"0.14"}],"timestamp":"1776808416429","event_type":"price_change"}}
{"capturedAt":1776808416,"payload":{"market":"0x125149c5918fc5f8c6d34682f700a898a1a19ea4f4e2ae68ff4c5794ba657074","price_changes":[{"asset_id":"45936375922793925919605092352922707796689801895417366600539442410775071099958","price":"0.86","size":"260.14","side":"BUY","hash":"5209689980225b16826cdce1b1bbd7706d55f332","best_bid":"0.86","best_ask":"0.87"},{"asset_id":"86520121088881862182423437128238697252500151785248183602134095101149900014256","price":"0.14","size":"260.14","side":"SELL","hash":"9aabdf23de08c6365774e150ae34b260fb68f743","best_bid":"0.13","best_ask":"0.14"}],"timestamp":"1776808416430","event_type":"price_change"}}
{"capturedAt":1776808416,"payload":{"market":"0x125149c5918fc5f8c6d34682f700a898a1a19ea4f4e2ae68ff4c5794ba657074","price_changes":[{"asset_id":"45936375922793925919605092352922707796689801895417366600539442410775071099958","price":"0.86","size":"284.14","side":"BUY","hash":"89bd5fc19d9d39a927b353c9681bb013530b576e","best_bid":"0.86","best_ask":"0.87"},{"asset_id":"86520121088881862182423437128238697252500151785248183602134095101149900014256","price":"0.14","size":"284.14","side":"SELL","hash":"0e90c15219800ef0eb91b9a711714d9693985a4d","best_bid":"0.13","best_ask":"0.14"}],"timestamp":"1776808416431","event_type":"price_change"}}
{"capturedAt":1776808416,"payload":{"market":"0x125149c5918fc5f8c6d34682f700a898a1a19ea4f4e2ae68ff4c5794ba657074","price_changes":[{"asset_id":"45936375922793925919605092352922707796689801895417366600539442410775071099958","price":"0.86","size":"307.14","side":"BUY","hash":"8694e1c01bbda010840de5624186d235113432c5","best_bid":"0.86","best_ask":"0.87"},{"asset_id":"86520121088881862182423437128238697252500151785248183602134095101149900014256","price":"0.14","size":"307.14","side":"SELL","hash":"8cfdbe8dad3c815392069a670a0e269bcf116b0b","best_bid":"0.13","best_ask":"0.14"}],"timestamp":"1776808416433","event_type":"price_change"}}
{"capturedAt":1776808416,"payload":{"market":"0x125149c5918fc5f8c6d34682f700a898a1a19ea4f4e2ae68ff4c5794ba657074","price_changes":[{"asset_id":"45936375922793925919605092352922707796689801895417366600539442410775071099958","price":"0.01","size":"12324.83","side":"BUY","hash":"af571fcf2c32ada47f59cc69e0d2e53b835204a8","best_bid":"0.86","best_ask":"0.87"},{"asset_id":"86520121088881862182423437128238697252500151785248183602134095101149900014256","price":"0.99","size":"12324.83","side":"SELL","hash":"62ff5af3db239e523550e04524c27cc4833c6c4c","best_bid":"0.13","best_ask":"0.14"}],"timestamp":"1776808416434","event_type":"price_change"}}
{"capturedAt":1776808416,"payload":{"market":"0x125149c5918fc5f8c6d34682f700a898a1a19ea4f4e2ae68ff4c5794ba657074","price_changes":[{"asset_id":"45936375922793925919605092352922707796689801895417366600539442410775071099958","price":"0.86","size":"326.14","side":"BUY","hash":"8dea4e29dde445167d16b655cea55eefc43a814d","best_bid":"0.86","best_ask":"0.87"},{"asset_id":"86520121088881862182423437128238697252500151785248183602134095101149900014256","price":"0.14","size":"326.14","side":"SELL","hash":"868afc6094a1b360f5bc62313dcaf8bd3633b218","best_bid":"0.13","best_ask":"0.14"}],"timestamp":"1776808416436","event_type":"price_change"}}
{"capturedAt":1776808416,"payload":{"market":"0x125149c5918fc5f8c6d34682f700a898a1a19ea4f4e2ae68ff4c5794ba657074","price_changes":[{"asset_id":"45936375922793925919605092352922707796689801895417366600539442410775071099958","price":"0.86","size":"348.14","side":"BUY","hash":"d6a12ba7f2492afdfbd8dc5c7077f4a885a5f3fc","best_bid":"0.86","best_ask":"0.87"},{"asset_id":"86520121088881862182423437128238697252500151785248183602134095101149900014256","price":"0.14","size":"348.14","side":"SELL","hash":"dcf491b2dec061618c196f11337d4c57dd593fe5","best_bid":"0.13","best_ask":"0.14"}],"timestamp":"1776808416437","event_type":"price_change"}}
{"capturedAt":1776808416,"payload":{"market":"0x125149c5918fc5f8c6d34682f700a898a1a19ea4f4e2ae68ff4c5794ba657074","price_changes":[{"asset_id":"45936375922793925919605092352922707796689801895417366600539442410775071099958","price":"0.86","size":"370.14","side":"BUY","hash":"82ad88f8d32848d2ad257f4a053e8776e00a10f3","best_bid":"0.86","best_ask":"0.87"},{"asset_id":"86520121088881862182423437128238697252500151785248183602134095101149900014256","price":"0.14","size":"370.14","side":"SELL","hash":"3ce0114e3114ad3b525d6267f422e3ffb68601f6","best_bid":"0.13","best_ask":"0.14"}],"timestamp":"1776808416439","event_type":"price_change"}}
{"capturedAt":1776808416,"payload":{"market":"0x125149c5918fc5f8c6d34682f700a898a1a19ea4f4e2ae68ff4c5794ba657074","price_changes":[{"asset_id":"45936375922793925919605092352922707796689801895417366600539442410775071099958","price":"0.86","size":"364.84","side":"BUY","hash":"e1ee8d293dfbff3b9fc164026b97fde14973e4ff","best_bid":"0.86","best_ask":"0.87"},{"asset_id":"86520121088881862182423437128238697252500151785248183602134095101149900014256","price":"0.14","size":"364.84","side":"SELL","hash":"42db673a1e7f806701bab1c5e0ff1d73bfb4a268","best_bid":"0.13","best_ask":"0.14"}],"timestamp":"1776808416440","event_type":"price_change"}}
{"capturedAt":1776808416,"payload":{"market":"0x125149c5918fc5f8c6d34682f700a898a1a19ea4f4e2ae68ff4c5794ba657074","price_changes":[{"asset_id":"45936375922793925919605092352922707796689801895417366600539442410775071099958","price":"0.86","size":"374.84","side":"BUY","hash":"ad3ba00228fe9bef995a62a5edee9c60a0164f74","best_bid":"0.86","best_ask":"0.87"},{"asset_id":"86520121088881862182423437128238697252500151785248183602134095101149900014256","price":"0.14","size":"374.84","side":"SELL","hash":"4e798f4b784658be6fe350806978a1586a0bd7de","best_bid":"0.13","best_ask":"0.14"}],"timestamp":"1776808416442","event_type":"price_change"}}
{"capturedAt":1776808416,"payload":{"market":"0x125149c5918fc5f8c6d34682f700a898a1a19ea4f4e2ae68ff4c5794ba657074","price_changes":[{"asset_id":"45936375922793925919605092352922707796689801895417366600539442410775071099958","price":"0.86","size":"379.89","side":"BUY","hash":"f2797c26072cbbcdb5eb4d7b78b94b701be07d75","best_bid":"0.86","best_ask":"0.87"},{"asset_id":"86520121088881862182423437128238697252500151785248183602134095101149900014256","price":"0.14","size":"379.89","side":"SELL","hash":"3fa8be64f7451ccec8280ece3d9b259bf70a3109","best_bid":"0.13","best_ask":"0.14"}],"timestamp":"1776808416444","event_type":"price_change"}}
{"capturedAt":1776808416,"payload":{"market":"0x125149c5918fc5f8c6d34682f700a898a1a19ea4f4e2ae68ff4c5794ba657074","price_changes":[{"asset_id":"45936375922793925919605092352922707796689801895417366600539442410775071099958","price":"0.86","size":"369.89","side":"BUY","hash":"af6259bb625c77ee064d3e12ea225ffe30210775","best_bid":"0.86","best_ask":"0.87"},{"asset_id":"86520121088881862182423437128238697252500151785248183602134095101149900014256","price":"0.14","size":"369.89","side":"SELL","hash":"d0bd3a0683e22edfc48d91be1dd78856aec07972","best_bid":"0.13","best_ask":"0.14"}],"timestamp":"1776808416446","event_type":"price_change"}}
{"capturedAt":1776808416,"payload":{"market":"0x125149c5918fc5f8c6d34682f700a898a1a19ea4f4e2ae68ff4c5794ba657074","price_changes":[{"asset_id":"45936375922793925919605092352922707796689801895417366600539442410775071099958","price":"0.86","size":"389.89","side":"BUY","hash":"e7bd62e106e66d55a66bb65b2191ca5995d52d8a","best_bid":"0.86","best_ask":"0.87"},{"asset_id":"86520121088881862182423437128238697252500151785248183602134095101149900014256","price":"0.14","size":"389.89","side":"SELL","hash":"95b83b4929b47ba1af4aa0a67d805dbc2c903dc0","best_bid":"0.13","best_ask":"0.14"}],"timestamp":"1776808416447","event_type":"price_change"}}
{"capturedAt":1776808416,"payload":{"market":"0x125149c5918fc5f8c6d34682f700a898a1a19ea4f4e2ae68ff4c5794ba657074","price_changes":[{"asset_id":"86520121088881862182423437128238697252500151785248183602134095101149900014256","price":"0.13","size":"149.74","side":"BUY","hash":"c47fc4370659e826f3660c87d86efe5f5df79116","best_bid":"0.13","best_ask":"0.14"},{"asset_id":"45936375922793925919605092352922707796689801895417366600539442410775071099958","price":"0.87","size":"149.74","side":"SELL","hash":"74f6e67383bb22dcbed1c3b195cdbb2605a95ade","best_bid":"0.86","best_ask":"0.87"}],"timestamp":"1776808416456","event_type":"price_change"}}
{"capturedAt":1776808416,"payload":{"market":"0x125149c5918fc5f8c6d34682f700a898a1a19ea4f4e2ae68ff4c5794ba657074","price_changes":[{"asset_id":"86520121088881862182423437128238697252500151785248183602134095101149900014256","price":"0.09","size":"202","side":"BUY","hash":"aeb244986364f1da45e5e7cb1dbb4b9147f6f426","best_bid":"0.13","best_ask":"0.14"},{"asset_id":"45936375922793925919605092352922707796689801895417366600539442410775071099958","price":"0.91","size":"202","side":"SELL","hash":"dd5029fc8e986dac61cd1facbab4a040d8cb8209","best_bid":"0.86","best_ask":"0.87"}],"timestamp":"1776808416464","event_type":"price_change"}}
{"capturedAt":1776808416,"payload":{"market":"0x125149c5918fc5f8c6d34682f700a898a1a19ea4f4e2ae68ff4c5794ba657074","price_changes":[{"asset_id":"45936375922793925919605092352922707796689801895417366600539442410775071099958","price":"0.86","size":"400.75","side":"BUY","hash":"a60ac45b26fcbdff817d7dca0d6e22d890a35bc9","best_bid":"0.86","best_ask":"0.87"},{"asset_id":"86520121088881862182423437128238697252500151785248183602134095101149900014256","price":"0.14","size":"400.75","side":"SELL","hash":"b2bf99c32d26fd2981dfd000644463e8ebd55b0b","best_bid":"0.13","best_ask":"0.14"}],"timestamp":"1776808416468","event_type":"price_change"}}
{"capturedAt":1776808416,"payload":{"market":"0x125149c5918fc5f8c6d34682f700a898a1a19ea4f4e2ae68ff4c5794ba657074","price_changes":[{"asset_id":"45936375922793925919605092352922707796689801895417366600539442410775071099958","price":"0.01","size":"12329.83","side":"BUY","hash":"ea9359b74c60b742f961f38daabf797ba44b5dee","best_bid":"0.86","best_ask":"0.87"},{"asset_id":"86520121088881862182423437128238697252500151785248183602134095101149900014256","price":"0.99","size":"12329.83","side":"SELL","hash":"0ae8d11215773bbb17981faf89c8ff90690cdd81","best_bid":"0.13","best_ask":"0.14"}],"timestamp":"1776808416465","event_type":"price_change"}}
{"capturedAt":1776808416,"payload":{"market":"0x125149c5918fc5f8c6d34682f700a898a1a19ea4f4e2ae68ff4c5794ba657074","price_changes":[{"asset_id":"45936375922793925919605092352922707796689801895417366600539442410775071099958","price":"0.01","size":"12329.83","side":"BUY","hash":"35f44cb6c4d392105d52b0fd11ec32da2616c9f3","best_bid":"0.86","best_ask":"0.87"},{"asset_id":"86520121088881862182423437128238697252500151785248183602134095101149900014256","price":"0.99","size":"12329.83","side":"SELL","hash":"9b44fb79d4682221589c22662e490529f72c0274","best_bid":"0.13","best_ask":"0.14"}],"timestamp":"1776808416483","event_type":"price_change"}}
{"capturedAt":1776808416,"payload":{"market":"0x125149c5918fc5f8c6d34682f700a898a1a19ea4f4e2ae68ff4c5794ba657074","price_changes":[{"asset_id":"45936375922793925919605092352922707796689801895417366600539442410775071099958","price":"0.86","size":"410.75","side":"BUY","hash":"46257b45d8dc785667287f6d471cc2b684107647","best_bid":"0.86","best_ask":"0.87"},{"asset_id":"86520121088881862182423437128238697252500151785248183602134095101149900014256","price":"0.14","size":"410.75","side":"SELL","hash":"0bcc34301e0b8418d84346daf05b789c3ce93d57","best_bid":"0.13","best_ask":"0.14"}],"timestamp":"1776808416475","event_type":"price_change"}}
{"capturedAt":1776808416,"payload":{"market":"0x125149c5918fc5f8c6d34682f700a898a1a19ea4f4e2ae68ff4c5794ba657074","price_changes":[{"asset_id":"45936375922793925919605092352922707796689801895417366600539442410775071099958","price":"0.01","size":"12334.83","side":"BUY","hash":"4867aefb8a5653fb10cbf9550836af5433524cdb","best_bid":"0.86","best_ask":"0.87"},{"asset_id":"86520121088881862182423437128238697252500151785248183602134095101149900014256","price":"0.99","size":"12334.83","side":"SELL","hash":"d916d95f71cd8fd61ca0b86d0f8dc99c70a8f452","best_bid":"0.13","best_ask":"0.14"}],"timestamp":"1776808416477","event_type":"price_change"}}
{"capturedAt":1776808416,"payload":{"market":"0x125149c5918fc5f8c6d34682f700a898a1a19ea4f4e2ae68ff4c5794ba657074","price_changes":[{"asset_id":"45936375922793925919605092352922707796689801895417366600539442410775071099958","price":"0.86","size":"383.75","side":"BUY","hash":"af34053948e6c050806b00568ab694dd6edb31fb","best_bid":"0.86","best_ask":"0.87"},{"asset_id":"86520121088881862182423437128238697252500151785248183602134095101149900014256","price":"0.14","size":"383.75","side":"SELL","hash":"9450579eb983a12ffd81001976cd15c0e1664210","best_bid":"0.13","best_ask":"0.14"}],"timestamp":"1776808416486","event_type":"price_change"}}
{"capturedAt":1776808416,"payload":{"market":"0x125149c5918fc5f8c6d34682f700a898a1a19ea4f4e2ae68ff4c5794ba657074","price_changes":[{"asset_id":"45936375922793925919605092352922707796689801895417366600539442410775071099958","price":"0.86","size":"368.75","side":"BUY","hash":"7081fff066d815dd4a4e2729c969bf8485fb1595","best_bid":"0.86","best_ask":"0.87"},{"asset_id":"86520121088881862182423437128238697252500151785248183602134095101149900014256","price":"0.14","size":"368.75","side":"SELL","hash":"62ee8e93ffadc0691d88266916a7b591c37c5b4b","best_bid":"0.13","best_ask":"0.14"}],"timestamp":"1776808416487","event_type":"price_change"}}
{"capturedAt":1776808416,"payload":{"market":"0x125149c5918fc5f8c6d34682f700a898a1a19ea4f4e2ae68ff4c5794ba657074","price_changes":[{"asset_id":"45936375922793925919605092352922707796689801895417366600539442410775071099958","price":"0.01","size":"12324.83","side":"BUY","hash":"209b5a82d8b8be7e23fc831882769eac3ee779f5","best_bid":"0.86","best_ask":"0.87"},{"asset_id":"86520121088881862182423437128238697252500151785248183602134095101149900014256","price":"0.99","size":"12324.83","side":"SELL","hash":"3ba931c37dcca3437a9d661c7370064ecee9d5c9","best_bid":"0.13","best_ask":"0.14"}],"timestamp":"1776808416499","event_type":"price_change"}}
{"capturedAt":1776808416,"payload":{"market":"0x125149c5918fc5f8c6d34682f700a898a1a19ea4f4e2ae68ff4c5794ba657074","price_changes":[{"asset_id":"45936375922793925919605092352922707796689801895417366600539442410775071099958","price":"0.86","size":"316.03","side":"BUY","hash":"4ed36b9c015537ef19a7b8cb1cde1ca3dea6e059","best_bid":"0.86","best_ask":"0.87"},{"asset_id":"86520121088881862182423437128238697252500151785248183602134095101149900014256","price":"0.14","size":"316.03","side":"SELL","hash":"58ac2b79393c99acb25fe69c098ebecf52c3e07f","best_bid":"0.13","best_ask":"0.14"}],"timestamp":"1776808416498","event_type":"price_change"}}
{"capturedAt":1776808416,"payload":{"market":"0x125149c5918fc5f8c6d34682f700a898a1a19ea4f4e2ae68ff4c5794ba657074","price_changes":[{"asset_id":"45936375922793925919605092352922707796689801895417366600539442410775071099958","price":"0.86","size":"358.75","side":"BUY","hash":"332ad9ec075af93641ec04617461a9fd8ddb0cae","best_bid":"0.86","best_ask":"0.87"},{"asset_id":"86520121088881862182423437128238697252500151785248183602134095101149900014256","price":"0.14","size":"358.75","side":"SELL","hash":"b0bc84d098ec93ef31b379878505e5d85d24ccb1","best_bid":"0.13","best_ask":"0.14"}],"timestamp":"1776808416491","event_type":"price_change"}}
{"capturedAt":1776808416,"payload":{"market":"0x125149c5918fc5f8c6d34682f700a898a1a19ea4f4e2ae68ff4c5794ba657074","price_changes":[{"asset_id":"45936375922793925919605092352922707796689801895417366600539442410775071099958","price":"0.86","size":"340.03","side":"BUY","hash":"fc5c4eba7c0182e5fc1444cdb307e1e42f448f7b","best_bid":"0.86","best_ask":"0.87"},{"asset_id":"86520121088881862182423437128238697252500151785248183602134095101149900014256","price":"0.14","size":"340.03","side":"SELL","hash":"0423a129abbbcae1ae81b88eb00cab25a6f8f993","best_bid":"0.13","best_ask":"0.14"}],"timestamp":"1776808416497","event_type":"price_change"}}
{"capturedAt":1776808416,"payload":{"market":"0x125149c5918fc5f8c6d34682f700a898a1a19ea4f4e2ae68ff4c5794ba657074","price_changes":[{"asset_id":"45936375922793925919605092352922707796689801895417366600539442410775071099958","price":"0.86","size":"364.03","side":"BUY","hash":"be91c00b80c04c40199e14ab4c69b53fdf15c3dd","best_bid":"0.86","best_ask":"0.87"},{"asset_id":"86520121088881862182423437128238697252500151785248183602134095101149900014256","price":"0.14","size":"364.03","side":"SELL","hash":"c638892c4c22821590dd9682d75d1a2013b15d56","best_bid":"0.13","best_ask":"0.14"}],"timestamp":"1776808416495","event_type":"price_change"}}
{"capturedAt":1776808416,"payload":{"market":"0x125149c5918fc5f8c6d34682f700a898a1a19ea4f4e2ae68ff4c5794ba657074","price_changes":[{"asset_id":"45936375922793925919605092352922707796689801895417366600539442410775071099958","price":"0.86","size":"280.03","side":"BUY","hash":"7e656d4c0cfdaa2a6574104783125f00b85dbe13","best_bid":"0.86","best_ask":"0.87"},{"asset_id":"86520121088881862182423437128238697252500151785248183602134095101149900014256","price":"0.14","size":"280.03","side":"SELL","hash":"217046ac2ccb77c7473861877b4fa6861f3a136d","best_bid":"0.13","best_ask":"0.14"}],"timestamp":"1776808416503","event_type":"price_change"}}
{"capturedAt":1776808416,"payload":{"market":"0x125149c5918fc5f8c6d34682f700a898a1a19ea4f4e2ae68ff4c5794ba657074","price_changes":[{"asset_id":"45936375922793925919605092352922707796689801895417366600539442410775071099958","price":"0.86","size":"237.03","side":"BUY","hash":"6dc3412fd987568dceb11d0ca8b085fb5e52c67c","best_bid":"0.86","best_ask":"0.87"},{"asset_id":"86520121088881862182423437128238697252500151785248183602134095101149900014256","price":"0.14","size":"237.03","side":"SELL","hash":"1602ee9b3c2a7a40f0eff965a88d2ce97469eea1","best_bid":"0.13","best_ask":"0.14"}],"timestamp":"1776808416536","event_type":"price_change"}}
{"capturedAt":1776808416,"payload":{"market":"0x125149c5918fc5f8c6d34682f700a898a1a19ea4f4e2ae68ff4c5794ba657074","price_changes":[{"asset_id":"45936375922793925919605092352922707796689801895417366600539442410775071099958","price":"0.86","size":"209.75","side":"BUY","hash":"40ed628f91e2563611c23e4d8cbb917954d84881","best_bid":"0.86","best_ask":"0.87"},{"asset_id":"86520121088881862182423437128238697252500151785248183602134095101149900014256","price":"0.14","size":"209.75","side":"SELL","hash":"b717b058ef4626f04c72303905933f71df5b7752","best_bid":"0.13","best_ask":"0.14"}],"timestamp":"1776808416539","event_type":"price_change"}}
{"capturedAt":1776808416,"payload":{"market":"0x125149c5918fc5f8c6d34682f700a898a1a19ea4f4e2ae68ff4c5794ba657074","price_changes":[{"asset_id":"45936375922793925919605092352922707796689801895417366600539442410775071099958","price":"0.86","size":"256.03","side":"BUY","hash":"601652763e3b302dcb2a4e208b5311d7089e9257","best_bid":"0.86","best_ask":"0.87"},{"asset_id":"86520121088881862182423437128238697252500151785248183602134095101149900014256","price":"0.14","size":"256.03","side":"SELL","hash":"541229ba1131b8fd04767b06197ce069453ee95d","best_bid":"0.13","best_ask":"0.14"}],"timestamp":"1776808416504","event_type":"price_change"}}
{"capturedAt":1776808416,"payload":{"market":"0x125149c5918fc5f8c6d34682f700a898a1a19ea4f4e2ae68ff4c5794ba657074","price_changes":[{"asset_id":"45936375922793925919605092352922707796689801895417366600539442410775071099958","price":"0.86","size":"215.03","side":"BUY","hash":"3dd49df454063d584c25ddbb24f05fff347204c4","best_bid":"0.86","best_ask":"0.87"},{"asset_id":"86520121088881862182423437128238697252500151785248183602134095101149900014256","price":"0.14","size":"215.03","side":"SELL","hash":"5348f645afc7e11b7997e3d0171524aa2bc06b77","best_bid":"0.13","best_ask":"0.14"}],"timestamp":"1776808416537","event_type":"price_change"}}
{"capturedAt":1776808416,"payload":{"market":"0x125149c5918fc5f8c6d34682f700a898a1a19ea4f4e2ae68ff4c5794ba657074","price_changes":[{"asset_id":"45936375922793925919605092352922707796689801895417366600539442410775071099958","price":"0.01","size":"12329.83","side":"BUY","hash":"918a376fe8fba4d7b382f740703d852ebe596e21","best_bid":"0.86","best_ask":"0.87"},{"asset_id":"86520121088881862182423437128238697252500151785248183602134095101149900014256","price":"0.99","size":"12329.83","side":"SELL","hash":"4638f2e14e642d1b2182faf5056ef5cc91361908","best_bid":"0.13","best_ask":"0.14"}],"timestamp":"1776808416543","event_type":"price_change"}}
{"capturedAt":1776808416,"payload":{"market":"0x125149c5918fc5f8c6d34682f700a898a1a19ea4f4e2ae68ff4c5794ba657074","price_changes":[{"asset_id":"45936375922793925919605092352922707796689801895417366600539442410775071099958","price":"0.86","size":"203.75","side":"BUY","hash":"b34bf93a185ddd87c46fd2fc7a9408b6d67f3532","best_bid":"0.86","best_ask":"0.87"},{"asset_id":"86520121088881862182423437128238697252500151785248183602134095101149900014256","price":"0.14","size":"203.75","side":"SELL","hash":"fa34706cfe2d22d6b1bbc77ee627978f08111875","best_bid":"0.13","best_ask":"0.14"}],"timestamp":"1776808416548","event_type":"price_change"}}
{"capturedAt":1776808416,"payload":{"market":"0x125149c5918fc5f8c6d34682f700a898a1a19ea4f4e2ae68ff4c5794ba657074","price_changes":[{"asset_id":"45936375922793925919605092352922707796689801895417366600539442410775071099958","price":"0.86","size":"181.75","side":"BUY","hash":"c46fb40de9f03ebdaf9d3282bf8a853d62b515e2","best_bid":"0.86","best_ask":"0.87"},{"asset_id":"86520121088881862182423437128238697252500151785248183602134095101149900014256","price":"0.14","size":"181.75","side":"SELL","hash":"6347305ce5191f548f70341349bbfb5c537aa88e","best_bid":"0.13","best_ask":"0.14"}],"timestamp":"1776808416550","event_type":"price_change"}}
{"capturedAt":1776808416,"payload":{"market":"0x125149c5918fc5f8c6d34682f700a898a1a19ea4f4e2ae68ff4c5794ba657074","price_changes":[{"asset_id":"86520121088881862182423437128238697252500151785248183602134095101149900014256","price":"0.11","size":"391.5","side":"BUY","hash":"d8784e289eaa8cd27d83f4e5f951cb99e409b3b5","best_bid":"0.13","best_ask":"0.14"},{"asset_id":"45936375922793925919605092352922707796689801895417366600539442410775071099958","price":"0.89","size":"391.5","side":"SELL","hash":"97bc37b6af6ff742a6849855ea962e2a6b3e834d","best_bid":"0.86","best_ask":"0.87"}],"timestamp":"1776808416484","event_type":"price_change"}}
{"capturedAt":1776808416,"payload":{"market":"0x125149c5918fc5f8c6d34682f700a898a1a19ea4f4e2ae68ff4c5794ba657074","price_changes":[{"asset_id":"45936375922793925919605092352922707796689801895417366600539442410775071099958","price":"0.86","size":"293.03","side":"BUY","hash":"98e13601db158c65e34e59191b9f89686b9580c2","best_bid":"0.86","best_ask":"0.87"},{"asset_id":"86520121088881862182423437128238697252500151785248183602134095101149900014256","price":"0.14","size":"293.03","side":"SELL","hash":"f605135ae13c5d0eb22d67f7d49719f092f6b165","best_bid":"0.13","best_ask":"0.14"}],"timestamp":"1776808416502","event_type":"price_change"}}
{"capturedAt":1776808416,"payload":{"market":"0x125149c5918fc5f8c6d34682f700a898a1a19ea4f4e2ae68ff4c5794ba657074","price_changes":[{"asset_id":"45936375922793925919605092352922707796689801895417366600539442410775071099958","price":"0.86","size":"223.75","side":"BUY","hash":"8ddb6ee1f514dafc8cba1dafbd77e9148d7f2e58","best_bid":"0.86","best_ask":"0.87"},{"asset_id":"86520121088881862182423437128238697252500151785248183602134095101149900014256","price":"0.14","size":"223.75","side":"SELL","hash":"8541288bc11f33b544eb59a776d6a47ebc142cbb","best_bid":"0.13","best_ask":"0.14"}],"timestamp":"1776808416544","event_type":"price_change"}}
{"capturedAt":1776808416,"payload":{"market":"0x125149c5918fc5f8c6d34682f700a898a1a19ea4f4e2ae68ff4c5794ba657074","price_changes":[{"asset_id":"45936375922793925919605092352922707796689801895417366600539442410775071099958","price":"0.86","size":"201.75","side":"BUY","hash":"f0c5c793dfbece71787e10adfe1595607de706c2","best_bid":"0.86","best_ask":"0.87"},{"asset_id":"86520121088881862182423437128238697252500151785248183602134095101149900014256","price":"0.14","size":"201.75","side":"SELL","hash":"2f326c33ddccb34f9f706c80ab8a01fd0ee4f4c2","best_bid":"0.13","best_ask":"0.14"}],"timestamp":"1776808416551","event_type":"price_change"}}
{"capturedAt":1776808416,"payload":{"market":"0x125149c5918fc5f8c6d34682f700a898a1a19ea4f4e2ae68ff4c5794ba657074","price_changes":[{"asset_id":"45936375922793925919605092352922707796689801895417366600539442410775071099958","price":"0.86","size":"395.5","side":"BUY","hash":"fa56bfa97752283ff8e070b9554d988876561615","best_bid":"0.86","best_ask":"0.87"},{"asset_id":"86520121088881862182423437128238697252500151785248183602134095101149900014256","price":"0.14","size":"395.5","side":"SELL","hash":"ac02cb93847317d9083cd79b3f1b456046c4bae2","best_bid":"0.13","best_ask":"0.14"}],"timestamp":"1776808416462","event_type":"price_change"}}
{"capturedAt":1776808416,"payload":{"market":"0x125149c5918fc5f8c6d34682f700a898a1a19ea4f4e2ae68ff4c5794ba657074","price_changes":[{"asset_id":"45936375922793925919605092352922707796689801895417366600539442410775071099958","price":"0.86","size":"221.75","side":"BUY","hash":"18e7539068badb36f0dca850f105448d755d5015","best_bid":"0.86","best_ask":"0.87"},{"asset_id":"86520121088881862182423437128238697252500151785248183602134095101149900014256","price":"0.14","size":"221.75","side":"SELL","hash":"e1874b329bbbb5edb0e7e83101a7877571795153","best_bid":"0.13","best_ask":"0.14"}],"timestamp":"1776808416553","event_type":"price_change"}}
{"capturedAt":1776808416,"payload":{"market":"0x125149c5918fc5f8c6d34682f700a898a1a19ea4f4e2ae68ff4c5794ba657074","price_changes":[{"asset_id":"45936375922793925919605092352922707796689801895417366600539442410775071099958","price":"0.86","size":"199.75","side":"BUY","hash":"5b4c50d73f9fc240a3d41bf342853bccf5c1447a","best_bid":"0.86","best_ask":"0.87"},{"asset_id":"86520121088881862182423437128238697252500151785248183602134095101149900014256","price":"0.14","size":"199.75","side":"SELL","hash":"b6656894089ff6679b66cc4d890db4c081a9e73d","best_bid":"0.13","best_ask":"0.14"}],"timestamp":"1776808416541","event_type":"price_change"}}
{"capturedAt":1776808416,"payload":{"market":"0x125149c5918fc5f8c6d34682f700a898a1a19ea4f4e2ae68ff4c5794ba657074","price_changes":[{"asset_id":"45936375922793925919605092352922707796689801895417366600539442410775071099958","price":"0.84","size":"383.63","side":"BUY","hash":"daf013895805ee11aa6bdd35f81def09a91a801f","best_bid":"0.86","best_ask":"0.87"},{"asset_id":"86520121088881862182423437128238697252500151785248183602134095101149900014256","price":"0.16","size":"383.63","side":"SELL","hash":"ddd5b72e3003a4209380302d4e35693d2c0537b2","best_bid":"0.13","best_ask":"0.14"}],"timestamp":"1776808416555","event_type":"price_change"}}
{"capturedAt":1776808416,"payload":{"market":"0x125149c5918fc5f8c6d34682f700a898a1a19ea4f4e2ae68ff4c5794ba657074","price_changes":[{"asset_id":"45936375922793925919605092352922707796689801895417366600539442410775071099958","price":"0.86","size":"234.5","side":"BUY","hash":"4388de3ceebd55d696f89625e7e625e306304370","best_bid":"0.86","best_ask":"0.87"},{"asset_id":"86520121088881862182423437128238697252500151785248183602134095101149900014256","price":"0.14","size":"234.5","side":"SELL","hash":"ea65e0e07e810adf52806cbca37810c2f5082ac9","best_bid":"0.13","best_ask":"0.14"}],"timestamp":"1776808416557","event_type":"price_change"}}
{"capturedAt":1776808416,"payload":{"market":"0x125149c5918fc5f8c6d34682f700a898a1a19ea4f4e2ae68ff4c5794ba657074","price_changes":[{"asset_id":"45936375922793925919605092352922707796689801895417366600539442410775071099958","price":"0.86","size":"224.5","side":"BUY","hash":"47181c8e0bdd326254eddeab04102403f31aa956","best_bid":"0.86","best_ask":"0.87"},{"asset_id":"86520121088881862182423437128238697252500151785248183602134095101149900014256","price":"0.14","size":"224.5","side":"SELL","hash":"e450a5cd36d9ecd721b8eff0f9e79932fe70387f","best_bid":"0.13","best_ask":"0.14"}],"timestamp":"1776808416559","event_type":"price_change"}}
{"capturedAt":1776808416,"payload":{"market":"0x125149c5918fc5f8c6d34682f700a898a1a19ea4f4e2ae68ff4c5794ba657074","price_changes":[{"asset_id":"45936375922793925919605092352922707796689801895417366600539442410775071099958","price":"0.86","size":"239.75","side":"BUY","hash":"ba39a21d5a9d5cbe61b9395f064bb03f3b1b0d19","best_bid":"0.86","best_ask":"0.87"},{"asset_id":"86520121088881862182423437128238697252500151785248183602134095101149900014256","price":"0.14","size":"239.75","side":"SELL","hash":"2785908db560364a38bb2b3e66d74e3263e92eab","best_bid":"0.13","best_ask":"0.14"}],"timestamp":"1776808416556","event_type":"price_change"}}
{"capturedAt":1776808416,"payload":{"market":"0x125149c5918fc5f8c6d34682f700a898a1a19ea4f4e2ae68ff4c5794ba657074","price_changes":[{"asset_id":"45936375922793925919605092352922707796689801895417366600539442410775071099958","price":"0.86","size":"234.5","side":"BUY","hash":"3fdd9abdd5573c8280db136ce197b36fc65dfdfa","best_bid":"0.86","best_ask":"0.87"},{"asset_id":"86520121088881862182423437128238697252500151785248183602134095101149900014256","price":"0.14","size":"234.5","side":"SELL","hash":"12e0500b41c59bb99b9cbd8466bbe7eb11c49dc5","best_bid":"0.13","best_ask":"0.14"}],"timestamp":"1776808416560","event_type":"price_change"}}
{"capturedAt":1776808416,"payload":{"market":"0x125149c5918fc5f8c6d34682f700a898a1a19ea4f4e2ae68ff4c5794ba657074","price_changes":[{"asset_id":"45936375922793925919605092352922707796689801895417366600539442410775071099958","price":"0.86","size":"246.5","side":"BUY","hash":"cb1ecf3342187ba25dbccb55b4e29de671a77d71","best_bid":"0.86","best_ask":"0.87"},{"asset_id":"86520121088881862182423437128238697252500151785248183602134095101149900014256","price":"0.14","size":"246.5","side":"SELL","hash":"e53d67f9dbb22ba3e066cd20bb78396252719147","best_bid":"0.13","best_ask":"0.14"}],"timestamp":"1776808416562","event_type":"price_change"}}
{"capturedAt":1776808416,"payload":{"market":"0x125149c5918fc5f8c6d34682f700a898a1a19ea4f4e2ae68ff4c5794ba657074","price_changes":[{"asset_id":"45936375922793925919605092352922707796689801895417366600539442410775071099958","price":"0.01","size":"12334.83","side":"BUY","hash":"17aadc55a15d3b378be186a68c3c05a2032586a9","best_bid":"0.86","best_ask":"0.87"},{"asset_id":"86520121088881862182423437128238697252500151785248183602134095101149900014256","price":"0.99","size":"12334.83","side":"SELL","hash":"c7a01118b66bbeb265e2bcd18cf18acd24053909","best_bid":"0.13","best_ask":"0.14"}],"timestamp":"1776808416563","event_type":"price_change"}}
{"capturedAt":1776808416,"payload":{"market":"0x125149c5918fc5f8c6d34682f700a898a1a19ea4f4e2ae68ff4c5794ba657074","price_changes":[{"asset_id":"45936375922793925919605092352922707796689801895417366600539442410775071099958","price":"0.86","size":"264.5","side":"BUY","hash":"b7a190071f84a10ef123fd0a90691b9a66666631","best_bid":"0.86","best_ask":"0.87"},{"asset_id":"86520121088881862182423437128238697252500151785248183602134095101149900014256","price":"0.14","size":"264.5","side":"SELL","hash":"b76845d168ccb0b4d35b3f250ac9c2c49dc7f2b6","best_bid":"0.13","best_ask":"0.14"}],"timestamp":"1776808416565","event_type":"price_change"}}
{"capturedAt":1776808416,"payload":{"market":"0x125149c5918fc5f8c6d34682f700a898a1a19ea4f4e2ae68ff4c5794ba657074","price_changes":[{"asset_id":"45936375922793925919605092352922707796689801895417366600539442410775071099958","price":"0.86","size":"284.5","side":"BUY","hash":"72a0488a7fb19e62cca6bc69755737283b8dfc95","best_bid":"0.86","best_ask":"0.87"},{"asset_id":"86520121088881862182423437128238697252500151785248183602134095101149900014256","price":"0.14","size":"284.5","side":"SELL","hash":"dea4deddbbbfef3b589d1fb91aea80bc8110ac58","best_bid":"0.13","best_ask":"0.14"}],"timestamp":"1776808416566","event_type":"price_change"}}
{"capturedAt":1776808416,"payload":{"market":"0x125149c5918fc5f8c6d34682f700a898a1a19ea4f4e2ae68ff4c5794ba657074","price_changes":[{"asset_id":"45936375922793925919605092352922707796689801895417366600539442410775071099958","price":"0.01","size":"12329.83","side":"BUY","hash":"0516bc34c928bf5c9f61afe04f62cf5e7f962a05","best_bid":"0.86","best_ask":"0.87"},{"asset_id":"86520121088881862182423437128238697252500151785248183602134095101149900014256","price":"0.99","size":"12329.83","side":"SELL","hash":"21f2b418021f68f2e3fe40e555556379e2859879","best_bid":"0.13","best_ask":"0.14"}],"timestamp":"1776808416569","event_type":"price_change"}}
{"capturedAt":1776808416,"payload":{"market":"0x125149c5918fc5f8c6d34682f700a898a1a19ea4f4e2ae68ff4c5794ba657074","price_changes":[{"asset_id":"45936375922793925919605092352922707796689801895417366600539442410775071099958","price":"0.86","size":"315.5","side":"BUY","hash":"815fae1a22908e60047b9c5c8a660b3b99a50bcd","best_bid":"0.86","best_ask":"0.87"},{"asset_id":"86520121088881862182423437128238697252500151785248183602134095101149900014256","price":"0.14","size":"315.5","side":"SELL","hash":"154cfe3c92120eb325e7012b757d5daf5a3f7ee6","best_bid":"0.13","best_ask":"0.14"}],"timestamp":"1776808416570","event_type":"price_change"}}
{"capturedAt":1776808416,"payload":{"market":"0x125149c5918fc5f8c6d34682f700a898a1a19ea4f4e2ae68ff4c5794ba657074","price_changes":[{"asset_id":"45936375922793925919605092352922707796689801895417366600539442410775071099958","price":"0.86","size":"303.5","side":"BUY","hash":"6bc9ed24b85503ee0b8cdeb697d1f9350123fbe2","best_bid":"0.86","best_ask":"0.87"},{"asset_id":"86520121088881862182423437128238697252500151785248183602134095101149900014256","price":"0.14","size":"303.5","side":"SELL","hash":"c323b49753751fe213206483b0b881e575e139f4","best_bid":"0.13","best_ask":"0.14"}],"timestamp":"1776808416567","event_type":"price_change"}}
{"capturedAt":1776808416,"payload":{"market":"0x125149c5918fc5f8c6d34682f700a898a1a19ea4f4e2ae68ff4c5794ba657074","price_changes":[{"asset_id":"45936375922793925919605092352922707796689801895417366600539442410775071099958","price":"0.86","size":"310.45","side":"BUY","hash":"a67defd889ed466a4aebf165e5cfa5cbec348701","best_bid":"0.86","best_ask":"0.87"},{"asset_id":"86520121088881862182423437128238697252500151785248183602134095101149900014256","price":"0.14","size":"310.45","side":"SELL","hash":"7b9dc4a86fa9c8f8e754ce998a5969b7f863a58e","best_bid":"0.13","best_ask":"0.14"}],"timestamp":"1776808416571","event_type":"price_change"}}
{"capturedAt":1776808416,"payload":{"market":"0x125149c5918fc5f8c6d34682f700a898a1a19ea4f4e2ae68ff4c5794ba657074","price_changes":[{"asset_id":"45936375922793925919605092352922707796689801895417366600539442410775071099958","price":"0.86","size":"328.45","side":"BUY","hash":"75e36c52b48670fdda5c7fe9d1503c15275139ab","best_bid":"0.86","best_ask":"0.87"},{"asset_id":"86520121088881862182423437128238697252500151785248183602134095101149900014256","price":"0.14","size":"328.45","side":"SELL","hash":"939c7a0e956993ce4c7e6c3d05a713dcff851202","best_bid":"0.13","best_ask":"0.14"}],"timestamp":"1776808416573","event_type":"price_change"}}
{"capturedAt":1776808416,"payload":{"market":"0x125149c5918fc5f8c6d34682f700a898a1a19ea4f4e2ae68ff4c5794ba657074","price_changes":[{"asset_id":"45936375922793925919605092352922707796689801895417366600539442410775071099958","price":"0.86","size":"346.45","side":"BUY","hash":"fcf18d648869f0b3a4b96df701d8cbd6cfad406a","best_bid":"0.86","best_ask":"0.87"},{"asset_id":"86520121088881862182423437128238697252500151785248183602134095101149900014256","price":"0.14","size":"346.45","side":"SELL","hash":"5e37010ea328ca742a40a4887b26905b8c2a6908","best_bid":"0.13","best_ask":"0.14"}],"timestamp":"1776808416575","event_type":"price_change"}}
{"capturedAt":1776808416,"payload":{"market":"0x125149c5918fc5f8c6d34682f700a898a1a19ea4f4e2ae68ff4c5794ba657074","price_changes":[{"asset_id":"45936375922793925919605092352922707796689801895417366600539442410775071099958","price":"0.86","size":"356.45","side":"BUY","hash":"4882b0a1931413b57b70d7c672a37fcf455db808","best_bid":"0.86","best_ask":"0.87"},{"asset_id":"86520121088881862182423437128238697252500151785248183602134095101149900014256","price":"0.14","size":"356.45","side":"SELL","hash":"855be8e1e5ab45d493202411d9afe296953813a3","best_bid":"0.13","best_ask":"0.14"}],"timestamp":"1776808416576","event_type":"price_change"}}
{"capturedAt":1776808416,"payload":{"market":"0x125149c5918fc5f8c6d34682f700a898a1a19ea4f4e2ae68ff4c5794ba657074","price_changes":[{"asset_id":"45936375922793925919605092352922707796689801895417366600539442410775071099958","price":"0.86","size":"361.87","side":"BUY","hash":"4154d48642d096e367486288260ded8ac25fe8de","best_bid":"0.86","best_ask":"0.87"},{"asset_id":"86520121088881862182423437128238697252500151785248183602134095101149900014256","price":"0.14","size":"361.87","side":"SELL","hash":"1ec9e6be519e8eac51e8201d1796d0e2432a31f6","best_bid":"0.13","best_ask":"0.14"}],"timestamp":"1776808416579","event_type":"price_change"}}
{"capturedAt":1776808416,"payload":{"market":"0x125149c5918fc5f8c6d34682f700a898a1a19ea4f4e2ae68ff4c5794ba657074","price_changes":[{"asset_id":"45936375922793925919605092352922707796689801895417366600539442410775071099958","price":"0.01","size":"12324.83","side":"BUY","hash":"5c2a9062fcdad68d012e918d00d35482eed61d74","best_bid":"0.86","best_ask":"0.87"},{"asset_id":"86520121088881862182423437128238697252500151785248183602134095101149900014256","price":"0.99","size":"12324.83","side":"SELL","hash":"95e1f274354768fc5fbdc749d85d0ab999c523d9","best_bid":"0.13","best_ask":"0.14"}],"timestamp":"1776808416582","event_type":"price_change"}}
{"capturedAt":1776808416,"payload":{"market":"0x125149c5918fc5f8c6d34682f700a898a1a19ea4f4e2ae68ff4c5794ba657074","price_changes":[{"asset_id":"45936375922793925919605092352922707796689801895417366600539442410775071099958","price":"0.86","size":"371.87","side":"BUY","hash":"875a23dcd9ab54cc407ae5afb266dcc28519206c","best_bid":"0.86","best_ask":"0.87"},{"asset_id":"86520121088881862182423437128238697252500151785248183602134095101149900014256","price":"0.14","size":"371.87","side":"SELL","hash":"9bbb52b44b34cad7e508fd8bc23e44755c01194b","best_bid":"0.13","best_ask":"0.14"}],"timestamp":"1776808416588","event_type":"price_change"}}
{"capturedAt":1776808416,"payload":{"market":"0x125149c5918fc5f8c6d34682f700a898a1a19ea4f4e2ae68ff4c5794ba657074","price_changes":[{"asset_id":"45936375922793925919605092352922707796689801895417366600539442410775071099958","price":"0.86","size":"377.56","side":"BUY","hash":"92580538879aa3e7acadf99cdf0589c7546dcddf","best_bid":"0.86","best_ask":"0.87"},{"asset_id":"86520121088881862182423437128238697252500151785248183602134095101149900014256","price":"0.14","size":"377.56","side":"SELL","hash":"41b61acd5c631c2cca9b660481dfac5976395635","best_bid":"0.13","best_ask":"0.14"}],"timestamp":"1776808416593","event_type":"price_change"}}
{"capturedAt":1776808416,"payload":{"market":"0x125149c5918fc5f8c6d34682f700a898a1a19ea4f4e2ae68ff4c5794ba657074","price_changes":[{"asset_id":"45936375922793925919605092352922707796689801895417366600539442410775071099958","price":"0.86","size":"382.79","side":"BUY","hash":"e720f1be1dbdabc29f98ebdf66e43bb134491dcc","best_bid":"0.86","best_ask":"0.87"},{"asset_id":"86520121088881862182423437128238697252500151785248183602134095101149900014256","price":"0.14","size":"382.79","side":"SELL","hash":"5f68b98e4fd9c192d7f844a75b068f668aa5ffac","best_bid":"0.13","best_ask":"0.14"}],"timestamp":"1776808416596","event_type":"price_change"}}
{"capturedAt":1776808416,"payload":{"market":"0x125149c5918fc5f8c6d34682f700a898a1a19ea4f4e2ae68ff4c5794ba657074","price_changes":[{"asset_id":"45936375922793925919605092352922707796689801895417366600539442410775071099958","price":"0.01","size":"12329.83","side":"BUY","hash":"37bf2288c2f624e8a9d56955bed02f5ddf7e6004","best_bid":"0.86","best_ask":"0.87"},{"asset_id":"86520121088881862182423437128238697252500151785248183602134095101149900014256","price":"0.99","size":"12329.83","side":"SELL","hash":"e6308cc5ae3ea3c430407204db35b0560f852708","best_bid":"0.13","best_ask":"0.14"}],"timestamp":"1776808416614","event_type":"price_change"}}
{"capturedAt":1776808416,"payload":{"market":"0x125149c5918fc5f8c6d34682f700a898a1a19ea4f4e2ae68ff4c5794ba657074","price_changes":[{"asset_id":"45936375922793925919605092352922707796689801895417366600539442410775071099958","price":"0.86","size":"348.79","side":"BUY","hash":"3b85547038218dec0032235aa83edd06a51c2c98","best_bid":"0.86","best_ask":"0.87"},{"asset_id":"86520121088881862182423437128238697252500151785248183602134095101149900014256","price":"0.14","size":"348.79","side":"SELL","hash":"70c2be141ea215eb4131c8527fbe73b4a9e1837b","best_bid":"0.13","best_ask":"0.14"}],"timestamp":"1776808416619","event_type":"price_change"}}
{"capturedAt":1776808416,"payload":{"market":"0x125149c5918fc5f8c6d34682f700a898a1a19ea4f4e2ae68ff4c5794ba657074","price_changes":[{"asset_id":"45936375922793925919605092352922707796689801895417366600539442410775071099958","price":"0.86","size":"358.79","side":"BUY","hash":"4fd22427e3456fca48a12f2e54c7424abb473beb","best_bid":"0.86","best_ask":"0.87"},{"asset_id":"86520121088881862182423437128238697252500151785248183602134095101149900014256","price":"0.14","size":"358.79","side":"SELL","hash":"6499ee19768d280b59016d95dc2410d25d99c88e","best_bid":"0.13","best_ask":"0.14"}],"timestamp":"1776808416616","event_type":"price_change"}}
{"capturedAt":1776808416,"payload":{"market":"0x125149c5918fc5f8c6d34682f700a898a1a19ea4f4e2ae68ff4c5794ba657074","price_changes":[{"asset_id":"45936375922793925919605092352922707796689801895417366600539442410775071099958","price":"0.86","size":"328.79","side":"BUY","hash":"0d70c68ea6dafd4fd4f3db6ee3089da5fa7e651c","best_bid":"0.86","best_ask":"0.87"},{"asset_id":"86520121088881862182423437128238697252500151785248183602134095101149900014256","price":"0.14","size":"328.79","side":"SELL","hash":"f84c7eade4b6966014a15797ccbb072353034fce","best_bid":"0.13","best_ask":"0.14"}],"timestamp":"1776808416621","event_type":"price_change"}}
{"capturedAt":1776808416,"payload":{"market":"0x125149c5918fc5f8c6d34682f700a898a1a19ea4f4e2ae68ff4c5794ba657074","price_changes":[{"asset_id":"45936375922793925919605092352922707796689801895417366600539442410775071099958","price":"0.86","size":"318.79","side":"BUY","hash":"f06b72ec76fd09754c1b201f651b3bdbb312375a","best_bid":"0.86","best_ask":"0.87"},{"asset_id":"86520121088881862182423437128238697252500151785248183602134095101149900014256","price":"0.14","size":"318.79","side":"SELL","hash":"a04e824e72b8f7d33b1793fe99cf329676bb2b51","best_bid":"0.13","best_ask":"0.14"}],"timestamp":"1776808416626","event_type":"price_change"}}
{"capturedAt":1776808416,"payload":{"market":"0x125149c5918fc5f8c6d34682f700a898a1a19ea4f4e2ae68ff4c5794ba657074","price_changes":[{"asset_id":"45936375922793925919605092352922707796689801895417366600539442410775071099958","price":"0.01","size":"12334.83","side":"BUY","hash":"c847a4eac4b1af6a3f61ffaa9d8b11b06f828b78","best_bid":"0.86","best_ask":"0.87"},{"asset_id":"86520121088881862182423437128238697252500151785248183602134095101149900014256","price":"0.99","size":"12334.83","side":"SELL","hash":"0ea80363bf6ae0aa4bba9f0faf8201b3ec2f82c3","best_bid":"0.13","best_ask":"0.14"}],"timestamp":"1776808416625","event_type":"price_change"}}
{"capturedAt":1776808416,"payload":{"market":"0x125149c5918fc5f8c6d34682f700a898a1a19ea4f4e2ae68ff4c5794ba657074","price_changes":[{"asset_id":"45936375922793925919605092352922707796689801895417366600539442410775071099958","price":"0.86","size":"298.79","side":"BUY","hash":"c6818e5158d57c57a849311d74897f59cc97d186","best_bid":"0.86","best_ask":"0.87"},{"asset_id":"86520121088881862182423437128238697252500151785248183602134095101149900014256","price":"0.14","size":"298.79","side":"SELL","hash":"68db34fe0fe1b92a2a8d2b925903b19ea3f87f5f","best_bid":"0.13","best_ask":"0.14"}],"timestamp":"1776808416627","event_type":"price_change"}}
{"capturedAt":1776808416,"payload":{"market":"0x125149c5918fc5f8c6d34682f700a898a1a19ea4f4e2ae68ff4c5794ba657074","price_changes":[{"asset_id":"45936375922793925919605092352922707796689801895417366600539442410775071099958","price":"0.86","size":"303.89","side":"BUY","hash":"b64c77f5e75522d6613e84e384bdda9029a7b6cb","best_bid":"0.86","best_ask":"0.87"},{"asset_id":"86520121088881862182423437128238697252500151785248183602134095101149900014256","price":"0.14","size":"303.89","side":"SELL","hash":"098ff7386a80893ee89388d23ef8553cdbd5cd9d","best_bid":"0.13","best_ask":"0.14"}],"timestamp":"1776808416628","event_type":"price_change"}}
{"capturedAt":1776808416,"payload":{"market":"0x125149c5918fc5f8c6d34682f700a898a1a19ea4f4e2ae68ff4c5794ba657074","price_changes":[{"asset_id":"45936375922793925919605092352922707796689801895417366600539442410775071099958","price":"0.86","size":"285.89","side":"BUY","hash":"2c00f01cf971f7128af52d1d6b4bfa89da5aa088","best_bid":"0.86","best_ask":"0.87"},{"asset_id":"86520121088881862182423437128238697252500151785248183602134095101149900014256","price":"0.14","size":"285.89","side":"SELL","hash":"f073ef565914eb9cdebaa9ce99c3b602c57b8913","best_bid":"0.13","best_ask":"0.14"}],"timestamp":"1776808416629","event_type":"price_change"}}
{"capturedAt":1776808416,"payload":{"market":"0x125149c5918fc5f8c6d34682f700a898a1a19ea4f4e2ae68ff4c5794ba657074","price_changes":[{"asset_id":"45936375922793925919605092352922707796689801895417366600539442410775071099958","price":"0.86","size":"273.89","side":"BUY","hash":"28c67de8a222c5b4ed968b222aee74d387870787","best_bid":"0.86","best_ask":"0.87"},{"asset_id":"86520121088881862182423437128238697252500151785248183602134095101149900014256","price":"0.14","size":"273.89","side":"SELL","hash":"5b86716a4c736f59e39a1d3646581818c20b24fa","best_bid":"0.13","best_ask":"0.14"}],"timestamp":"1776808416632","event_type":"price_change"}}
{"capturedAt":1776808416,"payload":{"market":"0x125149c5918fc5f8c6d34682f700a898a1a19ea4f4e2ae68ff4c5794ba657074","price_changes":[{"asset_id":"45936375922793925919605092352922707796689801895417366600539442410775071099958","price":"0.01","size":"12329.83","side":"BUY","hash":"97b219912904c1bcac5bddd9cccc079f0038dd8d","best_bid":"0.86","best_ask":"0.87"},{"asset_id":"86520121088881862182423437128238697252500151785248183602134095101149900014256","price":"0.99","size":"12329.83","side":"SELL","hash":"0fc1ee8d4d31ac169ffad4d421d1996b8c0fc0ed","best_bid":"0.13","best_ask":"0.14"}],"timestamp":"1776808416633","event_type":"price_change"}}
{"capturedAt":1776808416,"payload":{"market":"0x125149c5918fc5f8c6d34682f700a898a1a19ea4f4e2ae68ff4c5794ba657074","price_changes":[{"asset_id":"45936375922793925919605092352922707796689801895417366600539442410775071099958","price":"0.86","size":"255.89","side":"BUY","hash":"c012699948dacef153c85a145964f533e194ae21","best_bid":"0.86","best_ask":"0.87"},{"asset_id":"86520121088881862182423437128238697252500151785248183602134095101149900014256","price":"0.14","size":"255.89","side":"SELL","hash":"379dfbb83ef7ef98b1b94be30074b57e2f852bf5","best_bid":"0.13","best_ask":"0.14"}],"timestamp":"1776808416634","event_type":"price_change"}}
{"capturedAt":1776808416,"payload":{"market":"0x125149c5918fc5f8c6d34682f700a898a1a19ea4f4e2ae68ff4c5794ba657074","price_changes":[{"asset_id":"45936375922793925919605092352922707796689801895417366600539442410775071099958","price":"0.86","size":"235.89","side":"BUY","hash":"a01f893dc529c15c5a93ccff9ea1621e3b78ede0","best_bid":"0.86","best_ask":"0.87"},{"asset_id":"86520121088881862182423437128238697252500151785248183602134095101149900014256","price":"0.14","size":"235.89","side":"SELL","hash":"7a1427ff73134655956e0fdf504725a7fb3c712d","best_bid":"0.13","best_ask":"0.14"}],"timestamp":"1776808416635","event_type":"price_change"}}
{"capturedAt":1776808416,"payload":{"market":"0x125149c5918fc5f8c6d34682f700a898a1a19ea4f4e2ae68ff4c5794ba657074","price_changes":[{"asset_id":"45936375922793925919605092352922707796689801895417366600539442410775071099958","price":"0.86","size":"216.89","side":"BUY","hash":"63f0549abe48fbe43109c4d073420b958e81e84f","best_bid":"0.86","best_ask":"0.87"},{"asset_id":"86520121088881862182423437128238697252500151785248183602134095101149900014256","price":"0.14","size":"216.89","side":"SELL","hash":"6a9809d835cce9f2cd77082f942f344cdf3e8d8c","best_bid":"0.13","best_ask":"0.14"}],"timestamp":"1776808416637","event_type":"price_change"}}
{"capturedAt":1776808416,"payload":{"market":"0x125149c5918fc5f8c6d34682f700a898a1a19ea4f4e2ae68ff4c5794ba657074","price_changes":[{"asset_id":"45936375922793925919605092352922707796689801895417366600539442410775071099958","price":"0.86","size":"240.89","side":"BUY","hash":"8b364aec9436adaff098ea66eae14a6db927b9ac","best_bid":"0.86","best_ask":"0.87"},{"asset_id":"86520121088881862182423437128238697252500151785248183602134095101149900014256","price":"0.14","size":"240.89","side":"SELL","hash":"6a8fb0b2a9127d85b68c6f6f9a56d56422b02ac1","best_bid":"0.13","best_ask":"0.14"}],"timestamp":"1776808416639","event_type":"price_change"}}
{"capturedAt":1776808416,"payload":{"market":"0x125149c5918fc5f8c6d34682f700a898a1a19ea4f4e2ae68ff4c5794ba657074","price_changes":[{"asset_id":"45936375922793925919605092352922707796689801895417366600539442410775071099958","price":"0.86","size":"228.89","side":"BUY","hash":"4542a5b3d4689f3870ec97016a245152727b0239","best_bid":"0.86","best_ask":"0.87"},{"asset_id":"86520121088881862182423437128238697252500151785248183602134095101149900014256","price":"0.14","size":"228.89","side":"SELL","hash":"bb0967068d55bd4ce72b053c35e57681de2c0886","best_bid":"0.13","best_ask":"0.14"}],"timestamp":"1776808416639","event_type":"price_change"}}
{"capturedAt":1776808416,"payload":{"market":"0x125149c5918fc5f8c6d34682f700a898a1a19ea4f4e2ae68ff4c5794ba657074","price_changes":[{"asset_id":"45936375922793925919605092352922707796689801895417366600539442410775071099958","price":"0.01","size":"12324.83","side":"BUY","hash":"97fae67973a376fb72fa826a651e4e81b8215f7c","best_bid":"0.86","best_ask":"0.87"},{"asset_id":"86520121088881862182423437128238697252500151785248183602134095101149900014256","price":"0.99","size":"12324.83","side":"SELL","hash":"a010ca8d4827ba22fd1aaade676378c705017bd1","best_bid":"0.13","best_ask":"0.14"}],"timestamp":"1776808416643","event_type":"price_change"}}
{"capturedAt":1776808416,"payload":{"market":"0x125149c5918fc5f8c6d34682f700a898a1a19ea4f4e2ae68ff4c5794ba657074","price_changes":[{"asset_id":"45936375922793925919605092352922707796689801895417366600539442410775071099958","price":"0.86","size":"223.66","side":"BUY","hash":"345231458b498943096a047526a46e67b2876c58","best_bid":"0.86","best_ask":"0.87"},{"asset_id":"86520121088881862182423437128238697252500151785248183602134095101149900014256","price":"0.14","size":"223.66","side":"SELL","hash":"0630033ff6c7f31e1d3768920a0645b4c51a423f","best_bid":"0.13","best_ask":"0.14"}],"timestamp":"1776808416644","event_type":"price_change"}}
{"capturedAt":1776808416,"payload":{"market":"0x125149c5918fc5f8c6d34682f700a898a1a19ea4f4e2ae68ff4c5794ba657074","price_changes":[{"asset_id":"45936375922793925919605092352922707796689801895417366600539442410775071099958","price":"0.86","size":"205.66","side":"BUY","hash":"f9cb3560957c51bd2644dba79f60f6712a8bf5ff","best_bid":"0.86","best_ask":"0.87"},{"asset_id":"86520121088881862182423437128238697252500151785248183602134095101149900014256","price":"0.14","size":"205.66","side":"SELL","hash":"dcc6c4ae214f663a42865a33ebba504124bb1ec8","best_bid":"0.13","best_ask":"0.14"}],"timestamp":"1776808416645","event_type":"price_change"}}
{"capturedAt":1776808416,"payload":{"market":"0x125149c5918fc5f8c6d34682f700a898a1a19ea4f4e2ae68ff4c5794ba657074","price_changes":[{"asset_id":"45936375922793925919605092352922707796689801895417366600539442410775071099958","price":"0.86","size":"187.66","side":"BUY","hash":"de35c3026e658dab33277e354b7cbb6dbfa4ba11","best_bid":"0.86","best_ask":"0.87"},{"asset_id":"86520121088881862182423437128238697252500151785248183602134095101149900014256","price":"0.14","size":"187.66","side":"SELL","hash":"ce4c09d21400b59d949adb38e2eaec9936ad923e","best_bid":"0.13","best_ask":"0.14"}],"timestamp":"1776808416646","event_type":"price_change"}}
{"capturedAt":1776808416,"payload":{"market":"0x125149c5918fc5f8c6d34682f700a898a1a19ea4f4e2ae68ff4c5794ba657074","price_changes":[{"asset_id":"45936375922793925919605092352922707796689801895417366600539442410775071099958","price":"0.86","size":"171.97","side":"BUY","hash":"f6ebf3d16823076b678fa18ffdd641bea6fb4b5c","best_bid":"0.86","best_ask":"0.87"},{"asset_id":"86520121088881862182423437128238697252500151785248183602134095101149900014256","price":"0.14","size":"171.97","side":"SELL","hash":"3990d069af3c233d2ff684abe1f11310891ae4d1","best_bid":"0.13","best_ask":"0.14"}],"timestamp":"1776808416649","event_type":"price_change"}}
{"capturedAt":1776808416,"payload":{"market":"0x125149c5918fc5f8c6d34682f700a898a1a19ea4f4e2ae68ff4c5794ba657074","price_changes":[{"asset_id":"45936375922793925919605092352922707796689801895417366600539442410775071099958","price":"0.86","size":"177.66","side":"BUY","hash":"e45b888d75ae8c042d02d1e6a51e6c88440ebe40","best_bid":"0.86","best_ask":"0.87"},{"asset_id":"86520121088881862182423437128238697252500151785248183602134095101149900014256","price":"0.14","size":"177.66","side":"SELL","hash":"10411b09f56cd752e3f7b1ce6a217f8595aa0d41","best_bid":"0.13","best_ask":"0.14"}],"timestamp":"1776808416648","event_type":"price_change"}}
{"capturedAt":1776808416,"payload":{"market":"0x125149c5918fc5f8c6d34682f700a898a1a19ea4f4e2ae68ff4c5794ba657074","price_changes":[{"asset_id":"45936375922793925919605092352922707796689801895417366600539442410775071099958","price":"0.86","size":"184.97","side":"BUY","hash":"b3ca9f47d366dd232640d108eb5c7d20e43ef5c9","best_bid":"0.86","best_ask":"0.87"},{"asset_id":"86520121088881862182423437128238697252500151785248183602134095101149900014256","price":"0.14","size":"184.97","side":"SELL","hash":"455bc82e5af058817aece43324191896a07a7c28","best_bid":"0.13","best_ask":"0.14"}],"timestamp":"1776808416650","event_type":"price_change"}}
{"capturedAt":1776808416,"payload":{"market":"0x125149c5918fc5f8c6d34682f700a898a1a19ea4f4e2ae68ff4c5794ba657074","price_changes":[{"asset_id":"45936375922793925919605092352922707796689801895417366600539442410775071099958","price":"0.86","size":"202.31","side":"BUY","hash":"92448acedd723fefc6331f58550cf96e90e09ada","best_bid":"0.86","best_ask":"0.87"},{"asset_id":"86520121088881862182423437128238697252500151785248183602134095101149900014256","price":"0.14","size":"202.31","side":"SELL","hash":"3008d5efb44b506d3a2840cc9ff73b313714074d","best_bid":"0.13","best_ask":"0.14"}],"timestamp":"1776808416652","event_type":"price_change"}}
{"capturedAt":1776808416,"payload":{"market":"0x125149c5918fc5f8c6d34682f700a898a1a19ea4f4e2ae68ff4c5794ba657074","price_changes":[{"asset_id":"45936375922793925919605092352922707796689801895417366600539442410775071099958","price":"0.86","size":"190.31","side":"BUY","hash":"105704805d75f93bc5b1972b455ef221b35a8a98","best_bid":"0.86","best_ask":"0.87"},{"asset_id":"86520121088881862182423437128238697252500151785248183602134095101149900014256","price":"0.14","size":"190.31","side":"SELL","hash":"48454fb8a341dbbea0c3bbebc8f89479b3a42905","best_bid":"0.13","best_ask":"0.14"}],"timestamp":"1776808416651","event_type":"price_change"}}
{"capturedAt":1776808416,"payload":{"market":"0x125149c5918fc5f8c6d34682f700a898a1a19ea4f4e2ae68ff4c5794ba657074","price_changes":[{"asset_id":"45936375922793925919605092352922707796689801895417366600539442410775071099958","price":"0.86","size":"219.38","side":"BUY","hash":"62718aa2069ad3ad3b98fa360329327b430a10c7","best_bid":"0.86","best_ask":"0.87"},{"asset_id":"86520121088881862182423437128238697252500151785248183602134095101149900014256","price":"0.14","size":"219.38","side":"SELL","hash":"725469de853c556e8d8588f73425caa0edca9912","best_bid":"0.13","best_ask":"0.14"}],"timestamp":"1776808416657","event_type":"price_change"}}
{"capturedAt":1776808416,"payload":{"market":"0x125149c5918fc5f8c6d34682f700a898a1a19ea4f4e2ae68ff4c5794ba657074","price_changes":[{"asset_id":"86520121088881862182423437128238697252500151785248183602134095101149900014256","price":"0.05","size":"590.63","side":"BUY","hash":"cdc6eb72e5d1bbac6b503ff3707e7d58e6f5d9d3","best_bid":"0.13","best_ask":"0.14"},{"asset_id":"45936375922793925919605092352922707796689801895417366600539442410775071099958","price":"0.95","size":"590.63","side":"SELL","hash":"c724606fa179c480fcebc6bf6248f94bc35e98f3","best_bid":"0.86","best_ask":"0.87"}],"timestamp":"1776808416660","event_type":"price_change"}}
{"capturedAt":1776808416,"payload":{"market":"0x125149c5918fc5f8c6d34682f700a898a1a19ea4f4e2ae68ff4c5794ba657074","price_changes":[{"asset_id":"45936375922793925919605092352922707796689801895417366600539442410775071099958","price":"0.86","size":"214.28","side":"BUY","hash":"0540924e3fb917a3cd9d534f4cddc101c8ae4590","best_bid":"0.86","best_ask":"0.87"},{"asset_id":"86520121088881862182423437128238697252500151785248183602134095101149900014256","price":"0.14","size":"214.28","side":"SELL","hash":"3412ce8c8b87546001f3ac7a24244a30f815f0b3","best_bid":"0.13","best_ask":"0.14"}],"timestamp":"1776808416658","event_type":"price_change"}}
{"capturedAt":1776808416,"payload":{"market":"0x125149c5918fc5f8c6d34682f700a898a1a19ea4f4e2ae68ff4c5794ba657074","price_changes":[{"asset_id":"45936375922793925919605092352922707796689801895417366600539442410775071099958","price":"0.86","size":"207.38","side":"BUY","hash":"456d9941e4bc78ab6ab50231f1cbb83c348eef2d","best_bid":"0.86","best_ask":"0.87"},{"asset_id":"86520121088881862182423437128238697252500151785248183602134095101149900014256","price":"0.14","size":"207.38","side":"SELL","hash":"e24880c6def83ac8a3f76add45a745f40dd4fe0a","best_bid":"0.13","best_ask":"0.14"}],"timestamp":"1776808416655","event_type":"price_change"}}
{"capturedAt":1776808416,"payload":{"market":"0x125149c5918fc5f8c6d34682f700a898a1a19ea4f4e2ae68ff4c5794ba657074","price_changes":[{"asset_id":"45936375922793925919605092352922707796689801895417366600539442410775071099958","price":"0.86","size":"239.28","side":"BUY","hash":"86db3460a4c2703119101051e74815d013afcaab","best_bid":"0.86","best_ask":"0.87"},{"asset_id":"86520121088881862182423437128238697252500151785248183602134095101149900014256","price":"0.14","size":"239.28","side":"SELL","hash":"978cf092252ab69b721d561f2350461949ea23e9","best_bid":"0.13","best_ask":"0.14"}],"timestamp":"1776808416661","event_type":"price_change"}}
{"capturedAt":1776808416,"payload":{"market":"0x125149c5918fc5f8c6d34682f700a898a1a19ea4f4e2ae68ff4c5794ba657074","price_changes":[{"asset_id":"45936375922793925919605092352922707796689801895417366600539442410775071099958","price":"0.86","size":"278.28","side":"BUY","hash":"2b72972658d253d4eaaedc21bb4dd5de2134808b","best_bid":"0.86","best_ask":"0.87"},{"asset_id":"86520121088881862182423437128238697252500151785248183602134095101149900014256","price":"0.14","size":"278.28","side":"SELL","hash":"4c2a61408aed15c8671f246691de4625e387c36c","best_bid":"0.13","best_ask":"0.14"}],"timestamp":"1776808416667","event_type":"price_change"}}
{"capturedAt":1776808416,"payload":{"market":"0x125149c5918fc5f8c6d34682f700a898a1a19ea4f4e2ae68ff4c5794ba657074","price_changes":[{"asset_id":"45936375922793925919605092352922707796689801895417366600539442410775071099958","price":"0.86","size":"260.28","side":"BUY","hash":"837c4521dd85cd06dfbf726162f0ce76b362772b","best_bid":"0.86","best_ask":"0.87"},{"asset_id":"86520121088881862182423437128238697252500151785248183602134095101149900014256","price":"0.14","size":"260.28","side":"SELL","hash":"8d446b6a2ebdfe23a8c9859249f3eaa9c3a1e5a2","best_bid":"0.13","best_ask":"0.14"}],"timestamp":"1776808416664","event_type":"price_change"}}
{"capturedAt":1776808416,"payload":{"market":"0x125149c5918fc5f8c6d34682f700a898a1a19ea4f4e2ae68ff4c5794ba657074","price_changes":[{"asset_id":"45936375922793925919605092352922707796689801895417366600539442410775071099958","price":"0.86","size":"273.28","side":"BUY","hash":"111568c63b277cb42a882cb58898a0ebceda6bd9","best_bid":"0.86","best_ask":"0.87"},{"asset_id":"86520121088881862182423437128238697252500151785248183602134095101149900014256","price":"0.14","size":"273.28","side":"SELL","hash":"888e279fe891b4387c114131db93ed20c2504951","best_bid":"0.13","best_ask":"0.14"}],"timestamp":"1776808416670","event_type":"price_change"}}
{"capturedAt":1776808416,"payload":{"market":"0x125149c5918fc5f8c6d34682f700a898a1a19ea4f4e2ae68ff4c5794ba657074","price_changes":[{"asset_id":"86520121088881862182423437128238697252500151785248183602134095101149900014256","price":"0.12","size":"347.5","side":"BUY","hash":"cd6d3aa8ae80ae57ce47796cda66d5a5618ba9d0","best_bid":"0.13","best_ask":"0.14"},{"asset_id":"45936375922793925919605092352922707796689801895417366600539442410775071099958","price":"0.88","size":"347.5","side":"SELL","hash":"1dad84db6914403e5b0c53c35e38088234b662c3","best_bid":"0.86","best_ask":"0.87"}],"timestamp":"1776808416672","event_type":"price_change"}}
{"capturedAt":1776808416,"payload":{"market":"0x125149c5918fc5f8c6d34682f700a898a1a19ea4f4e2ae68ff4c5794ba657074","price_changes":[{"asset_id":"45936375922793925919605092352922707796689801895417366600539442410775071099958","price":"0.86","size":"268.28","side":"BUY","hash":"c0ad09e6458cccb49a7e265c47fe8de70640eaa1","best_bid":"0.86","best_ask":"0.87"},{"asset_id":"86520121088881862182423437128238697252500151785248183602134095101149900014256","price":"0.14","size":"268.28","side":"SELL","hash":"e0e40f5e4a77d0ce665ca45a0f2de2de742531be","best_bid":"0.13","best_ask":"0.14"}],"timestamp":"1776808416665","event_type":"price_change"}}
{"capturedAt":1776808416,"payload":{"market":"0x125149c5918fc5f8c6d34682f700a898a1a19ea4f4e2ae68ff4c5794ba657074","price_changes":[{"asset_id":"45936375922793925919605092352922707796689801895417366600539442410775071099958","price":"0.86","size":"262.52","side":"BUY","hash":"45ddde35d59a7c4fc98eb3992a68d6b42997a339","best_bid":"0.86","best_ask":"0.87"},{"asset_id":"86520121088881862182423437128238697252500151785248183602134095101149900014256","price":"0.14","size":"262.52","side":"SELL","hash":"a49752b03289a351ac59eb9cf6c933b343cf5691","best_bid":"0.13","best_ask":"0.14"}],"timestamp":"1776808416674","event_type":"price_change"}}
{"capturedAt":1776808416,"payload":{"market":"0x125149c5918fc5f8c6d34682f700a898a1a19ea4f4e2ae68ff4c5794ba657074","price_changes":[{"asset_id":"45936375922793925919605092352922707796689801895417366600539442410775071099958","price":"0.86","size":"267.94","side":"BUY","hash":"11eabe6e6866c17edea6daba235f72b47f912937","best_bid":"0.86","best_ask":"0.87"},{"asset_id":"86520121088881862182423437128238697252500151785248183602134095101149900014256","price":"0.14","size":"267.94","side":"SELL","hash":"2c25d769c33722258b0304f2cf33bd1135ceb28a","best_bid":"0.13","best_ask":"0.14"}],"timestamp":"1776808416673","event_type":"price_change"}}
{"capturedAt":1776808416,"payload":{"market":"0x125149c5918fc5f8c6d34682f700a898a1a19ea4f4e2ae68ff4c5794ba657074","price_changes":[{"asset_id":"45936375922793925919605092352922707796689801895417366600539442410775071099958","price":"0.86","size":"267.78","side":"BUY","hash":"8db4550c735507555828c9d6dbd4032f106c30f5","best_bid":"0.86","best_ask":"0.87"},{"asset_id":"86520121088881862182423437128238697252500151785248183602134095101149900014256","price":"0.14","size":"267.78","side":"SELL","hash":"68b0b6523f5a0e09964a074172f26ddf55f3cf7f","best_bid":"0.13","best_ask":"0.14"}],"timestamp":"1776808416676","event_type":"price_change"}}
{"capturedAt":1776808416,"payload":{"market":"0x125149c5918fc5f8c6d34682f700a898a1a19ea4f4e2ae68ff4c5794ba657074","price_changes":[{"asset_id":"45936375922793925919605092352922707796689801895417366600539442410775071099958","price":"0.86","size":"247.28","side":"BUY","hash":"556c86280bb4fd9e6e873c9d02397a7ba10f4925","best_bid":"0.86","best_ask":"0.87"},{"asset_id":"86520121088881862182423437128238697252500151785248183602134095101149900014256","price":"0.14","size":"247.28","side":"SELL","hash":"78476e9a60a1ce36aa5f8e6206aa3de59daa7de2","best_bid":"0.13","best_ask":"0.14"}],"timestamp":"1776808416663","event_type":"price_change"}}
{"capturedAt":1776808416,"payload":{"market":"0x125149c5918fc5f8c6d34682f700a898a1a19ea4f4e2ae68ff4c5794ba657074","price_changes":[{"asset_id":"45936375922793925919605092352922707796689801895417366600539442410775071099958","price":"0.01","size":"12334.83","side":"BUY","hash":"39ebd22c466cb79436950553d565894462fead34","best_bid":"0.86","best_ask":"0.87"},{"asset_id":"86520121088881862182423437128238697252500151785248183602134095101149900014256","price":"0.99","size":"12334.83","side":"SELL","hash":"9eb9343bf9b7c2d51f3fdabe35941225a7878466","best_bid":"0.13","best_ask":"0.14"}],"timestamp":"1776808416677","event_type":"price_change"}}
{"capturedAt":1776808416,"payload":{"market":"0x125149c5918fc5f8c6d34682f700a898a1a19ea4f4e2ae68ff4c5794ba657074","price_changes":[{"asset_id":"45936375922793925919605092352922707796689801895417366600539442410775071099958","price":"0.86","size":"279.78","side":"BUY","hash":"9d3947b628e3f55ab1281ac02e9f2bb272ad03fc","best_bid":"0.86","best_ask":"0.87"},{"asset_id":"86520121088881862182423437128238697252500151785248183602134095101149900014256","price":"0.14","size":"279.78","side":"SELL","hash":"372c74f06fc39e2829a357c3af8691cb2e6395f5","best_bid":"0.13","best_ask":"0.14"}],"timestamp":"1776808416679","event_type":"price_change"}}
{"capturedAt":1776808416,"payload":{"market":"0x125149c5918fc5f8c6d34682f700a898a1a19ea4f4e2ae68ff4c5794ba657074","price_changes":[{"asset_id":"45936375922793925919605092352922707796689801895417366600539442410775071099958","price":"0.86","size":"299.78","side":"BUY","hash":"d4f2644416f77c6d315505e587cdb508d08405e2","best_bid":"0.86","best_ask":"0.87"},{"asset_id":"86520121088881862182423437128238697252500151785248183602134095101149900014256","price":"0.14","size":"299.78","side":"SELL","hash":"9291eb3974d1c59c05119f949cf814da4161c039","best_bid":"0.13","best_ask":"0.14"}],"timestamp":"1776808416681","event_type":"price_change"}}
{"capturedAt":1776808416,"payload":{"market":"0x125149c5918fc5f8c6d34682f700a898a1a19ea4f4e2ae68ff4c5794ba657074","price_changes":[{"asset_id":"45936375922793925919605092352922707796689801895417366600539442410775071099958","price":"0.86","size":"311.78","side":"BUY","hash":"0aef8d254374e065a18c08aa253e7035e00f4546","best_bid":"0.86","best_ask":"0.87"},{"asset_id":"86520121088881862182423437128238697252500151785248183602134095101149900014256","price":"0.14","size":"311.78","side":"SELL","hash":"aeef1ee4990031ad51fbbd82015a2cc8dfddedd7","best_bid":"0.13","best_ask":"0.14"}],"timestamp":"1776808416683","event_type":"price_change"}}
{"capturedAt":1776808416,"payload":{"market":"0x125149c5918fc5f8c6d34682f700a898a1a19ea4f4e2ae68ff4c5794ba657074","price_changes":[{"asset_id":"45936375922793925919605092352922707796689801895417366600539442410775071099958","price":"0.86","size":"306.71","side":"BUY","hash":"d6c535197f71c7462e8b7f65e30c2a96764db071","best_bid":"0.86","best_ask":"0.87"},{"asset_id":"86520121088881862182423437128238697252500151785248183602134095101149900014256","price":"0.14","size":"306.71","side":"SELL","hash":"b04c716a5b33489d45041b5ff0fd22663cb01f65","best_bid":"0.13","best_ask":"0.14"}],"timestamp":"1776808416685","event_type":"price_change"}}
{"capturedAt":1776808416,"payload":{"market":"0x125149c5918fc5f8c6d34682f700a898a1a19ea4f4e2ae68ff4c5794ba657074","price_changes":[{"asset_id":"45936375922793925919605092352922707796689801895417366600539442410775071099958","price":"0.01","size":"12329.83","side":"BUY","hash":"faf1d217d522d20e5bc64a2a30a4e93317669814","best_bid":"0.86","best_ask":"0.87"},{"asset_id":"86520121088881862182423437128238697252500151785248183602134095101149900014256","price":"0.99","size":"12329.83","side":"SELL","hash":"8d62790330b384b1b8f8e3f6bea3489ebd1f0092","best_bid":"0.13","best_ask":"0.14"}],"timestamp":"1776808416666","event_type":"price_change"}}
{"capturedAt":1776808416,"payload":{"market":"0x125149c5918fc5f8c6d34682f700a898a1a19ea4f4e2ae68ff4c5794ba657074","price_changes":[{"asset_id":"45936375922793925919605092352922707796689801895417366600539442410775071099958","price":"0.01","size":"12329.83","side":"BUY","hash":"a059d07f22f3174affb4de3f8c9cd3b640728abe","best_bid":"0.86","best_ask":"0.87"},{"asset_id":"86520121088881862182423437128238697252500151785248183602134095101149900014256","price":"0.99","size":"12329.83","side":"SELL","hash":"4be074b45c18b5a7e0939489efe04a9f032460ef","best_bid":"0.13","best_ask":"0.14"}],"timestamp":"1776808416686","event_type":"price_change"}}
{"capturedAt":1776808416,"payload":{"market":"0x125149c5918fc5f8c6d34682f700a898a1a19ea4f4e2ae68ff4c5794ba657074","price_changes":[{"asset_id":"45936375922793925919605092352922707796689801895417366600539442410775071099958","price":"0.86","size":"289.78","side":"BUY","hash":"66a0fa30c065e2cb9d214290cffe84b94128a738","best_bid":"0.86","best_ask":"0.87"},{"asset_id":"86520121088881862182423437128238697252500151785248183602134095101149900014256","price":"0.14","size":"289.78","side":"SELL","hash":"e626dae53cf52195e050d91e0321827a81c0348a","best_bid":"0.13","best_ask":"0.14"}],"timestamp":"1776808416680","event_type":"price_change"}}
{"capturedAt":1776808416,"payload":{"market":"0x125149c5918fc5f8c6d34682f700a898a1a19ea4f4e2ae68ff4c5794ba657074","price_changes":[{"asset_id":"86520121088881862182423437128238697252500151785248183602134095101149900014256","price":"0.13","size":"154.74","side":"BUY","hash":"bbd2f1cc3fe8b1afabb3b811e1d409bfc19a070b","best_bid":"0.13","best_ask":"0.14"},{"asset_id":"45936375922793925919605092352922707796689801895417366600539442410775071099958","price":"0.87","size":"154.74","side":"SELL","hash":"9234e7b311e21297b28f0dee96dfa2518ebebf7d","best_bid":"0.86","best_ask":"0.87"}],"timestamp":"1776808416669","event_type":"price_change"}}
{"capturedAt":1776808416,"payload":{"market":"0x125149c5918fc5f8c6d34682f700a898a1a19ea4f4e2ae68ff4c5794ba657074","price_changes":[{"asset_id":"45936375922793925919605092352922707796689801895417366600539442410775071099958","price":"0.86","size":"226.28","side":"BUY","hash":"6d3048c60ffb7d1d86fa0cac5a3658be73879a4e","best_bid":"0.86","best_ask":"0.87"},{"asset_id":"86520121088881862182423437128238697252500151785248183602134095101149900014256","price":"0.14","size":"226.28","side":"SELL","hash":"1dad290584eea0896faa93631c7b06c1ed06098d","best_bid":"0.13","best_ask":"0.14"}],"timestamp":"1776808416660","event_type":"price_change"}}
{"capturedAt":1776808416,"payload":{"market":"0x125149c5918fc5f8c6d34682f700a898a1a19ea4f4e2ae68ff4c5794ba657074","price_changes":[{"asset_id":"86520121088881862182423437128238697252500151785248183602134095101149900014256","price":"0.03","size":"1803.83","side":"BUY","hash":"994ae7415c7acce84687fd9ab04775b4bad67af4","best_bid":"0.13","best_ask":"0.14"},{"asset_id":"45936375922793925919605092352922707796689801895417366600539442410775071099958","price":"0.97","size":"1803.83","side":"SELL","hash":"2e1967811b0c9c8aa9db245fb24f8a5f5abdb968","best_bid":"0.86","best_ask":"0.87"}],"timestamp":"1776808416690","event_type":"price_change"}}
{"capturedAt":1776808416,"payload":{"market":"0x125149c5918fc5f8c6d34682f700a898a1a19ea4f4e2ae68ff4c5794ba657074","price_changes":[{"asset_id":"45936375922793925919605092352922707796689801895417366600539442410775071099958","price":"0.81","size":"274.9","side":"BUY","hash":"1cc533d5a44dea1ba40c711e5998cb7476659359","best_bid":"0.86","best_ask":"0.87"},{"asset_id":"86520121088881862182423437128238697252500151785248183602134095101149900014256","price":"0.19","size":"274.9","side":"SELL","hash":"a21bb38e8716df298cab853e4125d024f41d29d3","best_bid":"0.13","best_ask":"0.14"}],"timestamp":"1776808416692","event_type":"price_change"}}
{"capturedAt":1776808416,"payload":{"market":"0x125149c5918fc5f8c6d34682f700a898a1a19ea4f4e2ae68ff4c5794ba657074","asset_id":"45936375922793925919605092352922707796689801895417366600539442410775071099958","best_bid":"0.86","best_ask":"0.87","spread":"0.01","timestamp":"1776808416697","event_type":"best_bid_ask"}}
{"capturedAt":1776808416,"payload":{"market":"0x125149c5918fc5f8c6d34682f700a898a1a19ea4f4e2ae68ff4c5794ba657074","asset_id":"86520121088881862182423437128238697252500151785248183602134095101149900014256","best_bid":"0.13","best_ask":"0.14","spread":"0.01","timestamp":"1776808416697","event_type":"best_bid_ask"}}
{"capturedAt":1776808416,"payload":{"market":"0x125149c5918fc5f8c6d34682f700a898a1a19ea4f4e2ae68ff4c5794ba657074","asset_id":"45936375922793925919605092352922707796689801895417366600539442410775071099958","bids":[{"price":"0.01","size":"12329.83"},{"price":"0.02","size":"1715.28"},{"price":"0.03","size":"1338.69"},{"price":"0.04","size":"583.84"},{"price":"0.05","size":"1006.34"},{"price":"0.06","size":"392.8"},{"price":"0.07","size":"304.69"},{"price":"0.08","size":"278.9"},{"price":"0.09","size":"225"},{"price":"0.1","size":"282"},{"price":"0.11","size":"217.79"},{"price":"0.12","size":"215.1"},{"price":"0.13","size":"202.8"},{"price":"0.14","size":"200.9"},{"price":"0.15","size":"209.2"},{"price":"0.16","size":"197.8"},{"price":"0.17","size":"202.39"},{"price":"0.18","size":"200.4"},{"price":"0.19","size":"194.4"},{"price":"0.2","size":"193.5"},{"price":"0.21","size":"215.31"},{"price":"0.22","size":"197"},{"price":"0.23","size":"229.34"},{"price":"0.24","size":"195.7"},{"price":"0.25","size":"190.2"},{"price":"0.26","size":"189.7"},{"price":"0.27","size":"194.3"},{"price":"0.28","size":"188.89"},{"price":"0.29","size":"188.5"},{"price":"0.3","size":"206.48"},{"price":"0.31","size":"394.45"},{"price":"0.32","size":"187.5"},{"price":"0.33","size":"193.55"},{"price":"0.34","size":"187"},{"price":"0.35","size":"602.68"},{"price":"0.36","size":"186.6"},{"price":"0.37","size":"191.96"},{"price":"0.38","size":"186.3"},{"price":"0.39","size":"491.36"},{"price":"0.4","size":"226"},{"price":"0.41","size":"203.32"},{"price":"0.42","size":"185.8"},{"price":"0.43","size":"190.8"},{"price":"0.44","size":"190.6"},{"price":"0.45","size":"230.58"},{"price":"0.46","size":"185.5"},{"price":"0.47","size":"245.86"},{"price":"0.48","size":"242.56"},{"price":"0.49","size":"222.4"},{"price":"0.5","size":"378.64"},{"price":"0.51","size":"205.25"},{"price":"0.52","size":"226.77"},{"price":"0.53","size":"136.71"},{"price":"0.54","size":"185.5"},{"price":"0.55","size":"207.66"},{"price":"0.56","size":"196.6"},{"price":"0.57","size":"180.7"},{"price":"0.58","size":"180.8"},{"price":"0.59","size":"180.9"},{"price":"0.6","size":"139"},{"price":"0.61","size":"185.46"},{"price":"0.62","size":"141.3"},{"price":"0.63","size":"131.4"},{"price":"0.64","size":"131.6"},{"price":"0.65","size":"136.8"},{"price":"0.66","size":"342"},{"price":"0.67","size":"232.3"},{"price":"0.68","size":"382.5"},{"price":"0.69","size":"182.8"},{"price":"0.7","size":"244.95"},{"price":"0.71","size":"405.5"},{"price":"0.72","size":"530.89"},{"price":"0.73","size":"217.3"},{"price":"0.74","size":"187.7"},{"price":"0.75","size":"475.29"},{"price":"0.76","size":"148.49"},{"price":"0.77","size":"229.3"},{"price":"0.78","size":"318.98"},{"price":"0.79","size":"184.7"},{"price":"0.8","size":"280.25"},{"price":"0.81","size":"274.9"},{"price":"0.82","size":"325.78"},{"price":"0.83","size":"349.46"},{"price":"0.84","size":"383.63"},{"price":"0.85","size":"457.28"},{"price":"0.86","size":"306.06"}],"asks":[{"price":"0.99","size":"12907.69"},{"price":"0.98","size":"1746.16"},{"price":"0.97","size":"1803.83"},{"price":"0.96","size":"938.3"},{"price":"0.95","size":"590.63"},{"price":"0.94","size":"427.8"},{"price":"0.93","size":"654.3"},{"price":"0.92","size":"656.9"},{"price":"0.91","size":"202"},{"price":"0.9","size":"812.8"},{"price":"0.89","size":"391.5"},{"price":"0.88","size":"347.5"},{"price":"0.87","size":"154.74"}],"hash":"99b7576928f9c058d1474dd8f671c66d24a6818d","timestamp":"1776808416696","event_type":"book"}}
{"capturedAt":1776808416,"payload":{"market":"0x125149c5918fc5f8c6d34682f700a898a1a19ea4f4e2ae68ff4c5794ba657074","price_changes":[{"asset_id":"45936375922793925919605092352922707796689801895417366600539442410775071099958","price":"0.01","size":"12324.83","side":"BUY","hash":"4c843417aa31b1cd690bd9a844d6f107ccc7df96","best_bid":"0.86","best_ask":"0.87"},{"asset_id":"86520121088881862182423437128238697252500151785248183602134095101149900014256","price":"0.99","size":"12324.83","side":"SELL","hash":"77cdd3c689789192c8ae4c0069f640b1f034148a","best_bid":"0.13","best_ask":"0.14"}],"timestamp":"1776808416697","event_type":"price_change"}}
{"capturedAt":1776808416,"payload":{"market":"0x125149c5918fc5f8c6d34682f700a898a1a19ea4f4e2ae68ff4c5794ba657074","asset_id":"86520121088881862182423437128238697252500151785248183602134095101149900014256","bids":[{"price":"0.01","size":"12907.69"},{"price":"0.02","size":"1746.16"},{"price":"0.03","size":"1803.83"},{"price":"0.04","size":"938.3"},{"price":"0.05","size":"590.63"},{"price":"0.06","size":"427.8"},{"price":"0.07","size":"654.3"},{"price":"0.08","size":"656.9"},{"price":"0.09","size":"202"},{"price":"0.1","size":"812.8"},{"price":"0.11","size":"391.5"},{"price":"0.12","size":"347.5"},{"price":"0.13","size":"154.74"}],"asks":[{"price":"0.99","size":"12329.83"},{"price":"0.98","size":"1715.28"},{"price":"0.97","size":"1338.69"},{"price":"0.96","size":"583.84"},{"price":"0.95","size":"1006.34"},{"price":"0.94","size":"392.8"},{"price":"0.93","size":"304.69"},{"price":"0.92","size":"278.9"},{"price":"0.91","size":"225"},{"price":"0.9","size":"282"},{"price":"0.89","size":"217.79"},{"price":"0.88","size":"215.1"},{"price":"0.87","size":"202.8"},{"price":"0.86","size":"200.9"},{"price":"0.85","size":"209.2"},{"price":"0.84","size":"197.8"},{"price":"0.83","size":"202.39"},{"price":"0.82","size":"200.4"},{"price":"0.81","size":"194.4"},{"price":"0.8","size":"193.5"},{"price":"0.79","size":"215.31"},{"price":"0.78","size":"197"},{"price":"0.77","size":"229.34"},{"price":"0.76","size":"195.7"},{"price":"0.75","size":"190.2"},{"price":"0.74","size":"189.7"},{"price":"0.73","size":"194.3"},{"price":"0.72","size":"188.89"},{"price":"0.71","size":"188.5"},{"price":"0.7","size":"206.48"},{"price":"0.69","size":"394.45"},{"price":"0.68","size":"187.5"},{"price":"0.67","size":"193.55"},{"price":"0.66","size":"187"},{"price":"0.65","size":"602.68"},{"price":"0.64","size":"186.6"},{"price":"0.63","size":"191.96"},{"price":"0.62","size":"186.3"},{"price":"0.61","size":"491.36"},{"price":"0.6","size":"226"},{"price":"0.59","size":"203.32"},{"price":"0.58","size":"185.8"},{"price":"0.57","size":"190.8"},{"price":"0.56","size":"190.6"},{"price":"0.55","size":"230.58"},{"price":"0.54","size":"185.5"},{"price":"0.53","size":"245.86"},{"price":"0.52","size":"242.56"},{"price":"0.51","size":"222.4"},{"price":"0.5","size":"378.64"},{"price":"0.49","size":"205.25"},{"price":"0.48","size":"226.77"},{"price":"0.47","size":"136.71"},{"price":"0.46","size":"185.5"},{"price":"0.45","size":"207.66"},{"price":"0.44","size":"196.6"},{"price":"0.43","size":"180.7"},{"price":"0.42","size":"180.8"},{"price":"0.41","size":"180.9"},{"price":"0.4","size":"139"},{"price":"0.39","size":"185.46"},{"price":"0.38","size":"141.3"},{"price":"0.37","size":"131.4"},{"price":"0.36","size":"131.6"},{"price":"0.35","size":"136.8"},{"price":"0.34","size":"342"},{"price":"0.33","size":"232.3"},{"price":"0.32","size":"382.5"},{"price":"0.31","size":"182.8"},{"price":"0.3","size":"244.95"},{"price":"0.29","size":"405.5"},{"price":"0.28","size":"530.89"},{"price":"0.27","size":"217.3"},{"price":"0.26","size":"187.7"},{"price":"0.25","size":"475.29"},{"price":"0.24","size":"148.49"},{"price":"0.23","size":"229.3"},{"price":"0.22","size":"318.98"},{"price":"0.21","size":"184.7"},{"price":"0.2","size":"280.25"},{"price":"0.19","size":"274.9"},{"price":"0.18","size":"325.78"},{"price":"0.17","size":"349.46"},{"price":"0.16","size":"383.63"},{"price":"0.15","size":"457.28"},{"price":"0.14","size":"306.06"}],"hash":"5a5f235de3117913e473abce76d45cd38c7bd7f8","timestamp":"1776808416696","event_type":"book"}}
{"capturedAt":1776808416,"payload":{"market":"0x125149c5918fc5f8c6d34682f700a898a1a19ea4f4e2ae68ff4c5794ba657074","price_changes":[{"asset_id":"86520121088881862182423437128238697252500151785248183602134095101149900014256","price":"0.13","size":"149.74","side":"BUY","hash":"32071264e141ecced98b1dd7a5be645b30d7bd74","best_bid":"0.13","best_ask":"0.14"},{"asset_id":"45936375922793925919605092352922707796689801895417366600539442410775071099958","price":"0.87","size":"149.74","side":"SELL","hash":"e06b7f3feb8743ccd688b8c1b01cca92a6eed663","best_bid":"0.86","best_ask":"0.87"}],"timestamp":"1776808416700","event_type":"price_change"}}
{"capturedAt":1776808416,"payload":{"market":"0x125149c5918fc5f8c6d34682f700a898a1a19ea4f4e2ae68ff4c5794ba657074","price_changes":[{"asset_id":"45936375922793925919605092352922707796689801895417366600539442410775071099958","price":"0.86","size":"316.43","side":"BUY","hash":"7492cf36d0ba5af9970c6495830208d72739ff01","best_bid":"0.86","best_ask":"0.87"},{"asset_id":"86520121088881862182423437128238697252500151785248183602134095101149900014256","price":"0.14","size":"316.43","side":"SELL","hash":"f9755caf62fee9060adbb10a7e47c4e3dc3cc56f","best_bid":"0.13","best_ask":"0.14"}],"timestamp":"1776808416708","event_type":"price_change"}}
{"capturedAt":1776808416,"payload":{"market":"0x125149c5918fc5f8c6d34682f700a898a1a19ea4f4e2ae68ff4c5794ba657074","price_changes":[{"asset_id":"45936375922793925919605092352922707796689801895417366600539442410775071099958","price":"0.86","size":"306.06","side":"BUY","hash":"99b7576928f9c058d1474dd8f671c66d24a6818d","best_bid":"0.86","best_ask":"0.87"},{"asset_id":"86520121088881862182423437128238697252500151785248183602134095101149900014256","price":"0.14","size":"306.06","side":"SELL","hash":"5a5f235de3117913e473abce76d45cd38c7bd7f8","best_bid":"0.13","best_ask":"0.14"}],"timestamp":"1776808416696","event_type":"price_change"}}
{"capturedAt":1776808416,"payload":{"market":"0x125149c5918fc5f8c6d34682f700a898a1a19ea4f4e2ae68ff4c5794ba657074","price_changes":[{"asset_id":"45936375922793925919605092352922707796689801895417366600539442410775071099958","price":"0.86","size":"311.43","side":"BUY","hash":"0d86e643872654fa607d962ed135f16ada1a4e58","best_bid":"0.86","best_ask":"0.87"},{"asset_id":"86520121088881862182423437128238697252500151785248183602134095101149900014256","price":"0.14","size":"311.43","side":"SELL","hash":"fcbd528904997be6b00a4d2058f472b1c5d6d53b","best_bid":"0.13","best_ask":"0.14"}],"timestamp":"1776808416707","event_type":"price_change"}}
{"capturedAt":1776808416,"payload":{"market":"0x125149c5918fc5f8c6d34682f700a898a1a19ea4f4e2ae68ff4c5794ba657074","asset_id":"45936375922793925919605092352922707796689801895417366600539442410775071099958","best_bid":"0.86","best_ask":"0.87","spread":"0.01","timestamp":"1776808416738","event_type":"best_bid_ask"}}
{"capturedAt":1776808416,"payload":{"market":"0x125149c5918fc5f8c6d34682f700a898a1a19ea4f4e2ae68ff4c5794ba657074","asset_id":"45936375922793925919605092352922707796689801895417366600539442410775071099958","price":"0.86","size":"0.65","fee_rate_bps":"1000","side":"SELL","timestamp":"1776808416717","event_type":"last_trade_price","transaction_hash":"0x2ec0e9a4773185bbdae83ef4f046581bb0ce2f51ba4f0d0e632b196faffeb1c1"}}
{"capturedAt":1776808416,"payload":{"market":"0x125149c5918fc5f8c6d34682f700a898a1a19ea4f4e2ae68ff4c5794ba657074","asset_id":"86520121088881862182423437128238697252500151785248183602134095101149900014256","best_bid":"0.13","best_ask":"0.14","spread":"0.01","timestamp":"1776808416738","event_type":"best_bid_ask"}}
{"capturedAt":1776808416,"payload":{"market":"0x125149c5918fc5f8c6d34682f700a898a1a19ea4f4e2ae68ff4c5794ba657074","price_changes":[{"asset_id":"45936375922793925919605092352922707796689801895417366600539442410775071099958","price":"0.86","size":"292.43","side":"BUY","hash":"d5ddc3fa82e2b798091dde238b9fab70de1a63d1","best_bid":"0.86","best_ask":"0.87"},{"asset_id":"86520121088881862182423437128238697252500151785248183602134095101149900014256","price":"0.14","size":"292.43","side":"SELL","hash":"74957c22a90211b387508db50c16b8c3f43d7bca","best_bid":"0.13","best_ask":"0.14"}],"timestamp":"1776808416731","event_type":"price_change"}}
{"capturedAt":1776808416,"payload":{"market":"0x125149c5918fc5f8c6d34682f700a898a1a19ea4f4e2ae68ff4c5794ba657074","asset_id":"86520121088881862182423437128238697252500151785248183602134095101149900014256","bids":[{"price":"0.01","size":"12907.69"},{"price":"0.02","size":"1746.16"},{"price":"0.03","size":"1803.83"},{"price":"0.04","size":"938.3"},{"price":"0.05","size":"590.63"},{"price":"0.06","size":"427.8"},{"price":"0.07","size":"654.3"},{"price":"0.08","size":"656.9"},{"price":"0.09","size":"202"},{"price":"0.1","size":"812.8"},{"price":"0.11","size":"391.5"},{"price":"0.12","size":"347.5"},{"price":"0.13","size":"149.74"}],"asks":[{"price":"0.99","size":"12324.83"},{"price":"0.98","size":"1715.28"},{"price":"0.97","size":"1338.69"},{"price":"0.96","size":"583.84"},{"price":"0.95","size":"1006.34"},{"price":"0.94","size":"392.8"},{"price":"0.93","size":"304.69"},{"price":"0.92","size":"278.9"},{"price":"0.91","size":"225"},{"price":"0.9","size":"282"},{"price":"0.89","size":"217.79"},{"price":"0.88","size":"215.1"},{"price":"0.87","size":"202.8"},{"price":"0.86","size":"200.9"},{"price":"0.85","size":"209.2"},{"price":"0.84","size":"197.8"},{"price":"0.83","size":"202.39"},{"price":"0.82","size":"200.4"},{"price":"0.81","size":"194.4"},{"price":"0.8","size":"193.5"},{"price":"0.79","size":"215.31"},{"price":"0.78","size":"197"},{"price":"0.77","size":"229.34"},{"price":"0.76","size":"195.7"},{"price":"0.75","size":"190.2"},{"price":"0.74","size":"189.7"},{"price":"0.73","size":"194.3"},{"price":"0.72","size":"188.89"},{"price":"0.71","size":"188.5"},{"price":"0.7","size":"206.48"},{"price":"0.69","size":"394.45"},{"price":"0.68","size":"187.5"},{"price":"0.67","size":"193.55"},{"price":"0.66","size":"187"},{"price":"0.65","size":"602.68"},{"price":"0.64","size":"186.6"},{"price":"0.63","size":"191.96"},{"price":"0.62","size":"186.3"},{"price":"0.61","size":"491.36"},{"price":"0.6","size":"226"},{"price":"0.59","size":"203.32"},{"price":"0.58","size":"185.8"},{"price":"0.57","size":"190.8"},{"price":"0.56","size":"190.6"},{"price":"0.55","size":"230.58"},{"price":"0.54","size":"185.5"},{"price":"0.53","size":"245.86"},{"price":"0.52","size":"242.56"},{"price":"0.51","size":"222.4"},{"price":"0.5","size":"378.64"},{"price":"0.49","size":"205.25"},{"price":"0.48","size":"226.77"},{"price":"0.47","size":"136.71"},{"price":"0.46","size":"185.5"},{"price":"0.45","size":"207.66"},{"price":"0.44","size":"196.6"},{"price":"0.43","size":"180.7"},{"price":"0.42","size":"180.8"},{"price":"0.41","size":"180.9"},{"price":"0.4","size":"139"},{"price":"0.39","size":"185.46"},{"price":"0.38","size":"141.3"},{"price":"0.37","size":"131.4"},{"price":"0.36","size":"131.6"},{"price":"0.35","size":"136.8"},{"price":"0.34","size":"342"},{"price":"0.33","size":"232.3"},{"price":"0.32","size":"382.5"},{"price":"0.31","size":"182.8"},{"price":"0.3","size":"244.95"},{"price":"0.29","size":"405.5"},{"price":"0.28","size":"530.89"},{"price":"0.27","size":"217.3"},{"price":"0.26","size":"187.7"},{"price":"0.25","size":"475.29"},{"price":"0.24","size":"148.49"},{"price":"0.23","size":"229.3"},{"price":"0.22","size":"318.98"},{"price":"0.21","size":"184.7"},{"price":"0.2","size":"280.25"},{"price":"0.19","size":"274.9"},{"price":"0.18","size":"325.78"},{"price":"0.17","size":"349.46"},{"price":"0.16","size":"383.63"},{"price":"0.15","size":"457.28"},{"price":"0.14","size":"297.52"}],"hash":"81f84d957a9c105a5a3de068de6c5826812c1c92","timestamp":"1776808416736","event_type":"book"}}
{"capturedAt":1776808416,"payload":{"market":"0x125149c5918fc5f8c6d34682f700a898a1a19ea4f4e2ae68ff4c5794ba657074","asset_id":"45936375922793925919605092352922707796689801895417366600539442410775071099958","bids":[{"price":"0.01","size":"12324.83"},{"price":"0.02","size":"1715.28"},{"price":"0.03","size":"1338.69"},{"price":"0.04","size":"583.84"},{"price":"0.05","size":"1006.34"},{"price":"0.06","size":"392.8"},{"price":"0.07","size":"304.69"},{"price":"0.08","size":"278.9"},{"price":"0.09","size":"225"},{"price":"0.1","size":"282"},{"price":"0.11","size":"217.79"},{"price":"0.12","size":"215.1"},{"price":"0.13","size":"202.8"},{"price":"0.14","size":"200.9"},{"price":"0.15","size":"209.2"},{"price":"0.16","size":"197.8"},{"price":"0.17","size":"202.39"},{"price":"0.18","size":"200.4"},{"price":"0.19","size":"194.4"},{"price":"0.2","size":"193.5"},{"price":"0.21","size":"215.31"},{"price":"0.22","size":"197"},{"price":"0.23","size":"229.34"},{"price":"0.24","size":"195.7"},{"price":"0.25","size":"190.2"},{"price":"0.26","size":"189.7"},{"price":"0.27","size":"194.3"},{"price":"0.28","size":"188.89"},{"price":"0.29","size":"188.5"},{"price":"0.3","size":"206.48"},{"price":"0.31","size":"394.45"},{"price":"0.32","size":"187.5"},{"price":"0.33","size":"193.55"},{"price":"0.34","size":"187"},{"price":"0.35","size":"602.68"},{"price":"0.36","size":"186.6"},{"price":"0.37","size":"191.96"},{"price":"0.38","size":"186.3"},{"price":"0.39","size":"491.36"},{"price":"0.4","size":"226"},{"price":"0.41","size":"203.32"},{"price":"0.42","size":"185.8"},{"price":"0.43","size":"190.8"},{"price":"0.44","size":"190.6"},{"price":"0.45","size":"230.58"},{"price":"0.46","size":"185.5"},{"price":"0.47","size":"245.86"},{"price":"0.48","size":"242.56"},{"price":"0.49","size":"222.4"},{"price":"0.5","size":"378.64"},{"price":"0.51","size":"205.25"},{"price":"0.52","size":"226.77"},{"price":"0.53","size":"136.71"},{"price":"0.54","size":"185.5"},{"price":"0.55","size":"207.66"},{"price":"0.56","size":"196.6"},{"price":"0.57","size":"180.7"},{"price":"0.58","size":"180.8"},{"price":"0.59","size":"180.9"},{"price":"0.6","size":"139"},{"price":"0.61","size":"185.46"},{"price":"0.62","size":"141.3"},{"price":"0.63","size":"131.4"},{"price":"0.64","size":"131.6"},{"price":"0.65","size":"136.8"},{"price":"0.66","size":"342"},{"price":"0.67","size":"232.3"},{"price":"0.68","size":"382.5"},{"price":"0.69","size":"182.8"},{"price":"0.7","size":"244.95"},{"price":"0.71","size":"405.5"},{"price":"0.72","size":"530.89"},{"price":"0.73","size":"217.3"},{"price":"0.74","size":"187.7"},{"price":"0.75","size":"475.29"},{"price":"0.76","size":"148.49"},{"price":"0.77","size":"229.3"},{"price":"0.78","size":"318.98"},{"price":"0.79","size":"184.7"},{"price":"0.8","size":"280.25"},{"price":"0.81","size":"274.9"},{"price":"0.82","size":"325.78"},{"price":"0.83","size":"349.46"},{"price":"0.84","size":"383.63"},{"price":"0.85","size":"457.28"},{"price":"0.86","size":"297.52"}],"asks":[{"price":"0.99","size":"12907.69"},{"price":"0.98","size":"1746.16"},{"price":"0.97","size":"1803.83"},{"price":"0.96","size":"938.3"},{"price":"0.95","size":"590.63"},{"price":"0.94","size":"427.8"},{"price":"0.93","size":"654.3"},{"price":"0.92","size":"656.9"},{"price":"0.91","size":"202"},{"price":"0.9","size":"812.8"},{"price":"0.89","size":"391.5"},{"price":"0.88","size":"347.5"},{"price":"0.87","size":"149.74"}],"hash":"6ca4dff8129490696b4e459197d687afe97f5c42","timestamp":"1776808416736","event_type":"book"}}
{"capturedAt":1776808416,"payload":{"market":"0x125149c5918fc5f8c6d34682f700a898a1a19ea4f4e2ae68ff4c5794ba657074","price_changes":[{"asset_id":"45936375922793925919605092352922707796689801895417366600539442410775071099958","price":"0.86","size":"284.52","side":"BUY","hash":"6ab9f4da8d7e6092a20fc110dc505ee5a47755d3","best_bid":"0.86","best_ask":"0.87"},{"asset_id":"86520121088881862182423437128238697252500151785248183602134095101149900014256","price":"0.14","size":"284.52","side":"SELL","hash":"6049404681900316e0fd3ef163cb0f1eb65d4326","best_bid":"0.13","best_ask":"0.14"}],"timestamp":"1776808416739","event_type":"price_change"}}
{"capturedAt":1776808416,"payload":{"market":"0x125149c5918fc5f8c6d34682f700a898a1a19ea4f4e2ae68ff4c5794ba657074","price_changes":[{"asset_id":"45936375922793925919605092352922707796689801895417366600539442410775071099958","price":"0.86","size":"297.52","side":"BUY","hash":"6ca4dff8129490696b4e459197d687afe97f5c42","best_bid":"0.86","best_ask":"0.87"},{"asset_id":"86520121088881862182423437128238697252500151785248183602134095101149900014256","price":"0.14","size":"297.52","side":"SELL","hash":"81f84d957a9c105a5a3de068de6c5826812c1c92","best_bid":"0.13","best_ask":"0.14"}],"timestamp":"1776808416736","event_type":"price_change"}}
{"capturedAt":1776808416,"payload":{"market":"0x125149c5918fc5f8c6d34682f700a898a1a19ea4f4e2ae68ff4c5794ba657074","price_changes":[{"asset_id":"45936375922793925919605092352922707796689801895417366600539442410775071099958","price":"0.01","size":"12329.83","side":"BUY","hash":"e591699b18f37e3e3ca4bddd0fa69842363f1400","best_bid":"0.86","best_ask":"0.87"},{"asset_id":"86520121088881862182423437128238697252500151785248183602134095101149900014256","price":"0.99","size":"12329.83","side":"SELL","hash":"38f9edf06e0429e5e4297f661b9b7f3c34cf6224","best_bid":"0.13","best_ask":"0.14"}],"timestamp":"1776808416738","event_type":"price_change"}}
{"capturedAt":1776808416,"payload":{"market":"0x125149c5918fc5f8c6d34682f700a898a1a19ea4f4e2ae68ff4c5794ba657074","price_changes":[{"asset_id":"45936375922793925919605092352922707796689801895417366600539442410775071099958","price":"0.86","size":"297.89","side":"BUY","hash":"eedd12c1261703d23015f0bf9d0f8d7e14ed4309","best_bid":"0.86","best_ask":"0.87"},{"asset_id":"86520121088881862182423437128238697252500151785248183602134095101149900014256","price":"0.14","size":"297.89","side":"SELL","hash":"92af85c24d6336df1017bca6e994bba435cb60de","best_bid":"0.13","best_ask":"0.14"}],"timestamp":"1776808416733","event_type":"price_change"}}
{"capturedAt":1776808416,"payload":{"market":"0x125149c5918fc5f8c6d34682f700a898a1a19ea4f4e2ae68ff4c5794ba657074","price_changes":[{"asset_id":"45936375922793925919605092352922707796689801895417366600539442410775071099958","price":"0.86","size":"272.52","side":"BUY","hash":"16a5629ebf36308e5ff582ec17cbb980544f3445","best_bid":"0.86","best_ask":"0.87"},{"asset_id":"86520121088881862182423437128238697252500151785248183602134095101149900014256","price":"0.14","size":"272.52","side":"SELL","hash":"bee45574c3e67fca5e48a64956e479a9be05127f","best_bid":"0.13","best_ask":"0.14"}],"timestamp":"1776808416741","event_type":"price_change"}}
{"capturedAt":1776808416,"payload":{"market":"0x125149c5918fc5f8c6d34682f700a898a1a19ea4f4e2ae68ff4c5794ba657074","price_changes":[{"asset_id":"45936375922793925919605092352922707796689801895417366600539442410775071099958","price":"0.82","size":"355.78","side":"BUY","hash":"ff11b343cb59c3346b3ae75e86cf3a55cad89114","best_bid":"0.86","best_ask":"0.87"},{"asset_id":"86520121088881862182423437128238697252500151785248183602134095101149900014256","price":"0.18","size":"355.78","side":"SELL","hash":"70716d38f4b22a245ca723f083e50209fea77be2","best_bid":"0.13","best_ask":"0.14"}],"timestamp":"1776808416742","event_type":"price_change"}}
{"capturedAt":1776808416,"payload":{"market":"0x125149c5918fc5f8c6d34682f700a898a1a19ea4f4e2ae68ff4c5794ba657074","price_changes":[{"asset_id":"45936375922793925919605092352922707796689801895417366600539442410775071099958","price":"0.86","size":"267.15","side":"BUY","hash":"d2099398f3f630e9f67eb4ee96e2985ba0b5d3b0","best_bid":"0.86","best_ask":"0.87"},{"asset_id":"86520121088881862182423437128238697252500151785248183602134095101149900014256","price":"0.14","size":"267.15","side":"SELL","hash":"27d5e32f6f9461b6dbe913d4b24a251b304fc43f","best_bid":"0.13","best_ask":"0.14"}],"timestamp":"1776808416743","event_type":"price_change"}}
{"capturedAt":1776808416,"payload":{"market":"0x125149c5918fc5f8c6d34682f700a898a1a19ea4f4e2ae68ff4c5794ba657074","price_changes":[{"asset_id":"45936375922793925919605092352922707796689801895417366600539442410775071099958","price":"0.86","size":"255.15","side":"BUY","hash":"56669639c55751e4c859816dbac3b77fd99c092f","best_bid":"0.86","best_ask":"0.87"},{"asset_id":"86520121088881862182423437128238697252500151785248183602134095101149900014256","price":"0.14","size":"255.15","side":"SELL","hash":"4ed5a4c4fde722fd9823ede2b357af898710432e","best_bid":"0.13","best_ask":"0.14"}],"timestamp":"1776808416744","event_type":"price_change"}}
{"capturedAt":1776808416,"payload":{"market":"0x125149c5918fc5f8c6d34682f700a898a1a19ea4f4e2ae68ff4c5794ba657074","price_changes":[{"asset_id":"45936375922793925919605092352922707796689801895417366600539442410775071099958","price":"0.86","size":"247.15","side":"BUY","hash":"7f9a93cd1ced5e72318e50ef795ba7ebf73b0c6d","best_bid":"0.86","best_ask":"0.87"},{"asset_id":"86520121088881862182423437128238697252500151785248183602134095101149900014256","price":"0.14","size":"247.15","side":"SELL","hash":"62a716aca5410fecf13266e26ad27886e4edb1ff","best_bid":"0.13","best_ask":"0.14"}],"timestamp":"1776808416745","event_type":"price_change"}}
{"capturedAt":1776808416,"payload":{"market":"0x125149c5918fc5f8c6d34682f700a898a1a19ea4f4e2ae68ff4c5794ba657074","price_changes":[{"asset_id":"45936375922793925919605092352922707796689801895417366600539442410775071099958","price":"0.86","size":"235.15","side":"BUY","hash":"245a05dc9b5ce5cf02c657e077a6b29f9a348e70","best_bid":"0.86","best_ask":"0.87"},{"asset_id":"86520121088881862182423437128238697252500151785248183602134095101149900014256","price":"0.14","size":"235.15","side":"SELL","hash":"17c8af8f035b309c4977059636f4b1ffe42fb40f","best_bid":"0.13","best_ask":"0.14"}],"timestamp":"1776808416746","event_type":"price_change"}}
{"capturedAt":1776808416,"payload":{"market":"0x125149c5918fc5f8c6d34682f700a898a1a19ea4f4e2ae68ff4c5794ba657074","price_changes":[{"asset_id":"45936375922793925919605092352922707796689801895417366600539442410775071099958","price":"0.86","size":"227.15","side":"BUY","hash":"39df268c52d36ea6ebf85d05764662248ece4f16","best_bid":"0.86","best_ask":"0.87"},{"asset_id":"86520121088881862182423437128238697252500151785248183602134095101149900014256","price":"0.14","size":"227.15","side":"SELL","hash":"92e91265a939b8d43a1b90194bbe22591e35e68f","best_bid":"0.13","best_ask":"0.14"}],"timestamp":"1776808416747","event_type":"price_change"}}
{"capturedAt":1776808416,"payload":{"market":"0x125149c5918fc5f8c6d34682f700a898a1a19ea4f4e2ae68ff4c5794ba657074","price_changes":[{"asset_id":"45936375922793925919605092352922707796689801895417366600539442410775071099958","price":"0.86","size":"214.15","side":"BUY","hash":"d125b91b335f210e4647d0e202d11a40701fbcc8","best_bid":"0.86","best_ask":"0.87"},{"asset_id":"86520121088881862182423437128238697252500151785248183602134095101149900014256","price":"0.14","size":"214.15","side":"SELL","hash":"839722a7a658476cb7c85d5b9be11ecc921def8d","best_bid":"0.13","best_ask":"0.14"}],"timestamp":"1776808416748","event_type":"price_change"}}
{"capturedAt":1776808416,"payload":{"market":"0x125149c5918fc5f8c6d34682f700a898a1a19ea4f4e2ae68ff4c5794ba657074","price_changes":[{"asset_id":"45936375922793925919605092352922707796689801895417366600539442410775071099958","price":"0.86","size":"204.15","side":"BUY","hash":"e3bcb062bf813747dd6d98a540b36e9a30e27de8","best_bid":"0.86","best_ask":"0.87"},{"asset_id":"86520121088881862182423437128238697252500151785248183602134095101149900014256","price":"0.14","size":"204.15","side":"SELL","hash":"b5cfe0866e10cd558936172c8367949a9bc07520","best_bid":"0.13","best_ask":"0.14"}],"timestamp":"1776808416749","event_type":"price_change"}}
{"capturedAt":1776808416,"payload":{"market":"0x125149c5918fc5f8c6d34682f700a898a1a19ea4f4e2ae68ff4c5794ba657074","price_changes":[{"asset_id":"86520121088881862182423437128238697252500151785248183602134095101149900014256","price":"0.12","size":"352.5","side":"BUY","hash":"5e062996df2c0ebb17b11fb2903022d19a5c7d44","best_bid":"0.13","best_ask":"0.14"},{"asset_id":"45936375922793925919605092352922707796689801895417366600539442410775071099958","price":"0.88","size":"352.5","side":"SELL","hash":"7c8365a8e6651c4f7ccebc13fedbcd8c95bd05d4","best_bid":"0.86","best_ask":"0.87"}],"timestamp":"1776808416751","event_type":"price_change"}}
{"capturedAt":1776808416,"payload":{"market":"0x125149c5918fc5f8c6d34682f700a898a1a19ea4f4e2ae68ff4c5794ba657074","price_changes":[{"asset_id":"45936375922793925919605092352922707796689801895417366600539442410775071099958","price":"0.01","size":"12334.84","side":"BUY","hash":"b2e8da51bda7b4132f2d68269e367ab1a8833052","best_bid":"0.86","best_ask":"0.87"},{"asset_id":"86520121088881862182423437128238697252500151785248183602134095101149900014256","price":"0.99","size":"12334.84","side":"SELL","hash":"32f69fddc3640a0991ca0c9f67912f6e80e946cf","best_bid":"0.13","best_ask":"0.14"}],"timestamp":"1776808416750","event_type":"price_change"}}
{"capturedAt":1776808416,"payload":{"market":"0x125149c5918fc5f8c6d34682f700a898a1a19ea4f4e2ae68ff4c5794ba657074","price_changes":[{"asset_id":"45936375922793925919605092352922707796689801895417366600539442410775071099958","price":"0.86","size":"191.15","side":"BUY","hash":"b824d020f8166d519f29ec091d320162277a3c56","best_bid":"0.86","best_ask":"0.87"},{"asset_id":"86520121088881862182423437128238697252500151785248183602134095101149900014256","price":"0.14","size":"191.15","side":"SELL","hash":"38108327855c2b4fc4926ead9d2778297b828641","best_bid":"0.13","best_ask":"0.14"}],"timestamp":"1776808416754","event_type":"price_change"}}
{"capturedAt":1776808416,"payload":{"market":"0x125149c5918fc5f8c6d34682f700a898a1a19ea4f4e2ae68ff4c5794ba657074","price_changes":[{"asset_id":"45936375922793925919605092352922707796689801895417366600539442410775071099958","price":"0.01","size":"12339.84","side":"BUY","hash":"d0e37c724ca0ccde89da815ecd279cd0bf3c59e8","best_bid":"0.86","best_ask":"0.87"},{"asset_id":"86520121088881862182423437128238697252500151785248183602134095101149900014256","price":"0.99","size":"12339.84","side":"SELL","hash":"1b2d7a5ea390e332677a07c686edb2e7fbe14167","best_bid":"0.13","best_ask":"0.14"}],"timestamp":"1776808416752","event_type":"price_change"}}
{"capturedAt":1776808416,"payload":{"market":"0x125149c5918fc5f8c6d34682f700a898a1a19ea4f4e2ae68ff4c5794ba657074","price_changes":[{"asset_id":"45936375922793925919605092352922707796689801895417366600539442410775071099958","price":"0.86","size":"196.22","side":"BUY","hash":"751f9e3bacd4f0e1be904b17264ba6dea5527294","best_bid":"0.86","best_ask":"0.87"},{"asset_id":"86520121088881862182423437128238697252500151785248183602134095101149900014256","price":"0.14","size":"196.22","side":"SELL","hash":"05b6cbcd9d55915733a64463177c83a491d38664","best_bid":"0.13","best_ask":"0.14"}],"timestamp":"1776808416755","event_type":"price_change"}}
{"capturedAt":1776808416,"payload":{"market":"0x125149c5918fc5f8c6d34682f700a898a1a19ea4f4e2ae68ff4c5794ba657074","price_changes":[{"asset_id":"45936375922793925919605092352922707796689801895417366600539442410775071099958","price":"0.86","size":"201.43","side":"BUY","hash":"020b1d21506fe7d5dbac2bb72a179f36b5af64d8","best_bid":"0.86","best_ask":"0.87"},{"asset_id":"86520121088881862182423437128238697252500151785248183602134095101149900014256","price":"0.14","size":"201.43","side":"SELL","hash":"6d806ed25fd8f9bb043c5037c520406d5113e6a0","best_bid":"0.13","best_ask":"0.14"}],"timestamp":"1776808416757","event_type":"price_change"}}
{"capturedAt":1776808416,"payload":{"market":"0x125149c5918fc5f8c6d34682f700a898a1a19ea4f4e2ae68ff4c5794ba657074","price_changes":[{"asset_id":"45936375922793925919605092352922707796689801895417366600539442410775071099958","price":"0.86","size":"189.43","side":"BUY","hash":"063c890054f2a214a4821cb0ee61415264e431a9","best_bid":"0.86","best_ask":"0.87"},{"asset_id":"86520121088881862182423437128238697252500151785248183602134095101149900014256","price":"0.14","size":"189.43","side":"SELL","hash":"8745d7ae7ab5c2b2a3d11bcaae283d6ceb480cf5","best_bid":"0.13","best_ask":"0.14"}],"timestamp":"1776808416758","event_type":"price_change"}}
{"capturedAt":1776808416,"payload":{"market":"0x125149c5918fc5f8c6d34682f700a898a1a19ea4f4e2ae68ff4c5794ba657074","price_changes":[{"asset_id":"45936375922793925919605092352922707796689801895417366600539442410775071099958","price":"0.86","size":"177.43","side":"BUY","hash":"e32b50c048a7a712ad16011bd576783dee5bbd5a","best_bid":"0.86","best_ask":"0.87"},{"asset_id":"86520121088881862182423437128238697252500151785248183602134095101149900014256","price":"0.14","size":"177.43","side":"SELL","hash":"651704864d1c0904ad13111e1cf4dca8105aa293","best_bid":"0.13","best_ask":"0.14"}],"timestamp":"1776808416759","event_type":"price_change"}}
{"capturedAt":1776808416,"payload":{"market":"0x125149c5918fc5f8c6d34682f700a898a1a19ea4f4e2ae68ff4c5794ba657074","asset_id":"45936375922793925919605092352922707796689801895417366600539442410775071099958","price":"0.86","size":"0.37","fee_rate_bps":"1000","side":"SELL","timestamp":"1776808416757","event_type":"last_trade_price","transaction_hash":"0x5b02b239c6001fd76b5a7fd76f369a76b8d1f7219a9af44b4fa4f5279a7b1b36"}}
{"capturedAt":1776808416,"payload":{"market":"0x125149c5918fc5f8c6d34682f700a898a1a19ea4f4e2ae68ff4c5794ba657074","price_changes":[{"asset_id":"45936375922793925919605092352922707796689801895417366600539442410775071099958","price":"0.01","size":"12334.84","side":"BUY","hash":"9ca75ae0d1cc442e677837c72982356483035af9","best_bid":"0.86","best_ask":"0.87"},{"asset_id":"86520121088881862182423437128238697252500151785248183602134095101149900014256","price":"0.99","size":"12334.84","side":"SELL","hash":"c18906575b0e5d2e62907e0c04b4873eb671b61c","best_bid":"0.13","best_ask":"0.14"}],"timestamp":"1776808416760","event_type":"price_change"}}
{"capturedAt":1776808416,"payload":{"market":"0x125149c5918fc5f8c6d34682f700a898a1a19ea4f4e2ae68ff4c5794ba657074","price_changes":[{"asset_id":"45936375922793925919605092352922707796689801895417366600539442410775071099958","price":"0.86","size":"167.43","side":"BUY","hash":"a115ecbf90236b0f655120771ba3e5428696e4af","best_bid":"0.86","best_ask":"0.87"},{"asset_id":"86520121088881862182423437128238697252500151785248183602134095101149900014256","price":"0.14","size":"167.43","side":"SELL","hash":"be76bf6cddadd39585b5836777f429db9c99f161","best_bid":"0.13","best_ask":"0.14"}],"timestamp":"1776808416762","event_type":"price_change"}}
{"capturedAt":1776808416,"payload":{"market":"0x125149c5918fc5f8c6d34682f700a898a1a19ea4f4e2ae68ff4c5794ba657074","price_changes":[{"asset_id":"45936375922793925919605092352922707796689801895417366600539442410775071099958","price":"0.86","size":"157.43","side":"BUY","hash":"b25a2a75ecb8d7f6fe4958d59eaf988abb6153ee","best_bid":"0.86","best_ask":"0.87"},{"asset_id":"86520121088881862182423437128238697252500151785248183602134095101149900014256","price":"0.14","size":"157.43","side":"SELL","hash":"bb976ee45b65af458b2051af1289dde348de449b","best_bid":"0.13","best_ask":"0.14"}],"timestamp":"1776808416763","event_type":"price_change"}}
{"capturedAt":1776808416,"payload":{"market":"0x125149c5918fc5f8c6d34682f700a898a1a19ea4f4e2ae68ff4c5794ba657074","price_changes":[{"asset_id":"45936375922793925919605092352922707796689801895417366600539442410775071099958","price":"0.86","size":"151.97","side":"BUY","hash":"5e4ca7ee7eef75ef154d722aa5d959ef6836938c","best_bid":"0.86","best_ask":"0.87"},{"asset_id":"86520121088881862182423437128238697252500151785248183602134095101149900014256","price":"0.14","size":"151.97","side":"SELL","hash":"a347c122a2423c15375ff08fd0addaa5d626ac59","best_bid":"0.13","best_ask":"0.14"}],"timestamp":"1776808416764","event_type":"price_change"}}
{"capturedAt":1776808416,"payload":{"market":"0x125149c5918fc5f8c6d34682f700a898a1a19ea4f4e2ae68ff4c5794ba657074","price_changes":[{"asset_id":"45936375922793925919605092352922707796689801895417366600539442410775071099958","price":"0.86","size":"156.97","side":"BUY","hash":"4c23866d96867b669cd15ab7ad9627bb8b27eb75","best_bid":"0.86","best_ask":"0.87"},{"asset_id":"86520121088881862182423437128238697252500151785248183602134095101149900014256","price":"0.14","size":"156.97","side":"SELL","hash":"b57551967fe926757ed28a4c140aad2ee9dfaac9","best_bid":"0.13","best_ask":"0.14"}],"timestamp":"1776808416765","event_type":"price_change"}}
{"capturedAt":1776808416,"payload":{"market":"0x125149c5918fc5f8c6d34682f700a898a1a19ea4f4e2ae68ff4c5794ba657074","price_changes":[{"asset_id":"45936375922793925919605092352922707796689801895417366600539442410775071099958","price":"0.01","size":"12339.84","side":"BUY","hash":"81bc3f1dd4714a43bc550583a2000ecbe34cea81","best_bid":"0.86","best_ask":"0.87"},{"asset_id":"86520121088881862182423437128238697252500151785248183602134095101149900014256","price":"0.99","size":"12339.84","side":"SELL","hash":"f0b780c7aed48f5325ef363e5c8a8e52b7b77d3b","best_bid":"0.13","best_ask":"0.14"}],"timestamp":"1776808416767","event_type":"price_change"}}
{"capturedAt":1776808416,"payload":{"market":"0x125149c5918fc5f8c6d34682f700a898a1a19ea4f4e2ae68ff4c5794ba657074","price_changes":[{"asset_id":"86520121088881862182423437128238697252500151785248183602134095101149900014256","price":"0.13","size":"154.74","side":"BUY","hash":"f6a0eaef3e6926b01885e2e38bd60800d4e55b78","best_bid":"0.13","best_ask":"0.14"},{"asset_id":"45936375922793925919605092352922707796689801895417366600539442410775071099958","price":"0.87","size":"154.74","side":"SELL","hash":"9596d9724d7cfd97d3ed2f6c7d78d5a625bef3f5","best_bid":"0.86","best_ask":"0.87"}],"timestamp":"1776808416768","event_type":"price_change"}}
{"capturedAt":1776808416,"payload":{"market":"0x125149c5918fc5f8c6d34682f700a898a1a19ea4f4e2ae68ff4c5794ba657074","price_changes":[{"asset_id":"86520121088881862182423437128238697252500151785248183602134095101149900014256","price":"0.13","size":"159.74","side":"BUY","hash":"47615838976cf05b12aa9bbf2bf0e8910139563a","best_bid":"0.13","best_ask":"0.14"},{"asset_id":"45936375922793925919605092352922707796689801895417366600539442410775071099958","price":"0.87","size":"159.74","side":"SELL","hash":"e4869df782d8bbefa4bd98478fe13979d7980213","best_bid":"0.86","best_ask":"0.87"}],"timestamp":"1776808416769","event_type":"price_change"}}
{"capturedAt":1776808416,"payload":{"market":"0x125149c5918fc5f8c6d34682f700a898a1a19ea4f4e2ae68ff4c5794ba657074","price_changes":[{"asset_id":"45936375922793925919605092352922707796689801895417366600539442410775071099958","price":"0.86","size":"161.97","side":"BUY","hash":"24bcd5802f3adba720062c228af955df537b9202","best_bid":"0.86","best_ask":"0.87"},{"asset_id":"86520121088881862182423437128238697252500151785248183602134095101149900014256","price":"0.14","size":"161.97","side":"SELL","hash":"afefa724e97eb2bb4508da5953683d7a8629a2f3","best_bid":"0.13","best_ask":"0.14"}],"timestamp":"1776808416770","event_type":"price_change"}}
{"capturedAt":1776808416,"payload":{"market":"0x125149c5918fc5f8c6d34682f700a898a1a19ea4f4e2ae68ff4c5794ba657074","price_changes":[{"asset_id":"86520121088881862182423437128238697252500151785248183602134095101149900014256","price":"0.13","size":"164.74","side":"BUY","hash":"39f2ac9df39641cb622eee75022194cc4dbecca2","best_bid":"0.13","best_ask":"0.14"},{"asset_id":"45936375922793925919605092352922707796689801895417366600539442410775071099958","price":"0.87","size":"164.74","side":"SELL","hash":"1aef2a71081115d64e2e04c374e4f627ffcd34af","best_bid":"0.86","best_ask":"0.87"}],"timestamp":"1776808416772","event_type":"price_change"}}
{"capturedAt":1776808416,"payload":{"market":"0x125149c5918fc5f8c6d34682f700a898a1a19ea4f4e2ae68ff4c5794ba657074","price_changes":[{"asset_id":"45936375922793925919605092352922707796689801895417366600539442410775071099958","price":"0.86","size":"166.97","side":"BUY","hash":"b38d3890a3eea6d3e03027e5eb53390e6434daf6","best_bid":"0.86","best_ask":"0.87"},{"asset_id":"86520121088881862182423437128238697252500151785248183602134095101149900014256","price":"0.14","size":"166.97","side":"SELL","hash":"ef94aee411b1fb128aa656056b975c143b5a5166","best_bid":"0.13","best_ask":"0.14"}],"timestamp":"1776808416772","event_type":"price_change"}}
{"capturedAt":1776808416,"payload":{"market":"0x125149c5918fc5f8c6d34682f700a898a1a19ea4f4e2ae68ff4c5794ba657074","price_changes":[{"asset_id":"86520121088881862182423437128238697252500151785248183602134095101149900014256","price":"0.13","size":"169.74","side":"BUY","hash":"5560e71930fea9dd2575982221cfa65f3f1f3732","best_bid":"0.13","best_ask":"0.14"},{"asset_id":"45936375922793925919605092352922707796689801895417366600539442410775071099958","price":"0.87","size":"169.74","side":"SELL","hash":"9ed03fe2c4afd9f806b954c3f03e918eeb0c3341","best_bid":"0.86","best_ask":"0.87"}],"timestamp":"1776808416773","event_type":"price_change"}}
{"capturedAt":1776808416,"payload":{"market":"0x125149c5918fc5f8c6d34682f700a898a1a19ea4f4e2ae68ff4c5794ba657074","price_changes":[{"asset_id":"45936375922793925919605092352922707796689801895417366600539442410775071099958","price":"0.01","size":"12334.84","side":"BUY","hash":"43a488ca7318fde5b57c9065572083c475fb8a7b","best_bid":"0.86","best_ask":"0.87"},{"asset_id":"86520121088881862182423437128238697252500151785248183602134095101149900014256","price":"0.99","size":"12334.84","side":"SELL","hash":"a7c3892339de524a4454b1a43870b89a28b2e2df","best_bid":"0.13","best_ask":"0.14"}],"timestamp":"1776808416774","event_type":"price_change"}}
{"capturedAt":1776808416,"payload":{"market":"0x125149c5918fc5f8c6d34682f700a898a1a19ea4f4e2ae68ff4c5794ba657074","price_changes":[{"asset_id":"45936375922793925919605092352922707796689801895417366600539442410775071099958","price":"0.86","size":"171.97","side":"BUY","hash":"6a395c9943cd9177845faafd701620534aa64365","best_bid":"0.86","best_ask":"0.87"},{"asset_id":"86520121088881862182423437128238697252500151785248183602134095101149900014256","price":"0.14","size":"171.97","side":"SELL","hash":"c22c86c9ca6a45d5f5dc3b31492a8ce71a4e29b4","best_bid":"0.13","best_ask":"0.14"}],"timestamp":"1776808416775","event_type":"price_change"}}
{"capturedAt":1776808416,"payload":{"market":"0x125149c5918fc5f8c6d34682f700a898a1a19ea4f4e2ae68ff4c5794ba657074","price_changes":[{"asset_id":"45936375922793925919605092352922707796689801895417366600539442410775071099958","price":"0.01","size":"12339.85","side":"BUY","hash":"5e2e1659bf7b41dfbf1158ea31222b575b6e1df9","best_bid":"0.86","best_ask":"0.87"},{"asset_id":"86520121088881862182423437128238697252500151785248183602134095101149900014256","price":"0.99","size":"12339.85","side":"SELL","hash":"ef7eca36670a2ae22800a969cbeca780fe46a4cf","best_bid":"0.13","best_ask":"0.14"}],"timestamp":"1776808416776","event_type":"price_change"}}
{"capturedAt":1776808416,"payload":{"market":"0x125149c5918fc5f8c6d34682f700a898a1a19ea4f4e2ae68ff4c5794ba657074","price_changes":[{"asset_id":"86520121088881862182423437128238697252500151785248183602134095101149900014256","price":"0.13","size":"174.74","side":"BUY","hash":"4c98f5cbbbca19beec58924a5744b3a5adce6cca","best_bid":"0.13","best_ask":"0.14"},{"asset_id":"45936375922793925919605092352922707796689801895417366600539442410775071099958","price":"0.87","size":"174.74","side":"SELL","hash":"0cdf9eb05eebb45a1919ff3f27c72f8d8c2d2386","best_bid":"0.86","best_ask":"0.87"}],"timestamp":"1776808416778","event_type":"price_change"}}
{"capturedAt":1776808416,"payload":{"market":"0x125149c5918fc5f8c6d34682f700a898a1a19ea4f4e2ae68ff4c5794ba657074","price_changes":[{"asset_id":"45936375922793925919605092352922707796689801895417366600539442410775071099958","price":"0.01","size":"12334.84","side":"BUY","hash":"b8285a1cc9729bc2b2c11641f21000ed749b2ed8","best_bid":"0.86","best_ask":"0.87"},{"asset_id":"86520121088881862182423437128238697252500151785248183602134095101149900014256","price":"0.99","size":"12334.84","side":"SELL","hash":"109a50a4b41601cc55723e8d50e8cdad7cc3602a","best_bid":"0.13","best_ask":"0.14"}],"timestamp":"1776808416778","event_type":"price_change"}}
{"capturedAt":1776808416,"payload":{"market":"0x125149c5918fc5f8c6d34682f700a898a1a19ea4f4e2ae68ff4c5794ba657074","price_changes":[{"asset_id":"45936375922793925919605092352922707796689801895417366600539442410775071099958","price":"0.86","size":"176.97","side":"BUY","hash":"235a6177283335fc9a81a3b0263aebde44271d49","best_bid":"0.86","best_ask":"0.87"},{"asset_id":"86520121088881862182423437128238697252500151785248183602134095101149900014256","price":"0.14","size":"176.97","side":"SELL","hash":"19a7f8f361af8033a5b3b287bf8fb6373c43c368","best_bid":"0.13","best_ask":"0.14"}],"timestamp":"1776808416780","event_type":"price_change"}}
{"capturedAt":1776808416,"payload":{"market":"0x125149c5918fc5f8c6d34682f700a898a1a19ea4f4e2ae68ff4c5794ba657074","price_changes":[{"asset_id":"45936375922793925919605092352922707796689801895417366600539442410775071099958","price":"0.86","size":"181.76","side":"BUY","hash":"5ccc5e941f9b6df7e3db4a66a26a8d70e773a499","best_bid":"0.86","best_ask":"0.87"},{"asset_id":"86520121088881862182423437128238697252500151785248183602134095101149900014256","price":"0.14","size":"181.76","side":"SELL","hash":"c3ae9be9ea4946d14fc9561fb0b5b72c913d7927","best_bid":"0.13","best_ask":"0.14"}],"timestamp":"1776808416782","event_type":"price_change"}}
{"capturedAt":1776808416,"payload":{"market":"0x125149c5918fc5f8c6d34682f700a898a1a19ea4f4e2ae68ff4c5794ba657074","price_changes":[{"asset_id":"86520121088881862182423437128238697252500151785248183602134095101149900014256","price":"0.13","size":"179.74","side":"BUY","hash":"8ef2195f480240908b774720968514c13eefd1b1","best_bid":"0.13","best_ask":"0.14"},{"asset_id":"45936375922793925919605092352922707796689801895417366600539442410775071099958","price":"0.87","size":"179.74","side":"SELL","hash":"2ee06104453e1ee14e63d956d9367c0f0a1e4c4e","best_bid":"0.86","best_ask":"0.87"}],"timestamp":"1776808416783","event_type":"price_change"}}
{"capturedAt":1776808416,"payload":{"market":"0x125149c5918fc5f8c6d34682f700a898a1a19ea4f4e2ae68ff4c5794ba657074","price_changes":[{"asset_id":"45936375922793925919605092352922707796689801895417366600539442410775071099958","price":"0.86","size":"171.76","side":"BUY","hash":"a1317f8467e3f766e7424c1957af7ee6d76f2ca6","best_bid":"0.86","best_ask":"0.87"},{"asset_id":"86520121088881862182423437128238697252500151785248183602134095101149900014256","price":"0.14","size":"171.76","side":"SELL","hash":"5677f8bd7fe768e8ce61ccfeef730875962b74d2","best_bid":"0.13","best_ask":"0.14"}],"timestamp":"1776808416780","event_type":"price_change"}}
{"capturedAt":1776808416,"payload":{"market":"0x125149c5918fc5f8c6d34682f700a898a1a19ea4f4e2ae68ff4c5794ba657074","price_changes":[{"asset_id":"45936375922793925919605092352922707796689801895417366600539442410775071099958","price":"0.86","size":"186.76","side":"BUY","hash":"14a9e9803a797c9465d42dd91f40a895c0d5073c","best_bid":"0.86","best_ask":"0.87"},{"asset_id":"86520121088881862182423437128238697252500151785248183602134095101149900014256","price":"0.14","size":"186.76","side":"SELL","hash":"48c4edc537bec2ac38fc9cfc887e309e66803b8c","best_bid":"0.13","best_ask":"0.14"}],"timestamp":"1776808416784","event_type":"price_change"}}
{"capturedAt":1776808416,"payload":{"market":"0x125149c5918fc5f8c6d34682f700a898a1a19ea4f4e2ae68ff4c5794ba657074","price_changes":[{"asset_id":"45936375922793925919605092352922707796689801895417366600539442410775071099958","price":"0.86","size":"181.69","side":"BUY","hash":"8475c654b3edccbb89818f1a2c14d35aa527567e","best_bid":"0.86","best_ask":"0.87"},{"asset_id":"86520121088881862182423437128238697252500151785248183602134095101149900014256","price":"0.14","size":"181.69","side":"SELL","hash":"b566ee08a0c7e346d8bfb30a9dda7a04601312ce","best_bid":"0.13","best_ask":"0.14"}],"timestamp":"1776808416785","event_type":"price_change"}}
{"capturedAt":1776808416,"payload":{"market":"0x125149c5918fc5f8c6d34682f700a898a1a19ea4f4e2ae68ff4c5794ba657074","price_changes":[{"asset_id":"86520121088881862182423437128238697252500151785248183602134095101149900014256","price":"0.13","size":"184.74","side":"BUY","hash":"db75a8388655a37ea69e4c3a1dd6559b763f507f","best_bid":"0.13","best_ask":"0.14"},{"asset_id":"45936375922793925919605092352922707796689801895417366600539442410775071099958","price":"0.87","size":"184.74","side":"SELL","hash":"516d54936b4aec42945802ae4d6d669df6be12f7","best_bid":"0.86","best_ask":"0.87"}],"timestamp":"1776808416787","event_type":"price_change"}}
{"capturedAt":1776808416,"payload":{"market":"0x125149c5918fc5f8c6d34682f700a898a1a19ea4f4e2ae68ff4c5794ba657074","price_changes":[{"asset_id":"86520121088881862182423437128238697252500151785248183602134095101149900014256","price":"0.13","size":"189.74","side":"BUY","hash":"fb5c0e46946482b4cb86c7eb97aa3b93f3875a5e","best_bid":"0.13","best_ask":"0.14"},{"asset_id":"45936375922793925919605092352922707796689801895417366600539442410775071099958","price":"0.87","size":"189.74","side":"SELL","hash":"2cf7c720dd5efce56762166fe4b250db56613eb6","best_bid":"0.86","best_ask":"0.87"}],"timestamp":"1776808416788","event_type":"price_change"}}
{"capturedAt":1776808416,"payload":{"market":"0x125149c5918fc5f8c6d34682f700a898a1a19ea4f4e2ae68ff4c5794ba657074","price_changes":[{"asset_id":"45936375922793925919605092352922707796689801895417366600539442410775071099958","price":"0.86","size":"186.69","side":"BUY","hash":"f56d166a2590922b92b1a8f3ca540edae257cdc6","best_bid":"0.86","best_ask":"0.87"},{"asset_id":"86520121088881862182423437128238697252500151785248183602134095101149900014256","price":"0.14","size":"186.69","side":"SELL","hash":"3ece7b024b854544f754053ffe3dc7ad4f6ee707","best_bid":"0.13","best_ask":"0.14"}],"timestamp":"1776808416789","event_type":"price_change"}}
{"capturedAt":1776808416,"payload":{"market":"0x125149c5918fc5f8c6d34682f700a898a1a19ea4f4e2ae68ff4c5794ba657074","price_changes":[{"asset_id":"86520121088881862182423437128238697252500151785248183602134095101149900014256","price":"0.13","size":"194.74","side":"BUY","hash":"3117c27194a0739426798cc906c31a04c2c59d1b","best_bid":"0.13","best_ask":"0.14"},{"asset_id":"45936375922793925919605092352922707796689801895417366600539442410775071099958","price":"0.87","size":"194.74","side":"SELL","hash":"6071547fae956aa8aeff28d26eac90abcee1d9c0","best_bid":"0.86","best_ask":"0.87"}],"timestamp":"1776808416789","event_type":"price_change"}}
{"capturedAt":1776808416,"payload":{"market":"0x125149c5918fc5f8c6d34682f700a898a1a19ea4f4e2ae68ff4c5794ba657074","price_changes":[{"asset_id":"45936375922793925919605092352922707796689801895417366600539442410775071099958","price":"0.01","size":"12329.84","side":"BUY","hash":"8ff47c5dd294411b27176ac51ca6528d3d153e98","best_bid":"0.86","best_ask":"0.87"},{"asset_id":"86520121088881862182423437128238697252500151785248183602134095101149900014256","price":"0.99","size":"12329.84","side":"SELL","hash":"db0ed6a194be13be8099ffbb800e990c783b5276","best_bid":"0.13","best_ask":"0.14"}],"timestamp":"1776808416790","event_type":"price_change"}}
{"capturedAt":1776808416,"payload":{"market":"0x125149c5918fc5f8c6d34682f700a898a1a19ea4f4e2ae68ff4c5794ba657074","price_changes":[{"asset_id":"45936375922793925919605092352922707796689801895417366600539442410775071099958","price":"0.86","size":"191.69","side":"BUY","hash":"d524724bd9d4f5209dec7a2fa7d3d3e7377ca968","best_bid":"0.86","best_ask":"0.87"},{"asset_id":"86520121088881862182423437128238697252500151785248183602134095101149900014256","price":"0.14","size":"191.69","side":"SELL","hash":"10d56dcefaa4807104892a2be861621533210cea","best_bid":"0.13","best_ask":"0.14"}],"timestamp":"1776808416791","event_type":"price_change"}}
{"capturedAt":1776808416,"payload":{"market":"0x125149c5918fc5f8c6d34682f700a898a1a19ea4f4e2ae68ff4c5794ba657074","price_changes":[{"asset_id":"45936375922793925919605092352922707796689801895417366600539442410775071099958","price":"0.86","size":"186.43","side":"BUY","hash":"d967c1205853619a2d05d11cdb6050249c0d3f4f","best_bid":"0.86","best_ask":"0.87"},{"asset_id":"86520121088881862182423437128238697252500151785248183602134095101149900014256","price":"0.14","size":"186.43","side":"SELL","hash":"9df27d0cccb8ce67b1a0dcbbbf1575d195e64470","best_bid":"0.13","best_ask":"0.14"}],"timestamp":"1776808416792","event_type":"price_change"}}
{"capturedAt":1776808416,"payload":{"market":"0x125149c5918fc5f8c6d34682f700a898a1a19ea4f4e2ae68ff4c5794ba657074","price_changes":[{"asset_id":"45936375922793925919605092352922707796689801895417366600539442410775071099958","price":"0.86","size":"191.84","side":"BUY","hash":"cb36eb2871b9b7dbe81f2fe5fa3e7cad253c1986","best_bid":"0.86","best_ask":"0.87"},{"asset_id":"86520121088881862182423437128238697252500151785248183602134095101149900014256","price":"0.14","size":"191.84","side":"SELL","hash":"4ab35d92f9b7c49abfa0999a9d70386b59ba5372","best_bid":"0.13","best_ask":"0.14"}],"timestamp":"1776808416793","event_type":"price_change"}}
{"capturedAt":1776808416,"payload":{"market":"0x125149c5918fc5f8c6d34682f700a898a1a19ea4f4e2ae68ff4c5794ba657074","price_changes":[{"asset_id":"45936375922793925919605092352922707796689801895417366600539442410775071099958","price":"0.86","size":"196.84","side":"BUY","hash":"ea6466a095c8646bd9cb6a39d8d50a0fe64b1bfa","best_bid":"0.86","best_ask":"0.87"},{"asset_id":"86520121088881862182423437128238697252500151785248183602134095101149900014256","price":"0.14","size":"196.84","side":"SELL","hash":"377c23724f00f4c6e9fcff94fe07b750fe733342","best_bid":"0.13","best_ask":"0.14"}],"timestamp":"1776808416794","event_type":"price_change"}}
{"capturedAt":1776808416,"payload":{"market":"0x125149c5918fc5f8c6d34682f700a898a1a19ea4f4e2ae68ff4c5794ba657074","price_changes":[{"asset_id":"45936375922793925919605092352922707796689801895417366600539442410775071099958","price":"0.01","size":"12334.84","side":"BUY","hash":"73e52482cbd27f4bf263ad0bb3546da4f6b927aa","best_bid":"0.86","best_ask":"0.87"},{"asset_id":"86520121088881862182423437128238697252500151785248183602134095101149900014256","price":"0.99","size":"12334.84","side":"SELL","hash":"99ae7c5303be55e672580f712d3bde603c1b7ea9","best_bid":"0.13","best_ask":"0.14"}],"timestamp":"1776808416795","event_type":"price_change"}}
{"capturedAt":1776808416,"payload":{"market":"0x125149c5918fc5f8c6d34682f700a898a1a19ea4f4e2ae68ff4c5794ba657074","price_changes":[{"asset_id":"45936375922793925919605092352922707796689801895417366600539442410775071099958","price":"0.86","size":"201.84","side":"BUY","hash":"68a52be0635e99babe31cee0222d32ebd5052dbe","best_bid":"0.86","best_ask":"0.87"},{"asset_id":"86520121088881862182423437128238697252500151785248183602134095101149900014256","price":"0.14","size":"201.84","side":"SELL","hash":"01a91aa6796dbe688de9e7402a24a65947e86aa3","best_bid":"0.13","best_ask":"0.14"}],"timestamp":"1776808416797","event_type":"price_change"}}
{"capturedAt":1776808416,"payload":{"market":"0x125149c5918fc5f8c6d34682f700a898a1a19ea4f4e2ae68ff4c5794ba657074","price_changes":[{"asset_id":"45936375922793925919605092352922707796689801895417366600539442410775071099958","price":"0.86","size":"211.84","side":"BUY","hash":"e4a7ee3b98d5fbd89b3d826da612cc58368a2718","best_bid":"0.86","best_ask":"0.87"},{"asset_id":"86520121088881862182423437128238697252500151785248183602134095101149900014256","price":"0.14","size":"211.84","side":"SELL","hash":"7aa055e214765a5032223587178252c0f332cc82","best_bid":"0.13","best_ask":"0.14"}],"timestamp":"1776808416798","event_type":"price_change"}}
{"capturedAt":1776808416,"payload":{"market":"0x125149c5918fc5f8c6d34682f700a898a1a19ea4f4e2ae68ff4c5794ba657074","price_changes":[{"asset_id":"86520121088881862182423437128238697252500151785248183602134095101149900014256","price":"0.13","size":"199.74","side":"BUY","hash":"4d8867f1f691d85c881bc023aa4c6137090a6b01","best_bid":"0.13","best_ask":"0.14"},{"asset_id":"45936375922793925919605092352922707796689801895417366600539442410775071099958","price":"0.87","size":"199.74","side":"SELL","hash":"efbcbaa893aeebbe07e4920a83183bd841cb55b6","best_bid":"0.86","best_ask":"0.87"}],"timestamp":"1776808416799","event_type":"price_change"}}
{"capturedAt":1776808416,"payload":{"market":"0x125149c5918fc5f8c6d34682f700a898a1a19ea4f4e2ae68ff4c5794ba657074","price_changes":[{"asset_id":"45936375922793925919605092352922707796689801895417366600539442410775071099958","price":"0.01","size":"12339.84","side":"BUY","hash":"82843b8ccb9ece07e770601acb95e3a47c60608b","best_bid":"0.86","best_ask":"0.87"},{"asset_id":"86520121088881862182423437128238697252500151785248183602134095101149900014256","price":"0.99","size":"12339.84","side":"SELL","hash":"eda9deeb32bc47929f4531bfadb12e655546d935","best_bid":"0.13","best_ask":"0.14"}],"timestamp":"1776808416800","event_type":"price_change"}}
{"capturedAt":1776808416,"payload":{"market":"0x125149c5918fc5f8c6d34682f700a898a1a19ea4f4e2ae68ff4c5794ba657074","price_changes":[{"asset_id":"45936375922793925919605092352922707796689801895417366600539442410775071099958","price":"0.86","size":"221.84","side":"BUY","hash":"ead4e54d634d5f3d542a613056795dd18658da3a","best_bid":"0.86","best_ask":"0.87"},{"asset_id":"86520121088881862182423437128238697252500151785248183602134095101149900014256","price":"0.14","size":"221.84","side":"SELL","hash":"1952beba603c86bda354fafe4b7f31c75b55ae35","best_bid":"0.13","best_ask":"0.14"}],"timestamp":"1776808416802","event_type":"price_change"}}
{"capturedAt":1776808416,"payload":{"market":"0x125149c5918fc5f8c6d34682f700a898a1a19ea4f4e2ae68ff4c5794ba657074","price_changes":[{"asset_id":"45936375922793925919605092352922707796689801895417366600539442410775071099958","price":"0.86","size":"226.84","side":"BUY","hash":"16b74144bceb1de0648c8f1e768813bef30eb232","best_bid":"0.86","best_ask":"0.87"},{"asset_id":"86520121088881862182423437128238697252500151785248183602134095101149900014256","price":"0.14","size":"226.84","side":"SELL","hash":"03b61149ce4f67dfd77c9c5373efa47fe5efac75","best_bid":"0.13","best_ask":"0.14"}],"timestamp":"1776808416803","event_type":"price_change"}}
{"capturedAt":1776808416,"payload":{"market":"0x125149c5918fc5f8c6d34682f700a898a1a19ea4f4e2ae68ff4c5794ba657074","price_changes":[{"asset_id":"45936375922793925919605092352922707796689801895417366600539442410775071099958","price":"0.01","size":"12334.83","side":"BUY","hash":"5675a658e61ffac752938d74e82f8dc85927b82c","best_bid":"0.86","best_ask":"0.87"},{"asset_id":"86520121088881862182423437128238697252500151785248183602134095101149900014256","price":"0.99","size":"12334.83","side":"SELL","hash":"5bd37ed0de5fb32ab6fd9a03a5864dfc1133dddc","best_bid":"0.13","best_ask":"0.14"}],"timestamp":"1776808416804","event_type":"price_change"}}
{"capturedAt":1776808416,"payload":{"market":"0x125149c5918fc5f8c6d34682f700a898a1a19ea4f4e2ae68ff4c5794ba657074","price_changes":[{"asset_id":"45936375922793925919605092352922707796689801895417366600539442410775071099958","price":"0.86","size":"221.43","side":"BUY","hash":"b09c1a38ffafba9c4926e6d130b69fe19c3a9e8e","best_bid":"0.86","best_ask":"0.87"},{"asset_id":"86520121088881862182423437128238697252500151785248183602134095101149900014256","price":"0.14","size":"221.43","side":"SELL","hash":"3340062a77d9df81f616bc38794ad7f86227b9f1","best_bid":"0.13","best_ask":"0.14"}],"timestamp":"1776808416813","event_type":"price_change"}}
{"capturedAt":1776808416,"payload":{"market":"0x125149c5918fc5f8c6d34682f700a898a1a19ea4f4e2ae68ff4c5794ba657074","price_changes":[{"asset_id":"45936375922793925919605092352922707796689801895417366600539442410775071099958","price":"0.01","size":"12329.83","side":"BUY","hash":"43c080fa5e96527f006c728a52929c799d8df2aa","best_bid":"0.86","best_ask":"0.87"},{"asset_id":"86520121088881862182423437128238697252500151785248183602134095101149900014256","price":"0.99","size":"12329.83","side":"SELL","hash":"fd975132f01e6100351bda5c2d75fea41e060a49","best_bid":"0.13","best_ask":"0.14"}],"timestamp":"1776808416815","event_type":"price_change"}}
{"capturedAt":1776808416,"payload":{"market":"0x125149c5918fc5f8c6d34682f700a898a1a19ea4f4e2ae68ff4c5794ba657074","price_changes":[{"asset_id":"45936375922793925919605092352922707796689801895417366600539442410775071099958","price":"0.01","size":"12324.83","side":"BUY","hash":"dbf04a6b93728b2feb5f5b71588957fbde31a3d1","best_bid":"0.86","best_ask":"0.87"},{"asset_id":"86520121088881862182423437128238697252500151785248183602134095101149900014256","price":"0.99","size":"12324.83","side":"SELL","hash":"48860496ae4024cca4ecdd1db8bffcc23e07225f","best_bid":"0.13","best_ask":"0.14"}],"timestamp":"1776808416819","event_type":"price_change"}}
{"capturedAt":1776808416,"payload":{"market":"0x125149c5918fc5f8c6d34682f700a898a1a19ea4f4e2ae68ff4c5794ba657074","price_changes":[{"asset_id":"45936375922793925919605092352922707796689801895417366600539442410775071099958","price":"0.86","size":"227.08","side":"BUY","hash":"740b6783319ff62a19c9b212a86609bc59ceebcb","best_bid":"0.86","best_ask":"0.87"},{"asset_id":"86520121088881862182423437128238697252500151785248183602134095101149900014256","price":"0.14","size":"227.08","side":"SELL","hash":"d73ca832420e27439c104a8d6902a559e6078e3e","best_bid":"0.13","best_ask":"0.14"}],"timestamp":"1776808416833","event_type":"price_change"}}
{"capturedAt":1776808416,"payload":{"market":"0x125149c5918fc5f8c6d34682f700a898a1a19ea4f4e2ae68ff4c5794ba657074","price_changes":[{"asset_id":"45936375922793925919605092352922707796689801895417366600539442410775071099958","price":"0.86","size":"222.08","side":"BUY","hash":"fa50ecdea4bf5c361d81c88e700ed882db7ce163","best_bid":"0.86","best_ask":"0.87"},{"asset_id":"86520121088881862182423437128238697252500151785248183602134095101149900014256","price":"0.14","size":"222.08","side":"SELL","hash":"081c86e8d896f3d9e0776f7d10e404df8530c332","best_bid":"0.13","best_ask":"0.14"}],"timestamp":"1776808416835","event_type":"price_change"}}
{"capturedAt":1776808416,"payload":{"market":"0x125149c5918fc5f8c6d34682f700a898a1a19ea4f4e2ae68ff4c5794ba657074","price_changes":[{"asset_id":"45936375922793925919605092352922707796689801895417366600539442410775071099958","price":"0.01","size":"12329.83","side":"BUY","hash":"3c964acba819dda908b8e11f5e5d2bc138c56f33","best_bid":"0.86","best_ask":"0.87"},{"asset_id":"86520121088881862182423437128238697252500151785248183602134095101149900014256","price":"0.99","size":"12329.83","side":"SELL","hash":"3afadb4cc4ee1122887b761c06bc2d22ed697dde","best_bid":"0.13","best_ask":"0.14"}],"timestamp":"1776808416838","event_type":"price_change"}}
{"capturedAt":1776808416,"payload":{"market":"0x125149c5918fc5f8c6d34682f700a898a1a19ea4f4e2ae68ff4c5794ba657074","price_changes":[{"asset_id":"86520121088881862182423437128238697252500151785248183602134095101149900014256","price":"0.13","size":"194.74","side":"BUY","hash":"3de4862feb6cc5546ac02219218c47418aab0d9a","best_bid":"0.13","best_ask":"0.14"},{"asset_id":"45936375922793925919605092352922707796689801895417366600539442410775071099958","price":"0.87","size":"194.74","side":"SELL","hash":"a418a620137cb29f38bb622279504f067d02debb","best_bid":"0.86","best_ask":"0.87"}],"timestamp":"1776808416841","event_type":"price_change"}}
{"capturedAt":1776808416,"payload":{"market":"0x125149c5918fc5f8c6d34682f700a898a1a19ea4f4e2ae68ff4c5794ba657074","price_changes":[{"asset_id":"45936375922793925919605092352922707796689801895417366600539442410775071099958","price":"0.86","size":"217.08","side":"BUY","hash":"f4031abd3ec48bb7514883cbfe51e51a2d39df73","best_bid":"0.86","best_ask":"0.87"},{"asset_id":"86520121088881862182423437128238697252500151785248183602134095101149900014256","price":"0.14","size":"217.08","side":"SELL","hash":"f504f1033c29b3f14a98e6483bee42f8f9ddc048","best_bid":"0.13","best_ask":"0.14"}],"timestamp":"1776808416841","event_type":"price_change"}}
{"capturedAt":1776808416,"payload":{"market":"0x125149c5918fc5f8c6d34682f700a898a1a19ea4f4e2ae68ff4c5794ba657074","price_changes":[{"asset_id":"45936375922793925919605092352922707796689801895417366600539442410775071099958","price":"0.86","size":"207.08","side":"BUY","hash":"428e1459cf06c4f03ac9a0ed24761eb435fbc1d4","best_bid":"0.86","best_ask":"0.87"},{"asset_id":"86520121088881862182423437128238697252500151785248183602134095101149900014256","price":"0.14","size":"207.08","side":"SELL","hash":"c024ea7fd74d7874ef5afb697bb2774bc93c634d","best_bid":"0.13","best_ask":"0.14"}],"timestamp":"1776808416843","event_type":"price_change"}}
{"capturedAt":1776808416,"payload":{"market":"0x125149c5918fc5f8c6d34682f700a898a1a19ea4f4e2ae68ff4c5794ba657074","price_changes":[{"asset_id":"86520121088881862182423437128238697252500151785248183602134095101149900014256","price":"0.13","size":"189.74","side":"BUY","hash":"7e79c587bae263355b6a941a019a05cc0c8843cd","best_bid":"0.13","best_ask":"0.14"},{"asset_id":"45936375922793925919605092352922707796689801895417366600539442410775071099958","price":"0.87","size":"189.74","side":"SELL","hash":"176a967670a63be3ca0586193ab9f421f757ef42","best_bid":"0.86","best_ask":"0.87"}],"timestamp":"1776808416844","event_type":"price_change"}}
{"capturedAt":1776808416,"payload":{"market":"0x125149c5918fc5f8c6d34682f700a898a1a19ea4f4e2ae68ff4c5794ba657074","price_changes":[{"asset_id":"45936375922793925919605092352922707796689801895417366600539442410775071099958","price":"0.86","size":"202.08","side":"BUY","hash":"7a663bfbfe7dbdf52d04b7081f8c50b631da17f4","best_bid":"0.86","best_ask":"0.87"},{"asset_id":"86520121088881862182423437128238697252500151785248183602134095101149900014256","price":"0.14","size":"202.08","side":"SELL","hash":"70f7adf60b08720ae3a05ed8fb00e22d44d730dd","best_bid":"0.13","best_ask":"0.14"}],"timestamp":"1776808416845","event_type":"price_change"}}
{"capturedAt":1776808416,"payload":{"market":"0x125149c5918fc5f8c6d34682f700a898a1a19ea4f4e2ae68ff4c5794ba657074","price_changes":[{"asset_id":"45936375922793925919605092352922707796689801895417366600539442410775071099958","price":"0.86","size":"197.08","side":"BUY","hash":"3982f2a3ae2db4cf1a0d05573ca25dc3f24c8fcb","best_bid":"0.86","best_ask":"0.87"},{"asset_id":"86520121088881862182423437128238697252500151785248183602134095101149900014256","price":"0.14","size":"197.08","side":"SELL","hash":"f8e92216c0b1462cb7d55c962dcd9313e403dc14","best_bid":"0.13","best_ask":"0.14"}],"timestamp":"1776808416845","event_type":"price_change"}}
{"capturedAt":1776808416,"payload":{"market":"0x125149c5918fc5f8c6d34682f700a898a1a19ea4f4e2ae68ff4c5794ba657074","price_changes":[{"asset_id":"86520121088881862182423437128238697252500151785248183602134095101149900014256","price":"0.13","size":"184.74","side":"BUY","hash":"bfed339e575225c5a7719cda60214185d679e428","best_bid":"0.13","best_ask":"0.14"},{"asset_id":"45936375922793925919605092352922707796689801895417366600539442410775071099958","price":"0.87","size":"184.74","side":"SELL","hash":"6376c267d5ee0febf7f9e8844d22a2d22b26beab","best_bid":"0.86","best_ask":"0.87"}],"timestamp":"1776808416846","event_type":"price_change"}}
{"capturedAt":1776808416,"payload":{"market":"0x125149c5918fc5f8c6d34682f700a898a1a19ea4f4e2ae68ff4c5794ba657074","price_changes":[{"asset_id":"86520121088881862182423437128238697252500151785248183602134095101149900014256","price":"0.22","size":"268.98","side":"SELL","hash":"aacf210a38634e1597fc79d640ec7269694bfbf2","best_bid":"0.13","best_ask":"0.14"},{"asset_id":"45936375922793925919605092352922707796689801895417366600539442410775071099958","price":"0.78","size":"268.98","side":"BUY","hash":"7590c97caf1664a9327158e323ee36610e826840","best_bid":"0.86","best_ask":"0.87"}],"timestamp":"1776808416847","event_type":"price_change"}}
{"capturedAt":1776808416,"payload":{"market":"0x125149c5918fc5f8c6d34682f700a898a1a19ea4f4e2ae68ff4c5794ba657074","price_changes":[{"asset_id":"45936375922793925919605092352922707796689801895417366600539442410775071099958","price":"0.78","size":"218.98","side":"BUY","hash":"73205643a833205814e0e12ef668df43ea15f790","best_bid":"0.86","best_ask":"0.87"},{"asset_id":"86520121088881862182423437128238697252500151785248183602134095101149900014256","price":"0.22","size":"218.98","side":"SELL","hash":"8243662818248e291204bf4598f0f628a84be87c","best_bid":"0.13","best_ask":"0.14"}],"timestamp":"1776808416848","event_type":"price_change"}}
{"capturedAt":1776808416,"payload":{"market":"0x125149c5918fc5f8c6d34682f700a898a1a19ea4f4e2ae68ff4c5794ba657074","price_changes":[{"asset_id":"45936375922793925919605092352922707796689801895417366600539442410775071099958","price":"0.79","size":"234.7","side":"BUY","hash":"9a0dc76bbdf81f83b249d4d3e93031e2d296b804","best_bid":"0.86","best_ask":"0.87"},{"asset_id":"86520121088881862182423437128238697252500151785248183602134095101149900014256","price":"0.21","size":"234.7","side":"SELL","hash":"cc61c38f88b8c78d97ac6e308072531d79c2658a","best_bid":"0.13","best_ask":"0.14"}],"timestamp":"1776808416850","event_type":"price_change"}}
{"capturedAt":1776808416,"payload":{"market":"0x125149c5918fc5f8c6d34682f700a898a1a19ea4f4e2ae68ff4c5794ba657074","price_changes":[{"asset_id":"86520121088881862182423437128238697252500151785248183602134095101149900014256","price":"0.21","size":"284.7","side":"SELL","hash":"1c8de96a0a939c1ca1e8b0999dc6419488893d1b","best_bid":"0.13","best_ask":"0.14"},{"asset_id":"45936375922793925919605092352922707796689801895417366600539442410775071099958","price":"0.79","size":"284.7","side":"BUY","hash":"a3ab0d346df20af388b125c34d4978afff627e05","best_bid":"0.86","best_ask":"0.87"}],"timestamp":"1776808416851","event_type":"price_change"}}
{"capturedAt":1776808416,"payload":{"market":"0x125149c5918fc5f8c6d34682f700a898a1a19ea4f4e2ae68ff4c5794ba657074","price_changes":[{"asset_id":"45936375922793925919605092352922707796689801895417366600539442410775071099958","price":"0.01","size":"12334.83","side":"BUY","hash":"ea87506702b9fc46240a26315a250ad9e1930dba","best_bid":"0.86","best_ask":"0.87"},{"asset_id":"86520121088881862182423437128238697252500151785248183602134095101149900014256","price":"0.99","size":"12334.83","side":"SELL","hash":"b4188c8de25d46f4952b26c2049153b72f0f21e4","best_bid":"0.13","best_ask":"0.14"}],"timestamp":"1776808416852","event_type":"price_change"}}
{"capturedAt":1776808416,"payload":{"market":"0x125149c5918fc5f8c6d34682f700a898a1a19ea4f4e2ae68ff4c5794ba657074","price_changes":[{"asset_id":"86520121088881862182423437128238697252500151785248183602134095101149900014256","price":"0.13","size":"179.74","side":"BUY","hash":"63dad136b80cb435ea3b2980ec698415780b986d","best_bid":"0.13","best_ask":"0.14"},{"asset_id":"45936375922793925919605092352922707796689801895417366600539442410775071099958","price":"0.87","size":"179.74","side":"SELL","hash":"40d1013f799e96342cf72c4859db3b204fa7e4a5","best_bid":"0.86","best_ask":"0.87"}],"timestamp":"1776808416853","event_type":"price_change"}}
{"capturedAt":1776808416,"payload":{"market":"0x125149c5918fc5f8c6d34682f700a898a1a19ea4f4e2ae68ff4c5794ba657074","price_changes":[{"asset_id":"45936375922793925919605092352922707796689801895417366600539442410775071099958","price":"0.86","size":"192.08","side":"BUY","hash":"13791f68a6f671196f11c7475a37fc4ba4ea14bc","best_bid":"0.86","best_ask":"0.87"},{"asset_id":"86520121088881862182423437128238697252500151785248183602134095101149900014256","price":"0.14","size":"192.08","side":"SELL","hash":"c4af33d39770723fea045b8bd85ac2232d87d123","best_bid":"0.13","best_ask":"0.14"}],"timestamp":"1776808416853","event_type":"price_change"}}
{"capturedAt":1776808416,"payload":{"market":"0x125149c5918fc5f8c6d34682f700a898a1a19ea4f4e2ae68ff4c5794ba657074","price_changes":[{"asset_id":"86520121088881862182423437128238697252500151785248183602134095101149900014256","price":"0.13","size":"174.74","side":"BUY","hash":"00664b6c3b2c79faa9e26f658f4bde6b2072a96c","best_bid":"0.13","best_ask":"0.14"},{"asset_id":"45936375922793925919605092352922707796689801895417366600539442410775071099958","price":"0.87","size":"174.74","side":"SELL","hash":"e6713d91b0b7e203f6bca04e433831cb6110c319","best_bid":"0.86","best_ask":"0.87"}],"timestamp":"1776808416854","event_type":"price_change"}}
{"capturedAt":1776808416,"payload":{"market":"0x125149c5918fc5f8c6d34682f700a898a1a19ea4f4e2ae68ff4c5794ba657074","price_changes":[{"asset_id":"45936375922793925919605092352922707796689801895417366600539442410775071099958","price":"0.86","size":"187.08","side":"BUY","hash":"2997b6ba471d2077644c85874f59b2ead6c5a8a6","best_bid":"0.86","best_ask":"0.87"},{"asset_id":"86520121088881862182423437128238697252500151785248183602134095101149900014256","price":"0.14","size":"187.08","side":"SELL","hash":"f0775938e54d7673b1fd413df56a6fc281bd3a45","best_bid":"0.13","best_ask":"0.14"}],"timestamp":"1776808416855","event_type":"price_change"}}
{"capturedAt":1776808416,"payload":{"market":"0x125149c5918fc5f8c6d34682f700a898a1a19ea4f4e2ae68ff4c5794ba657074","price_changes":[{"asset_id":"45936375922793925919605092352922707796689801895417366600539442410775071099958","price":"0.01","size":"12329.83","side":"BUY","hash":"adda809e45330bf1844934705f7ac1b1aa78e625","best_bid":"0.86","best_ask":"0.87"},{"asset_id":"86520121088881862182423437128238697252500151785248183602134095101149900014256","price":"0.99","size":"12329.83","side":"SELL","hash":"d92b0d65bab54090a681a1d463e12483a6e88ab9","best_bid":"0.13","best_ask":"0.14"}],"timestamp":"1776808416857","event_type":"price_change"}}
{"capturedAt":1776808416,"payload":{"market":"0x125149c5918fc5f8c6d34682f700a898a1a19ea4f4e2ae68ff4c5794ba657074","price_changes":[{"asset_id":"45936375922793925919605092352922707796689801895417366600539442410775071099958","price":"0.86","size":"181.43","side":"BUY","hash":"3096f63f30edb28ed72cd1cd9b4098bf582b965a","best_bid":"0.86","best_ask":"0.87"},{"asset_id":"86520121088881862182423437128238697252500151785248183602134095101149900014256","price":"0.14","size":"181.43","side":"SELL","hash":"f6b233b374aaa75dcfaadad1cbde57a568345377","best_bid":"0.13","best_ask":"0.14"}],"timestamp":"1776808416861","event_type":"price_change"}}
{"capturedAt":1776808416,"payload":{"market":"0x125149c5918fc5f8c6d34682f700a898a1a19ea4f4e2ae68ff4c5794ba657074","price_changes":[{"asset_id":"86520121088881862182423437128238697252500151785248183602134095101149900014256","price":"0.13","size":"169.74","side":"BUY","hash":"e76ff99608ea86da1a2bbda605b463228aeb1fc2","best_bid":"0.13","best_ask":"0.14"},{"asset_id":"45936375922793925919605092352922707796689801895417366600539442410775071099958","price":"0.87","size":"169.74","side":"SELL","hash":"50318c25a2aca61e8d3f73c677aad45c595a3a97","best_bid":"0.86","best_ask":"0.87"}],"timestamp":"1776808416862","event_type":"price_change"}}
{"capturedAt":1776808416,"payload":{"market":"0x125149c5918fc5f8c6d34682f700a898a1a19ea4f4e2ae68ff4c5794ba657074","price_changes":[{"asset_id":"45936375922793925919605092352922707796689801895417366600539442410775071099958","price":"0.86","size":"176.43","side":"BUY","hash":"a693e8ad2c60e680c2c34f0d1ba1a837ad647f1a","best_bid":"0.86","best_ask":"0.87"},{"asset_id":"86520121088881862182423437128238697252500151785248183602134095101149900014256","price":"0.14","size":"176.43","side":"SELL","hash":"d7fb84d204bc5d811bfdcb7a95f68593f32a1471","best_bid":"0.13","best_ask":"0.14"}],"timestamp":"1776808416862","event_type":"price_change"}}
{"capturedAt":1776808416,"payload":{"market":"0x125149c5918fc5f8c6d34682f700a898a1a19ea4f4e2ae68ff4c5794ba657074","price_changes":[{"asset_id":"45936375922793925919605092352922707796689801895417366600539442410775071099958","price":"0.86","size":"182.43","side":"BUY","hash":"4b73666fa9c775a7b221c678e8ca2e8e573d5cd1","best_bid":"0.86","best_ask":"0.87"},{"asset_id":"86520121088881862182423437128238697252500151785248183602134095101149900014256","price":"0.14","size":"182.43","side":"SELL","hash":"63db46b306c7a8944b2fbc5a67ea07806269bcc2","best_bid":"0.13","best_ask":"0.14"}],"timestamp":"1776808416864","event_type":"price_change"}}
{"capturedAt":1776808416,"payload":{"market":"0x125149c5918fc5f8c6d34682f700a898a1a19ea4f4e2ae68ff4c5794ba657074","price_changes":[{"asset_id":"86520121088881862182423437128238697252500151785248183602134095101149900014256","price":"0.13","size":"164.74","side":"BUY","hash":"7682b42e0b27d93c019b05b07c63294ae5f86f2c","best_bid":"0.13","best_ask":"0.14"},{"asset_id":"45936375922793925919605092352922707796689801895417366600539442410775071099958","price":"0.87","size":"164.74","side":"SELL","hash":"11196138765cb478ef20a02583f71b2e4022e41d","best_bid":"0.86","best_ask":"0.87"}],"timestamp":"1776808416865","event_type":"price_change"}}
{"capturedAt":1776808416,"payload":{"market":"0x125149c5918fc5f8c6d34682f700a898a1a19ea4f4e2ae68ff4c5794ba657074","price_changes":[{"asset_id":"45936375922793925919605092352922707796689801895417366600539442410775071099958","price":"0.86","size":"177.43","side":"BUY","hash":"f3f59089735a10580b5f94b9e96633ebe8025dd2","best_bid":"0.86","best_ask":"0.87"},{"asset_id":"86520121088881862182423437128238697252500151785248183602134095101149900014256","price":"0.14","size":"177.43","side":"SELL","hash":"5728488092aad6bb6cc734649bd50c455f15c84e","best_bid":"0.13","best_ask":"0.14"}],"timestamp":"1776808416865","event_type":"price_change"}}
{"capturedAt":1776808416,"payload":{"market":"0x125149c5918fc5f8c6d34682f700a898a1a19ea4f4e2ae68ff4c5794ba657074","price_changes":[{"asset_id":"86520121088881862182423437128238697252500151785248183602134095101149900014256","price":"0.13","size":"159.74","side":"BUY","hash":"3031729d718c491c40935e810612b26a80613e77","best_bid":"0.13","best_ask":"0.14"},{"asset_id":"45936375922793925919605092352922707796689801895417366600539442410775071099958","price":"0.87","size":"159.74","side":"SELL","hash":"e01f9c1b49f79527424d2a590bfc566662126ade","best_bid":"0.86","best_ask":"0.87"}],"timestamp":"1776808416867","event_type":"price_change"}}
{"capturedAt":1776808416,"payload":{"market":"0x125149c5918fc5f8c6d34682f700a898a1a19ea4f4e2ae68ff4c5794ba657074","price_changes":[{"asset_id":"45936375922793925919605092352922707796689801895417366600539442410775071099958","price":"0.86","size":"183.43","side":"BUY","hash":"572738f50a07824e7691520978e834b70086f639","best_bid":"0.86","best_ask":"0.87"},{"asset_id":"86520121088881862182423437128238697252500151785248183602134095101149900014256","price":"0.14","size":"183.43","side":"SELL","hash":"e0219905bafa27b3394f4d0b9000e024cac2da33","best_bid":"0.13","best_ask":"0.14"}],"timestamp":"1776808416867","event_type":"price_change"}}
{"capturedAt":1776808416,"payload":{"market":"0x125149c5918fc5f8c6d34682f700a898a1a19ea4f4e2ae68ff4c5794ba657074","price_changes":[{"asset_id":"45936375922793925919605092352922707796689801895417366600539442410775071099958","price":"0.86","size":"178.43","side":"BUY","hash":"1a49319737573a3df674932fd1158be5ad6b2dfb","best_bid":"0.86","best_ask":"0.87"},{"asset_id":"86520121088881862182423437128238697252500151785248183602134095101149900014256","price":"0.14","size":"178.43","side":"SELL","hash":"bb5605e1a6c7a229c3a10e2c26e4d29da6fb9786","best_bid":"0.13","best_ask":"0.14"}],"timestamp":"1776808416869","event_type":"price_change"}}
{"capturedAt":1776808416,"payload":{"market":"0x125149c5918fc5f8c6d34682f700a898a1a19ea4f4e2ae68ff4c5794ba657074","price_changes":[{"asset_id":"45936375922793925919605092352922707796689801895417366600539442410775071099958","price":"0.86","size":"184.43","side":"BUY","hash":"00af171b062577bb816ce7cb17f3cdda52173dad","best_bid":"0.86","best_ask":"0.87"},{"asset_id":"86520121088881862182423437128238697252500151785248183602134095101149900014256","price":"0.14","size":"184.43","side":"SELL","hash":"04379bd87416600bdb40f42e9871fa8627dd1d47","best_bid":"0.13","best_ask":"0.14"}],"timestamp":"1776808416870","event_type":"price_change"}}
{"capturedAt":1776808416,"payload":{"market":"0x125149c5918fc5f8c6d34682f700a898a1a19ea4f4e2ae68ff4c5794ba657074","price_changes":[{"asset_id":"86520121088881862182423437128238697252500151785248183602134095101149900014256","price":"0.13","size":"154.74","side":"BUY","hash":"27f55854a903cfd53effbda341c6bdde7c158ae7","best_bid":"0.13","best_ask":"0.14"},{"asset_id":"45936375922793925919605092352922707796689801895417366600539442410775071099958","price":"0.87","size":"154.74","side":"SELL","hash":"f3f1246837283e7531656e9285b411225bc16a46","best_bid":"0.86","best_ask":"0.87"}],"timestamp":"1776808416871","event_type":"price_change"}}
{"capturedAt":1776808416,"payload":{"market":"0x125149c5918fc5f8c6d34682f700a898a1a19ea4f4e2ae68ff4c5794ba657074","price_changes":[{"asset_id":"45936375922793925919605092352922707796689801895417366600539442410775071099958","price":"0.86","size":"179.43","side":"BUY","hash":"ff410226a7c5749b50301603f00214292bb0a6c0","best_bid":"0.86","best_ask":"0.87"},{"asset_id":"86520121088881862182423437128238697252500151785248183602134095101149900014256","price":"0.14","size":"179.43","side":"SELL","hash":"2cbcd07e1e14586ee7d29d3879f927508fe7e157","best_bid":"0.13","best_ask":"0.14"}],"timestamp":"1776808416871","event_type":"price_change"}}
{"capturedAt":1776808416,"payload":{"market":"0x125149c5918fc5f8c6d34682f700a898a1a19ea4f4e2ae68ff4c5794ba657074","price_changes":[{"asset_id":"45936375922793925919605092352922707796689801895417366600539442410775071099958","price":"0.86","size":"189.43","side":"BUY","hash":"87c4abbcfa0e1c6e1ebefd83025d8aedd24e4f64","best_bid":"0.86","best_ask":"0.87"},{"asset_id":"86520121088881862182423437128238697252500151785248183602134095101149900014256","price":"0.14","size":"189.43","side":"SELL","hash":"a578fc6f0e0fbb3f71ea8d51f70cf1c8e722ad83","best_bid":"0.13","best_ask":"0.14"}],"timestamp":"1776808416872","event_type":"price_change"}}
{"capturedAt":1776808416,"payload":{"market":"0x125149c5918fc5f8c6d34682f700a898a1a19ea4f4e2ae68ff4c5794ba657074","price_changes":[{"asset_id":"45936375922793925919605092352922707796689801895417366600539442410775071099958","price":"0.86","size":"195.43","side":"BUY","hash":"770927491918978b69fd9349902337e18e3f5dde","best_bid":"0.86","best_ask":"0.87"},{"asset_id":"86520121088881862182423437128238697252500151785248183602134095101149900014256","price":"0.14","size":"195.43","side":"SELL","hash":"90445f343c9fe7ba6ad6e9ab7e80d7134fef6716","best_bid":"0.13","best_ask":"0.14"}],"timestamp":"1776808416874","event_type":"price_change"}}
{"capturedAt":1776808416,"payload":{"market":"0x125149c5918fc5f8c6d34682f700a898a1a19ea4f4e2ae68ff4c5794ba657074","price_changes":[{"asset_id":"45936375922793925919605092352922707796689801895417366600539442410775071099958","price":"0.86","size":"175.43","side":"BUY","hash":"eaa2ece66117139d490e088e8a39bf09adf56c37","best_bid":"0.86","best_ask":"0.87"},{"asset_id":"86520121088881862182423437128238697252500151785248183602134095101149900014256","price":"0.14","size":"175.43","side":"SELL","hash":"f3777e42910a0e5a1839fa9d32dd97f7d191f13e","best_bid":"0.13","best_ask":"0.14"}],"timestamp":"1776808416878","event_type":"price_change"}}
{"capturedAt":1776808416,"payload":{"market":"0x125149c5918fc5f8c6d34682f700a898a1a19ea4f4e2ae68ff4c5794ba657074","price_changes":[{"asset_id":"45936375922793925919605092352922707796689801895417366600539442410775071099958","price":"0.86","size":"185.43","side":"BUY","hash":"3ce925d4e6407c32ccf333520baabc56842be82d","best_bid":"0.86","best_ask":"0.87"},{"asset_id":"86520121088881862182423437128238697252500151785248183602134095101149900014256","price":"0.14","size":"185.43","side":"SELL","hash":"50d1ead684b2f5a56cd3ed14c080b3f3441c465f","best_bid":"0.13","best_ask":"0.14"}],"timestamp":"1776808416876","event_type":"price_change"}}
{"capturedAt":1776808416,"payload":{"market":"0x125149c5918fc5f8c6d34682f700a898a1a19ea4f4e2ae68ff4c5794ba657074","price_changes":[{"asset_id":"86520121088881862182423437128238697252500151785248183602134095101149900014256","price":"0.13","size":"149.74","side":"BUY","hash":"45fa7e77371ac285602fa1d0ab37b61986d36bb3","best_bid":"0.13","best_ask":"0.14"},{"asset_id":"45936375922793925919605092352922707796689801895417366600539442410775071099958","price":"0.87","size":"149.74","side":"SELL","hash":"a58fbad2aada5288e1205b1c44fe30fda7b2cd8f","best_bid":"0.86","best_ask":"0.87"}],"timestamp":"1776808416879","event_type":"price_change"}}
{"capturedAt":1776808416,"payload":{"market":"0x125149c5918fc5f8c6d34682f700a898a1a19ea4f4e2ae68ff4c5794ba657074","price_changes":[{"asset_id":"45936375922793925919605092352922707796689801895417366600539442410775071099958","price":"0.86","size":"170.43","side":"BUY","hash":"d74d3eef35ab306217492b64d6038fc714e5dc10","best_bid":"0.86","best_ask":"0.87"},{"asset_id":"86520121088881862182423437128238697252500151785248183602134095101149900014256","price":"0.14","size":"170.43","side":"SELL","hash":"1adb6774722208eac4d76ae97b1143845d232071","best_bid":"0.13","best_ask":"0.14"}],"timestamp":"1776808416880","event_type":"price_change"}}
{"capturedAt":1776808416,"payload":{"market":"0x125149c5918fc5f8c6d34682f700a898a1a19ea4f4e2ae68ff4c5794ba657074","price_changes":[{"asset_id":"45936375922793925919605092352922707796689801895417366600539442410775071099958","price":"0.86","size":"175.43","side":"BUY","hash":"31657b1749eef1b149f70efab9d30075c4d493a7","best_bid":"0.86","best_ask":"0.87"},{"asset_id":"86520121088881862182423437128238697252500151785248183602134095101149900014256","price":"0.14","size":"175.43","side":"SELL","hash":"4070b2b5e9d7779127aee27c67bb57b9783fda75","best_bid":"0.13","best_ask":"0.14"}],"timestamp":"1776808416882","event_type":"price_change"}}
{"capturedAt":1776808416,"payload":{"market":"0x125149c5918fc5f8c6d34682f700a898a1a19ea4f4e2ae68ff4c5794ba657074","price_changes":[{"asset_id":"45936375922793925919605092352922707796689801895417366600539442410775071099958","price":"0.86","size":"181.43","side":"BUY","hash":"e7dca9cdbc7cdd5b2a45c4e8f2691d375f54614f","best_bid":"0.86","best_ask":"0.87"},{"asset_id":"86520121088881862182423437128238697252500151785248183602134095101149900014256","price":"0.14","size":"181.43","side":"SELL","hash":"5cd9a57e751a46c75ec6560cac396875c101877b","best_bid":"0.13","best_ask":"0.14"}],"timestamp":"1776808416885","event_type":"price_change"}}
{"capturedAt":1776808416,"payload":{"market":"0x125149c5918fc5f8c6d34682f700a898a1a19ea4f4e2ae68ff4c5794ba657074","price_changes":[{"asset_id":"45936375922793925919605092352922707796689801895417366600539442410775071099958","price":"0.86","size":"186.71","side":"BUY","hash":"93d1786c0bae38199cf901131f632a15d139b36c","best_bid":"0.86","best_ask":"0.87"},{"asset_id":"86520121088881862182423437128238697252500151785248183602134095101149900014256","price":"0.14","size":"186.71","side":"SELL","hash":"66b452729211c3799ef0cd044c6ace31bd42a69a","best_bid":"0.13","best_ask":"0.14"}],"timestamp":"1776808416887","event_type":"price_change"}}
{"capturedAt":1776808416,"payload":{"market":"0x125149c5918fc5f8c6d34682f700a898a1a19ea4f4e2ae68ff4c5794ba657074","price_changes":[{"asset_id":"45936375922793925919605092352922707796689801895417366600539442410775071099958","price":"0.01","size":"12334.83","side":"BUY","hash":"c937ada0b38e58be7de6563fdccc964414570178","best_bid":"0.86","best_ask":"0.87"},{"asset_id":"86520121088881862182423437128238697252500151785248183602134095101149900014256","price":"0.99","size":"12334.83","side":"SELL","hash":"429b38b3c3c83ba810296b752005e28e978479b2","best_bid":"0.13","best_ask":"0.14"}],"timestamp":"1776808416888","event_type":"price_change"}}
{"capturedAt":1776808416,"payload":{"market":"0x125149c5918fc5f8c6d34682f700a898a1a19ea4f4e2ae68ff4c5794ba657074","price_changes":[{"asset_id":"45936375922793925919605092352922707796689801895417366600539442410775071099958","price":"0.86","size":"192.71","side":"BUY","hash":"a535433b3a1296817877d8b5be6b777366119574","best_bid":"0.86","best_ask":"0.87"},{"asset_id":"86520121088881862182423437128238697252500151785248183602134095101149900014256","price":"0.14","size":"192.71","side":"SELL","hash":"4f4828f578bedec74a63e4c36e3e70ae311d4312","best_bid":"0.13","best_ask":"0.14"}],"timestamp":"1776808416890","event_type":"price_change"}}
{"capturedAt":1776808416,"payload":{"market":"0x125149c5918fc5f8c6d34682f700a898a1a19ea4f4e2ae68ff4c5794ba657074","price_changes":[{"asset_id":"45936375922793925919605092352922707796689801895417366600539442410775071099958","price":"0.86","size":"198.71","side":"BUY","hash":"8c1c05733bfbfe871fbe20b677bb8605a89dc8df","best_bid":"0.86","best_ask":"0.87"},{"asset_id":"86520121088881862182423437128238697252500151785248183602134095101149900014256","price":"0.14","size":"198.71","side":"SELL","hash":"6853852a312a61f090e96f722b0cb4e792f1f3dd","best_bid":"0.13","best_ask":"0.14"}],"timestamp":"1776808416893","event_type":"price_change"}}
{"capturedAt":1776808416,"payload":{"market":"0x125149c5918fc5f8c6d34682f700a898a1a19ea4f4e2ae68ff4c5794ba657074","price_changes":[{"asset_id":"45936375922793925919605092352922707796689801895417366600539442410775071099958","price":"0.01","size":"12339.83","side":"BUY","hash":"9267918ac11644adea08303dad0744aa5511d17e","best_bid":"0.86","best_ask":"0.87"},{"asset_id":"86520121088881862182423437128238697252500151785248183602134095101149900014256","price":"0.99","size":"12339.83","side":"SELL","hash":"aafb6dba003e70cd2d364b2c0392f9f255aad953","best_bid":"0.13","best_ask":"0.14"}],"timestamp":"1776808416898","event_type":"price_change"}}
{"capturedAt":1776808416,"payload":{"market":"0x125149c5918fc5f8c6d34682f700a898a1a19ea4f4e2ae68ff4c5794ba657074","price_changes":[{"asset_id":"45936375922793925919605092352922707796689801895417366600539442410775071099958","price":"0.86","size":"203.71","side":"BUY","hash":"e2458c637d7f7206af0d2c2110418d693746d522","best_bid":"0.86","best_ask":"0.87"},{"asset_id":"86520121088881862182423437128238697252500151785248183602134095101149900014256","price":"0.14","size":"203.71","side":"SELL","hash":"1f5ea38890b9fa29cfb0b8ec8186ed25a7a8f39a","best_bid":"0.13","best_ask":"0.14"}],"timestamp":"1776808416900","event_type":"price_change"}}
{"capturedAt":1776808416,"payload":{"market":"0x125149c5918fc5f8c6d34682f700a898a1a19ea4f4e2ae68ff4c5794ba657074","price_changes":[{"asset_id":"45936375922793925919605092352922707796689801895417366600539442410775071099958","price":"0.86","size":"213.71","side":"BUY","hash":"210868256c5449ea571a84a8e7ea2a2fc7be7cf7","best_bid":"0.86","best_ask":"0.87"},{"asset_id":"86520121088881862182423437128238697252500151785248183602134095101149900014256","price":"0.14","size":"213.71","side":"SELL","hash":"1ef24198956e10cbffe94e82ef2bc03579976caf","best_bid":"0.13","best_ask":"0.14"}],"timestamp":"1776808416903","event_type":"price_change"}}
{"capturedAt":1776808416,"payload":{"market":"0x125149c5918fc5f8c6d34682f700a898a1a19ea4f4e2ae68ff4c5794ba657074","price_changes":[{"asset_id":"45936375922793925919605092352922707796689801895417366600539442410775071099958","price":"0.86","size":"219.71","side":"BUY","hash":"fc494a8c1a32da58e9577baa9a2d1dd41d2d16f5","best_bid":"0.86","best_ask":"0.87"},{"asset_id":"86520121088881862182423437128238697252500151785248183602134095101149900014256","price":"0.14","size":"219.71","side":"SELL","hash":"b1a09a421dd140781c609432862c6c65ce19adba","best_bid":"0.13","best_ask":"0.14"}],"timestamp":"1776808416906","event_type":"price_change"}}
