{"capturedAt":1776808416,"payload":{"market":"0x125149c5918fc5f8c6d34682f700a898a1a19ea4f4e2ae68ff4c5794ba657074","price_changes":[{"asset_id":"45936375922793925919605092352922707796689801895417366600539442410775071099958","price":"0.01","size":"12334.83","side":"BUY","hash":"900096615aaaec80af53bc66d759e975eb0c4624","best_bid":"0.86","best_ask":"0.87"},{"asset_id":"86520121088881862182423437128238697252500151785248183602134095101149900014256","price":"0.99","size":"12334.83","side":"SELL","hash":"bc1422e359a2b95d6aa98cbeb7e7519a1da03e3d","best_bid":"0.13","best_ask":"0.14"}],"timestamp":"1776808416907","event_type":"price_change"}}
{"capturedAt":1776808416,"payload":{"market":"0x125149c5918fc5f8c6d34682f700a898a1a19ea4f4e2ae68ff4c5794ba657074","price_changes":[{"asset_id":"45936375922793925919605092352922707796689801895417366600539442410775071099958","price":"0.86","size":"225.71","side":"BUY","hash":"15fe5bc116faf8e6fd46b54231a4ca3d96c9cdb6","best_bid":"0.86","best_ask":"0.87"},{"asset_id":"86520121088881862182423437128238697252500151785248183602134095101149900014256","price":"0.14","size":"225.71","side":"SELL","hash":"093932747d89c2d1b6afe1cfe94d4f07b12b6ce0","best_bid":"0.13","best_ask":"0.14"}],"timestamp":"1776808416909","event_type":"price_change"}}
{"capturedAt":1776808416,"payload":{"market":"0x125149c5918fc5f8c6d34682f700a898a1a19ea4f4e2ae68ff4c5794ba657074","price_changes":[{"asset_id":"45936375922793925919605092352922707796689801895417366600539442410775071099958","price":"0.86","size":"235.71","side":"BUY","hash":"54ac2fa93c202bd1db7320576d00bfed3c31c4a8","best_bid":"0.86","best_ask":"0.87"},{"asset_id":"86520121088881862182423437128238697252500151785248183602134095101149900014256","price":"0.14","size":"235.71","side":"SELL","hash":"859cd3af468ddfcbbc2a3439331838b54e71c988","best_bid":"0.13","best_ask":"0.14"}],"timestamp":"1776808416910","event_type":"price_change"}}
{"capturedAt":1776808416,"payload":{"market":"0x125149c5918fc5f8c6d34682f700a898a1a19ea4f4e2ae68ff4c5794ba657074","price_changes":[{"asset_id":"45936375922793925919605092352922707796689801895417366600539442410775071099958","price":"0.01","size":"12329.83","side":"BUY","hash":"bb992230b90eca5119b50f50f2d489c8904d616e","best_bid":"0.86","best_ask":"0.87"},{"asset_id":"86520121088881862182423437128238697252500151785248183602134095101149900014256","price":"0.99","size":"12329.83","side":"SELL","hash":"07ddbce6d31eddf6eb0b55fa12b724aa8e2a9a8f","best_bid":"0.13","best_ask":"0.14"}],"timestamp":"1776808416934","event_type":"price_change"}}
{"capturedAt":1776808416,"payload":{"market":"0x125149c5918fc5f8c6d34682f700a898a1a19ea4f4e2ae68ff4c5794ba657074","price_changes":[{"asset_id":"45936375922793925919605092352922707796689801895417366600539442410775071099958","price":"0.84","size":"389.37","side":"BUY","hash":"1c860a45599d97f632376338f55f5c24f86b1e83","best_bid":"0.86","best_ask":"0.87"},{"asset_id":"86520121088881862182423437128238697252500151785248183602134095101149900014256","price":"0.16","size":"389.37","side":"SELL","hash":"8bea12c14412ea8d8cf6d1a792b866e6cf480bf7","best_bid":"0.13","best_ask":"0.14"}],"timestamp":"1776808416936","event_type":"price_change"}}
{"capturedAt":1776808416,"payload":{"market":"0x125149c5918fc5f8c6d34682f700a898a1a19ea4f4e2ae68ff4c5794ba657074","price_changes":[{"asset_id":"45936375922793925919605092352922707796689801895417366600539442410775071099958","price":"0.85","size":"437.28","side":"BUY","hash":"1191d103213a47177d50db5ff19bb506df30d270","best_bid":"0.86","best_ask":"0.87"},{"asset_id":"86520121088881862182423437128238697252500151785248183602134095101149900014256","price":"0.15","size":"437.28","side":"SELL","hash":"e60da1e516627db87ddd7ef8712488703dd7955f","best_bid":"0.13","best_ask":"0.14"}],"timestamp":"1776808416937","event_type":"price_change"}}
{"capturedAt":1776808416,"payload":{"market":"0x125149c5918fc5f8c6d34682f700a898a1a19ea4f4e2ae68ff4c5794ba657074","price_changes":[{"asset_id":"45936375922793925919605092352922707796689801895417366600539442410775071099958","price":"0.86","size":"230.43","side":"BUY","hash":"5dac71ff72a6576139e5285689af7e708fd97fdb","best_bid":"0.86","best_ask":"0.87"},{"asset_id":"86520121088881862182423437128238697252500151785248183602134095101149900014256","price":"0.14","size":"230.43","side":"SELL","hash":"e48cc5654ae36ee402027a951e39a7ef0cf5da90","best_bid":"0.13","best_ask":"0.14"}],"timestamp":"1776808416938","event_type":"price_change"}}
{"capturedAt":1776808416,"payload":{"market":"0x125149c5918fc5f8c6d34682f700a898a1a19ea4f4e2ae68ff4c5794ba657074","price_changes":[{"asset_id":"45936375922793925919605092352922707796689801895417366600539442410775071099958","price":"0.86","size":"235.7","side":"BUY","hash":"29abfeaa8b7c53eb4a51c48f4d13f8f63afdbd8e","best_bid":"0.86","best_ask":"0.87"},{"asset_id":"86520121088881862182423437128238697252500151785248183602134095101149900014256","price":"0.14","size":"235.7","side":"SELL","hash":"d31bb012f6a24c1a5dbeb52174f6a2bb0bb6da9a","best_bid":"0.13","best_ask":"0.14"}],"timestamp":"1776808416940","event_type":"price_change"}}
{"capturedAt":1776808416,"payload":{"market":"0x125149c5918fc5f8c6d34682f700a898a1a19ea4f4e2ae68ff4c5794ba657074","price_changes":[{"asset_id":"45936375922793925919605092352922707796689801895417366600539442410775071099958","price":"0.86","size":"229.7","side":"BUY","hash":"438339af7978c2b3b3be205384150ac0bb2f900e","best_bid":"0.86","best_ask":"0.87"},{"asset_id":"86520121088881862182423437128238697252500151785248183602134095101149900014256","price":"0.14","size":"229.7","side":"SELL","hash":"3a6e4b12aeb58c031d734978a6211067ff3b5d23","best_bid":"0.13","best_ask":"0.14"}],"timestamp":"1776808416941","event_type":"price_change"}}
{"capturedAt":1776808416,"payload":{"market":"0x125149c5918fc5f8c6d34682f700a898a1a19ea4f4e2ae68ff4c5794ba657074","price_changes":[{"asset_id":"45936375922793925919605092352922707796689801895417366600539442410775071099958","price":"0.86","size":"219.7","side":"BUY","hash":"cb171ab6c6f437aea56e4f282832c8c5adbcc7de","best_bid":"0.86","best_ask":"0.87"},{"asset_id":"86520121088881862182423437128238697252500151785248183602134095101149900014256","price":"0.14","size":"219.7","side":"SELL","hash":"46aff4fd2d675c403bc2bbe2df7434e8afaaff35","best_bid":"0.13","best_ask":"0.14"}],"timestamp":"1776808416942","event_type":"price_change"}}
{"capturedAt":1776808416,"payload":{"market":"0x125149c5918fc5f8c6d34682f700a898a1a19ea4f4e2ae68ff4c5794ba657074","price_changes":[{"asset_id":"45936375922793925919605092352922707796689801895417366600539442410775071099958","price":"0.01","size":"12334.83","side":"BUY","hash":"87fbae4731de745802628fd5f0db95814aa78522","best_bid":"0.86","best_ask":"0.87"},{"asset_id":"86520121088881862182423437128238697252500151785248183602134095101149900014256","price":"0.99","size":"12334.83","side":"SELL","hash":"1d6bdee74e6d9a1502e6d47090e59cb1bd9961a9","best_bid":"0.13","best_ask":"0.14"}],"timestamp":"1776808416943","event_type":"price_change"}}
{"capturedAt":1776808416,"payload":{"market":"0x125149c5918fc5f8c6d34682f700a898a1a19ea4f4e2ae68ff4c5794ba657074","price_changes":[{"asset_id":"45936375922793925919605092352922707796689801895417366600539442410775071099958","price":"0.86","size":"213.7","side":"BUY","hash":"fa98e5bdc940fe6f4d98d6d136f1fef132bef292","best_bid":"0.86","best_ask":"0.87"},{"asset_id":"86520121088881862182423437128238697252500151785248183602134095101149900014256","price":"0.14","size":"213.7","side":"SELL","hash":"129c14bc1e2e6c2762385d65646df80716ea19d0","best_bid":"0.13","best_ask":"0.14"}],"timestamp":"1776808416944","event_type":"price_change"}}
{"capturedAt":1776808416,"payload":{"market":"0x125149c5918fc5f8c6d34682f700a898a1a19ea4f4e2ae68ff4c5794ba657074","price_changes":[{"asset_id":"45936375922793925919605092352922707796689801895417366600539442410775071099958","price":"0.86","size":"207.7","side":"BUY","hash":"1ffa153479785a39cfed2db35310349dc6cca43b","best_bid":"0.86","best_ask":"0.87"},{"asset_id":"86520121088881862182423437128238697252500151785248183602134095101149900014256","price":"0.14","size":"207.7","side":"SELL","hash":"66b5b0c78e58bac664e49779780ebb53146655f5","best_bid":"0.13","best_ask":"0.14"}],"timestamp":"1776808416945","event_type":"price_change"}}
{"capturedAt":1776808416,"payload":{"market":"0x125149c5918fc5f8c6d34682f700a898a1a19ea4f4e2ae68ff4c5794ba657074","price_changes":[{"asset_id":"45936375922793925919605092352922707796689801895417366600539442410775071099958","price":"0.86","size":"201.7","side":"BUY","hash":"694c200257a9622f3b9f9143488d0fac41e45ad4","best_bid":"0.86","best_ask":"0.87"},{"asset_id":"86520121088881862182423437128238697252500151785248183602134095101149900014256","price":"0.14","size":"201.7","side":"SELL","hash":"4758596c307c66cb57ee839ed7f28455cb9e91fb","best_bid":"0.13","best_ask":"0.14"}],"timestamp":"1776808416946","event_type":"price_change"}}
{"capturedAt":1776808416,"payload":{"market":"0x125149c5918fc5f8c6d34682f700a898a1a19ea4f4e2ae68ff4c5794ba657074","price_changes":[{"asset_id":"45936375922793925919605092352922707796689801895417366600539442410775071099958","price":"0.01","size":"12339.83","side":"BUY","hash":"25665f57447e7c3573c5ecf5f6025f38ed9ae17e","best_bid":"0.86","best_ask":"0.87"},{"asset_id":"86520121088881862182423437128238697252500151785248183602134095101149900014256","price":"0.99","size":"12339.83","side":"SELL","hash":"8c966ae0de3381e59232206e8d685ec9ae72e69d","best_bid":"0.13","best_ask":"0.14"}],"timestamp":"1776808416950","event_type":"price_change"}}
{"capturedAt":1776808416,"payload":{"market":"0x125149c5918fc5f8c6d34682f700a898a1a19ea4f4e2ae68ff4c5794ba657074","price_changes":[{"asset_id":"45936375922793925919605092352922707796689801895417366600539442410775071099958","price":"0.86","size":"196.7","side":"BUY","hash":"596b7246f82919d88fd64b47efe2158c83bc7630","best_bid":"0.86","best_ask":"0.87"},{"asset_id":"86520121088881862182423437128238697252500151785248183602134095101149900014256","price":"0.14","size":"196.7","side":"SELL","hash":"a4bf5dd82450910d74596f70b830c540abff05f2","best_bid":"0.13","best_ask":"0.14"}],"timestamp":"1776808416952","event_type":"price_change"}}
{"capturedAt":1776808416,"payload":{"market":"0x125149c5918fc5f8c6d34682f700a898a1a19ea4f4e2ae68ff4c5794ba657074","price_changes":[{"asset_id":"45936375922793925919605092352922707796689801895417366600539442410775071099958","price":"0.86","size":"190.7","side":"BUY","hash":"9094e229f584d6dbede1f40841cf5edc39bdd14c","best_bid":"0.86","best_ask":"0.87"},{"asset_id":"86520121088881862182423437128238697252500151785248183602134095101149900014256","price":"0.14","size":"190.7","side":"SELL","hash":"5edb9189ca410f3cbad95b46eb9d35b765fced5e","best_bid":"0.13","best_ask":"0.14"}],"timestamp":"1776808416956","event_type":"price_change"}}
{"capturedAt":1776808416,"payload":{"market":"0x125149c5918fc5f8c6d34682f700a898a1a19ea4f4e2ae68ff4c5794ba657074","price_changes":[{"asset_id":"45936375922793925919605092352922707796689801895417366600539442410775071099958","price":"0.86","size":"184.7","side":"BUY","hash":"fa8cc8a2395e560c3814b973f2e54c56a3a96eed","best_bid":"0.86","best_ask":"0.87"},{"asset_id":"86520121088881862182423437128238697252500151785248183602134095101149900014256","price":"0.14","size":"184.7","side":"SELL","hash":"00317afbea701d734033f463b3e728f90c53be5a","best_bid":"0.13","best_ask":"0.14"}],"timestamp":"1776808416960","event_type":"price_change"}}
{"capturedAt":1776808416,"payload":{"market":"0x125149c5918fc5f8c6d34682f700a898a1a19ea4f4e2ae68ff4c5794ba657074","price_changes":[{"asset_id":"45936375922793925919605092352922707796689801895417366600539442410775071099958","price":"0.01","size":"12334.83","side":"BUY","hash":"7a08393f3e2da8f95deb55a30159a4e91cec4e4c","best_bid":"0.86","best_ask":"0.87"},{"asset_id":"86520121088881862182423437128238697252500151785248183602134095101149900014256","price":"0.99","size":"12334.83","side":"SELL","hash":"76e655a1f9bfbda59d19149cb89190933f74835c","best_bid":"0.13","best_ask":"0.14"}],"timestamp":"1776808416962","event_type":"price_change"}}
{"capturedAt":1776808416,"payload":{"market":"0x125149c5918fc5f8c6d34682f700a898a1a19ea4f4e2ae68ff4c5794ba657074","price_changes":[{"asset_id":"45936375922793925919605092352922707796689801895417366600539442410775071099958","price":"0.86","size":"190.7","side":"BUY","hash":"886a7d874f1e6fd30d5415d061956fafd2e3dff6","best_bid":"0.86","best_ask":"0.87"},{"asset_id":"86520121088881862182423437128238697252500151785248183602134095101149900014256","price":"0.14","size":"190.7","side":"SELL","hash":"9b19771286a595b12d459cb559d42423081551cc","best_bid":"0.13","best_ask":"0.14"}],"timestamp":"1776808416963","event_type":"price_change"}}
{"capturedAt":1776808416,"payload":{"market":"0x125149c5918fc5f8c6d34682f700a898a1a19ea4f4e2ae68ff4c5794ba657074","price_changes":[{"asset_id":"45936375922793925919605092352922707796689801895417366600539442410775071099958","price":"0.86","size":"184.7","side":"BUY","hash":"3ad934596064883bdd250ed1e01e7b2ecf299d1a","best_bid":"0.86","best_ask":"0.87"},{"asset_id":"86520121088881862182423437128238697252500151785248183602134095101149900014256","price":"0.14","size":"184.7","side":"SELL","hash":"17674142d3d1c9f6179609b1d3e48ad8af53ba62","best_bid":"0.13","best_ask":"0.14"}],"timestamp":"1776808416964","event_type":"price_change"}}
{"capturedAt":1776808416,"payload":{"market":"0x125149c5918fc5f8c6d34682f700a898a1a19ea4f4e2ae68ff4c5794ba657074","price_changes":[{"asset_id":"45936375922793925919605092352922707796689801895417366600539442410775071099958","price":"0.86","size":"190.7","side":"BUY","hash":"53438bf96356eb1c550c561f810be6a2e8b562aa","best_bid":"0.86","best_ask":"0.87"},{"asset_id":"86520121088881862182423437128238697252500151785248183602134095101149900014256","price":"0.14","size":"190.7","side":"SELL","hash":"a3b94a3a5d77e52fbcad269e16b1aa325d271036","best_bid":"0.13","best_ask":"0.14"}],"timestamp":"1776808416968","event_type":"price_change"}}
{"capturedAt":1776808416,"payload":{"market":"0x125149c5918fc5f8c6d34682f700a898a1a19ea4f4e2ae68ff4c5794ba657074","price_changes":[{"asset_id":"45936375922793925919605092352922707796689801895417366600539442410775071099958","price":"0.01","size":"12329.83","side":"BUY","hash":"71b6b743807088645ce95aab2beb7da56fa10cf4","best_bid":"0.86","best_ask":"0.87"},{"asset_id":"86520121088881862182423437128238697252500151785248183602134095101149900014256","price":"0.99","size":"12329.83","side":"SELL","hash":"e5781a2c6fb72fb8b159eec0d459e9117bce6040","best_bid":"0.13","best_ask":"0.14"}],"timestamp":"1776808416969","event_type":"price_change"}}
{"capturedAt":1776808416,"payload":{"market":"0x125149c5918fc5f8c6d34682f700a898a1a19ea4f4e2ae68ff4c5794ba657074","price_changes":[{"asset_id":"45936375922793925919605092352922707796689801895417366600539442410775071099958","price":"0.86","size":"202.7","side":"BUY","hash":"8f7bdd7484027dc25fc51e0415c9187b227d696f","best_bid":"0.86","best_ask":"0.87"},{"asset_id":"86520121088881862182423437128238697252500151785248183602134095101149900014256","price":"0.14","size":"202.7","side":"SELL","hash":"6f9a3b81b361ad7c4df1aeff001887f927758ce3","best_bid":"0.13","best_ask":"0.14"}],"timestamp":"1776808416973","event_type":"price_change"}}
{"capturedAt":1776808416,"payload":{"market":"0x125149c5918fc5f8c6d34682f700a898a1a19ea4f4e2ae68ff4c5794ba657074","price_changes":[{"asset_id":"45936375922793925919605092352922707796689801895417366600539442410775071099958","price":"0.86","size":"197.7","side":"BUY","hash":"c5fe7342111a227d5dc3cbc9ac0b81789e6ad0f0","best_bid":"0.86","best_ask":"0.87"},{"asset_id":"86520121088881862182423437128238697252500151785248183602134095101149900014256","price":"0.14","size":"197.7","side":"SELL","hash":"b76f3a7298b6e5cd6ce5b492fdcc51918fbda267","best_bid":"0.13","best_ask":"0.14"}],"timestamp":"1776808416970","event_type":"price_change"}}
{"capturedAt":1776808416,"payload":{"market":"0x125149c5918fc5f8c6d34682f700a898a1a19ea4f4e2ae68ff4c5794ba657074","price_changes":[{"asset_id":"45936375922793925919605092352922707796689801895417366600539442410775071099958","price":"0.86","size":"207.7","side":"BUY","hash":"15455beaf946814f311930f77f5831d806cd8a58","best_bid":"0.86","best_ask":"0.87"},{"asset_id":"86520121088881862182423437128238697252500151785248183602134095101149900014256","price":"0.14","size":"207.7","side":"SELL","hash":"f4275dca5c63c13a6500afa2fe7e73890966dbea","best_bid":"0.13","best_ask":"0.14"}],"timestamp":"1776808416972","event_type":"price_change"}}
{"capturedAt":1776808416,"payload":{"market":"0x125149c5918fc5f8c6d34682f700a898a1a19ea4f4e2ae68ff4c5794ba657074","price_changes":[{"asset_id":"45936375922793925919605092352922707796689801895417366600539442410775071099958","price":"0.86","size":"208.7","side":"BUY","hash":"6ce188baa6902beeb4983f8d4bda0a8e8bf8f949","best_bid":"0.86","best_ask":"0.87"},{"asset_id":"86520121088881862182423437128238697252500151785248183602134095101149900014256","price":"0.14","size":"208.7","side":"SELL","hash":"d2922ff7a6339f77cb98f93dd75f6af0e624d6f8","best_bid":"0.13","best_ask":"0.14"}],"timestamp":"1776808416975","event_type":"price_change"}}
{"capturedAt":1776808416,"payload":{"market":"0x125149c5918fc5f8c6d34682f700a898a1a19ea4f4e2ae68ff4c5794ba657074","price_changes":[{"asset_id":"45936375922793925919605092352922707796689801895417366600539442410775071099958","price":"0.86","size":"213.7","side":"BUY","hash":"ae036027ca1643df36c9598892945c93c441a0e9","best_bid":"0.86","best_ask":"0.87"},{"asset_id":"86520121088881862182423437128238697252500151785248183602134095101149900014256","price":"0.14","size":"213.7","side":"SELL","hash":"e7be30d8f1724d7c733cbb7addcb973b69d9aa3c","best_bid":"0.13","best_ask":"0.14"}],"timestamp":"1776808416978","event_type":"price_change"}}
{"capturedAt":1776808416,"payload":{"market":"0x125149c5918fc5f8c6d34682f700a898a1a19ea4f4e2ae68ff4c5794ba657074","price_changes":[{"asset_id":"45936375922793925919605092352922707796689801895417366600539442410775071099958","price":"0.86","size":"207.7","side":"BUY","hash":"d76ffceb16aa6fe1c5f3ff405707d43620e36ecf","best_bid":"0.86","best_ask":"0.87"},{"asset_id":"86520121088881862182423437128238697252500151785248183602134095101149900014256","price":"0.14","size":"207.7","side":"SELL","hash":"93b3cb52a50beebb62a2a49f110739c4325b21bd","best_bid":"0.13","best_ask":"0.14"}],"timestamp":"1776808416979","event_type":"price_change"}}
{"capturedAt":1776808417,"payload":{"market":"0x125149c5918fc5f8c6d34682f700a898a1a19ea4f4e2ae68ff4c5794ba657074","price_changes":[{"asset_id":"45936375922793925919605092352922707796689801895417366600539442410775071099958","price":"0.86","size":"201.7","side":"BUY","hash":"38667deb3f12994fd645ab372d6f4a243f477d50","best_bid":"0.86","best_ask":"0.87"},{"asset_id":"86520121088881862182423437128238697252500151785248183602134095101149900014256","price":"0.14","size":"201.7","side":"SELL","hash":"eb9e4da29b168d01de12bfeae7680e85ca3b7dc6","best_bid":"0.13","best_ask":"0.14"}],"timestamp":"1776808416982","event_type":"price_change"}}
{"capturedAt":1776808417,"payload":{"market":"0x125149c5918fc5f8c6d34682f700a898a1a19ea4f4e2ae68ff4c5794ba657074","price_changes":[{"asset_id":"45936375922793925919605092352922707796689801895417366600539442410775071099958","price":"0.01","size":"12334.83","side":"BUY","hash":"06cfdb1bed6b17cdb35a7309782416509e3f3597","best_bid":"0.86","best_ask":"0.87"},{"asset_id":"86520121088881862182423437128238697252500151785248183602134095101149900014256","price":"0.99","size":"12334.83","side":"SELL","hash":"2ac59162e8482d01bf1a9230ef1f6c982b70e8c4","best_bid":"0.13","best_ask":"0.14"}],"timestamp":"1776808416989","event_type":"price_change"}}
{"capturedAt":1776808417,"payload":{"market":"0x125149c5918fc5f8c6d34682f700a898a1a19ea4f4e2ae68ff4c5794ba657074","price_changes":[{"asset_id":"45936375922793925919605092352922707796689801895417366600539442410775071099958","price":"0.86","size":"191.7","side":"BUY","hash":"f0d7e82c28b7572670a4c9c0bdc1fb93f7b127e0","best_bid":"0.86","best_ask":"0.87"},{"asset_id":"86520121088881862182423437128238697252500151785248183602134095101149900014256","price":"0.14","size":"191.7","side":"SELL","hash":"6081dd0acc5dec06fc2955a05e1ae2952d9c31ac","best_bid":"0.13","best_ask":"0.14"}],"timestamp":"1776808416984","event_type":"price_change"}}
{"capturedAt":1776808417,"payload":{"market":"0x125149c5918fc5f8c6d34682f700a898a1a19ea4f4e2ae68ff4c5794ba657074","price_changes":[{"asset_id":"45936375922793925919605092352922707796689801895417366600539442410775071099958","price":"0.86","size":"193.7","side":"BUY","hash":"e2eee51a7dfdef286d27061c2eab41f41d1363c2","best_bid":"0.86","best_ask":"0.87"},{"asset_id":"86520121088881862182423437128238697252500151785248183602134095101149900014256","price":"0.14","size":"193.7","side":"SELL","hash":"8b02df13dfd51e7f11d3e61c36dc749bee887e31","best_bid":"0.13","best_ask":"0.14"}],"timestamp":"1776808416990","event_type":"price_change"}}
{"capturedAt":1776808417,"payload":{"market":"0x125149c5918fc5f8c6d34682f700a898a1a19ea4f4e2ae68ff4c5794ba657074","price_changes":[{"asset_id":"45936375922793925919605092352922707796689801895417366600539442410775071099958","price":"0.01","size":"12339.83","side":"BUY","hash":"74a1602e149e98e4ca08b2e44aaa7892fc9a4e48","best_bid":"0.86","best_ask":"0.87"},{"asset_id":"86520121088881862182423437128238697252500151785248183602134095101149900014256","price":"0.99","size":"12339.83","side":"SELL","hash":"2de5d867407c4f656b00082f877c3e7985daa067","best_bid":"0.13","best_ask":"0.14"}],"timestamp":"1776808417000","event_type":"price_change"}}
{"capturedAt":1776808417,"payload":{"market":"0x125149c5918fc5f8c6d34682f700a898a1a19ea4f4e2ae68ff4c5794ba657074","price_changes":[{"asset_id":"86520121088881862182423437128238697252500151785248183602134095101149900014256","price":"0.13","size":"132.24","side":"BUY","hash":"cd3e473e401878c42af5b1847a3fa730ffd9e938","best_bid":"0.13","best_ask":"0.14"},{"asset_id":"45936375922793925919605092352922707796689801895417366600539442410775071099958","price":"0.87","size":"132.24","side":"SELL","hash":"576cd9c811f64640f7d4d077a8a0448f4714a361","best_bid":"0.86","best_ask":"0.87"}],"timestamp":"1776808416991","event_type":"price_change"}}
{"capturedAt":1776808417,"payload":{"market":"0x125149c5918fc5f8c6d34682f700a898a1a19ea4f4e2ae68ff4c5794ba657074","price_changes":[{"asset_id":"45936375922793925919605092352922707796689801895417366600539442410775071099958","price":"0.86","size":"211.7","side":"BUY","hash":"e18f0578ce77f1bdd6a2f0133f6b1b9a1ac25914","best_bid":"0.86","best_ask":"0.87"},{"asset_id":"86520121088881862182423437128238697252500151785248183602134095101149900014256","price":"0.14","size":"211.7","side":"SELL","hash":"ad72b099291b7fe17f37ba65847ca93ea5f96b27","best_bid":"0.13","best_ask":"0.14"}],"timestamp":"1776808417006","event_type":"price_change"}}
{"capturedAt":1776808417,"payload":{"market":"0x125149c5918fc5f8c6d34682f700a898a1a19ea4f4e2ae68ff4c5794ba657074","price_changes":[{"asset_id":"45936375922793925919605092352922707796689801895417366600539442410775071099958","price":"0.86","size":"199.7","side":"BUY","hash":"a1369a5b6a46d32328a7b0f5fd8990993b689568","best_bid":"0.86","best_ask":"0.87"},{"asset_id":"86520121088881862182423437128238697252500151785248183602134095101149900014256","price":"0.14","size":"199.7","side":"SELL","hash":"e3197e4c4042b248a387cda3af3190a3e368ee62","best_bid":"0.13","best_ask":"0.14"}],"timestamp":"1776808416993","event_type":"price_change"}}
{"capturedAt":1776808417,"payload":{"market":"0x125149c5918fc5f8c6d34682f700a898a1a19ea4f4e2ae68ff4c5794ba657074","price_changes":[{"asset_id":"86520121088881862182423437128238697252500151785248183602134095101149900014256","price":"0.12","size":"370","side":"BUY","hash":"69ab9ee61574a26dc36ab148274d5db480256726","best_bid":"0.13","best_ask":"0.14"},{"asset_id":"45936375922793925919605092352922707796689801895417366600539442410775071099958","price":"0.88","size":"370","side":"SELL","hash":"f7b7f15d6264ef9eb065f8e8bd8f09fd08891a15","best_bid":"0.86","best_ask":"0.87"}],"timestamp":"1776808417009","event_type":"price_change"}}
{"capturedAt":1776808417,"payload":{"market":"0x125149c5918fc5f8c6d34682f700a898a1a19ea4f4e2ae68ff4c5794ba657074","price_changes":[{"asset_id":"45936375922793925919605092352922707796689801895417366600539442410775071099958","price":"0.86","size":"187.7","side":"BUY","hash":"a3c715c4afacc49c644b40858c526e13cd608563","best_bid":"0.86","best_ask":"0.87"},{"asset_id":"86520121088881862182423437128238697252500151785248183602134095101149900014256","price":"0.14","size":"187.7","side":"SELL","hash":"26e9d6a4bcaa80a2688751fb0f6eb25296595d99","best_bid":"0.13","best_ask":"0.14"}],"timestamp":"1776808416987","event_type":"price_change"}}
{"capturedAt":1776808417,"payload":{"market":"0x125149c5918fc5f8c6d34682f700a898a1a19ea4f4e2ae68ff4c5794ba657074","price_changes":[{"asset_id":"45936375922793925919605092352922707796689801895417366600539442410775071099958","price":"0.01","size":"12334.83","side":"BUY","hash":"fa7d3f85d15bac4aa0152caaea40727ab17046f4","best_bid":"0.86","best_ask":"0.87"},{"asset_id":"86520121088881862182423437128238697252500151785248183602134095101149900014256","price":"0.99","size":"12334.83","side":"SELL","hash":"6592485372541b6a57067ed5be842a2caca1a989","best_bid":"0.13","best_ask":"0.14"}],"timestamp":"1776808417012","event_type":"price_change"}}
{"capturedAt":1776808417,"payload":{"market":"0x125149c5918fc5f8c6d34682f700a898a1a19ea4f4e2ae68ff4c5794ba657074","price_changes":[{"asset_id":"45936375922793925919605092352922707796689801895417366600539442410775071099958","price":"0.86","size":"218.7","side":"BUY","hash":"486122f3c96b49e12c189e9b170f4be466ba5690","best_bid":"0.86","best_ask":"0.87"},{"asset_id":"86520121088881862182423437128238697252500151785248183602134095101149900014256","price":"0.14","size":"218.7","side":"SELL","hash":"c2d6a9cef00a906fde234028e96201a0c22cbbb8","best_bid":"0.13","best_ask":"0.14"}],"timestamp":"1776808417008","event_type":"price_change"}}
{"capturedAt":1776808417,"payload":{"market":"0x125149c5918fc5f8c6d34682f700a898a1a19ea4f4e2ae68ff4c5794ba657074","price_changes":[{"asset_id":"45936375922793925919605092352922707796689801895417366600539442410775071099958","price":"0.86","size":"204.7","side":"BUY","hash":"2072ae9443d9e923f9dcc15f96b6ea032aeb1fe4","best_bid":"0.86","best_ask":"0.87"},{"asset_id":"86520121088881862182423437128238697252500151785248183602134095101149900014256","price":"0.14","size":"204.7","side":"SELL","hash":"81c77e51330bf2b40d85cd9fb358aae76fcd9b71","best_bid":"0.13","best_ask":"0.14"}],"timestamp":"1776808417003","event_type":"price_change"}}
{"capturedAt":1776808417,"payload":{"market":"0x125149c5918fc5f8c6d34682f700a898a1a19ea4f4e2ae68ff4c5794ba657074","price_changes":[{"asset_id":"45936375922793925919605092352922707796689801895417366600539442410775071099958","price":"0.01","size":"12329.83","side":"BUY","hash":"3c7b1d5479c6fb9e72c3fac17e089a76818db548","best_bid":"0.86","best_ask":"0.87"},{"asset_id":"86520121088881862182423437128238697252500151785248183602134095101149900014256","price":"0.99","size":"12329.83","side":"SELL","hash":"39e01bb78785d78a324f1f6eba6b19615f0ab24d","best_bid":"0.13","best_ask":"0.14"}],"timestamp":"1776808417014","event_type":"price_change"}}
{"capturedAt":1776808417,"payload":{"market":"0x125149c5918fc5f8c6d34682f700a898a1a19ea4f4e2ae68ff4c5794ba657074","price_changes":[{"asset_id":"45936375922793925919605092352922707796689801895417366600539442410775071099958","price":"0.73","size":"211.3","side":"BUY","hash":"637d8201886214a40c2328f1c4cf2398906aef5e","best_bid":"0.86","best_ask":"0.87"},{"asset_id":"86520121088881862182423437128238697252500151785248183602134095101149900014256","price":"0.27","size":"211.3","side":"SELL","hash":"9b982e81a5719e3ad439ff84e1b31e8b94097efe","best_bid":"0.13","best_ask":"0.14"}],"timestamp":"1776808417019","event_type":"price_change"}}
{"capturedAt":1776808417,"payload":{"market":"0x125149c5918fc5f8c6d34682f700a898a1a19ea4f4e2ae68ff4c5794ba657074","price_changes":[{"asset_id":"45936375922793925919605092352922707796689801895417366600539442410775071099958","price":"0.86","size":"228.7","side":"BUY","hash":"9d6d8a73d6ede00060bc9714c968f908c30b0e5a","best_bid":"0.86","best_ask":"0.87"},{"asset_id":"86520121088881862182423437128238697252500151785248183602134095101149900014256","price":"0.14","size":"228.7","side":"SELL","hash":"5cdb29babcb37ed71fd700f10cf388fbae6bba5a","best_bid":"0.13","best_ask":"0.14"}],"timestamp":"1776808417015","event_type":"price_change"}}
{"capturedAt":1776808417,"payload":{"market":"0x125149c5918fc5f8c6d34682f700a898a1a19ea4f4e2ae68ff4c5794ba657074","price_changes":[{"asset_id":"45936375922793925919605092352922707796689801895417366600539442410775071099958","price":"0.86","size":"238.7","side":"BUY","hash":"14f090ec91db6540fc01fbc53fbaf6d015b8359e","best_bid":"0.86","best_ask":"0.87"},{"asset_id":"86520121088881862182423437128238697252500151785248183602134095101149900014256","price":"0.14","size":"238.7","side":"SELL","hash":"8844e2bf349c4ec32cb8aa18a136ed9df17ddfeb","best_bid":"0.13","best_ask":"0.14"}],"timestamp":"1776808417017","event_type":"price_change"}}
{"capturedAt":1776808417,"payload":{"market":"0x125149c5918fc5f8c6d34682f700a898a1a19ea4f4e2ae68ff4c5794ba657074","price_changes":[{"asset_id":"45936375922793925919605092352922707796689801895417366600539442410775071099958","price":"0.86","size":"232.7","side":"BUY","hash":"5d10d07f96d6b393d267ee8388df5e7a83e1f28a","best_bid":"0.86","best_ask":"0.87"},{"asset_id":"86520121088881862182423437128238697252500151785248183602134095101149900014256","price":"0.14","size":"232.7","side":"SELL","hash":"cef8fae7c9991819c35ca445326aa09c22519240","best_bid":"0.13","best_ask":"0.14"}],"timestamp":"1776808417032","event_type":"price_change"}}
{"capturedAt":1776808417,"payload":{"market":"0x125149c5918fc5f8c6d34682f700a898a1a19ea4f4e2ae68ff4c5794ba657074","price_changes":[{"asset_id":"45936375922793925919605092352922707796689801895417366600539442410775071099958","price":"0.01","size":"12324.83","side":"BUY","hash":"eee729359e5536f3f9b740cddd35c3855d443909","best_bid":"0.86","best_ask":"0.87"},{"asset_id":"86520121088881862182423437128238697252500151785248183602134095101149900014256","price":"0.99","size":"12324.83","side":"SELL","hash":"75d7f81d83e38baa62de5a44230bc7b020c6baaa","best_bid":"0.13","best_ask":"0.14"}],"timestamp":"1776808417020","event_type":"price_change"}}
{"capturedAt":1776808417,"payload":{"market":"0x125149c5918fc5f8c6d34682f700a898a1a19ea4f4e2ae68ff4c5794ba657074","price_changes":[{"asset_id":"86520121088881862182423437128238697252500151785248183602134095101149900014256","price":"0.01","size":"12912.69","side":"BUY","hash":"38b7b0cdae4dd5711de5b74e24faf21247a43331","best_bid":"0.13","best_ask":"0.14"},{"asset_id":"45936375922793925919605092352922707796689801895417366600539442410775071099958","price":"0.99","size":"12912.69","side":"SELL","hash":"7ce248bf6ac624272f4c14baf52160a47b948766","best_bid":"0.86","best_ask":"0.87"}],"timestamp":"1776808417045","event_type":"price_change"}}
{"capturedAt":1776808417,"payload":{"market":"0x125149c5918fc5f8c6d34682f700a898a1a19ea4f4e2ae68ff4c5794ba657074","price_changes":[{"asset_id":"45936375922793925919605092352922707796689801895417366600539442410775071099958","price":"0.86","size":"219.7","side":"BUY","hash":"38632aceb7a52b1c98ab95d28f492f355e1eae64","best_bid":"0.86","best_ask":"0.87"},{"asset_id":"86520121088881862182423437128238697252500151785248183602134095101149900014256","price":"0.14","size":"219.7","side":"SELL","hash":"c0e0b8400802b210d18aff31df06025a27975e54","best_bid":"0.13","best_ask":"0.14"}],"timestamp":"1776808417042","event_type":"price_change"}}
{"capturedAt":1776808417,"payload":{"market":"0x125149c5918fc5f8c6d34682f700a898a1a19ea4f4e2ae68ff4c5794ba657074","price_changes":[{"asset_id":"45936375922793925919605092352922707796689801895417366600539442410775071099958","price":"0.86","size":"197.7","side":"BUY","hash":"0160c9c288a348f5f18c6d49a3039a84ce542e0e","best_bid":"0.86","best_ask":"0.87"},{"asset_id":"86520121088881862182423437128238697252500151785248183602134095101149900014256","price":"0.14","size":"197.7","side":"SELL","hash":"312f75ca96d649cec48e84465c8cd59e53f304b1","best_bid":"0.13","best_ask":"0.14"}],"timestamp":"1776808416985","event_type":"price_change"}}
{"capturedAt":1776808417,"payload":{"market":"0x125149c5918fc5f8c6d34682f700a898a1a19ea4f4e2ae68ff4c5794ba657074","price_changes":[{"asset_id":"45936375922793925919605092352922707796689801895417366600539442410775071099958","price":"0.86","size":"198.7","side":"BUY","hash":"0bec9bcef50aa71318668d2eaafce5ccc883074b","best_bid":"0.86","best_ask":"0.87"},{"asset_id":"86520121088881862182423437128238697252500151785248183602134095101149900014256","price":"0.14","size":"198.7","side":"SELL","hash":"55d3bc1665ca3e562b5d2d953ce34ab7bd1d85ad","best_bid":"0.13","best_ask":"0.14"}],"timestamp":"1776808417048","event_type":"price_change"}}
{"capturedAt":1776808417,"payload":{"market":"0x125149c5918fc5f8c6d34682f700a898a1a19ea4f4e2ae68ff4c5794ba657074","price_changes":[{"asset_id":"45936375922793925919605092352922707796689801895417366600539442410775071099958","price":"0.86","size":"209.7","side":"BUY","hash":"c8d0e692251bc138ff1d2b5888664e43bf2e44fb","best_bid":"0.86","best_ask":"0.87"},{"asset_id":"86520121088881862182423437128238697252500151785248183602134095101149900014256","price":"0.14","size":"209.7","side":"SELL","hash":"11aa95ccaa0227d2b9cccb1b4bb4ad6f9e57d668","best_bid":"0.13","best_ask":"0.14"}],"timestamp":"1776808417045","event_type":"price_change"}}
{"capturedAt":1776808417,"payload":{"market":"0x125149c5918fc5f8c6d34682f700a898a1a19ea4f4e2ae68ff4c5794ba657074","price_changes":[{"asset_id":"45936375922793925919605092352922707796689801895417366600539442410775071099958","price":"0.86","size":"226.7","side":"BUY","hash":"071a4c90f11bcd674574b15077307052c2a5b211","best_bid":"0.86","best_ask":"0.87"},{"asset_id":"86520121088881862182423437128238697252500151785248183602134095101149900014256","price":"0.14","size":"226.7","side":"SELL","hash":"bf7bb0e6574c986944a173ff77c203feba137afa","best_bid":"0.13","best_ask":"0.14"}],"timestamp":"1776808417039","event_type":"price_change"}}
{"capturedAt":1776808417,"payload":{"market":"0x125149c5918fc5f8c6d34682f700a898a1a19ea4f4e2ae68ff4c5794ba657074","price_changes":[{"asset_id":"45936375922793925919605092352922707796689801895417366600539442410775071099958","price":"0.73","size":"217.3","side":"BUY","hash":"404987677f009b4a24af13812540d94b1dfa891c","best_bid":"0.86","best_ask":"0.87"},{"asset_id":"86520121088881862182423437128238697252500151785248183602134095101149900014256","price":"0.27","size":"217.3","side":"SELL","hash":"de63d42145a7487baa0debdf0b047226588ce01b","best_bid":"0.13","best_ask":"0.14"}],"timestamp":"1776808417049","event_type":"price_change"}}
{"capturedAt":1776808417,"payload":{"market":"0x125149c5918fc5f8c6d34682f700a898a1a19ea4f4e2ae68ff4c5794ba657074","price_changes":[{"asset_id":"45936375922793925919605092352922707796689801895417366600539442410775071099958","price":"0.01","size":"12329.83","side":"BUY","hash":"08a884783deb0c1703b257a1793cda49b97ceb13","best_bid":"0.86","best_ask":"0.87"},{"asset_id":"86520121088881862182423437128238697252500151785248183602134095101149900014256","price":"0.99","size":"12329.83","side":"SELL","hash":"3897f2e682c1609832b95c7871b26379b4665fbc","best_bid":"0.13","best_ask":"0.14"}],"timestamp":"1776808417037","event_type":"price_change"}}
{"capturedAt":1776808417,"payload":{"market":"0x125149c5918fc5f8c6d34682f700a898a1a19ea4f4e2ae68ff4c5794ba657074","price_changes":[{"asset_id":"45936375922793925919605092352922707796689801895417366600539442410775071099958","price":"0.01","size":"12334.83","side":"BUY","hash":"7b5a2fa683fe7def944e4e1e0bc4afb30fbb3ba6","best_bid":"0.86","best_ask":"0.87"},{"asset_id":"86520121088881862182423437128238697252500151785248183602134095101149900014256","price":"0.99","size":"12334.83","side":"SELL","hash":"962ce833747791e35b13e8c290d1e9a93502eeb4","best_bid":"0.13","best_ask":"0.14"}],"timestamp":"1776808417051","event_type":"price_change"}}
{"capturedAt":1776808417,"payload":{"market":"0x125149c5918fc5f8c6d34682f700a898a1a19ea4f4e2ae68ff4c5794ba657074","price_changes":[{"asset_id":"45936375922793925919605092352922707796689801895417366600539442410775071099958","price":"0.86","size":"203.7","side":"BUY","hash":"f1eeb1b527916e9ac4569ce4021dc895150e2cd6","best_bid":"0.86","best_ask":"0.87"},{"asset_id":"86520121088881862182423437128238697252500151785248183602134095101149900014256","price":"0.14","size":"203.7","side":"SELL","hash":"2630099cfa616252ad27e427e727c9747d334e7c","best_bid":"0.13","best_ask":"0.14"}],"timestamp":"1776808417047","event_type":"price_change"}}
{"capturedAt":1776808417,"payload":{"market":"0x125149c5918fc5f8c6d34682f700a898a1a19ea4f4e2ae68ff4c5794ba657074","price_changes":[{"asset_id":"45936375922793925919605092352922707796689801895417366600539442410775071099958","price":"0.01","size":"12329.83","side":"BUY","hash":"01fd167567776d4b1240e3a5220db0ea1971d796","best_bid":"0.86","best_ask":"0.87"},{"asset_id":"86520121088881862182423437128238697252500151785248183602134095101149900014256","price":"0.99","size":"12329.83","side":"SELL","hash":"2684e4df3b0f3b4ddaa72877e85fe88bc7fdb08d","best_bid":"0.13","best_ask":"0.14"}],"timestamp":"1776808417055","event_type":"price_change"}}
{"capturedAt":1776808417,"payload":{"market":"0x125149c5918fc5f8c6d34682f700a898a1a19ea4f4e2ae68ff4c5794ba657074","price_changes":[{"asset_id":"45936375922793925919605092352922707796689801895417366600539442410775071099958","price":"0.86","size":"192.7","side":"BUY","hash":"72436e320800d4d727017af7361557040e0b12a4","best_bid":"0.86","best_ask":"0.87"},{"asset_id":"86520121088881862182423437128238697252500151785248183602134095101149900014256","price":"0.14","size":"192.7","side":"SELL","hash":"353887e9d11d45f5c53ea33215f8a7ae577b22b4","best_bid":"0.13","best_ask":"0.14"}],"timestamp":"1776808417056","event_type":"price_change"}}
{"capturedAt":1776808417,"payload":{"market":"0x125149c5918fc5f8c6d34682f700a898a1a19ea4f4e2ae68ff4c5794ba657074","price_changes":[{"asset_id":"45936375922793925919605092352922707796689801895417366600539442410775071099958","price":"0.86","size":"185.7","side":"BUY","hash":"b52a14e51d91f7c875a78a27bae3c8ae52d198c5","best_bid":"0.86","best_ask":"0.87"},{"asset_id":"86520121088881862182423437128238697252500151785248183602134095101149900014256","price":"0.14","size":"185.7","side":"SELL","hash":"7ad984d73417434e9eb42156f94969958e4bddb6","best_bid":"0.13","best_ask":"0.14"}],"timestamp":"1776808417064","event_type":"price_change"}}
{"capturedAt":1776808417,"payload":{"market":"0x125149c5918fc5f8c6d34682f700a898a1a19ea4f4e2ae68ff4c5794ba657074","price_changes":[{"asset_id":"86520121088881862182423437128238697252500151785248183602134095101149900014256","price":"0.13","size":"137.24","side":"BUY","hash":"5937f42a5743c651246b017c724149457ad5951c","best_bid":"0.13","best_ask":"0.14"},{"asset_id":"45936375922793925919605092352922707796689801895417366600539442410775071099958","price":"0.87","size":"137.24","side":"SELL","hash":"91faa90f4cc9daa8e8332c523bd1fe1f8f9deccc","best_bid":"0.86","best_ask":"0.87"}],"timestamp":"1776808417066","event_type":"price_change"}}
{"capturedAt":1776808417,"payload":{"market":"0x125149c5918fc5f8c6d34682f700a898a1a19ea4f4e2ae68ff4c5794ba657074","price_changes":[{"asset_id":"45936375922793925919605092352922707796689801895417366600539442410775071099958","price":"0.86","size":"190.7","side":"BUY","hash":"1c364d85e51bfbc31f574e3dd164443cdc88e2b0","best_bid":"0.86","best_ask":"0.87"},{"asset_id":"86520121088881862182423437128238697252500151785248183602134095101149900014256","price":"0.14","size":"190.7","side":"SELL","hash":"b146603a1a42b0ebdedfea416bb3348444997ca8","best_bid":"0.13","best_ask":"0.14"}],"timestamp":"1776808417067","event_type":"price_change"}}
{"capturedAt":1776808417,"payload":{"market":"0x125149c5918fc5f8c6d34682f700a898a1a19ea4f4e2ae68ff4c5794ba657074","price_changes":[{"asset_id":"45936375922793925919605092352922707796689801895417366600539442410775071099958","price":"0.86","size":"185.7","side":"BUY","hash":"f91109b4a1dedf49c4d7840d911d51d8d24310cc","best_bid":"0.86","best_ask":"0.87"},{"asset_id":"86520121088881862182423437128238697252500151785248183602134095101149900014256","price":"0.14","size":"185.7","side":"SELL","hash":"617a2512c252b02c5c5eae1545452e425ebca04e","best_bid":"0.13","best_ask":"0.14"}],"timestamp":"1776808417071","event_type":"price_change"}}
{"capturedAt":1776808417,"payload":{"market":"0x125149c5918fc5f8c6d34682f700a898a1a19ea4f4e2ae68ff4c5794ba657074","price_changes":[{"asset_id":"45936375922793925919605092352922707796689801895417366600539442410775071099958","price":"0.86","size":"191.7","side":"BUY","hash":"4954dbd43a956a37f7b3034b0afd272e1ab4acc6","best_bid":"0.86","best_ask":"0.87"},{"asset_id":"86520121088881862182423437128238697252500151785248183602134095101149900014256","price":"0.14","size":"191.7","side":"SELL","hash":"74120633731b3d67c62d371f8470da1d67fb6a0d","best_bid":"0.13","best_ask":"0.14"}],"timestamp":"1776808417062","event_type":"price_change"}}
{"capturedAt":1776808417,"payload":{"market":"0x125149c5918fc5f8c6d34682f700a898a1a19ea4f4e2ae68ff4c5794ba657074","price_changes":[{"asset_id":"45936375922793925919605092352922707796689801895417366600539442410775071099958","price":"0.01","size":"12324.83","side":"BUY","hash":"23a58792259d91385981bfb34d769bae34fd9859","best_bid":"0.86","best_ask":"0.87"},{"asset_id":"86520121088881862182423437128238697252500151785248183602134095101149900014256","price":"0.99","size":"12324.83","side":"SELL","hash":"9f8a1541e0d4e47476225d1a7ce84b61bea90e4a","best_bid":"0.13","best_ask":"0.14"}],"timestamp":"1776808417070","event_type":"price_change"}}
{"capturedAt":1776808417,"payload":{"market":"0x125149c5918fc5f8c6d34682f700a898a1a19ea4f4e2ae68ff4c5794ba657074","price_changes":[{"asset_id":"86520121088881862182423437128238697252500151785248183602134095101149900014256","price":"0.12","size":"365","side":"BUY","hash":"e8a9882fcf87b8b22f6e3ac7a3fdd0ca38907c00","best_bid":"0.13","best_ask":"0.14"},{"asset_id":"45936375922793925919605092352922707796689801895417366600539442410775071099958","price":"0.88","size":"365","side":"SELL","hash":"6a47a972a9779b8c87227f01f98f9881be8cf032","best_bid":"0.86","best_ask":"0.87"}],"timestamp":"1776808417071","event_type":"price_change"}}
{"capturedAt":1776808417,"payload":{"market":"0x125149c5918fc5f8c6d34682f700a898a1a19ea4f4e2ae68ff4c5794ba657074","price_changes":[{"asset_id":"45936375922793925919605092352922707796689801895417366600539442410775071099958","price":"0.86","size":"186.7","side":"BUY","hash":"775a60be36775a5fb0d48d56171274d9402990f5","best_bid":"0.86","best_ask":"0.87"},{"asset_id":"86520121088881862182423437128238697252500151785248183602134095101149900014256","price":"0.14","size":"186.7","side":"SELL","hash":"dc8f2dc477755b6aaf3c111cca96aa5945ee931e","best_bid":"0.13","best_ask":"0.14"}],"timestamp":"1776808417059","event_type":"price_change"}}
{"capturedAt":1776808417,"payload":{"market":"0x125149c5918fc5f8c6d34682f700a898a1a19ea4f4e2ae68ff4c5794ba657074","price_changes":[{"asset_id":"45936375922793925919605092352922707796689801895417366600539442410775071099958","price":"0.86","size":"190.74","side":"BUY","hash":"ea88f4b5ddc792f5a6715d3d3a92ace1166c44b5","best_bid":"0.86","best_ask":"0.87"},{"asset_id":"86520121088881862182423437128238697252500151785248183602134095101149900014256","price":"0.14","size":"190.74","side":"SELL","hash":"e2e658a1a333e6577cc84ff91e2a412e832023cd","best_bid":"0.13","best_ask":"0.14"}],"timestamp":"1776808417072","event_type":"price_change"}}
{"capturedAt":1776808417,"payload":{"market":"0x125149c5918fc5f8c6d34682f700a898a1a19ea4f4e2ae68ff4c5794ba657074","price_changes":[{"asset_id":"45936375922793925919605092352922707796689801895417366600539442410775071099958","price":"0.86","size":"195.74","side":"BUY","hash":"feac234b3ac4019f33c04bbfb28fd71877236edb","best_bid":"0.86","best_ask":"0.87"},{"asset_id":"86520121088881862182423437128238697252500151785248183602134095101149900014256","price":"0.14","size":"195.74","side":"SELL","hash":"cd5a40360c81ac68fb3b6d27452c5fc77d9de96f","best_bid":"0.13","best_ask":"0.14"}],"timestamp":"1776808417074","event_type":"price_change"}}
{"capturedAt":1776808417,"payload":{"market":"0x125149c5918fc5f8c6d34682f700a898a1a19ea4f4e2ae68ff4c5794ba657074","price_changes":[{"asset_id":"45936375922793925919605092352922707796689801895417366600539442410775071099958","price":"0.86","size":"190.47","side":"BUY","hash":"f39d3c31ee0faef879a8a6caf310dc9be4eeb1e7","best_bid":"0.86","best_ask":"0.87"},{"asset_id":"86520121088881862182423437128238697252500151785248183602134095101149900014256","price":"0.14","size":"190.47","side":"SELL","hash":"1e71a7c04590a208cae0f8fbcbf44450d4defc6d","best_bid":"0.13","best_ask":"0.14"}],"timestamp":"1776808417075","event_type":"price_change"}}
{"capturedAt":1776808417,"payload":{"market":"0x125149c5918fc5f8c6d34682f700a898a1a19ea4f4e2ae68ff4c5794ba657074","price_changes":[{"asset_id":"45936375922793925919605092352922707796689801895417366600539442410775071099958","price":"0.86","size":"185.47","side":"BUY","hash":"1b672329ef09859641d3251442852518b884b8e0","best_bid":"0.86","best_ask":"0.87"},{"asset_id":"86520121088881862182423437128238697252500151785248183602134095101149900014256","price":"0.14","size":"185.47","side":"SELL","hash":"7664c482ed129ec12275b01be7b3db02506ce9f0","best_bid":"0.13","best_ask":"0.14"}],"timestamp":"1776808417076","event_type":"price_change"}}
{"capturedAt":1776808417,"payload":{"market":"0x125149c5918fc5f8c6d34682f700a898a1a19ea4f4e2ae68ff4c5794ba657074","price_changes":[{"asset_id":"45936375922793925919605092352922707796689801895417366600539442410775071099958","price":"0.86","size":"190.47","side":"BUY","hash":"6df5f3ad125f714db6776b6b833e2ddfb7699a48","best_bid":"0.86","best_ask":"0.87"},{"asset_id":"86520121088881862182423437128238697252500151785248183602134095101149900014256","price":"0.14","size":"190.47","side":"SELL","hash":"b703f36546d831f8178fe7d4147b87f71b3125b7","best_bid":"0.13","best_ask":"0.14"}],"timestamp":"1776808417077","event_type":"price_change"}}
{"capturedAt":1776808417,"payload":{"market":"0x125149c5918fc5f8c6d34682f700a898a1a19ea4f4e2ae68ff4c5794ba657074","price_changes":[{"asset_id":"45936375922793925919605092352922707796689801895417366600539442410775071099958","price":"0.86","size":"183.47","side":"BUY","hash":"31cb59d40d47c6909d3cbeda3345358f7d4d7804","best_bid":"0.86","best_ask":"0.87"},{"asset_id":"86520121088881862182423437128238697252500151785248183602134095101149900014256","price":"0.14","size":"183.47","side":"SELL","hash":"c26d998694e3021807f804e28d9934660eac0d63","best_bid":"0.13","best_ask":"0.14"}],"timestamp":"1776808417078","event_type":"price_change"}}
{"capturedAt":1776808417,"payload":{"market":"0x125149c5918fc5f8c6d34682f700a898a1a19ea4f4e2ae68ff4c5794ba657074","price_changes":[{"asset_id":"45936375922793925919605092352922707796689801895417366600539442410775071099958","price":"0.86","size":"176.47","side":"BUY","hash":"f5c8adb9428dce0b468aa837b74d22e0f7f31797","best_bid":"0.86","best_ask":"0.87"},{"asset_id":"86520121088881862182423437128238697252500151785248183602134095101149900014256","price":"0.14","size":"176.47","side":"SELL","hash":"7f68594b6d94c0dc59503a4cc8e7a6a8bbf4dffd","best_bid":"0.13","best_ask":"0.14"}],"timestamp":"1776808417080","event_type":"price_change"}}
{"capturedAt":1776808417,"payload":{"market":"0x125149c5918fc5f8c6d34682f700a898a1a19ea4f4e2ae68ff4c5794ba657074","price_changes":[{"asset_id":"45936375922793925919605092352922707796689801895417366600539442410775071099958","price":"0.86","size":"181.47","side":"BUY","hash":"898bb18865ddf06582ae8cbda9af40af5a4e0fac","best_bid":"0.86","best_ask":"0.87"},{"asset_id":"86520121088881862182423437128238697252500151785248183602134095101149900014256","price":"0.14","size":"181.47","side":"SELL","hash":"4c6260b3fe694ee7201d130ae829f9b37b7e7424","best_bid":"0.13","best_ask":"0.14"}],"timestamp":"1776808417085","event_type":"price_change"}}
{"capturedAt":1776808417,"payload":{"market":"0x125149c5918fc5f8c6d34682f700a898a1a19ea4f4e2ae68ff4c5794ba657074","price_changes":[{"asset_id":"86520121088881862182423437128238697252500151785248183602134095101149900014256","price":"0.13","size":"142.24","side":"BUY","hash":"6b9d174240f32060532c0b49752b015d52f02503","best_bid":"0.13","best_ask":"0.14"},{"asset_id":"45936375922793925919605092352922707796689801895417366600539442410775071099958","price":"0.87","size":"142.24","side":"SELL","hash":"da75dc44f722f9d9e4439e173c99e4f1edd0ca4b","best_bid":"0.86","best_ask":"0.87"}],"timestamp":"1776808417084","event_type":"price_change"}}
{"capturedAt":1776808417,"payload":{"market":"0x125149c5918fc5f8c6d34682f700a898a1a19ea4f4e2ae68ff4c5794ba657074","price_changes":[{"asset_id":"45936375922793925919605092352922707796689801895417366600539442410775071099958","price":"0.86","size":"171.47","side":"BUY","hash":"80c8420ef79ca729f6e037920beb3ada6ce3f2ec","best_bid":"0.86","best_ask":"0.87"},{"asset_id":"86520121088881862182423437128238697252500151785248183602134095101149900014256","price":"0.14","size":"171.47","side":"SELL","hash":"75b5c1ef2744a2096166513fe6060b92e044b2e9","best_bid":"0.13","best_ask":"0.14"}],"timestamp":"1776808417088","event_type":"price_change"}}
{"capturedAt":1776808417,"payload":{"market":"0x125149c5918fc5f8c6d34682f700a898a1a19ea4f4e2ae68ff4c5794ba657074","price_changes":[{"asset_id":"45936375922793925919605092352922707796689801895417366600539442410775071099958","price":"0.86","size":"161.47","side":"BUY","hash":"239f668ee1226886ad3c122c9202133ec1f56404","best_bid":"0.86","best_ask":"0.87"},{"asset_id":"86520121088881862182423437128238697252500151785248183602134095101149900014256","price":"0.14","size":"161.47","side":"SELL","hash":"69cb1270eee3a25f8b993dd8648f81fe3c8a1846","best_bid":"0.13","best_ask":"0.14"}],"timestamp":"1776808417090","event_type":"price_change"}}
{"capturedAt":1776808417,"payload":{"market":"0x125149c5918fc5f8c6d34682f700a898a1a19ea4f4e2ae68ff4c5794ba657074","price_changes":[{"asset_id":"45936375922793925919605092352922707796689801895417366600539442410775071099958","price":"0.01","size":"12329.83","side":"BUY","hash":"baa7d5dab30df69be950e6fb95028e58196da2eb","best_bid":"0.86","best_ask":"0.87"},{"asset_id":"86520121088881862182423437128238697252500151785248183602134095101149900014256","price":"0.99","size":"12329.83","side":"SELL","hash":"4064bdcdd544635af192557abf871f6305677480","best_bid":"0.13","best_ask":"0.14"}],"timestamp":"1776808417091","event_type":"price_change"}}
{"capturedAt":1776808417,"payload":{"market":"0x125149c5918fc5f8c6d34682f700a898a1a19ea4f4e2ae68ff4c5794ba657074","price_changes":[{"asset_id":"45936375922793925919605092352922707796689801895417366600539442410775071099958","price":"0.86","size":"171.47","side":"BUY","hash":"373bc1fc18aa166114b251b92e3fe4baa4062c32","best_bid":"0.86","best_ask":"0.87"},{"asset_id":"86520121088881862182423437128238697252500151785248183602134095101149900014256","price":"0.14","size":"171.47","side":"SELL","hash":"68a9a3b1915177faf141aa74eb97bcd02f96f711","best_bid":"0.13","best_ask":"0.14"}],"timestamp":"1776808417092","event_type":"price_change"}}
{"capturedAt":1776808417,"payload":{"market":"0x125149c5918fc5f8c6d34682f700a898a1a19ea4f4e2ae68ff4c5794ba657074","price_changes":[{"asset_id":"45936375922793925919605092352922707796689801895417366600539442410775071099958","price":"0.86","size":"172.43","side":"BUY","hash":"5ad4fec7f909ce64bb8b9e81c23e3bfa3495abf5","best_bid":"0.86","best_ask":"0.87"},{"asset_id":"86520121088881862182423437128238697252500151785248183602134095101149900014256","price":"0.14","size":"172.43","side":"SELL","hash":"b16a46261a50adb4db2ce90f63ca39350d092c33","best_bid":"0.13","best_ask":"0.14"}],"timestamp":"1776808417094","event_type":"price_change"}}
{"capturedAt":1776808417,"payload":{"market":"0x125149c5918fc5f8c6d34682f700a898a1a19ea4f4e2ae68ff4c5794ba657074","price_changes":[{"asset_id":"45936375922793925919605092352922707796689801895417366600539442410775071099958","price":"0.86","size":"166.43","side":"BUY","hash":"91028a6b1ebede5c50b26d880422bc86d0330979","best_bid":"0.86","best_ask":"0.87"},{"asset_id":"86520121088881862182423437128238697252500151785248183602134095101149900014256","price":"0.14","size":"166.43","side":"SELL","hash":"4255a566e16bd5ff29adf4cd20dc90a68ed008d3","best_bid":"0.13","best_ask":"0.14"}],"timestamp":"1776808417093","event_type":"price_change"}}
{"capturedAt":1776808417,"payload":{"market":"0x125149c5918fc5f8c6d34682f700a898a1a19ea4f4e2ae68ff4c5794ba657074","price_changes":[{"asset_id":"86520121088881862182423437128238697252500151785248183602134095101149900014256","price":"0.13","size":"147.24","side":"BUY","hash":"07b0383057e3291759974b1df29ad83992ee591e","best_bid":"0.13","best_ask":"0.14"},{"asset_id":"45936375922793925919605092352922707796689801895417366600539442410775071099958","price":"0.87","size":"147.24","side":"SELL","hash":"9197a04eb19b9896056bd29740367ad4c8cd32de","best_bid":"0.86","best_ask":"0.87"}],"timestamp":"1776808417096","event_type":"price_change"}}
{"capturedAt":1776808417,"payload":{"market":"0x125149c5918fc5f8c6d34682f700a898a1a19ea4f4e2ae68ff4c5794ba657074","price_changes":[{"asset_id":"86520121088881862182423437128238697252500151785248183602134095101149900014256","price":"0.13","size":"142.24","side":"BUY","hash":"8a298f8a1f812092f4b17720e4ba06e8d8446299","best_bid":"0.13","best_ask":"0.14"},{"asset_id":"45936375922793925919605092352922707796689801895417366600539442410775071099958","price":"0.87","size":"142.24","side":"SELL","hash":"f9d12689e6b16871b99bf69e50f337e54cf77ad2","best_bid":"0.86","best_ask":"0.87"}],"timestamp":"1776808417096","event_type":"price_change"}}
{"capturedAt":1776808417,"payload":{"market":"0x125149c5918fc5f8c6d34682f700a898a1a19ea4f4e2ae68ff4c5794ba657074","price_changes":[{"asset_id":"45936375922793925919605092352922707796689801895417366600539442410775071099958","price":"0.01","size":"12334.83","side":"BUY","hash":"697ec3eae3cd3702aedd1cfbe7fd725988e85f09","best_bid":"0.86","best_ask":"0.87"},{"asset_id":"86520121088881862182423437128238697252500151785248183602134095101149900014256","price":"0.99","size":"12334.83","side":"SELL","hash":"9ffa84ca231c834040e41551c0a9fa2a8c333b08","best_bid":"0.13","best_ask":"0.14"}],"timestamp":"1776808417099","event_type":"price_change"}}
{"capturedAt":1776808417,"payload":{"market":"0x125149c5918fc5f8c6d34682f700a898a1a19ea4f4e2ae68ff4c5794ba657074","price_changes":[{"asset_id":"45936375922793925919605092352922707796689801895417366600539442410775071099958","price":"0.86","size":"177.43","side":"BUY","hash":"ed83b701dc25731e70e0b1aa8b3ef458ba7a725c","best_bid":"0.86","best_ask":"0.87"},{"asset_id":"86520121088881862182423437128238697252500151785248183602134095101149900014256","price":"0.14","size":"177.43","side":"SELL","hash":"7763000a42adf52d1ce122892f4af14b24f95933","best_bid":"0.13","best_ask":"0.14"}],"timestamp":"1776808417097","event_type":"price_change"}}
{"capturedAt":1776808417,"payload":{"market":"0x125149c5918fc5f8c6d34682f700a898a1a19ea4f4e2ae68ff4c5794ba657074","price_changes":[{"asset_id":"45936375922793925919605092352922707796689801895417366600539442410775071099958","price":"0.8","size":"275.25","side":"BUY","hash":"c727ece8e6ed7d7d9513b6b66a16408e7e201f86","best_bid":"0.86","best_ask":"0.87"},{"asset_id":"86520121088881862182423437128238697252500151785248183602134095101149900014256","price":"0.2","size":"275.25","side":"SELL","hash":"98ee355a0c6ae5e61075ce43e03f1d9d5b34d13b","best_bid":"0.13","best_ask":"0.14"}],"timestamp":"1776808417100","event_type":"price_change"}}
{"capturedAt":1776808417,"payload":{"market":"0x125149c5918fc5f8c6d34682f700a898a1a19ea4f4e2ae68ff4c5794ba657074","price_changes":[{"asset_id":"45936375922793925919605092352922707796689801895417366600539442410775071099958","price":"0.86","size":"182.43","side":"BUY","hash":"63a1d0142c4017d7741fb07014456c72e5e6f7d9","best_bid":"0.86","best_ask":"0.87"},{"asset_id":"86520121088881862182423437128238697252500151785248183602134095101149900014256","price":"0.14","size":"182.43","side":"SELL","hash":"4d3098197391ad912869f0b6005e0d0db825150f","best_bid":"0.13","best_ask":"0.14"}],"timestamp":"1776808417102","event_type":"price_change"}}
{"capturedAt":1776808417,"payload":{"market":"0x125149c5918fc5f8c6d34682f700a898a1a19ea4f4e2ae68ff4c5794ba657074","price_changes":[{"asset_id":"45936375922793925919605092352922707796689801895417366600539442410775071099958","price":"0.86","size":"187.43","side":"BUY","hash":"00e8086fceabc2ff72fb40a0ee4152af92e87126","best_bid":"0.86","best_ask":"0.87"},{"asset_id":"86520121088881862182423437128238697252500151785248183602134095101149900014256","price":"0.14","size":"187.43","side":"SELL","hash":"a53aa2f694bbd6887293f0f797e7fee6b6cb1fe1","best_bid":"0.13","best_ask":"0.14"}],"timestamp":"1776808417103","event_type":"price_change"}}
{"capturedAt":1776808417,"payload":{"market":"0x125149c5918fc5f8c6d34682f700a898a1a19ea4f4e2ae68ff4c5794ba657074","price_changes":[{"asset_id":"45936375922793925919605092352922707796689801895417366600539442410775071099958","price":"0.86","size":"193.43","side":"BUY","hash":"fe96daf98eb305590d0d6bd27a5269778730e2bc","best_bid":"0.86","best_ask":"0.87"},{"asset_id":"86520121088881862182423437128238697252500151785248183602134095101149900014256","price":"0.14","size":"193.43","side":"SELL","hash":"0c13cb1a2ae6a3b5e0fdabf97b10ca210b55e9a1","best_bid":"0.13","best_ask":"0.14"}],"timestamp":"1776808417109","event_type":"price_change"}}
{"capturedAt":1776808417,"payload":{"market":"0x125149c5918fc5f8c6d34682f700a898a1a19ea4f4e2ae68ff4c5794ba657074","price_changes":[{"asset_id":"45936375922793925919605092352922707796689801895417366600539442410775071099958","price":"0.86","size":"199.43","side":"BUY","hash":"a67c5a47c5059071672cc3577294b4a74aa1a557","best_bid":"0.86","best_ask":"0.87"},{"asset_id":"86520121088881862182423437128238697252500151785248183602134095101149900014256","price":"0.14","size":"199.43","side":"SELL","hash":"113b3d858966fa2e5bfc685917d5b10eb910920a","best_bid":"0.13","best_ask":"0.14"}],"timestamp":"1776808417111","event_type":"price_change"}}
{"capturedAt":1776808417,"payload":{"market":"0x125149c5918fc5f8c6d34682f700a898a1a19ea4f4e2ae68ff4c5794ba657074","price_changes":[{"asset_id":"45936375922793925919605092352922707796689801895417366600539442410775071099958","price":"0.86","size":"209.43","side":"BUY","hash":"29219671a3568da6d3646834c6b59162fbbd245c","best_bid":"0.86","best_ask":"0.87"},{"asset_id":"86520121088881862182423437128238697252500151785248183602134095101149900014256","price":"0.14","size":"209.43","side":"SELL","hash":"949bcd81fd289b6b6ef41340eb49eb388e35861a","best_bid":"0.13","best_ask":"0.14"}],"timestamp":"1776808417116","event_type":"price_change"}}
{"capturedAt":1776808417,"payload":{"market":"0x125149c5918fc5f8c6d34682f700a898a1a19ea4f4e2ae68ff4c5794ba657074","price_changes":[{"asset_id":"45936375922793925919605092352922707796689801895417366600539442410775071099958","price":"0.01","size":"12324.83","side":"BUY","hash":"b7cdfd56f8316fe26f174a08714d684fe9241906","best_bid":"0.86","best_ask":"0.87"},{"asset_id":"86520121088881862182423437128238697252500151785248183602134095101149900014256","price":"0.99","size":"12324.83","side":"SELL","hash":"83b6ee4c864f88119e9963ef4961b4b9ef4fa7ff","best_bid":"0.13","best_ask":"0.14"}],"timestamp":"1776808417119","event_type":"price_change"}}
{"capturedAt":1776808417,"payload":{"market":"0x125149c5918fc5f8c6d34682f700a898a1a19ea4f4e2ae68ff4c5794ba657074","price_changes":[{"asset_id":"45936375922793925919605092352922707796689801895417366600539442410775071099958","price":"0.86","size":"219.43","side":"BUY","hash":"c05cf683c9f3a574b59fa29af947afa2ad631f30","best_bid":"0.86","best_ask":"0.87"},{"asset_id":"86520121088881862182423437128238697252500151785248183602134095101149900014256","price":"0.14","size":"219.43","side":"SELL","hash":"48ba027c45848710acd7e513868fcaf4098b9109","best_bid":"0.13","best_ask":"0.14"}],"timestamp":"1776808417118","event_type":"price_change"}}
{"capturedAt":1776808417,"payload":{"market":"0x125149c5918fc5f8c6d34682f700a898a1a19ea4f4e2ae68ff4c5794ba657074","price_changes":[{"asset_id":"45936375922793925919605092352922707796689801895417366600539442410775071099958","price":"0.01","size":"12329.83","side":"BUY","hash":"be281aa3c2e65a9d90cbc51501d1a2a2ab479f4d","best_bid":"0.86","best_ask":"0.87"},{"asset_id":"86520121088881862182423437128238697252500151785248183602134095101149900014256","price":"0.99","size":"12329.83","side":"SELL","hash":"0ba61acbe04c2dd219e781c61e6eb5ae1e85df76","best_bid":"0.13","best_ask":"0.14"}],"timestamp":"1776808417117","event_type":"price_change"}}
{"capturedAt":1776808417,"payload":{"market":"0x125149c5918fc5f8c6d34682f700a898a1a19ea4f4e2ae68ff4c5794ba657074","price_changes":[{"asset_id":"86520121088881862182423437128238697252500151785248183602134095101149900014256","price":"0.13","size":"147.24","side":"BUY","hash":"a93b84268a7cde815da89b74222d74f0d9e341a4","best_bid":"0.13","best_ask":"0.14"},{"asset_id":"45936375922793925919605092352922707796689801895417366600539442410775071099958","price":"0.87","size":"147.24","side":"SELL","hash":"811be8b69344c932095b707a3da821bc243b4536","best_bid":"0.86","best_ask":"0.87"}],"timestamp":"1776808417146","event_type":"price_change"}}
{"capturedAt":1776808417,"payload":{"market":"0x125149c5918fc5f8c6d34682f700a898a1a19ea4f4e2ae68ff4c5794ba657074","price_changes":[{"asset_id":"86520121088881862182423437128238697252500151785248183602134095101149900014256","price":"0.12","size":"370","side":"BUY","hash":"80fcf1232aff33e3b2d2d0a07102a7502a85cf1a","best_bid":"0.13","best_ask":"0.14"},{"asset_id":"45936375922793925919605092352922707796689801895417366600539442410775071099958","price":"0.88","size":"370","side":"SELL","hash":"b786725e2f76f90b295ca4d016b21f176edaac98","best_bid":"0.86","best_ask":"0.87"}],"timestamp":"1776808417147","event_type":"price_change"}}
{"capturedAt":1776808417,"payload":{"market":"0x125149c5918fc5f8c6d34682f700a898a1a19ea4f4e2ae68ff4c5794ba657074","price_changes":[{"asset_id":"86520121088881862182423437128238697252500151785248183602134095101149900014256","price":"0.13","size":"152.24","side":"BUY","hash":"a444fdff20feea90cfef2f57c9c2e5281d142959","best_bid":"0.13","best_ask":"0.14"},{"asset_id":"45936375922793925919605092352922707796689801895417366600539442410775071099958","price":"0.87","size":"152.24","side":"SELL","hash":"a0f1cc17f8b52563069becdf533ae1ca52f5fda3","best_bid":"0.86","best_ask":"0.87"}],"timestamp":"1776808417148","event_type":"price_change"}}
{"capturedAt":1776808417,"payload":{"market":"0x125149c5918fc5f8c6d34682f700a898a1a19ea4f4e2ae68ff4c5794ba657074","price_changes":[{"asset_id":"45936375922793925919605092352922707796689801895417366600539442410775071099958","price":"0.86","size":"214.43","side":"BUY","hash":"05814f5068021f846c2ad3dcbf2dd899deba729f","best_bid":"0.86","best_ask":"0.87"},{"asset_id":"86520121088881862182423437128238697252500151785248183602134095101149900014256","price":"0.14","size":"214.43","side":"SELL","hash":"e6db8f67b3e1573d27c2108e49ef78fd9259f3fb","best_bid":"0.13","best_ask":"0.14"}],"timestamp":"1776808417149","event_type":"price_change"}}
{"capturedAt":1776808417,"payload":{"market":"0x125149c5918fc5f8c6d34682f700a898a1a19ea4f4e2ae68ff4c5794ba657074","price_changes":[{"asset_id":"45936375922793925919605092352922707796689801895417366600539442410775071099958","price":"0.81","size":"279.9","side":"BUY","hash":"7e9a9ae8246f51c1917b92b67312e965b82dcc26","best_bid":"0.86","best_ask":"0.87"},{"asset_id":"86520121088881862182423437128238697252500151785248183602134095101149900014256","price":"0.19","size":"279.9","side":"SELL","hash":"19058c9a0ccb552dca179f18578c1563350aa022","best_bid":"0.13","best_ask":"0.14"}],"timestamp":"1776808417150","event_type":"price_change"}}
{"capturedAt":1776808417,"payload":{"market":"0x125149c5918fc5f8c6d34682f700a898a1a19ea4f4e2ae68ff4c5794ba657074","price_changes":[{"asset_id":"45936375922793925919605092352922707796689801895417366600539442410775071099958","price":"0.86","size":"209.43","side":"BUY","hash":"827212169217fdd68057aca04ebdc159e437d337","best_bid":"0.86","best_ask":"0.87"},{"asset_id":"86520121088881862182423437128238697252500151785248183602134095101149900014256","price":"0.14","size":"209.43","side":"SELL","hash":"e05c47acd57ce7066d36406f42bee9244e4cc4fa","best_bid":"0.13","best_ask":"0.14"}],"timestamp":"1776808417152","event_type":"price_change"}}
{"capturedAt":1776808417,"payload":{"market":"0x125149c5918fc5f8c6d34682f700a898a1a19ea4f4e2ae68ff4c5794ba657074","price_changes":[{"asset_id":"45936375922793925919605092352922707796689801895417366600539442410775071099958","price":"0.86","size":"214.56","side":"BUY","hash":"84e69cfe461261c4d6793b959aa0dcb24ca713f7","best_bid":"0.86","best_ask":"0.87"},{"asset_id":"86520121088881862182423437128238697252500151785248183602134095101149900014256","price":"0.14","size":"214.56","side":"SELL","hash":"9142d3fbc0525c4e4e5f774030eb6b6b26d4f200","best_bid":"0.13","best_ask":"0.14"}],"timestamp":"1776808417153","event_type":"price_change"}}
{"capturedAt":1776808417,"payload":{"market":"0x125149c5918fc5f8c6d34682f700a898a1a19ea4f4e2ae68ff4c5794ba657074","price_changes":[{"asset_id":"45936375922793925919605092352922707796689801895417366600539442410775071099958","price":"0.86","size":"209.56","side":"BUY","hash":"7e34f327f471f553439917d3cb482f28cc2243ad","best_bid":"0.86","best_ask":"0.87"},{"asset_id":"86520121088881862182423437128238697252500151785248183602134095101149900014256","price":"0.14","size":"209.56","side":"SELL","hash":"06cfebe7658b0ceb092bf49d7c73cb003f938e20","best_bid":"0.13","best_ask":"0.14"}],"timestamp":"1776808417154","event_type":"price_change"}}
{"capturedAt":1776808417,"payload":{"market":"0x125149c5918fc5f8c6d34682f700a898a1a19ea4f4e2ae68ff4c5794ba657074","price_changes":[{"asset_id":"45936375922793925919605092352922707796689801895417366600539442410775071099958","price":"0.86","size":"214.56","side":"BUY","hash":"6fefbfaa2593e668ac370513221ad57a07260875","best_bid":"0.86","best_ask":"0.87"},{"asset_id":"86520121088881862182423437128238697252500151785248183602134095101149900014256","price":"0.14","size":"214.56","side":"SELL","hash":"11921eea8fb445ba443780bbdb4ce11a9db08064","best_bid":"0.13","best_ask":"0.14"}],"timestamp":"1776808417155","event_type":"price_change"}}
{"capturedAt":1776808417,"payload":{"market":"0x125149c5918fc5f8c6d34682f700a898a1a19ea4f4e2ae68ff4c5794ba657074","price_changes":[{"asset_id":"45936375922793925919605092352922707796689801895417366600539442410775071099958","price":"0.86","size":"209.56","side":"BUY","hash":"9174771c142832c818c33b99a744bb72d9f543f4","best_bid":"0.86","best_ask":"0.87"},{"asset_id":"86520121088881862182423437128238697252500151785248183602134095101149900014256","price":"0.14","size":"209.56","side":"SELL","hash":"884d18bb6defe15f71212c9279970472f52dd7b5","best_bid":"0.13","best_ask":"0.14"}],"timestamp":"1776808417156","event_type":"price_change"}}
{"capturedAt":1776808417,"payload":{"market":"0x125149c5918fc5f8c6d34682f700a898a1a19ea4f4e2ae68ff4c5794ba657074","price_changes":[{"asset_id":"86520121088881862182423437128238697252500151785248183602134095101149900014256","price":"0.13","size":"147.24","side":"BUY","hash":"da789f05a580ecb1d6e64a86aa4d18f985c5cba2","best_bid":"0.13","best_ask":"0.14"},{"asset_id":"45936375922793925919605092352922707796689801895417366600539442410775071099958","price":"0.87","size":"147.24","side":"SELL","hash":"93f9eee06b447319bd3cf196f5f83c407325bbce","best_bid":"0.86","best_ask":"0.87"}],"timestamp":"1776808417157","event_type":"price_change"}}
{"capturedAt":1776808417,"payload":{"market":"0x125149c5918fc5f8c6d34682f700a898a1a19ea4f4e2ae68ff4c5794ba657074","price_changes":[{"asset_id":"45936375922793925919605092352922707796689801895417366600539442410775071099958","price":"0.86","size":"204.56","side":"BUY","hash":"25887f6e112ba89274e5e7b2bed8acb7d1505455","best_bid":"0.86","best_ask":"0.87"},{"asset_id":"86520121088881862182423437128238697252500151785248183602134095101149900014256","price":"0.14","size":"204.56","side":"SELL","hash":"d20358f9aecbb2c93784c2eb8ec34619044aad95","best_bid":"0.13","best_ask":"0.14"}],"timestamp":"1776808417158","event_type":"price_change"}}
{"capturedAt":1776808417,"payload":{"market":"0x125149c5918fc5f8c6d34682f700a898a1a19ea4f4e2ae68ff4c5794ba657074","price_changes":[{"asset_id":"45936375922793925919605092352922707796689801895417366600539442410775071099958","price":"0.01","size":"12329.83","side":"BUY","hash":"9ce3ba0b1b62284c2fe15d9fac3d0503b20392a1","best_bid":"0.86","best_ask":"0.87"},{"asset_id":"86520121088881862182423437128238697252500151785248183602134095101149900014256","price":"0.99","size":"12329.83","side":"SELL","hash":"39d4efabc87accaeb45b3fe588f499bcd80a4fae","best_bid":"0.13","best_ask":"0.14"}],"timestamp":"1776808417163","event_type":"price_change"}}
{"capturedAt":1776808417,"payload":{"market":"0x125149c5918fc5f8c6d34682f700a898a1a19ea4f4e2ae68ff4c5794ba657074","price_changes":[{"asset_id":"45936375922793925919605092352922707796689801895417366600539442410775071099958","price":"0.01","size":"12334.83","side":"BUY","hash":"ef504b4f849ce9369e57786799007d34af5d60d9","best_bid":"0.86","best_ask":"0.87"},{"asset_id":"86520121088881862182423437128238697252500151785248183602134095101149900014256","price":"0.99","size":"12334.83","side":"SELL","hash":"9895e3a52c8baf39cb0e85e9c6aa05cd1b6ca678","best_bid":"0.13","best_ask":"0.14"}],"timestamp":"1776808417165","event_type":"price_change"}}
{"capturedAt":1776808417,"payload":{"market":"0x125149c5918fc5f8c6d34682f700a898a1a19ea4f4e2ae68ff4c5794ba657074","price_changes":[{"asset_id":"45936375922793925919605092352922707796689801895417366600539442410775071099958","price":"0.86","size":"198.56","side":"BUY","hash":"3743727b1865c5d5277840080ebb544077abb138","best_bid":"0.86","best_ask":"0.87"},{"asset_id":"86520121088881862182423437128238697252500151785248183602134095101149900014256","price":"0.14","size":"198.56","side":"SELL","hash":"ea6529191641aabb2be88df5e47db07d08f75c01","best_bid":"0.13","best_ask":"0.14"}],"timestamp":"1776808417166","event_type":"price_change"}}
{"capturedAt":1776808417,"payload":{"market":"0x125149c5918fc5f8c6d34682f700a898a1a19ea4f4e2ae68ff4c5794ba657074","price_changes":[{"asset_id":"45936375922793925919605092352922707796689801895417366600539442410775071099958","price":"0.86","size":"193.56","side":"BUY","hash":"8c056c006cea429a07aea21b5e72949b82ee6511","best_bid":"0.86","best_ask":"0.87"},{"asset_id":"86520121088881862182423437128238697252500151785248183602134095101149900014256","price":"0.14","size":"193.56","side":"SELL","hash":"e3a7808feccc56713c9f4ae359f6a000b6f1e323","best_bid":"0.13","best_ask":"0.14"}],"timestamp":"1776808417170","event_type":"price_change"}}
{"capturedAt":1776808417,"payload":{"market":"0x125149c5918fc5f8c6d34682f700a898a1a19ea4f4e2ae68ff4c5794ba657074","price_changes":[{"asset_id":"86520121088881862182423437128238697252500151785248183602134095101149900014256","price":"0.13","size":"142.24","side":"BUY","hash":"9c7ea1218004eb5d868754ec57e5a4876a6dc459","best_bid":"0.13","best_ask":"0.14"},{"asset_id":"45936375922793925919605092352922707796689801895417366600539442410775071099958","price":"0.87","size":"142.24","side":"SELL","hash":"a7500fe7f21db54f2dcce501dd6840fb94e55e93","best_bid":"0.86","best_ask":"0.87"}],"timestamp":"1776808417170","event_type":"price_change"}}
{"capturedAt":1776808417,"payload":{"market":"0x125149c5918fc5f8c6d34682f700a898a1a19ea4f4e2ae68ff4c5794ba657074","price_changes":[{"asset_id":"45936375922793925919605092352922707796689801895417366600539442410775071099958","price":"0.86","size":"188.56","side":"BUY","hash":"76b3cd5f0a616a64d650ab2d42021df0241cc3b8","best_bid":"0.86","best_ask":"0.87"},{"asset_id":"86520121088881862182423437128238697252500151785248183602134095101149900014256","price":"0.14","size":"188.56","side":"SELL","hash":"90d0066e10bac80195b89c7ca279b3b5df2ebeec","best_bid":"0.13","best_ask":"0.14"}],"timestamp":"1776808417171","event_type":"price_change"}}
{"capturedAt":1776808417,"payload":{"market":"0x125149c5918fc5f8c6d34682f700a898a1a19ea4f4e2ae68ff4c5794ba657074","price_changes":[{"asset_id":"45936375922793925919605092352922707796689801895417366600539442410775071099958","price":"0.86","size":"173.43","side":"BUY","hash":"a649344d896016ae9464d5ca6842ba0b2a655332","best_bid":"0.86","best_ask":"0.87"},{"asset_id":"86520121088881862182423437128238697252500151785248183602134095101149900014256","price":"0.14","size":"173.43","side":"SELL","hash":"5af846d4f2e4f33139873dafd0a0afd837ca308f","best_bid":"0.13","best_ask":"0.14"}],"timestamp":"1776808417173","event_type":"price_change"}}
{"capturedAt":1776808417,"payload":{"market":"0x125149c5918fc5f8c6d34682f700a898a1a19ea4f4e2ae68ff4c5794ba657074","price_changes":[{"asset_id":"45936375922793925919605092352922707796689801895417366600539442410775071099958","price":"0.86","size":"178.43","side":"BUY","hash":"4052506c006f50bb2e76e3e2db212aa0b62e0b74","best_bid":"0.86","best_ask":"0.87"},{"asset_id":"86520121088881862182423437128238697252500151785248183602134095101149900014256","price":"0.14","size":"178.43","side":"SELL","hash":"bc72530d4916336332ec808fa0e875452ca78c8e","best_bid":"0.13","best_ask":"0.14"}],"timestamp":"1776808417174","event_type":"price_change"}}
{"capturedAt":1776808417,"payload":{"market":"0x125149c5918fc5f8c6d34682f700a898a1a19ea4f4e2ae68ff4c5794ba657074","price_changes":[{"asset_id":"45936375922793925919605092352922707796689801895417366600539442410775071099958","price":"0.86","size":"183.43","side":"BUY","hash":"ac7581dc3ec6aabd8095ac927d33edfadb505b1f","best_bid":"0.86","best_ask":"0.87"},{"asset_id":"86520121088881862182423437128238697252500151785248183602134095101149900014256","price":"0.14","size":"183.43","side":"SELL","hash":"9ed2d7b7ab53cbb0d7e8e8d2e55b1fd04ebd6f21","best_bid":"0.13","best_ask":"0.14"}],"timestamp":"1776808417172","event_type":"price_change"}}
{"capturedAt":1776808417,"payload":{"market":"0x125149c5918fc5f8c6d34682f700a898a1a19ea4f4e2ae68ff4c5794ba657074","price_changes":[{"asset_id":"86520121088881862182423437128238697252500151785248183602134095101149900014256","price":"0.13","size":"147.24","side":"BUY","hash":"55fe966ccd3e4e1bd859018bc2b57ded32b96634","best_bid":"0.13","best_ask":"0.14"},{"asset_id":"45936375922793925919605092352922707796689801895417366600539442410775071099958","price":"0.87","size":"147.24","side":"SELL","hash":"a3aa070b223b8c93245221a5ae367caaf0e58885","best_bid":"0.86","best_ask":"0.87"}],"timestamp":"1776808417181","event_type":"price_change"}}
{"capturedAt":1776808417,"payload":{"market":"0x125149c5918fc5f8c6d34682f700a898a1a19ea4f4e2ae68ff4c5794ba657074","price_changes":[{"asset_id":"45936375922793925919605092352922707796689801895417366600539442410775071099958","price":"0.01","size":"12329.83","side":"BUY","hash":"d7efe179d9ed8a57affeb9eeddd8dbf5b7b671d9","best_bid":"0.86","best_ask":"0.87"},{"asset_id":"86520121088881862182423437128238697252500151785248183602134095101149900014256","price":"0.99","size":"12329.83","side":"SELL","hash":"9b78052d74d5f95e975d6f65ff91f6fbbad17acb","best_bid":"0.13","best_ask":"0.14"}],"timestamp":"1776808417184","event_type":"price_change"}}
{"capturedAt":1776808417,"payload":{"market":"0x125149c5918fc5f8c6d34682f700a898a1a19ea4f4e2ae68ff4c5794ba657074","price_changes":[{"asset_id":"45936375922793925919605092352922707796689801895417366600539442410775071099958","price":"0.86","size":"177.43","side":"BUY","hash":"c8cfbfccc26ddf78b1c01de58befae81c4182d7c","best_bid":"0.86","best_ask":"0.87"},{"asset_id":"86520121088881862182423437128238697252500151785248183602134095101149900014256","price":"0.14","size":"177.43","side":"SELL","hash":"f7a1b636b98c2ae50176e97889671bcaf1c538f0","best_bid":"0.13","best_ask":"0.14"}],"timestamp":"1776808417186","event_type":"price_change"}}
{"capturedAt":1776808417,"payload":{"market":"0x125149c5918fc5f8c6d34682f700a898a1a19ea4f4e2ae68ff4c5794ba657074","price_changes":[{"asset_id":"45936375922793925919605092352922707796689801895417366600539442410775071099958","price":"0.8","size":"257.75","side":"BUY","hash":"1650edde20d6c7eb799bc7cf9693c9bc22abbaa4","best_bid":"0.86","best_ask":"0.87"},{"asset_id":"86520121088881862182423437128238697252500151785248183602134095101149900014256","price":"0.2","size":"257.75","side":"SELL","hash":"08634b8c1728b8e353feef85eefb916a71860480","best_bid":"0.13","best_ask":"0.14"}],"timestamp":"1776808417191","event_type":"price_change"}}
{"capturedAt":1776808417,"payload":{"market":"0x125149c5918fc5f8c6d34682f700a898a1a19ea4f4e2ae68ff4c5794ba657074","price_changes":[{"asset_id":"45936375922793925919605092352922707796689801895417366600539442410775071099958","price":"0.86","size":"182.43","side":"BUY","hash":"93aec586f870873b87042225728db12e9f04da18","best_bid":"0.86","best_ask":"0.87"},{"asset_id":"86520121088881862182423437128238697252500151785248183602134095101149900014256","price":"0.14","size":"182.43","side":"SELL","hash":"f50d6d10811fef162ce456576c855b3a078cdc31","best_bid":"0.13","best_ask":"0.14"}],"timestamp":"1776808417187","event_type":"price_change"}}
{"capturedAt":1776808417,"payload":{"market":"0x125149c5918fc5f8c6d34682f700a898a1a19ea4f4e2ae68ff4c5794ba657074","price_changes":[{"asset_id":"45936375922793925919605092352922707796689801895417366600539442410775071099958","price":"0.86","size":"176.43","side":"BUY","hash":"a5502f3f246342661fa6b6e6026e896b2f691163","best_bid":"0.86","best_ask":"0.87"},{"asset_id":"86520121088881862182423437128238697252500151785248183602134095101149900014256","price":"0.14","size":"176.43","side":"SELL","hash":"fc167625736f461e29e197f41b1901d778c0e8f3","best_bid":"0.13","best_ask":"0.14"}],"timestamp":"1776808417190","event_type":"price_change"}}
{"capturedAt":1776808417,"payload":{"market":"0x125149c5918fc5f8c6d34682f700a898a1a19ea4f4e2ae68ff4c5794ba657074","price_changes":[{"asset_id":"45936375922793925919605092352922707796689801895417366600539442410775071099958","price":"0.86","size":"181.43","side":"BUY","hash":"1bc85687ebdc614ce67ceeef34179b5adf532858","best_bid":"0.86","best_ask":"0.87"},{"asset_id":"86520121088881862182423437128238697252500151785248183602134095101149900014256","price":"0.14","size":"181.43","side":"SELL","hash":"9a15acbf76b557436c2d21b633ecd90f40f58b7d","best_bid":"0.13","best_ask":"0.14"}],"timestamp":"1776808417193","event_type":"price_change"}}
{"capturedAt":1776808417,"payload":{"market":"0x125149c5918fc5f8c6d34682f700a898a1a19ea4f4e2ae68ff4c5794ba657074","price_changes":[{"asset_id":"45936375922793925919605092352922707796689801895417366600539442410775071099958","price":"0.01","size":"12329.83","side":"BUY","hash":"b8c7823fb2ba451429fed5f294267b2502a1b396","best_bid":"0.86","best_ask":"0.87"},{"asset_id":"86520121088881862182423437128238697252500151785248183602134095101149900014256","price":"0.99","size":"12329.83","side":"SELL","hash":"f035621092218a014fb3ffe71facd89adca22631","best_bid":"0.13","best_ask":"0.14"}],"timestamp":"1776808417192","event_type":"price_change"}}
{"capturedAt":1776808417,"payload":{"market":"0x125149c5918fc5f8c6d34682f700a898a1a19ea4f4e2ae68ff4c5794ba657074","price_changes":[{"asset_id":"45936375922793925919605092352922707796689801895417366600539442410775071099958","price":"0.86","size":"186.43","side":"BUY","hash":"5553f069e0176ec2c78f89098c51387c6cc75a6d","best_bid":"0.86","best_ask":"0.87"},{"asset_id":"86520121088881862182423437128238697252500151785248183602134095101149900014256","price":"0.14","size":"186.43","side":"SELL","hash":"a6518b9344fa731dbd838f3952579b32efc2a5df","best_bid":"0.13","best_ask":"0.14"}],"timestamp":"1776808417195","event_type":"price_change"}}
{"capturedAt":1776808417,"payload":{"market":"0x125149c5918fc5f8c6d34682f700a898a1a19ea4f4e2ae68ff4c5794ba657074","price_changes":[{"asset_id":"45936375922793925919605092352922707796689801895417366600539442410775071099958","price":"0.86","size":"198.93","side":"BUY","hash":"15c3ddfee2fe71f20f0054b2d107c5aa63ab1694","best_bid":"0.86","best_ask":"0.87"},{"asset_id":"86520121088881862182423437128238697252500151785248183602134095101149900014256","price":"0.14","size":"198.93","side":"SELL","hash":"4cabb7a003b5c38996b66c61f694ce5750892a4e","best_bid":"0.13","best_ask":"0.14"}],"timestamp":"1776808417198","event_type":"price_change"}}
{"capturedAt":1776808417,"payload":{"market":"0x125149c5918fc5f8c6d34682f700a898a1a19ea4f4e2ae68ff4c5794ba657074","price_changes":[{"asset_id":"45936375922793925919605092352922707796689801895417366600539442410775071099958","price":"0.86","size":"191.43","side":"BUY","hash":"e5dc4a7fa135e89a20d703bd80fa5c0e847c0230","best_bid":"0.86","best_ask":"0.87"},{"asset_id":"86520121088881862182423437128238697252500151785248183602134095101149900014256","price":"0.14","size":"191.43","side":"SELL","hash":"b51d3534a6d53001592b98bc0c881b14cb66e919","best_bid":"0.13","best_ask":"0.14"}],"timestamp":"1776808417196","event_type":"price_change"}}
{"capturedAt":1776808417,"payload":{"market":"0x125149c5918fc5f8c6d34682f700a898a1a19ea4f4e2ae68ff4c5794ba657074","price_changes":[{"asset_id":"86520121088881862182423437128238697252500151785248183602134095101149900014256","price":"0.13","size":"152.24","side":"BUY","hash":"178269879d7955f6141bdf90e158379b57998255","best_bid":"0.13","best_ask":"0.14"},{"asset_id":"45936375922793925919605092352922707796689801895417366600539442410775071099958","price":"0.87","size":"152.24","side":"SELL","hash":"819067afe65553f861e4cdabf426fdff891cafa3","best_bid":"0.86","best_ask":"0.87"}],"timestamp":"1776808417201","event_type":"price_change"}}
{"capturedAt":1776808417,"payload":{"market":"0x125149c5918fc5f8c6d34682f700a898a1a19ea4f4e2ae68ff4c5794ba657074","price_changes":[{"asset_id":"45936375922793925919605092352922707796689801895417366600539442410775071099958","price":"0.86","size":"193.93","side":"BUY","hash":"427229bbaa146fa0136cee065dc1d90e92f3e7bb","best_bid":"0.86","best_ask":"0.87"},{"asset_id":"86520121088881862182423437128238697252500151785248183602134095101149900014256","price":"0.14","size":"193.93","side":"SELL","hash":"20df81feafce60f97381f301a153e46cf17ed8cb","best_bid":"0.13","best_ask":"0.14"}],"timestamp":"1776808417200","event_type":"price_change"}}
{"capturedAt":1776808417,"payload":{"market":"0x125149c5918fc5f8c6d34682f700a898a1a19ea4f4e2ae68ff4c5794ba657074","price_changes":[{"asset_id":"45936375922793925919605092352922707796689801895417366600539442410775071099958","price":"0.86","size":"188.93","side":"BUY","hash":"454c9a41c24f49bd12aa9c7cb58a1fad5016b075","best_bid":"0.86","best_ask":"0.87"},{"asset_id":"86520121088881862182423437128238697252500151785248183602134095101149900014256","price":"0.14","size":"188.93","side":"SELL","hash":"bb594866e2f14a904db3964540178707c6c8c81b","best_bid":"0.13","best_ask":"0.14"}],"timestamp":"1776808417199","event_type":"price_change"}}
{"capturedAt":1776808417,"payload":{"market":"0x125149c5918fc5f8c6d34682f700a898a1a19ea4f4e2ae68ff4c5794ba657074","price_changes":[{"asset_id":"45936375922793925919605092352922707796689801895417366600539442410775071099958","price":"0.86","size":"208.93","side":"BUY","hash":"54adb78886de9047762a5dca588c8469ced670c7","best_bid":"0.86","best_ask":"0.87"},{"asset_id":"86520121088881862182423437128238697252500151785248183602134095101149900014256","price":"0.14","size":"208.93","side":"SELL","hash":"106d431644bf85d9391bba156303e68fbcb867f7","best_bid":"0.13","best_ask":"0.14"}],"timestamp":"1776808417203","event_type":"price_change"}}
{"capturedAt":1776808417,"payload":{"market":"0x125149c5918fc5f8c6d34682f700a898a1a19ea4f4e2ae68ff4c5794ba657074","price_changes":[{"asset_id":"45936375922793925919605092352922707796689801895417366600539442410775071099958","price":"0.86","size":"198.93","side":"BUY","hash":"6894156cb8c1e949e9931ce525f95b5e94394547","best_bid":"0.86","best_ask":"0.87"},{"asset_id":"86520121088881862182423437128238697252500151785248183602134095101149900014256","price":"0.14","size":"198.93","side":"SELL","hash":"e5d172de0bf8870b47f1c68ee77f63b857c3fc7c","best_bid":"0.13","best_ask":"0.14"}],"timestamp":"1776808417202","event_type":"price_change"}}
{"capturedAt":1776808417,"payload":{"market":"0x125149c5918fc5f8c6d34682f700a898a1a19ea4f4e2ae68ff4c5794ba657074","price_changes":[{"asset_id":"45936375922793925919605092352922707796689801895417366600539442410775071099958","price":"0.86","size":"181.43","side":"BUY","hash":"118e731feecd23709de59c8c8013aec4446dbb6d","best_bid":"0.86","best_ask":"0.87"},{"asset_id":"86520121088881862182423437128238697252500151785248183602134095101149900014256","price":"0.14","size":"181.43","side":"SELL","hash":"e6643675a5086c9f580f969790b1e37e006aadef","best_bid":"0.13","best_ask":"0.14"}],"timestamp":"1776808417197","event_type":"price_change"}}
{"capturedAt":1776808417,"payload":{"market":"0x125149c5918fc5f8c6d34682f700a898a1a19ea4f4e2ae68ff4c5794ba657074","price_changes":[{"asset_id":"45936375922793925919605092352922707796689801895417366600539442410775071099958","price":"0.01","size":"12329.83","side":"BUY","hash":"237e1d45a951dafc29aaef1e3a23ab20a6bd3137","best_bid":"0.86","best_ask":"0.87"},{"asset_id":"86520121088881862182423437128238697252500151785248183602134095101149900014256","price":"0.99","size":"12329.83","side":"SELL","hash":"bde1d34a420081596ba38006d99d9ac73e533804","best_bid":"0.13","best_ask":"0.14"}],"timestamp":"1776808417213","event_type":"price_change"}}
{"capturedAt":1776808417,"payload":{"market":"0x125149c5918fc5f8c6d34682f700a898a1a19ea4f4e2ae68ff4c5794ba657074","price_changes":[{"asset_id":"45936375922793925919605092352922707796689801895417366600539442410775071099958","price":"0.86","size":"172.43","side":"BUY","hash":"4ec8674f4f2027bc0f83a6bbc8c752ea273d0b1e","best_bid":"0.86","best_ask":"0.87"},{"asset_id":"86520121088881862182423437128238697252500151785248183602134095101149900014256","price":"0.14","size":"172.43","side":"SELL","hash":"9d209661f49c6985633b917ebd53ea0256cac34a","best_bid":"0.13","best_ask":"0.14"}],"timestamp":"1776808417182","event_type":"price_change"}}
{"capturedAt":1776808417,"payload":{"market":"0x125149c5918fc5f8c6d34682f700a898a1a19ea4f4e2ae68ff4c5794ba657074","price_changes":[{"asset_id":"45936375922793925919605092352922707796689801895417366600539442410775071099958","price":"0.86","size":"220.93","side":"BUY","hash":"be7f0ee04515d48103852a2d29064e8832218b95","best_bid":"0.86","best_ask":"0.87"},{"asset_id":"86520121088881862182423437128238697252500151785248183602134095101149900014256","price":"0.14","size":"220.93","side":"SELL","hash":"1ed6f1716fbc4367b9f5f67dc06a5950e15f794f","best_bid":"0.13","best_ask":"0.14"}],"timestamp":"1776808417221","event_type":"price_change"}}
{"capturedAt":1776808417,"payload":{"market":"0x125149c5918fc5f8c6d34682f700a898a1a19ea4f4e2ae68ff4c5794ba657074","price_changes":[{"asset_id":"45936375922793925919605092352922707796689801895417366600539442410775071099958","price":"0.86","size":"214.93","side":"BUY","hash":"90869d12b57921e4a23f36ffff9b2a4560a78880","best_bid":"0.86","best_ask":"0.87"},{"asset_id":"86520121088881862182423437128238697252500151785248183602134095101149900014256","price":"0.14","size":"214.93","side":"SELL","hash":"631eac27bd6ac204c61238811762237c8f6f97f7","best_bid":"0.13","best_ask":"0.14"}],"timestamp":"1776808417207","event_type":"price_change"}}
{"capturedAt":1776808417,"payload":{"market":"0x125149c5918fc5f8c6d34682f700a898a1a19ea4f4e2ae68ff4c5794ba657074","price_changes":[{"asset_id":"45936375922793925919605092352922707796689801895417366600539442410775071099958","price":"0.86","size":"240.93","side":"BUY","hash":"734fda1774ca1bae1f67f52c80966a0746637c45","best_bid":"0.86","best_ask":"0.87"},{"asset_id":"86520121088881862182423437128238697252500151785248183602134095101149900014256","price":"0.14","size":"240.93","side":"SELL","hash":"af27ee44f37dda7b8923abf609c3de052606ca10","best_bid":"0.13","best_ask":"0.14"}],"timestamp":"1776808417228","event_type":"price_change"}}
{"capturedAt":1776808417,"payload":{"market":"0x125149c5918fc5f8c6d34682f700a898a1a19ea4f4e2ae68ff4c5794ba657074","price_changes":[{"asset_id":"45936375922793925919605092352922707796689801895417366600539442410775071099958","price":"0.01","size":"12324.83","side":"BUY","hash":"068517dd27c2c2ab58485fdd991421518bc457ca","best_bid":"0.86","best_ask":"0.87"},{"asset_id":"86520121088881862182423437128238697252500151785248183602134095101149900014256","price":"0.99","size":"12324.83","side":"SELL","hash":"42b26e4729280468e0ba98b7c146f48c41786325","best_bid":"0.13","best_ask":"0.14"}],"timestamp":"1776808417211","event_type":"price_change"}}
{"capturedAt":1776808417,"payload":{"market":"0x125149c5918fc5f8c6d34682f700a898a1a19ea4f4e2ae68ff4c5794ba657074","price_changes":[{"asset_id":"45936375922793925919605092352922707796689801895417366600539442410775071099958","price":"0.01","size":"12324.83","side":"BUY","hash":"9f6d370d9a35ff3aa7d662ecba14ab38c5ff3f75","best_bid":"0.86","best_ask":"0.87"},{"asset_id":"86520121088881862182423437128238697252500151785248183602134095101149900014256","price":"0.99","size":"12324.83","side":"SELL","hash":"01c8afb08d841a511405806899f53216b21ef6f5","best_bid":"0.13","best_ask":"0.14"}],"timestamp":"1776808417188","event_type":"price_change"}}
{"capturedAt":1776808417,"payload":{"market":"0x125149c5918fc5f8c6d34682f700a898a1a19ea4f4e2ae68ff4c5794ba657074","price_changes":[{"asset_id":"45936375922793925919605092352922707796689801895417366600539442410775071099958","price":"0.01","size":"12334.83","side":"BUY","hash":"2f3558f41257e8374256200e36ec8c98fc8d4c1d","best_bid":"0.86","best_ask":"0.87"},{"asset_id":"86520121088881862182423437128238697252500151785248183602134095101149900014256","price":"0.99","size":"12334.83","side":"SELL","hash":"22bbabbbaf220a88481fecd7ad270a09ece756f3","best_bid":"0.13","best_ask":"0.14"}],"timestamp":"1776808417225","event_type":"price_change"}}
{"capturedAt":1776808417,"payload":{"market":"0x125149c5918fc5f8c6d34682f700a898a1a19ea4f4e2ae68ff4c5794ba657074","price_changes":[{"asset_id":"45936375922793925919605092352922707796689801895417366600539442410775071099958","price":"0.01","size":"12334.84","side":"BUY","hash":"62e187f02e6296f25fe72dd2f11c57f695d1fcc3","best_bid":"0.86","best_ask":"0.87"},{"asset_id":"86520121088881862182423437128238697252500151785248183602134095101149900014256","price":"0.99","size":"12334.84","side":"SELL","hash":"15cd66324f8b4555ad1d67c3cb2b88cce69ec8d0","best_bid":"0.13","best_ask":"0.14"}],"timestamp":"1776808417239","event_type":"price_change"}}
{"capturedAt":1776808417,"payload":{"market":"0x125149c5918fc5f8c6d34682f700a898a1a19ea4f4e2ae68ff4c5794ba657074","price_changes":[{"asset_id":"45936375922793925919605092352922707796689801895417366600539442410775071099958","price":"0.01","size":"12329.83","side":"BUY","hash":"6546f9ce888377e7c44ea1ee0c19bc94db9d38f0","best_bid":"0.86","best_ask":"0.87"},{"asset_id":"86520121088881862182423437128238697252500151785248183602134095101149900014256","price":"0.99","size":"12329.83","side":"SELL","hash":"9a681b21a6266f45bc747062a5a7294d205e1929","best_bid":"0.13","best_ask":"0.14"}],"timestamp":"1776808417231","event_type":"price_change"}}
{"capturedAt":1776808417,"payload":{"market":"0x125149c5918fc5f8c6d34682f700a898a1a19ea4f4e2ae68ff4c5794ba657074","price_changes":[{"asset_id":"45936375922793925919605092352922707796689801895417366600539442410775071099958","price":"0.01","size":"12329.84","side":"BUY","hash":"f18e6028b8e0b5c1c9d2b8db059b615a7fb0723b","best_bid":"0.86","best_ask":"0.87"},{"asset_id":"86520121088881862182423437128238697252500151785248183602134095101149900014256","price":"0.99","size":"12329.84","side":"SELL","hash":"e6e3eb6db4494ec35de468bbb42a5777f65b2902","best_bid":"0.13","best_ask":"0.14"}],"timestamp":"1776808417242","event_type":"price_change"}}
{"capturedAt":1776808417,"payload":{"market":"0x125149c5918fc5f8c6d34682f700a898a1a19ea4f4e2ae68ff4c5794ba657074","price_changes":[{"asset_id":"45936375922793925919605092352922707796689801895417366600539442410775071099958","price":"0.86","size":"230.93","side":"BUY","hash":"430574f2900b6831c39892ec019fe341112db51f","best_bid":"0.86","best_ask":"0.87"},{"asset_id":"86520121088881862182423437128238697252500151785248183602134095101149900014256","price":"0.14","size":"230.93","side":"SELL","hash":"4f365bb4ff63a7d0f5901801d2ad30c81ba73760","best_bid":"0.13","best_ask":"0.14"}],"timestamp":"1776808417226","event_type":"price_change"}}
{"capturedAt":1776808417,"payload":{"market":"0x125149c5918fc5f8c6d34682f700a898a1a19ea4f4e2ae68ff4c5794ba657074","price_changes":[{"asset_id":"86520121088881862182423437128238697252500151785248183602134095101149900014256","price":"0.13","size":"147.24","side":"BUY","hash":"c01d2bf08255f0f5fad39f3bb65a580edbe72621","best_bid":"0.13","best_ask":"0.14"},{"asset_id":"45936375922793925919605092352922707796689801895417366600539442410775071099958","price":"0.87","size":"147.24","side":"SELL","hash":"e611fc53c95ed19cb1c3fbdc50efedbdd1de7fbc","best_bid":"0.86","best_ask":"0.87"}],"timestamp":"1776808417258","event_type":"price_change"}}
{"capturedAt":1776808417,"payload":{"market":"0x125149c5918fc5f8c6d34682f700a898a1a19ea4f4e2ae68ff4c5794ba657074","price_changes":[{"asset_id":"45936375922793925919605092352922707796689801895417366600539442410775071099958","price":"0.79","size":"294.7","side":"BUY","hash":"fc23a5c168d04207c16ff2e4bbff6c78fac84148","best_bid":"0.86","best_ask":"0.87"},{"asset_id":"86520121088881862182423437128238697252500151785248183602134095101149900014256","price":"0.21","size":"294.7","side":"SELL","hash":"93ca9d29dcf653e1a64dfcc5edf6a0fe9a0d9623","best_bid":"0.13","best_ask":"0.14"}],"timestamp":"1776808417234","event_type":"price_change"}}
{"capturedAt":1776808417,"payload":{"market":"0x125149c5918fc5f8c6d34682f700a898a1a19ea4f4e2ae68ff4c5794ba657074","price_changes":[{"asset_id":"45936375922793925919605092352922707796689801895417366600539442410775071099958","price":"0.86","size":"240.97","side":"BUY","hash":"976ceb1400632e3d89236e291a6e4c318a624ab1","best_bid":"0.86","best_ask":"0.87"},{"asset_id":"86520121088881862182423437128238697252500151785248183602134095101149900014256","price":"0.14","size":"240.97","side":"SELL","hash":"4086b46fb7e0f4eaee9e0a00555467666fba6666","best_bid":"0.13","best_ask":"0.14"}],"timestamp":"1776808417244","event_type":"price_change"}}
{"capturedAt":1776808417,"payload":{"market":"0x125149c5918fc5f8c6d34682f700a898a1a19ea4f4e2ae68ff4c5794ba657074","price_changes":[{"asset_id":"45936375922793925919605092352922707796689801895417366600539442410775071099958","price":"0.86","size":"235.97","side":"BUY","hash":"0370d2acce015b096d5c2320db7e540b8338cb4b","best_bid":"0.86","best_ask":"0.87"},{"asset_id":"86520121088881862182423437128238697252500151785248183602134095101149900014256","price":"0.14","size":"235.97","side":"SELL","hash":"199330a68db2f4b3f8a45fa491145d41f7fe8cf2","best_bid":"0.13","best_ask":"0.14"}],"timestamp":"1776808417255","event_type":"price_change"}}
{"capturedAt":1776808417,"payload":{"market":"0x125149c5918fc5f8c6d34682f700a898a1a19ea4f4e2ae68ff4c5794ba657074","price_changes":[{"asset_id":"45936375922793925919605092352922707796689801895417366600539442410775071099958","price":"0.86","size":"245.97","side":"BUY","hash":"788f180ff9362d9d8e3bc833d04503336cf200cd","best_bid":"0.86","best_ask":"0.87"},{"asset_id":"86520121088881862182423437128238697252500151785248183602134095101149900014256","price":"0.14","size":"245.97","side":"SELL","hash":"badff006f906123dcea4534b80c7e4e54526271d","best_bid":"0.13","best_ask":"0.14"}],"timestamp":"1776808417233","event_type":"price_change"}}
{"capturedAt":1776808417,"payload":{"market":"0x125149c5918fc5f8c6d34682f700a898a1a19ea4f4e2ae68ff4c5794ba657074","price_changes":[{"asset_id":"45936375922793925919605092352922707796689801895417366600539442410775071099958","price":"0.86","size":"230.97","side":"BUY","hash":"75cdc37221cd5ca713599c8f75267d6e6bf2f04f","best_bid":"0.86","best_ask":"0.87"},{"asset_id":"86520121088881862182423437128238697252500151785248183602134095101149900014256","price":"0.14","size":"230.97","side":"SELL","hash":"9d070e0858b5762e9452480c50ff28325bf0deee","best_bid":"0.13","best_ask":"0.14"}],"timestamp":"1776808417259","event_type":"price_change"}}
{"capturedAt":1776808417,"payload":{"market":"0x125149c5918fc5f8c6d34682f700a898a1a19ea4f4e2ae68ff4c5794ba657074","price_changes":[{"asset_id":"45936375922793925919605092352922707796689801895417366600539442410775071099958","price":"0.86","size":"220.97","side":"BUY","hash":"b46e8f51be6a7dd6c381949654751c58302df7b7","best_bid":"0.86","best_ask":"0.87"},{"asset_id":"86520121088881862182423437128238697252500151785248183602134095101149900014256","price":"0.14","size":"220.97","side":"SELL","hash":"c7b36c9d804adfb425ba5ec254baeb54d52e68a7","best_bid":"0.13","best_ask":"0.14"}],"timestamp":"1776808417261","event_type":"price_change"}}
{"capturedAt":1776808417,"payload":{"market":"0x125149c5918fc5f8c6d34682f700a898a1a19ea4f4e2ae68ff4c5794ba657074","price_changes":[{"asset_id":"45936375922793925919605092352922707796689801895417366600539442410775071099958","price":"0.86","size":"215.97","side":"BUY","hash":"d9a27393715ca43fcc52d26873b4b76e0d52620f","best_bid":"0.86","best_ask":"0.87"},{"asset_id":"86520121088881862182423437128238697252500151785248183602134095101149900014256","price":"0.14","size":"215.97","side":"SELL","hash":"e746c4e296e944d0998782d63bb6e6bf83a60d4b","best_bid":"0.13","best_ask":"0.14"}],"timestamp":"1776808417263","event_type":"price_change"}}
{"capturedAt":1776808417,"payload":{"market":"0x125149c5918fc5f8c6d34682f700a898a1a19ea4f4e2ae68ff4c5794ba657074","price_changes":[{"asset_id":"45936375922793925919605092352922707796689801895417366600539442410775071099958","price":"0.01","size":"12324.83","side":"BUY","hash":"b63ce5a3c7f29ecf5fbaa6efb8421c481cf78997","best_bid":"0.86","best_ask":"0.87"},{"asset_id":"86520121088881862182423437128238697252500151785248183602134095101149900014256","price":"0.99","size":"12324.83","side":"SELL","hash":"0e4930e015db9bfd57fd766e726443eb2537a8e8","best_bid":"0.13","best_ask":"0.14"}],"timestamp":"1776808417264","event_type":"price_change"}}
{"capturedAt":1776808417,"payload":{"market":"0x125149c5918fc5f8c6d34682f700a898a1a19ea4f4e2ae68ff4c5794ba657074","price_changes":[{"asset_id":"45936375922793925919605092352922707796689801895417366600539442410775071099958","price":"0.01","size":"12329.83","side":"BUY","hash":"22f8e549d5312c56286514058666860faa22748f","best_bid":"0.86","best_ask":"0.87"},{"asset_id":"86520121088881862182423437128238697252500151785248183602134095101149900014256","price":"0.99","size":"12329.83","side":"SELL","hash":"bec81f172203340b6d548b03b201ae5fac92e318","best_bid":"0.13","best_ask":"0.14"}],"timestamp":"1776808417266","event_type":"price_change"}}
{"capturedAt":1776808417,"payload":{"market":"0x125149c5918fc5f8c6d34682f700a898a1a19ea4f4e2ae68ff4c5794ba657074","price_changes":[{"asset_id":"45936375922793925919605092352922707796689801895417366600539442410775071099958","price":"0.86","size":"210.97","side":"BUY","hash":"8343efbe229b7714ae7b8240a017ffb65d861e37","best_bid":"0.86","best_ask":"0.87"},{"asset_id":"86520121088881862182423437128238697252500151785248183602134095101149900014256","price":"0.14","size":"210.97","side":"SELL","hash":"3a745199ed12f209792c4fcbe9b24b71b13a163e","best_bid":"0.13","best_ask":"0.14"}],"timestamp":"1776808417267","event_type":"price_change"}}
{"capturedAt":1776808417,"payload":{"market":"0x125149c5918fc5f8c6d34682f700a898a1a19ea4f4e2ae68ff4c5794ba657074","price_changes":[{"asset_id":"86520121088881862182423437128238697252500151785248183602134095101149900014256","price":"0.13","size":"142.24","side":"BUY","hash":"55c240b375c6e51d3fea8a076fb1162b5a341d04","best_bid":"0.13","best_ask":"0.14"},{"asset_id":"45936375922793925919605092352922707796689801895417366600539442410775071099958","price":"0.87","size":"142.24","side":"SELL","hash":"bc0b89a2c03b0d3fd70c980601db3bccb799b051","best_bid":"0.86","best_ask":"0.87"}],"timestamp":"1776808417270","event_type":"price_change"}}
{"capturedAt":1776808417,"payload":{"market":"0x125149c5918fc5f8c6d34682f700a898a1a19ea4f4e2ae68ff4c5794ba657074","price_changes":[{"asset_id":"45936375922793925919605092352922707796689801895417366600539442410775071099958","price":"0.86","size":"205.97","side":"BUY","hash":"851a5b4e50c08aec2309ab4eb7637eddcc526c4b","best_bid":"0.86","best_ask":"0.87"},{"asset_id":"86520121088881862182423437128238697252500151785248183602134095101149900014256","price":"0.14","size":"205.97","side":"SELL","hash":"0f5ecc34a8165a5e6b047990ad33348e493f6281","best_bid":"0.13","best_ask":"0.14"}],"timestamp":"1776808417271","event_type":"price_change"}}
{"capturedAt":1776808417,"payload":{"market":"0x125149c5918fc5f8c6d34682f700a898a1a19ea4f4e2ae68ff4c5794ba657074","price_changes":[{"asset_id":"45936375922793925919605092352922707796689801895417366600539442410775071099958","price":"0.01","size":"12334.84","side":"BUY","hash":"e23ab893d1fecb61586de6bb2d87df73e1342b83","best_bid":"0.86","best_ask":"0.87"},{"asset_id":"86520121088881862182423437128238697252500151785248183602134095101149900014256","price":"0.99","size":"12334.84","side":"SELL","hash":"863e8c92b328c8c8c489bc89bafe39a6a2c9491d","best_bid":"0.13","best_ask":"0.14"}],"timestamp":"1776808417273","event_type":"price_change"}}
{"capturedAt":1776808417,"payload":{"market":"0x125149c5918fc5f8c6d34682f700a898a1a19ea4f4e2ae68ff4c5794ba657074","price_changes":[{"asset_id":"45936375922793925919605092352922707796689801895417366600539442410775071099958","price":"0.86","size":"200.97","side":"BUY","hash":"1ae8209c5d580cb04def5e19efb604c61dec0a48","best_bid":"0.86","best_ask":"0.87"},{"asset_id":"86520121088881862182423437128238697252500151785248183602134095101149900014256","price":"0.14","size":"200.97","side":"SELL","hash":"fc7b629e2b8afe84f0f93a5983c97b7d6f994466","best_bid":"0.13","best_ask":"0.14"}],"timestamp":"1776808417272","event_type":"price_change"}}
{"capturedAt":1776808417,"payload":{"market":"0x125149c5918fc5f8c6d34682f700a898a1a19ea4f4e2ae68ff4c5794ba657074","price_changes":[{"asset_id":"45936375922793925919605092352922707796689801895417366600539442410775071099958","price":"0.86","size":"195.97","side":"BUY","hash":"f14e2a5381f9529aa37e71e098283f0bbd271c3a","best_bid":"0.86","best_ask":"0.87"},{"asset_id":"86520121088881862182423437128238697252500151785248183602134095101149900014256","price":"0.14","size":"195.97","side":"SELL","hash":"dd3be7d6d6561aec2da846f0d8e80aa4ab40551d","best_bid":"0.13","best_ask":"0.14"}],"timestamp":"1776808417274","event_type":"price_change"}}
{"capturedAt":1776808417,"payload":{"market":"0x125149c5918fc5f8c6d34682f700a898a1a19ea4f4e2ae68ff4c5794ba657074","price_changes":[{"asset_id":"45936375922793925919605092352922707796689801895417366600539442410775071099958","price":"0.01","size":"12339.84","side":"BUY","hash":"528220960850e7e99c74731e08ecb8de2c7326cd","best_bid":"0.86","best_ask":"0.87"},{"asset_id":"86520121088881862182423437128238697252500151785248183602134095101149900014256","price":"0.99","size":"12339.84","side":"SELL","hash":"7bd19b346aae33c3853b95d035d51e6a58761c1a","best_bid":"0.13","best_ask":"0.14"}],"timestamp":"1776808417275","event_type":"price_change"}}
{"capturedAt":1776808417,"payload":{"market":"0x125149c5918fc5f8c6d34682f700a898a1a19ea4f4e2ae68ff4c5794ba657074","price_changes":[{"asset_id":"45936375922793925919605092352922707796689801895417366600539442410775071099958","price":"0.86","size":"190.97","side":"BUY","hash":"674e88f951395f3416fb958729cab033c1e5a45c","best_bid":"0.86","best_ask":"0.87"},{"asset_id":"86520121088881862182423437128238697252500151785248183602134095101149900014256","price":"0.14","size":"190.97","side":"SELL","hash":"a2b0fd444254292fb5194c9d39d6dd62a20ae244","best_bid":"0.13","best_ask":"0.14"}],"timestamp":"1776808417276","event_type":"price_change"}}
{"capturedAt":1776808417,"payload":{"market":"0x125149c5918fc5f8c6d34682f700a898a1a19ea4f4e2ae68ff4c5794ba657074","price_changes":[{"asset_id":"86520121088881862182423437128238697252500151785248183602134095101149900014256","price":"0.13","size":"137.24","side":"BUY","hash":"1afecf994135b44f96ac2e0e9891d9653512535f","best_bid":"0.13","best_ask":"0.14"},{"asset_id":"45936375922793925919605092352922707796689801895417366600539442410775071099958","price":"0.87","size":"137.24","side":"SELL","hash":"2984303a6baf49799e3f78401ae6c3952198b38f","best_bid":"0.86","best_ask":"0.87"}],"timestamp":"1776808417278","event_type":"price_change"}}
{"capturedAt":1776808417,"payload":{"market":"0x125149c5918fc5f8c6d34682f700a898a1a19ea4f4e2ae68ff4c5794ba657074","price_changes":[{"asset_id":"45936375922793925919605092352922707796689801895417366600539442410775071099958","price":"0.86","size":"195.97","side":"BUY","hash":"7cb98856e3dc056b60f27eaedd097345e15769c4","best_bid":"0.86","best_ask":"0.87"},{"asset_id":"86520121088881862182423437128238697252500151785248183602134095101149900014256","price":"0.14","size":"195.97","side":"SELL","hash":"185fc4788b7f56b17e2d00a84a04751eab0c6db6","best_bid":"0.13","best_ask":"0.14"}],"timestamp":"1776808417277","event_type":"price_change"}}
{"capturedAt":1776808417,"payload":{"market":"0x125149c5918fc5f8c6d34682f700a898a1a19ea4f4e2ae68ff4c5794ba657074","price_changes":[{"asset_id":"45936375922793925919605092352922707796689801895417366600539442410775071099958","price":"0.86","size":"189.97","side":"BUY","hash":"a80528ba629638f5b68304d4ea942ca0f90a997b","best_bid":"0.86","best_ask":"0.87"},{"asset_id":"86520121088881862182423437128238697252500151785248183602134095101149900014256","price":"0.14","size":"189.97","side":"SELL","hash":"7af4a58aa9d7a6782529ae559dfb5296594eebf3","best_bid":"0.13","best_ask":"0.14"}],"timestamp":"1776808417279","event_type":"price_change"}}
{"capturedAt":1776808417,"payload":{"market":"0x125149c5918fc5f8c6d34682f700a898a1a19ea4f4e2ae68ff4c5794ba657074","price_changes":[{"asset_id":"45936375922793925919605092352922707796689801895417366600539442410775071099958","price":"0.86","size":"194.97","side":"BUY","hash":"bdb309d54120ccc7de1a828e95980c60e69c7427","best_bid":"0.86","best_ask":"0.87"},{"asset_id":"86520121088881862182423437128238697252500151785248183602134095101149900014256","price":"0.14","size":"194.97","side":"SELL","hash":"362a551629d79e9cd088999bf92155e100e8e83b","best_bid":"0.13","best_ask":"0.14"}],"timestamp":"1776808417280","event_type":"price_change"}}
{"capturedAt":1776808417,"payload":{"market":"0x125149c5918fc5f8c6d34682f700a898a1a19ea4f4e2ae68ff4c5794ba657074","price_changes":[{"asset_id":"86520121088881862182423437128238697252500151785248183602134095101149900014256","price":"0.13","size":"142.24","side":"BUY","hash":"fb2b154560eb8c6a56c50af12daf63460501e4b2","best_bid":"0.13","best_ask":"0.14"},{"asset_id":"45936375922793925919605092352922707796689801895417366600539442410775071099958","price":"0.87","size":"142.24","side":"SELL","hash":"99d3b65fca67fe41b240d0ba99f4fcb986a3a937","best_bid":"0.86","best_ask":"0.87"}],"timestamp":"1776808417282","event_type":"price_change"}}
{"capturedAt":1776808417,"payload":{"market":"0x125149c5918fc5f8c6d34682f700a898a1a19ea4f4e2ae68ff4c5794ba657074","price_changes":[{"asset_id":"45936375922793925919605092352922707796689801895417366600539442410775071099958","price":"0.86","size":"199.97","side":"BUY","hash":"a1b17ee3fb1435c0f5ec6c948772219bb603c78b","best_bid":"0.86","best_ask":"0.87"},{"asset_id":"86520121088881862182423437128238697252500151785248183602134095101149900014256","price":"0.14","size":"199.97","side":"SELL","hash":"20d76a58699734721717bc723a38a18e1457a0e5","best_bid":"0.13","best_ask":"0.14"}],"timestamp":"1776808417282","event_type":"price_change"}}
{"capturedAt":1776808417,"payload":{"market":"0x125149c5918fc5f8c6d34682f700a898a1a19ea4f4e2ae68ff4c5794ba657074","price_changes":[{"asset_id":"45936375922793925919605092352922707796689801895417366600539442410775071099958","price":"0.01","size":"12334.84","side":"BUY","hash":"ad4d5f232002c9567969fbb1cce6b22414512ae5","best_bid":"0.86","best_ask":"0.87"},{"asset_id":"86520121088881862182423437128238697252500151785248183602134095101149900014256","price":"0.99","size":"12334.84","side":"SELL","hash":"2f476994071218d15e3c01a99f6fc267b82c43fb","best_bid":"0.13","best_ask":"0.14"}],"timestamp":"1776808417284","event_type":"price_change"}}
{"capturedAt":1776808417,"payload":{"market":"0x125149c5918fc5f8c6d34682f700a898a1a19ea4f4e2ae68ff4c5794ba657074","price_changes":[{"asset_id":"86520121088881862182423437128238697252500151785248183602134095101149900014256","price":"0.95","size":"906.34","side":"SELL","hash":"8b7ae8af155d633ff37efe03fa39279cf10a2c70","best_bid":"0.13","best_ask":"0.14"},{"asset_id":"45936375922793925919605092352922707796689801895417366600539442410775071099958","price":"0.05","size":"906.34","side":"BUY","hash":"72db7be2d0eda5cc3994c7a38f1271ca6262da0c","best_bid":"0.86","best_ask":"0.87"}],"timestamp":"1776808417291","event_type":"price_change"}}
{"capturedAt":1776808417,"payload":{"market":"0x125149c5918fc5f8c6d34682f700a898a1a19ea4f4e2ae68ff4c5794ba657074","price_changes":[{"asset_id":"45936375922793925919605092352922707796689801895417366600539442410775071099958","price":"0.86","size":"209.97","side":"BUY","hash":"b505ae9993513bc38850fe61e1b5ad76eb83ccad","best_bid":"0.86","best_ask":"0.87"},{"asset_id":"86520121088881862182423437128238697252500151785248183602134095101149900014256","price":"0.14","size":"209.97","side":"SELL","hash":"cc1a2982d7a88111410c189e187b4c1f2c09ea95","best_bid":"0.13","best_ask":"0.14"}],"timestamp":"1776808417290","event_type":"price_change"}}
{"capturedAt":1776808417,"payload":{"market":"0x125149c5918fc5f8c6d34682f700a898a1a19ea4f4e2ae68ff4c5794ba657074","price_changes":[{"asset_id":"45936375922793925919605092352922707796689801895417366600539442410775071099958","price":"0.86","size":"209.97","side":"BUY","hash":"c62f947c237e46b073a5f0b2ac30259d39732406","best_bid":"0.86","best_ask":"0.87"},{"asset_id":"86520121088881862182423437128238697252500151785248183602134095101149900014256","price":"0.14","size":"209.97","side":"SELL","hash":"8170a40e8d09babda411655d67804c82a5f52c1d","best_bid":"0.13","best_ask":"0.14"}],"timestamp":"1776808417294","event_type":"price_change"}}
{"capturedAt":1776808417,"payload":{"market":"0x125149c5918fc5f8c6d34682f700a898a1a19ea4f4e2ae68ff4c5794ba657074","price_changes":[{"asset_id":"45936375922793925919605092352922707796689801895417366600539442410775071099958","price":"0.86","size":"215.97","side":"BUY","hash":"5ca680ca1e09a9621a4bd60067e46be6c5a0c137","best_bid":"0.86","best_ask":"0.87"},{"asset_id":"86520121088881862182423437128238697252500151785248183602134095101149900014256","price":"0.14","size":"215.97","side":"SELL","hash":"3683f9f5d3e04889a179869b06021a4a049d4532","best_bid":"0.13","best_ask":"0.14"}],"timestamp":"1776808417293","event_type":"price_change"}}
{"capturedAt":1776808417,"payload":{"market":"0x125149c5918fc5f8c6d34682f700a898a1a19ea4f4e2ae68ff4c5794ba657074","price_changes":[{"asset_id":"45936375922793925919605092352922707796689801895417366600539442410775071099958","price":"0.86","size":"215.97","side":"BUY","hash":"81b5ec044bb817919a470fddea5c171d4789cb90","best_bid":"0.86","best_ask":"0.87"},{"asset_id":"86520121088881862182423437128238697252500151785248183602134095101149900014256","price":"0.14","size":"215.97","side":"SELL","hash":"29d5c23320a6c260468de38353abe3fddfe2d6fd","best_bid":"0.13","best_ask":"0.14"}],"timestamp":"1776808417297","event_type":"price_change"}}
{"capturedAt":1776808417,"payload":{"market":"0x125149c5918fc5f8c6d34682f700a898a1a19ea4f4e2ae68ff4c5794ba657074","price_changes":[{"asset_id":"45936375922793925919605092352922707796689801895417366600539442410775071099958","price":"0.01","size":"12329.84","side":"BUY","hash":"b0e690fb2139896a10e3680db32a7df5c9de4d88","best_bid":"0.86","best_ask":"0.87"},{"asset_id":"86520121088881862182423437128238697252500151785248183602134095101149900014256","price":"0.99","size":"12329.84","side":"SELL","hash":"6c9ffa7a7e05f1e5ced8876d391549e39a34d6b6","best_bid":"0.13","best_ask":"0.14"}],"timestamp":"1776808417295","event_type":"price_change"}}
{"capturedAt":1776808417,"payload":{"market":"0x125149c5918fc5f8c6d34682f700a898a1a19ea4f4e2ae68ff4c5794ba657074","price_changes":[{"asset_id":"45936375922793925919605092352922707796689801895417366600539442410775071099958","price":"0.86","size":"210.97","side":"BUY","hash":"e23d0b8bdf8ce00d15cffef10d10c354ddc254ef","best_bid":"0.86","best_ask":"0.87"},{"asset_id":"86520121088881862182423437128238697252500151785248183602134095101149900014256","price":"0.14","size":"210.97","side":"SELL","hash":"51b31800b7fb55cf33d22d5869bac68fb38801c0","best_bid":"0.13","best_ask":"0.14"}],"timestamp":"1776808417299","event_type":"price_change"}}
{"capturedAt":1776808417,"payload":{"market":"0x125149c5918fc5f8c6d34682f700a898a1a19ea4f4e2ae68ff4c5794ba657074","price_changes":[{"asset_id":"45936375922793925919605092352922707796689801895417366600539442410775071099958","price":"0.86","size":"220.97","side":"BUY","hash":"8d7aa5c05fca8763054e071130be4fd600429a3d","best_bid":"0.86","best_ask":"0.87"},{"asset_id":"86520121088881862182423437128238697252500151785248183602134095101149900014256","price":"0.14","size":"220.97","side":"SELL","hash":"e1d00c58cfdaf378c51660e668c769a0dde64117","best_bid":"0.13","best_ask":"0.14"}],"timestamp":"1776808417298","event_type":"price_change"}}
{"capturedAt":1776808417,"payload":{"market":"0x125149c5918fc5f8c6d34682f700a898a1a19ea4f4e2ae68ff4c5794ba657074","price_changes":[{"asset_id":"45936375922793925919605092352922707796689801895417366600539442410775071099958","price":"0.86","size":"205.93","side":"BUY","hash":"27a34ea160ab5d77252682372ca6a39f4785b593","best_bid":"0.86","best_ask":"0.87"},{"asset_id":"86520121088881862182423437128238697252500151785248183602134095101149900014256","price":"0.14","size":"205.93","side":"SELL","hash":"2da0e015e26e91bb0bf7c6e2f33c604b0522abb6","best_bid":"0.13","best_ask":"0.14"}],"timestamp":"1776808417300","event_type":"price_change"}}
{"capturedAt":1776808417,"payload":{"market":"0x125149c5918fc5f8c6d34682f700a898a1a19ea4f4e2ae68ff4c5794ba657074","price_changes":[{"asset_id":"45936375922793925919605092352922707796689801895417366600539442410775071099958","price":"0.01","size":"12324.83","side":"BUY","hash":"bbfe4ebffa39b1f814aa0a92a962596f86bb657e","best_bid":"0.86","best_ask":"0.87"},{"asset_id":"86520121088881862182423437128238697252500151785248183602134095101149900014256","price":"0.99","size":"12324.83","side":"SELL","hash":"cb4c334b07ced100f6034abe562d9377f4d67cf5","best_bid":"0.13","best_ask":"0.14"}],"timestamp":"1776808417301","event_type":"price_change"}}
{"capturedAt":1776808417,"payload":{"market":"0x125149c5918fc5f8c6d34682f700a898a1a19ea4f4e2ae68ff4c5794ba657074","price_changes":[{"asset_id":"45936375922793925919605092352922707796689801895417366600539442410775071099958","price":"0.86","size":"195.93","side":"BUY","hash":"2a8e973aab1e93856cec31c6c59694f0e962c2f3","best_bid":"0.86","best_ask":"0.87"},{"asset_id":"86520121088881862182423437128238697252500151785248183602134095101149900014256","price":"0.14","size":"195.93","side":"SELL","hash":"31f5b48980bdeb132cbb520a9b222e9645becd78","best_bid":"0.13","best_ask":"0.14"}],"timestamp":"1776808417302","event_type":"price_change"}}
{"capturedAt":1776808417,"payload":{"market":"0x125149c5918fc5f8c6d34682f700a898a1a19ea4f4e2ae68ff4c5794ba657074","price_changes":[{"asset_id":"86520121088881862182423437128238697252500151785248183602134095101149900014256","price":"0.95","size":"1006.34","side":"SELL","hash":"ec2130e74127b9fc079050caae051482d7f5b73b","best_bid":"0.13","best_ask":"0.14"},{"asset_id":"45936375922793925919605092352922707796689801895417366600539442410775071099958","price":"0.05","size":"1006.34","side":"BUY","hash":"6c0a66f670a830cbcbbc5d6cd73b88d83c370783","best_bid":"0.86","best_ask":"0.87"}],"timestamp":"1776808417304","event_type":"price_change"}}
{"capturedAt":1776808417,"payload":{"market":"0x125149c5918fc5f8c6d34682f700a898a1a19ea4f4e2ae68ff4c5794ba657074","price_changes":[{"asset_id":"45936375922793925919605092352922707796689801895417366600539442410775071099958","price":"0.86","size":"200.93","side":"BUY","hash":"7ca84ace8c0bf9ffb228d8d58a6137949ec194f5","best_bid":"0.86","best_ask":"0.87"},{"asset_id":"86520121088881862182423437128238697252500151785248183602134095101149900014256","price":"0.14","size":"200.93","side":"SELL","hash":"99c3e0f693b435cf996bbe9f3cb6a8265b052530","best_bid":"0.13","best_ask":"0.14"}],"timestamp":"1776808417305","event_type":"price_change"}}
{"capturedAt":1776808417,"payload":{"market":"0x125149c5918fc5f8c6d34682f700a898a1a19ea4f4e2ae68ff4c5794ba657074","price_changes":[{"asset_id":"86520121088881862182423437128238697252500151785248183602134095101149900014256","price":"0.95","size":"906.34","side":"SELL","hash":"98ed45a35011d02271010b4fb933c979953565a2","best_bid":"0.13","best_ask":"0.14"},{"asset_id":"45936375922793925919605092352922707796689801895417366600539442410775071099958","price":"0.05","size":"906.34","side":"BUY","hash":"710c1a90cd808b3b94fb48e3718a5f5b89e2caed","best_bid":"0.86","best_ask":"0.87"}],"timestamp":"1776808417306","event_type":"price_change"}}
{"capturedAt":1776808417,"payload":{"market":"0x125149c5918fc5f8c6d34682f700a898a1a19ea4f4e2ae68ff4c5794ba657074","price_changes":[{"asset_id":"45936375922793925919605092352922707796689801895417366600539442410775071099958","price":"0.86","size":"205.93","side":"BUY","hash":"37e0a7cb416ad58bbffd83dce80566d04e3b5f60","best_bid":"0.86","best_ask":"0.87"},{"asset_id":"86520121088881862182423437128238697252500151785248183602134095101149900014256","price":"0.14","size":"205.93","side":"SELL","hash":"8856e792962fd6212bbc3cc1658863d3a24828e1","best_bid":"0.13","best_ask":"0.14"}],"timestamp":"1776808417307","event_type":"price_change"}}
{"capturedAt":1776808417,"payload":{"market":"0x125149c5918fc5f8c6d34682f700a898a1a19ea4f4e2ae68ff4c5794ba657074","price_changes":[{"asset_id":"45936375922793925919605092352922707796689801895417366600539442410775071099958","price":"0.86","size":"210.93","side":"BUY","hash":"228923c62cff034371c9fb6da7de356fe80785dc","best_bid":"0.86","best_ask":"0.87"},{"asset_id":"86520121088881862182423437128238697252500151785248183602134095101149900014256","price":"0.14","size":"210.93","side":"SELL","hash":"4b6cd0c4f21c3be94c4da27c5512a62b262ca3c4","best_bid":"0.13","best_ask":"0.14"}],"timestamp":"1776808417309","event_type":"price_change"}}
{"capturedAt":1776808417,"payload":{"market":"0x125149c5918fc5f8c6d34682f700a898a1a19ea4f4e2ae68ff4c5794ba657074","price_changes":[{"asset_id":"45936375922793925919605092352922707796689801895417366600539442410775071099958","price":"0.01","size":"12329.83","side":"BUY","hash":"fcb54b020d2d6dbfddafc240215d4798436a7866","best_bid":"0.86","best_ask":"0.87"},{"asset_id":"86520121088881862182423437128238697252500151785248183602134095101149900014256","price":"0.99","size":"12329.83","side":"SELL","hash":"92a11c98f7bf81e6eb1662d2885ceb27a7a18f1a","best_bid":"0.13","best_ask":"0.14"}],"timestamp":"1776808417332","event_type":"price_change"}}
{"capturedAt":1776808417,"payload":{"market":"0x125149c5918fc5f8c6d34682f700a898a1a19ea4f4e2ae68ff4c5794ba657074","price_changes":[{"asset_id":"45936375922793925919605092352922707796689801895417366600539442410775071099958","price":"0.86","size":"215.93","side":"BUY","hash":"e95127c01af8a6438d8b2579dd65f9ff4b1a0b8f","best_bid":"0.86","best_ask":"0.87"},{"asset_id":"86520121088881862182423437128238697252500151785248183602134095101149900014256","price":"0.14","size":"215.93","side":"SELL","hash":"9afb07b0b2be2ddf3caa3a485da4a35a1e6602e5","best_bid":"0.13","best_ask":"0.14"}],"timestamp":"1776808417331","event_type":"price_change"}}
{"capturedAt":1776808417,"payload":{"market":"0x125149c5918fc5f8c6d34682f700a898a1a19ea4f4e2ae68ff4c5794ba657074","price_changes":[{"asset_id":"45936375922793925919605092352922707796689801895417366600539442410775071099958","price":"0.86","size":"220.99","side":"BUY","hash":"9f43c8feebb442f497eea7a4d31c3e20d09aa67b","best_bid":"0.86","best_ask":"0.87"},{"asset_id":"86520121088881862182423437128238697252500151785248183602134095101149900014256","price":"0.14","size":"220.99","side":"SELL","hash":"c6d50029c2a36fa5be7785ca97494ede83de4080","best_bid":"0.13","best_ask":"0.14"}],"timestamp":"1776808417333","event_type":"price_change"}}
{"capturedAt":1776808417,"payload":{"market":"0x125149c5918fc5f8c6d34682f700a898a1a19ea4f4e2ae68ff4c5794ba657074","price_changes":[{"asset_id":"86520121088881862182423437128238697252500151785248183602134095101149900014256","price":"0.95","size":"1006.34","side":"SELL","hash":"37fc9db723a0883bbd8bc3cb5e763205a83f1eec","best_bid":"0.13","best_ask":"0.14"},{"asset_id":"45936375922793925919605092352922707796689801895417366600539442410775071099958","price":"0.05","size":"1006.34","side":"BUY","hash":"4e9a4b2af96990eb2b18a7c5c8d9151477c0060f","best_bid":"0.86","best_ask":"0.87"}],"timestamp":"1776808417335","event_type":"price_change"}}
{"capturedAt":1776808417,"payload":{"market":"0x125149c5918fc5f8c6d34682f700a898a1a19ea4f4e2ae68ff4c5794ba657074","price_changes":[{"asset_id":"45936375922793925919605092352922707796689801895417366600539442410775071099958","price":"0.86","size":"230.99","side":"BUY","hash":"c1e15cc2b1451859352657cbaea6519667414b62","best_bid":"0.86","best_ask":"0.87"},{"asset_id":"86520121088881862182423437128238697252500151785248183602134095101149900014256","price":"0.14","size":"230.99","side":"SELL","hash":"d806791332c43e5c292398d7291d01a4c5eb05e0","best_bid":"0.13","best_ask":"0.14"}],"timestamp":"1776808417336","event_type":"price_change"}}
{"capturedAt":1776808417,"payload":{"market":"0x125149c5918fc5f8c6d34682f700a898a1a19ea4f4e2ae68ff4c5794ba657074","price_changes":[{"asset_id":"45936375922793925919605092352922707796689801895417366600539442410775071099958","price":"0.86","size":"236.99","side":"BUY","hash":"75083b317cddfa3dfecd260c0ad1fb047f4ff0ce","best_bid":"0.86","best_ask":"0.87"},{"asset_id":"86520121088881862182423437128238697252500151785248183602134095101149900014256","price":"0.14","size":"236.99","side":"SELL","hash":"35861f60dbf8915987dc87fa2f32fc46554391dd","best_bid":"0.13","best_ask":"0.14"}],"timestamp":"1776808417337","event_type":"price_change"}}
{"capturedAt":1776808417,"payload":{"market":"0x125149c5918fc5f8c6d34682f700a898a1a19ea4f4e2ae68ff4c5794ba657074","price_changes":[{"asset_id":"45936375922793925919605092352922707796689801895417366600539442410775071099958","price":"0.01","size":"12334.83","side":"BUY","hash":"9aa369a1f2217d79c16ff1f7d085cb410dd24340","best_bid":"0.86","best_ask":"0.87"},{"asset_id":"86520121088881862182423437128238697252500151785248183602134095101149900014256","price":"0.99","size":"12334.83","side":"SELL","hash":"6400a2e3c19e318065a78eb36f6729b9d1ee94b6","best_bid":"0.13","best_ask":"0.14"}],"timestamp":"1776808417338","event_type":"price_change"}}
{"capturedAt":1776808417,"payload":{"market":"0x125149c5918fc5f8c6d34682f700a898a1a19ea4f4e2ae68ff4c5794ba657074","price_changes":[{"asset_id":"45936375922793925919605092352922707796689801895417366600539442410775071099958","price":"0.86","size":"246.99","side":"BUY","hash":"b5e53d889917dc191135aae23e7407ac5bd95f5e","best_bid":"0.86","best_ask":"0.87"},{"asset_id":"86520121088881862182423437128238697252500151785248183602134095101149900014256","price":"0.14","size":"246.99","side":"SELL","hash":"879096333412f3280f3218012a96caedf6e5f2cc","best_bid":"0.13","best_ask":"0.14"}],"timestamp":"1776808417339","event_type":"price_change"}}
{"capturedAt":1776808417,"payload":{"market":"0x125149c5918fc5f8c6d34682f700a898a1a19ea4f4e2ae68ff4c5794ba657074","price_changes":[{"asset_id":"86520121088881862182423437128238697252500151785248183602134095101149900014256","price":"0.12","size":"332.5","side":"BUY","hash":"b1051120f214b9d4d14287510958a06301a97492","best_bid":"0.13","best_ask":"0.14"},{"asset_id":"45936375922793925919605092352922707796689801895417366600539442410775071099958","price":"0.88","size":"332.5","side":"SELL","hash":"72a01af61541c15d91e18c2d0cc5f96f939d7067","best_bid":"0.86","best_ask":"0.87"}],"timestamp":"1776808417341","event_type":"price_change"}}
{"capturedAt":1776808417,"payload":{"market":"0x125149c5918fc5f8c6d34682f700a898a1a19ea4f4e2ae68ff4c5794ba657074","price_changes":[{"asset_id":"45936375922793925919605092352922707796689801895417366600539442410775071099958","price":"0.86","size":"246.1","side":"BUY","hash":"086c853825f20142a716406b6ee9285abbf08ca2","best_bid":"0.86","best_ask":"0.87"},{"asset_id":"86520121088881862182423437128238697252500151785248183602134095101149900014256","price":"0.14","size":"246.1","side":"SELL","hash":"3c94955ca4cd4b87f4eab9de253afdb202c19e24","best_bid":"0.13","best_ask":"0.14"}],"timestamp":"1776808417340","event_type":"price_change"}}
{"capturedAt":1776808417,"payload":{"market":"0x125149c5918fc5f8c6d34682f700a898a1a19ea4f4e2ae68ff4c5794ba657074","price_changes":[{"asset_id":"45936375922793925919605092352922707796689801895417366600539442410775071099958","price":"0.86","size":"228.6","side":"BUY","hash":"fdb0119159a80880afb6bf154f661fbdb48f3ff1","best_bid":"0.86","best_ask":"0.87"},{"asset_id":"86520121088881862182423437128238697252500151785248183602134095101149900014256","price":"0.14","size":"228.6","side":"SELL","hash":"59bd30f4eb614b3117d62a916e6934ddd2250331","best_bid":"0.13","best_ask":"0.14"}],"timestamp":"1776808417342","event_type":"price_change"}}
{"capturedAt":1776808417,"payload":{"market":"0x125149c5918fc5f8c6d34682f700a898a1a19ea4f4e2ae68ff4c5794ba657074","price_changes":[{"asset_id":"86520121088881862182423437128238697252500151785248183602134095101149900014256","price":"0.13","size":"191.24","side":"BUY","hash":"3888b08f72f2ef0b13776d9e928eafda7a6d7ec9","best_bid":"0.13","best_ask":"0.14"},{"asset_id":"45936375922793925919605092352922707796689801895417366600539442410775071099958","price":"0.87","size":"191.24","side":"SELL","hash":"245dd11ccf7d6b7a589f7889e99b2bf3fc9b969e","best_bid":"0.86","best_ask":"0.87"}],"timestamp":"1776808417343","event_type":"price_change"}}
{"capturedAt":1776808417,"payload":{"market":"0x125149c5918fc5f8c6d34682f700a898a1a19ea4f4e2ae68ff4c5794ba657074","price_changes":[{"asset_id":"86520121088881862182423437128238697252500151785248183602134095101149900014256","price":"0.13","size":"208.74","side":"BUY","hash":"52b81257edd92613130c1edea0b240a4150a5e20","best_bid":"0.13","best_ask":"0.14"},{"asset_id":"45936375922793925919605092352922707796689801895417366600539442410775071099958","price":"0.87","size":"208.74","side":"SELL","hash":"047e7bd79e278642e1ad7275c07c412a5f1765c6","best_bid":"0.86","best_ask":"0.87"}],"timestamp":"1776808417344","event_type":"price_change"}}
{"capturedAt":1776808417,"payload":{"market":"0x125149c5918fc5f8c6d34682f700a898a1a19ea4f4e2ae68ff4c5794ba657074","price_changes":[{"asset_id":"86520121088881862182423437128238697252500151785248183602134095101149900014256","price":"0.11","size":"374","side":"BUY","hash":"4ad6ecd19d93a3b4e90548fd11757070b3872e95","best_bid":"0.13","best_ask":"0.14"},{"asset_id":"45936375922793925919605092352922707796689801895417366600539442410775071099958","price":"0.89","size":"374","side":"SELL","hash":"b9c2bd054d3680c7cfd65365d9bb6763226f2cd7","best_bid":"0.86","best_ask":"0.87"}],"timestamp":"1776808417345","event_type":"price_change"}}
{"capturedAt":1776808417,"payload":{"market":"0x125149c5918fc5f8c6d34682f700a898a1a19ea4f4e2ae68ff4c5794ba657074","price_changes":[{"asset_id":"45936375922793925919605092352922707796689801895417366600539442410775071099958","price":"0.85","size":"457.28","side":"BUY","hash":"497a4ba0bd8368612772306a2c9a2044fd05daa6","best_bid":"0.86","best_ask":"0.87"},{"asset_id":"86520121088881862182423437128238697252500151785248183602134095101149900014256","price":"0.15","size":"457.28","side":"SELL","hash":"52a258ab8473b43f2aa8cbd4869377b762410446","best_bid":"0.13","best_ask":"0.14"}],"timestamp":"1776808417346","event_type":"price_change"}}
{"capturedAt":1776808417,"payload":{"market":"0x125149c5918fc5f8c6d34682f700a898a1a19ea4f4e2ae68ff4c5794ba657074","price_changes":[{"asset_id":"45936375922793925919605092352922707796689801895417366600539442410775071099958","price":"0.86","size":"266.1","side":"BUY","hash":"9aac4d7c39118aeac73464edbdaf92c7c0a874f7","best_bid":"0.86","best_ask":"0.87"},{"asset_id":"86520121088881862182423437128238697252500151785248183602134095101149900014256","price":"0.14","size":"266.1","side":"SELL","hash":"79ccf4127c45ad68f95e79bf5bae435dbdeb62dd","best_bid":"0.13","best_ask":"0.14"}],"timestamp":"1776808417347","event_type":"price_change"}}
{"capturedAt":1776808417,"payload":{"market":"0x125149c5918fc5f8c6d34682f700a898a1a19ea4f4e2ae68ff4c5794ba657074","price_changes":[{"asset_id":"45936375922793925919605092352922707796689801895417366600539442410775071099958","price":"0.86","size":"251.1","side":"BUY","hash":"4e47c08e7283d346b2424ecfdc74aeb4cdb0d84f","best_bid":"0.86","best_ask":"0.87"},{"asset_id":"86520121088881862182423437128238697252500151785248183602134095101149900014256","price":"0.14","size":"251.1","side":"SELL","hash":"5bfe4d3abc2da780aa64a8f0169153a59a69c637","best_bid":"0.13","best_ask":"0.14"}],"timestamp":"1776808417349","event_type":"price_change"}}
{"capturedAt":1776808417,"payload":{"market":"0x125149c5918fc5f8c6d34682f700a898a1a19ea4f4e2ae68ff4c5794ba657074","price_changes":[{"asset_id":"45936375922793925919605092352922707796689801895417366600539442410775071099958","price":"0.01","size":"12329.83","side":"BUY","hash":"59be481b4c9cca011b22d72075d8ebdd06ede228","best_bid":"0.86","best_ask":"0.87"},{"asset_id":"86520121088881862182423437128238697252500151785248183602134095101149900014256","price":"0.99","size":"12329.83","side":"SELL","hash":"fe30e3d1135a3d7b04a72e4e69d9351e1cd1199b","best_bid":"0.13","best_ask":"0.14"}],"timestamp":"1776808417350","event_type":"price_change"}}
{"capturedAt":1776808417,"payload":{"market":"0x125149c5918fc5f8c6d34682f700a898a1a19ea4f4e2ae68ff4c5794ba657074","price_changes":[{"asset_id":"45936375922793925919605092352922707796689801895417366600539442410775071099958","price":"0.86","size":"261.1","side":"BUY","hash":"765894ef2951f5916b5b6e042b39894ea53f59a0","best_bid":"0.86","best_ask":"0.87"},{"asset_id":"86520121088881862182423437128238697252500151785248183602134095101149900014256","price":"0.14","size":"261.1","side":"SELL","hash":"852bbb2b1fb04b107df5c785c4027551eec37621","best_bid":"0.13","best_ask":"0.14"}],"timestamp":"1776808417348","event_type":"price_change"}}
{"capturedAt":1776808417,"payload":{"market":"0x125149c5918fc5f8c6d34682f700a898a1a19ea4f4e2ae68ff4c5794ba657074","price_changes":[{"asset_id":"86520121088881862182423437128238697252500151785248183602134095101149900014256","price":"0.13","size":"203.74","side":"BUY","hash":"a0192bb1460b28aa0e50602b562375e2f630ab71","best_bid":"0.13","best_ask":"0.14"},{"asset_id":"45936375922793925919605092352922707796689801895417366600539442410775071099958","price":"0.87","size":"203.74","side":"SELL","hash":"22242fc17b529e617072114af600957ab30b49ca","best_bid":"0.86","best_ask":"0.87"}],"timestamp":"1776808417352","event_type":"price_change"}}
{"capturedAt":1776808417,"payload":{"market":"0x125149c5918fc5f8c6d34682f700a898a1a19ea4f4e2ae68ff4c5794ba657074","price_changes":[{"asset_id":"45936375922793925919605092352922707796689801895417366600539442410775071099958","price":"0.86","size":"246.1","side":"BUY","hash":"cd635bc3250f5da99d0f49c967cf39bc50be56c9","best_bid":"0.86","best_ask":"0.87"},{"asset_id":"86520121088881862182423437128238697252500151785248183602134095101149900014256","price":"0.14","size":"246.1","side":"SELL","hash":"229c56b4f53f1b1c21b76cfc7e37e3a4983f1892","best_bid":"0.13","best_ask":"0.14"}],"timestamp":"1776808417352","event_type":"price_change"}}
{"capturedAt":1776808417,"payload":{"market":"0x125149c5918fc5f8c6d34682f700a898a1a19ea4f4e2ae68ff4c5794ba657074","price_changes":[{"asset_id":"86520121088881862182423437128238697252500151785248183602134095101149900014256","price":"0.12","size":"327.5","side":"BUY","hash":"f49cc30ceca8bdfea8036cfbf20ed3a124214e4f","best_bid":"0.13","best_ask":"0.14"},{"asset_id":"45936375922793925919605092352922707796689801895417366600539442410775071099958","price":"0.88","size":"327.5","side":"SELL","hash":"4673267cc6151da508201d220741211b7eb53d2c","best_bid":"0.86","best_ask":"0.87"}],"timestamp":"1776808417354","event_type":"price_change"}}
{"capturedAt":1776808417,"payload":{"market":"0x125149c5918fc5f8c6d34682f700a898a1a19ea4f4e2ae68ff4c5794ba657074","price_changes":[{"asset_id":"45936375922793925919605092352922707796689801895417366600539442410775071099958","price":"0.86","size":"241.1","side":"BUY","hash":"b3b48beb0bb81b92e1896225201b311422f22e1a","best_bid":"0.86","best_ask":"0.87"},{"asset_id":"86520121088881862182423437128238697252500151785248183602134095101149900014256","price":"0.14","size":"241.1","side":"SELL","hash":"455e7765c597af89cfecc41a06ed88de33d09176","best_bid":"0.13","best_ask":"0.14"}],"timestamp":"1776808417353","event_type":"price_change"}}
{"capturedAt":1776808417,"payload":{"market":"0x125149c5918fc5f8c6d34682f700a898a1a19ea4f4e2ae68ff4c5794ba657074","price_changes":[{"asset_id":"45936375922793925919605092352922707796689801895417366600539442410775071099958","price":"0.01","size":"12324.83","side":"BUY","hash":"9fb1298890ea897a6e9aa089bc82fbdcd7528a94","best_bid":"0.86","best_ask":"0.87"},{"asset_id":"86520121088881862182423437128238697252500151785248183602134095101149900014256","price":"0.99","size":"12324.83","side":"SELL","hash":"15f246544213b58d26b2dcfd17d5ee473f31984e","best_bid":"0.13","best_ask":"0.14"}],"timestamp":"1776808417356","event_type":"price_change"}}
{"capturedAt":1776808417,"payload":{"market":"0x125149c5918fc5f8c6d34682f700a898a1a19ea4f4e2ae68ff4c5794ba657074","price_changes":[{"asset_id":"45936375922793925919605092352922707796689801895417366600539442410775071099958","price":"0.86","size":"236.1","side":"BUY","hash":"50c6308d3a561558a065629b403617f64c139a91","best_bid":"0.86","best_ask":"0.87"},{"asset_id":"86520121088881862182423437128238697252500151785248183602134095101149900014256","price":"0.14","size":"236.1","side":"SELL","hash":"aef4733ef550f1845ab02710e5b8fee0cbd59bfd","best_bid":"0.13","best_ask":"0.14"}],"timestamp":"1776808417355","event_type":"price_change"}}
{"capturedAt":1776808417,"payload":{"market":"0x125149c5918fc5f8c6d34682f700a898a1a19ea4f4e2ae68ff4c5794ba657074","price_changes":[{"asset_id":"86520121088881862182423437128238697252500151785248183602134095101149900014256","price":"0.13","size":"208.74","side":"BUY","hash":"b9973a14c22c2a3d54fed74d848a8d46739fb5b2","best_bid":"0.13","best_ask":"0.14"},{"asset_id":"45936375922793925919605092352922707796689801895417366600539442410775071099958","price":"0.87","size":"208.74","side":"SELL","hash":"3e18fd79ba17a56a6afe644f7388af08e970092d","best_bid":"0.86","best_ask":"0.87"}],"timestamp":"1776808417358","event_type":"price_change"}}
{"capturedAt":1776808417,"payload":{"market":"0x125149c5918fc5f8c6d34682f700a898a1a19ea4f4e2ae68ff4c5794ba657074","price_changes":[{"asset_id":"45936375922793925919605092352922707796689801895417366600539442410775071099958","price":"0.86","size":"230.1","side":"BUY","hash":"dab28c254ede1c1d745827b36655ac969ff68458","best_bid":"0.86","best_ask":"0.87"},{"asset_id":"86520121088881862182423437128238697252500151785248183602134095101149900014256","price":"0.14","size":"230.1","side":"SELL","hash":"766d36a2e5aaedb077a3782e56fc7d0738a08153","best_bid":"0.13","best_ask":"0.14"}],"timestamp":"1776808417364","event_type":"price_change"}}
{"capturedAt":1776808417,"payload":{"market":"0x125149c5918fc5f8c6d34682f700a898a1a19ea4f4e2ae68ff4c5794ba657074","price_changes":[{"asset_id":"86520121088881862182423437128238697252500151785248183602134095101149900014256","price":"0.04","size":"738.3","side":"BUY","hash":"b2de6c4da16028d2d0543620ca2b3e163547cb03","best_bid":"0.13","best_ask":"0.14"},{"asset_id":"45936375922793925919605092352922707796689801895417366600539442410775071099958","price":"0.96","size":"738.3","side":"SELL","hash":"67f8c7406e1a4043090020e3d41de1aa1af8f72a","best_bid":"0.86","best_ask":"0.87"}],"timestamp":"1776808417365","event_type":"price_change"}}
{"capturedAt":1776808417,"payload":{"market":"0x125149c5918fc5f8c6d34682f700a898a1a19ea4f4e2ae68ff4c5794ba657074","price_changes":[{"asset_id":"45936375922793925919605092352922707796689801895417366600539442410775071099958","price":"0.86","size":"224.65","side":"BUY","hash":"1dc9a601aa0ead2c92366860adcffa7166c85d39","best_bid":"0.86","best_ask":"0.87"},{"asset_id":"86520121088881862182423437128238697252500151785248183602134095101149900014256","price":"0.14","size":"224.65","side":"SELL","hash":"61d280744971de861c0062171c539b09f46fe5df","best_bid":"0.13","best_ask":"0.14"}],"timestamp":"1776808417366","event_type":"price_change"}}
{"capturedAt":1776808417,"payload":{"market":"0x125149c5918fc5f8c6d34682f700a898a1a19ea4f4e2ae68ff4c5794ba657074","price_changes":[{"asset_id":"86520121088881862182423437128238697252500151785248183602134095101149900014256","price":"0.06","size":"447.8","side":"BUY","hash":"3502f8a33a3eff03bd1d87f5beb9717ba71f3526","best_bid":"0.13","best_ask":"0.14"},{"asset_id":"45936375922793925919605092352922707796689801895417366600539442410775071099958","price":"0.94","size":"447.8","side":"SELL","hash":"4aa3c696b0779ae98e180ff1bcc5377a5f919a5d","best_bid":"0.86","best_ask":"0.87"}],"timestamp":"1776808417367","event_type":"price_change"}}
{"capturedAt":1776808417,"payload":{"market":"0x125149c5918fc5f8c6d34682f700a898a1a19ea4f4e2ae68ff4c5794ba657074","price_changes":[{"asset_id":"45936375922793925919605092352922707796689801895417366600539442410775071099958","price":"0.86","size":"218.65","side":"BUY","hash":"71f6e31af57ebb50e4dcbb041bd6a4b64ac8f305","best_bid":"0.86","best_ask":"0.87"},{"asset_id":"86520121088881862182423437128238697252500151785248183602134095101149900014256","price":"0.14","size":"218.65","side":"SELL","hash":"d86783ac61e9f0f75f2f917d212411e673b05399","best_bid":"0.13","best_ask":"0.14"}],"timestamp":"1776808417368","event_type":"price_change"}}
{"capturedAt":1776808417,"payload":{"market":"0x125149c5918fc5f8c6d34682f700a898a1a19ea4f4e2ae68ff4c5794ba657074","price_changes":[{"asset_id":"45936375922793925919605092352922707796689801895417366600539442410775071099958","price":"0.86","size":"233.65","side":"BUY","hash":"98bff52c1ba46c6e0c0fd077fb43ea2d21560dc0","best_bid":"0.86","best_ask":"0.87"},{"asset_id":"86520121088881862182423437128238697252500151785248183602134095101149900014256","price":"0.14","size":"233.65","side":"SELL","hash":"6410db6bc0ff155bed195a34232678b689a1e7fa","best_bid":"0.13","best_ask":"0.14"}],"timestamp":"1776808417369","event_type":"price_change"}}
{"capturedAt":1776808417,"payload":{"market":"0x125149c5918fc5f8c6d34682f700a898a1a19ea4f4e2ae68ff4c5794ba657074","price_changes":[{"asset_id":"86520121088881862182423437128238697252500151785248183602134095101149900014256","price":"0.44","size":"208.59","side":"SELL","hash":"da1bfec328565560768c3173411f6e60d724969e","best_bid":"0.13","best_ask":"0.14"},{"asset_id":"45936375922793925919605092352922707796689801895417366600539442410775071099958","price":"0.56","size":"208.59","side":"BUY","hash":"6fc7a4ae42815e5b6cdba5d4abab573bb995844c","best_bid":"0.86","best_ask":"0.87"}],"timestamp":"1776808417371","event_type":"price_change"}}
{"capturedAt":1776808417,"payload":{"market":"0x125149c5918fc5f8c6d34682f700a898a1a19ea4f4e2ae68ff4c5794ba657074","price_changes":[{"asset_id":"45936375922793925919605092352922707796689801895417366600539442410775071099958","price":"0.86","size":"228.65","side":"BUY","hash":"7a5be5c83af836a4858b731d73087d2026910ecc","best_bid":"0.86","best_ask":"0.87"},{"asset_id":"86520121088881862182423437128238697252500151785248183602134095101149900014256","price":"0.14","size":"228.65","side":"SELL","hash":"187062e45f803e3a762ff3bae19469a51d421013","best_bid":"0.13","best_ask":"0.14"}],"timestamp":"1776808417372","event_type":"price_change"}}
{"capturedAt":1776808417,"payload":{"market":"0x125149c5918fc5f8c6d34682f700a898a1a19ea4f4e2ae68ff4c5794ba657074","price_changes":[{"asset_id":"45936375922793925919605092352922707796689801895417366600539442410775071099958","price":"0.86","size":"233.65","side":"BUY","hash":"fefc09bb30536f4141cd8611c82cd989bae2d7bd","best_bid":"0.86","best_ask":"0.87"},{"asset_id":"86520121088881862182423437128238697252500151785248183602134095101149900014256","price":"0.14","size":"233.65","side":"SELL","hash":"b8b4f97daf5effeed7cab2deeaaa96dc9b587e8c","best_bid":"0.13","best_ask":"0.14"}],"timestamp":"1776808417373","event_type":"price_change"}}
{"capturedAt":1776808417,"payload":{"market":"0x125149c5918fc5f8c6d34682f700a898a1a19ea4f4e2ae68ff4c5794ba657074","price_changes":[{"asset_id":"45936375922793925919605092352922707796689801895417366600539442410775071099958","price":"0.86","size":"239.65","side":"BUY","hash":"cf7a6b5e80d7b4131ef1fe35827a615b0adf0ff8","best_bid":"0.86","best_ask":"0.87"},{"asset_id":"86520121088881862182423437128238697252500151785248183602134095101149900014256","price":"0.14","size":"239.65","side":"SELL","hash":"fe97fa101ac60ce48de39a7bb0e72fd0531ebf87","best_bid":"0.13","best_ask":"0.14"}],"timestamp":"1776808417375","event_type":"price_change"}}
{"capturedAt":1776808417,"payload":{"market":"0x125149c5918fc5f8c6d34682f700a898a1a19ea4f4e2ae68ff4c5794ba657074","price_changes":[{"asset_id":"45936375922793925919605092352922707796689801895417366600539442410775071099958","price":"0.86","size":"234.65","side":"BUY","hash":"c8e9dbc551a39d536d06fc4fdda2c53877379aa3","best_bid":"0.86","best_ask":"0.87"},{"asset_id":"86520121088881862182423437128238697252500151785248183602134095101149900014256","price":"0.14","size":"234.65","side":"SELL","hash":"418c1a4239f8479ffee91111629da60baf414bd4","best_bid":"0.13","best_ask":"0.14"}],"timestamp":"1776808417376","event_type":"price_change"}}
{"capturedAt":1776808417,"payload":{"market":"0x125149c5918fc5f8c6d34682f700a898a1a19ea4f4e2ae68ff4c5794ba657074","price_changes":[{"asset_id":"45936375922793925919605092352922707796689801895417366600539442410775071099958","price":"0.86","size":"229.59","side":"BUY","hash":"8ab4dce20ada08e74f2fcf77c94a381223b38c1b","best_bid":"0.86","best_ask":"0.87"},{"asset_id":"86520121088881862182423437128238697252500151785248183602134095101149900014256","price":"0.14","size":"229.59","side":"SELL","hash":"194ea53ee148bd89c3fb1bf7fe3c83379ceeee12","best_bid":"0.13","best_ask":"0.14"}],"timestamp":"1776808417377","event_type":"price_change"}}
{"capturedAt":1776808417,"payload":{"market":"0x125149c5918fc5f8c6d34682f700a898a1a19ea4f4e2ae68ff4c5794ba657074","price_changes":[{"asset_id":"45936375922793925919605092352922707796689801895417366600539442410775071099958","price":"0.86","size":"239.59","side":"BUY","hash":"ad25ae3b1398b18249b32113ad56848310a84526","best_bid":"0.86","best_ask":"0.87"},{"asset_id":"86520121088881862182423437128238697252500151785248183602134095101149900014256","price":"0.14","size":"239.59","side":"SELL","hash":"682a907b04cc48c097449029b95ff3e889e73564","best_bid":"0.13","best_ask":"0.14"}],"timestamp":"1776808417378","event_type":"price_change"}}
{"capturedAt":1776808417,"payload":{"market":"0x125149c5918fc5f8c6d34682f700a898a1a19ea4f4e2ae68ff4c5794ba657074","price_changes":[{"asset_id":"45936375922793925919605092352922707796689801895417366600539442410775071099958","price":"0.86","size":"234.59","side":"BUY","hash":"9c212af9d8b9d12bc9484acbf95d633bdd45f06e","best_bid":"0.86","best_ask":"0.87"},{"asset_id":"86520121088881862182423437128238697252500151785248183602134095101149900014256","price":"0.14","size":"234.59","side":"SELL","hash":"7dbfef87b77f45b2c3d489a07b7cdbd7bf775da4","best_bid":"0.13","best_ask":"0.14"}],"timestamp":"1776808417379","event_type":"price_change"}}
{"capturedAt":1776808417,"payload":{"market":"0x125149c5918fc5f8c6d34682f700a898a1a19ea4f4e2ae68ff4c5794ba657074","price_changes":[{"asset_id":"45936375922793925919605092352922707796689801895417366600539442410775071099958","price":"0.86","size":"240.38","side":"BUY","hash":"51dfd72dd6416c7702a47b127a05f5511621c55f","best_bid":"0.86","best_ask":"0.87"},{"asset_id":"86520121088881862182423437128238697252500151785248183602134095101149900014256","price":"0.14","size":"240.38","side":"SELL","hash":"833e2c8bc632da779505a77a2e2e308ea7e7b4ec","best_bid":"0.13","best_ask":"0.14"}],"timestamp":"1776808417380","event_type":"price_change"}}
{"capturedAt":1776808417,"payload":{"market":"0x125149c5918fc5f8c6d34682f700a898a1a19ea4f4e2ae68ff4c5794ba657074","price_changes":[{"asset_id":"45936375922793925919605092352922707796689801895417366600539442410775071099958","price":"0.86","size":"235.38","side":"BUY","hash":"7ead8825c4cfc94e73bba030acd6b14f19d6aa46","best_bid":"0.86","best_ask":"0.87"},{"asset_id":"86520121088881862182423437128238697252500151785248183602134095101149900014256","price":"0.14","size":"235.38","side":"SELL","hash":"57d105d526da0c39fd08417f6ce657ab4153e12d","best_bid":"0.13","best_ask":"0.14"}],"timestamp":"1776808417383","event_type":"price_change"}}
{"capturedAt":1776808417,"payload":{"market":"0x125149c5918fc5f8c6d34682f700a898a1a19ea4f4e2ae68ff4c5794ba657074","price_changes":[{"asset_id":"45936375922793925919605092352922707796689801895417366600539442410775071099958","price":"0.86","size":"246.38","side":"BUY","hash":"d3fcc266886c169cc33bde9cadb57751ac1beae9","best_bid":"0.86","best_ask":"0.87"},{"asset_id":"86520121088881862182423437128238697252500151785248183602134095101149900014256","price":"0.14","size":"246.38","side":"SELL","hash":"4cfe7c7dc30290dfb09cff6b5a0d596ba0284d1e","best_bid":"0.13","best_ask":"0.14"}],"timestamp":"1776808417384","event_type":"price_change"}}
{"capturedAt":1776808417,"payload":{"market":"0x125149c5918fc5f8c6d34682f700a898a1a19ea4f4e2ae68ff4c5794ba657074","price_changes":[{"asset_id":"45936375922793925919605092352922707796689801895417366600539442410775071099958","price":"0.86","size":"251.38","side":"BUY","hash":"3a418b8b119004a82669437a0fb82335aa12dc1b","best_bid":"0.86","best_ask":"0.87"},{"asset_id":"86520121088881862182423437128238697252500151785248183602134095101149900014256","price":"0.14","size":"251.38","side":"SELL","hash":"e22a0a136e5c32ec3140f25a391e09e65b772b17","best_bid":"0.13","best_ask":"0.14"}],"timestamp":"1776808417385","event_type":"price_change"}}
{"capturedAt":1776808417,"payload":{"market":"0x125149c5918fc5f8c6d34682f700a898a1a19ea4f4e2ae68ff4c5794ba657074","price_changes":[{"asset_id":"45936375922793925919605092352922707796689801895417366600539442410775071099958","price":"0.01","size":"12329.83","side":"BUY","hash":"0adaa766adc02ea300bf508e3b05436d7963dbb1","best_bid":"0.86","best_ask":"0.87"},{"asset_id":"86520121088881862182423437128238697252500151785248183602134095101149900014256","price":"0.99","size":"12329.83","side":"SELL","hash":"4e27a6a07de1d030465c8a11baf72bb90d741c67","best_bid":"0.13","best_ask":"0.14"}],"timestamp":"1776808417388","event_type":"price_change"}}
{"capturedAt":1776808417,"payload":{"market":"0x125149c5918fc5f8c6d34682f700a898a1a19ea4f4e2ae68ff4c5794ba657074","price_changes":[{"asset_id":"45936375922793925919605092352922707796689801895417366600539442410775071099958","price":"0.86","size":"257.12","side":"BUY","hash":"0f4df4a97ae42b3c5bd3e3fb748aea514168cb90","best_bid":"0.86","best_ask":"0.87"},{"asset_id":"86520121088881862182423437128238697252500151785248183602134095101149900014256","price":"0.14","size":"257.12","side":"SELL","hash":"5d525bbb52c67d783db0ac399ae3722864c2fc32","best_bid":"0.13","best_ask":"0.14"}],"timestamp":"1776808417387","event_type":"price_change"}}
{"capturedAt":1776808417,"payload":{"market":"0x125149c5918fc5f8c6d34682f700a898a1a19ea4f4e2ae68ff4c5794ba657074","price_changes":[{"asset_id":"45936375922793925919605092352922707796689801895417366600539442410775071099958","price":"0.83","size":"319.46","side":"BUY","hash":"b9b513435d8bec5f4cd42d4289443a25e7b6b8a1","best_bid":"0.86","best_ask":"0.87"},{"asset_id":"86520121088881862182423437128238697252500151785248183602134095101149900014256","price":"0.17","size":"319.46","side":"SELL","hash":"1dc547734efdb6370de094847c8aee4d2517991c","best_bid":"0.13","best_ask":"0.14"}],"timestamp":"1776808417393","event_type":"price_change"}}
{"capturedAt":1776808417,"payload":{"market":"0x125149c5918fc5f8c6d34682f700a898a1a19ea4f4e2ae68ff4c5794ba657074","price_changes":[{"asset_id":"45936375922793925919605092352922707796689801895417366600539442410775071099958","price":"0.97","size":"1773.83","side":"SELL","hash":"b9b513435d8bec5f4cd42d4289443a25e7b6b8a1","best_bid":"0.86","best_ask":"0.87"},{"asset_id":"86520121088881862182423437128238697252500151785248183602134095101149900014256","price":"0.03","size":"1773.83","side":"BUY","hash":"1dc547734efdb6370de094847c8aee4d2517991c","best_bid":"0.13","best_ask":"0.14"}],"timestamp":"1776808417393","event_type":"price_change"}}
{"capturedAt":1776808417,"payload":{"market":"0x125149c5918fc5f8c6d34682f700a898a1a19ea4f4e2ae68ff4c5794ba657074","price_changes":[{"asset_id":"45936375922793925919605092352922707796689801895417366600539442410775071099958","price":"0.86","size":"264.12","side":"BUY","hash":"89d3f043a6d710eaeafdf9585e78c5c2e810486e","best_bid":"0.86","best_ask":"0.87"},{"asset_id":"86520121088881862182423437128238697252500151785248183602134095101149900014256","price":"0.14","size":"264.12","side":"SELL","hash":"c94511ce813c855988b0ee6b58cc64f6de990e5f","best_bid":"0.13","best_ask":"0.14"}],"timestamp":"1776808417396","event_type":"price_change"}}
{"capturedAt":1776808417,"payload":{"market":"0x125149c5918fc5f8c6d34682f700a898a1a19ea4f4e2ae68ff4c5794ba657074","price_changes":[{"asset_id":"45936375922793925919605092352922707796689801895417366600539442410775071099958","price":"0.86","size":"275.12","side":"BUY","hash":"d066c102ac28e201654b329cce71967d9dfada56","best_bid":"0.86","best_ask":"0.87"},{"asset_id":"86520121088881862182423437128238697252500151785248183602134095101149900014256","price":"0.14","size":"275.12","side":"SELL","hash":"df03e54dd36d184528a668a0ce3be9dbd7d439a4","best_bid":"0.13","best_ask":"0.14"}],"timestamp":"1776808417397","event_type":"price_change"}}
{"capturedAt":1776808417,"payload":{"market":"0x125149c5918fc5f8c6d34682f700a898a1a19ea4f4e2ae68ff4c5794ba657074","price_changes":[{"asset_id":"45936375922793925919605092352922707796689801895417366600539442410775071099958","price":"0.86","size":"286.12","side":"BUY","hash":"bff31bc20f150e49bf3ae2f65ff49b8ed79d0b0b","best_bid":"0.86","best_ask":"0.87"},{"asset_id":"86520121088881862182423437128238697252500151785248183602134095101149900014256","price":"0.14","size":"286.12","side":"SELL","hash":"ca57cd2b1338bf9ec342fbfb7effce9922bab8ec","best_bid":"0.13","best_ask":"0.14"}],"timestamp":"1776808417398","event_type":"price_change"}}
{"capturedAt":1776808417,"payload":{"market":"0x125149c5918fc5f8c6d34682f700a898a1a19ea4f4e2ae68ff4c5794ba657074","price_changes":[{"asset_id":"45936375922793925919605092352922707796689801895417366600539442410775071099958","price":"0.92","size":"641.9","side":"SELL","hash":"382db8b4f00ee2fb5f2ff54afef1fceced95909b","best_bid":"0.86","best_ask":"0.87"},{"asset_id":"86520121088881862182423437128238697252500151785248183602134095101149900014256","price":"0.08","size":"641.9","side":"BUY","hash":"72f6e3a0694247d728d8b6d5fe728370c246a6d9","best_bid":"0.13","best_ask":"0.14"}],"timestamp":"1776808417399","event_type":"price_change"}}
{"capturedAt":1776808417,"payload":{"market":"0x125149c5918fc5f8c6d34682f700a898a1a19ea4f4e2ae68ff4c5794ba657074","price_changes":[{"asset_id":"45936375922793925919605092352922707796689801895417366600539442410775071099958","price":"0.76","size":"133.49","side":"BUY","hash":"382db8b4f00ee2fb5f2ff54afef1fceced95909b","best_bid":"0.86","best_ask":"0.87"},{"asset_id":"86520121088881862182423437128238697252500151785248183602134095101149900014256","price":"0.24","size":"133.49","side":"SELL","hash":"72f6e3a0694247d728d8b6d5fe728370c246a6d9","best_bid":"0.13","best_ask":"0.14"}],"timestamp":"1776808417399","event_type":"price_change"}}
{"capturedAt":1776808417,"payload":{"market":"0x125149c5918fc5f8c6d34682f700a898a1a19ea4f4e2ae68ff4c5794ba657074","price_changes":[{"asset_id":"45936375922793925919605092352922707796689801895417366600539442410775071099958","price":"0.82","size":"371.78","side":"BUY","hash":"6bb9134245e7d99d2fedba056594e86940189f22","best_bid":"0.86","best_ask":"0.87"},{"asset_id":"86520121088881862182423437128238697252500151785248183602134095101149900014256","price":"0.18","size":"371.78","side":"SELL","hash":"a3ac1bd5c5dea5caa4a9867c5a3c19e8d09dc26e","best_bid":"0.13","best_ask":"0.14"}],"timestamp":"1776808417400","event_type":"price_change"}}
{"capturedAt":1776808417,"payload":{"market":"0x125149c5918fc5f8c6d34682f700a898a1a19ea4f4e2ae68ff4c5794ba657074","price_changes":[{"asset_id":"45936375922793925919605092352922707796689801895417366600539442410775071099958","price":"0.86","size":"271.12","side":"BUY","hash":"266e12a7344530015a2e6c0d902f98a9e47838a7","best_bid":"0.86","best_ask":"0.87"},{"asset_id":"86520121088881862182423437128238697252500151785248183602134095101149900014256","price":"0.14","size":"271.12","side":"SELL","hash":"27823b1fb352e7bd811e911b5766eade57af1c26","best_bid":"0.13","best_ask":"0.14"}],"timestamp":"1776808417401","event_type":"price_change"}}
{"capturedAt":1776808417,"payload":{"market":"0x125149c5918fc5f8c6d34682f700a898a1a19ea4f4e2ae68ff4c5794ba657074","price_changes":[{"asset_id":"45936375922793925919605092352922707796689801895417366600539442410775071099958","price":"0.86","size":"281.12","side":"BUY","hash":"4f303e4b8d2c3b6b781ead687889994284c01987","best_bid":"0.86","best_ask":"0.87"},{"asset_id":"86520121088881862182423437128238697252500151785248183602134095101149900014256","price":"0.14","size":"281.12","side":"SELL","hash":"e030da3aaf69382fe6cccebaa44821ed20123043","best_bid":"0.13","best_ask":"0.14"}],"timestamp":"1776808417402","event_type":"price_change"}}
{"capturedAt":1776808417,"payload":{"market":"0x125149c5918fc5f8c6d34682f700a898a1a19ea4f4e2ae68ff4c5794ba657074","price_changes":[{"asset_id":"45936375922793925919605092352922707796689801895417366600539442410775071099958","price":"0.01","size":"12334.83","side":"BUY","hash":"6a5467f5142effd43d67839c02d1cc36ce3ec478","best_bid":"0.86","best_ask":"0.87"},{"asset_id":"86520121088881862182423437128238697252500151785248183602134095101149900014256","price":"0.99","size":"12334.83","side":"SELL","hash":"286534bc1f24a701bf75ed714fe83010598c6221","best_bid":"0.13","best_ask":"0.14"}],"timestamp":"1776808417403","event_type":"price_change"}}
{"capturedAt":1776808417,"payload":{"market":"0x125149c5918fc5f8c6d34682f700a898a1a19ea4f4e2ae68ff4c5794ba657074","price_changes":[{"asset_id":"45936375922793925919605092352922707796689801895417366600539442410775071099958","price":"0.76","size":"138.49","side":"BUY","hash":"c8ed5dbde3d7736ee02379c868b7803dd88f79f0","best_bid":"0.86","best_ask":"0.87"},{"asset_id":"86520121088881862182423437128238697252500151785248183602134095101149900014256","price":"0.24","size":"138.49","side":"SELL","hash":"8f6e84850ecadd2adb68b650f549ab8d59aa4f75","best_bid":"0.13","best_ask":"0.14"}],"timestamp":"1776808417404","event_type":"price_change"}}
{"capturedAt":1776808417,"payload":{"market":"0x125149c5918fc5f8c6d34682f700a898a1a19ea4f4e2ae68ff4c5794ba657074","price_changes":[{"asset_id":"45936375922793925919605092352922707796689801895417366600539442410775071099958","price":"0.86","size":"275.33","side":"BUY","hash":"b63ae3981a501d734e96d4ce065c5762330f3de5","best_bid":"0.86","best_ask":"0.87"},{"asset_id":"86520121088881862182423437128238697252500151785248183602134095101149900014256","price":"0.14","size":"275.33","side":"SELL","hash":"3396cc87e7ad5011cfc7db3d5a58ea76c72052a3","best_bid":"0.13","best_ask":"0.14"}],"timestamp":"1776808417405","event_type":"price_change"}}
{"capturedAt":1776808417,"payload":{"market":"0x125149c5918fc5f8c6d34682f700a898a1a19ea4f4e2ae68ff4c5794ba657074","price_changes":[{"asset_id":"86520121088881862182423437128238697252500151785248183602134095101149900014256","price":"0.13","size":"203.74","side":"BUY","hash":"c84a73a44025054a77d0bd8dcefa504f2058df7d","best_bid":"0.13","best_ask":"0.14"},{"asset_id":"45936375922793925919605092352922707796689801895417366600539442410775071099958","price":"0.87","size":"203.74","side":"SELL","hash":"fce6f25bf87abbbaed15543c3e18049166759656","best_bid":"0.86","best_ask":"0.87"}],"timestamp":"1776808417406","event_type":"price_change"}}
{"capturedAt":1776808417,"payload":{"market":"0x125149c5918fc5f8c6d34682f700a898a1a19ea4f4e2ae68ff4c5794ba657074","price_changes":[{"asset_id":"45936375922793925919605092352922707796689801895417366600539442410775071099958","price":"0.86","size":"270.33","side":"BUY","hash":"6ca37a2912cffdeca57f3e55a03289877e57af07","best_bid":"0.86","best_ask":"0.87"},{"asset_id":"86520121088881862182423437128238697252500151785248183602134095101149900014256","price":"0.14","size":"270.33","side":"SELL","hash":"5b15de1192d193430ebfbad2000c003fef210052","best_bid":"0.13","best_ask":"0.14"}],"timestamp":"1776808417407","event_type":"price_change"}}
{"capturedAt":1776808417,"payload":{"market":"0x125149c5918fc5f8c6d34682f700a898a1a19ea4f4e2ae68ff4c5794ba657074","price_changes":[{"asset_id":"45936375922793925919605092352922707796689801895417366600539442410775071099958","price":"0.86","size":"264.59","side":"BUY","hash":"ee9906fb3a47afdbbd2cefd7ff5f5bb664090a95","best_bid":"0.86","best_ask":"0.87"},{"asset_id":"86520121088881862182423437128238697252500151785248183602134095101149900014256","price":"0.14","size":"264.59","side":"SELL","hash":"6d420c3f90c98fcc4edc4c260ac13742a49711a5","best_bid":"0.13","best_ask":"0.14"}],"timestamp":"1776808417408","event_type":"price_change"}}
{"capturedAt":1776808417,"payload":{"market":"0x125149c5918fc5f8c6d34682f700a898a1a19ea4f4e2ae68ff4c5794ba657074","price_changes":[{"asset_id":"45936375922793925919605092352922707796689801895417366600539442410775071099958","price":"0.86","size":"275.59","side":"BUY","hash":"363c7199f806863b203f6cb1107c14d402f25a83","best_bid":"0.86","best_ask":"0.87"},{"asset_id":"86520121088881862182423437128238697252500151785248183602134095101149900014256","price":"0.14","size":"275.59","side":"SELL","hash":"53d38ff6494ffafb63a9be3d124c7094c8cf7bf8","best_bid":"0.13","best_ask":"0.14"}],"timestamp":"1776808417409","event_type":"price_change"}}
{"capturedAt":1776808417,"payload":{"market":"0x125149c5918fc5f8c6d34682f700a898a1a19ea4f4e2ae68ff4c5794ba657074","price_changes":[{"asset_id":"45936375922793925919605092352922707796689801895417366600539442410775071099958","price":"0.86","size":"269.59","side":"BUY","hash":"f1c12069e16ea3955a7092508e2586dc255237dd","best_bid":"0.86","best_ask":"0.87"},{"asset_id":"86520121088881862182423437128238697252500151785248183602134095101149900014256","price":"0.14","size":"269.59","side":"SELL","hash":"76d389e44aa21b16755f4b8d0cdf26b49e450f2c","best_bid":"0.13","best_ask":"0.14"}],"timestamp":"1776808417409","event_type":"price_change"}}
{"capturedAt":1776808417,"payload":{"market":"0x125149c5918fc5f8c6d34682f700a898a1a19ea4f4e2ae68ff4c5794ba657074","price_changes":[{"asset_id":"86520121088881862182423437128238697252500151785248183602134095101149900014256","price":"0.13","size":"154.74","side":"BUY","hash":"0c48bbfc5c03a3ea1a07338fed77511ecc3bb74a","best_bid":"0.13","best_ask":"0.14"},{"asset_id":"45936375922793925919605092352922707796689801895417366600539442410775071099958","price":"0.87","size":"154.74","side":"SELL","hash":"efda9768e2069483b97b3cde6328ce82a7751850","best_bid":"0.86","best_ask":"0.87"}],"timestamp":"1776808417411","event_type":"price_change"}}
{"capturedAt":1776808417,"payload":{"market":"0x125149c5918fc5f8c6d34682f700a898a1a19ea4f4e2ae68ff4c5794ba657074","price_changes":[{"asset_id":"45936375922793925919605092352922707796689801895417366600539442410775071099958","price":"0.86","size":"280.59","side":"BUY","hash":"93e2c676b81ae327d758b14a213bb5817fdc2d42","best_bid":"0.86","best_ask":"0.87"},{"asset_id":"86520121088881862182423437128238697252500151785248183602134095101149900014256","price":"0.14","size":"280.59","side":"SELL","hash":"b6389e84b397228251cbe0a6a3037d55e053f0d2","best_bid":"0.13","best_ask":"0.14"}],"timestamp":"1776808417411","event_type":"price_change"}}
{"capturedAt":1776808417,"payload":{"market":"0x125149c5918fc5f8c6d34682f700a898a1a19ea4f4e2ae68ff4c5794ba657074","price_changes":[{"asset_id":"86520121088881862182423437128238697252500151785248183602134095101149900014256","price":"0.04","size":"938.3","side":"BUY","hash":"7fb8661d096ef773cceb2d40e4f6ff9582a05d6d","best_bid":"0.13","best_ask":"0.14"},{"asset_id":"45936375922793925919605092352922707796689801895417366600539442410775071099958","price":"0.96","size":"938.3","side":"SELL","hash":"eb4cf9a94232498a2b10256a32f057508ae92ed4","best_bid":"0.86","best_ask":"0.87"}],"timestamp":"1776808417415","event_type":"price_change"}}
{"capturedAt":1776808417,"payload":{"market":"0x125149c5918fc5f8c6d34682f700a898a1a19ea4f4e2ae68ff4c5794ba657074","price_changes":[{"asset_id":"45936375922793925919605092352922707796689801895417366600539442410775071099958","price":"0.86","size":"270.59","side":"BUY","hash":"faecc1ff43d5f9ef2919370151454e82f9619537","best_bid":"0.86","best_ask":"0.87"},{"asset_id":"86520121088881862182423437128238697252500151785248183602134095101149900014256","price":"0.14","size":"270.59","side":"SELL","hash":"1cd8ed0b5b997090807a0097f5e485acace72f29","best_bid":"0.13","best_ask":"0.14"}],"timestamp":"1776808417421","event_type":"price_change"}}
{"capturedAt":1776808417,"payload":{"market":"0x125149c5918fc5f8c6d34682f700a898a1a19ea4f4e2ae68ff4c5794ba657074","price_changes":[{"asset_id":"45936375922793925919605092352922707796689801895417366600539442410775071099958","price":"0.01","size":"12329.83","side":"BUY","hash":"dcaa5d860dc4e8f77822d51c996de08bd2d5392d","best_bid":"0.86","best_ask":"0.87"},{"asset_id":"86520121088881862182423437128238697252500151785248183602134095101149900014256","price":"0.99","size":"12329.83","side":"SELL","hash":"b7eed3386254147be276e46826b1ae8d17f6eba7","best_bid":"0.13","best_ask":"0.14"}],"timestamp":"1776808417422","event_type":"price_change"}}
{"capturedAt":1776808417,"payload":{"market":"0x125149c5918fc5f8c6d34682f700a898a1a19ea4f4e2ae68ff4c5794ba657074","price_changes":[{"asset_id":"45936375922793925919605092352922707796689801895417366600539442410775071099958","price":"0.01","size":"12324.83","side":"BUY","hash":"8dcdfc5df1b79a3a7bc7c7dc8f3ffd60bd6a90e3","best_bid":"0.86","best_ask":"0.87"},{"asset_id":"86520121088881862182423437128238697252500151785248183602134095101149900014256","price":"0.99","size":"12324.83","side":"SELL","hash":"d42e2f3f979d02c95bf0ca6577fd6870e649f5ac","best_bid":"0.13","best_ask":"0.14"}],"timestamp":"1776808417424","event_type":"price_change"}}
{"capturedAt":1776808417,"payload":{"market":"0x125149c5918fc5f8c6d34682f700a898a1a19ea4f4e2ae68ff4c5794ba657074","price_changes":[{"asset_id":"45936375922793925919605092352922707796689801895417366600539442410775071099958","price":"0.97","size":"1803.83","side":"SELL","hash":"c7a4d94e081719036785480cf2114d3e41db4ba2","best_bid":"0.86","best_ask":"0.87"},{"asset_id":"86520121088881862182423437128238697252500151785248183602134095101149900014256","price":"0.03","size":"1803.83","side":"BUY","hash":"99e49a2b11aec1ddb81218f6b062a8b52b40852a","best_bid":"0.13","best_ask":"0.14"}],"timestamp":"1776808417425","event_type":"price_change"}}
{"capturedAt":1776808417,"payload":{"market":"0x125149c5918fc5f8c6d34682f700a898a1a19ea4f4e2ae68ff4c5794ba657074","price_changes":[{"asset_id":"45936375922793925919605092352922707796689801895417366600539442410775071099958","price":"0.91","size":"217","side":"SELL","hash":"259e62404356d233b9e1c7e615fbb0b4e391fb0c","best_bid":"0.86","best_ask":"0.87"},{"asset_id":"86520121088881862182423437128238697252500151785248183602134095101149900014256","price":"0.09","size":"217","side":"BUY","hash":"76d4eaf0fcdbcc0e4016b03b3d00deb99bf7d9e1","best_bid":"0.13","best_ask":"0.14"}],"timestamp":"1776808417426","event_type":"price_change"}}
{"capturedAt":1776808417,"payload":{"market":"0x125149c5918fc5f8c6d34682f700a898a1a19ea4f4e2ae68ff4c5794ba657074","price_changes":[{"asset_id":"45936375922793925919605092352922707796689801895417366600539442410775071099958","price":"0.75","size":"490.29","side":"BUY","hash":"436d23d23e260d53ff3a3a56eace725a17da7ad4","best_bid":"0.86","best_ask":"0.87"},{"asset_id":"86520121088881862182423437128238697252500151785248183602134095101149900014256","price":"0.25","size":"490.29","side":"SELL","hash":"e572701a64f867978202c1169ec8ad368cecdba7","best_bid":"0.13","best_ask":"0.14"}],"timestamp":"1776808417427","event_type":"price_change"}}
{"capturedAt":1776808417,"payload":{"market":"0x125149c5918fc5f8c6d34682f700a898a1a19ea4f4e2ae68ff4c5794ba657074","price_changes":[{"asset_id":"45936375922793925919605092352922707796689801895417366600539442410775071099958","price":"0.82","size":"401.78","side":"BUY","hash":"5896064f667feeb06e84e7ea9550a6c2d01f310c","best_bid":"0.86","best_ask":"0.87"},{"asset_id":"86520121088881862182423437128238697252500151785248183602134095101149900014256","price":"0.18","size":"401.78","side":"SELL","hash":"b15a38b41649319acb4c724b123224f0a7238c8c","best_bid":"0.13","best_ask":"0.14"}],"timestamp":"1776808417428","event_type":"price_change"}}
{"capturedAt":1776808417,"payload":{"market":"0x125149c5918fc5f8c6d34682f700a898a1a19ea4f4e2ae68ff4c5794ba657074","price_changes":[{"asset_id":"45936375922793925919605092352922707796689801895417366600539442410775071099958","price":"0.86","size":"280.59","side":"BUY","hash":"61aee625b06778f34968b3d57b32dac47633bd2e","best_bid":"0.86","best_ask":"0.87"},{"asset_id":"86520121088881862182423437128238697252500151785248183602134095101149900014256","price":"0.14","size":"280.59","side":"SELL","hash":"d8717f93c8c25d9b05cbb1adf44b5fd5d89b74d6","best_bid":"0.13","best_ask":"0.14"}],"timestamp":"1776808417434","event_type":"price_change"}}
{"capturedAt":1776808417,"payload":{"market":"0x125149c5918fc5f8c6d34682f700a898a1a19ea4f4e2ae68ff4c5794ba657074","price_changes":[{"asset_id":"86520121088881862182423437128238697252500151785248183602134095101149900014256","price":"0.13","size":"203.74","side":"BUY","hash":"ee6905d93071b5a93d9f79e2657ed8fc8047a1c5","best_bid":"0.13","best_ask":"0.14"},{"asset_id":"45936375922793925919605092352922707796689801895417366600539442410775071099958","price":"0.87","size":"203.74","side":"SELL","hash":"2217f143b43563b95c0e5fcc0c98074a36375140","best_bid":"0.86","best_ask":"0.87"}],"timestamp":"1776808417436","event_type":"price_change"}}
{"capturedAt":1776808417,"payload":{"market":"0x125149c5918fc5f8c6d34682f700a898a1a19ea4f4e2ae68ff4c5794ba657074","price_changes":[{"asset_id":"45936375922793925919605092352922707796689801895417366600539442410775071099958","price":"0.86","size":"290.59","side":"BUY","hash":"f87f2730d390919c7e1f5c21aa66b05b1b16f1b8","best_bid":"0.86","best_ask":"0.87"},{"asset_id":"86520121088881862182423437128238697252500151785248183602134095101149900014256","price":"0.14","size":"290.59","side":"SELL","hash":"4122d465be8801e0b3fb082248b25c447039ea7d","best_bid":"0.13","best_ask":"0.14"}],"timestamp":"1776808417435","event_type":"price_change"}}
{"capturedAt":1776808417,"payload":{"market":"0x125149c5918fc5f8c6d34682f700a898a1a19ea4f4e2ae68ff4c5794ba657074","price_changes":[{"asset_id":"45936375922793925919605092352922707796689801895417366600539442410775071099958","price":"0.76","size":"133.49","side":"BUY","hash":"1c8333512b534d6444dcfd6edcba96d5b0b6c42d","best_bid":"0.86","best_ask":"0.87"},{"asset_id":"86520121088881862182423437128238697252500151785248183602134095101149900014256","price":"0.24","size":"133.49","side":"SELL","hash":"4f05bf8bbb5eb9d3fd547fd67bcf4bff0fb7aac7","best_bid":"0.13","best_ask":"0.14"}],"timestamp":"1776808417437","event_type":"price_change"}}
{"capturedAt":1776808417,"payload":{"market":"0x125149c5918fc5f8c6d34682f700a898a1a19ea4f4e2ae68ff4c5794ba657074","price_changes":[{"asset_id":"45936375922793925919605092352922707796689801895417366600539442410775071099958","price":"0.86","size":"280.59","side":"BUY","hash":"18577893514ac89d9e4457c011f59f3bd7f47b7b","best_bid":"0.86","best_ask":"0.87"},{"asset_id":"86520121088881862182423437128238697252500151785248183602134095101149900014256","price":"0.14","size":"280.59","side":"SELL","hash":"25e8270dcdf6098775f6eb3e2737fbf7fb23c516","best_bid":"0.13","best_ask":"0.14"}],"timestamp":"1776808417438","event_type":"price_change"}}
{"capturedAt":1776808417,"payload":{"market":"0x125149c5918fc5f8c6d34682f700a898a1a19ea4f4e2ae68ff4c5794ba657074","price_changes":[{"asset_id":"45936375922793925919605092352922707796689801895417366600539442410775071099958","price":"0.86","size":"285.64","side":"BUY","hash":"8189130426396267b5870e6a458770d0dea6b8d2","best_bid":"0.86","best_ask":"0.87"},{"asset_id":"86520121088881862182423437128238697252500151785248183602134095101149900014256","price":"0.14","size":"285.64","side":"SELL","hash":"e8f6957735a2cc9978b9515d65dd44ae652896df","best_bid":"0.13","best_ask":"0.14"}],"timestamp":"1776808417439","event_type":"price_change"}}
{"capturedAt":1776808417,"payload":{"market":"0x125149c5918fc5f8c6d34682f700a898a1a19ea4f4e2ae68ff4c5794ba657074","price_changes":[{"asset_id":"45936375922793925919605092352922707796689801895417366600539442410775071099958","price":"0.86","size":"280.64","side":"BUY","hash":"278d8f9d4d4774855962e768dbc7e0ced00b56e0","best_bid":"0.86","best_ask":"0.87"},{"asset_id":"86520121088881862182423437128238697252500151785248183602134095101149900014256","price":"0.14","size":"280.64","side":"SELL","hash":"01f6d9ad128e332d91dd7eaab386ef145b07887e","best_bid":"0.13","best_ask":"0.14"}],"timestamp":"1776808417442","event_type":"price_change"}}
{"capturedAt":1776808417,"payload":{"market":"0x125149c5918fc5f8c6d34682f700a898a1a19ea4f4e2ae68ff4c5794ba657074","price_changes":[{"asset_id":"45936375922793925919605092352922707796689801895417366600539442410775071099958","price":"0.97","size":"1773.83","side":"SELL","hash":"ef8aa4f56193603696141b2aa55d54c7cb5d053f","best_bid":"0.86","best_ask":"0.87"},{"asset_id":"86520121088881862182423437128238697252500151785248183602134095101149900014256","price":"0.03","size":"1773.83","side":"BUY","hash":"530aa471f547f6e08b28cacb8c272f3a97b2096b","best_bid":"0.13","best_ask":"0.14"}],"timestamp":"1776808417447","event_type":"price_change"}}
{"capturedAt":1776808417,"payload":{"market":"0x125149c5918fc5f8c6d34682f700a898a1a19ea4f4e2ae68ff4c5794ba657074","price_changes":[{"asset_id":"45936375922793925919605092352922707796689801895417366600539442410775071099958","price":"0.82","size":"371.78","side":"BUY","hash":"ef8aa4f56193603696141b2aa55d54c7cb5d053f","best_bid":"0.86","best_ask":"0.87"},{"asset_id":"86520121088881862182423437128238697252500151785248183602134095101149900014256","price":"0.18","size":"371.78","side":"SELL","hash":"530aa471f547f6e08b28cacb8c272f3a97b2096b","best_bid":"0.13","best_ask":"0.14"}],"timestamp":"1776808417447","event_type":"price_change"}}
{"capturedAt":1776808417,"payload":{"market":"0x125149c5918fc5f8c6d34682f700a898a1a19ea4f4e2ae68ff4c5794ba657074","price_changes":[{"asset_id":"86520121088881862182423437128238697252500151785248183602134095101149900014256","price":"0.04","size":"968.3","side":"BUY","hash":"5d55c446bbe3988421594ee600654907774b9ce0","best_bid":"0.13","best_ask":"0.14"},{"asset_id":"45936375922793925919605092352922707796689801895417366600539442410775071099958","price":"0.96","size":"968.3","side":"SELL","hash":"813d7740bfb414805c92e3fb2724d7357828de18","best_bid":"0.86","best_ask":"0.87"}],"timestamp":"1776808417448","event_type":"price_change"}}
{"capturedAt":1776808417,"payload":{"market":"0x125149c5918fc5f8c6d34682f700a898a1a19ea4f4e2ae68ff4c5794ba657074","price_changes":[{"asset_id":"45936375922793925919605092352922707796689801895417366600539442410775071099958","price":"0.86","size":"290.64","side":"BUY","hash":"843c39d42f67c1884c3bc92eef2a940bb7774cb6","best_bid":"0.86","best_ask":"0.87"},{"asset_id":"86520121088881862182423437128238697252500151785248183602134095101149900014256","price":"0.14","size":"290.64","side":"SELL","hash":"092166b5c963b0b929a96dc82a0412ab8920f277","best_bid":"0.13","best_ask":"0.14"}],"timestamp":"1776808417449","event_type":"price_change"}}
{"capturedAt":1776808417,"payload":{"market":"0x125149c5918fc5f8c6d34682f700a898a1a19ea4f4e2ae68ff4c5794ba657074","price_changes":[{"asset_id":"45936375922793925919605092352922707796689801895417366600539442410775071099958","price":"0.86","size":"280.64","side":"BUY","hash":"5ca5294be445ceec78755e836c4d2f42fd11dc9f","best_bid":"0.86","best_ask":"0.87"},{"asset_id":"86520121088881862182423437128238697252500151785248183602134095101149900014256","price":"0.14","size":"280.64","side":"SELL","hash":"fad4f06b3d1e89724544835bcc0b539c5ab6ed15","best_bid":"0.13","best_ask":"0.14"}],"timestamp":"1776808417452","event_type":"price_change"}}
{"capturedAt":1776808417,"payload":{"market":"0x125149c5918fc5f8c6d34682f700a898a1a19ea4f4e2ae68ff4c5794ba657074","price_changes":[{"asset_id":"45936375922793925919605092352922707796689801895417366600539442410775071099958","price":"0.97","size":"1743.83","side":"SELL","hash":"5be8cac72210aa173f767d8beaf9ccd34326afed","best_bid":"0.86","best_ask":"0.87"},{"asset_id":"86520121088881862182423437128238697252500151785248183602134095101149900014256","price":"0.03","size":"1743.83","side":"BUY","hash":"8f50776e5aa6971115f5a5d873268a9df4d9af61","best_bid":"0.13","best_ask":"0.14"}],"timestamp":"1776808417453","event_type":"price_change"}}
{"capturedAt":1776808417,"payload":{"market":"0x125149c5918fc5f8c6d34682f700a898a1a19ea4f4e2ae68ff4c5794ba657074","price_changes":[{"asset_id":"45936375922793925919605092352922707796689801895417366600539442410775071099958","price":"0.82","size":"341.78","side":"BUY","hash":"5be8cac72210aa173f767d8beaf9ccd34326afed","best_bid":"0.86","best_ask":"0.87"},{"asset_id":"86520121088881862182423437128238697252500151785248183602134095101149900014256","price":"0.18","size":"341.78","side":"SELL","hash":"8f50776e5aa6971115f5a5d873268a9df4d9af61","best_bid":"0.13","best_ask":"0.14"}],"timestamp":"1776808417453","event_type":"price_change"}}
{"capturedAt":1776808417,"payload":{"market":"0x125149c5918fc5f8c6d34682f700a898a1a19ea4f4e2ae68ff4c5794ba657074","price_changes":[{"asset_id":"86520121088881862182423437128238697252500151785248183602134095101149900014256","price":"0.04","size":"998.3","side":"BUY","hash":"39072e43dc0c25f392070db99bcd70d49076a511","best_bid":"0.13","best_ask":"0.14"},{"asset_id":"45936375922793925919605092352922707796689801895417366600539442410775071099958","price":"0.96","size":"998.3","side":"SELL","hash":"75aa1375348ee54f28d6710afc7cee3d0c5c2bbc","best_bid":"0.86","best_ask":"0.87"}],"timestamp":"1776808417455","event_type":"price_change"}}
{"capturedAt":1776808417,"payload":{"market":"0x125149c5918fc5f8c6d34682f700a898a1a19ea4f4e2ae68ff4c5794ba657074","price_changes":[{"asset_id":"86520121088881862182423437128238697252500151785248183602134095101149900014256","price":"0.13","size":"208.74","side":"BUY","hash":"473e8181f4d9fa3efaf793c8cf3cf3e602846e68","best_bid":"0.13","best_ask":"0.14"},{"asset_id":"45936375922793925919605092352922707796689801895417366600539442410775071099958","price":"0.87","size":"208.74","side":"SELL","hash":"9fd176dc4a7a118feed4b330c56e9c43e48c9309","best_bid":"0.86","best_ask":"0.87"}],"timestamp":"1776808417456","event_type":"price_change"}}
{"capturedAt":1776808417,"payload":{"market":"0x125149c5918fc5f8c6d34682f700a898a1a19ea4f4e2ae68ff4c5794ba657074","price_changes":[{"asset_id":"45936375922793925919605092352922707796689801895417366600539442410775071099958","price":"0.86","size":"274.64","side":"BUY","hash":"187ebd864c1a50221586a1f1f999f4ebe078eaeb","best_bid":"0.86","best_ask":"0.87"},{"asset_id":"86520121088881862182423437128238697252500151785248183602134095101149900014256","price":"0.14","size":"274.64","side":"SELL","hash":"2ffb5df7d599450b01d3d2888069783c0c1ef648","best_bid":"0.13","best_ask":"0.14"}],"timestamp":"1776808417457","event_type":"price_change"}}
{"capturedAt":1776808417,"payload":{"market":"0x125149c5918fc5f8c6d34682f700a898a1a19ea4f4e2ae68ff4c5794ba657074","price_changes":[{"asset_id":"45936375922793925919605092352922707796689801895417366600539442410775071099958","price":"0.86","size":"263.64","side":"BUY","hash":"37796cb53f5053b3560805dd84c3c647b14b9dec","best_bid":"0.86","best_ask":"0.87"},{"asset_id":"86520121088881862182423437128238697252500151785248183602134095101149900014256","price":"0.14","size":"263.64","side":"SELL","hash":"20bb8993f4054fdd722aa08bf2838d914db8d9c1","best_bid":"0.13","best_ask":"0.14"}],"timestamp":"1776808417458","event_type":"price_change"}}
{"capturedAt":1776808417,"payload":{"market":"0x125149c5918fc5f8c6d34682f700a898a1a19ea4f4e2ae68ff4c5794ba657074","price_changes":[{"asset_id":"45936375922793925919605092352922707796689801895417366600539442410775071099958","price":"0.86","size":"252.64","side":"BUY","hash":"6a9e8c019eab2cc35a7c1224f3beadb92fa544fe","best_bid":"0.86","best_ask":"0.87"},{"asset_id":"86520121088881862182423437128238697252500151785248183602134095101149900014256","price":"0.14","size":"252.64","side":"SELL","hash":"625338d9c3b56e9d276de13f01bdcc10cd1903ed","best_bid":"0.13","best_ask":"0.14"}],"timestamp":"1776808417459","event_type":"price_change"}}
{"capturedAt":1776808417,"payload":{"market":"0x125149c5918fc5f8c6d34682f700a898a1a19ea4f4e2ae68ff4c5794ba657074","price_changes":[{"asset_id":"45936375922793925919605092352922707796689801895417366600539442410775071099958","price":"0.86","size":"247.59","side":"BUY","hash":"3917b1f1618aa165796161879d604c49c31fc457","best_bid":"0.86","best_ask":"0.87"},{"asset_id":"86520121088881862182423437128238697252500151785248183602134095101149900014256","price":"0.14","size":"247.59","side":"SELL","hash":"f5734b77693f0c37380d7c0d62c172b5906b9083","best_bid":"0.13","best_ask":"0.14"}],"timestamp":"1776808417460","event_type":"price_change"}}
{"capturedAt":1776808417,"payload":{"market":"0x125149c5918fc5f8c6d34682f700a898a1a19ea4f4e2ae68ff4c5794ba657074","price_changes":[{"asset_id":"45936375922793925919605092352922707796689801895417366600539442410775071099958","price":"0.48","size":"237.56","side":"BUY","hash":"6e0900187caf0f2caf405e3bfbedf8c432e20a32","best_bid":"0.86","best_ask":"0.87"},{"asset_id":"86520121088881862182423437128238697252500151785248183602134095101149900014256","price":"0.52","size":"237.56","side":"SELL","hash":"b42d689a3ac94ad3ba0192e90ee1413866012da2","best_bid":"0.13","best_ask":"0.14"}],"timestamp":"1776808417461","event_type":"price_change"}}
{"capturedAt":1776808417,"payload":{"market":"0x125149c5918fc5f8c6d34682f700a898a1a19ea4f4e2ae68ff4c5794ba657074","price_changes":[{"asset_id":"45936375922793925919605092352922707796689801895417366600539442410775071099958","price":"0.86","size":"242.59","side":"BUY","hash":"78d20d5dfc2a818620b623228a95f355509a3fbc","best_bid":"0.86","best_ask":"0.87"},{"asset_id":"86520121088881862182423437128238697252500151785248183602134095101149900014256","price":"0.14","size":"242.59","side":"SELL","hash":"b271b8a0c877962202203024775f849d522241d6","best_bid":"0.13","best_ask":"0.14"}],"timestamp":"1776808417462","event_type":"price_change"}}
{"capturedAt":1776808417,"payload":{"market":"0x125149c5918fc5f8c6d34682f700a898a1a19ea4f4e2ae68ff4c5794ba657074","price_changes":[{"asset_id":"45936375922793925919605092352922707796689801895417366600539442410775071099958","price":"0.86","size":"249.59","side":"BUY","hash":"645131cce91d6e01dba0f06e19e60f3326d9fa4f","best_bid":"0.86","best_ask":"0.87"},{"asset_id":"86520121088881862182423437128238697252500151785248183602134095101149900014256","price":"0.14","size":"249.59","side":"SELL","hash":"e7fb25caffa51ce1a59f425b9dc9758ca1d28539","best_bid":"0.13","best_ask":"0.14"}],"timestamp":"1776808417465","event_type":"price_change"}}
{"capturedAt":1776808417,"payload":{"market":"0x125149c5918fc5f8c6d34682f700a898a1a19ea4f4e2ae68ff4c5794ba657074","price_changes":[{"asset_id":"45936375922793925919605092352922707796689801895417366600539442410775071099958","price":"0.01","size":"12329.83","side":"BUY","hash":"a9d5931ce6dacb1b6dd9759bc95c43e457bf1c07","best_bid":"0.86","best_ask":"0.87"},{"asset_id":"86520121088881862182423437128238697252500151785248183602134095101149900014256","price":"0.99","size":"12329.83","side":"SELL","hash":"89ba61f3e9facf467625974de49c515813d5159b","best_bid":"0.13","best_ask":"0.14"}],"timestamp":"1776808417464","event_type":"price_change"}}
{"capturedAt":1776808417,"payload":{"market":"0x125149c5918fc5f8c6d34682f700a898a1a19ea4f4e2ae68ff4c5794ba657074","price_changes":[{"asset_id":"45936375922793925919605092352922707796689801895417366600539442410775071099958","price":"0.86","size":"242.59","side":"BUY","hash":"b893a4dacd7baab8e37ec97924f5baa3ebeb9e3e","best_bid":"0.86","best_ask":"0.87"},{"asset_id":"86520121088881862182423437128238697252500151785248183602134095101149900014256","price":"0.14","size":"242.59","side":"SELL","hash":"2eea0b36284713a6bf266a48a4ecab4460835e77","best_bid":"0.13","best_ask":"0.14"}],"timestamp":"1776808417466","event_type":"price_change"}}
{"capturedAt":1776808417,"payload":{"market":"0x125149c5918fc5f8c6d34682f700a898a1a19ea4f4e2ae68ff4c5794ba657074","price_changes":[{"asset_id":"45936375922793925919605092352922707796689801895417366600539442410775071099958","price":"0.86","size":"231.59","side":"BUY","hash":"0f5b8fffdadb45cf6e37f5709a1fb5923fcdb898","best_bid":"0.86","best_ask":"0.87"},{"asset_id":"86520121088881862182423437128238697252500151785248183602134095101149900014256","price":"0.14","size":"231.59","side":"SELL","hash":"ee72d387818ec9249bb89f4fbdd66649e75f18ff","best_bid":"0.13","best_ask":"0.14"}],"timestamp":"1776808417467","event_type":"price_change"}}
{"capturedAt":1776808417,"payload":{"market":"0x125149c5918fc5f8c6d34682f700a898a1a19ea4f4e2ae68ff4c5794ba657074","price_changes":[{"asset_id":"45936375922793925919605092352922707796689801895417366600539442410775071099958","price":"0.86","size":"241.59","side":"BUY","hash":"a6232b9b2576817ce6cf3bbb3f12c7e6131800a2","best_bid":"0.86","best_ask":"0.87"},{"asset_id":"86520121088881862182423437128238697252500151785248183602134095101149900014256","price":"0.14","size":"241.59","side":"SELL","hash":"a4c25b0736218c7cbd38d295eb91b2df8bfe59db","best_bid":"0.13","best_ask":"0.14"}],"timestamp":"1776808417469","event_type":"price_change"}}
{"capturedAt":1776808417,"payload":{"market":"0x125149c5918fc5f8c6d34682f700a898a1a19ea4f4e2ae68ff4c5794ba657074","price_changes":[{"asset_id":"45936375922793925919605092352922707796689801895417366600539442410775071099958","price":"0.01","size":"12334.83","side":"BUY","hash":"89541e39dadfbe646f308b14b9d5e0f819e6c192","best_bid":"0.86","best_ask":"0.87"},{"asset_id":"86520121088881862182423437128238697252500151785248183602134095101149900014256","price":"0.99","size":"12334.83","side":"SELL","hash":"7e9f237a696079bc336d031ad43270e6f45b9582","best_bid":"0.13","best_ask":"0.14"}],"timestamp":"1776808417474","event_type":"price_change"}}
{"capturedAt":1776808417,"payload":{"market":"0x125149c5918fc5f8c6d34682f700a898a1a19ea4f4e2ae68ff4c5794ba657074","price_changes":[{"asset_id":"45936375922793925919605092352922707796689801895417366600539442410775071099958","price":"0.86","size":"231.59","side":"BUY","hash":"edf248a2aa37c88b61fa8d2b98a5f5631af98f98","best_bid":"0.86","best_ask":"0.87"},{"asset_id":"86520121088881862182423437128238697252500151785248183602134095101149900014256","price":"0.14","size":"231.59","side":"SELL","hash":"e8bd3912a7377ccb77f5bb6c8ef5de8db1201eda","best_bid":"0.13","best_ask":"0.14"}],"timestamp":"1776808417475","event_type":"price_change"}}
{"capturedAt":1776808417,"payload":{"market":"0x125149c5918fc5f8c6d34682f700a898a1a19ea4f4e2ae68ff4c5794ba657074","price_changes":[{"asset_id":"86520121088881862182423437128238697252500151785248183602134095101149900014256","price":"0.12","size":"332.5","side":"BUY","hash":"a1230e7e35f5e34fbafe0876772f2d3531517d50","best_bid":"0.13","best_ask":"0.14"},{"asset_id":"45936375922793925919605092352922707796689801895417366600539442410775071099958","price":"0.88","size":"332.5","side":"SELL","hash":"7e3e55f475f85e4e5bfe8a35315980215791ba8a","best_bid":"0.86","best_ask":"0.87"}],"timestamp":"1776808417478","event_type":"price_change"}}
{"capturedAt":1776808417,"payload":{"market":"0x125149c5918fc5f8c6d34682f700a898a1a19ea4f4e2ae68ff4c5794ba657074","price_changes":[{"asset_id":"45936375922793925919605092352922707796689801895417366600539442410775071099958","price":"0.85","size":"452.28","side":"BUY","hash":"5a68de7c6ab270cd939561bfb4c2babcab4ec724","best_bid":"0.86","best_ask":"0.87"},{"asset_id":"86520121088881862182423437128238697252500151785248183602134095101149900014256","price":"0.15","size":"452.28","side":"SELL","hash":"e38d95cc9883b9c2a2f9ab52b8494d5547a3969f","best_bid":"0.13","best_ask":"0.14"}],"timestamp":"1776808417476","event_type":"price_change"}}
{"capturedAt":1776808417,"payload":{"market":"0x125149c5918fc5f8c6d34682f700a898a1a19ea4f4e2ae68ff4c5794ba657074","price_changes":[{"asset_id":"86520121088881862182423437128238697252500151785248183602134095101149900014256","price":"0.13","size":"203.74","side":"BUY","hash":"e927a86f26ffdd119e912593774864031ed38bdf","best_bid":"0.13","best_ask":"0.14"},{"asset_id":"45936375922793925919605092352922707796689801895417366600539442410775071099958","price":"0.87","size":"203.74","side":"SELL","hash":"d1db74ffcc72eabb846d4a86751a5f3c662282c6","best_bid":"0.86","best_ask":"0.87"}],"timestamp":"1776808417478","event_type":"price_change"}}
{"capturedAt":1776808417,"payload":{"market":"0x125149c5918fc5f8c6d34682f700a898a1a19ea4f4e2ae68ff4c5794ba657074","price_changes":[{"asset_id":"45936375922793925919605092352922707796689801895417366600539442410775071099958","price":"0.86","size":"220.59","side":"BUY","hash":"7a886b7b2197486e52364abba5bbf3feefba2687","best_bid":"0.86","best_ask":"0.87"},{"asset_id":"86520121088881862182423437128238697252500151785248183602134095101149900014256","price":"0.14","size":"220.59","side":"SELL","hash":"da73b266dad7929e9cca216851b2182fe7c0cc31","best_bid":"0.13","best_ask":"0.14"}],"timestamp":"1776808417479","event_type":"price_change"}}
{"capturedAt":1776808417,"payload":{"market":"0x125149c5918fc5f8c6d34682f700a898a1a19ea4f4e2ae68ff4c5794ba657074","price_changes":[{"asset_id":"45936375922793925919605092352922707796689801895417366600539442410775071099958","price":"0.91","size":"202","side":"SELL","hash":"c480d8a714d2e580aba5aefc672df68201b08ac0","best_bid":"0.86","best_ask":"0.87"},{"asset_id":"86520121088881862182423437128238697252500151785248183602134095101149900014256","price":"0.09","size":"202","side":"BUY","hash":"0ad77f213b78dff96775ce510c80446d10b465b1","best_bid":"0.13","best_ask":"0.14"}],"timestamp":"1776808417481","event_type":"price_change"}}
{"capturedAt":1776808417,"payload":{"market":"0x125149c5918fc5f8c6d34682f700a898a1a19ea4f4e2ae68ff4c5794ba657074","price_changes":[{"asset_id":"45936375922793925919605092352922707796689801895417366600539442410775071099958","price":"0.75","size":"475.29","side":"BUY","hash":"c480d8a714d2e580aba5aefc672df68201b08ac0","best_bid":"0.86","best_ask":"0.87"},{"asset_id":"86520121088881862182423437128238697252500151785248183602134095101149900014256","price":"0.25","size":"475.29","side":"SELL","hash":"0ad77f213b78dff96775ce510c80446d10b465b1","best_bid":"0.13","best_ask":"0.14"}],"timestamp":"1776808417481","event_type":"price_change"}}
{"capturedAt":1776808417,"payload":{"market":"0x125149c5918fc5f8c6d34682f700a898a1a19ea4f4e2ae68ff4c5794ba657074","price_changes":[{"asset_id":"45936375922793925919605092352922707796689801895417366600539442410775071099958","price":"0.82","size":"371.78","side":"BUY","hash":"1a518f4394b8867de5a29232f05d262f94121bd0","best_bid":"0.86","best_ask":"0.87"},{"asset_id":"86520121088881862182423437128238697252500151785248183602134095101149900014256","price":"0.18","size":"371.78","side":"SELL","hash":"0dd0bd69156e10abbcb1a466019d78430df73640","best_bid":"0.13","best_ask":"0.14"}],"timestamp":"1776808417483","event_type":"price_change"}}
{"capturedAt":1776808417,"payload":{"market":"0x125149c5918fc5f8c6d34682f700a898a1a19ea4f4e2ae68ff4c5794ba657074","price_changes":[{"asset_id":"45936375922793925919605092352922707796689801895417366600539442410775071099958","price":"0.81","size":"309.9","side":"BUY","hash":"75d43f584c611c1c814f0309a926fed3f37caab0","best_bid":"0.86","best_ask":"0.87"},{"asset_id":"86520121088881862182423437128238697252500151785248183602134095101149900014256","price":"0.19","size":"309.9","side":"SELL","hash":"348498cb709421a2ba097bfd7f201038b68897f9","best_bid":"0.13","best_ask":"0.14"}],"timestamp":"1776808417485","event_type":"price_change"}}
{"capturedAt":1776808417,"payload":{"market":"0x125149c5918fc5f8c6d34682f700a898a1a19ea4f4e2ae68ff4c5794ba657074","price_changes":[{"asset_id":"45936375922793925919605092352922707796689801895417366600539442410775071099958","price":"0.01","size":"12329.83","side":"BUY","hash":"360d545082cb5123e8191a73f2ee3cdfbb392a6c","best_bid":"0.86","best_ask":"0.87"},{"asset_id":"86520121088881862182423437128238697252500151785248183602134095101149900014256","price":"0.99","size":"12329.83","side":"SELL","hash":"7a9954ce0c228f77b795aceabcd7b13fb8037602","best_bid":"0.13","best_ask":"0.14"}],"timestamp":"1776808417486","event_type":"price_change"}}
{"capturedAt":1776808417,"payload":{"market":"0x125149c5918fc5f8c6d34682f700a898a1a19ea4f4e2ae68ff4c5794ba657074","price_changes":[{"asset_id":"45936375922793925919605092352922707796689801895417366600539442410775071099958","price":"0.96","size":"1028.3","side":"SELL","hash":"b1c50e096ad35b7478d3b9439d4fc8d998feb9fc","best_bid":"0.86","best_ask":"0.87"},{"asset_id":"86520121088881862182423437128238697252500151785248183602134095101149900014256","price":"0.04","size":"1028.3","side":"BUY","hash":"80c5094e44fc6fa9a40b2fa26557a956ea3eb168","best_bid":"0.13","best_ask":"0.14"}],"timestamp":"1776808417488","event_type":"price_change"}}
{"capturedAt":1776808417,"payload":{"market":"0x125149c5918fc5f8c6d34682f700a898a1a19ea4f4e2ae68ff4c5794ba657074","price_changes":[{"asset_id":"45936375922793925919605092352922707796689801895417366600539442410775071099958","price":"0.86","size":"209.59","side":"BUY","hash":"2592226d54c10dddcf969e1f6da3497933ceef84","best_bid":"0.86","best_ask":"0.87"},{"asset_id":"86520121088881862182423437128238697252500151785248183602134095101149900014256","price":"0.14","size":"209.59","side":"SELL","hash":"2025e38d51a78653b03d4d62bab17f5af9fa2d94","best_bid":"0.13","best_ask":"0.14"}],"timestamp":"1776808417489","event_type":"price_change"}}
{"capturedAt":1776808417,"payload":{"market":"0x125149c5918fc5f8c6d34682f700a898a1a19ea4f4e2ae68ff4c5794ba657074","price_changes":[{"asset_id":"86520121088881862182423437128238697252500151785248183602134095101149900014256","price":"0.04","size":"998.3","side":"BUY","hash":"b543d289cf6429b613b20cb9d33e74a40633cd8a","best_bid":"0.13","best_ask":"0.14"},{"asset_id":"45936375922793925919605092352922707796689801895417366600539442410775071099958","price":"0.96","size":"998.3","side":"SELL","hash":"958d8b2fba0fdfb45f2d84fb9a43dc92cee85407","best_bid":"0.86","best_ask":"0.87"}],"timestamp":"1776808417490","event_type":"price_change"}}
{"capturedAt":1776808417,"payload":{"market":"0x125149c5918fc5f8c6d34682f700a898a1a19ea4f4e2ae68ff4c5794ba657074","price_changes":[{"asset_id":"45936375922793925919605092352922707796689801895417366600539442410775071099958","price":"0.82","size":"341.78","side":"BUY","hash":"99bae55be413db6948f4458cb539966d8bec6c1e","best_bid":"0.86","best_ask":"0.87"},{"asset_id":"86520121088881862182423437128238697252500151785248183602134095101149900014256","price":"0.18","size":"341.78","side":"SELL","hash":"14435f445e379df660ca378c98656f954ae70b60","best_bid":"0.13","best_ask":"0.14"}],"timestamp":"1776808417492","event_type":"price_change"}}
{"capturedAt":1776808417,"payload":{"market":"0x125149c5918fc5f8c6d34682f700a898a1a19ea4f4e2ae68ff4c5794ba657074","price_changes":[{"asset_id":"45936375922793925919605092352922707796689801895417366600539442410775071099958","price":"0.82","size":"335.9","side":"BUY","hash":"e3d6109a93899c8ebdf6419ac5bfba4d05c8311d","best_bid":"0.86","best_ask":"0.87"},{"asset_id":"86520121088881862182423437128238697252500151785248183602134095101149900014256","price":"0.18","size":"335.9","side":"SELL","hash":"dbea405fa28f67ee66c1f5836e4daef919ea9290","best_bid":"0.13","best_ask":"0.14"}],"timestamp":"1776808417494","event_type":"price_change"}}
{"capturedAt":1776808417,"payload":{"market":"0x125149c5918fc5f8c6d34682f700a898a1a19ea4f4e2ae68ff4c5794ba657074","price_changes":[{"asset_id":"86520121088881862182423437128238697252500151785248183602134095101149900014256","price":"0.1","size":"793.5","side":"BUY","hash":"4627ddee40c63d31a09115ed6454e4e25ffa153e","best_bid":"0.13","best_ask":"0.14"},{"asset_id":"45936375922793925919605092352922707796689801895417366600539442410775071099958","price":"0.9","size":"793.5","side":"SELL","hash":"02e5df8edec4f05a9996b9fc4e03f7971fb4508f","best_bid":"0.86","best_ask":"0.87"}],"timestamp":"1776808417495","event_type":"price_change"}}
{"capturedAt":1776808417,"payload":{"market":"0x125149c5918fc5f8c6d34682f700a898a1a19ea4f4e2ae68ff4c5794ba657074","price_changes":[{"asset_id":"45936375922793925919605092352922707796689801895417366600539442410775071099958","price":"0.68","size":"362.5","side":"BUY","hash":"3db84ce7d714d6b2d4c30f4bd115c7c698f859e4","best_bid":"0.86","best_ask":"0.87"},{"asset_id":"86520121088881862182423437128238697252500151785248183602134095101149900014256","price":"0.32","size":"362.5","side":"SELL","hash":"8cf669d68ec6a90e8451acd55f61757bc0489afa","best_bid":"0.13","best_ask":"0.14"}],"timestamp":"1776808417493","event_type":"price_change"}}
{"capturedAt":1776808417,"payload":{"market":"0x125149c5918fc5f8c6d34682f700a898a1a19ea4f4e2ae68ff4c5794ba657074","price_changes":[{"asset_id":"86520121088881862182423437128238697252500151785248183602134095101149900014256","price":"0.04","size":"968.3","side":"BUY","hash":"c5db78dbf18a788b5f7753d65d1a187a772e08b9","best_bid":"0.13","best_ask":"0.14"},{"asset_id":"45936375922793925919605092352922707796689801895417366600539442410775071099958","price":"0.96","size":"968.3","side":"SELL","hash":"8ac42418910b81df17e52d75b3fb011b3d818aca","best_bid":"0.86","best_ask":"0.87"}],"timestamp":"1776808417491","event_type":"price_change"}}
{"capturedAt":1776808417,"payload":{"market":"0x125149c5918fc5f8c6d34682f700a898a1a19ea4f4e2ae68ff4c5794ba657074","price_changes":[{"asset_id":"45936375922793925919605092352922707796689801895417366600539442410775071099958","price":"0.96","size":"998.3","side":"SELL","hash":"5f633347b7be337c2319babb1ec5389ede2bee0d","best_bid":"0.86","best_ask":"0.87"},{"asset_id":"86520121088881862182423437128238697252500151785248183602134095101149900014256","price":"0.04","size":"998.3","side":"BUY","hash":"38ec4159b23f877aaef21e2baa6c161b8d854ba5","best_bid":"0.13","best_ask":"0.14"}],"timestamp":"1776808417496","event_type":"price_change"}}
{"capturedAt":1776808417,"payload":{"market":"0x125149c5918fc5f8c6d34682f700a898a1a19ea4f4e2ae68ff4c5794ba657074","price_changes":[{"asset_id":"86520121088881862182423437128238697252500151785248183602134095101149900014256","price":"0.13","size":"208.74","side":"BUY","hash":"73b19f8227f5df6c05d1f849d2158b80f14eb13a","best_bid":"0.13","best_ask":"0.14"},{"asset_id":"45936375922793925919605092352922707796689801895417366600539442410775071099958","price":"0.87","size":"208.74","side":"SELL","hash":"0e4f0d141efa5399f08fc03c537278e839c914e7","best_bid":"0.86","best_ask":"0.87"}],"timestamp":"1776808417497","event_type":"price_change"}}
{"capturedAt":1776808417,"payload":{"market":"0x125149c5918fc5f8c6d34682f700a898a1a19ea4f4e2ae68ff4c5794ba657074","price_changes":[{"asset_id":"86520121088881862182423437128238697252500151785248183602134095101149900014256","price":"0.1","size":"593.5","side":"BUY","hash":"fe5ee6d9e29fde80a2bf046f7c2e5553bf736a81","best_bid":"0.13","best_ask":"0.14"},{"asset_id":"45936375922793925919605092352922707796689801895417366600539442410775071099958","price":"0.9","size":"593.5","side":"SELL","hash":"e12586b4fa77ea4b0a85e13c2cda7467414b4c7b","best_bid":"0.86","best_ask":"0.87"}],"timestamp":"1776808417498","event_type":"price_change"}}
{"capturedAt":1776808417,"payload":{"market":"0x125149c5918fc5f8c6d34682f700a898a1a19ea4f4e2ae68ff4c5794ba657074","price_changes":[{"asset_id":"45936375922793925919605092352922707796689801895417366600539442410775071099958","price":"0.75","size":"275.29","side":"BUY","hash":"168798f3145fca0e2f9a8b07a962553acc1c4a58","best_bid":"0.86","best_ask":"0.87"},{"asset_id":"86520121088881862182423437128238697252500151785248183602134095101149900014256","price":"0.25","size":"275.29","side":"SELL","hash":"b20f5a6dc5126c892f9d7cd1050683ab2a0663b7","best_bid":"0.13","best_ask":"0.14"}],"timestamp":"1776808417498","event_type":"price_change"}}
{"capturedAt":1776808417,"payload":{"market":"0x125149c5918fc5f8c6d34682f700a898a1a19ea4f4e2ae68ff4c5794ba657074","price_changes":[{"asset_id":"86520121088881862182423437128238697252500151785248183602134095101149900014256","price":"0.07","size":"454.3","side":"BUY","hash":"611d93a441fde129f79b647bf2f7a12de2dfc264","best_bid":"0.13","best_ask":"0.14"},{"asset_id":"45936375922793925919605092352922707796689801895417366600539442410775071099958","price":"0.93","size":"454.3","side":"SELL","hash":"ba7f3a58364775bb00c3ed97bb579f1ea5fd72c6","best_bid":"0.86","best_ask":"0.87"}],"timestamp":"1776808417500","event_type":"price_change"}}
{"capturedAt":1776808417,"payload":{"market":"0x125149c5918fc5f8c6d34682f700a898a1a19ea4f4e2ae68ff4c5794ba657074","price_changes":[{"asset_id":"86520121088881862182423437128238697252500151785248183602134095101149900014256","price":"0.1","size":"593.5","side":"BUY","hash":"611d93a441fde129f79b647bf2f7a12de2dfc264","best_bid":"0.13","best_ask":"0.14"},{"asset_id":"45936375922793925919605092352922707796689801895417366600539442410775071099958","price":"0.9","size":"593.5","side":"SELL","hash":"ba7f3a58364775bb00c3ed97bb579f1ea5fd72c6","best_bid":"0.86","best_ask":"0.87"}],"timestamp":"1776808417500","event_type":"price_change"}}
